Workbook

Sheet التعليم الابتدائي
A1: مدارس الابتدائي للوقف الشيعي | F1: جنس المدرسة | I1: بيئة المدرسة | K1: دوام المدرسة | O1: استقلالية المدرسة | Q1: نوع الازدواج | U1: هل المدرسة فتح جديد | V1: تحتوي على المدرسة | Y1: عدد التلامذة المستجدين حسب العمر | AN1: عدد التلامذة المسجلين في الصف الاول الابتدائي حسب العمر والجنس | BC1: عدد التلامذة المسجلين في الصف الثاني الابتدائي حسب العمر والجنس | BP1: عدد التلامذة المسجلين في الصف الثالث الابتدائي حسب العمر والجنس | CC1: عدد التلامذة المسجلين في الصف الرابع الابتدائي حسب العمر والجنس | CP1: عدد التلامذة المسجلين في الصف الخامس الابتدائي حسب العمر والجنس | DC1: عدد التلامذة المسجلين في الصف السادس الابتدائي حسب العمر والجنس | DP1: مجموع عدد التلاميذ المسجلين حسب العمر والجنس | EO1: عدد الشعب حسب الصف والجنس | FK1: عدد التلاميذ التاركين حسب الصف والجنس للعام2026 /2025 | FZ1: عدد التلاميذ الناجحين حسب الصف والجنس للعام الدراسي2024 /2025 | GO1: عدد التلاميذ الراسبين بسبب الفشل في الامتحان و حسب الصف والجنس للعام الدراسي2024 /2025 | HD1: عدد التلاميذ الراسبين بسبب تجاوز ايام الغياب وحسب الصف والجنس للعام الدراسي2024 /2025 | HS1: عدد التلاميذ الراسبين لأسباب اخرى وحسب الصف والجنس للعام الدراسي2024 /2025 | IH1: عدد التلاميذ الراسبين لجميع الاسباب وحسب الصف والجنس للعام الدراسي2024 /2025 | IW1: اعضاء الهيئة التعليمية حسب العنوان الوظيفي | JH1: الموظفون الاداريون والخدميون حسب العنوان الوظيفي | JZ1: عدد الهيئة التعليمية حسب الجنسية | KI1: عدد اعضاء الهيئة التعليمية حسب الحالة الوظيفية | LE1: عدد اعضاء الهيئة التعليمية حسب الشهادة والتخصص | MB1: عدد اعضاء الهيئة التعليمية حسب الشهادة والتخصص | MY1: عدد اعضاء الهيئة التعليمية حسب الشهادة والتخصص | NV1: عدد اعضاء الهيئة التعليمية حسب الشهادة والتخصص | OS1: عدد اعضاء الهيئة التعليمية حسب الشهادة والتخصص | PP1: عدد اعضاء الهيئة التعليمية حسب الشهادة والتخصص | QM1: عدد اعضاء الهيئة التعليمية حسب الشهادة والتخصص | RJ1: عدد اعضاء الهيئة التعليمية حسب الشهادة والتخصص | SG1: عدد اعضاء الهيئة التعليمية حسب الشهادة والتخصص | TD1: عدد اعضاء الهيئة التعليمية حسب الشهادة والتخصص | UA1: عدد اعضاء الهيئة التعليمية حسب الشهادة والتخصص | UX1: عدد اعضاء الهيئة التعليمية حسب الشهادة والتخصص | VU1: عدد اعضاء الهيئة التعليمية حسب الشهادة والتخصص | WR1: عدد اعضاء الهيئة التعليمية حسب الشهادة والتخصص | XO1: عدد اعضاء الهيئة التعليمية حسب الشهادة والتخصص | YL1: عدد اعضاء الهيئة التعليمية حسب الشهادة والتخصص | ZI1: عدد اعضاء الهيئة التعليمية حسب الشهادة والتخصص | AAF1: عدد اعضاء الهيئة التعليمية حسب الشهادة والتخصص | ABC1: عدد اعضاء الهيئة التعليمية حسب الشهادة والتخصص | ABZ1: عدد اعضاء الهيئة التعليمية حسب الشهادة والتخصص | ACW1: عدد اعضاء الهيئة التعليمية حسب الشهادة والتخصص | ADT1: عدد اعضاء الهيئة التعليمية حسب الشهادة والتخصص | AEQ1: عدد اعضاء الهيئة التعليمية حسب سنوات الخدمة | AFQ1: عدد اعضاء الهيئة التعليمية حسب الحالة الاجتماعية | AGB1: دالة التصحيح للملاك | AGE1: عدد اعضاء الهيئة التعليمية المشاركين في الدورات التدريبية للعام السابق | AGH1: عدد التلامذة المسجلين من غير العراقيين | AGK1: التطــــبــــيـــــــــــــــــقاتـــ ( هل المدرسة مشمولة بــ : ) | AHA1: المدارس المشمولة بالتربية الخاصة | ALJ1: المختبرات المدرسية | ALL1: اقرب نقطة دالة للمدرسة | ALM1: المدير | ALN1: رقم الموبايل
AFD2: عدد اعضاء الهيئة التعليمية حسب سنوات العمر | AHO2: الأبــــنــــيــــــة المـــــــــدرســـــــية | AKJ2: التجهيزات والاثاث :- | AKP2: الحاسبات :- | AKV2: هل توجد مكتبة | ALG2: عدد الكتب والمجلات
A3: التعليم الابتدائي 2025/2026 | Y3: 5 سنوات | AA3: 6 سنوات | AC3: 7 سنوات | AE3: 8 سنوات | AG3: 9 سنوات | AI3: 10 سنوات | AK3: المجموع | KI3: داخل القوة العمل | KK3: خارج القوة العمل | LB3: المجموع | LE3: التربية الاسلامية | MB3: اللغة العربية | MY3: اللغة الانكليزية | NV3: اللغة الكردية | OS3: الرياضيات | PP3: العلوم ( علوم الحياة ) | QM3: الكيمياء | RJ3: الفيزياء | SG3: اجتماعيات | TD3: التاريخ | UA3: الجغرافية | UX3: اقتصاد منزلي | VU3: تربية خاصة | WR3: تربية وعلم النفس | XO3: التربية الفنية | YL3: التربية الرياضية | ZI3: الحاسوب | AAF3: اللغة التركمانية | ABC3: اللغة السريانية | ABZ3: عــــــــــــــام | ACW3: اخــــــــــــــــرى | ADT3: المجموع الكلي | AGK3: الارشاد التربوي | AGM3: التغذية المدرسية | AGO3: خدمة الانترنت | AGQ3: الحاسوب | AGS3: اللغات الاجنبية | AGU3: الــــلــــغــات | AHA3: هل المدرسة مشمولة بالتربية الخاصة | AHC3: عدد التلامذة | AHF3: عدد الشعب | AHJ3: عدد المعلمين | AHM3: هل المدرسة مشمولة بالفنون الصناعية | AHO3: عدد الابنية المدرسية حسب :- | AIQ3: هل البناية مزودة بخدمة المجاري | AIS3: نوع الخدمة | AIU3: هل ترتبط البناية بشبكة الماء الصالح للشرب | AIW3: مصدر الماء | AJB3: هل هناك سياج حول البناية | AJD3: نوع السياج | AJG3: حالة السياج | AJJ3: هل توجد حديقة مدرسية | AJL3: هل توجد قاعة انشطة مستقلة | AJN3: هل توجد ساحة رياضية | AJP3: نوع الساحة الرياضية | AJU3: هل تتوفر في البناية مرافق صحية | AKJ3: عدد الرحلات المزدوجة (ذات المقعدين) الصالحة | AKL3: عدد الرحلات (ذات المقعد الواحد) الصالحة | AKN3: عدد لوحات الكتابة (السبورات) الصالحة | AKP3: عدد الحاسبات الالكترونية (كومبيوتر) | AKR3: عدد الطابعات | AKT3: عدد الماسحات الضوئية (سكنرات) | AKX3: المسؤول عن المكتبة | ALC3: نوعية المكتبة
AN4: 5 سنوات | AP4: 6 سنوات | AR4: 7 سنوات | AT4: 8 سنوات | AV4: 9 سنوات | AX4: 10 سنوات | AZ4: المجموع | BC4: 7 سنوات | BE4: 8 سنوات | BG4: 9 سنوات | BI4: 10 سنوات | BK4: 11 سنة | BM4: المجموع | BP4: 8 سنوات | BR4: 9 سنوات | BT4: 10 سنوات | BV4: 11 سنة | BX4: 12 سنة | BZ4: المجموع | CC4: 9 سنوات | CE4: 10 سنوات | CG4: 11 سنة | CI4: 12 سنة | CK4: 13 سنة | CM4: المجموع | CP4: 10 سنوات | CR4: 11 سنة | CT4: 12 سنة | CV4: 13سنة | CX4: 14 سنة | CZ4: المجموع | DC4: 11 سنة | DE4: 12 سنة | DG4: 13 سنة | DI4: 14 سنة | DK4: 15 سنة | DM4: المجموع | DP4: 5 سنة | DR4: 6 سنة | DT4: 7سنة | DV4: 8سنة | DX4: 9سنة | DZ4: 10سنة | EB4: 11سنة | ED4: 12سنة | EF4: 13سنة | EH4: 14سنة | EJ4: 15سنة | EL4: المجموع الكلي | EO4: الاول الابتدائي | ER4: الثاني الابتدائي | EU4: الثالث الابتدائي | EX4: الرابع الابتدائي | FA4: الخامس الابتدائي | FD4: السادس ابتدائي | FG4: المجموع | FK4: الاول الابتدائي | FM4: الثاني الابتدائي | FO4: الثالث الابتدائي | FQ4: الرابع الابتدائي | FS4: الخامس الابتدائي | FU4: السادس الابتدائي | FW4: المجموع | FZ4: الاول الابتدائي | GB4: الثاني الابتدائي | GD4: الثالث الابتدائي | GF4: الرابع الابتدائي | GH4: الخامس الابتدائي | GJ4: السادس الابتدائي | GL4: المجموع | GO4: الاول الابتدائي | GQ4: الثاني الابتدائي | GS4: الثالث الابتدائي | GU4: الرابع الابتدائي | GW4: الخامس الابتدائي | GY4: السادس الابتدائي | HA4: المجموع | HD4: الاول الابتدائي | HF4: الثاني الابتدائي | HH4: الثالث الابتدائي | HJ4: الرابع الابتدائي | HL4: الخامس الابتدائي | HN4: السادس الابتدائي | HP4: المجموع | HS4: الاول الابتدائي | HU4: الثاني الابتدائي | HW4: الثالث الابتدائي | HY4: الرابع الابتدائي | IA4: الخامس الابتدائي | IC4: السادس الابتدائي | IE4: المجموع | IH4: الاول الابتدائي | IJ4: الثاني الابتدائي | IL4: الثالث الابتدائي | IN4: الرابع الابتدائي | IP4: الخامس الابتدائي | IR4: السادس الابتدائي | IT4: المجموع | IW4: مدير | IY4: معاون | JA4: معلم | JC4: مرشد تربوي | JE4: المجموع | JH4: موظف ادارة | JJ4: محاسب | JL4: كاتب | JN4: امين مكتبة | JP4: موظف خدمات | JR4: حرفي | JT4: فلاح | JU4: حارس | JV4: سائق | JW4: المجموع | JZ4: عراقية | KB4: عربية | KD4: اجنبية | KF4: المجموع | KK4: بعثة او زمالة دراسية | KM4: اجازة دراسية | KO4: اجازة مصاحبة | KQ4: اجازة بدون راتب | KS4: اجازة مرضية طويلة | KU4: اجازة الامومة | KV4: منسب الى جهة اخرى | KX4: 5-4سنوات | KZ4: المجموع | LE4: اعدادية ومهنية ودور المعلمات (دورات تربوية) | LG4: دبلوم تعليمي لمعهد المعلمين والمعاهد المركزية | LI4: دبلوم فنون جميلة | LK4: دبلوم عام | LM4: بكلوريوس تعليمية | LO4: بكلوريوس عام | LQ4: دبلوم عالي | LS4: ماجستير | LU4: دكتوراه | LW4: اخرى | LY4: المجموع | MB4: اعدادية ومهنية ودور المعلمات | MD4: دبلوم تعليمي لمعهد المعلمين والمعاهد المركزية | MF4: دبلوم فنون جميلة | MH4: دبلوم عام | MJ4: بكلوريوس تعليمية | ML4: بكالوريوس عام | MN4: دبلوم عالي | MP4: ماجستير | MR4: دكتوراه | MT4: اخرى | MV4: المجموع | MY4: اعدادية ومهنية ودور المعلمات | NA4: دبلوم تعليمي لمعهد المعلمين والمعاهد المركزية | NC4: دبلوم فنون جميلة | NE4: دبلوم عام | NG4: بكلوريوس تعليمية | NI4: بكالوريوس عام | NK4: دبلوم عالي | NM4: ماجستير | NO4: دكتوراه | NQ4: اخرى | NS4: المجموع | NV4: اعدادية ومهنية ودور المعلمات | NX4: دبلوم تعليمي لمعهد المعلمين والمعاهد المركزية | NZ4: دبلوم فنون جميلة | OB4: دبلوم عام | OD4: بكلوريوس تعليمية | OF4: بكالوريوس عام | OH4: دبلوم عالي | OJ4: ماجستير | OL4: دكتوراه | ON4: اخرى | OP4: المجموع | OS4: اعدادية ومهنية ودور المعلمات | OU4: دبلوم تعليمي لمعهد المعلمين والمعاهد المركزية | OW4: دبلوم فنون جميلة | OY4: دبلوم عام | PA4: بكلوريوس تعليمية | PC4: بكالوريوس عام | PE4: دبلوم عالي | PG4: ماجستير | PI4: دكتوراه | PK4: اخرى | PM4: المجموع | PP4: اعدادية ومهنية ودور المعلمات | PR4: دبلوم تعليمي لمعهد المعلمين والمعاهد المركزية | PT4: دبلوم فنون جميلة | PV4: دبلوم عام | PX4: بكلوريوس تعليمية | PZ4: بكالوريوس عام | QB4: دبلوم عالي | QD4: ماجستير | QF4: دكتوراه | QH4: اخرى | QJ4: المجموع | QM4: اعدادية ومهنية ودور المعلمات | QO4: دبلوم تعليمي لمعهد المعلمين والمعاهد المركزية | QQ4: دبلوم فنون جميلة | QS4: دبلوم عام | QU4: بكلوريوس تعليمية | QW4: بكالوريوس عام | QY4: دبلوم عالي | RA4: ماجستير | RC4: دكتوراه | RE4: اخرى | RG4: المجموع | RJ4: اعدادية ومهنية ودور المعلمات | RL4: دبلوم تعليمي لمعهد المعلمين والمعاهد المركزية | RN4: دبلوم فنون جميلة | RP4: دبلوم عام | RR4: بكلوريوس تعليمية | RT4: بكالوريوس عام | RV4: دبلوم عالي | RX4: ماجستير | RZ4: دكتوراه | SB4: اخرى | SD4: المجموع | SG4: اعدادية ومهنية ودور المعلمات | SI4: دبلوم تعليمي لمعهد المعلمين والمعاهد المركزية | SK4: دبلوم فنون جميلة | SM4: دبلوم عام | SO4: بكلوريوس تعليمية | SQ4: بكالوريوس عام | SS4: دبلوم عالي | SU4: ماجستير | SW4: دكتوراه | SY4: اخرى | TA4: المجموع | TD4: اعدادية ومهنية ودور المعلمات | TF4: دبلوم تعليمي لمعهد المعلمين والمعاهد المركزية | TH4: دبلوم فنون جميلة | TJ4: دبلوم عام | TL4: بكلوريوس تعليمية | TN4: بكالوريوس عام | TP4: دبلوم عالي | TR4: ماجستير | TT4: دكتوراه | TV4: اخرى | TX4: المجموع | UA4: اعدادية ومهنية ودور المعلمات | UC4: دبلوم تعليمي لمعهد المعلمين والمعاهد المركزية | UE4: دبلوم فنون جميلة | UG4: دبلوم عام | UI4: بكلوريوس تعليمية | UK4: بكالوريوس عام | UM4: دبلوم عالي | UO4: ماجستير | UQ4: دكتوراه | US4: اخرى | UU4: المجموع | UX4: اعدادية ومهنية ودور المعلمات | UZ4: دبلوم تعليمي لمعهد المعلمين والمعاهد المركزية | VB4: دبلوم فنون جميلة | VD4: دبلوم عام | VF4: بكلوريوس تعليمية | VH4: بكالوريوس عام | VJ4: دبلوم عالي | VL4: ماجستير | VN4: دكتوراه | VP4: اخرى | VR4: المجموع | VU4: اعدادية ومهنية ودور المعلمات | VW4: دبلوم تعليمي لمعهد المعلمين والمعاهد المركزية | VY4: دبلوم فنون جميلة | WA4: دبلوم عام | WC4: بكلوريوس تعليمية | WE4: بكالوريوس عام | WG4: دبلوم عالي | WI4: ماجستير | WK4: دكتوراه | WM4: اخرى | WO4: المجموع | WR4: اعدادية ومهنية ودور المعلمات | WT4: دبلوم تعليمي لمعهد المعلمين والمعاهد المركزية | WV4: دبلوم فنون جميلة | WX4: دبلوم عام | WZ4: بكلوريوس تعليمية | XB4: بكالوريوس عام | XD4: دبلوم عالي | XF4: ماجستير | XH4: دكتوراه | XJ4: اخرى | XL4: المجموع | XO4: اعدادية ومهنية ودور المعلمات | XQ4: دبلوم تعليمي لمعهد المعلمين والمعاهد المركزية | XS4: دبلوم فنون جميلة | XU4: دبلوم عام | XW4: بكلوريوس تعليمية | XY4: بكالوريوس عام | YA4: دبلوم عالي | YC4: ماجستير | YE4: دكتوراه | YG4: اخرى | YI4: المجموع | YL4: اعدادية ومهنية ودور المعلمات | YN4: دبلوم تعليمي لمعهد المعلمين والمعاهد المركزية | YP4: دبلوم فنون جميلة | YR4: دبلوم عام | YT4: بكلوريوس تعليمية | YV4: بكالوريوس عام | YX4: دبلوم عالي | YZ4: ماجستير | ZB4: دكتوراه | ZD4: اخرى | ZF4: المجموع | ZI4: اعدادية ومهنية ودور المعلمات | ZK4: دبلوم تعليمي لمعهد المعلمين والمعاهد المركزية | ZM4: دبلوم فنون جميلة | ZO4: دبلوم عام | ZQ4: بكلوريوس تعليمية | ZS4: بكالوريوس عام | ZU4: دبلوم عالي | ZW4: ماجستير | ZY4: دكتوراه | AAA4: اخرى | AAC4: المجموع | AAF4: اعدادية ومهنية ودور المعلمات | AAH4: دبلوم تعليمي لمعهد المعلمين والمعاهد المركزية | AAJ4: دبلوم فنون جميلة | AAL4: دبلوم عام | AAN4: بكلوريوس تعليمية | AAP4: بكالوريوس عام | AAR4: دبلوم عالي | AAT4: ماجستير | AAV4: دكتوراه | AAX4: اخرى | AAZ4: المجموع | ABC4: اعدادية ومهنية ودور المعلمات | ABE4: دبلوم تعليمي لمعهد المعلمين والمعاهد المركزية | ABG4: دبلوم فنون جميلة | ABI4: دبلوم عام | ABK4: بكلوريوس تعليمية | ABM4: بكالوريوس عام | ABO4: دبلوم عالي | ABQ4: ماجستير | ABS4: دكتوراه | ABU4: اخرى | ABW4: المجموع | ABZ4: اعدادية ومهنية ودور المعلمات | ACB4: دبلوم تعليمي لمعهد المعلمين والمعاهد المركزية | ACD4: دبلوم فنون جميلة | ACF4: دبلوم عام | ACH4: بكلوريوس تعليمية | ACJ4: بكالوريوس عام | ACL4: دبلوم عالي | ACN4: ماجستير | ACP4: دكتوراه | ACR4: اخرى | ACT4: المجموع | ACW4: اعدادية ومهنية ودور المعلمات | ACY4: دبلوم تعليمي لمعهد المعلمين والمعاهد المركزية | ADA4: دبلوم فنون جميلة | ADC4: دبلوم عام | ADE4: بكلوريوس تعليمية | ADG4: بكالوريوس عام | ADI4: دبلوم عالي | ADK4: ماجستير | ADM4: دكتوراه | ADO4: اخرى | ADQ4: المجموع | ADT4: اعدادية ومهنية ودور المعلمات | ADV4: دبلوم تعليمي لمعهد المعلمين والمعاهد المركزية | ADX4: دبلوم فنون جميلة | ADZ4: دبلوم عام | AEB4: بكلوريوس تعليمية | AED4: بكالوريوس عام | AEF4: دبلوم عالي | AEH4: ماجستير | AEJ4: دكتوراه | AEL4: اخرى | AEN4: المجموع | AEQ4: خمس سنوات ـ فأقل | AES4: 6ــــ10 | AEU4: 11ــــ15 | AEW4: 11ــــ16 | AEY4: اكثرمن 16 | AFA4: المجموع | AFD4: اقل من 30 | AFF4: 30ـ 39 | AFH4: 40ــ49 | AFJ4: 50ــ59 | AFL4: 60 فأكثر ــ | AFN4: المجموع | AFQ4: اعزب | AFS4: متزوج | AFU4: ارمل | AFW4: مطلق | AFY4: المجموع | AGE4: عدد المعلمين | AGU4: فرنسي | AGV4: روسي | AGW4: اسباني | AGX4: كردي | AGY4: تركماني | AGZ4: سرياني | AHO4: نوع البناء | AHQ4: البناية | AHT4: هل توجد مساحة للتوسع | AHV4: عدد الطوابق | AHY4: هل المدرسة بحاجة الى صفوف اضافية | AIA4: عدد الصفوف التي تحتاجها المدرسة | AIB4: عدد الصفوف الكلي | AIC4: عدد الغرف الاخرى | AID4: المجموع | AIE4: حجم المدرسة | AIJ4: مادة البناء | AKA4: عدد المدارس التي تشغلها | AKD4: العائدية | AKG4: الحالة العمرانية | ALJ4: مختبر العلوم يخص المرحلة الابتدائية
A5: القضاء | B5: الناحية | C5: ت | D5: الرقم الاحصائي | E5: اسم المدرسة | F5: بنون | G5: بنات | H5: مختلط | I5: حضر | J5: ريف | K5: صباحا | L5: ظهرا | M5: صباحا وظهرا | N5: مساءا | O5: اصلية | P5: ضيف | Q5: غير مزدوجة | R5: مع نفسها | S5: مع اخرى | T5: مع نفسها ومع اخرى | U5: مدارس فتح جديد | V5: صفوف تربية خاصة | W5: صفوف يافعين | X5: فنون صناعية | Y5: بنون | Z5: بنات | AA5: بنون | AB5: بنات | AC5: بنون | AD5: بنات | AE5: بنون | AF5: بنات | AG5: بنون | AH5: بنات | AI5: بنون | AJ5: بنات | AK5: بنون | AL5: بنات | AM5: المجموع | AN5: بنون | AO5: بنات | AP5: بنون | AQ5: بنات | AR5: بنون | AS5: بنات | AT5: بنون | AU5: بنات | AV5: بنون | AW5: بنات | AX5: بنون | AY5: بنات | AZ5: بنون | BA5: بنات | BB5: المجموع | BC5: بنون | BD5: بنات | BE5: بنون | BF5: بنات | BG5: بنون | BH5: بنات | BI5: بنون | BJ5: بنات | BK5: بنون | BL5: بنات | BM5: بنون | BN5: بنات | BO5: المجموع | BP5: بنون | BQ5: بنات | BR5: بنون | BS5: بنات | BT5: بنون | BU5: بنات | BV5: بنون | BW5: بنات | BX5: بنون | BY5: بنات | BZ5: بنون | CA5: بنات | CB5: المجموع | CC5: بنون | CD5: بنات | CE5: بنون | CF5: بنات | CG5: بنون | CH5: بنات | CI5: بنون | CJ5: بنات | CK5: بنون | CL5: بنات | CM5: بنون | CN5: بنات | CO5: المجموع | CP5: بنون | CQ5: بنات | CR5: بنون | CS5: بنات | CT5: بنون | CU5: بنات | CV5: بنون | CW5: بنات | CX5: بنون | CY5: بنات | CZ5: بنون | DA5: بنات | DB5: المجموع | DC5: بنون | DD5: بنات | DE5: بنون | DF5: بنات | DG5: بنون | DH5: بنات | DI5: بنون | DJ5: بنات | DK5: بنون | DL5: بنات | DM5: بنون | DN5: بنات | DO5: المجموع | DP5: بنون | DQ5: بنات | DR5: بنون | DS5: بنات | DT5: بنون | DU5: بنات | DV5: بنون | DW5: بنات | DX5: بنون | DY5: بنات | DZ5: بنون | EA5: بنات | EB5: بنون | EC5: بنات | EE5: بنات | EF5: بنون | EG5: بنات | EH5: بنون | EI5: بنات | EJ5: بنون | EK5: بنات | EL5: بنون | EM5: بنات | EN5: المجموع | EO5: بنون | EP5: بنات | EQ5: مختلط | ER5: بنون | ES5: بنات | ET5: مختلط | EU5: بنون | EV5: بنات | EW5: مختلط | EX5: بنون | EY5: بنات | EZ5: مختلط | FA5: بنون | FB5: بنات | FC5: مختلط | FD5: بنون | FE5: بنات | FF5: مختلط | FG5: بنون | FH5: بنات | FI5: مختلط | FJ5: المجموع | FK5: بنون | FL5: بنات | FM5: بنون | FN5: بنات | FO5: بنون | FP5: بنات | FQ5: بنون | FR5: بنات | FS5: بنون | FT5: بنات | FU5: بنون | FV5: بنات | FW5: بنون | FX5: بنات | FY5: المجموع | FZ5: بنون | GA5: بنات | GB5: بنون | GC5: بنات | GD5: بنون | GE5: بنات | GF5: بنون | GG5: بنات | GH5: بنون | GI5: بنات | GJ5: بنون | GK5: بنات | GL5: بنون | GM5: بنات | GN5: المجموع | GO5: بنون | GP5: بنات | GQ5: بنون | GR5: بنات | GS5: بنون | GT5: بنات | GU5: بنون | GV5: بنات | GW5: بنون | GX5: بنات | GY5: بنون | GZ5: بنات | HA5: بنون | HB5: بنات | HC5: المجموع | HD5: بنون | HE5: بنات | HF5: بنون | HG5: بنات | HH5: بنون | HI5: بنات | HJ5: بنون | HK5: بنات | HL5: بنون | HM5: بنات | HN5: بنون | HO5: بنات | HP5: بنون | HQ5: بنات | HR5: المجموع | HS5: بنون | HT5: بنات | HU5: بنون | HV5: بنات | HW5: بنون | HX5: بنات | HY5: بنون | HZ5: بنات | IA5: بنون | IB5: بنات | IC5: بنون | ID5: بنات | IE5: بنون | IF5: بنات | IG5: المجموع | IH5: بنون | II5: بنات | IJ5: بنون | IK5: بنات | IL5: بنون | IM5: بنات | IN5: بنون | IO5: بنات | IP5: بنون | IQ5: بنات | IR5: بنون | IS5: بنات | IT5: بنون | IU5: بنات | IV5: المجموع | IW5: ذكور | IX5: اناث | IY5: ذكور | IZ5: اناث | JA5: ذكور | JB5: اناث | JC5: ذكور | JD5: اناث | JE5: ذكور | JF5: اناث | JG5: المجموع | JH5: ذكور | JI5: اناث | JJ5: ذكور | JK5: اناث | JL5: ذكور | JM5: اناث | JN5: ذكور | JO5: اناث | JP5: ذكور | JQ5: اناث | JR5: ذكور | JS5: اناث | JT5: ذكور | JU5: ذكور | JV5: ذكور | JW5: ذكور | JX5: اناث | JY5: المجموع | JZ5: ذكور | KA5: اناث | KB5: ذكور | KC5: اناث | KD5: ذكور | KE5: اناث | KF5: ذكور | KG5: اناث | KH5: المجموع | KI5: ذكور | KJ5: اناث | KK5: ذكور | KL5: اناث | KM5: ذكور | KN5: اناث | KO5: ذكور | KP5: اناث | KQ5: ذكور | KR5: اناث | KS5: ذكور | KT5: اناث | KU5: اناث | KV5: ذكور | KW5: اناث | KX5: ذكور | KY5: اناث | KZ5: ذكور | LA5: اناث | LB5: ذكور | LC5: اناث | LD5: المجموع | LE5: ذكور | LF5: اناث | LG5: ذكور | LH5: اناث | LI5: ذكور | LJ5: اناث | LK5: ذكور | LL5: اناث | LM5: ذكور | LN5: اناث | LO5: ذكور | LP5: اناث | LQ5: ذكور | LR5: اناث | LS5: ذكور | LT5: اناث | LU5: ذكور | LV5: اناث | LW5: ذكور | LX5: اناث | LY5: ذكور | LZ5: اناث | MA5: المجموع | MB5: ذكور | MC5: اناث | MD5: ذكور | ME5: اناث | MF5: ذكور | MG5: اناث | MH5: ذكور | MI5: اناث | MJ5: ذكور | MK5: اناث | ML5: ذكور | MM5: اناث | MN5: ذكور | MO5: اناث | MP5: ذكور | MQ5: اناث | MR5: ذكور | MS5: اناث | MT5: ذكور | MU5: اناث | MV5: ذكور | MW5: اناث | MX5: المجموع | MY5: ذكور | MZ5: اناث | NA5: ذكور | NB5: اناث | NC5: ذكور | ND5: اناث | NE5: ذكور | NF5: اناث | NG5: ذكور | NH5: اناث | NI5: ذكور | NJ5: اناث | NK5: ذكور | NL5: اناث | NM5: ذكور | NN5: اناث | NO5: ذكور | NP5: اناث | NQ5: ذكور | NR5: اناث | NS5: ذكور | NT5: اناث | NU5: المجموع | NV5: ذكور | NW5: اناث | NX5: ذكور | NY5: اناث | NZ5: ذكور | OA5: اناث | OB5: ذكور | OC5: اناث | OD5: ذكور | OE5: اناث | OF5: ذكور | OG5: اناث | OH5: ذكور | OI5: اناث | OJ5: ذكور | OK5: اناث | OL5: ذكور | OM5: اناث | ON5: ذكور | OO5: اناث | OP5: ذكور | OQ5: اناث | OR5: المجموع | OS5: ذكور | OT5: اناث | OU5: ذكور | OV5: اناث | OW5: ذكور | OX5: اناث | OY5: ذكور | OZ5: اناث | PA5: ذكور | PB5: اناث | PC5: ذكور | PD5: اناث | PE5: ذكور | PF5: اناث | PG5: ذكور | PH5: اناث | PI5: ذكور | PJ5: اناث | PK5: ذكور | PL5: اناث | PM5: ذكور | PN5: اناث | PO5: المجموع | PP5: ذكور | PQ5: اناث | PR5: ذكور | PS5: اناث | PT5: ذكور | PU5: اناث | PV5: ذكور | PW5: اناث | PX5: ذكور | PY5: اناث | PZ5: ذكور | QA5: اناث | QB5: ذكور | QC5: اناث | QD5: ذكور | QE5: اناث | QF5: ذكور | QG5: اناث | QH5: ذكور | QI5: اناث | QJ5: ذكور | QK5: اناث | QL5: المجموع | QM5: ذكور | QN5: اناث | QO5: ذكور | QP5: اناث | QQ5: ذكور | QR5: اناث | QS5: ذكور | QT5: اناث | QU5: ذكور | QV5: اناث | QW5: ذكور | QX5: اناث | QY5: ذكور | QZ5: اناث | RA5: ذكور | RB5: اناث | RC5: ذكور | RD5: اناث | RE5: ذكور | RF5: اناث | RG5: ذكور | RH5: اناث | RI5: المجموع | RJ5: ذكور | RK5: اناث | RL5: ذكور | RM5: اناث | RN5: ذكور | RO5: اناث | RP5: ذكور | RQ5: اناث | RR5: ذكور | RS5: اناث | RT5: ذكور | RU5: اناث | RV5: ذكور | RW5: اناث | RX5: ذكور | RY5: اناث | RZ5: ذكور | SA5: اناث | SB5: ذكور | SC5: اناث | SD5: ذكور | SE5: اناث | SF5: المجموع | SG5: ذكور | SH5: اناث | SI5: ذكور | SJ5: اناث | SK5: ذكور | SL5: اناث | SM5: ذكور | SN5: اناث | SO5: ذكور | SP5: اناث | SQ5: ذكور | SR5: اناث | SS5: ذكور | ST5: اناث | SU5: ذكور | SV5: اناث | SW5: ذكور | SX5: اناث | SY5: ذكور | SZ5: اناث | TA5: ذكور | TB5: اناث | TC5: المجموع | TD5: ذكور | TE5: اناث | TF5: ذكور | TG5: اناث | TH5: ذكور | TI5: اناث | TJ5: ذكور | TK5: اناث | TL5: ذكور | TM5: اناث | TN5: ذكور | TO5: اناث | TP5: ذكور | TQ5: اناث | TR5: ذكور | TS5: اناث | TT5: ذكور | TU5: اناث | TV5: ذكور | TW5: اناث | TX5: ذكور | TY5: اناث | TZ5: المجموع | UA5: ذكور | UB5: اناث | UC5: ذكور | UD5: اناث | UE5: ذكور | UF5: اناث | UG5: ذكور | UH5: اناث | UI5: ذكور | UJ5: اناث | UK5: ذكور | UL5: اناث | UM5: ذكور | UN5: اناث | UO5: ذكور | UP5: اناث | UQ5: ذكور | UR5: اناث | US5: ذكور | UT5: اناث | UU5: ذكور | UV5: اناث | UW5: المجموع | UX5: ذكور | UY5: اناث | UZ5: ذكور | VA5: اناث | VB5: ذكور | VC5: اناث | VD5: ذكور | VE5: اناث | VF5: ذكور | VG5: اناث | VH5: ذكور | VI5: اناث | VJ5: ذكور | VK5: اناث | VL5: ذكور | VM5: اناث | VN5: ذكور | VO5: اناث | VP5: ذكور | VQ5: اناث | VR5: ذكور | VS5: اناث | VT5: المجموع | VU5: ذكور | VV5: اناث | VW5: ذكور | VX5: اناث | VY5: ذكور | VZ5: اناث | WA5: ذكور | WB5: اناث | WC5: ذكور | WD5: اناث | WE5: ذكور | WF5: اناث | WG5: ذكور | WH5: اناث | WI5: ذكور | WJ5: اناث | WK5: ذكور | WL5: اناث | WM5: ذكور | WN5: اناث | WO5: ذكور | WP5: اناث | WQ5: المجموع | WR5: ذكور | WS5: اناث | WT5: ذكور | WU5: اناث | WV5: ذكور | WW5: اناث | WX5: ذكور | WY5: اناث | WZ5: ذكور | XA5: اناث | XB5: ذكور | XC5: اناث | XD5: ذكور | XE5: اناث | XF5: ذكور | XG5: اناث | XH5: ذكور | XI5: اناث | XJ5: ذكور | XK5: اناث | XL5: ذكور | XM5: اناث | XN5: المجموع | XO5: ذكور | XP5: اناث | XQ5: ذكور | XR5: اناث | XS5: ذكور | XT5: اناث | XU5: ذكور | XV5: اناث | XW5: ذكور | XX5: اناث | XY5: ذكور | XZ5: اناث | YA5: ذكور | YB5: اناث | YC5: ذكور | YD5: اناث | YE5: ذكور | YF5: اناث | YG5: ذكور | YH5: اناث | YI5: ذكور | YJ5: اناث | YK5: المجموع | YL5: ذكور | YM5: اناث | YN5: ذكور | YO5: اناث | YP5: ذكور | YQ5: اناث | YR5: ذكور | YS5: اناث | YT5: ذكور | YU5: اناث | YV5: ذكور | YW5: اناث | YX5: ذكور | YY5: اناث | YZ5: ذكور | ZA5: اناث | ZB5: ذكور | ZC5: اناث | ZD5: ذكور | ZE5: اناث | ZF5: ذكور | ZG5: اناث | ZH5: المجموع | ZI5: ذكور | ZJ5: اناث | ZK5: ذكور | ZL5: اناث | ZM5: ذكور | ZN5: اناث | ZO5: ذكور | ZP5: اناث | ZQ5: ذكور | ZR5: اناث | ZS5: ذكور | ZT5: اناث | ZU5: ذكور | ZV5: اناث | ZW5: ذكور | ZX5: اناث | ZY5: ذكور | ZZ5: اناث | AAA5: ذكور | AAB5: اناث | AAC5: ذكور | AAD5: اناث | AAE5: المجموع | AAF5: ذكور | AAG5: اناث | AAH5: ذكور | AAI5: اناث | AAJ5: ذكور | AAK5: اناث | AAL5: ذكور | AAM5: اناث | AAN5: ذكور | AAO5: اناث | AAP5: ذكور | AAQ5: اناث | AAR5: ذكور | AAS5: اناث | AAT5: ذكور | AAU5: اناث | AAV5: ذكور | AAW5: اناث | AAX5: ذكور | AAY5: اناث | AAZ5: ذكور | ABA5: اناث | ABB5: المجموع | ABC5: ذكور | ABD5: اناث | ABE5: ذكور | ABF5: اناث | ABG5: ذكور | ABH5: اناث | ABI5: ذكور | ABJ5: اناث | ABK5: ذكور | ABL5: اناث | ABM5: ذكور | ABN5: اناث | ABO5: ذكور | ABP5: اناث | ABQ5: ذكور | ABR5: اناث | ABS5: ذكور | ABT5: اناث | ABU5: ذكور | ABV5: اناث | ABW5: ذكور | ABX5: اناث | ABY5: المجموع | ABZ5: ذكور | ACA5: اناث | ACB5: ذكور | ACC5: اناث | ACD5: ذكور | ACE5: اناث | ACF5: ذكور | ACG5: اناث | ACH5: ذكور | ACI5: اناث | ACJ5: ذكور | ACK5: اناث | ACL5: ذكور | ACM5: اناث | ACN5: ذكور | ACO5: اناث | ACP5: ذكور | ACQ5: اناث | ACR5: ذكور | ACS5: اناث | ACT5: ذكور | ACU5: اناث | ACV5: المجموع | ACW5: ذكور | ACX5: اناث | ACY5: ذكور | ACZ5: اناث | ADA5: ذكور | ADB5: اناث | ADC5: ذكور | ADD5: اناث | ADE5: ذكور | ADF5: اناث | ADG5: ذكور | ADH5: اناث | ADI5: ذكور | ADJ5: اناث | ADK5: ذكور | ADL5: اناث | ADM5: ذكور | ADN5: اناث | ADO5: ذكور | ADP5: اناث | ADQ5: ذكور | ADR5: اناث | ADS5: المجموع | ADT5: ذكور | ADU5: اناث | ADV5: ذكور | ADW5: اناث | ADX5: ذكور | ADY5: اناث | ADZ5: ذكور | AEA5: اناث | AEB5: ذكور | AEC5: اناث | AED5: ذكور | AEE5: اناث | AEF5: ذكور | AEG5: اناث | AEH5: ذكور | AEI5: اناث | AEJ5: ذكور | AEK5: اناث | AEL5: ذكور | AEM5: اناث | AEN5: ذكور | AEO5: اناث | AEP5: المجموع الكلي | AEQ5: ذكور | AER5: اناث | AES5: ذكور | AET5: اناث | AEU5: ذكور | AEV5: اناث | AEW5: ذكور | AEX5: اناث | AEY5: ذكور | AEZ5: اناث | AFA5: ذكور | AFB5: اناث | AFC5: المجموع الكلي | AFD5: ذكور | AFE5: اناث | AFF5: ذكور | AFG5: اناث | AFH5: ذكور | AFI5: اناث | AFJ5: ذكور | AFK5: اناث | AFL5: ذكور | AFM5: اناث | AFN5: ذكور | AFO5: اناث | AFP5: المجموع الكلي | AFQ5: ذكور | AFR5: اناث | AFS5: ذكور | AFT5: اناث | AFU5: ذكور | AFV5: اناث | AFW5: ذكور | AFX5: اناث | AFY5: ذكور | AFZ5: اناث | AGA5: المجموع | AGB5: ذكور | AGC5: اناث | AGD5: المجموع | AGE5: ذكور | AGF5: اناث | AGG5: المجموع | AGH5: بنون | AGI5: بنات | AGJ5: المجموع | AGK5: نعم | AGL5: كلا | AGM5: نعم | AGN5: كلا | AGO5: نعم | AGP5: كلا | AGQ5: نعم | AGR5: كلا | AGS5: نعم | AGT5: كلا | AHA5: نعم | AHB5: كلا | AHC5: بنون | AHD5: بنات | AHE5: مجموع | AHF5: بنون | AHG5: بنات | AHH5: مختلط | AHI5: مجموع | AHJ5: ذكور | AHK5: اناث | AHL5: مجموع | AHM5: نعم | AHN5: كلا | AHO5: مدرسي | AHP5: غير مدرسي | AHQ5: سنة البناء | AHR5: رقم القطعة | AHS5: رقم المقاطعة | AHT5: نعم | AHU5: كلا | AHV5: طابق واحد | AHW5: طابقين | AHX5: ثلاث طوابق | AHY5: نعم | AHZ5: كلا | AIE5: 6صف | AIF5: 9صف | AIG5: 12صف | AIH5: 18صف | AII5: 24صف | AIJ5: طابوق او حجر او بلوك | AIK5: طين | AIL5: صريفة او خيمة | AIM5: هياكل حديدية | AIN5: بناء جاهز | AIO5: كرفان | AIP5: اخرى | AIQ5: نعم | AIR5: كلا | AIS5: شبكة المجاري | AIT5: خزانات | AIU5: نعم | AIV5: كلا | AIW5: بلدية | AIX5: بئر عميق | AIY5: نهر | AIZ5: صهاريج | AJA5: اخرى | AJB5: نعم | AJC5: كلا | AJD5: بناء | AJE5: اسلاك | AJF5: اخرى | AJG5: جيد | AJH5: متصدع | AJI5: غيرامن | AJJ5: نعم | AJK5: كلا | AJL5: نعم | AJM5: كلا | AJN5: نعم | AJO5: كلا | AJP5: كرة قدم | AJQ5: كرة سلة | AJR5: كرة طائرة | AJS5: ساحة رياضية | AJT5: اخرى | AJU5: نعم | AJV5: كلا | AJW5: صالحة | AJX5: غير صالحة | AJY5: كافية | AJZ5: غير كافية | AKA5: مدرسة واحدة | AKB5: مدرستان | AKC5: ثلاث مدارس | AKD5: حكومية تابعة لوزارة التربية | AKE5: حكومية تابعة لجهات اخرى | AKF5: مستأجرة | AKG5: صالحة | AKH5: بحاجة الى ترميم | AKI5: غير صالحة | AKJ5: صالحة | AKK5: غيرصالحة | AKL5: صالحة | AKM5: غيرصالحة | AKN5: صالحة | AKO5: غيرصالحة | AKP5: صالحة | AKQ5: عاطلة | AKR5: صالحة | AKS5: عاطلة | AKT5: صالحة | AKU5: عاطلة | AKV5: نعم | AKW5: كلا | AKX5: مدير | AKY5: معاون | AKZ5: معلم او مدرس | ALA5: امين المكتبة | ALB5: موظف ادارة | ALC5: قاعة مستقلة | ALD5: غرفة | ALE5: خزانة | ALF5: رفوف عارضة | ALG5: عدد الكتب | ALH5: عدد المجلات والقصص | ALI5: المجموع | ALJ5: نعم | ALK5: كلا
A6: النجف | B6: المركز | C6: 1 | D6: 1400902 | E6: سيدة النساء الابتدائية للبنات | G6: 1 | I6: 1 | L6: 1 | P6: 1 | S6: 1 | Z6: 3 | AB6: 49 | AD6: 3 | AK6: =AI6+AG6+AE6+AC6+AA6+Y6 -> 0 | AL6: =AJ6+AH6+AF6+AD6+AB6+Z6 -> 55 | AM6: =AL6+AK6 -> 55 | AN6: =Y6 -> 0 | AO6: =Z6 -> 3 | AP6: =AA6 -> 0 | AQ6: =AB6 -> 49 | AS6: 3 | AZ6: =AX6+AV6+AT6+AR6+AP6+AN6 -> 0 | BA6: =AY6+AW6+AU6+AS6+AQ6+AO6 -> 55 | BB6: =BA6+AZ6 -> 55 | BD6: 80 | BF6: 4 | BM6: =BK6+BI6+BG6+BE6+BC6 -> 0 | BN6: =BL6+BJ6+BH6+BF6+BD6 -> 84 | BO6: =BN6+BM6 -> 84 | BQ6: 65 | BS6: 6 | BZ6: =BX6+BV6+BT6+BR6+BP6 -> 0 | CA6: =BY6+BW6+BU6+BS6+BQ6 -> 71 | CB6: =CA6+BZ6 -> 71 | CD6: 62 | CF6: 6 | CM6: =CK6+CI6+CG6+CE6+CC6 -> 0 | CN6: =CL6+CJ6+CH6+CF6+CD6 -> 68 | CO6: =CN6+CM6 -> 68 | CQ6: 65 | CS6: 6 | CZ6: =CX6+CV6+CT6+CR6+CP6 -> 0 | DA6: =CY6+CW6+CU6+CS6+CQ6 -> 71 | DB6: =DA6+CZ6 -> 71 | DD6: 57 | DF6: 3 | DH6: 1 | DM6: =DK6+DI6+DG6+DE6+DC6 -> 0 | DN6: =DL6+DJ6+DH6+DF6+DD6 -> 61 | DO6: =DN6+DM6 -> 61 | DP6: =AN6 -> 0 | DQ6: =AO6 -> 3 | DR6: =AP6 -> 0 | DS6: =AQ6 -> 49 | DT6: =AR6+BC6 -> 0 | DU6: =AS6+BD6 -> 83 | DV6: =AT6+BE6+BP6 -> 0 | DW6: =AU6+BF6+BQ6 -> 69 | DX6: =AV6+BG6+BR6+CC6 -> 0 | DY6: =AW6+BH6+BS6+CD6 -> 68 | DZ6: =AX6+BI6+BT6+CE6+CP6 -> 0 | EA6: =AY6+BJ6+BU6+CF6+CQ6 -> 71 | EB6: =BK6+BV6+CG6+CR6+DC6 -> 0 | EC6: =BL6+BW6+CH6+CS6+DD6 -> 63 | ED6: =BX6+CI6+CT6+DE6 -> 0 | EE6: =BY6+CJ6+CU6+DF6 -> 3 | EF6: =CK6+CV6+DG6 -> 0 | EG6: =CL6+CW6+DH6 -> 1 | EH6: =CX6+DI6 -> 0 | EI6: =CY6+DJ6 -> 0 | EJ6: =DK6 -> 0 | EK6: =DL6 -> 0 | EL6: =EJ6+EH6+EF6+ED6+EB6+DZ6+DX6+DV6+DT6+DR6+DP6 -> 0 | EM6: =EK6+EI6+EG6+EE6+EC6+EA6+DY6+DW6+DU6+DS6+DQ6 -> 410 | EN6: =EM6+EL6 -> 410 | EP6: 2 | ES6: 2 | EV6: 2 | EY6: 2 | FB6: 2 | FE6: 2 | FG6: =FD6+FA6+EX6+EU6+ER6+EO6 -> 0 | FH6: =FE6+FB6+EY6+EV6+ES6+EP6 -> 12 | FI6: =FF6+FC6+EZ6+EW6+ET6+EQ6 -> 0 | FJ6: =FI6+FH6+FG6 -> 12 | FW6: =FU6+FS6+FQ6+FO6+FM6+FK6 -> 0 | FX6: =FV6+FT6+FR6+FP6+FN6+FL6 -> 0 | FY6: =FX6+FW6 -> 0 | GA6: 81 | GC6: 70 | GE6: 67 | GG6: 70 | GI6: 61 | GK6: 65 | GL6: =GJ6+GH6+GF6+GD6+GB6+FZ6 -> 0 | GM6: =GK6+GI6+GG6+GE6+GC6+GA6 -> 414 | GN6: =GM6+GL6 -> 414 | GP6: 3 | GR6: 1 | GT6: 5 | GX6: 1 | HA6: =GY6+GW6+GU6+GS6+GQ6+GO6 -> 0 | HB6: =GZ6+GX6+GV6+GT6+GR6+GP6 -> 10 | HC6: =HB6+HA6 -> 10 | HP6: =HN6+HL6+HJ6+HH6+HF6+HD6 -> 0 | HQ6: =HO6+HM6+HK6+HI6+HG6+HE6 -> 0 | HR6: =HQ6+HP6 -> 0 | IE6: =IC6+IA6+HY6+HW6+HU6+HS6 -> 0 | IF6: =ID6+IB6+HZ6+HX6+HV6+HT6 -> 0 | IG6: =IF6+IE6 -> 0 | IH6: =HS6+GO6+HD6 -> 0 | II6: =HT6+HE6+GP6 -> 3 | IJ6: =HU6+HF6+GQ6 -> 0 | IK6: =HV6+HG6+GR6 -> 1 | IL6: =HW6+HH6+GS6 -> 0 | IM6: =HX6+HI6+GT6 -> 5 | IN6: =HY6+HJ6+GU6 -> 0 | IO6: =HZ6+HK6+GV6 -> 0 | IP6: =IA6+HL6+GW6 -> 0 | ... IS6: =ID6+HO6+GZ6 -> 0 | IT6: =IR6+IP6+IN6+IL6+IJ6+IH6 -> 0 | IU6: =IS6+IQ6+IO6+IM6+IK6+II6 -> 10 | IV6: =IU6+IT6 -> 10 | IX6: 1 | IZ6: 1 | JB6: 21 | JE6: =JC6+JA6+IY6+IW6 -> 0 | JF6: =JD6+JB6+IZ6+IX6 -> 23 | JG6: =JF6+JE6 -> 23 | JI6: 1 | JQ6: 1 | JW6: =JV6+JU6+JT6+JP6+JN6+JJ6+JH6+JR6+JL6 -> 0 | JX6: =JQ6+JO6+JK6+JI6+JM6+JS6 -> 2 | JY6: =JX6+JW6 -> 2 | KA6: 23 | KF6: =KD6+KB6+JZ6 -> 0 | KG6: =KE6+KC6+KA6 -> 23 | KH6: =KG6+KF6 -> 23 | KJ6: 20 | KN6: 2 | KT6: 1 | KZ6: =KV6+KS6+KQ6+KO6+KM6+KK6 -> 0 | LA6: =KW6+KU6+KT6+KR6+KP6+KN6+KL6 -> 3 | LB6: =KZ6+KI6 -> 0 | LC6: =LA6+KJ6 -> 23 | LD6: =LC6+LB6 -> 23 | LH6: 6 | LN6: 1 | LY6: =LW6+LU6+LS6+LQ6+LO6+LM6+LK6+LI6+LG6+LE6 -> 0 | LZ6: =LX6+LV6+LT6+LR6+LP6+LN6+LL6+LJ6+LH6+LF6 -> 7 | MA6: =LZ6+LY6 -> 7 | ME6: 2 | MK6: 2 | MM6: 1 | MV6: =MT6+MR6+MP6+MN6+ML6+MJ6+MH6+MF6+MD6+MB6 -> 0 | MW6: =MU6+MS6+MQ6+MO6+MM6+MK6+MI6+MG6+ME6+MC6 -> 5 | MX6: =MW6+MV6 -> 5 | NB6: 1 | NH6: 2 | NS6: =NQ6+NO6+NM6+NK6+NI6+NG6+NE6+NC6+NA6+MY6 -> 0 | NT6: =NR6+NP6+NN6+NL6+NJ6+NH6+NF6+ND6+NB6+MZ6 -> 3 | NU6: =NT6+NS6 -> 3 | OP6: =ON6+OL6+OJ6+OH6+OF6+OD6+OB6+NZ6+NX6+NV6 -> 0 | OQ6: =OO6+OM6+OK6+OI6+OG6+OE6+OC6+OA6+NY6+NW6 -> 0 | OR6: =OQ6+OP6 -> 0 | PB6: 6 | PM6: =PK6+PI6+PG6+PE6+PC6+PA6+OY6+OW6+OU6+OS6 -> 0 | PN6: =PL6+PJ6+PH6+PF6+PD6+PB6+OZ6+OX6+OV6+OT6 -> 6 | PO6: =PN6+PM6 -> 6 | PY6: 1 | QJ6: =QH6+QF6+QD6+QB6+PZ6+PX6+PV6+PT6+PR6+PP6 -> 0 | QK6: =QI6+QG6+QE6+QC6+QA6+PY6+PW6+PU6+PS6+PQ6 -> 1 | QL6: =QK6+QJ6 -> 1 | RG6: =RE6+RC6+RA6+QY6+QW6+QU6+QS6+QQ6+QO6+QM6 -> 0 | RH6: =RF6+RD6+RB6+QZ6+QX6+QV6+QT6+QR6+QP6+QN6 -> 0 | RI6: =RH6+RG6 -> 0 | SD6: =SB6+RZ6+RX6+RV6+RT6+RR6+RP6+RN6+RL6+RJ6 -> 0 | SE6: =SC6+SA6+RY6+RW6+RU6+RS6+RQ6+RO6+RM6+RK6 -> 0 | SF6: =SE6+SD6 -> 0 | TA6: =SY6+SW6+SU6+SS6+SQ6+SO6+SM6+SK6+SI6+SG6 -> 0 | TB6: =SZ6+SX6+SV6+ST6+SR6+SP6+SN6+SL6+SJ6+SH6 -> 0 | TC6: =TB6+TA6 -> 0 | TX6: =TV6+TT6+TR6+TP6+TN6+TL6+TJ6+TH6+TF6+TD6 -> 0 | TY6: =TW6+TU6+TS6+TQ6+TO6+TM6+TK6+TI6+TG6+TE6 -> 0 | TZ6: =TY6+TX6 -> 0 | UU6: =US6+UQ6+UO6+UM6+UK6+UI6+UG6+UE6+UC6+UA6 -> 0 | UV6: =UT6+UR6+UP6+UN6+UL6+UJ6+UH6+UF6+UD6+UB6 -> 0 | UW6: =UV6+UU6 -> 0 | VR6: =VP6+VN6+VL6+VJ6+VH6+VF6+VD6+VB6+UZ6+UX6 -> 0 | VS6: =VQ6+VO6+VM6+VK6+VI6+VG6+VE6+VC6+VA6+UY6 -> 0 | VT6: =VS6+VR6 -> 0 | WO6: =WM6+WK6+WI6+WG6+WE6+WC6+WA6+VY6+VW6+VU6 -> 0 | WP6: =WN6+WL6+WJ6+WH6+WF6+WD6+WB6+VZ6+VX6+VV6 -> 0 | WQ6: =WP6+WO6 -> 0 | XL6: =XJ6+XH6+XF6+XD6+XB6+WZ6+WX6+WV6+WT6+WR6 -> 0 | XM6: =XK6+XI6+XG6+XE6+XC6+XA6+WY6+WW6+WU6+WS6 -> 0 | XN6: =XM6+XL6 -> 0 | XX6: 1 | YI6: =YG6+YE6+YC6+YA6+XY6+XW6+XU6+XS6+XQ6+XO6 -> 0 | YJ6: =YH6+YF6+YD6+YB6+XZ6+XX6+XV6+XT6+XR6+XP6 -> 1 | YK6: =YJ6+YI6 -> 1 | ZF6: =ZD6+ZB6+YZ6+YX6+YV6+YT6+YR6+YP6+YN6+YL6 -> 0 | ZG6: =ZE6+ZC6+ZA6+YY6+YW6+YU6+YS6+YQ6+YO6+YM6 -> 0 | ZH6: =ZG6+ZF6 -> 0 | AAC6: =AAA6+ZY6+ZW6+ZU6+ZS6+ZQ6+ZO6+ZM6+ZK6+ZI6 -> 0 | AAD6: =AAB6+ZZ6+ZX6+ZV6+ZT6+ZR6+ZP6+ZN6+ZL6+ZJ6 -> 0 | AAE6: =AAD6+AAC6 -> 0 | AAZ6: =AAX6+AAV6+AAT6+AAR6+AAP6+AAN6+AAL6+AAJ6+AAH6+AAF6 -> 0 | ABA6: =AAY6+AAW6+AAU6+AAS6+AAQ6+AAO6+AAM6+AAK6+AAI6+AAG6 -> 0 | ABB6: =ABA6+AAZ6 -> 0 | ABW6: =ABU6+ABS6+ABQ6+ABO6+ABM6+ABK6+ABI6+ABG6+ABE6+ABC6 -> 0 | ABX6: =ABV6+ABT6+ABR6+ABP6+ABN6+ABL6+ABJ6+ABH6+ABF6+ABD6 -> 0 | ABY6: =ABX6+ABW6 -> 0 | ACT6: =ACR6+ACP6+ACN6+ACL6+ACJ6+ACH6+ACF6+ACD6+ACB6+ABZ6 -> 0 | ACU6: =ACS6+ACQ6+ACO6+ACM6+ACK6+ACI6+ACG6+ACE6+ACC6+ACA6 -> 0 | ACV6: =ACU6+ACT6 -> 0 | ADQ6: =ADO6+ADM6+ADK6+ADI6+ADG6+ADE6+ADC6+ADA6+ACY6+ACW6 -> 0 | ADR6: =ADP6+ADN6+ADL6+ADJ6+ADH6+ADF6+ADD6+ADB6+ACZ6+ACX6 -> 0 | ADS6: =ADR6+ADQ6 -> 0 | ADT6: =ACW6+ABZ6+ABC6+AAF6+ZI6+YL6+XO6+WR6+VU6+UX6+UA6+TD6+SG6+RJ6+QM6+PP6+OS6+NV6+MY6+MB6+LE6 -> 0 | ADU6: =ACX6+ACA6+ABD6+AAG6+ZJ6+YM6+XP6+WS6+VV6+UY6+UB6+TE6+SH6+RK6+QN6+PQ6+OT6+NW6+MZ6+MC6+LF6 -> 0 | ADV6: =ACY6+ACB6+ABE6+AAH6+ZK6+YN6+XQ6+WT6+VW6+UZ6+UC6+TF6+SI6+RL6+QO6+PR6+OU6+NX6+NA6+MD6+LG6 -> 0 | ADW6: =ACZ6+ACC6+ABF6+AAI6+ZL6+YO6+XR6+WU6+VX6+VA6+UD6+TG6+SJ6+RM6+QP6+PS6+OV6+NY6+NB6+ME6+LH6 -> 9 | ADX6: =ADA6+ACD6+ABG6+AAJ6+ZM6+YP6+XS6+WV6+VY6+VB6+UE6+TH6+SK6+RN6+QQ6+PT6+OW6+NZ6+NC6+MF6+LI6 -> 0 | ADY6: =ADB6+ACE6+ABH6+AAK6+ZN6+YQ6+XT6+WW6+VZ6+VC6+UF6+TI6+SL6+RO6+QR6+PU6+OX6+OA6+ND6+MG6+LJ6 -> 0 | ADZ6: =ADC6+ACF6+ABI6+AAL6+ZO6+YR6+XU6+WX6+WA6+VD6+UG6+TJ6+SM6+RP6+QS6+PV6+OY6+OB6+NE6+MH6+LK6 -> 0 | AEA6: =ADD6+ACG6+ABJ6+AAM6+ZP6+YS6+XV6+WY6+WB6+VE6+UH6+TK6+SN6+RQ6+QT6+PW6+OZ6+OC6+NF6+MI6+LL6 -> 0 | ... AEM6: =ADP6+ACS6+ABV6+AAY6+AAB6+ZE6+YH6+XK6+WN6+VQ6+UT6+TW6+SZ6+SC6+RF6+QI6+PL6+OO6+NR6+MU6+LX6 -> 0 | AEN6: =AEL6+AEJ6+AEH6+AEF6+AED6+AEB6+ADZ6+ADX6+ADV6+ADT6 -> 0 | AEO6: =AEM6+AEK6+AEI6+AEG6+AEE6+AEC6+AEA6+ADY6+ADW6+ADU6 -> 23 | AEP6: =AEO6+AEN6 -> 23 | AER6: 1 | AET6: 7 | AEV6: 2 | AEX6: 13 | AFA6: =AEU6+AES6+AEQ6+AEY6+AEW6 -> 0 | AFB6: =AEV6+AET6+AER6+AEZ6+AEX6 -> 23 | AFC6: =SUM(AFA6:AFB6) -> 23 | AFE6: 1 | AFG6: 8 | AFI6: 11 | AFK6: 3 | AFN6: =AFL6+AFJ6+AFH6+AFF6+AFD6 -> 0 | AFO6: =AFM6+AFK6+AFI6+AFG6+AFE6 -> 23 | AFP6: =SUM(AFN6:AFO6) -> 23 | AFR6: 3 | AFT6: 19 | AFX6: 1 | AFY6: =AFW6+AFU6+AFS6+AFQ6 -> 0 | AFZ6: =AFX6+AFV6+AFT6+AFR6 -> 23 | AGA6: =AFZ6+AFY6 -> 23 | AGB6: =IF((AFY6=AFN6)*AND(AFA6=AEN6)*AND(LB6=JE6),"صح","خطأ") -> صح | AGC6: =IF((AFZ6=AFO6)*AND(AFB6=AEO6)*AND(LC6=JF6),"صح","خطأ") -> صح | AGD6: =IF((AGA6=AFP6)*AND(AFC6=AEP6)*AND(LD6=JG6),"صح","خطأ") -> صح | AGF6: 2 | AGG6: =SUM(AGE6:AGF6) -> 2 | AGJ6: =AGI6+AGH6 -> 0 | AGL6: 1 | AGN6: 1 | AGP6: 1 | AGR6: 1 | AGT6: 1 | AHB6: 1 | AHE6: =AHD6+AHC6 -> 0 | AHI6: =AHH6+AHG6+AHF6 -> 0 | AHL6: =AHK6+AHJ6 -> 0 | AHN6: 1 | AID6: =AIC6+AIB6 -> 0 | AKP6: 1 | AKR6: 1 | AKV6: 1 | AKZ6: 1 | ALD6: 1 | ALG6: 100 | ALH6: 50 | ALI6: =ALH6+ALG6 -> 150 | ALJ6: 1 | ALL6: مجمع الوقف الشيعي بجانب قرية الغدير | ALM6: حلا زغير كريم | ALN6: 7819222082
A7: النجف | B7: المركز | C7: 2 | D7: 1400903 | E7: وليد الكعبة الابتدائية للبنين | F7: 1 | I7: 1 | K7: 1 | O7: 1 | S7: 1 | Y7: 10 | AA7: 70 | AG7: 1 | AK7: =AI7+AG7+AE7+AC7+AA7+Y7 -> 81 | AL7: =AJ7+AH7+AF7+AD7+AB7+Z7 -> 0 | AM7: =AL7+AK7 -> 81 | AN7: =Y7 -> 10 | AO7: =Z7 -> 0 | AP7: =AA7 -> 70 | AQ7: =AB7 -> 0 | AV7: 1 | AZ7: =AX7+AV7+AT7+AR7+AP7+AN7 -> 81 | BA7: =AY7+AW7+AU7+AS7+AQ7+AO7 -> 0 | BB7: =BA7+AZ7 -> 81 | BC7: 90 | BE7: 3 | BM7: =BK7+BI7+BG7+BE7+BC7 -> 93 | BN7: =BL7+BJ7+BH7+BF7+BD7 -> 0 | BO7: =BN7+BM7 -> 93 | BP7: 62 | BR7: 3 | BT7: 2 | BZ7: =BX7+BV7+BT7+BR7+BP7 -> 67 | CA7: =BY7+BW7+BU7+BS7+BQ7 -> 0 | CB7: =CA7+BZ7 -> 67 | CC7: 74 | CE7: 6 | CG7: 2 | CK7: 1 | CM7: =CK7+CI7+CG7+CE7+CC7 -> 83 | CN7: =CL7+CJ7+CH7+CF7+CD7 -> 0 | CO7: =CN7+CM7 -> 83 | CP7: 70 | CR7: 14 | CT7: 7 | CX7: 3 | CZ7: =CX7+CV7+CT7+CR7+CP7 -> 94 | DA7: =CY7+CW7+CU7+CS7+CQ7 -> 0 | DB7: =DA7+CZ7 -> 94 | DC7: 66 | DE7: 11 | DG7: 2 | DI7: 1 | DM7: =DK7+DI7+DG7+DE7+DC7 -> 80 | DN7: =DL7+DJ7+DH7+DF7+DD7 -> 0 | DO7: =DN7+DM7 -> 80 | DP7: =AN7 -> 10 | DQ7: =AO7 -> 0 | DR7: =AP7 -> 70 | DS7: =AQ7 -> 0 | DT7: =AR7+BC7 -> 90 | DU7: =AS7+BD7 -> 0 | DV7: =AT7+BE7+BP7 -> 65 | DW7: =AU7+BF7+BQ7 -> 0 | DX7: =AV7+BG7+BR7+CC7 -> 78 | DY7: =AW7+BH7+BS7+CD7 -> 0 | DZ7: =AX7+BI7+BT7+CE7+CP7 -> 78 | EA7: =AY7+BJ7+BU7+CF7+CQ7 -> 0 | EB7: =BK7+BV7+CG7+CR7+DC7 -> 82 | EC7: =BL7+BW7+CH7+CS7+DD7 -> 0 | ED7: =BX7+CI7+CT7+DE7 -> 18 | EE7: =BY7+CJ7+CU7+DF7 -> 0 | EF7: =CK7+CV7+DG7 -> 3 | EG7: =CL7+CW7+DH7 -> 0 | EH7: =CX7+DI7 -> 4 | EI7: =CY7+DJ7 -> 0 | EJ7: =DK7 -> 0 | EK7: =DL7 -> 0 | EL7: =EJ7+EH7+EF7+ED7+EB7+DZ7+DX7+DV7+DT7+DR7+DP7 -> 498 | EM7: =EK7+EI7+EG7+EE7+EC7+EA7+DY7+DW7+DU7+DS7+DQ7 -> 0 | EN7: =EM7+EL7 -> 498 | EO7: 2 | ER7: 2 | EU7: 2 | EX7: 2 | FA7: 2 | FD7: 2 | FG7: =FD7+FA7+EX7+EU7+ER7+EO7 -> 12 | FH7: =FE7+FB7+EY7+EV7+ES7+EP7 -> 0 | FI7: =FF7+FC7+EZ7+EW7+ET7+EQ7 -> 0 | FJ7: =FI7+FH7+FG7 -> 12 | FK7: 1 | FM7: 2 | FS7: 1 | FW7: =FU7+FS7+FQ7+FO7+FM7+FK7 -> 4 | FX7: =FV7+FT7+FR7+FP7+FN7+FL7 -> 0 | FY7: =FX7+FW7 -> 4 | FZ7: 95 | GB7: 66 | GD7: 81 | GF7: 71 | GH7: 82 | GJ7: 78 | GL7: =GJ7+GH7+GF7+GD7+GB7+FZ7 -> 473 | GM7: =GK7+GI7+GG7+GE7+GC7+GA7 -> 0 | GN7: =GM7+GL7 -> 473 | GO7: 2 | GQ7: 1 | GS7: 4 | GU7: 5 | GW7: 2 | HA7: =GY7+GW7+GU7+GS7+GQ7+GO7 -> 14 | HB7: =GZ7+GX7+GV7+GT7+GR7+GP7 -> 0 | HC7: =HB7+HA7 -> 14 | HP7: =HN7+HL7+HJ7+HH7+HF7+HD7 -> 0 | HQ7: =HO7+HM7+HK7+HI7+HG7+HE7 -> 0 | HR7: =HQ7+HP7 -> 0 | IE7: =IC7+IA7+HY7+HW7+HU7+HS7 -> 0 | IF7: =ID7+IB7+HZ7+HX7+HV7+HT7 -> 0 | IG7: =IF7+IE7 -> 0 | IH7: =HS7+GO7+HD7 -> 2 | II7: =HT7+HE7+GP7 -> 0 | IJ7: =HU7+HF7+GQ7 -> 1 | IK7: =HV7+HG7+GR7 -> 0 | IL7: =HW7+HH7+GS7 -> 4 | IM7: =HX7+HI7+GT7 -> 0 | IN7: =HY7+HJ7+GU7 -> 5 | IO7: =HZ7+HK7+GV7 -> 0 | IP7: =IA7+HL7+GW7 -> 2 | ... IS7: =ID7+HO7+GZ7 -> 0 | IT7: =IR7+IP7+IN7+IL7+IJ7+IH7 -> 14 | IU7: =IS7+IQ7+IO7+IM7+IK7+II7 -> 0 | IV7: =IU7+IT7 -> 14 | IW7: 1 | IY7: 2 | JA7: 22 | JB7: 2 | JC7: 1 | JE7: =JC7+JA7+IY7+IW7 -> 26 | JF7: =JD7+JB7+IZ7+IX7 -> 2 | JG7: =JF7+JE7 -> 28 | JO7: 1 | JW7: =JV7+JU7+JT7+JP7+JN7+JJ7+JH7+JR7+JL7 -> 0 | JX7: =JQ7+JO7+JK7+JI7+JM7+JS7 -> 1 | JY7: =JX7+JW7 -> 1 | JZ7: 26 | KA7: 2 | KF7: =KD7+KB7+JZ7 -> 26 | KG7: =KE7+KC7+KA7 -> 2 | KH7: =KG7+KF7 -> 28 | KI7: 24 | KJ7: 1 | KS7: 2 | KU7: 1 | KZ7: =KV7+KS7+KQ7+KO7+KM7+KK7 -> 2 | LA7: =KW7+KU7+KT7+KR7+KP7+KN7+KL7 -> 1 | LB7: =KZ7+KI7 -> 26 | LC7: =LA7+KJ7 -> 2 | LD7: =LC7+LB7 -> 28 | LG7: 3 | LM7: 8 | LY7: =LW7+LU7+LS7+LQ7+LO7+LM7+LK7+LI7+LG7+LE7 -> 11 | LZ7: =LX7+LV7+LT7+LR7+LP7+LN7+LL7+LJ7+LH7+LF7 -> 0 | MA7: =LZ7+LY7 -> 11 | MD7: 2 | MJ7: 1 | ML7: 1 | MV7: =MT7+MR7+MP7+MN7+ML7+MJ7+MH7+MF7+MD7+MB7 -> 4 | MW7: =MU7+MS7+MQ7+MO7+MM7+MK7+MI7+MG7+ME7+MC7 -> 0 | MX7: =MW7+MV7 -> 4 | NA7: 1 | NG7: 1 | NS7: =NQ7+NO7+NM7+NK7+NI7+NG7+NE7+NC7+NA7+MY7 -> 2 | NT7: =NR7+NP7+NN7+NL7+NJ7+NH7+NF7+ND7+NB7+MZ7 -> 0 | NU7: =NT7+NS7 -> 2 | OP7: =ON7+OL7+OJ7+OH7+OF7+OD7+OB7+NZ7+NX7+NV7 -> 0 | OQ7: =OO7+OM7+OK7+OI7+OG7+OE7+OC7+OA7+NY7+NW7 -> 0 | OR7: =OQ7+OP7 -> 0 | OU7: 4 | OV7: 1 | PM7: =PK7+PI7+PG7+PE7+PC7+PA7+OY7+OW7+OU7+OS7 -> 4 | PN7: =PL7+PJ7+PH7+PF7+PD7+PB7+OZ7+OX7+OV7+OT7 -> 1 | PO7: =PN7+PM7 -> 5 | QA7: 1 | QJ7: =QH7+QF7+QD7+QB7+PZ7+PX7+PV7+PT7+PR7+PP7 -> 0 | QK7: =QI7+QG7+QE7+QC7+QA7+PY7+PW7+PU7+PS7+PQ7 -> 1 | QL7: =QK7+QJ7 -> 1 | RG7: =RE7+RC7+RA7+QY7+QW7+QU7+QS7+QQ7+QO7+QM7 -> 0 | RH7: =RF7+RD7+RB7+QZ7+QX7+QV7+QT7+QR7+QP7+QN7 -> 0 | RI7: =RH7+RG7 -> 0 | SD7: =SB7+RZ7+RX7+RV7+RT7+RR7+RP7+RN7+RL7+RJ7 -> 0 | SE7: =SC7+SA7+RY7+RW7+RU7+RS7+RQ7+RO7+RM7+RK7 -> 0 | SF7: =SE7+SD7 -> 0 | TA7: =SY7+SW7+SU7+SS7+SQ7+SO7+SM7+SK7+SI7+SG7 -> 0 | TB7: =SZ7+SX7+SV7+ST7+SR7+SP7+SN7+SL7+SJ7+SH7 -> 0 | TC7: =TB7+TA7 -> 0 | TX7: =TV7+TT7+TR7+TP7+TN7+TL7+TJ7+TH7+TF7+TD7 -> 0 | TY7: =TW7+TU7+TS7+TQ7+TO7+TM7+TK7+TI7+TG7+TE7 -> 0 | TZ7: =TY7+TX7 -> 0 | UU7: =US7+UQ7+UO7+UM7+UK7+UI7+UG7+UE7+UC7+UA7 -> 0 | UV7: =UT7+UR7+UP7+UN7+UL7+UJ7+UH7+UF7+UD7+UB7 -> 0 | UW7: =UV7+UU7 -> 0 | VR7: =VP7+VN7+VL7+VJ7+VH7+VF7+VD7+VB7+UZ7+UX7 -> 0 | VS7: =VQ7+VO7+VM7+VK7+VI7+VG7+VE7+VC7+VA7+UY7 -> 0 | VT7: =VS7+VR7 -> 0 | WO7: =WM7+WK7+WI7+WG7+WE7+WC7+WA7+VY7+VW7+VU7 -> 0 | WP7: =WN7+WL7+WJ7+WH7+WF7+WD7+WB7+VZ7+VX7+VV7 -> 0 | WQ7: =WP7+WO7 -> 0 | WZ7: 2 | XL7: =XJ7+XH7+XF7+XD7+XB7+WZ7+WX7+WV7+WT7+WR7 -> 2 | XM7: =XK7+XI7+XG7+XE7+XC7+XA7+WY7+WW7+WU7+WS7 -> 0 | XN7: =XM7+XL7 -> 2 | YI7: =YG7+YE7+YC7+YA7+XY7+XW7+XU7+XS7+XQ7+XO7 -> 0 | YJ7: =YH7+YF7+YD7+YB7+XZ7+XX7+XV7+XT7+XR7+XP7 -> 0 | YK7: =YJ7+YI7 -> 0 | YN7: 2 | ZF7: =ZD7+ZB7+YZ7+YX7+YV7+YT7+YR7+YP7+YN7+YL7 -> 2 | ZG7: =ZE7+ZC7+ZA7+YY7+YW7+YU7+YS7+YQ7+YO7+YM7 -> 0 | ZH7: =ZG7+ZF7 -> 2 | AAC7: =AAA7+ZY7+ZW7+ZU7+ZS7+ZQ7+ZO7+ZM7+ZK7+ZI7 -> 0 | AAD7: =AAB7+ZZ7+ZX7+ZV7+ZT7+ZR7+ZP7+ZN7+ZL7+ZJ7 -> 0 | AAE7: =AAD7+AAC7 -> 0 | AAZ7: =AAX7+AAV7+AAT7+AAR7+AAP7+AAN7+AAL7+AAJ7+AAH7+AAF7 -> 0 | ABA7: =AAY7+AAW7+AAU7+AAS7+AAQ7+AAO7+AAM7+AAK7+AAI7+AAG7 -> 0 | ABB7: =ABA7+AAZ7 -> 0 | ABW7: =ABU7+ABS7+ABQ7+ABO7+ABM7+ABK7+ABI7+ABG7+ABE7+ABC7 -> 0 | ABX7: =ABV7+ABT7+ABR7+ABP7+ABN7+ABL7+ABJ7+ABH7+ABF7+ABD7 -> 0 | ABY7: =ABX7+ABW7 -> 0 | ACT7: =ACR7+ACP7+ACN7+ACL7+ACJ7+ACH7+ACF7+ACD7+ACB7+ABZ7 -> 0 | ACU7: =ACS7+ACQ7+ACO7+ACM7+ACK7+ACI7+ACG7+ACE7+ACC7+ACA7 -> 0 | ACV7: =ACU7+ACT7 -> 0 | ADG7: 1 | ADQ7: =ADO7+ADM7+ADK7+ADI7+ADG7+ADE7+ADC7+ADA7+ACY7+ACW7 -> 1 | ADR7: =ADP7+ADN7+ADL7+ADJ7+ADH7+ADF7+ADD7+ADB7+ACZ7+ACX7 -> 0 | ADS7: =ADR7+ADQ7 -> 1 | ADT7: =ACW7+ABZ7+ABC7+AAF7+ZI7+YL7+XO7+WR7+VU7+UX7+UA7+TD7+SG7+RJ7+QM7+PP7+OS7+NV7+MY7+MB7+LE7 -> 0 | ADU7: =ACX7+ACA7+ABD7+AAG7+ZJ7+YM7+XP7+WS7+VV7+UY7+UB7+TE7+SH7+RK7+QN7+PQ7+OT7+NW7+MZ7+MC7+LF7 -> 0 | ADV7: =ACY7+ACB7+ABE7+AAH7+ZK7+YN7+XQ7+WT7+VW7+UZ7+UC7+TF7+SI7+RL7+QO7+PR7+OU7+NX7+NA7+MD7+LG7 -> 12 | ADW7: =ACZ7+ACC7+ABF7+AAI7+ZL7+YO7+XR7+WU7+VX7+VA7+UD7+TG7+SJ7+RM7+QP7+PS7+OV7+NY7+NB7+ME7+LH7 -> 1 | ADX7: =ADA7+ACD7+ABG7+AAJ7+ZM7+YP7+XS7+WV7+VY7+VB7+UE7+TH7+SK7+RN7+QQ7+PT7+OW7+NZ7+NC7+MF7+LI7 -> 0 | ADY7: =ADB7+ACE7+ABH7+AAK7+ZN7+YQ7+XT7+WW7+VZ7+VC7+UF7+TI7+SL7+RO7+QR7+PU7+OX7+OA7+ND7+MG7+LJ7 -> 0 | ADZ7: =ADC7+ACF7+ABI7+AAL7+ZO7+YR7+XU7+WX7+WA7+VD7+UG7+TJ7+SM7+RP7+QS7+PV7+OY7+OB7+NE7+MH7+LK7 -> 0 | AEA7: =ADD7+ACG7+ABJ7+AAM7+ZP7+YS7+XV7+WY7+WB7+VE7+UH7+TK7+SN7+RQ7+QT7+PW7+OZ7+OC7+NF7+MI7+LL7 -> 0 | ... AEM7: =ADP7+ACS7+ABV7+AAY7+AAB7+ZE7+YH7+XK7+WN7+VQ7+UT7+TW7+SZ7+SC7+RF7+QI7+PL7+OO7+NR7+MU7+LX7 -> 0 | AEN7: =AEL7+AEJ7+AEH7+AEF7+AED7+AEB7+ADZ7+ADX7+ADV7+ADT7 -> 26 | AEO7: =AEM7+AEK7+AEI7+AEG7+AEE7+AEC7+AEA7+ADY7+ADW7+ADU7 -> 2 | AEP7: =AEO7+AEN7 -> 28 | AEQ7: 4 | AER7: 2 | AES7: 4 | AEU7: 5 | AEW7: 13 | AFA7: =AEU7+AES7+AEQ7+AEY7+AEW7 -> 26 | AFB7: =AEV7+AET7+AER7+AEZ7+AEX7 -> 2 | AFC7: =SUM(AFA7:AFB7) -> 28 | AFE7: 1 | AFF7: 10 | AFG7: 1 | AFH7: 11 | AFJ7: 4 | AFL7: 1 | AFN7: =AFL7+AFJ7+AFH7+AFF7+AFD7 -> 26 | AFO7: =AFM7+AFK7+AFI7+AFG7+AFE7 -> 2 | AFP7: =SUM(AFN7:AFO7) -> 28 | AFQ7: 1 | AFS7: 24 | AFT7: 2 | AFW7: 1 | AFY7: =AFW7+AFU7+AFS7+AFQ7 -> 26 | AFZ7: =AFX7+AFV7+AFT7+AFR7 -> 2 | AGA7: =AFZ7+AFY7 -> 28 | AGB7: =IF((AFY7=AFN7)*AND(AFA7=AEN7)*AND(LB7=JE7),"صح","خطأ") -> صح | AGC7: =IF((AFZ7=AFO7)*AND(AFB7=AEO7)*AND(LC7=JF7),"صح","خطأ") -> صح | AGD7: =IF((AGA7=AFP7)*AND(AFC7=AEP7)*AND(LD7=JG7),"صح","خطأ") -> صح | AGG7: =SUM(AGE7:AGF7) -> 0 | AGJ7: =AGI7+AGH7 -> 0 | AGL7: 1 | AGN7: 1 | AGP7: 1 | AGR7: 1 | AGT7: 1 | AHB7: 1 | AHE7: =AHD7+AHC7 -> 0 | AHI7: =AHH7+AHG7+AHF7 -> 0 | AHL7: =AHK7+AHJ7 -> 0 | AHN7: 1 | AHO7: 1 | AHQ7: 2015 | AHU7: 1 | AHW7: 1 | AHZ7: 1 | AIB7: 18 | AIC7: 2 | AID7: =AIC7+AIB7 -> 20 | AIH7: 1 | AIJ7: 1 | AIQ7: 1 | AIT7: 1 | AIU7: 1 | AIW7: 1 | AJB7: 1 | AJD7: 1 | AJG7: 1 | AJK7: 1 | AJM7: 1 | AJN7: 1 | AJQ7: 1 | AJU7: 1 | AJW7: 1 | AJY7: 1 | AKB7: 1 | AKE7: 1 | AKG7: 1 | AKJ7: 150 | AKN7: 12 | AKP7: 1 | AKR7: 1 | AKT7: 1 | AKV7: 1 | ALA7: 1 | ALD7: 1 | ALG7: 84 | ALH7: 80 | ALI7: =ALH7+ALG7 -> 164 | ALK7: 1 | ALL7: مجمع الوقف الشيعي بجانب قرية الغدير | ALM7: احمد عبد الرضا هادي | ALN7: 7726020029
A8: خلاصة مركز النجف | F8: =SUM(F6:F7) -> 1 | G8: =SUM(G6:G7) -> 1 | H8: =SUM(H6:H7) -> 0 | I8: =SUM(I6:I7) -> 2 | J8: =SUM(J6:J7) -> 0 | K8: =SUM(K6:K7) -> 1 | L8: =SUM(L6:L7) -> 1 | M8: =SUM(M6:M7) -> 0 | ... JK8: =SUM(JK6:JK7) -> 0 | JN8: =SUM(JN6:JN7) -> 0 | JO8: =SUM(JO6:JO7) -> 1 | JP8: =SUM(JP6:JP7) -> 0 | JQ8: =SUM(JQ6:JQ7) -> 1 | JR8: =SUM(JR6:JR7) -> 0 | JS8: =SUM(JS6:JS7) -> 0 | JT8: =SUM(JT6:JT7) -> 0 | JU8: =SUM(JU6:JU7) -> 0 | ... AGA8: =SUM(AGA6:AGA7) -> 51 | AGB8: =IF((AFY8=AFN8)*AND(AFA8=AEN8)*AND(LB8=JE8),"صح","خطأ") -> صح | AGC8: =IF((AFZ8=AFO8)*AND(AFB8=AEO8)*AND(LC8=JF8),"صح","خطأ") -> صح | AGD8: =IF((AGA8=AFP8)*AND(AFC8=AEP8)*AND(LD8=JG8),"صح","خطأ") -> صح | AGE8: =SUM(AGE6:AGE7) -> 0 | AGF8: =SUM(AGF6:AGF7) -> 2 | AGG8: =SUM(AGG6:AGG7) -> 2 | AGH8: =SUM(AGH6:AGH7) -> 0 | AGI8: =SUM(AGI6:AGI7) -> 0 | AGJ8: =SUM(AGJ6:AGJ7) -> 0 | AGK8: =SUM(AGK6:AGK7) -> 0 | AGL8: =SUM(AGL6:AGL7) -> 2 | ... AHP8: =SUM(AHP6:AHP7) -> 0 | AHR8: =SUM(AHR6:AHR7) -> 0 | AHS8: =SUM(AHS6:AHS7) -> 0 | AHT8: =SUM(AHT6:AHT7) -> 0 | AHU8: =SUM(AHU6:AHU7) -> 1 | AHV8: =SUM(AHV6:AHV7) -> 0 | AHW8: =SUM(AHW6:AHW7) -> 1 | AHX8: =SUM(AHX6:AHX7) -> 0 | AHY8: =SUM(AHY6:AHY7) -> 0 | ... ALK8: =SUM(ALK6:ALK7) -> 1
A9: النجف | B9: الحيدرية | C9: 3 | D9: 1401184 | E9: العترة الطاهرة المختلطة | H9: 1 | J9: 1 | K9: 1 | O9: 1 | Q9: 1 | AA9: 27 | AB9: 28 | AC9: 5 | AD9: 2 | AE9: 2 | AF9: 1 | AH9: 1 | AK9: =AI9+AG9+AE9+AC9+AA9+Y9 -> 34 | AL9: =AJ9+AH9+AF9+AD9+AB9+Z9 -> 32 | AM9: =AL9+AK9 -> 66 | AN9: =Y9 -> 0 | AO9: =Z9 -> 0 | AP9: =AA9 -> 27 | AQ9: =AB9 -> 28 | AR9: 5 | AS9: 2 | AT9: 2 | AU9: 1 | AW9: 1 | AZ9: =AX9+AV9+AT9+AR9+AP9+AN9 -> 34 | BA9: =AY9+AW9+AU9+AS9+AQ9+AO9 -> 32 | BB9: =BA9+AZ9 -> 66 | BC9: 21 | BD9: 14 | BE9: 6 | BF9: 10 | BG9: 3 | BH9: 1 | BI9: 1 | BK9: 1 | BL9: 1 | BM9: =BK9+BI9+BG9+BE9+BC9 -> 32 | BN9: =BL9+BJ9+BH9+BF9+BD9 -> 26 | BO9: =BN9+BM9 -> 58 | BP9: 15 | BQ9: 18 | BR9: 9 | BS9: 4 | BT9: 6 | BU9: 1 | BV9: 1 | BW9: 3 | BX9: 1 | BZ9: =BX9+BV9+BT9+BR9+BP9 -> 32 | CA9: =BY9+BW9+BU9+BS9+BQ9 -> 26 | CB9: =CA9+BZ9 -> 58 | CC9: 11 | CD9: 16 | CE9: 8 | CF9: 6 | CG9: 3 | CH9: 5 | CI9: 2 | CJ9: 1 | CK9: 3 | CL9: 1 | CM9: =CC9+CE9+CG9+CI9+CK10 -> 27 | CN9: =CD9+CF9+CH9+CJ9+CL9 -> 29 | CO9: =CN9+CM9 -> 56 | CP9: 17 | CQ9: 10 | CR9: 10 | CS9: 1 | CT9: 3 | CU9: 1 | CX9: 1 | CZ9: =CX9+CV9+CT9+CR9+CP9 -> 31 | DA9: =CY9+CW9+CU9+CS9+CQ9 -> 12 | DB9: =DA9+CZ9 -> 43 | DC9: 11 | DD9: 12 | DE9: 5 | DF9: 5 | DG9: 4 | DI9: 4 | DM9: =DK9+DI9+DG9+DE9+DC9 -> 24 | DN9: =DL9+DJ9+DH9+DF9+DD9 -> 17 | DO9: =DN9+DM9 -> 41 | DP9: =AN9 -> 0 | DQ9: =AO9 -> 0 | DR9: =AP9 -> 27 | DS9: =AQ9 -> 28 | DT9: =AR9+BC9 -> 26 | DU9: =AS9+BD9 -> 16 | DV9: =AT9+BE9+BP9 -> 23 | DW9: =AU9+BF9+BQ9 -> 29 | DX9: =AV9+BG9+BR9+CC9 -> 23 | DY9: =AW9+BH9+BS9+CD9 -> 22 | DZ9: =AX9+BI9+BT9+CE9+CP9 -> 32 | EA9: =AY9+BJ9+BU9+CF9+CQ9 -> 17 | EB9: =BK9+BV9+CG9+CR9+DC9 -> 26 | EC9: =BL9+BW9+CH9+CS9+DD9 -> 22 | ED9: =BX9+CI9+CT9+DE9 -> 11 | EE9: =BY9+CJ9+CU9+DF9 -> 7 | EF9: =CK9+CV9+DG9 -> 7 | EG9: =CL9+CW9+DH9 -> 1 | EH9: =CX9+DI9 -> 5 | EI9: =CY9+DJ9 -> 0 | EJ9: =DK9 -> 0 | EK9: =DL9 -> 0 | EL9: =EJ9+EH9+EF9+ED9+EB9+DZ9+DX9+DV9+DT9+DR9+DP9 -> 180 | EM9: =EK9+EI9+EG9+EE9+EC9+EA9+DY9+DW9+DU9+DS9+DQ9 -> 142 | EN9: =EM9+EL9 -> 322 | EQ9: 2 | ER9: 1 | ES9: 1 | EU9: 1 | EV9: 1 | EX9: 1 | EY9: 1 | FC9: 1 | FD9: 1 | FE9: 1 | FG9: =FD9+FA9+EX9+EU9+ER9+EO9 -> 4 | FH9: =FE9+FB9+EY9+EV9+ES9+EP9 -> 4 | FI9: =FF9+FC9+EZ9+EW9+ET9+EQ9 -> 3 | FJ9: =FI9+FH9+FG9 -> 11 | FK9: 1 | FM9: 2 | FO9: 2 | FU9: 1 | FW9: =FU9+FS9+FQ9+FO9+FM9+FK9 -> 6 | FX9: =FV9+FT9+FR9+FP9+FN9+FL9 -> 0 | FY9: =FX9+FW9 -> 6 | FZ9: 25 | GA9: 16 | GB9: 23 | GC9: 20 | GD9: 19 | GE9: 20 | GF9: 19 | GG9: 25 | GH9: 19 | GI9: 9 | GJ9: 13 | GK9: 17 | GL9: =GJ9+GH9+GF9+GD9+GB9+FZ9 -> 118 | GM9: =GK9+GI9+GG9+GE9+GC9+GA9 -> 107 | GN9: =GM9+GL9 -> 225 | GO9: 2 | GP9: 1 | GQ9: 1 | GR9: 1 | GS9: 2 | GW9: 3 | HA9: =GY9+GW9+GU9+GS9+GQ9+GO9 -> 8 | HB9: =GZ9+GX9+GV9+GT9+GR9+GP9 -> 2 | HC9: =HB9+HA9 -> 10 | HD9: 1 | HF9: 2 | HH9: 2 | HN9: 1 | HP9: =HD9+HF9+HH9+HJ9+HL9+HN9 -> 6 | HQ9: =HO9+HM9+HK9+HI9+HG9+HE9 -> 0 | HR9: =HQ9+HP9 -> 6 | IE9: =IC9+IA9+HY9+HW9+HU9+HS9 -> 0 | IF9: =ID9+IB9+HZ9+HX9+HV9+HT9 -> 0 | IG9: =IF9+IE9 -> 0 | IH9: =HS9+GO9+HD9 -> 3 | II9: =HT9+HE9+GP9 -> 1 | IJ9: =HU9+HF9+GQ9 -> 3 | IK9: =HV9+HG9+GR9 -> 1 | IL9: =HW9+HH9+GS9 -> 4 | IM9: =HX9+HI9+GT9 -> 0 | IN9: =HY9+HJ9+GU9 -> 0 | IO9: =HZ9+HK9+GV9 -> 0 | IP9: =IA9+HL9+GW9 -> 3 | ... IS9: =ID9+HO9+GZ9 -> 0 | IT9: =IR9+IP9+IN9+IL9+IJ9+IH9 -> 14 | IU9: =IS9+IQ9+IO9+IM9+IK9+II9 -> 2 | IV9: =IU9+IT9 -> 16 | IW9: 1 | IZ9: 1 | JA9: 6 | JB9: 8 | JE9: =JC9+JA9+IY9+IW9 -> 7 | JF9: =JD9+JB9+IZ9+IX9 -> 9 | JG9: =JF9+JE9 -> 16 | JI9: 1 | JK9: 1 | JP9: 1 | JQ9: 1 | JW9: =JV9+JU9+JT9+JP9+JN9+JJ9+JH9+JR9+JL9 -> 1 | JX9: =JQ9+JO9+JK9+JI9+JM9+JS9 -> 3 | JY9: =JX9+JW9 -> 4 | JZ9: 7 | KA9: 9 | KF9: =KD9+KB9+JZ9 -> 7 | KG9: =KE9+KC9+KA9 -> 9 | KH9: =KG9+KF9 -> 16 | KI9: 7 | KJ9: 9 | KZ9: =KV9+KS9+KQ9+KO9+KM9+KK9 -> 0 | LA9: =KW9+KU9+KT9+KR9+KP9+KN9+KL9 -> 0 | LB9: =KZ9+KI9 -> 7 | LC9: =LA9+KJ9 -> 9 | LD9: =LC9+LB9 -> 16 | LM9: 2 | LN9: 1 | LS9: 2 | LT9: 1 | LY9: =LW9+LU9+LS9+LQ9+LO9+LM9+LK9+LI9+LG9+LE9 -> 4 | LZ9: =LX9+LV9+LT9+LR9+LP9+LN9+LL9+LJ9+LH9+LF9 -> 2 | MA9: =LZ9+LY9 -> 6 | MJ9: 1 | MK9: 1 | MP9: 1 | MV9: =MT9+MR9+MP9+MN9+ML9+MJ9+MH9+MF9+MD9+MB9 -> 2 | MW9: =MU9+MS9+MQ9+MO9+MM9+MK9+MI9+MG9+ME9+MC9 -> 1 | MX9: =MW9+MV9 -> 3 | NS9: =NQ9+NO9+NM9+NK9+NI9+NG9+NE9+NC9+NA9+MY9 -> 0 | NT9: =NR9+NP9+NN9+NL9+NJ9+NH9+NF9+ND9+NB9+MZ9 -> 0 | NU9: =NT9+NS9 -> 0 | OP9: =ON9+OL9+OJ9+OH9+OF9+OD9+OB9+NZ9+NX9+NV9 -> 0 | OQ9: =OO9+OM9+OK9+OI9+OG9+OE9+OC9+OA9+NY9+NW9 -> 0 | OR9: =OQ9+OP9 -> 0 | OV9: 3 | PB9: 1 | PM9: =PK9+PI9+PG9+PE9+PC9+PA9+OY9+OW9+OU9+OS9 -> 0 | PN9: =PL9+PJ9+PH9+PF9+PD9+PB9+OZ9+OX9+OV9+OT9 -> 4 | PO9: =PN9+PM9 -> 4 | QA9: 2 | QJ9: =QH9+QF9+QD9+QB9+PZ9+PX9+PV9+PT9+PR9+PP9 -> 0 | QK9: =QI9+QG9+QE9+QC9+QA9+PY9+PW9+PU9+PS9+PQ9 -> 2 | QL9: =QK9+QJ9 -> 2 | RG9: =RE9+RC9+RA9+QY9+QW9+QU9+QS9+QQ9+QO9+QM9 -> 0 | RH9: =RF9+RD9+RB9+QZ9+QX9+QV9+QT9+QR9+QP9+QN9 -> 0 | RI9: =RH9+RG9 -> 0 | SD9: =SB9+RZ9+RX9+RV9+RT9+RR9+RP9+RN9+RL9+RJ9 -> 0 | SE9: =SC9+SA9+RY9+RW9+RU9+RS9+RQ9+RO9+RM9+RK9 -> 0 | SF9: =SE9+SD9 -> 0 | TA9: =SY9+SW9+SU9+SS9+SQ9+SO9+SM9+SK9+SI9+SG9 -> 0 | TB9: =SZ9+SX9+SV9+ST9+SR9+SP9+SN9+SL9+SJ9+SH9 -> 0 | TC9: =TB9+TA9 -> 0 | TX9: =TV9+TT9+TR9+TP9+TN9+TL9+TJ9+TH9+TF9+TD9 -> 0 | TY9: =TW9+TU9+TS9+TQ9+TO9+TM9+TK9+TI9+TG9+TE9 -> 0 | TZ9: =TY9+TX9 -> 0 | UI9: 1 | UU9: =US9+UQ9+UO9+UM9+UK9+UI9+UG9+UE9+UC9+UA9 -> 1 | UV9: =UT9+UR9+UP9+UN9+UL9+UJ9+UH9+UF9+UD9+UB9 -> 0 | UW9: =UV9+UU9 -> 1 | VR9: =VP9+VN9+VL9+VJ9+VH9+VF9+VD9+VB9+UZ9+UX9 -> 0 | VS9: =VQ9+VO9+VM9+VK9+VI9+VG9+VE9+VC9+VA9+UY9 -> 0 | VT9: =VS9+VR9 -> 0 | WO9: =WM9+WK9+WI9+WG9+WE9+WC9+WA9+VY9+VW9+VU9 -> 0 | WP9: =WN9+WL9+WJ9+WH9+WF9+WD9+WB9+VZ9+VX9+VV9 -> 0 | WQ9: =WP9+WO9 -> 0 | XL9: =XJ9+XH9+XF9+XD9+XB9+WZ9+WX9+WV9+WT9+WR9 -> 0 | XM9: =XK9+XI9+XG9+XE9+XC9+XA9+WY9+WW9+WU9+WS9 -> 0 | XN9: =XM9+XL9 -> 0 | YI9: =YG9+YE9+YC9+YA9+XY9+XW9+XU9+XS9+XQ9+XO9 -> 0 | YJ9: =YH9+YF9+YD9+YB9+XZ9+XX9+XV9+XT9+XR9+XP9 -> 0 | YK9: =YJ9+YI9 -> 0 | ZF9: =ZD9+ZB9+YZ9+YX9+YV9+YT9+YR9+YP9+YN9+YL9 -> 0 | ZG9: =ZE9+ZC9+ZA9+YY9+YW9+YU9+YS9+YQ9+YO9+YM9 -> 0 | ZH9: =ZG9+ZF9 -> 0 | AAC9: =AAA9+ZY9+ZW9+ZU9+ZS9+ZQ9+ZO9+ZM9+ZK9+ZI9 -> 0 | AAD9: =AAB9+ZZ9+ZX9+ZV9+ZT9+ZR9+ZP9+ZN9+ZL9+ZJ9 -> 0 | AAE9: =AAD9+AAC9 -> 0 | AAZ9: =AAX9+AAV9+AAT9+AAR9+AAP9+AAN9+AAL9+AAJ9+AAH9+AAF9 -> 0 | ABA9: =AAY9+AAW9+AAU9+AAS9+AAQ9+AAO9+AAM9+AAK9+AAI9+AAG9 -> 0 | ABB9: =ABA9+AAZ9 -> 0 | ABW9: =ABU9+ABS9+ABQ9+ABO9+ABM9+ABK9+ABI9+ABG9+ABE9+ABC9 -> 0 | ABX9: =ABV9+ABT9+ABR9+ABP9+ABN9+ABL9+ABJ9+ABH9+ABF9+ABD9 -> 0 | ABY9: =ABX9+ABW9 -> 0 | ACT9: =ACR9+ACP9+ACN9+ACL9+ACJ9+ACH9+ACF9+ACD9+ACB9+ABZ9 -> 0 | ACU9: =ACS9+ACQ9+ACO9+ACM9+ACK9+ACI9+ACG9+ACE9+ACC9+ACA9 -> 0 | ACV9: =ACU9+ACT9 -> 0 | ADQ9: =ADO9+ADM9+ADK9+ADI9+ADG9+ADE9+ADC9+ADA9+ACY9+ACW9 -> 0 | ADR9: =ADP9+ADN9+ADL9+ADJ9+ADH9+ADF9+ADD9+ADB9+ACZ9+ACX9 -> 0 | ADS9: =ADR9+ADQ9 -> 0 | ADT9: =ACW9+ABZ9+ABC9+AAF9+ZI9+YL9+XO9+WR9+VU9+UX9+UA9+TD9+SG9+RJ9+QM9+PP9+OS9+NV9+MY9+MB9+LE9 -> 0 | ADU9: =ACX9+ACA9+ABD9+AAG9+ZJ9+YM9+XP9+WS9+VV9+UY9+UB9+TE9+SH9+RK9+QN9+PQ9+OT9+NW9+MZ9+MC9+LF9 -> 0 | ADV9: =ACY9+ACB9+ABE9+AAH9+ZK9+YN9+XQ9+WT9+VW9+UZ9+UC9+TF9+SI9+RL9+QO9+PR9+OU9+NX9+NA9+MD9+LG9 -> 0 | ADW9: =ACZ9+ACC9+ABF9+AAI9+ZL9+YO9+XR9+WU9+VX9+VA9+UD9+TG9+SJ9+RM9+QP9+PS9+OV9+NY9+NB9+ME9+LH9 -> 3 | ADX9: =ADA9+ACD9+ABG9+AAJ9+ZM9+YP9+XS9+WV9+VY9+VB9+UE9+TH9+SK9+RN9+QQ9+PT9+OW9+NZ9+NC9+MF9+LI9 -> 0 | ADY9: =ADB9+ACE9+ABH9+AAK9+ZN9+YQ9+XT9+WW9+VZ9+VC9+UF9+TI9+SL9+RO9+QR9+PU9+OX9+OA9+ND9+MG9+LJ9 -> 0 | ADZ9: =ADC9+ACF9+ABI9+AAL9+ZO9+YR9+XU9+WX9+WA9+VD9+UG9+TJ9+SM9+RP9+QS9+PV9+OY9+OB9+NE9+MH9+LK9 -> 0 | AEA9: =ADD9+ACG9+ABJ9+AAM9+ZP9+YS9+XV9+WY9+WB9+VE9+UH9+TK9+SN9+RQ9+QT9+PW9+OZ9+OC9+NF9+MI9+LL9 -> 0 | ... AEM9: =ADP9+ACS9+ABV9+AAY9+AAB9+ZE9+YH9+XK9+WN9+VQ9+UT9+TW9+SZ9+SC9+RF9+QI9+PL9+OO9+NR9+MU9+LX9 -> 0 | AEN9: =AEL9+AEJ9+AEH9+AEF9+AED9+AEB9+ADZ9+ADX9+ADV9+ADT9 -> 7 | AEO9: =AEM9+AEK9+AEI9+AEG9+AEE9+AEC9+AEA9+ADY9+ADW9+ADU9 -> 9 | AEP9: =AEO9+AEN9 -> 16 | AEQ9: 2 | AER9: 1 | AES9: 5 | AET9: 8 | AFA9: =AEU9+AES9+AEQ9+AEY9 -> 7 | AFB9: =AEV9+AET9+AER9+AEZ9 -> 9 | AFC9: =SUM(AFA9:AFB9) -> 16 | AFF9: 2 | AFG9: 3 | AFH9: 5 | AFI9: 6 | AFN9: =AFL9+AFJ9+AFH9+AFF9+AFD9 -> 7 | AFO9: =AFM9+AFK9+AFI9+AFG9+AFE9 -> 9 | AFP9: =SUM(AFN9:AFO9) -> 16 | AFS9: 7 | AFT9: 7 | AFV9: 1 | AFX9: 1 | AFY9: =AFW9+AFU9+AFS9+AFQ9 -> 7 | AFZ9: =AFX9+AFV9+AFT9+AFR9 -> 9 | AGA9: =AFZ9+AFY9 -> 16 | AGB9: =IF((AFY9=AFN9)*AND(AFA9=AEN9)*AND(LB9=JE9),"صح","خطأ") -> صح | AGC9: =IF((AFZ9=AFO9)*AND(AFB9=AEO9)*AND(LC9=JF9),"صح","خطأ") -> صح | AGD9: =IF((AGA9=AFP9)*AND(AFC9=AEP9)*AND(LD9=JG9),"صح","خطأ") -> صح | AGE9: 2 | AGF9: 2 | AGG9: =SUM(AGE9:AGF9) -> 4 | AGH9: 1 | AGJ9: =AGI9+AGH9 -> 1 | AGL9: 1 | AGN9: 1 | AGO9: 1 | AGR9: 1 | AGT9: 1 | AHB9: 1 | AHE9: =AHD9+AHC9 -> 0 | AHI9: =AHH9+AHG9+AHF9 -> 0 | AHL9: =AHK9+AHJ9 -> 0 | AHN9: 1 | AHO9: 1 | AHQ9: 2015 | AHT9: 1 | AHV9: 1 | AHY9: 1 | AIB9: 11 | AIC9: 4 | AID9: =AIC9+AIB9 -> 15 | AIG9: 1 | AIO9: 1 | AIQ9: 1 | AIT9: 1 | AIU9: 1 | AIW9: 1 | AJB9: 1 | AJD9: 1 | AJG9: 1 | AJJ9: 1 | AJM9: 1 | AJN9: 1 | AJT9: 1 | AJU9: 1 | AJW9: 1 | AJY9: 1 | AKA9: 1 | AKE9: 1 | AKG9: 1 | AKJ9: 120 | AKK9: 10 | AKL9: 10 | AKN9: 11 | AKO9: 2 | AKP9: 2 | AKQ9: 1 | AKR9: 2 | AKS9: 2 | AKW9: 1 | ALI9: =ALH9+ALG9 -> 0 | ALK9: 1 | ALL9: طريق ياحسين عمود143 | ALM9: امير محمد كريم الطائي | ALN9: 7832453411
A10: خلاصة ناحية الحيدرية | F10: =SUM(F9:F9) -> 0 | G10: =SUM(G9:G9) -> 0 | H10: =SUM(H9:H9) -> 1 | I10: =SUM(I9:I9) -> 0 | J10: =SUM(J9:J9) -> 1 | K10: =SUM(K9:K9) -> 1 | L10: =SUM(L9:L9) -> 0 | M10: =SUM(M9:M9) -> 0 | ... FV10: =SUM(FV9:FV9) -> 0 | FX10: =SUM(FX9:FX9) -> 0 | FY10: =SUM(FY9:FY9) -> 6 | FZ10: =SUM(FZ9:FZ9) -> 25 | GA10: =SUM(GA9:GA9) -> 16 | GB10: =SUM(GB9:GB9) -> 23 | GC10: =SUM(GC9:GC9) -> 20 | GD10: =SUM(GD9:GD9) -> 19 | GE10: =SUM(GE9:GE9) -> 20 | ... JK10: =SUM(JK9:JK9) -> 1 | JN10: =SUM(JN9:JN9) -> 0 | JO10: =SUM(JO9:JO9) -> 0 | JP10: =SUM(JP9:JP9) -> 1 | JQ10: =SUM(JQ9:JQ9) -> 1 | JR10: =SUM(JR9:JR9) -> 0 | JS10: =SUM(JS9:JS9) -> 0 | JT10: =SUM(JT9:JT9) -> 0 | JU10: =SUM(JU9:JU9) -> 0 | ... AGA10: =SUM(AGA9:AGA9) -> 16 | AGE10: =SUM(AGE9:AGE9) -> 2 | AGF10: =SUM(AGF9:AGF9) -> 2 | AGG10: =SUM(AGG9:AGG9) -> 4 | AGH10: =SUM(AGH9:AGH9) -> 1 | AGI10: =SUM(AGI9:AGI9) -> 0 | AGJ10: =SUM(AGJ9:AGJ9) -> 1 | AGK10: =SUM(AGK9:AGK9) -> 0 | AGL10: =SUM(AGL9:AGL9) -> 1 | ... AHP10: =SUM(AHP9:AHP9) -> 0 | AHT10: =SUM(AHT9:AHT9) -> 1 | AHU10: =SUM(AHU9:AHU9) -> 0 | AHV10: =SUM(AHV9:AHV9) -> 1 | AHW10: =SUM(AHW9:AHW9) -> 0 | AHX10: =SUM(AHX9:AHX9) -> 0 | AHY10: =SUM(AHY9:AHY9) -> 1 | AHZ10: =SUM(AHZ9:AHZ9) -> 0 | AIA10: =SUM(AIA9:AIA9) -> 0 | ... ALK10: =SUM(ALK9:ALK9) -> 1
A12: خلاصة ناحية الشبكة | F12: =F11 -> 0 | G12: =G11 -> 0 | H12: =H11 -> 0 | I12: =I11 -> 0 | J12: =J11 -> 0 | K12: =K11 -> 0 | L12: =L11 -> 0 | M12: =M11 -> 0 | ... JK12: =JK11 -> 0 | JN12: =JN11 -> 0 | JO12: =JO11 -> 0 | JP12: =JP11 -> 0 | JQ12: =JQ11 -> 0 | JR12: =JR11 -> 0 | JS12: =JS11 -> 0 | JT12: =JT11 -> 0 | JU12: =JU11 -> 0 | ... AHP12: =AHP11 -> 0 | AHT12: =AHT11 -> 0 | AHU12: =AHU11 -> 0 | AHV12: =AHV11 -> 0 | AHW12: =AHW11 -> 0 | AHX12: =AHX11 -> 0 | AHY12: =AHY11 -> 0 | AHZ12: =AHZ11 -> 0 | AIA12: =AIA11 -> 0 | ... ALK12: =ALK11 -> 0
A13: خلاصة قضاء النجف | F13: =F12+F10+F8 -> 1 | G13: =G12+G10+G8 -> 1 | H13: =H12+H10+H8 -> 1 | I13: =I12+I10+I8 -> 2 | J13: =J12+J10+J8 -> 1 | K13: =K12+K10+K8 -> 2 | L13: =L12+L10+L8 -> 1 | M13: =M12+M10+M8 -> 0 | ... FV13: =FV12+FV10+FV8 -> 0 | FW13: =FW12+FW9+FW8 -> 10 | FX13: =FX12+FX10+FX8 -> 0 | FY13: =FY12+FY10+FY8 -> 10 | FZ13: =FZ12+FZ10+FZ8 -> 120 | GA13: =GA12+GA10+GA8 -> 97 | GB13: =GB12+GB10+GB8 -> 89 | GC13: =GC12+GC10+GC8 -> 90 | GD13: =GD12+GD10+GD8 -> 100 | GE13: =GE12+GE10+GE8 -> 87 | ... JK13: =JK12+JK10+JK8 -> 1 | JN13: =JN12+JN10+JN8 -> 0 | JO13: =JO12+JO10+JO8 -> 1 | JP13: =JP12+JP10+JP8 -> 1 | JQ13: =JQ12+JQ10+JQ8 -> 2 | JR13: =JR12+JR10+JR8 -> 0 | JS13: =JS12+JS10+JS8 -> 0 | JT13: =JT12+JT10+JT8 -> 0 | JU13: =JU12+JU10+JU8 -> 0 | ... AGA13: =AGA12+AGA10+AGA8 -> 67 | AGB13: =IF((AFY13=AFN13)*AND(AFA13=AEN13)*AND(LB13=JE13),"صح","خطأ") -> صح | AGC13: =IF((AFZ13=AFO13)*AND(AFB13=AEO13)*AND(LC13=JF13),"صح","خطأ") -> صح | AGD13: =IF((AGA13=AFP13)*AND(AFC13=AEP13)*AND(LD13=JG13),"صح","خطأ") -> صح | AGE13: =AGE12+AGE10+AGE8 -> 2 | AGF13: =AGF12+AGF10+AGF8 -> 4 | AGG13: =AGG12+AGG10+AGG8 -> 6 | AGH13: =AGH12+AGH10+AGH8 -> 1 | AGI13: =AGI12+AGI10+AGI8 -> 0 | AGJ13: =AGJ12+AGJ10+AGJ8 -> 1 | AGK13: =AGK12+AGK10+AGK8 -> 0 | AGL13: =AGL12+AGL10+AGL8 -> 3 | ... AHP13: =AHP12+AHP10+AHP8 -> 0 | AHT13: =AHT12+AHT10+AHT8 -> 1 | AHU13: =AHU12+AHU10+AHU8 -> 1 | AHV13: =AHV12+AHV10+AHV8 -> 1 | AHW13: =AHW12+AHW10+AHW8 -> 1 | AHX13: =AHX12+AHX10+AHX8 -> 0 | AHY13: =AHY12+AHY10+AHY8 -> 1 | AHZ13: =AHZ12+AHZ10+AHZ8 -> 1 | AIA13: =AIA12+AIA10+AIA8 -> 0 | ... ALK13: =ALK12+ALK10+ALK8 -> 2
