Workbook

Sheet مدارس التعليم الاساسية
A1: المديرية العامة للتربية في محافظة النجف الاشرف | V1: هل المدرسة فتح جديد | IR1: اعضاء الهيئة التعليمية والتدريسية حسب العنوان الوظيفي | JP1: عدد اعضاء الهيئة التعليمية والتدريسية حسب العنوان الوظيفي والجنس
F2: نوع المدرسة | H2: جنس المدرسة | K2: بيئة المدرسة | M2: دوام المدرسة | P2: استقلالية المدرسة | R2: نوع الازدواج | X2: عدد التلامذة الجدد في الصف الاول الابتدائي | AM2: عدد الطلبة الجدد في الصف الاول متوسط ( السابع ) | AZ2: عدد التلامذة المسجلين في الاول الابتدائي | BO2: عدد التلامذة المسجلين في الثاني الابتدائي | CB2: عدد التلامذة المسجلين في الثالث الابتدائي | CO2: عدد التلامذة المسجلين في الصف الرابع الابتدائي | DB2: عدد التلامذة المسجلين في الصف الخامس الابتدائي | DO2: عدد التلامذة المسجلين في الصف السادس الابتدائي | EB2: مجموع المرحلة الابتدائية | FA2: عدد الطلبة المسجلين للصف الاول متوسط ( السابع ) | FN2: عدد الطلبة المسجلين للصف الثاني متوسط ( الثامن ) | GA2: عدد الطلبة المسجلين للصف الثالث متوسط ( التاسع ) | GN2: مجموع عدد الطلبة للتعليم المتوسط | HE2: عدد الشعب حسب الصف والجنس | KC2: الأبنية المدرسية | LM2: المكتبات المدرسية :- | LZ2: المختبرات المدرسية :-
A3: التعليم الاساسي والتكميلي | HE3: شعبــــــــــــــــــــــــــــ المرحلة الابتدائية | IA3: شعب المرحلة المتوسطة | IN3: المجموع الكلي | IR3: المرحلة الابتدائية | JC3: المرحلة المتوسطة | KC3: عدد الابنية المدرسية حسب :- | LE3: هل البناية مزودة بخدمة المجاري | LG3: هل ترتبط البناية بشبكة الماء الصالح للشرب | LI3: هل هناك سياج حول البناية | LK3: هل تتوفر في البناية مرافق صحية | LM3: هل توجد مكتبة | LO3: من المسؤول عن المكتبة | LT3: نوعية المكتبة | LW3: عدد الكتب في المكتبة | LY3: عدد الكتب الكلي | LZ3: هل يوجد مختبر :-
X4: عمر 5 | Z4: عمر 6 | AB4: عمر 7 | AD4: عمر 8 | AF4: عمر 9 | AH4: عمر 10 | AJ4: المجموع | AM4: عمر 12 | AO4: عمر 13 | AQ4: عمر 14 | AS4: عمر 15 | AU4: عمر 16 | AW4: المجموع | AZ4: عمر 5 | BB4: عمر 6 | BD4: عمر 7 | BF4: عمر 8 | BH4: عمر 9 | BJ4: عمر 10 | BL4: المجموع | BO4: عمر 7 | BQ4: عمر 8 | BS4: عمر 9 | BU4: عمر 10 | BW4: عمر 11 | BY4: المجموع | CB4: عمر 8 | CD4: عمر 9 | CF4: عمر 10 | CH4: عمر 11 | CJ4: عمر 12 | CL4: المجموع | CO4: عمر 9 | CQ4: عمر 10 | CS4: عمر 11 | CU4: عمر 12 | CW4: عمر 13 | CY4: المجموع | DB4: عمر 10 | DD4: عمر 11 | DF4: عمر 12 | DH4: عمر 13 | DJ4: عمر 14 | DL4: المجموع | DO4: عمر 11 | DQ4: عمر 12 | DS4: عمر 13 | DU4: عمر 14 | DW4: عمر 15 | DY4: المجموع | EB4: عمر 5 | ED4: عمر 6 | EF4: عمر 7 | EH4: عمر 8 | EJ4: عمر 9 | EL4: عمر 10 | EN4: عمر 11 | EP4: عمر 12 | ER4: عمر 13 | ET4: عمر 14 | EV4: عمر 15 | EX4: المجموع | FA4: 12سنة | FC4: 13سنة | FE4: 14سنة | FG4: 15سنة | FI4: 16سنة | FK4: المجموع | FN4: 13سنة | FP4: 14سنة | FR4: 15سنة | FT4: 16سنة | FV4: 17سنة | FX4: المجموع | GA4: 14سنة | GC4: 15سنة | GE4: 16سنة | GG4: 17سنة | GI4: 18سنة | GK4: المجموع | GN4: 12سنة | GP4: 13سنة | GR4: 14سنة | GT4: 15سنة | GV4: 16سنة | GX4: 17سنة | GZ4: 18سنة فأكثر | HB4: المجموع | HE4: الاول الابتدائي | HH4: الثاني الابتدائي | HK4: الثالث الابتدائي | HN4: الرابع الابتدائي | HQ4: الخامس الابتدائي | HT4: السادس الابتدائي | HW4: مجموع شعب الابتدائي | IA4: الاول متوسط ( السابع ) | ID4: الثاني متوسط ( الثامن ) | IG4: الثالث متوسط ( التاسع ) | IJ4: مجموع المرحلة المتوسطة | IR4: مدير | IT4: معاون | IV4: معلم | IX4: مرشد تربوي | IZ4: المجموع | JC4: مدير | JE4: معاون | JG4: مدرس | JI4: معلم | JK4: مرشد | JM4: المجموع | JP4: مدير | JR4: معاون | JT4: مدرس | JV4: معلم | JX4: مرشد تربوي | JZ4: المجموع | KC4: نوع البناء | KE4: عدد الطوابق | KH4: حجم المدرسة | KM4: عدد الغرف في البناية | KP4: العائدية | KS4: عدد المدارس التي تشغلها | KV4: الحالة العمرانية | KY4: مادة البناء | LZ4: هل يوجد مختبر | MB4: مختبر العلوم | MD4: مختبر الفيزياء | MF4: مختبر الكيمياء | MH4: مختبر الاحياء | MJ4: مجمع مختبرات | ML4: مختبرلغة | MN4: مختبر حاسوب
A5: القضاء | B5: الناحية | C5: ت | D5: الرقم الاحصائي | E5: اسم المدرسة | F5: اساسي | G5: تكميلي | H5: بنون | I5: بنات | J5: مختلط | K5: حضر | L5: ريف | M5: صباحا | N5: ظهرا | O5: صباحا وظهرا | P5: اصلية | Q5: ضيف | R5: غير مزدوجة | S5: مع نفسها | T5: مع اخرى | U5: مع نفسها ومع اخرى | V5: نعم | W5: كلا | X5: بنون | Y5: بنات | Z5: بنون | AA5: بنات | AB5: بنون | AC5: بنات | AD5: بنون | AE5: بنات | AF5: بنون | AG5: بنات | AH5: بنون | AI5: بنات | AJ5: بنون | AK5: بنات | AL5: المجموع | AM5: بنون | AN5: بنات | AO5: بنون | AP5: بنات | AQ5: بنون | AR5: بنات | AS5: بنون | AT5: بنات | AU5: بنون | AV5: بنات | AW5: بنون | AX5: بنات | AY5: المجموع | AZ5: بنون | BA5: بنات | BB5: بنون | BC5: بنات | BD5: بنون | BE5: بنات | BF5: بنون | BG5: بنات | BH5: بنون | BI5: بنات | BJ5: بنون | BK5: بنات | BL5: بنون | BM5: بنات | BN5: المجموع | BO5: بنون | BP5: بنات | BQ5: بنون | BR5: بنات | BS5: بنون | BT5: بنات | BU5: بنون | BV5: بنات | BW5: بنون | BX5: بنات | BY5: بنون | BZ5: بنات | CA5: المجموع | CB5: بنون | CC5: بنات | CD5: بنون | CE5: بنات | CF5: بنون | CG5: بنات | CH5: بنون | CI5: بنات | CJ5: بنون | CK5: بنات | CL5: بنون | CM5: بنات | CN5: المجموع | CO5: بنون | CP5: بنات | CQ5: بنون | CR5: بنات | CS5: بنون | CT5: بنات | CU5: بنون | CV5: بنات | CW5: بنون | CX5: بنات | CY5: بنون | CZ5: بنات | DA5: المجموع | DB5: بنون | DC5: بنات | DD5: بنون | DE5: بنات | DF5: بنون | DG5: بنات | DH5: بنون | DI5: بنات | DJ5: بنون | DK5: بنات | DL5: بنون | DM5: بنات | DN5: المجموع | DO5: بنون | DP5: بنات | DQ5: بنون | DR5: بنات | DS5: بنون | DT5: بنات | DU5: بنون | DV5: بنات | DW5: بنون | DX5: بنات | DY5: بنون | DZ5: بنات | EA5: المجموع | EB5: بنون | EC5: بنات | ED5: بنون | EE5: بنات | EF5: بنون | EG5: بنات | EH5: بنون | EI5: بنات | EJ5: بنون | EK5: بنات | EL5: بنون | EM5: بنات | EN5: بنون | EO5: بنات | EP5: بنون | EQ5: بنات | ER5: بنون | ES5: بنات | ET5: بنون | EU5: بنات | EV5: بنون | EW5: بنات | EX5: بنون | EY5: بنات | EZ5: المجموع | FA5: بنون | FB5: بنات | FC5: بنون | FD5: بنات | FE5: بنون | FF5: بنات | FG5: بنون | FH5: بنات | FI5: بنون | FJ5: بنات | FK5: بنون | FL5: بنات | FM5: المجموع | FN5: بنون | FO5: بنات | FP5: بنون | FQ5: بنات | FR5: بنون | FS5: بنات | FT5: بنون | FU5: بنات | FV5: بنون | FW5: بنات | FX5: بنون | FY5: بنات | FZ5: المجموع | GA5: بنون | GB5: بنات | GC5: بنون | GD5: بنات | GE5: بنون | GF5: بنات | GG5: بنون | GH5: بنات | GI5: بنون | GJ5: بنات | GK5: بنون | GL5: بنات | GM5: المجموع | GN5: بنون | GO5: بنات | GP5: بنون | GQ5: بنات | GR5: بنون | GS5: بنات | GT5: بنون | GU5: بنات | GV5: بنون | GW5: بنات | GX5: بنون | GY5: بنات | GZ5: بنون | HA5: بنات | HB5: بنون | HC5: بنات | HD5: المجموع | HE5: بنون | HF5: بنات | HG5: مختلط | HH5: بنون | HI5: بنات | HJ5: مختلط | HK5: بنون | HL5: بنات | HM5: مختلط | HN5: بنون | HO5: بنات | HP5: مختلط | HQ5: بنون | HR5: بنات | HS5: مختلط | HT5: بنون | HU5: بنات | HV5: مختلط | HW5: بنون | HX5: بنات | HY5: مختلط | HZ5: المجموع | IA5: بنون | IB5: بنات | IC5: مختلط | ID5: بنون | IE5: بنات | IF5: مختلط | IG5: بنون | IH5: بنات | II5: مختلط | IJ5: بنون | IK5: بنات | IL5: مختلط | IM5: المجموع | IN5: بنون | IO5: بنات | IP5: مختلط | IQ5: المجموع | IR5: ذكور | IS5: اناث | IT5: ذكور | IU5: اناث | IV5: ذكور | IW5: اناث | IX5: ذكور | IY5: اناث | IZ5: ذكور | JA5: اناث | JB5: المجموع | JC5: ذكور | JD5: اناث | JE5: ذكور | JF5: اناث | JG5: ذكور | JH5: اناث | JI5: ذكور | JJ5: اناث | JK5: ذكور | JL5: اناث | JM5: ذكور | JN5: اناث | JO5: المجموع | JP5: ذكور | JQ5: اناث | JR5: ذكور | JS5: اناث | JT5: ذكور | JU5: اناث | JV5: ذكور | JW5: اناث | JX5: ذكور | JY5: اناث | JZ5: ذكور | KA5: اناث | KB5: المجموع | KC5: مدرسي | KD5: غير مدرسي | KE5: طابق واحد | KF5: طابقين | KG5: ثلاث طوابق | KH5: 6صف | KI5: 9صف | KJ5: 12صف | KK5: 18صف | KL5: 24صف | KM5: عدد الصفوف | KN5: عدد الغرف الاخرى | KO5: المجموع | KP5: حكومية تابعة لوزارة التربية | KQ5: حكومية تابعة لجهات اخرى | KR5: مستأجرة | KS5: مدرسة واحدة | KT5: مدرستان | KU5: ثلاث مدارس | KV5: صالحة | KW5: بحاجة الى ترميم | KX5: غير صالحة | KY5: طابوق او حجر او بلوك | KZ5: طين اوصريفة | LA5: هياكل حديدية | LB5: كرفان | LC5: بناء جاهز | LD5: اخرى | LE5: نعم | LF5: كلا | LG5: نعم | LH5: كلا | LI5: نعم | LJ5: كلا | LK5: نعم | LL5: كلا | LM5: نعم | LN5: كلا | LO5: مدير | LP5: معاون | LQ5: معلم او مدرس | LR5: امين مكتبة | LS5: موظف ادارة | LT5: غرفة مستقلة | LU5: خزانة | LV5: رفوف | LW5: عدد الكتب | LX5: عدد القصص والمجلات | LZ5: نعم | MA5: كلا | MB5: نعم | MC5: كلا | MD5: نعم | ME5: كلا | MF5: نعم | MG5: كلا | MH5: نعم | MI5: كلا | MJ5: نعم | MK5: كلا | ML5: نعم | MM5: كلا | MN5: نعم | MO5: كلا
A6: النجف | B6: المركز | C6: 1 | D6: 1400186 | E6: السدير الأساسية | F6: 1 | H6: 1 | K6: 1 | M6: 1 | P6: 1 | R6: 1 | W6: 1 | X6: 3 | Z6: 40 | AB6: 4 | AD6: 1 | AJ6: =AH6+AF6+AD6+AB6+Z6+X6 -> 48 | AK6: =AI6+AG6+AE6+AC6+AA6+Y6 -> 0 | AL6: =SUM(AJ6:AK6) -> 48 | AW6: =AU6+AS6+AQ6+AO6+AM6 -> 0 | AX6: =AV6+AT6+AR6+AP6+AN6 -> 0 | AY6: =SUM(AW6:AX6) -> 0 | AZ6: 3 | BB6: 40 | BD6: 5 | BF6: 2 | BH6: 1 | BL6: =BJ6+BH6+BF6+BD6+BB6+AZ6 -> 51 | BM6: =BK6+BI6+BG6+BE6+BC6+BA6 -> 0 | BN6: =SUM(BL6:BM6) -> 51 | BO6: 18 | BQ6: 7 | BS6: 2 | BY6: =BW6+BU6+BS6+BQ6+BO6 -> 27 | BZ6: =BX6+BV6+BT6+BR6+BP6 -> 0 | CA6: =SUM(BY6:BZ6) -> 27 | CB6: 20 | CD6: 6 | CF6: 3 | CH6: 1 | CJ6: 1 | CL6: =CJ6+CH6+CF6+CD6+CB6 -> 31 | CM6: =CK6+CI6+CG6+CE6+CC6 -> 0 | CN6: =SUM(CL6:CM6) -> 31 | CO6: 26 | CQ6: 6 | CS6: 3 | CU6: 4 | CW6: 1 | CY6: =CW6+CU6+CS6+CQ6+CO6 -> 40 | CZ6: =CX6+CV6+CT6+CR6+CP6 -> 0 | DA6: =SUM(CY6:CZ6) -> 40 | DB6: 35 | DD6: 13 | DF6: 8 | DH6: 3 | DL6: =DJ6+DH6+DF6+DD6+DB6 -> 59 | DM6: =DK6+DI6+DG6+DE6+DC6 -> 0 | DN6: =SUM(DL6:DM6) -> 59 | DO6: 30 | DQ6: 17 | DS6: 5 | DU6: 1 | DW6: 2 | DY6: =DW6+DU6+DS6+DQ6+DO6 -> 55 | DZ6: =DX6+DV6+DT6+DR6+DP6 -> 0 | EA6: =SUM(DY6:DZ6) -> 55 | EB6: =AZ6 -> 3 | EC6: =BA6 -> 0 | ED6: =BB6 -> 40 | EE6: =BC6 -> 0 | EF6: =BO6+BD6 -> 23 | EG6: =BP6+BE6 -> 0 | EH6: =CB6+BQ6+BF6 -> 29 | EI6: =CC6+BR6+BG6 -> 0 | EJ6: =CO6+CD6+BS6+BH6 -> 35 | EK6: =CP6+CE6+BT6+BI6 -> 0 | EL6: =DB6+CQ6+CF6+BU6+BJ6 -> 44 | EM6: =DC6+CR6+CG6+BV6+BK6 -> 0 | EN6: =DO6+DD6+CS6+CH6+BW6 -> 47 | EO6: =DP6+DE6+CT6+CI6+BX6 -> 0 | EP6: =DQ6+DF6+CU6+CJ6 -> 30 | EQ6: =DR6+DG6+CV6+CK6 -> 0 | ER6: =DS6+DH6+CW6 -> 9 | ES6: =DT6+DI6+CX6 -> 0 | ET6: =DU6+DJ6 -> 1 | EU6: =DV6+DK6 -> 0 | EV6: =DW6 -> 2 | EW6: =DX6 -> 0 | EX6: =EV6+ET6+ER6+EP6+EN6+EL6+EJ6+EH6+EF6+ED6+EB6 -> 263 | EY6: =EW6+EU6+ES6+EQ6+EO6+EM6+EK6+EI6+EG6+EE6+EC6 -> 0 | EZ6: =SUM(EX6:EY6) -> 263 | FK6: =FI6+FG6+FE6+FC6+FA6 -> 0 | FL6: =FJ6+FH6+FF6+FD6+FB6 -> 0 | FM6: =SUM(FK6:FL6) -> 0 | FX6: =FV6+FT6+FR6+FP6+FN6 -> 0 | FY6: =FW6+FU6+FS6+FQ6+FO6 -> 0 | FZ6: =SUM(FX6:FY6) -> 0 | GK6: =GI6+GG6+GE6+GC6+GA6 -> 0 | GL6: =GJ6+GH6+GF6+GD6+GB6 -> 0 | GM6: =SUM(GK6:GL6) -> 0 | GN6: =FA6 -> 0 | GO6: =FB6 -> 0 | GP6: =FN6+FC6 -> 0 | GQ6: =FO6+FD6 -> 0 | GR6: =GA6+FP6+FE6 -> 0 | GS6: =GB6+FQ6+FF6 -> 0 | GT6: =GC6+FR6+FG6 -> 0 | GU6: =GD6+FS6+FH6 -> 0 | GV6: =GE6+FT6+FI6 -> 0 | GW6: =GF6+FU6+FJ6 -> 0 | GX6: =GG6+FV6 -> 0 | GY6: =GH6+FW6 -> 0 | GZ6: =GI6 -> 0 | HA6: =GJ6 -> 0 | HB6: =GZ6+GX6+GV6+GT6+GR6+GP6+GN6 -> 0 | HC6: =HA6+GY6+GW6+GU6+GS6+GQ6+GO6 -> 0 | HD6: =SUM(HB6:HC6) -> 0 | HE6: 2 | HH6: 1 | HK6: 1 | HN6: 1 | HQ6: 2 | HT6: 2 | HW6: =HT6+HQ6+HN6+HK6+HH6+HE6 -> 9 | HX6: =HU6+HR6+HO6+HL6+HI6+HF6 -> 0 | HY6: =HV6+HS6+HP6+HM6+HJ6+HG6 -> 0 | HZ6: =SUM(HW6:HY6) -> 9 | IJ6: =IG6+ID6+IA6 -> 0 | IK6: =IH6+IE6+IB6 -> 0 | IL6: =II6+IF6+IC6 -> 0 | IM6: =SUM(IJ6:IL6) -> 0 | IN6: =IJ6+HW6 -> 9 | IO6: =IK6+HX6 -> 0 | IP6: =IL6+HY6 -> 0 | IQ6: =IM6+HZ6 -> 9 | IR6: 1 | IU6: 1 | IV6: 7 | IW6: 16 | IZ6: =IX6+IV6+IT6+IR6 -> 8 | JA6: =IY6+IW6+IU6+IS6 -> 17 | JB6: =SUM(IZ6:JA6) -> 25 | JM6: =JK6+JG6+JE6+JC6 -> 0 | JN6: =JL6+JH6+JF6+JD6 -> 0 | JO6: =SUM(JM6:JN6) -> 0 | JP6: =JC6+IR6 -> 1 | JQ6: =JD6+IS6 -> 0 | JR6: =JE6+IT6 -> 0 | JS6: =JF6+IU6 -> 1 | JT6: =JG6 -> 0 | JU6: =JH6 -> 0 | JV6: =IV6+JI6 -> 7 | JW6: =IW6+JJ6 -> 16 | JX6: =JK6+IX6 -> 0 | JY6: =JL6+IY6 -> 0 | JZ6: =JX6+JV6+JT6+JR6+JP6 -> 8 | KA6: =JY6+JW6+JU6+JS6+JQ6 -> 17 | KB6: =SUM(JZ6:KA6) -> 25 | KC6: 1 | KF6: 1 | KK6: 1 | KM6: 18 | KN6: 6 | KO6: =SUM(KM6:KN6) -> 24 | KQ6: 1 | KS6: 1 | KV6: 1 | KY6: 1 | LE6: 1 | LG6: 1 | LI6: 1 | LK6: 1 | LM6: 1 | LQ6: 1 | LT6: 1 | LW6: 25 | LX6: 100 | LY6: =SUM(LW6:LX6) -> 125 | MA6: 1
A7: النجف | B7: المركز | C7: 2 | D7: 1400193 | E7: دمشق الأساسية | F7: 1 | H7: 1 | K7: 1 | M7: 1 | P7: 1 | T7: 1 | W7: 1 | Z7: 35 | AB7: 2 | AD7: 1 | AJ7: =AH7+AF7+AD7+AB7+Z7+X7 -> 38 | AK7: =AI7+AG7+AE7+AC7+AA7+Y7 -> 0 | AL7: =SUM(AJ7:AK7) -> 38 | AW7: =AU7+AS7+AQ7+AO7+AM7 -> 0 | AX7: =AV7+AT7+AR7+AP7+AN7 -> 0 | AY7: =SUM(AW7:AX7) -> 0 | BB7: 35 | BD7: 6 | BF7: 2 | BH7: 4 | BL7: =BJ7+BH7+BF7+BD7+BB7+AZ7 -> 47 | BM7: =BK7+BI7+BG7+BE7+BC7+BA7 -> 0 | BN7: =SUM(BL7:BM7) -> 47 | BO7: 47 | BQ7: 5 | BS7: 1 | BU7: 1 | BY7: =BW7+BU7+BS7+BQ7+BO7 -> 54 | BZ7: =BX7+BV7+BT7+BR7+BP7 -> 0 | CA7: =SUM(BY7:BZ7) -> 54 | CB7: 44 | CD7: 10 | CF7: 2 | CL7: =CJ7+CH7+CF7+CD7+CB7 -> 56 | CM7: =CK7+CI7+CG7+CE7+CC7 -> 0 | CN7: =SUM(CL7:CM7) -> 56 | CO7: 32 | CQ7: 7 | CS7: 3 | CU7: 2 | CY7: =CW7+CU7+CS7+CQ7+CO7 -> 44 | CZ7: =CX7+CV7+CT7+CR7+CP7 -> 0 | DA7: =SUM(CY7:CZ7) -> 44 | DB7: 40 | DD7: 13 | DF7: 4 | DH7: 3 | DJ7: 1 | DL7: =DJ7+DH7+DF7+DD7+DB7 -> 61 | DM7: =DK7+DI7+DG7+DE7+DC7 -> 0 | DN7: =SUM(DL7:DM7) -> 61 | DO7: 35 | DQ7: 5 | DU7: 1 | DY7: =DW7+DU7+DS7+DQ7+DO7 -> 41 | DZ7: =DX7+DV7+DT7+DR7+DP7 -> 0 | EA7: =SUM(DY7:DZ7) -> 41 | EB7: =AZ7 -> 0 | EC7: =BA7 -> 0 | ED7: =BB7 -> 35 | EE7: =BC7 -> 0 | EF7: =BO7+BD7 -> 53 | EG7: =BP7+BE7 -> 0 | EH7: =CB7+BQ7+BF7 -> 51 | EI7: =CC7+BR7+BG7 -> 0 | EJ7: =CO7+CD7+BS7+BH7 -> 47 | EK7: =CP7+CE7+BT7+BI7 -> 0 | EL7: =DB7+CQ7+CF7+BU7+BJ7 -> 50 | EM7: =DC7+CR7+CG7+BV7+BK7 -> 0 | EN7: =DO7+DD7+CS7+CH7+BW7 -> 51 | EO7: =DP7+DE7+CT7+CI7+BX7 -> 0 | EP7: =DQ7+DF7+CU7+CJ7 -> 11 | EQ7: =DR7+DG7+CV7+CK7 -> 0 | ER7: =DS7+DH7+CW7 -> 3 | ES7: =DT7+DI7+CX7 -> 0 | ET7: =DU7+DJ7 -> 2 | EU7: =DV7+DK7 -> 0 | EV7: =DW7 -> 0 | EW7: =DX7 -> 0 | EX7: =EV7+ET7+ER7+EP7+EN7+EL7+EJ7+EH7+EF7+ED7+EB7 -> 303 | EY7: =EW7+EU7+ES7+EQ7+EO7+EM7+EK7+EI7+EG7+EE7+EC7 -> 0 | EZ7: =SUM(EX7:EY7) -> 303 | FK7: =FI7+FG7+FE7+FC7+FA7 -> 0 | FL7: =FJ7+FH7+FF7+FD7+FB7 -> 0 | FM7: =SUM(FK7:FL7) -> 0 | FX7: =FV7+FT7+FR7+FP7+FN7 -> 0 | FY7: =FW7+FU7+FS7+FQ7+FO7 -> 0 | FZ7: =SUM(FX7:FY7) -> 0 | GK7: =GI7+GG7+GE7+GC7+GA7 -> 0 | GL7: =GJ7+GH7+GF7+GD7+GB7 -> 0 | GM7: =SUM(GK7:GL7) -> 0 | GN7: =FA7 -> 0 | GO7: =FB7 -> 0 | GP7: =FN7+FC7 -> 0 | GQ7: =FO7+FD7 -> 0 | GR7: =GA7+FP7+FE7 -> 0 | GS7: =GB7+FQ7+FF7 -> 0 | GT7: =GC7+FR7+FG7 -> 0 | GU7: =GD7+FS7+FH7 -> 0 | GV7: =GE7+FT7+FI7 -> 0 | GW7: =GF7+FU7+FJ7 -> 0 | GX7: =GG7+FV7 -> 0 | GY7: =GH7+FW7 -> 0 | GZ7: =GI7 -> 0 | HA7: =GJ7 -> 0 | HB7: =GZ7+GX7+GV7+GT7+GR7+GP7+GN7 -> 0 | HC7: =HA7+GY7+GW7+GU7+GS7+GQ7+GO7 -> 0 | HD7: =SUM(HB7:HC7) -> 0 | HE7: 2 | HH7: 2 | HK7: 2 | HN7: 2 | HQ7: 2 | HT7: 2 | HW7: =HT7+HQ7+HN7+HK7+HH7+HE7 -> 12 | HX7: =HU7+HR7+HO7+HL7+HI7+HF7 -> 0 | HY7: =HV7+HS7+HP7+HM7+HJ7+HG7 -> 0 | HZ7: =SUM(HW7:HY7) -> 12 | IJ7: =IG7+ID7+IA7 -> 0 | IK7: =IH7+IE7+IB7 -> 0 | IL7: =II7+IF7+IC7 -> 0 | IM7: =SUM(IJ7:IL7) -> 0 | IN7: =IJ7+HW7 -> 12 | IO7: =IK7+HX7 -> 0 | IP7: =IL7+HY7 -> 0 | IQ7: =IM7+HZ7 -> 12 | IR7: 1 | IT7: 1 | IU7: 1 | IV7: 5 | IW7: 7 | IY7: 1 | IZ7: =IX7+IV7+IT7+IR7 -> 7 | JA7: =IY7+IW7+IU7+IS7 -> 9 | JB7: =SUM(IZ7:JA7) -> 16 | JM7: =JK7+JG7+JE7+JC7 -> 0 | JN7: =JL7+JH7+JF7+JD7 -> 0 | JO7: =SUM(JM7:JN7) -> 0 | JP7: =JC7+IR7 -> 1 | JQ7: =JD7+IS7 -> 0 | JR7: =JE7+IT7 -> 1 | JS7: =JF7+IU7 -> 1 | JT7: =JG7 -> 0 | JU7: =JH7 -> 0 | JV7: =IV7+JI7 -> 5 | JW7: =IW7+JJ7 -> 7 | JX7: =JK7+IX7 -> 0 | JY7: =JL7+IY7 -> 1 | JZ7: =JX7+JV7+JT7+JR7+JP7 -> 7 | KA7: =JY7+JW7+JU7+JS7+JQ7 -> 9 | KB7: =SUM(JZ7:KA7) -> 16 | KC7: 1 | KF7: 1 | KJ7: 1 | KM7: 12 | KN7: 7 | KO7: =SUM(KM7:KN7) -> 19 | KQ7: 1 | KT7: 1 | KV7: 1 | KY7: 1 | LE7: 1 | LG7: 1 | LI7: 1 | LK7: 1 | LN7: 1 | LY7: =SUM(LW7:LX7) -> 0 | MA7: 1
A8: النجف | B8: المركز | C8: 3 | D8: 1400197 | E8: بغداد الأساسية | F8: 1 | H8: 1 | K8: 1 | M8: 1 | P8: 1 | R8: 1 | W8: 1 | AJ8: =AH8+AF8+AD8+AB8+Z8+X8 -> 0 | AK8: =AI8+AG8+AE8+AC8+AA8+Y8 -> 0 | AL8: =SUM(AJ8:AK8) -> 0 | AW8: =AU8+AS8+AQ8+AO8+AM8 -> 0 | AX8: =AV8+AT8+AR8+AP8+AN8 -> 0 | AY8: =SUM(AW8:AX8) -> 0 | BL8: =BJ8+BH8+BF8+BD8+BB8+AZ8 -> 0 | BM8: =BK8+BI8+BG8+BE8+BC8+BA8 -> 0 | BN8: =SUM(BL8:BM8) -> 0 | BY8: =BW8+BU8+BS8+BQ8+BO8 -> 0 | BZ8: =BX8+BV8+BT8+BR8+BP8 -> 0 | CA8: =SUM(BY8:BZ8) -> 0 | CL8: =CJ8+CH8+CF8+CD8+CB8 -> 0 | CM8: =CK8+CI8+CG8+CE8+CC8 -> 0 | CN8: =SUM(CL8:CM8) -> 0 | CY8: =CW8+CU8+CS8+CQ8+CO8 -> 0 | CZ8: =CX8+CV8+CT8+CR8+CP8 -> 0 | DA8: =SUM(CY8:CZ8) -> 0 | DL8: =DJ8+DH8+DF8+DD8+DB8 -> 0 | DM8: =DK8+DI8+DG8+DE8+DC8 -> 0 | DN8: =SUM(DL8:DM8) -> 0 | DY8: =DW8+DU8+DS8+DQ8+DO8 -> 0 | DZ8: =DX8+DV8+DT8+DR8+DP8 -> 0 | EA8: =SUM(DY8:DZ8) -> 0 | EB8: =AZ8 -> 0 | EC8: =BA8 -> 0 | ED8: =BB8 -> 0 | EE8: =BC8 -> 0 | EF8: =BO8+BD8 -> 0 | EG8: =BP8+BE8 -> 0 | EH8: =CB8+BQ8+BF8 -> 0 | EI8: =CC8+BR8+BG8 -> 0 | EJ8: =CO8+CD8+BS8+BH8 -> 0 | EK8: =CP8+CE8+BT8+BI8 -> 0 | EL8: =DB8+CQ8+CF8+BU8+BJ8 -> 0 | EM8: =DC8+CR8+CG8+BV8+BK8 -> 0 | EN8: =DO8+DD8+CS8+CH8+BW8 -> 0 | EO8: =DP8+DE8+CT8+CI8+BX8 -> 0 | EP8: =DQ8+DF8+CU8+CJ8 -> 0 | EQ8: =DR8+DG8+CV8+CK8 -> 0 | ER8: =DS8+DH8+CW8 -> 0 | ES8: =DT8+DI8+CX8 -> 0 | ET8: =DU8+DJ8 -> 0 | EU8: =DV8+DK8 -> 0 | EV8: =DW8 -> 0 | EW8: =DX8 -> 0 | EX8: =EV8+ET8+ER8+EP8+EN8+EL8+EJ8+EH8+EF8+ED8+EB8 -> 0 | EY8: =EW8+EU8+ES8+EQ8+EO8+EM8+EK8+EI8+EG8+EE8+EC8 -> 0 | EZ8: =SUM(EX8:EY8) -> 0 | FK8: =FI8+FG8+FE8+FC8+FA8 -> 0 | FL8: =FJ8+FH8+FF8+FD8+FB8 -> 0 | FM8: =SUM(FK8:FL8) -> 0 | FX8: =FV8+FT8+FR8+FP8+FN8 -> 0 | FY8: =FW8+FU8+FS8+FQ8+FO8 -> 0 | FZ8: =SUM(FX8:FY8) -> 0 | GK8: =GI8+GG8+GE8+GC8+GA8 -> 0 | GL8: =GJ8+GH8+GF8+GD8+GB8 -> 0 | GM8: =SUM(GK8:GL8) -> 0 | GN8: =FA8 -> 0 | GO8: =FB8 -> 0 | GP8: =FN8+FC8 -> 0 | GQ8: =FO8+FD8 -> 0 | GR8: =GA8+FP8+FE8 -> 0 | GS8: =GB8+FQ8+FF8 -> 0 | GT8: =GC8+FR8+FG8 -> 0 | GU8: =GD8+FS8+FH8 -> 0 | GV8: =GE8+FT8+FI8 -> 0 | GW8: =GF8+FU8+FJ8 -> 0 | GX8: =GG8+FV8 -> 0 | GY8: =GH8+FW8 -> 0 | GZ8: =GI8 -> 0 | HA8: =GJ8 -> 0 | HB8: =GZ8+GX8+GV8+GT8+GR8+GP8+GN8 -> 0 | HC8: =HA8+GY8+GW8+GU8+GS8+GQ8+GO8 -> 0 | HD8: =SUM(HB8:HC8) -> 0 | HW8: =HT8+HQ8+HN8+HK8+HH8+HE8 -> 0 | HX8: =HU8+HR8+HO8+HL8+HI8+HF8 -> 0 | HY8: =HV8+HS8+HP8+HM8+HJ8+HG8 -> 0 | HZ8: =SUM(HW8:HY8) -> 0 | IJ8: =IG8+ID8+IA8 -> 0 | IK8: =IH8+IE8+IB8 -> 0 | IL8: =II8+IF8+IC8 -> 0 | IM8: =SUM(IJ8:IL8) -> 0 | IN8: =IJ8+HW8 -> 0 | IO8: =IK8+HX8 -> 0 | IP8: =IL8+HY8 -> 0 | IQ8: =IM8+HZ8 -> 0 | IR8: 1 | IZ8: =IX8+IV8+IT8+IR8 -> 1 | JA8: =IY8+IW8+IU8+IS8 -> 0 | JB8: =SUM(IZ8:JA8) -> 1 | JM8: =JK8+JG8+JE8+JC8 -> 0 | JN8: =JL8+JH8+JF8+JD8 -> 0 | JO8: =SUM(JM8:JN8) -> 0 | JP8: =JC8+IR8 -> 1 | JQ8: =JD8+IS8 -> 0 | JR8: =JE8+IT8 -> 0 | JS8: =JF8+IU8 -> 0 | JT8: =JG8 -> 0 | JU8: =JH8 -> 0 | JV8: =IV8+JI8 -> 0 | JW8: =IW8+JJ8 -> 0 | JX8: =JK8+IX8 -> 0 | JY8: =JL8+IY8 -> 0 | JZ8: =JX8+JV8+JT8+JR8+JP8 -> 1 | KA8: =JY8+JW8+JU8+JS8+JQ8 -> 0 | KB8: =SUM(JZ8:KA8) -> 1 | KC8: 1 | KE8: 1 | KJ8: 1 | KM8: 14 | KN8: 3 | KO8: =SUM(KM8:KN8) -> 17 | KQ8: 1 | KS8: 1 | KX8: 1 | KY8: 1 | LE8: 1 | LG8: 1 | LI8: 1 | LK8: 1 | LM8: 1 | LQ8: 1 | LV8: 1 | LW8: 30 | LX8: 300 | LY8: =SUM(LW8:LX8) -> 330 | MA8: 1
A9: النجف | B9: المركز | C9: 4 | D9: 1400201 | E9: الامام الهادي الأساسية | F9: 1 | H9: 1 | K9: 1 | M9: 1 | P9: 1 | R9: 1 | W9: 1 | X9: 5 | Z9: 61 | AB9: 5 | AJ9: =AH9+AF9+AD9+AB9+Z9+X9 -> 71 | AK9: =AI9+AG9+AE9+AC9+AA9+Y9 -> 0 | AL9: =SUM(AJ9:AK9) -> 71 | AW9: =AU9+AS9+AQ9+AO9+AM9 -> 0 | AX9: =AV9+AT9+AR9+AP9+AN9 -> 0 | AY9: =SUM(AW9:AX9) -> 0 | AZ9: 5 | BB9: 61 | BD9: 5 | BL9: =BJ9+BH9+BF9+BD9+BB9+AZ9 -> 71 | BM9: =BK9+BI9+BG9+BE9+BC9+BA9 -> 0 | BN9: =SUM(BL9:BM9) -> 71 | BO9: 50 | BQ9: 2 | BS9: 3 | BY9: =BW9+BU9+BS9+BQ9+BO9 -> 55 | BZ9: =BX9+BV9+BT9+BR9+BP9 -> 0 | CA9: =SUM(BY9:BZ9) -> 55 | CB9: 56 | CD9: 3 | CF9: 3 | CL9: =CJ9+CH9+CF9+CD9+CB9 -> 62 | CM9: =CK9+CI9+CG9+CE9+CC9 -> 0 | CN9: =SUM(CL9:CM9) -> 62 | CO9: 75 | CQ9: 2 | CS9: 3 | CU9: 3 | CY9: =CW9+CU9+CS9+CQ9+CO9 -> 83 | CZ9: =CX9+CV9+CT9+CR9+CP9 -> 0 | DA9: =SUM(CY9:CZ9) -> 83 | DB9: 50 | DD9: 4 | DF9: 1 | DH9: 2 | DJ9: 3 | DL9: =DJ9+DH9+DF9+DD9+DB9 -> 60 | DM9: =DK9+DI9+DG9+DE9+DC9 -> 0 | DN9: =SUM(DL9:DM9) -> 60 | DO9: 66 | DQ9: 4 | DS9: 2 | DU9: 1 | DW9: 2 | DY9: =DW9+DU9+DS9+DQ9+DO9 -> 75 | DZ9: =DX9+DV9+DT9+DR9+DP9 -> 0 | EA9: =SUM(DY9:DZ9) -> 75 | EB9: =AZ9 -> 5 | EC9: =BA9 -> 0 | ED9: =BB9 -> 61 | EE9: =BC9 -> 0 | EF9: =BO9+BD9 -> 55 | EG9: =BP9+BE9 -> 0 | EH9: =CB9+BQ9+BF9 -> 58 | EI9: =CC9+BR9+BG9 -> 0 | EJ9: =CO9+CD9+BS9+BH9 -> 81 | EK9: =CP9+CE9+BT9+BI9 -> 0 | EL9: =DB9+CQ9+CF9+BU9+BJ9 -> 55 | EM9: =DC9+CR9+CG9+BV9+BK9 -> 0 | EN9: =DO9+DD9+CS9+CH9+BW9 -> 73 | EO9: =DP9+DE9+CT9+CI9+BX9 -> 0 | EP9: =DQ9+DF9+CU9+CJ9 -> 8 | EQ9: =DR9+DG9+CV9+CK9 -> 0 | ER9: =DS9+DH9+CW9 -> 4 | ES9: =DT9+DI9+CX9 -> 0 | ET9: =DU9+DJ9 -> 4 | EU9: =DV9+DK9 -> 0 | EV9: =DW9 -> 2 | EW9: =DX9 -> 0 | EX9: =EV9+ET9+ER9+EP9+EN9+EL9+EJ9+EH9+EF9+ED9+EB9 -> 406 | EY9: =EW9+EU9+ES9+EQ9+EO9+EM9+EK9+EI9+EG9+EE9+EC9 -> 0 | EZ9: =SUM(EX9:EY9) -> 406 | FK9: =FI9+FG9+FE9+FC9+FA9 -> 0 | FL9: =FJ9+FH9+FF9+FD9+FB9 -> 0 | FM9: =SUM(FK9:FL9) -> 0 | FX9: =FV9+FT9+FR9+FP9+FN9 -> 0 | FY9: =FW9+FU9+FS9+FQ9+FO9 -> 0 | FZ9: =SUM(FX9:FY9) -> 0 | GK9: =GI9+GG9+GE9+GC9+GA9 -> 0 | GL9: =GJ9+GH9+GF9+GD9+GB9 -> 0 | GM9: =SUM(GK9:GL9) -> 0 | GN9: =FA9 -> 0 | GO9: =FB9 -> 0 | GP9: =FN9+FC9 -> 0 | GQ9: =FO9+FD9 -> 0 | GR9: =GA9+FP9+FE9 -> 0 | GS9: =GB9+FQ9+FF9 -> 0 | GT9: =GC9+FR9+FG9 -> 0 | GU9: =GD9+FS9+FH9 -> 0 | GV9: =GE9+FT9+FI9 -> 0 | GW9: =GF9+FU9+FJ9 -> 0 | GX9: =GG9+FV9 -> 0 | GY9: =GH9+FW9 -> 0 | GZ9: =GI9 -> 0 | HA9: =GJ9 -> 0 | HB9: =GZ9+GX9+GV9+GT9+GR9+GP9+GN9 -> 0 | HC9: =HA9+GY9+GW9+GU9+GS9+GQ9+GO9 -> 0 | HD9: =SUM(HB9:HC9) -> 0 | HE9: 2 | HH9: 2 | HK9: 2 | HN9: 2 | HQ9: 2 | HT9: 2 | HW9: =HT9+HQ9+HN9+HK9+HH9+HE9 -> 12 | HX9: =HU9+HR9+HO9+HL9+HI9+HF9 -> 0 | HY9: =HV9+HS9+HP9+HM9+HJ9+HG9 -> 0 | HZ9: =SUM(HW9:HY9) -> 12 | IJ9: =IG9+ID9+IA9 -> 0 | IK9: =IH9+IE9+IB9 -> 0 | IL9: =II9+IF9+IC9 -> 0 | IM9: =SUM(IJ9:IL9) -> 0 | IN9: =IJ9+HW9 -> 12 | IO9: =IK9+HX9 -> 0 | IP9: =IL9+HY9 -> 0 | IQ9: =IM9+HZ9 -> 12 | IR9: 1 | IT9: 1 | IU9: 1 | IV9: 5 | IW9: 17 | IZ9: =IX9+IV9+IT9+IR9 -> 7 | JA9: =IY9+IW9+IU9+IS9 -> 18 | JB9: =SUM(IZ9:JA9) -> 25 | JM9: =JK9+JG9+JE9+JC9 -> 0 | JN9: =JL9+JH9+JF9+JD9 -> 0 | JO9: =SUM(JM9:JN9) -> 0 | JP9: =JC9+IR9 -> 1 | JQ9: =JD9+IS9 -> 0 | JR9: =JE9+IT9 -> 1 | JS9: =JF9+IU9 -> 1 | JT9: =JG9 -> 0 | JU9: =JH9 -> 0 | JV9: =IV9+JI9 -> 5 | JW9: =IW9+JJ9 -> 17 | JX9: =JK9+IX9 -> 0 | JY9: =JL9+IY9 -> 0 | JZ9: =JX9+JV9+JT9+JR9+JP9 -> 7 | KA9: =JY9+JW9+JU9+JS9+JQ9 -> 18 | KB9: =SUM(JZ9:KA9) -> 25 | KC9: 1 | KF9: 1 | KJ9: 1 | KM9: 12 | KN9: 6 | KO9: =SUM(KM9:KN9) -> 18 | KQ9: 1 | KS9: 1 | KW9: 1 | KY9: 1 | LE9: 1 | LG9: 1 | LI9: 1 | LK9: 1 | LM9: 1 | LQ9: 1 | LT9: 1 | LW9: 500 | LX9: 148 | LY9: =SUM(LW9:LX9) -> 648 | MA9: 1
A10: النجف | B10: المركز | C10: 5 | D10: 1400225 | E10: بلقيس الأساسية | F10: 1 | I10: 1 | K10: 1 | M10: 1 | P10: 1 | T10: 1 | W10: 1 | Y10: 2 | AA10: 36 | AC10: 1 | AJ10: =AH10+AF10+AD10+AB10+Z10+X10 -> 0 | AK10: =AI10+AG10+AE10+AC10+AA10+Y10 -> 39 | AL10: =SUM(AJ10:AK10) -> 39 | AW10: =AU10+AS10+AQ10+AO10+AM10 -> 0 | AX10: =AV10+AT10+AR10+AP10+AN10 -> 0 | AY10: =SUM(AW10:AX10) -> 0 | BA10: 2 | BC10: 36 | BE10: 1 | BL10: =BJ10+BH10+BF10+BD10+BB10+AZ10 -> 0 | BM10: =BK10+BI10+BG10+BE10+BC10+BA10 -> 39 | BN10: =SUM(BL10:BM10) -> 39 | BP10: 49 | BR10: 3 | BY10: =BW10+BU10+BS10+BQ10+BO10 -> 0 | BZ10: =BX10+BV10+BT10+BR10+BP10 -> 52 | CA10: =SUM(BY10:BZ10) -> 52 | CC10: 47 | CE10: 3 | CL10: =CJ10+CH10+CF10+CD10+CB10 -> 0 | CM10: =CK10+CI10+CG10+CE10+CC10 -> 50 | CN10: =SUM(CL10:CM10) -> 50 | CP10: 30 | CR10: 4 | CY10: =CW10+CU10+CS10+CQ10+CO10 -> 0 | CZ10: =CX10+CV10+CT10+CR10+CP10 -> 34 | DA10: =SUM(CY10:CZ10) -> 34 | DC10: 41 | DE10: 8 | DG10: 2 | DI10: 1 | DL10: =DJ10+DH10+DF10+DD10+DB10 -> 0 | DM10: =DK10+DI10+DG10+DE10+DC10 -> 52 | DN10: =SUM(DL10:DM10) -> 52 | DP10: 30 | DR10: 1 | DT10: 2 | DY10: =DW10+DU10+DS10+DQ10+DO10 -> 0 | DZ10: =DX10+DV10+DT10+DR10+DP10 -> 33 | EA10: =SUM(DY10:DZ10) -> 33 | EB10: =AZ10 -> 0 | EC10: =BA10 -> 2 | ED10: =BB10 -> 0 | EE10: =BC10 -> 36 | EF10: =BO10+BD10 -> 0 | EG10: =BP10+BE10 -> 50 | EH10: =CB10+BQ10+BF10 -> 0 | EI10: =CC10+BR10+BG10 -> 50 | EJ10: =CO10+CD10+BS10+BH10 -> 0 | EK10: =CP10+CE10+BT10+BI10 -> 33 | EL10: =DB10+CQ10+CF10+BU10+BJ10 -> 0 | EM10: =DC10+CR10+CG10+BV10+BK10 -> 45 | EN10: =DO10+DD10+CS10+CH10+BW10 -> 0 | EO10: =DP10+DE10+CT10+CI10+BX10 -> 38 | EP10: =DQ10+DF10+CU10+CJ10 -> 0 | EQ10: =DR10+DG10+CV10+CK10 -> 3 | ER10: =DS10+DH10+CW10 -> 0 | ES10: =DT10+DI10+CX10 -> 3 | ET10: =DU10+DJ10 -> 0 | EU10: =DV10+DK10 -> 0 | EV10: =DW10 -> 0 | EW10: =DX10 -> 0 | EX10: =EV10+ET10+ER10+EP10+EN10+EL10+EJ10+EH10+EF10+ED10+EB10 -> 0 | EY10: =EW10+EU10+ES10+EQ10+EO10+EM10+EK10+EI10+EG10+EE10+EC10 -> 260 | EZ10: =SUM(EX10:EY10) -> 260 | FK10: =FI10+FG10+FE10+FC10+FA10 -> 0 | FL10: =FJ10+FH10+FF10+FD10+FB10 -> 0 | FM10: =SUM(FK10:FL10) -> 0 | FX10: =FV10+FT10+FR10+FP10+FN10 -> 0 | FY10: =FW10+FU10+FS10+FQ10+FO10 -> 0 | FZ10: =SUM(FX10:FY10) -> 0 | GK10: =GI10+GG10+GE10+GC10+GA10 -> 0 | GL10: =GJ10+GH10+GF10+GD10+GB10 -> 0 | GM10: =SUM(GK10:GL10) -> 0 | GN10: =FA10 -> 0 | GO10: =FB10 -> 0 | GP10: =FN10+FC10 -> 0 | GQ10: =FO10+FD10 -> 0 | GR10: =GA10+FP10+FE10 -> 0 | GS10: =GB10+FQ10+FF10 -> 0 | GT10: =GC10+FR10+FG10 -> 0 | GU10: =GD10+FS10+FH10 -> 0 | GV10: =GE10+FT10+FI10 -> 0 | GW10: =GF10+FU10+FJ10 -> 0 | GX10: =GG10+FV10 -> 0 | GY10: =GH10+FW10 -> 0 | GZ10: =GI10 -> 0 | HA10: =GJ10 -> 0 | HB10: =GZ10+GX10+GV10+GT10+GR10+GP10+GN10 -> 0 | HC10: =HA10+GY10+GW10+GU10+GS10+GQ10+GO10 -> 0 | HD10: =SUM(HB10:HC10) -> 0 | HF10: 2 | HI10: 2 | HL10: 2 | HO10: 1 | HR10: 2 | HU10: 2 | HW10: =HT10+HQ10+HN10+HK10+HH10+HE10 -> 0 | HX10: =HU10+HR10+HO10+HL10+HI10+HF10 -> 11 | HY10: =HV10+HS10+HP10+HM10+HJ10+HG10 -> 0 | HZ10: =SUM(HW10:HY10) -> 11 | IJ10: =IG10+ID10+IA10 -> 0 | IK10: =IH10+IE10+IB10 -> 0 | IL10: =II10+IF10+IC10 -> 0 | IM10: =SUM(IJ10:IL10) -> 0 | IN10: =IJ10+HW10 -> 0 | IO10: =IK10+HX10 -> 11 | IP10: =IL10+HY10 -> 0 | IQ10: =IM10+HZ10 -> 11 | IS10: 1 | IU10: 1 | IW10: 12 | IZ10: =IX10+IV10+IT10+IR10 -> 0 | JA10: =IY10+IW10+IU10+IS10 -> 14 | JB10: =SUM(IZ10:JA10) -> 14 | JM10: =JK10+JG10+JE10+JC10 -> 0 | JN10: =JL10+JH10+JF10+JD10 -> 0 | JO10: =SUM(JM10:JN10) -> 0 | JP10: =JC10+IR10 -> 0 | JQ10: =JD10+IS10 -> 1 | JR10: =JE10+IT10 -> 0 | JS10: =JF10+IU10 -> 1 | JT10: =JG10 -> 0 | JU10: =JH10 -> 0 | JV10: =IV10+JI10 -> 0 | JW10: =IW10+JJ10 -> 12 | JX10: =JK10+IX10 -> 0 | JY10: =JL10+IY10 -> 0 | JZ10: =JX10+JV10+JT10+JR10+JP10 -> 0 | KA10: =JY10+JW10+JU10+JS10+JQ10 -> 14 | KB10: =SUM(JZ10:KA10) -> 14 | KC10: 1 | KF10: 1 | KL10: 1 | KM10: 24 | KN10: 8 | KO10: =SUM(KM10:KN10) -> 32 | KQ10: 1 | KT10: 1 | KV10: 1 | KY10: 1 | LE10: 1 | LG10: 1 | LI10: 1 | LK10: 1 | LM10: 1 | LQ10: 1 | LT10: 1 | LW10: 950 | LX10: 50 | LY10: =SUM(LW10:LX10) -> 1000 | MA10: 1
A11: النجف | B11: الشبكة | C11: 9 | D11: 1400336 | E11: الشبكة الاساسية | F11: 1 | J11: 1 | K11: 1 | M11: 1 | P11: 1 | R11: 1 | W11: 1 | AJ11: =AH11+AF11+AD11+AB11+Z11+X11 -> 0 | AK11: =AI11+AG11+AE11+AC11+AA11+Y11 -> 0 | AL11: =SUM(AJ11:AK11) -> 0 | AW11: =AU11+AS11+AQ11+AO11+AM11 -> 0 | AX11: =AV11+AT11+AR11+AP11+AN11 -> 0 | AY11: =SUM(AW11:AX11) -> 0 | BL11: =BJ11+BH11+BF11+BD11+BB11+AZ11 -> 0 | BM11: =BK11+BI11+BG11+BE11+BC11+BA11 -> 0 | BN11: =SUM(BL11:BM11) -> 0 | BY11: =BW11+BU11+BS11+BQ11+BO11 -> 0 | BZ11: =BX11+BV11+BT11+BR11+BP11 -> 0 | CA11: =SUM(BY11:BZ11) -> 0 | CL11: =CJ11+CH11+CF11+CD11+CB11 -> 0 | CM11: =CK11+CI11+CG11+CE11+CC11 -> 0 | CN11: =SUM(CL11:CM11) -> 0 | CY11: =CW11+CU11+CS11+CQ11+CO11 -> 0 | CZ11: =CX11+CV11+CT11+CR11+CP11 -> 0 | DA11: =SUM(CY11:CZ11) -> 0 | DL11: =DJ11+DH11+DF11+DD11+DB11 -> 0 | DM11: =DK11+DI11+DG11+DE11+DC11 -> 0 | DN11: =SUM(DL11:DM11) -> 0 | DY11: =DW11+DU11+DS11+DQ11+DO11 -> 0 | DZ11: =DX11+DV11+DT11+DR11+DP11 -> 0 | EA11: =SUM(DY11:DZ11) -> 0 | EB11: =AZ11 -> 0 | EC11: =BA11 -> 0 | ED11: =BB11 -> 0 | EE11: =BC11 -> 0 | EF11: =BO11+BD11 -> 0 | EG11: =BP11+BE11 -> 0 | EH11: =CB11+BQ11+BF11 -> 0 | EI11: =CC11+BR11+BG11 -> 0 | EJ11: =CO11+CD11+BS11+BH11 -> 0 | EK11: =CP11+CE11+BT11+BI11 -> 0 | EL11: =DB11+CQ11+CF11+BU11+BJ11 -> 0 | EM11: =DC11+CR11+CG11+BV11+BK11 -> 0 | EN11: =DO11+DD11+CS11+CH11+BW11 -> 0 | EO11: =DP11+DE11+CT11+CI11+BX11 -> 0 | EP11: =DQ11+DF11+CU11+CJ11 -> 0 | EQ11: =DR11+DG11+CV11+CK11 -> 0 | ER11: =DS11+DH11+CW11 -> 0 | ES11: =DT11+DI11+CX11 -> 0 | ET11: =DU11+DJ11 -> 0 | EU11: =DV11+DK11 -> 0 | EV11: =DW11 -> 0 | EW11: =DX11 -> 0 | EX11: =EV11+ET11+ER11+EP11+EN11+EL11+EJ11+EH11+EF11+ED11+EB11 -> 0 | EY11: =EW11+EU11+ES11+EQ11+EO11+EM11+EK11+EI11+EG11+EE11+EC11 -> 0 | EZ11: =SUM(EX11:EY11) -> 0 | FK11: =FI11+FG11+FE11+FC11+FA11 -> 0 | FL11: =FJ11+FH11+FF11+FD11+FB11 -> 0 | FM11: =SUM(FK11:FL11) -> 0 | FX11: =FV11+FT11+FR11+FP11+FN11 -> 0 | FY11: =FW11+FU11+FS11+FQ11+FO11 -> 0 | FZ11: =SUM(FX11:FY11) -> 0 | GK11: =GI11+GG11+GE11+GC11+GA11 -> 0 | GL11: =GJ11+GH11+GF11+GD11+GB11 -> 0 | GM11: =SUM(GK11:GL11) -> 0 | GN11: =FA11 -> 0 | GO11: =FB11 -> 0 | GP11: =FN11+FC11 -> 0 | GQ11: =FO11+FD11 -> 0 | GR11: =GA11+FP11+FE11 -> 0 | GS11: =GB11+FQ11+FF11 -> 0 | GT11: =GC11+FR11+FG11 -> 0 | GU11: =GD11+FS11+FH11 -> 0 | GV11: =GE11+FT11+FI11 -> 0 | GW11: =GF11+FU11+FJ11 -> 0 | GX11: =GG11+FV11 -> 0 | GY11: =GH11+FW11 -> 0 | GZ11: =GI11 -> 0 | HA11: =GJ11 -> 0 | HB11: =GZ11+GX11+GV11+GT11+GR11+GP11+GN11 -> 0 | HC11: =HA11+GY11+GW11+GU11+GS11+GQ11+GO11 -> 0 | HD11: =SUM(HB11:HC11) -> 0 | HW11: =HT11+HQ11+HN11+HK11+HH11+HE11 -> 0 | HX11: =HU11+HR11+HO11+HL11+HI11+HF11 -> 0 | HY11: =HV11+HS11+HP11+HM11+HJ11+HG11 -> 0 | HZ11: =SUM(HW11:HY11) -> 0 | IJ11: =IG11+ID11+IA11 -> 0 | IK11: =IH11+IE11+IB11 -> 0 | IL11: =II11+IF11+IC11 -> 0 | IM11: =SUM(IJ11:IL11) -> 0 | IN11: =IJ11+HW11 -> 0 | IO11: =IK11+HX11 -> 0 | IP11: =IL11+HY11 -> 0 | IQ11: =IM11+HZ11 -> 0 | IR11: 1 | IZ11: =IX11+IV11+IT11+IR11 -> 1 | JA11: =IY11+IW11+IU11+IS11 -> 0 | JB11: =SUM(IZ11:JA11) -> 1 | JM11: =JK11+JG11+JE11+JC11 -> 0 | JN11: =JL11+JH11+JF11+JD11 -> 0 | JO11: =SUM(JM11:JN11) -> 0 | JP11: =JC11+IR11 -> 1 | JQ11: =JD11+IS11 -> 0 | JR11: =JE11+IT11 -> 0 | JS11: =JF11+IU11 -> 0 | JT11: =JG11 -> 0 | JU11: =JH11 -> 0 | JV11: =IV11+JI11 -> 0 | JW11: =IW11+JJ11 -> 0 | JX11: =JK11+IX11 -> 0 | JY11: =JL11+IY11 -> 0 | JZ11: =JX11+JV11+JT11+JR11+JP11 -> 1 | KA11: =JY11+JW11+JU11+JS11+JQ11 -> 0 | KB11: =SUM(JZ11:KA11) -> 1 | KC11: 1 | KE11: 1 | KI11: 1 | KM11: 9 | KN11: 3 | KO11: =SUM(KM11:KN11) -> 12 | KQ11: 1 | KS11: 1 | KV11: 1 | KY11: 1 | LE11: 1 | LG11: 1 | LI11: 1 | LK11: 1 | LN11: 1 | LY11: =SUM(LW11:LX11) -> 0 | MA11: 1
C15: مجموع الابتدائي مركزالنجف | F15: =SUM(F6:F11) -> 6 | G15: =SUM(G6:G11) -> 0 | H15: =SUM(H6:H11) -> 4 | I15: =SUM(I6:I11) -> 1 | J15: =SUM(J6:J11) -> 1 | K15: =SUM(K6:K11) -> 6 | L15: =SUM(L6:L11) -> 0 | M15: =SUM(M6:M11) -> 6 | ... MO15: =SUM(MO6:MO11) -> 0
A16: النجف | B16: المركز | C16: 10 | D16: 1400003 | E16: م . السدير الأساسية | F16: 1 | H16: 1 | K16: 1 | M16: 1 | P16: 1 | R16: 1 | W16: 1 | AJ16: =AH16+AF16+AD16+AB16+Z16+X16 -> 0 | AK16: =AI16+AG16+AE16+AC16+AA16+Y16 -> 0 | AL16: =SUM(AJ16:AK16) -> 0 | AW16: =AU16+AS16+AQ16+AO16+AM16 -> 0 | AX16: =AV16+AT16+AR16+AP16+AN16 -> 0 | AY16: =SUM(AW16:AX16) -> 0 | BL16: =BJ16+BH16+BF16+BD16+BB16+AZ16 -> 0 | BM16: =BK16+BI16+BG16+BE16+BC16+BA16 -> 0 | BN16: =SUM(BL16:BM16) -> 0 | BY16: =BW16+BU16+BS16+BQ16+BO16 -> 0 | BZ16: =BX16+BV16+BT16+BR16+BP16 -> 0 | CA16: =SUM(BY16:BZ16) -> 0 | CL16: =CJ16+CH16+CF16+CD16+CB16 -> 0 | CM16: =CK16+CI16+CG16+CE16+CC16 -> 0 | CN16: =SUM(CL16:CM16) -> 0 | CY16: =CW16+CU16+CS16+CQ16+CO16 -> 0 | CZ16: =CX16+CV16+CT16+CR16+CP16 -> 0 | DA16: =SUM(CY16:CZ16) -> 0 | DL16: =DJ16+DH16+DF16+DD16+DB16 -> 0 | DM16: =DK16+DI16+DG16+DE16+DC16 -> 0 | DN16: =SUM(DL16:DM16) -> 0 | DY16: =DW16+DU16+DS16+DQ16+DO16 -> 0 | DZ16: =DX16+DV16+DT16+DR16+DP16 -> 0 | EA16: =SUM(DY16:DZ16) -> 0 | EB16: =AZ16 -> 0 | EC16: =BA16 -> 0 | ED16: =BB16 -> 0 | EE16: =BC16 -> 0 | EF16: =BO16+BD16 -> 0 | EG16: =BP16+BE16 -> 0 | EH16: =CB16+BQ16+BF16 -> 0 | EI16: =CC16+BR16+BG16 -> 0 | EJ16: =CO16+CD16+BS16+BH16 -> 0 | EK16: =CP16+CE16+BT16+BI16 -> 0 | EL16: =DB16+CQ16+CF16+BU16+BJ16 -> 0 | EM16: =DC16+CR16+CG16+BV16+BK16 -> 0 | EN16: =DO16+DD16+CS16+CH16+BW16 -> 0 | EO16: =DP16+DE16+CT16+CI16+BX16 -> 0 | EP16: =DQ16+DF16+CU16+CJ16 -> 0 | EQ16: =DR16+DG16+CV16+CK16 -> 0 | ER16: =DS16+DH16+CW16 -> 0 | ES16: =DT16+DI16+CX16 -> 0 | ET16: =DU16+DJ16 -> 0 | EU16: =DV16+DK16 -> 0 | EV16: =DW16 -> 0 | EW16: =DX16 -> 0 | EX16: =EV16+ET16+ER16+EP16+EN16+EL16+EJ16+EH16+EF16+ED16+EB16 -> 0 | EY16: =EW16+EU16+ES16+EQ16+EO16+EM16+EK16+EI16+EG16+EE16+EC16 -> 0 | EZ16: =SUM(EX16:EY16) -> 0 | FK16: =FI16+FG16+FE16+FC16+FA16 -> 0 | FL16: =FJ16+FH16+FF16+FD16+FB16 -> 0 | FM16: =SUM(FK16:FL16) -> 0 | FX16: =FV16+FT16+FR16+FP16+FN16 -> 0 | FY16: =FW16+FU16+FS16+FQ16+FO16 -> 0 | FZ16: =SUM(FX16:FY16) -> 0 | GK16: =GI16+GG16+GE16+GC16+GA16 -> 0 | GL16: =GJ16+GH16+GF16+GD16+GB16 -> 0 | GM16: =SUM(GK16:GL16) -> 0 | GN16: =FA16 -> 0 | GO16: =FB16 -> 0 | GP16: =FN16+FC16 -> 0 | GQ16: =FO16+FD16 -> 0 | GR16: =GA16+FP16+FE16 -> 0 | GS16: =GB16+FQ16+FF16 -> 0 | GT16: =GC16+FR16+FG16 -> 0 | GU16: =GD16+FS16+FH16 -> 0 | GV16: =GE16+FT16+FI16 -> 0 | GW16: =GF16+FU16+FJ16 -> 0 | GX16: =GG16+FV16 -> 0 | GY16: =GH16+FW16 -> 0 | GZ16: =GI16 -> 0 | HA16: =GJ16 -> 0 | HB16: =GZ16+GX16+GV16+GT16+GR16+GP16+GN16 -> 0 | HC16: =HA16+GY16+GW16+GU16+GS16+GQ16+GO16 -> 0 | HD16: =SUM(HB16:HC16) -> 0 | HW16: =HT16+HQ16+HN16+HK16+HH16+HE16 -> 0 | HX16: =HU16+HR16+HO16+HL16+HI16+HF16 -> 0 | HY16: =HV16+HS16+HP16+HM16+HJ16+HG16 -> 0 | HZ16: =SUM(HW16:HY16) -> 0 | IJ16: =IG16+ID16+IA16 -> 0 | IK16: =IH16+IE16+IB16 -> 0 | IL16: =II16+IF16+IC16 -> 0 | IM16: =SUM(IJ16:IL16) -> 0 | IN16: =IJ16+HW16 -> 0 | IO16: =IK16+HX16 -> 0 | IP16: =IL16+HY16 -> 0 | IQ16: =IM16+HZ16 -> 0 | IZ16: =IX16+IV16+IT16+IR16 -> 0 | JA16: =IY16+IW16+IU16+IS16 -> 0 | JB16: =SUM(IZ16:JA16) -> 0 | JC16: 1 | JM16: =JK16+JG16+JE16+JC16+JI16 -> 1 | JN16: =JL16+JH16+JF16+JD16+JJ16 -> 0 | JO16: =SUM(JM16:JN16) -> 1 | JP16: =JC16+IR16 -> 1 | JQ16: =JD16+IS16 -> 0 | JR16: =JE16+IT16 -> 0 | JS16: =JF16+IU16 -> 0 | JT16: =JG16 -> 0 | JU16: =JH16 -> 0 | JV16: =IV16+JI16 -> 0 | JW16: =IW16+JJ16 -> 0 | JX16: =JK16+IX16 -> 0 | JY16: =JL16+IY16 -> 0 | JZ16: =JX16+JV16+JT16+JR16+JP16 -> 1 | KA16: =JY16+JW16+JU16+JS16+JQ16 -> 0 | KB16: =SUM(JZ16:KA16) -> 1 | KC16: 1 | KF16: 1 | KJ16: 1 | KM16: 12 | KN16: 15 | KO16: =SUM(KM16:KN16) -> 27 | KQ16: 1 | KS16: 1 | KV16: 1 | KY16: 1 | LE16: 1 | LG16: 1 | LI16: 1 | LK16: 1 | LM16: 1 | LQ16: 1 | LT16: 1 | LW16: 1953 | LX16: 460 | LY16: =SUM(LW16:LX16) -> 2413 | LZ16: 1 | MC16: 1 | MD16: 1 | MF16: 1 | MH16: 1 | MK16: 1 | MM16: 1 | MN16: 1
A17: النجف | B17: المركز | C17: 11 | D17: 1400012 | E17: م . دمشق الأساسية | F17: 1 | H17: 1 | K17: 1 | M17: 1 | P17: 1 | R17: 1 | W17: 1 | AJ17: =AH17+AF17+AD17+AB17+Z17+X17 -> 0 | AK17: =AI17+AG17+AE17+AC17+AA17+Y17 -> 0 | AL17: =SUM(AJ17:AK17) -> 0 | AW17: =AU17+AS17+AQ17+AO17+AM17 -> 0 | AX17: =AV17+AT17+AR17+AP17+AN17 -> 0 | AY17: =SUM(AW17:AX17) -> 0 | BL17: =BJ17+BH17+BF17+BD17+BB17+AZ17 -> 0 | BM17: =BK17+BI17+BG17+BE17+BC17+BA17 -> 0 | BN17: =SUM(BL17:BM17) -> 0 | BY17: =BW17+BU17+BS17+BQ17+BO17 -> 0 | BZ17: =BX17+BV17+BT17+BR17+BP17 -> 0 | CA17: =SUM(BY17:BZ17) -> 0 | CL17: =CJ17+CH17+CF17+CD17+CB17 -> 0 | CM17: =CK17+CI17+CG17+CE17+CC17 -> 0 | CN17: =SUM(CL17:CM17) -> 0 | CY17: =CW17+CU17+CS17+CQ17+CO17 -> 0 | CZ17: =CX17+CV17+CT17+CR17+CP17 -> 0 | DA17: =SUM(CY17:CZ17) -> 0 | DL17: =DJ17+DH17+DF17+DD17+DB17 -> 0 | DM17: =DK17+DI17+DG17+DE17+DC17 -> 0 | DN17: =SUM(DL17:DM17) -> 0 | DY17: =DW17+DU17+DS17+DQ17+DO17 -> 0 | DZ17: =DX17+DV17+DT17+DR17+DP17 -> 0 | EA17: =SUM(DY17:DZ17) -> 0 | EB17: =AZ17 -> 0 | EC17: =BA17 -> 0 | ED17: =BB17 -> 0 | EE17: =BC17 -> 0 | EF17: =BO17+BD17 -> 0 | EG17: =BP17+BE17 -> 0 | EH17: =CB17+BQ17+BF17 -> 0 | EI17: =CC17+BR17+BG17 -> 0 | EJ17: =CO17+CD17+BS17+BH17 -> 0 | EK17: =CP17+CE17+BT17+BI17 -> 0 | EL17: =DB17+CQ17+CF17+BU17+BJ17 -> 0 | EM17: =DC17+CR17+CG17+BV17+BK17 -> 0 | EN17: =DO17+DD17+CS17+CH17+BW17 -> 0 | EO17: =DP17+DE17+CT17+CI17+BX17 -> 0 | EP17: =DQ17+DF17+CU17+CJ17 -> 0 | EQ17: =DR17+DG17+CV17+CK17 -> 0 | ER17: =DS17+DH17+CW17 -> 0 | ES17: =DT17+DI17+CX17 -> 0 | ET17: =DU17+DJ17 -> 0 | EU17: =DV17+DK17 -> 0 | EV17: =DW17 -> 0 | EW17: =DX17 -> 0 | EX17: =EV17+ET17+ER17+EP17+EN17+EL17+EJ17+EH17+EF17+ED17+EB17 -> 0 | EY17: =EW17+EU17+ES17+EQ17+EO17+EM17+EK17+EI17+EG17+EE17+EC17 -> 0 | EZ17: =SUM(EX17:EY17) -> 0 | FK17: =FI17+FG17+FE17+FC17+FA17 -> 0 | FL17: =FJ17+FH17+FF17+FD17+FB17 -> 0 | FM17: =SUM(FK17:FL17) -> 0 | FX17: =FV17+FT17+FR17+FP17+FN17 -> 0 | FY17: =FW17+FU17+FS17+FQ17+FO17 -> 0 | FZ17: =SUM(FX17:FY17) -> 0 | GK17: =GI17+GG17+GE17+GC17+GA17 -> 0 | GL17: =GJ17+GH17+GF17+GD17+GB17 -> 0 | GM17: =SUM(GK17:GL17) -> 0 | GN17: =FA17 -> 0 | GO17: =FB17 -> 0 | GP17: =FN17+FC17 -> 0 | GQ17: =FO17+FD17 -> 0 | GR17: =GA17+FP17+FE17 -> 0 | GS17: =GB17+FQ17+FF17 -> 0 | GT17: =GC17+FR17+FG17 -> 0 | GU17: =GD17+FS17+FH17 -> 0 | GV17: =GE17+FT17+FI17 -> 0 | GW17: =GF17+FU17+FJ17 -> 0 | GX17: =GG17+FV17 -> 0 | GY17: =GH17+FW17 -> 0 | GZ17: =GI17 -> 0 | HA17: =GJ17 -> 0 | HB17: =GZ17+GX17+GV17+GT17+GR17+GP17+GN17 -> 0 | HC17: =HA17+GY17+GW17+GU17+GS17+GQ17+GO17 -> 0 | HD17: =SUM(HB17:HC17) -> 0 | HW17: =HT17+HQ17+HN17+HK17+HH17+HE17 -> 0 | HX17: =HU17+HR17+HO17+HL17+HI17+HF17 -> 0 | HY17: =HV17+HS17+HP17+HM17+HJ17+HG17 -> 0 | HZ17: =SUM(HW17:HY17) -> 0 | IJ17: =IG17+ID17+IA17 -> 0 | IK17: =IH17+IE17+IB17 -> 0 | IL17: =II17+IF17+IC17 -> 0 | IM17: =SUM(IJ17:IL17) -> 0 | IN17: =IJ17+HW17 -> 0 | IO17: =IK17+HX17 -> 0 | IP17: =IL17+HY17 -> 0 | IQ17: =IM17+HZ17 -> 0 | IZ17: =IX17+IV17+IT17+IR17 -> 0 | JA17: =IY17+IW17+IU17+IS17 -> 0 | JB17: =SUM(IZ17:JA17) -> 0 | JC17: 1 | JM17: =JK17+JG17+JE17+JC17+JI17 -> 1 | JN17: =JL17+JH17+JF17+JD17+JJ17 -> 0 | JO17: =SUM(JM17:JN17) -> 1 | JP17: =JC17+IR17 -> 1 | JQ17: =JD17+IS17 -> 0 | JR17: =JE17+IT17 -> 0 | JS17: =JF17+IU17 -> 0 | JT17: =JG17 -> 0 | JU17: =JH17 -> 0 | JV17: =IV17+JI17 -> 0 | JW17: =IW17+JJ17 -> 0 | JX17: =JK17+IX17 -> 0 | JY17: =JL17+IY17 -> 0 | JZ17: =JX17+JV17+JT17+JR17+JP17 -> 1 | KA17: =JY17+JW17+JU17+JS17+JQ17 -> 0 | KB17: =SUM(JZ17:KA17) -> 1 | KC17: 1 | KF17: 1 | KJ17: 1 | KM17: 12 | KN17: 14 | KO17: =SUM(KM17:KN17) -> 26 | KQ17: 1 | KS17: 1 | KV17: 1 | KY17: 1 | LE17: 1 | LG17: 1 | LI17: 1 | LK17: 1 | LM17: 1 | LQ17: 1 | LT17: 1 | LW17: 522 | LX17: 85 | LY17: =SUM(LW17:LX17) -> 607 | LZ17: 1 | MC17: 1 | MD17: 1 | MF17: 1 | MH17: 1 | MK17: 1 | MM17: 1 | MN17: 1
A18: النجف | B18: المركز | C18: 12 | D18: 1400013 | E18: م . بغداد الأساسية | F18: 1 | H18: 1 | K18: 1 | M18: 1 | P18: 1 | R18: 1 | W18: 1 | AJ18: =AH18+AF18+AD18+AB18+Z18+X18 -> 0 | AK18: =AI18+AG18+AE18+AC18+AA18+Y18 -> 0 | AL18: =SUM(AJ18:AK18) -> 0 | AW18: =AU18+AS18+AQ18+AO18+AM18 -> 0 | AX18: =AV18+AT18+AR18+AP18+AN18 -> 0 | AY18: =SUM(AW18:AX18) -> 0 | BL18: =BJ18+BH18+BF18+BD18+BB18+AZ18 -> 0 | BM18: =BK18+BI18+BG18+BE18+BC18+BA18 -> 0 | BN18: =SUM(BL18:BM18) -> 0 | BY18: =BW18+BU18+BS18+BQ18+BO18 -> 0 | BZ18: =BX18+BV18+BT18+BR18+BP18 -> 0 | CA18: =SUM(BY18:BZ18) -> 0 | CL18: =CJ18+CH18+CF18+CD18+CB18 -> 0 | CM18: =CK18+CI18+CG18+CE18+CC18 -> 0 | CN18: =SUM(CL18:CM18) -> 0 | CY18: =CW18+CU18+CS18+CQ18+CO18 -> 0 | CZ18: =CX18+CV18+CT18+CR18+CP18 -> 0 | DA18: =SUM(CY18:CZ18) -> 0 | DL18: =DJ18+DH18+DF18+DD18+DB18 -> 0 | DM18: =DK18+DI18+DG18+DE18+DC18 -> 0 | DN18: =SUM(DL18:DM18) -> 0 | DY18: =DW18+DU18+DS18+DQ18+DO18 -> 0 | DZ18: =DX18+DV18+DT18+DR18+DP18 -> 0 | EA18: =SUM(DY18:DZ18) -> 0 | EB18: =AZ18 -> 0 | EC18: =BA18 -> 0 | ED18: =BB18 -> 0 | EE18: =BC18 -> 0 | EF18: =BO18+BD18 -> 0 | EG18: =BP18+BE18 -> 0 | EH18: =CB18+BQ18+BF18 -> 0 | EI18: =CC18+BR18+BG18 -> 0 | EJ18: =CO18+CD18+BS18+BH18 -> 0 | EK18: =CP18+CE18+BT18+BI18 -> 0 | EL18: =DB18+CQ18+CF18+BU18+BJ18 -> 0 | EM18: =DC18+CR18+CG18+BV18+BK18 -> 0 | EN18: =DO18+DD18+CS18+CH18+BW18 -> 0 | EO18: =DP18+DE18+CT18+CI18+BX18 -> 0 | EP18: =DQ18+DF18+CU18+CJ18 -> 0 | EQ18: =DR18+DG18+CV18+CK18 -> 0 | ER18: =DS18+DH18+CW18 -> 0 | ES18: =DT18+DI18+CX18 -> 0 | ET18: =DU18+DJ18 -> 0 | EU18: =DV18+DK18 -> 0 | EV18: =DW18 -> 0 | EW18: =DX18 -> 0 | EX18: =EV18+ET18+ER18+EP18+EN18+EL18+EJ18+EH18+EF18+ED18+EB18 -> 0 | EY18: =EW18+EU18+ES18+EQ18+EO18+EM18+EK18+EI18+EG18+EE18+EC18 -> 0 | EZ18: =SUM(EX18:EY18) -> 0 | FK18: =FI18+FG18+FE18+FC18+FA18 -> 0 | FL18: =FJ18+FH18+FF18+FD18+FB18 -> 0 | FM18: =SUM(FK18:FL18) -> 0 | FX18: =FV18+FT18+FR18+FP18+FN18 -> 0 | FY18: =FW18+FU18+FS18+FQ18+FO18 -> 0 | FZ18: =SUM(FX18:FY18) -> 0 | GK18: =GI18+GG18+GE18+GC18+GA18 -> 0 | GL18: =GJ18+GH18+GF18+GD18+GB18 -> 0 | GM18: =SUM(GK18:GL18) -> 0 | GN18: =FA18 -> 0 | GO18: =FB18 -> 0 | GP18: =FN18+FC18 -> 0 | GQ18: =FO18+FD18 -> 0 | GR18: =GA18+FP18+FE18 -> 0 | GS18: =GB18+FQ18+FF18 -> 0 | GT18: =GC18+FR18+FG18 -> 0 | GU18: =GD18+FS18+FH18 -> 0 | GV18: =GE18+FT18+FI18 -> 0 | GW18: =GF18+FU18+FJ18 -> 0 | GX18: =GG18+FV18 -> 0 | GY18: =GH18+FW18 -> 0 | GZ18: =GI18 -> 0 | HA18: =GJ18 -> 0 | HB18: =GZ18+GX18+GV18+GT18+GR18+GP18+GN18 -> 0 | HC18: =HA18+GY18+GW18+GU18+GS18+GQ18+GO18 -> 0 | HD18: =SUM(HB18:HC18) -> 0 | HW18: =HT18+HQ18+HN18+HK18+HH18+HE18 -> 0 | HX18: =HU18+HR18+HO18+HL18+HI18+HF18 -> 0 | HY18: =HV18+HS18+HP18+HM18+HJ18+HG18 -> 0 | HZ18: =SUM(HW18:HY18) -> 0 | IJ18: =IG18+ID18+IA18 -> 0 | IK18: =IH18+IE18+IB18 -> 0 | IL18: =II18+IF18+IC18 -> 0 | IM18: =SUM(IJ18:IL18) -> 0 | IN18: =IJ18+HW18 -> 0 | IO18: =IK18+HX18 -> 0 | IP18: =IL18+HY18 -> 0 | IQ18: =IM18+HZ18 -> 0 | IZ18: =IX18+IV18+IT18+IR18 -> 0 | JA18: =IY18+IW18+IU18+IS18 -> 0 | JB18: =SUM(IZ18:JA18) -> 0 | JC18: 1 | JM18: =JK18+JG18+JE18+JC18+JI18 -> 1 | JN18: =JL18+JH18+JF18+JD18+JJ18 -> 0 | JO18: =SUM(JM18:JN18) -> 1 | JP18: =JC18+IR18 -> 1 | JQ18: =JD18+IS18 -> 0 | JR18: =JE18+IT18 -> 0 | JS18: =JF18+IU18 -> 0 | JT18: =JG18 -> 0 | JU18: =JH18 -> 0 | JV18: =IV18+JI18 -> 0 | JW18: =IW18+JJ18 -> 0 | JX18: =JK18+IX18 -> 0 | JY18: =JL18+IY18 -> 0 | JZ18: =JX18+JV18+JT18+JR18+JP18 -> 1 | KA18: =JY18+JW18+JU18+JS18+JQ18 -> 0 | KB18: =SUM(JZ18:KA18) -> 1 | KC18: 1 | KF18: 1 | KJ18: 1 | KM18: 12 | KN18: 13 | KO18: =SUM(KM18:KN18) -> 25 | KQ18: 1 | KS18: 1 | KV18: 1 | KY18: 1 | LE18: 1 | LG18: 1 | LI18: 1 | LK18: 1 | LM18: 1 | LQ18: 1 | LT18: 1 | LW18: 445 | LX18: 25 | LY18: =SUM(LW18:LX18) -> 470 | LZ18: 1 | MC18: 1 | MD18: 1 | MF18: 1 | MH18: 1 | MK18: 1 | MM18: 1 | MN18: 1
A19: النجف | B19: المركز | C19: 13 | D19: 1400016 | E19: م . الامام الهادي الأساسية | F19: 1 | H19: 1 | K19: 1 | M19: 1 | P19: 1 | R19: 1 | W19: 1 | AJ19: =AH19+AF19+AD19+AB19+Z19+X19 -> 0 | AK19: =AI19+AG19+AE19+AC19+AA19+Y19 -> 0 | AL19: =SUM(AJ19:AK19) -> 0 | AW19: =AU19+AS19+AQ19+AO19+AM19 -> 0 | AX19: =AV19+AT19+AR19+AP19+AN19 -> 0 | AY19: =SUM(AW19:AX19) -> 0 | BL19: =BJ19+BH19+BF19+BD19+BB19+AZ19 -> 0 | BM19: =BK19+BI19+BG19+BE19+BC19+BA19 -> 0 | BN19: =SUM(BL19:BM19) -> 0 | BY19: =BW19+BU19+BS19+BQ19+BO19 -> 0 | BZ19: =BX19+BV19+BT19+BR19+BP19 -> 0 | CA19: =SUM(BY19:BZ19) -> 0 | CL19: =CJ19+CH19+CF19+CD19+CB19 -> 0 | CM19: =CK19+CI19+CG19+CE19+CC19 -> 0 | CN19: =SUM(CL19:CM19) -> 0 | CY19: =CW19+CU19+CS19+CQ19+CO19 -> 0 | CZ19: =CX19+CV19+CT19+CR19+CP19 -> 0 | DA19: =SUM(CY19:CZ19) -> 0 | DL19: =DJ19+DH19+DF19+DD19+DB19 -> 0 | DM19: =DK19+DI19+DG19+DE19+DC19 -> 0 | DN19: =SUM(DL19:DM19) -> 0 | DY19: =DW19+DU19+DS19+DQ19+DO19 -> 0 | DZ19: =DX19+DV19+DT19+DR19+DP19 -> 0 | EA19: =SUM(DY19:DZ19) -> 0 | EB19: =AZ19 -> 0 | EC19: =BA19 -> 0 | ED19: =BB19 -> 0 | EE19: =BC19 -> 0 | EF19: =BO19+BD19 -> 0 | EG19: =BP19+BE19 -> 0 | EH19: =CB19+BQ19+BF19 -> 0 | EI19: =CC19+BR19+BG19 -> 0 | EJ19: =CO19+CD19+BS19+BH19 -> 0 | EK19: =CP19+CE19+BT19+BI19 -> 0 | EL19: =DB19+CQ19+CF19+BU19+BJ19 -> 0 | EM19: =DC19+CR19+CG19+BV19+BK19 -> 0 | EN19: =DO19+DD19+CS19+CH19+BW19 -> 0 | EO19: =DP19+DE19+CT19+CI19+BX19 -> 0 | EP19: =DQ19+DF19+CU19+CJ19 -> 0 | EQ19: =DR19+DG19+CV19+CK19 -> 0 | ER19: =DS19+DH19+CW19 -> 0 | ES19: =DT19+DI19+CX19 -> 0 | ET19: =DU19+DJ19 -> 0 | EU19: =DV19+DK19 -> 0 | EV19: =DW19 -> 0 | EW19: =DX19 -> 0 | EX19: =EV19+ET19+ER19+EP19+EN19+EL19+EJ19+EH19+EF19+ED19+EB19 -> 0 | EY19: =EW19+EU19+ES19+EQ19+EO19+EM19+EK19+EI19+EG19+EE19+EC19 -> 0 | EZ19: =SUM(EX19:EY19) -> 0 | FK19: =FI19+FG19+FE19+FC19+FA19 -> 0 | FL19: =FJ19+FH19+FF19+FD19+FB19 -> 0 | FM19: =SUM(FK19:FL19) -> 0 | FX19: =FV19+FT19+FR19+FP19+FN19 -> 0 | FY19: =FW19+FU19+FS19+FQ19+FO19 -> 0 | FZ19: =SUM(FX19:FY19) -> 0 | GK19: =GI19+GG19+GE19+GC19+GA19 -> 0 | GL19: =GJ19+GH19+GF19+GD19+GB19 -> 0 | GM19: =SUM(GK19:GL19) -> 0 | GN19: =FA19 -> 0 | GO19: =FB19 -> 0 | GP19: =FN19+FC19 -> 0 | GQ19: =FO19+FD19 -> 0 | GR19: =GA19+FP19+FE19 -> 0 | GS19: =GB19+FQ19+FF19 -> 0 | GT19: =GC19+FR19+FG19 -> 0 | GU19: =GD19+FS19+FH19 -> 0 | GV19: =GE19+FT19+FI19 -> 0 | GW19: =GF19+FU19+FJ19 -> 0 | GX19: =GG19+FV19 -> 0 | GY19: =GH19+FW19 -> 0 | GZ19: =GI19 -> 0 | HA19: =GJ19 -> 0 | HB19: =GZ19+GX19+GV19+GT19+GR19+GP19+GN19 -> 0 | HC19: =HA19+GY19+GW19+GU19+GS19+GQ19+GO19 -> 0 | HD19: =SUM(HB19:HC19) -> 0 | HW19: =HT19+HQ19+HN19+HK19+HH19+HE19 -> 0 | HX19: =HU19+HR19+HO19+HL19+HI19+HF19 -> 0 | HY19: =HV19+HS19+HP19+HM19+HJ19+HG19 -> 0 | HZ19: =SUM(HW19:HY19) -> 0 | IJ19: =IG19+ID19+IA19 -> 0 | IK19: =IH19+IE19+IB19 -> 0 | IL19: =II19+IF19+IC19 -> 0 | IM19: =SUM(IJ19:IL19) -> 0 | IN19: =IJ19+HW19 -> 0 | IO19: =IK19+HX19 -> 0 | IP19: =IL19+HY19 -> 0 | IQ19: =IM19+HZ19 -> 0 | IZ19: =IX19+IV19+IT19+IR19 -> 0 | JA19: =IY19+IW19+IU19+IS19 -> 0 | JB19: =SUM(IZ19:JA19) -> 0 | JC19: 1 | JM19: =JK19+JG19+JE19+JC19+JI19 -> 1 | JN19: =JL19+JH19+JF19+JD19+JJ19 -> 0 | JO19: =SUM(JM19:JN19) -> 1 | JP19: =JC19+IR19 -> 1 | JQ19: =JD19+IS19 -> 0 | JR19: =JE19+IT19 -> 0 | JS19: =JF19+IU19 -> 0 | JT19: =JG19 -> 0 | JU19: =JH19 -> 0 | JV19: =IV19+JI19 -> 0 | JW19: =IW19+JJ19 -> 0 | JX19: =JK19+IX19 -> 0 | JY19: =JL19+IY19 -> 0 | JZ19: =JX19+JV19+JT19+JR19+JP19 -> 1 | KA19: =JY19+JW19+JU19+JS19+JQ19 -> 0 | KB19: =SUM(JZ19:KA19) -> 1 | KC19: 1 | KF19: 1 | KK19: 1 | KM19: 18 | KN19: 11 | KO19: =SUM(KM19:KN19) -> 29 | KQ19: 1 | KS19: 1 | KV19: 1 | KY19: 1 | LE19: 1 | LG19: 1 | LI19: 1 | LK19: 1 | LM19: 1 | LQ19: 1 | LU19: 1 | LW19: 168 | LX19: 70 | LY19: =SUM(LW19:LX19) -> 238 | LZ19: 1 | MC19: 1 | MD19: 1 | MF19: 1 | MH19: 1 | MK19: 1 | MM19: 1 | MN19: 1
A20: النجف | B20: المركز | C20: 14 | D20: 1400030 | E20: م . بلقيس الأساسية | F20: 1 | I20: 1 | K20: 1 | N20: 1 | Q20: 1 | T20: 1 | W20: 1 | AJ20: =AH20+AF20+AD20+AB20+Z20+X20 -> 0 | AK20: =AI20+AG20+AE20+AC20+AA20+Y20 -> 0 | AL20: =SUM(AJ20:AK20) -> 0 | AW20: =AU20+AS20+AQ20+AO20+AM20 -> 0 | AX20: =AV20+AT20+AR20+AP20+AN20 -> 0 | AY20: =SUM(AW20:AX20) -> 0 | BL20: =BJ20+BH20+BF20+BD20+BB20+AZ20 -> 0 | BM20: =BK20+BI20+BG20+BE20+BC20+BA20 -> 0 | BN20: =SUM(BL20:BM20) -> 0 | BY20: =BW20+BU20+BS20+BQ20+BO20 -> 0 | BZ20: =BX20+BV20+BT20+BR20+BP20 -> 0 | CA20: =SUM(BY20:BZ20) -> 0 | CL20: =CJ20+CH20+CF20+CD20+CB20 -> 0 | CM20: =CK20+CI20+CG20+CE20+CC20 -> 0 | CN20: =SUM(CL20:CM20) -> 0 | CY20: =CW20+CU20+CS20+CQ20+CO20 -> 0 | CZ20: =CX20+CV20+CT20+CR20+CP20 -> 0 | DA20: =SUM(CY20:CZ20) -> 0 | DL20: =DJ20+DH20+DF20+DD20+DB20 -> 0 | DM20: =DK20+DI20+DG20+DE20+DC20 -> 0 | DN20: =SUM(DL20:DM20) -> 0 | DY20: =DW20+DU20+DS20+DQ20+DO20 -> 0 | DZ20: =DX20+DV20+DT20+DR20+DP20 -> 0 | EA20: =SUM(DY20:DZ20) -> 0 | EB20: =AZ20 -> 0 | EC20: =BA20 -> 0 | ED20: =BB20 -> 0 | EE20: =BC20 -> 0 | EF20: =BO20+BD20 -> 0 | EG20: =BP20+BE20 -> 0 | EH20: =CB20+BQ20+BF20 -> 0 | EI20: =CC20+BR20+BG20 -> 0 | EJ20: =CO20+CD20+BS20+BH20 -> 0 | EK20: =CP20+CE20+BT20+BI20 -> 0 | EL20: =DB20+CQ20+CF20+BU20+BJ20 -> 0 | EM20: =DC20+CR20+CG20+BV20+BK20 -> 0 | EN20: =DO20+DD20+CS20+CH20+BW20 -> 0 | EO20: =DP20+DE20+CT20+CI20+BX20 -> 0 | EP20: =DQ20+DF20+CU20+CJ20 -> 0 | EQ20: =DR20+DG20+CV20+CK20 -> 0 | ER20: =DS20+DH20+CW20 -> 0 | ES20: =DT20+DI20+CX20 -> 0 | ET20: =DU20+DJ20 -> 0 | EU20: =DV20+DK20 -> 0 | EV20: =DW20 -> 0 | EW20: =DX20 -> 0 | EX20: =EV20+ET20+ER20+EP20+EN20+EL20+EJ20+EH20+EF20+ED20+EB20 -> 0 | EY20: =EW20+EU20+ES20+EQ20+EO20+EM20+EK20+EI20+EG20+EE20+EC20 -> 0 | EZ20: =SUM(EX20:EY20) -> 0 | FK20: =FI20+FG20+FE20+FC20+FA20 -> 0 | FL20: =FJ20+FH20+FF20+FD20+FB20 -> 0 | FM20: =SUM(FK20:FL20) -> 0 | FX20: =FV20+FT20+FR20+FP20+FN20 -> 0 | FY20: =FW20+FU20+FS20+FQ20+FO20 -> 0 | FZ20: =SUM(FX20:FY20) -> 0 | GK20: =GI20+GG20+GE20+GC20+GA20 -> 0 | GL20: =GJ20+GH20+GF20+GD20+GB20 -> 0 | GM20: =SUM(GK20:GL20) -> 0 | GN20: =FA20 -> 0 | GO20: =FB20 -> 0 | GP20: =FN20+FC20 -> 0 | GQ20: =FO20+FD20 -> 0 | GR20: =GA20+FP20+FE20 -> 0 | GS20: =GB20+FQ20+FF20 -> 0 | GT20: =GC20+FR20+FG20 -> 0 | GU20: =GD20+FS20+FH20 -> 0 | GV20: =GE20+FT20+FI20 -> 0 | GW20: =GF20+FU20+FJ20 -> 0 | GX20: =GG20+FV20 -> 0 | GY20: =GH20+FW20 -> 0 | GZ20: =GI20 -> 0 | HA20: =GJ20 -> 0 | HB20: =GZ20+GX20+GV20+GT20+GR20+GP20+GN20 -> 0 | HC20: =HA20+GY20+GW20+GU20+GS20+GQ20+GO20 -> 0 | HD20: =SUM(HB20:HC20) -> 0 | HW20: =HT20+HQ20+HN20+HK20+HH20+HE20 -> 0 | HX20: =HU20+HR20+HO20+HL20+HI20+HF20 -> 0 | HY20: =HV20+HS20+HP20+HM20+HJ20+HG20 -> 0 | HZ20: =SUM(HW20:HY20) -> 0 | IJ20: =IG20+ID20+IA20 -> 0 | IK20: =IH20+IE20+IB20 -> 0 | IL20: =II20+IF20+IC20 -> 0 | IM20: =SUM(IJ20:IL20) -> 0 | IN20: =IJ20+HW20 -> 0 | IO20: =IK20+HX20 -> 0 | IP20: =IL20+HY20 -> 0 | IQ20: =IM20+HZ20 -> 0 | IZ20: =IX20+IV20+IT20+IR20 -> 0 | JA20: =IY20+IW20+IU20+IS20 -> 0 | JB20: =SUM(IZ20:JA20) -> 0 | JD20: 1 | JM20: =JK20+JG20+JE20+JC20+JI20 -> 0 | JN20: =JL20+JH20+JF20+JD20+JJ20 -> 1 | JO20: =SUM(JM20:JN20) -> 1 | JP20: =JC20+IR20 -> 0 | JQ20: =JD20+IS20 -> 1 | JR20: =JE20+IT20 -> 0 | JS20: =JF20+IU20 -> 0 | JT20: =JG20 -> 0 | JU20: =JH20 -> 0 | JV20: =IV20+JI20 -> 0 | JW20: =IW20+JJ20 -> 0 | JX20: =JK20+IX20 -> 0 | JY20: =JL20+IY20 -> 0 | JZ20: =JX20+JV20+JT20+JR20+JP20 -> 0 | KA20: =JY20+JW20+JU20+JS20+JQ20 -> 1 | KB20: =SUM(JZ20:KA20) -> 1 | KO20: =SUM(KM20:KN20) -> 0 | LM20: 1 | LQ20: 1 | LT20: 1 | LW20: 714 | LY20: =SUM(LW20:LX20) -> 714 | LZ20: 1 | MC20: 1 | MD20: 1 | MF20: 1 | MH20: 1 | MK20: 1 | MM20: 1 | MO20: 1
C21: مجموع الثانوي مركزالنجف | F21: =SUM(F16:F20) -> 5 | G21: =SUM(G16:G20) -> 0 | H21: =SUM(H16:H20) -> 4 | I21: =SUM(I16:I20) -> 1 | J21: =SUM(J16:J20) -> 0 | K21: =SUM(K16:K20) -> 5 | L21: =SUM(L16:L20) -> 0 | M21: =SUM(M16:M20) -> 4 | ... MO21: =SUM(MO16:MO20) -> 1
A22: النجف | B22: الحيدرية | C22: 15 | D22: 1400327 | E22: الفجر الجديد التكميلي | G22: 1 | J22: 1 | L22: 1 | M22: 1 | P22: 1 | R22: 1 | W22: 1 | AJ22: =AH22+AF22+AD22+AB22+Z22+X22 -> 0 | AK22: =AI22+AG22+AE22+AC22+AA22+Y22 -> 0 | AL22: =SUM(AJ22:AK22) -> 0 | AW22: =AU22+AS22+AQ22+AO22+AM22 -> 0 | AX22: =AV22+AT22+AR22+AP22+AN22 -> 0 | AY22: =SUM(AW22:AX22) -> 0 | BL22: =BJ22+BH22+BF22+BD22+BB22+AZ22 -> 0 | BM22: =BK22+BI22+BG22+BE22+BC22+BA22 -> 0 | BN22: =SUM(BL22:BM22) -> 0 | BY22: =BW22+BU22+BS22+BQ22+BO22 -> 0 | BZ22: =BX22+BV22+BT22+BR22+BP22 -> 0 | CA22: =SUM(BY22:BZ22) -> 0 | CL22: =CJ22+CH22+CF22+CD22+CB22 -> 0 | CM22: =CK22+CI22+CG22+CE22+CC22 -> 0 | CN22: =SUM(CL22:CM22) -> 0 | CY22: =CW22+CU22+CS22+CQ22+CO22 -> 0 | CZ22: =CX22+CV22+CT22+CR22+CP22 -> 0 | DA22: =SUM(CY22:CZ22) -> 0 | DL22: =DJ22+DH22+DF22+DD22+DB22 -> 0 | DM22: =DK22+DI22+DG22+DE22+DC22 -> 0 | DN22: =SUM(DL22:DM22) -> 0 | DY22: =DW22+DU22+DS22+DQ22+DO22 -> 0 | DZ22: =DX22+DV22+DT22+DR22+DP22 -> 0 | EA22: =SUM(DY22:DZ22) -> 0 | EB22: =AZ22 -> 0 | EC22: =BA22 -> 0 | ED22: =BB22 -> 0 | EE22: =BC22 -> 0 | EF22: =BO22+BD22 -> 0 | EG22: =BP22+BE22 -> 0 | EH22: =CB22+BQ22+BF22 -> 0 | EI22: =CC22+BR22+BG22 -> 0 | EJ22: =CO22+CD22+BS22+BH22 -> 0 | EK22: =CP22+CE22+BT22+BI22 -> 0 | EL22: =DB22+CQ22+CF22+BU22+BJ22 -> 0 | EM22: =DC22+CR22+CG22+BV22+BK22 -> 0 | EN22: =DO22+DD22+CS22+CH22+BW22 -> 0 | EO22: =DP22+DE22+CT22+CI22+BX22 -> 0 | EP22: =DQ22+DF22+CU22+CJ22 -> 0 | EQ22: =DR22+DG22+CV22+CK22 -> 0 | ER22: =DS22+DH22+CW22 -> 0 | ES22: =DT22+DI22+CX22 -> 0 | ET22: =DU22+DJ22 -> 0 | EU22: =DV22+DK22 -> 0 | EV22: =DW22 -> 0 | EW22: =DX22 -> 0 | EX22: =EV22+ET22+ER22+EP22+EN22+EL22+EJ22+EH22+EF22+ED22+EB22 -> 0 | EY22: =EW22+EU22+ES22+EQ22+EO22+EM22+EK22+EI22+EG22+EE22+EC22 -> 0 | EZ22: =SUM(EX22:EY22) -> 0 | FK22: =FI22+FG22+FE22+FC22+FA22 -> 0 | FL22: =FJ22+FH22+FF22+FD22+FB22 -> 0 | FM22: =SUM(FK22:FL22) -> 0 | FX22: =FV22+FT22+FR22+FP22+FN22 -> 0 | FY22: =FW22+FU22+FS22+FQ22+FO22 -> 0 | FZ22: =SUM(FX22:FY22) -> 0 | GK22: =GI22+GG22+GE22+GC22+GA22 -> 0 | GL22: =GJ22+GH22+GF22+GD22+GB22 -> 0 | GM22: =SUM(GK22:GL22) -> 0 | GN22: =FA22 -> 0 | GO22: =FB22 -> 0 | GP22: =FN22+FC22 -> 0 | GQ22: =FO22+FD22 -> 0 | GR22: =GA22+FP22+FE22 -> 0 | GS22: =GB22+FQ22+FF22 -> 0 | GT22: =GC22+FR22+FG22 -> 0 | GU22: =GD22+FS22+FH22 -> 0 | GV22: =GE22+FT22+FI22 -> 0 | GW22: =GF22+FU22+FJ22 -> 0 | GX22: =GG22+FV22 -> 0 | GY22: =GH22+FW22 -> 0 | GZ22: =GI22 -> 0 | HA22: =GJ22 -> 0 | HB22: =GZ22+GX22+GV22+GT22+GR22+GP22+GN22 -> 0 | HC22: =HA22+GY22+GW22+GU22+GS22+GQ22+GO22 -> 0 | HD22: =SUM(HB22:HC22) -> 0 | HW22: =HT22+HQ22+HN22+HK22+HH22+HE22 -> 0 | HX22: =HU22+HR22+HO22+HL22+HI22+HF22 -> 0 | HY22: =HV22+HS22+HP22+HM22+HJ22+HG22 -> 0 | HZ22: =SUM(HW22:HY22) -> 0 | IJ22: =IG22+ID22+IA22 -> 0 | IK22: =IH22+IE22+IB22 -> 0 | IL22: =II22+IF22+IC22 -> 0 | IM22: =SUM(IJ22:IL22) -> 0 | IN22: =IJ22+HW22 -> 0 | IO22: =IK22+HX22 -> 0 | IP22: =IL22+HY22 -> 0 | IQ22: =IM22+HZ22 -> 0 | IR22: 1 | IZ22: =IX22+IV22+IT22+IR22 -> 1 | JA22: =IY22+IW22+IU22+IS22 -> 0 | JB22: =SUM(IZ22:JA22) -> 1 | JM22: =JK22+JG22+JE22+JC22+JI22 -> 0 | JN22: =JL22+JH22+JF22+JD22+JJ22 -> 0 | JO22: =SUM(JM22:JN22) -> 0 | JP22: =JC22+IR22 -> 1 | JQ22: =JD22+IS22 -> 0 | JR22: =JE22+IT22 -> 0 | JS22: =JF22+IU22 -> 0 | JT22: =JG22 -> 0 | JU22: =JH22 -> 0 | JV22: =IV22+JI22 -> 0 | JW22: =IW22+JJ22 -> 0 | JX22: =JK22+IX22 -> 0 | JY22: =JL22+IY22 -> 0 | JZ22: =JX22+JV22+JT22+JR22+JP22 -> 1 | KA22: =JY22+JW22+JU22+JS22+JQ22 -> 0 | KB22: =SUM(JZ22:KA22) -> 1 | KC22: 1 | KF22: 1 | KK22: 1 | KM22: 18 | KN22: 4 | KO22: =SUM(KM22:KN22) -> 22 | KQ22: 1 | KS22: 1 | KV22: 1 | KY22: 1 | LE22: 1 | LG22: 1 | LI22: 1 | LK22: 1 | LM22: 1 | LQ22: 1 | LT22: 1 | LW22: 5 | LX22: 50 | LY22: =SUM(LW22:LX22) -> 55 | MA22: 1
A23: النجف | B23: الحيدرية | C23: 16 | E23: البوادي التكميلي | G23: 1 | I23: 1 | L23: 1 | M23: 1 | P23: 1 | R23: 1 | W23: 1 | AJ23: =AH23+AF23+AD23+AB23+Z23+X23 -> 0 | AK23: =AI23+AG23+AE23+AC23+AA23+Y23 -> 0 | AL23: =SUM(AJ23:AK23) -> 0 | AW23: =AU23+AS23+AQ23+AO23+AM23 -> 0 | AX23: =AV23+AT23+AR23+AP23+AN23 -> 0 | AY23: =SUM(AW23:AX23) -> 0 | BL23: =BJ23+BH23+BF23+BD23+BB23+AZ23 -> 0 | BM23: =BK23+BI23+BG23+BE23+BC23+BA23 -> 0 | BN23: =SUM(BL23:BM23) -> 0 | BY23: =BW23+BU23+BS23+BQ23+BO23 -> 0 | BZ23: =BX23+BV23+BT23+BR23+BP23 -> 0 | CA23: =SUM(BY23:BZ23) -> 0 | CL23: =CJ23+CH23+CF23+CD23+CB23 -> 0 | CM23: =CK23+CI23+CG23+CE23+CC23 -> 0 | CN23: =SUM(CL23:CM23) -> 0 | CY23: =CW23+CU23+CS23+CQ23+CO23 -> 0 | CZ23: =CX23+CV23+CT23+CR23+CP23 -> 0 | DA23: =SUM(CY23:CZ23) -> 0 | DL23: =DJ23+DH23+DF23+DD23+DB23 -> 0 | DM23: =DK23+DI23+DG23+DE23+DC23 -> 0 | DN23: =SUM(DL23:DM23) -> 0 | DY23: =DW23+DU23+DS23+DQ23+DO23 -> 0 | DZ23: =DX23+DV23+DT23+DR23+DP23 -> 0 | EA23: =SUM(DY23:DZ23) -> 0 | EB23: =AZ23 -> 0 | EC23: =BA23 -> 0 | ED23: =BB23 -> 0 | EE23: =BC23 -> 0 | EF23: =BO23+BD23 -> 0 | EG23: =BP23+BE23 -> 0 | EH23: =CB23+BQ23+BF23 -> 0 | EI23: =CC23+BR23+BG23 -> 0 | EJ23: =CO23+CD23+BS23+BH23 -> 0 | EK23: =CP23+CE23+BT23+BI23 -> 0 | EL23: =DB23+CQ23+CF23+BU23+BJ23 -> 0 | EM23: =DC23+CR23+CG23+BV23+BK23 -> 0 | EN23: =DO23+DD23+CS23+CH23+BW23 -> 0 | EO23: =DP23+DE23+CT23+CI23+BX23 -> 0 | EP23: =DQ23+DF23+CU23+CJ23 -> 0 | EQ23: =DR23+DG23+CV23+CK23 -> 0 | ER23: =DS23+DH23+CW23 -> 0 | ES23: =DT23+DI23+CX23 -> 0 | ET23: =DU23+DJ23 -> 0 | EU23: =DV23+DK23 -> 0 | EV23: =DW23 -> 0 | EW23: =DX23 -> 0 | EX23: =EV23+ET23+ER23+EP23+EN23+EL23+EJ23+EH23+EF23+ED23+EB23 -> 0 | EY23: =EW23+EU23+ES23+EQ23+EO23+EM23+EK23+EI23+EG23+EE23+EC23 -> 0 | EZ23: =SUM(EX23:EY23) -> 0 | FK23: =FI23+FG23+FE23+FC23+FA23 -> 0 | FL23: =FJ23+FH23+FF23+FD23+FB23 -> 0 | FM23: =SUM(FK23:FL23) -> 0 | FX23: =FV23+FT23+FR23+FP23+FN23 -> 0 | FY23: =FW23+FU23+FS23+FQ23+FO23 -> 0 | FZ23: =SUM(FX23:FY23) -> 0 | GK23: =GI23+GG23+GE23+GC23+GA23 -> 0 | GL23: =GJ23+GH23+GF23+GD23+GB23 -> 0 | GM23: =SUM(GK23:GL23) -> 0 | GN23: =FA23 -> 0 | GO23: =FB23 -> 0 | GP23: =FN23+FC23 -> 0 | GQ23: =FO23+FD23 -> 0 | GR23: =GA23+FP23+FE23 -> 0 | GS23: =GB23+FQ23+FF23 -> 0 | GT23: =GC23+FR23+FG23 -> 0 | GU23: =GD23+FS23+FH23 -> 0 | GV23: =GE23+FT23+FI23 -> 0 | GW23: =GF23+FU23+FJ23 -> 0 | GX23: =GG23+FV23 -> 0 | GY23: =GH23+FW23 -> 0 | GZ23: =GI23 -> 0 | HA23: =GJ23 -> 0 | HB23: =GZ23+GX23+GV23+GT23+GR23+GP23+GN23 -> 0 | HC23: =HA23+GY23+GW23+GU23+GS23+GQ23+GO23 -> 0 | HD23: =SUM(HB23:HC23) -> 0 | HW23: =HT23+HQ23+HN23+HK23+HH23+HE23 -> 0 | HX23: =HU23+HR23+HO23+HL23+HI23+HF23 -> 0 | HY23: =HV23+HS23+HP23+HM23+HJ23+HG23 -> 0 | HZ23: =SUM(HW23:HY23) -> 0 | IJ23: =IG23+ID23+IA23 -> 0 | IK23: =IH23+IE23+IB23 -> 0 | IL23: =II23+IF23+IC23 -> 0 | IM23: =SUM(IJ23:IL23) -> 0 | IN23: =IJ23+HW23 -> 0 | IO23: =IK23+HX23 -> 0 | IP23: =IL23+HY23 -> 0 | IQ23: =IM23+HZ23 -> 0 | IS23: 1 | IZ23: =IX23+IV23+IT23+IR23 -> 0 | JA23: =IY23+IW23+IU23+IS23 -> 1 | JB23: =SUM(IZ23:JA23) -> 1 | JM23: =JK23+JG23+JE23+JC23+JI23 -> 0 | JN23: =JL23+JH23+JF23+JD23+JJ23 -> 0 | JO23: =SUM(JM23:JN23) -> 0 | JP23: =JC23+IR23 -> 0 | JQ23: =JD23+IS23 -> 1 | JR23: =JE23+IT23 -> 0 | JS23: =JF23+IU23 -> 0 | JT23: =JG23 -> 0 | JU23: =JH23 -> 0 | JV23: =IV23+JI23 -> 0 | JW23: =IW23+JJ23 -> 0 | JX23: =JK23+IX23 -> 0 | JY23: =JL23+IY23 -> 0 | JZ23: =JX23+JV23+JT23+JR23+JP23 -> 0 | KA23: =JY23+JW23+JU23+JS23+JQ23 -> 1 | KB23: =SUM(JZ23:KA23) -> 1 | KC23: 1 | KF23: 1 | KK23: 1 | KM23: 18 | KN23: 5 | KO23: =SUM(KM23:KN23) -> 23 | KQ23: 1 | KS23: 1 | KW23: 1 | KY23: 1 | LE23: 1 | LG23: 1 | LI23: 1 | LK23: 1 | LM23: 1 | LQ23: 1 | LT23: 1 | LW23: 84 | LY23: =SUM(LW23:LX23) -> 84 | MA23: 1
C24: مجموع الحيدرية | F24: =SUM(F22:F23) -> 0 | G24: =SUM(G22:G23) -> 2 | H24: =SUM(H22:H23) -> 0 | I24: =SUM(I22:I23) -> 1 | J24: =SUM(J22:J23) -> 1 | K24: =SUM(K22:K23) -> 0 | L24: =SUM(L22:L23) -> 2 | M24: =SUM(M22:M23) -> 2 | ... MO24: =SUM(MO22:MO23) -> 0
A25: مجموع قضاء النجف | F25: =F21+F15+F24 -> 11 | G25: =G21+G15+G24 -> 2 | H25: =H21+H15+H24 -> 8 | I25: =I21+I15+I24 -> 3 | J25: =J21+J15+J24 -> 2 | K25: =K21+K15+K24 -> 11 | L25: =L21+L15+L24 -> 2 | M25: =M21+M15+M24 -> 12 | ... MO25: =MO21+MO15+MO24 -> 1
