Workbook

Sheet التعليم المسرع
A1: المديرية العامة للتربية في النجف الاشرف | F1: نوع صفوف المسرع | H1: جنس المدرسة | K1: بيئة المدرسة | M1: دوام المدرسة | Q1: استقلالية المدرسة | T1: نوع الازدواج | X1: هل المدرسة فتح جديد | Y1: المرحلة الاولى | AP1: المرحلة الثانية | BG1: المرحلة الثالثة | BX1: المجموع الكلي | CO1: عدد الشعب حسب الصف والجنس | DB1: عدد التلاميذ التاركين حسب الصف والجنس للعام 2026 / 2025 | DK1: عدد التلاميذ الناجحين حسب الصف والجنس للعام الدراسي 2025 / 2024 | DT1: عدد التلامذة الراسبين (الفشل بالامتحان ) لعام 2025 /2024 | EC1: عدد التلامذة الراسبين ( تجاوز الغياب )لعام 2025 /2024 | EL1: عدد التلامذة الراسبين ( الاسباب الاخري )لعام 2021 /2024 | EU1: اعضاء الهيئة التعليمية حسب العنوان الوظيفي | FF1: الموظفون الاداريون والخدميون حسب العنوان الوظيفي | FX1: الهيئة التعليمية حسب الشهادة والجنس | GQ1: عدد الهيئة التعليمية حسب الجنسية | GZ1: عدد اعضاء الهيئة التعليمية حسب الحالة الوظيفية | HT1: عدد اعضاء الهيئة التعليمية حسب الحالة الاجتماعية | IE1: عدد المعلمين المشاركين بدورات تربوية للعام الماضي
IQ2: التجهيزات والاثاث :- | IT2: الحاسبات :-
A3: التعليم المسرع 2026/2025 | GZ3: داخل القوة العمل | HB3: خارج القوة العمل | HQ3: المجموع | IG3: هل المدرسة مشمولة بالارشاد التربوي | II3: هل المدرسة مشمولة بالحاسوب | IK3: هل المدرسة مشمولة باللغات الاجنبية | IM3: اللغات | IQ3: عدد الرحلات المزدوجة (ذات المقعدين) الصالحة | IR3: عدد الرحلات (ذات المقعد الواحد) الصالحة | IS3: عدد لوحات الكتابة (السبورات) الصالحة | IT3: عدد الحاسبات الالكترونية (كومبيوتر) | IU3: عدد الطابعات | IV3: عدد الماسحات الضوئية (سكنرات) | IW3: هل توجد مكتبة
Y4: 12 | AA4: 13 | AC4: 14 | AE4: 15 | AG4: 16 | AI4: 17 | AK4: 18 | AM4: المجموع | AP4: 12 | AR4: 13 | AT4: 14 | AV4: 15 | AX4: 16 | AZ4: 17 | BB4: 18 | BD4: المجموع | BG4: 12 | BI4: 13 | BK4: 14 | BM4: 15 | BO4: 16 | BQ4: 17 | BS4: 18 | BU4: المجموع | BX4: 12 | BZ4: 13 | CB4: 14 | CD4: 15 | CF4: 16 | CH4: 17 | CJ4: 18 | CL4: المجموع الكلي | CO4: المرحلة الاولى | CR4: المرحلة الثانية | CU4: المرحلة الثالثة | CX4: المجموع | DB4: المرحلة الاولى | DD4: المرحلة الثانية | DF4: المرحلة الثالثة | DH4: المجموع | DK4: المرحلة الاولى | DM4: المرحلة الثانية | DO4: المرحلة الثالثة | DQ4: المجموع | DT4: المرحلة الاولى | DV4: المرحلة الثانية | DX4: المرحلة الثالثة | DZ4: المجموع | EC4: المرحلة الاولى | EE4: المرحلة الثانية | EG4: المرحلة الثالثة | EI4: المجموع | EL4: المرحلة الاولى | EN4: المرحلة الثانية | EP4: المرحلة الثالثة | ER4: المجموع | EU4: مدير | EW4: معاون | EY4: معلم | FA4: مرشد تربوي | FC4: المجموع | FF4: موظف ادارة | FH4: محاسب | FJ4: كاتب | FL4: امين مكتبة | FN4: موظف خدمات | FP4: حرفي | FR4: فلاح | FS4: حارس | FT4: سايق | FU4: المجموع | FX4: اعدادية | FZ4: دور معلمين | GB4: دبلوم تعليمي | GD4: مدارس مهنية | GF4: دبلوم عام | GH4: بكلوريوس تعليمية | GJ4: بكلوريوس عام | GL4: اخرى | GN4: المجموع | GP4: المجموع | GQ4: عراقية | GS4: عربية | GU4: اجنبية | GW4: المجموع | HB4: بعثة او زمالة دراسية | HD4: اجازة دراسية | HF4: اجازة مصاحبة | HH4: اجازة بدون راتب | HJ4: اجازة مرضية طويلة | HL4: اجازة امومة | HM4: منسب الى جهة اخرى | HO4: 4-5سنوات | HT4: اعزب | HV4: متزوج | HX4: مطلق | HZ4: ارمل | IB4: المجموع | ID4: المجموع الكلي | IE4: عدد المعلمين | IM4: فرنسي | IN4: روسي | IO4: اسباني | IP4: كردي
A5: القضاء | B5: الناحية | C5: ت | D5: الرقم الاحصائي | E5: اسم المدرسة | F5: صف مسرع في مدرسة | G5: مدرسة مسرع | H5: بنون | I5: بنات | J5: مختلط | K5: حضر | L5: ريف | M5: صباحا | N5: ظهرا | O5: صباحا وظهرا | P5: مساءا | Q5: اصلية | R5: ضيف | S5: استضافة | T5: غير مزدوجة | U5: مع نفسها | V5: مع اخرى | W5: مع نفسها ومع اخرى | X5: الجديد | Y5: بنون | Z5: بنات | AA5: بنون | AB5: بنات | AC5: بنون | AD5: بنات | AE5: بنون | AF5: بنات | AG5: بنون | AH5: بنات | AI5: بنون | AJ5: بنات | AK5: بنون | AL5: بنات | AM5: بنون | AN5: بنات | AO5: المجموع | AP5: بنون | AQ5: بنات | AR5: بنون | AS5: بنات | AT5: بنون | AU5: بنات | AV5: بنون | AW5: بنات | AX5: بنون | AY5: بنات | AZ5: بنون | BA5: بنات | BB5: بنون | BC5: بنات | BD5: بنون | BE5: بنات | BF5: المجموع | BG5: بنون | BH5: بنات | BI5: بنون | BJ5: بنات | BK5: بنون | BL5: بنات | BM5: بنون | BN5: بنات | BO5: بنون | BP5: بنات | BQ5: بنون | BR5: بنات | BS5: بنون | BT5: بنات | BU5: بنون | BV5: بنات | BW5: المجموع | BX5: بنون | BY5: بنات | BZ5: بنون | CA5: بنات | CB5: بنون | CC5: بنات | CD5: بنون | CE5: بنات | CF5: بنون | CG5: بنات | CH5: بنون | CI5: بنات | CJ5: بنون | CK5: بنات | CL5: بنون | CM5: بنات | CN5: المجموع | CO5: بنون | CP5: بنات | CQ5: مختلط | CR5: بنون | CS5: بنات | CT5: مختلط | CU5: بنون | CV5: بنات | CW5: مختلط | CX5: بنون | CY5: بنات | CZ5: مختلط | DA5: المجموع | DB5: بنون | DC5: بنات | DD5: بنون | DE5: بنات | DF5: بنون | DG5: بنات | DH5: بنون | DI5: بنات | DJ5: المجموع | DK5: بنون | DL5: بنات | DM5: بنون | DN5: بنات | DO5: بنون | DP5: بنات | DQ5: بنون | DR5: بنات | DS5: المجموع | DT5: بنون | DU5: بنات | DV5: بنون | DW5: بنات | DX5: بنون | DY5: بنات | DZ5: بنون | EA5: بنات | EB5: المجموع | EC5: بنون | ED5: بنات | EE5: بنون | EF5: بنات | EG5: بنون | EH5: بنات | EI5: بنون | EJ5: بنات | EK5: المجموع | EL5: بنون | EM5: بنات | EN5: بنون | EO5: بنات | EP5: بنون | EQ5: بنات | ER5: بنون | ES5: بنات | ET5: المجموع | EU5: ذكور | EV5: اناث | EW5: ذكور | EX5: اناث | EY5: ذكور | EZ5: اناث | FA5: ذكور | FB5: اناث | FC5: ذكور | FD5: اناث | FE5: المجموع | FF5: ذكور | FG5: اناث | FH5: ذكور | FI5: اناث | FJ5: ذكور | FK5: اناث | FL5: ذكور | FM5: اناث | FN5: ذكور | FO5: اناث | FP5: ذكور | FQ5: اناث | FR5: ذكور | FS5: ذكور | FT5: ذكور | FU5: ذكور | FV5: اناث | FW5: المجموع | FX5: ذكور | FY5: اناث | FZ5: ذكور | GA5: اناث | GB5: ذكور | GC5: اناث | GD5: ذكور | GE5: اناث | GF5: ذكور | GG5: اناث | GH5: ذكور | GI5: اناث | GJ5: ذكور | GK5: اناث | GL5: ذكور | GM5: اناث | GN5: ذكور | GO5: اناث | GQ5: ذكور | GR5: اناث | GS5: ذكور | GT5: اناث | GU5: ذكور | GV5: اناث | GW5: ذكور | GX5: اناث | GY5: المجموع | GZ5: ذكور | HA5: اناث | HB5: ذكور | HC5: اناث | HD5: ذكور | HE5: اناث | HF5: ذكور | HG5: اناث | HH5: ذكور | HI5: اناث | HJ5: ذكور | HK5: اناث | HL5: اناث | HM5: ذكور | HN5: اناث | HO5: ذكور | HP5: اناث | HQ5: ذكور | HR5: اناث | HS5: المجموع | HT5: ذكور | HU5: اناث | HV5: ذكور | HW5: اناث | HX5: ذكور | HY5: اناث | HZ5: ذكور | IA5: اناث | IB5: ذكور | IC5: اناث | IE5: ذكور | IF5: اناث | IG5: نعم | IH5: كلا | II5: نعم | IJ5: كلا | IK5: نعم | IL5: كلا | IW5: نعم | IX5: كلا | IY5: المدير | IZ5: رقم الموبايل | JA5: اقرب نقطة
A6: النجف | B6: المركز | C6: 1 | D6: 1400724 | E6: مدينة العلم | G6: 1 | H6: 1 | K6: 1 | N6: 1 | R6: 1 | V6: 1 | Y6: 5 | AA6: 9 | AC6: 13 | AE6: 6 | AG6: 9 | AI6: 8 | AK6: 4 | AM6: =AK6+AI6+AG6+AE6+AC6+AA6+Y6 -> 54 | AN6: =AL6+AJ6+AH6+AF6+AD6+AB6+Z6 -> 0 | AO6: =AN6+AM6 -> 54 | AR6: 2 | AT6: 10 | AV6: 12 | AX6: 13 | AZ6: 8 | BB6: 6 | BD6: =BB6+AZ6+AX6+AV6+AT6+AR6+AP6 -> 51 | BE6: =BC6+BA6+AY6+AW6+AU6+AS6+AQ6 -> 0 | BF6: =BE6+BD6 -> 51 | BG6: 1 | BI6: 1 | BK6: 12 | BM6: 19 | BO6: 33 | BQ6: 31 | BS6: 30 | BU6: =BS6+BQ6+BO6+BM6+BK6+BI6+BG6 -> 127 | BV6: =BT6+BR6+BP6+BN6+BL6+BJ6+BH6 -> 0 | BW6: =BV6+BU6 -> 127 | BX6: =BG6+AP6+Y6 -> 6 | BY6: =BH6+AQ6+Z6 -> 0 | BZ6: =BI6+AR6+AA6 -> 12 | CA6: =BJ6+AS6+AB6 -> 0 | CB6: =BK6+AT6+AC6 -> 35 | CC6: =BL6+AU6+AD6 -> 0 | CD6: =BM6+AV6+AE6 -> 37 | CE6: =BN6+AW6+AF6 -> 0 | ... CK6: =BT6+BC6+AL6 -> 0 | CL6: =CJ6+CH6+CF6+CD6+CB6+BZ6+BX6 -> 232 | CM6: =CK6+CI6+CG6+CE6+CC6+CA6+BY6 -> 0 | CN6: =CM6+CL6 -> 232 | CO6: 2 | CR6: 2 | CU6: 4 | CX6: =CU6+CR6+CO6 -> 8 | CY6: =CV6+CS6+CP6 -> 0 | CZ6: =CW6+CT6+CQ6 -> 0 | DA6: =CZ6+CY6+CX6 -> 8 | DB6: 23 | DH6: =DF6+DD6+DB6 -> 23 | DI6: =DG6+DE6+DC6 -> 0 | DJ6: =DI6+DH6 -> 23 | DK6: 31 | DM6: 39 | DO6: 66 | DQ6: =DO6+DM6+DK6 -> 136 | DR6: =DP6+DN6+DL6 -> 0 | DS6: =DR6+DQ6 -> 136 | DT6: 11 | DV6: 12 | DX6: 20 | DZ6: =DX6+DV6+DT6 -> 43 | EA6: =DY6+DW6+DU6 -> 0 | EB6: =EA6+DZ6 -> 43 | EI6: =EG6+EE6+EC6 -> 0 | EJ6: =EH6+EF6+ED6 -> 0 | EK6: =EJ6+EI6 -> 0 | ER6: =EP6+EN6+EL6 -> 0 | ES6: =EQ6+EO6+EM6 -> 0 | ET6: =ES6+ER6 -> 0 | EU6: 1 | EW6: 1 | EY6: 4 | EZ6: 1 | FC6: =FA6+EY6+EW6+EU6 -> 6 | FD6: =FB6+EZ6+EX6+EV6 -> 1 | FE6: =FD6+FC6 -> 7 | FN6: 2 | FU6: =FT6+FS6+FR6+FN6+FL6+FH6+FF6+FP6+FJ6 -> 2 | FV6: =FO6+FM6+FI6+FG6+FK6+FQ6 -> 0 | FW6: =FV6+FU6 -> 2 | GB6: 3 | GC6: 1 | GH6: 2 | GJ6: 1 | GN6: =GL6+GJ6+GH6+GF6+GD6+GB6+FZ6+FX6 -> 6 | GO6: =GM6+GK6+GI6+GG6+GE6+GC6+GA6+FY6 -> 1 | GP6: =GO6+GN6 -> 7 | GQ6: 6 | GR6: 1 | GW6: =GU6+GS6+GQ6 -> 6 | GX6: =GV6+GT6+GR6 -> 1 | GY6: =GX6+GW6 -> 7 | GZ6: 5 | HA6: 1 | HO6: 1 | HQ6: =HO6+GZ6+HM6+HJ6+HH6+HF6+HD6+HB6 -> 6 | HR6: =HP6+HA6+HN6+HL6+HK6+HI6+HG6+HE6+HC6 -> 1 | HS6: =HR6+HQ6 -> 7 | HV6: 6 | HW6: 1 | IB6: =HZ6+HX6+HV6+HT6 -> 6 | IC6: =IA6+HY6+HW6+HU6 -> 1 | ID6: =IC6+IB6 -> 7 | IH6: 1 | IJ6: 1 | IL6: 1 | IS6: 8 | IT6: 1 | IU6: 3 | IX6: 1 | IY6: سعد طارق سعد | IZ6: 7801262206 | JA6: قرب تقاطع العسكريين - حي العلماء مع مدرسة مصطفى جواد الابتدائية
A7: النجف | B7: المركز | C7: 2 | D7: 1400725 | E7: الاقمار المنيرة | G7: 1 | I7: 1 | K7: 1 | N7: 1 | R7: 1 | V7: 1 | Z7: 2 | AB7: 1 | AF7: 1 | AM7: =AK7+AI7+AG7+AE7+AC7+AA7+Y7 -> 0 | AN7: =AL7+AJ7+AH7+AF7+AD7+AB7+Z7 -> 4 | AO7: =AN7+AM7 -> 4 | AS7: 1 | AU7: 5 | AW7: 2 | AY7: 3 | BA7: 2 | BC7: 2 | BD7: =BB7+AZ7+AX7+AV7+AT7+AR7+AP7 -> 0 | BE7: =BC7+BA7+AY7+AW7+AU7+AS7+AQ7 -> 15 | BF7: =BE7+BD7 -> 15 | BL7: 5 | BN7: 2 | BP7: 7 | BR7: 5 | BT7: 4 | BU7: =BS7+BQ7+BO7+BM7+BK7+BI7+BG7 -> 0 | BV7: =BT7+BR7+BP7+BN7+BL7+BJ7+BH7 -> 23 | BW7: =BV7+BU7 -> 23 | BX7: =BG7+AP7+Y7 -> 0 | BY7: =BH7+AQ7+Z7 -> 2 | BZ7: =BI7+AR7+AA7 -> 0 | CA7: =BJ7+AS7+AB7 -> 2 | CB7: =BK7+AT7+AC7 -> 0 | CC7: =BL7+AU7+AD7 -> 10 | CD7: =BM7+AV7+AE7 -> 0 | CE7: =BN7+AW7+AF7 -> 5 | ... CK7: =BT7+BC7+AL7 -> 6 | CL7: =CJ7+CH7+CF7+CD7+CB7+BZ7+BX7 -> 0 | CM7: =CK7+CI7+CG7+CE7+CC7+CA7+BY7 -> 42 | CN7: =CM7+CL7 -> 42 | CP7: 1 | CS7: 1 | CV7: 1 | CX7: =CU7+CR7+CO7 -> 0 | CY7: =CV7+CS7+CP7 -> 3 | CZ7: =CW7+CT7+CQ7 -> 0 | DA7: =CZ7+CY7+CX7 -> 3 | DC7: 1 | DG7: 7 | DH7: =DF7+DD7+DB7 -> 0 | DI7: =DG7+DE7+DC7 -> 8 | DJ7: =DI7+DH7 -> 8 | DL7: 4 | DN7: 10 | DP7: 28 | DQ7: =DO7+DM7+DK7 -> 0 | DR7: =DP7+DN7+DL7 -> 42 | DS7: =DR7+DQ7 -> 42 | DU7: 6 | DW7: 5 | DY7: 10 | DZ7: =DX7+DV7+DT7 -> 0 | EA7: =DY7+DW7+DU7 -> 21 | EB7: =EA7+DZ7 -> 21 | EI7: =EG7+EE7+EC7 -> 0 | EJ7: =EH7+EF7+ED7 -> 0 | EK7: =EJ7+EI7 -> 0 | ER7: =EP7+EN7+EL7 -> 0 | ES7: =EQ7+EO7+EM7 -> 0 | ET7: =ES7+ER7 -> 0 | EV7: 1 | EZ7: 2 | FC7: =FA7+EY7+EW7+EU7 -> 0 | FD7: =FB7+EZ7+EX7+EV7 -> 3 | FE7: =FD7+FC7 -> 3 | FO7: 1 | FU7: =FT7+FS7+FR7+FN7+FL7+FH7+FF7+FP7+FJ7 -> 0 | FV7: =FO7+FM7+FI7+FG7+FK7+FQ7 -> 1 | FW7: =FV7+FU7 -> 1 | GI7: 3 | GN7: =GL7+GJ7+GH7+GF7+GD7+GB7+FZ7+FX7 -> 0 | GO7: =GM7+GK7+GI7+GG7+GE7+GC7+GA7+FY7 -> 3 | GP7: =GO7+GN7 -> 3 | GR7: 3 | GW7: =GU7+GS7+GQ7 -> 0 | GX7: =GV7+GT7+GR7 -> 3 | GY7: =GX7+GW7 -> 3 | HA7: 3 | HQ7: =HO7+GZ7+HM7+HJ7+HH7+HF7+HD7+HB7 -> 0 | HR7: =HP7+HA7+HN7+HL7+HK7+HI7+HG7+HE7+HC7 -> 3 | HS7: =HR7+HQ7 -> 3 | HW7: 3 | IB7: =HZ7+HX7+HV7+HT7 -> 0 | IC7: =IA7+HY7+HW7+HU7 -> 3 | ID7: =IC7+IB7 -> 3 | IF7: 1 | IH7: 1 | IJ7: 1 | IL7: 1 | IQ7: 52 | IR7: 10 | IS7: 7 | IT7: 1 | IU7: 1 | IX7: 1 | IY7: اسراء مصطفى محسن | IZ7: 7812422149 | JA7: حي السلام - مع مدرسة الدعاء المستجاب الابتدائية
A8: النجف | B8: المركز | C8: 3 | D8: 1400726 | E8: اعلام الدين | G8: 1 | H8: 1 | K8: 1 | N8: 1 | R8: 1 | V8: 1 | Y8: 5 | AA8: 7 | AC8: 10 | AE8: 8 | AG8: 1 | AI8: 1 | AM8: =AK8+AI8+AG8+AE8+AC8+AA8+Y8 -> 32 | AN8: =AL8+AJ8+AH8+AF8+AD8+AB8+Z8 -> 0 | AO8: =AN8+AM8 -> 32 | AP8: 6 | AR8: 8 | AT8: 11 | AV8: 5 | AX8: 16 | AZ8: 3 | BB8: 2 | BD8: =BB8+AZ8+AX8+AV8+AT8+AR8+AP8 -> 51 | BE8: =BC8+BA8+AY8+AW8+AU8+AS8+AQ8 -> 0 | BF8: =BE8+BD8 -> 51 | BI8: 3 | BK8: 3 | BM8: 11 | BO8: 15 | BQ8: 5 | BS8: 7 | BU8: =BS8+BQ8+BO8+BM8+BK8+BI8+BG8 -> 44 | BV8: =BT8+BR8+BP8+BN8+BL8+BJ8+BH8 -> 0 | BW8: =BV8+BU8 -> 44 | BX8: =BG8+AP8+Y8 -> 11 | BY8: =BH8+AQ8+Z8 -> 0 | BZ8: =BI8+AR8+AA8 -> 18 | CA8: =BJ8+AS8+AB8 -> 0 | CB8: =BK8+AT8+AC8 -> 24 | CC8: =BL8+AU8+AD8 -> 0 | CD8: =BM8+AV8+AE8 -> 24 | CE8: =BN8+AW8+AF8 -> 0 | ... CK8: =BT8+BC8+AL8 -> 0 | CL8: =CJ8+CH8+CF8+CD8+CB8+BZ8+BX8 -> 127 | CM8: =CK8+CI8+CG8+CE8+CC8+CA8+BY8 -> 0 | CN8: =CM8+CL8 -> 127 | CO8: 2 | CR8: 2 | CU8: 2 | CX8: =CU8+CR8+CO8 -> 6 | CY8: =CV8+CS8+CP8 -> 0 | CZ8: =CW8+CT8+CQ8 -> 0 | DA8: =CZ8+CY8+CX8 -> 6 | DB8: 10 | DD8: 8 | DF8: 25 | DH8: =DF8+DD8+DB8 -> 43 | DI8: =DG8+DE8+DC8 -> 0 | DJ8: =DI8+DH8 -> 43 | DK8: 16 | DM8: 20 | DO8: 32 | DQ8: =DO8+DM8+DK8 -> 68 | DR8: =DP8+DN8+DL8 -> 0 | DS8: =DR8+DQ8 -> 68 | DT8: 5 | DV8: 4 | DX8: 1 | DZ8: =DX8+DV8+DT8 -> 10 | EA8: =DY8+DW8+DU8 -> 0 | EB8: =EA8+DZ8 -> 10 | EI8: =EG8+EE8+EC8 -> 0 | EJ8: =EH8+EF8+ED8 -> 0 | EK8: =EJ8+EI8 -> 0 | ER8: =EP8+EN8+EL8 -> 0 | ES8: =EQ8+EO8+EM8 -> 0 | ET8: =ES8+ER8 -> 0 | EU8: 1 | EY8: 3 | EZ8: 1 | FC8: =FA8+EY8+EW8+EU8 -> 4 | FD8: =FB8+EZ8+EX8+EV8 -> 1 | FE8: =FD8+FC8 -> 5 | FN8: 2 | FU8: =FT8+FS8+FR8+FN8+FL8+FH8+FF8+FP8+FJ8 -> 2 | FV8: =FO8+FM8+FI8+FG8+FK8+FQ8 -> 0 | FW8: =FV8+FU8 -> 2 | GB8: 3 | GC8: 1 | GH8: 1 | GN8: =GL8+GJ8+GH8+GF8+GD8+GB8+FZ8+FX8 -> 4 | GO8: =GM8+GK8+GI8+GG8+GE8+GC8+GA8+FY8 -> 1 | GP8: =GO8+GN8 -> 5 | GQ8: 4 | GR8: 1 | GW8: =GU8+GS8+GQ8 -> 4 | GX8: =GV8+GT8+GR8 -> 1 | GY8: =GX8+GW8 -> 5 | GZ8: 4 | HA8: 1 | HQ8: =HO8+GZ8+HM8+HJ8+HH8+HF8+HD8+HB8 -> 4 | HR8: =HP8+HA8+HN8+HL8+HK8+HI8+HG8+HE8+HC8 -> 1 | HS8: =HR8+HQ8 -> 5 | HV8: 4 | HW8: 1 | IB8: =HZ8+HX8+HV8+HT8 -> 4 | IC8: =IA8+HY8+HW8+HU8 -> 1 | ID8: =IC8+IB8 -> 5 | IG8: 1 | IJ8: 1 | IL8: 1 | IT8: 1 | IU8: 2 | IX8: 1 | IY8: كرار ابراهيم حطاب | IZ8: 7810640813 | JA8: حي الانصار - مع م . الفارس العربي للبنين
A9: النجف | B9: المركز | C9: 4 | D9: 1400727 | E9: البيت المعمور | G9: 1 | I9: 1 | K9: 1 | N9: 1 | R9: 1 | V9: 1 | Z9: 15 | AB9: 9 | AD9: 12 | AF9: 3 | AH9: 3 | AJ9: 3 | AM9: =AK9+AI9+AG9+AE9+AC9+AA9+Y9 -> 0 | AN9: =AL9+AJ9+AH9+AF9+AD9+AB9+Z9 -> 45 | AO9: =AN9+AM9 -> 45 | AQ9: 8 | AS9: 9 | AU9: 7 | AW9: 5 | AY9: 3 | BA9: 2 | BD9: =BB9+AZ9+AX9+AV9+AT9+AR9+AP9 -> 0 | BE9: =BC9+BA9+AY9+AW9+AU9+AS9+AQ9 -> 34 | BF9: =BE9+BD9 -> 34 | BH9: 4 | BJ9: 9 | BL9: 5 | BN9: 3 | BP9: 7 | BR9: 2 | BT9: 2 | BU9: =BS9+BQ9+BO9+BM9+BK9+BI9+BG9 -> 0 | BV9: =BT9+BR9+BP9+BN9+BL9+BJ9+BH9 -> 32 | BW9: =BV9+BU9 -> 32 | BX9: =BG9+AP9+Y9 -> 0 | BY9: =BH9+AQ9+Z9 -> 27 | BZ9: =BI9+AR9+AA9 -> 0 | CA9: =BJ9+AS9+AB9 -> 27 | CB9: =BK9+AT9+AC9 -> 0 | CC9: =BL9+AU9+AD9 -> 24 | CD9: =BM9+AV9+AE9 -> 0 | CE9: =BN9+AW9+AF9 -> 11 | ... CK9: =BT9+BC9+AL9 -> 2 | CL9: =CJ9+CH9+CF9+CD9+CB9+BZ9+BX9 -> 0 | CM9: =CK9+CI9+CG9+CE9+CC9+CA9+BY9 -> 111 | CN9: =CM9+CL9 -> 111 | CP9: 1 | CS9: 1 | CV9: 1 | CX9: =CU9+CR9+CO9 -> 0 | CY9: =CV9+CS9+CP9 -> 3 | CZ9: =CW9+CT9+CQ9 -> 0 | DA9: =CZ9+CY9+CX9 -> 3 | DC9: 4 | DE9: 2 | DG9: 5 | DH9: =DF9+DD9+DB9 -> 0 | DI9: =DG9+DE9+DC9 -> 11 | DJ9: =DI9+DH9 -> 11 | DL9: 22 | DN9: 23 | DP9: 31 | DQ9: =DO9+DM9+DK9 -> 0 | DR9: =DP9+DN9+DL9 -> 76 | DS9: =DR9+DQ9 -> 76 | DU9: 14 | DW9: 6 | DY9: 3 | DZ9: =DX9+DV9+DT9 -> 0 | EA9: =DY9+DW9+DU9 -> 23 | EB9: =EA9+DZ9 -> 23 | EI9: =EG9+EE9+EC9 -> 0 | EJ9: =EH9+EF9+ED9 -> 0 | EK9: =EJ9+EI9 -> 0 | ER9: =EP9+EN9+EL9 -> 0 | ES9: =EQ9+EO9+EM9 -> 0 | ET9: =ES9+ER9 -> 0 | EV9: 1 | EX9: 1 | EZ9: 5 | FC9: =FA9+EY9+EW9+EU9 -> 0 | FD9: =FB9+EZ9+EX9+EV9 -> 7 | FE9: =FD9+FC9 -> 7 | FO9: 1 | FU9: =FT9+FS9+FR9+FN9+FL9+FH9+FF9+FP9+FJ9 -> 0 | FV9: =FO9+FM9+FI9+FG9+FK9+FQ9 -> 1 | FW9: =FV9+FU9 -> 1 | GC9: 2 | GI9: 4 | GK9: 1 | GN9: =GL9+GJ9+GH9+GF9+GD9+GB9+FZ9+FX9 -> 0 | GO9: =GM9+GK9+GI9+GG9+GE9+GC9+GA9+FY9 -> 7 | GP9: =GO9+GN9 -> 7 | GR9: 7 | GW9: =GU9+GS9+GQ9 -> 0 | GX9: =GV9+GT9+GR9 -> 7 | GY9: =GX9+GW9 -> 7 | HA9: 7 | HQ9: =HO9+GZ9+HM9+HJ9+HH9+HF9+HD9+HB9 -> 0 | HR9: =HP9+HA9+HN9+HL9+HK9+HI9+HG9+HE9+HC9 -> 7 | HS9: =HR9+HQ9 -> 7 | HU9: 2 | HW9: 5 | IB9: =HZ9+HX9+HV9+HT9 -> 0 | IC9: =IA9+HY9+HW9+HU9 -> 7 | ID9: =IC9+IB9 -> 7 | IH9: 1 | IJ9: 1 | IL9: 1 | IT9: 1 | IU9: 1 | IV9: 1 | IX9: 1 | IY9: هيفاء منعم شاكر | IZ9: 7804303945 | JA9: الجديدة الرابعة - قرب اعدادية الصناعة مع مدرسة الوطن الابتدائية
A10: النجف | B10: المركز | C10: 5 | D10: 1400810 | E10: الركن اليماني | G10: 1 | H10: 1 | K10: 1 | N10: 1 | R10: 1 | V10: 1 | Y10: 12 | AA10: 21 | AC10: 20 | AE10: 15 | AG10: 7 | AI10: 2 | AK10: 4 | AM10: =AK10+AI10+AG10+AE10+AC10+AA10+Y10 -> 81 | AN10: =AL10+AJ10+AH10+AF10+AD10+AB10+Z10 -> 0 | AO10: =AN10+AM10 -> 81 | AR10: 1 | AT10: 9 | AV10: 13 | AX10: 10 | AZ10: 11 | BB10: 8 | BD10: =BB10+AZ10+AX10+AV10+AT10+AR10+AP10 -> 52 | BE10: =BC10+BA10+AY10+AW10+AU10+AS10+AQ10 -> 0 | BF10: =BE10+BD10 -> 52 | BI10: 1 | BK10: 4 | BM10: 12 | BO10: 21 | BQ10: 10 | BS10: 6 | BU10: =BS10+BQ10+BO10+BM10+BK10+BI10+BG10 -> 54 | BV10: =BT10+BR10+BP10+BN10+BL10+BJ10+BH10 -> 0 | BW10: =BV10+BU10 -> 54 | BX10: =BG10+AP10+Y10 -> 12 | BY10: =BH10+AQ10+Z10 -> 0 | BZ10: =BI10+AR10+AA10 -> 23 | CA10: =BJ10+AS10+AB10 -> 0 | CB10: =BK10+AT10+AC10 -> 33 | CC10: =BL10+AU10+AD10 -> 0 | CD10: =BM10+AV10+AE10 -> 40 | CE10: =BN10+AW10+AF10 -> 0 | ... CK10: =BT10+BC10+AL10 -> 0 | CL10: =CJ10+CH10+CF10+CD10+CB10+BZ10+BX10 -> 187 | CM10: =CK10+CI10+CG10+CE10+CC10+CA10+BY10 -> 0 | CN10: =CM10+CL10 -> 187 | CO10: 2 | CR10: 2 | CU10: 2 | CX10: =CU10+CR10+CO10 -> 6 | CY10: =CV10+CS10+CP10 -> 0 | CZ10: =CW10+CT10+CQ10 -> 0 | DA10: =CZ10+CY10+CX10 -> 6 | DH10: =DF10+DD10+DB10 -> 0 | DI10: =DG10+DE10+DC10 -> 0 | DJ10: =DI10+DH10 -> 0 | DK10: 29 | DM10: 27 | DO10: 51 | DQ10: =DO10+DM10+DK10 -> 107 | DR10: =DP10+DN10+DL10 -> 0 | DS10: =DR10+DQ10 -> 107 | DT10: 40 | DV10: 4 | DX10: 11 | DZ10: =DX10+DV10+DT10 -> 55 | EA10: =DY10+DW10+DU10 -> 0 | EB10: =EA10+DZ10 -> 55 | EI10: =EG10+EE10+EC10 -> 0 | EJ10: =EH10+EF10+ED10 -> 0 | EK10: =EJ10+EI10 -> 0 | ER10: =EP10+EN10+EL10 -> 0 | ES10: =EQ10+EO10+EM10 -> 0 | ET10: =ES10+ER10 -> 0 | EU10: 1 | EW10: 1 | EY10: 5 | FC10: =FA10+EY10+EW10+EU10 -> 7 | FD10: =FB10+EZ10+EX10+EV10 -> 0 | FE10: =FD10+FC10 -> 7 | FN10: 1 | FU10: =FT10+FS10+FR10+FN10+FL10+FH10+FF10+FP10+FJ10 -> 1 | FV10: =FO10+FM10+FI10+FG10+FK10+FQ10 -> 0 | FW10: =FV10+FU10 -> 1 | GB10: 3 | GH10: 4 | GN10: =GL10+GJ10+GH10+GF10+GD10+GB10+FZ10+FX10 -> 7 | GO10: =GM10+GK10+GI10+GG10+GE10+GC10+GA10+FY10 -> 0 | GP10: =GO10+GN10 -> 7 | GQ10: 7 | GW10: =GU10+GS10+GQ10 -> 7 | GX10: =GV10+GT10+GR10 -> 0 | GY10: =GX10+GW10 -> 7 | GZ10: 6 | HJ10: 1 | HQ10: =HO10+GZ10+HM10+HJ10+HH10+HF10+HD10+HB10 -> 7 | HR10: =HP10+HA10+HN10+HL10+HK10+HI10+HG10+HE10+HC10 -> 0 | HS10: =HR10+HQ10 -> 7 | HV10: 7 | IB10: =HZ10+HX10+HV10+HT10 -> 7 | IC10: =IA10+HY10+HW10+HU10 -> 0 | ID10: =IC10+IB10 -> 7 | IE10: 6 | IH10: 1 | IJ10: 1 | IL10: 1 | IT10: 1 | IU10: 2 | IX10: 1 | IY10: نسيم كريم عباس | IZ10: 7807478284 | JA10: الجديدة الرابعة - قرب سوق الحديقة مع م . النهروان للبنين
A11: النجف | B11: المركز | C11: 6 | D11: 1400811 | E11: الجنائن المعلقة | G11: 1 | I11: 1 | K11: 1 | N11: 1 | R11: 1 | V11: 1 | Z11: 7 | AB11: 5 | AD11: 5 | AF11: 3 | AH11: 5 | AJ11: 5 | AL11: 5 | AM11: =AK11+AI11+AG11+AE11+AC11+AA11+Y11 -> 0 | AN11: =AL11+AJ11+AH11+AF11+AD11+AB11+Z11 -> 35 | AO11: =AN11+AM11 -> 35 | AQ11: 2 | AS11: 5 | AU11: 10 | AW11: 5 | AY11: 7 | BA11: 5 | BC11: 5 | BD11: =BB11+AZ11+AX11+AV11+AT11+AR11+AP11 -> 0 | BE11: =BC11+BA11+AY11+AW11+AU11+AS11+AQ11 -> 39 | BF11: =BE11+BD11 -> 39 | BH11: 4 | BJ11: 4 | BL11: 4 | BN11: 7 | BP11: 9 | BR11: 4 | BT11: 5 | BU11: =BS11+BQ11+BO11+BM11+BK11+BI11+BG11 -> 0 | BV11: =BT11+BR11+BP11+BN11+BL11+BJ11+BH11 -> 37 | BW11: =BV11+BU11 -> 37 | BX11: =BG11+AP11+Y11 -> 0 | BY11: =BH11+AQ11+Z11 -> 13 | BZ11: =BI11+AR11+AA11 -> 0 | CA11: =BJ11+AS11+AB11 -> 14 | CB11: =BK11+AT11+AC11 -> 0 | CC11: =BL11+AU11+AD11 -> 19 | CD11: =BM11+AV11+AE11 -> 0 | CE11: =BN11+AW11+AF11 -> 15 | ... CK11: =BT11+BC11+AL11 -> 15 | CL11: =CJ11+CH11+CF11+CD11+CB11+BZ11+BX11 -> 0 | CM11: =CK11+CI11+CG11+CE11+CC11+CA11+BY11 -> 111 | CN11: =CM11+CL11 -> 111 | CP11: 2 | CS11: 2 | CV11: 2 | CX11: =CU11+CR11+CO11 -> 0 | CY11: =CV11+CS11+CP11 -> 6 | CZ11: =CW11+CT11+CQ11 -> 0 | DA11: =CZ11+CY11+CX11 -> 6 | DC11: 1 | DE11: 5 | DG11: 4 | DH11: =DF11+DD11+DB11 -> 0 | DI11: =DG11+DE11+DC11 -> 10 | DJ11: =DI11+DH11 -> 10 | DL11: 11 | DN11: 20 | DP11: 34 | DQ11: =DO11+DM11+DK11 -> 0 | DR11: =DP11+DN11+DL11 -> 65 | DS11: =DR11+DQ11 -> 65 | DU11: 3 | DW11: 11 | DZ11: =DX11+DV11+DT11 -> 0 | EA11: =DY11+DW11+DU11 -> 14 | EB11: =EA11+DZ11 -> 14 | EI11: =EG11+EE11+EC11 -> 0 | EJ11: =EH11+EF11+ED11 -> 0 | EK11: =EJ11+EI11 -> 0 | ER11: =EP11+EN11+EL11 -> 0 | ES11: =EQ11+EO11+EM11 -> 0 | ET11: =ES11+ER11 -> 0 | EV11: 1 | EZ11: 7 | FC11: =FA11+EY11+EW11+EU11 -> 0 | FD11: =FB11+EZ11+EX11+EV11 -> 8 | FE11: =FD11+FC11 -> 8 | FO11: 1 | FU11: =FT11+FS11+FR11+FN11+FL11+FH11+FF11+FP11+FJ11 -> 0 | FV11: =FO11+FM11+FI11+FG11+FK11+FQ11 -> 1 | FW11: =FV11+FU11 -> 1 | GC11: 2 | GI11: 6 | GN11: =GL11+GJ11+GH11+GF11+GD11+GB11+FZ11+FX11 -> 0 | GO11: =GM11+GK11+GI11+GG11+GE11+GC11+GA11+FY11 -> 8 | GP11: =GO11+GN11 -> 8 | GR11: 8 | GW11: =GU11+GS11+GQ11 -> 0 | GX11: =GV11+GT11+GR11 -> 8 | GY11: =GX11+GW11 -> 8 | HA11: 8 | HQ11: =HO11+GZ11+HM11+HJ11+HH11+HF11+HD11+HB11 -> 0 | HR11: =HP11+HA11+HN11+HL11+HK11+HI11+HG11+HE11+HC11 -> 8 | HS11: =HR11+HQ11 -> 8 | HW11: 7 | IA11: 1 | IB11: =HZ11+HX11+HV11+HT11 -> 0 | IC11: =IA11+HY11+HW11+HU11 -> 8 | ID11: =IC11+IB11 -> 8 | IF11: 3 | IH11: 1 | IJ11: 1 | IL11: 1 | IQ11: 50 | IS11: 5 | IT11: 2 | IU11: 2 | IX11: 1 | IY11: غسق مجيد حميد | IZ11: 7828100829 | JA11: الجديدة الثالثة - مقابل متنزه حي المعلمين مع م . الخنساء للبنات
A12: النجف | B12: المركز | C12: 7 | D12: 1400812 | E12: الحزام الاخضر | G12: 1 | I12: 1 | K12: 1 | N12: 1 | R12: 1 | V12: 1 | Z12: 3 | AB12: 4 | AD12: 3 | AF12: 4 | AH12: 4 | AJ12: 4 | AL12: 2 | AM12: =AK12+AI12+AG12+AE12+AC12+AA12+Y12 -> 0 | AN12: =AL12+AJ12+AH12+AF12+AD12+AB12+Z12 -> 24 | AO12: =AN12+AM12 -> 24 | AS12: 2 | AU12: 7 | AW12: 5 | AY12: 10 | BA12: 11 | BC12: 9 | BD12: =BB12+AZ12+AX12+AV12+AT12+AR12+AP12 -> 0 | BE12: =BC12+BA12+AY12+AW12+AU12+AS12+AQ12 -> 44 | BF12: =BE12+BD12 -> 44 | BJ12: 1 | BL12: 3 | BN12: 5 | BP12: 8 | BR12: 7 | BT12: 10 | BU12: =BS12+BQ12+BO12+BM12+BK12+BI12+BG12 -> 0 | BV12: =BT12+BR12+BP12+BN12+BL12+BJ12+BH12 -> 34 | BW12: =BV12+BU12 -> 34 | BX12: =BG12+AP12+Y12 -> 0 | BY12: =BH12+AQ12+Z12 -> 3 | BZ12: =BI12+AR12+AA12 -> 0 | CA12: =BJ12+AS12+AB12 -> 7 | CB12: =BK12+AT12+AC12 -> 0 | CC12: =BL12+AU12+AD12 -> 13 | CD12: =BM12+AV12+AE12 -> 0 | CE12: =BN12+AW12+AF12 -> 14 | ... CK12: =BT12+BC12+AL12 -> 21 | CL12: =CJ12+CH12+CF12+CD12+CB12+BZ12+BX12 -> 0 | CM12: =CK12+CI12+CG12+CE12+CC12+CA12+BY12 -> 102 | CN12: =CM12+CL12 -> 102 | CP12: 1 | CS12: 2 | CV12: 1 | CX12: =CU12+CR12+CO12 -> 0 | CY12: =CV12+CS12+CP12 -> 4 | CZ12: =CW12+CT12+CQ12 -> 0 | DA12: =CZ12+CY12+CX12 -> 4 | DC12: 13 | DE12: 15 | DG12: 7 | DH12: =DF12+DD12+DB12 -> 0 | DI12: =DG12+DE12+DC12 -> 35 | DJ12: =DI12+DH12 -> 35 | DL12: 18 | DN12: 24 | DP12: 33 | DQ12: =DO12+DM12+DK12 -> 0 | DR12: =DP12+DN12+DL12 -> 75 | DS12: =DR12+DQ12 -> 75 | DU12: 15 | DW12: 25 | DY12: 14 | DZ12: =DX12+DV12+DT12 -> 0 | EA12: =DY12+DW12+DU12 -> 54 | EB12: =EA12+DZ12 -> 54 | EI12: =EG12+EE12+EC12 -> 0 | EJ12: =EH12+EF12+ED12 -> 0 | EK12: =EJ12+EI12 -> 0 | ER12: =EP12+EN12+EL12 -> 0 | ES12: =EQ12+EO12+EM12 -> 0 | ET12: =ES12+ER12 -> 0 | EV12: 1 | EX12: 1 | EZ12: 3 | FC12: =FA12+EY12+EW12+EU12 -> 0 | FD12: =FB12+EZ12+EX12+EV12 -> 5 | FE12: =FD12+FC12 -> 5 | FO12: 1 | FU12: =FT12+FS12+FR12+FN12+FL12+FH12+FF12+FP12+FJ12 -> 0 | FV12: =FO12+FM12+FI12+FG12+FK12+FQ12 -> 1 | FW12: =FV12+FU12 -> 1 | GC12: 1 | GI12: 3 | GM12: 1 | GN12: =GL12+GJ12+GH12+GF12+GD12+GB12+FZ12+FX12 -> 0 | GO12: =GM12+GK12+GI12+GG12+GE12+GC12+GA12+FY12 -> 5 | GP12: =GO12+GN12 -> 5 | GR12: 5 | GW12: =GU12+GS12+GQ12 -> 0 | GX12: =GV12+GT12+GR12 -> 5 | GY12: =GX12+GW12 -> 5 | HA12: 4 | HL12: 1 | HQ12: =HO12+GZ12+HM12+HJ12+HH12+HF12+HD12+HB12 -> 0 | HR12: =HP12+HA12+HN12+HL12+HK12+HI12+HG12+HE12+HC12 -> 5 | HS12: =HR12+HQ12 -> 5 | HW12: 5 | IB12: =HZ12+HX12+HV12+HT12 -> 0 | IC12: =IA12+HY12+HW12+HU12 -> 5 | ID12: =IC12+IB12 -> 5 | IH12: 1 | IJ12: 1 | IL12: 1 | IT12: 1 | IU12: 1 | IX12: 1 | IY12: سحر موسى سلمان | IZ12: 7840007696 | JA12: حي الميلاد - مع مدرسة اليعقوبي
A13: النجف | B13: المركز | C13: 8 | D13: 1400962 | E13: الجواهر | G13: 1 | I13: 1 | K13: 1 | N13: 1 | R13: 1 | V13: 1 | Z13: 10 | AB13: 3 | AD13: 3 | AF13: 1 | AH13: 2 | AL13: 3 | AM13: =AK13+AI13+AG13+AE13+AC13+AA13+Y13 -> 0 | AN13: =AL13+AJ13+AH13+AF13+AD13+AB13+Z13 -> 22 | AO13: =AN13+AM13 -> 22 | AQ13: 6 | AS13: 3 | AU13: 5 | AW13: 6 | AY13: 3 | BA13: 6 | BC13: 3 | BD13: =BB13+AZ13+AX13+AV13+AT13+AR13+AP13 -> 0 | BE13: =BC13+BA13+AY13+AW13+AU13+AS13+AQ13 -> 32 | BF13: =BE13+BD13 -> 32 | BH13: 7 | BJ13: 7 | BL13: 13 | BN13: 13 | BP13: 13 | BR13: 5 | BT13: 13 | BU13: =BS13+BQ13+BO13+BM13+BK13+BI13+BG13 -> 0 | BV13: =BT13+BR13+BP13+BN13+BL13+BJ13+BH13 -> 71 | BW13: =BV13+BU13 -> 71 | BX13: =BG13+AP13+Y13 -> 0 | BY13: =BH13+AQ13+Z13 -> 23 | BZ13: =BI13+AR13+AA13 -> 0 | CA13: =BJ13+AS13+AB13 -> 13 | CB13: =BK13+AT13+AC13 -> 0 | CC13: =BL13+AU13+AD13 -> 21 | CD13: =BM13+AV13+AE13 -> 0 | CE13: =BN13+AW13+AF13 -> 20 | ... CK13: =BT13+BC13+AL13 -> 19 | CL13: =CJ13+CH13+CF13+CD13+CB13+BZ13+BX13 -> 0 | CM13: =CK13+CI13+CG13+CE13+CC13+CA13+BY13 -> 125 | CN13: =CM13+CL13 -> 125 | CP13: 1 | CS13: 1 | CV13: 2 | CX13: =CU13+CR13+CO13 -> 0 | CY13: =CV13+CS13+CP13 -> 4 | CZ13: =CW13+CT13+CQ13 -> 0 | DA13: =CZ13+CY13+CX13 -> 4 | DH13: =DF13+DD13+DB13 -> 0 | DI13: =DG13+DE13+DC13 -> 0 | DJ13: =DI13+DH13 -> 0 | DL13: 12 | DN13: 18 | DP13: 55 | DQ13: =DO13+DM13+DK13 -> 0 | DR13: =DP13+DN13+DL13 -> 85 | DS13: =DR13+DQ13 -> 85 | DU13: 8 | DW13: 9 | DY13: 40 | DZ13: =DX13+DV13+DT13 -> 0 | EA13: =DY13+DW13+DU13 -> 57 | EB13: =EA13+DZ13 -> 57 | EI13: =EG13+EE13+EC13 -> 0 | EJ13: =EH13+EF13+ED13 -> 0 | EK13: =EJ13+EI13 -> 0 | ER13: =EP13+EN13+EL13 -> 0 | ES13: =EQ13+EO13+EM13 -> 0 | ET13: =ES13+ER13 -> 0 | EV13: 1 | EX13: 1 | EZ13: 7 | FB13: 1 | FC13: =FA13+EY13+EW13+EU13 -> 0 | FD13: =FB13+EZ13+EX13+EV13 -> 10 | FE13: =FD13+FC13 -> 10 | FU13: =FT13+FS13+FR13+FN13+FL13+FH13+FF13 -> 0 | FV13: =FO13+FM13+FI13+FG13 -> 0 | FW13: =FV13+FU13 -> 0 | GC13: 2 | GG13: 1 | GI13: 7 | GN13: =GL13+GJ13+GH13+GF13+GD13+GB13+FZ13+FX13 -> 0 | GO13: =GM13+GK13+GI13+GG13+GE13+GC13+GA13+FY13 -> 10 | GP13: =GO13+GN13 -> 10 | GR13: 10 | GW13: =GU13+GS13+GQ13 -> 0 | GX13: =GV13+GT13+GR13 -> 10 | GY13: =GX13+GW13 -> 10 | HA13: 7 | HK13: 1 | HP13: 2 | HQ13: =HO13+GZ13+HM13+HJ13+HH13+HF13+HD13+HB13 -> 0 | HR13: =HP13+HA13+HN13+HL13+HK13+HI13+HG13+HE13+HC13 -> 10 | HS13: =HR13+HQ13 -> 10 | HW13: 9 | IA13: 1 | IB13: =HZ13+HX13+HV13+HT13 -> 0 | IC13: =IA13+HY13+HW13+HU13 -> 10 | ID13: =IC13+IB13 -> 10 | IG13: 1 | IJ13: 1 | IL13: 1 | IQ13: 45 | IS13: 5 | IT13: 1 | IU13: 1 | IX13: 1 | IY13: ايمان علي صيهود | IZ13: 7811776202 | JA13: حي ابو طالب - مع مدرسة الاعتماد
A14: النجف | B14: المركز | C14: 9 | D14: 1400813 | E14: السمو | G14: 1 | H14: 1 | K14: 1 | N14: 1 | R14: 1 | V14: 1 | Y14: 5 | AA14: 8 | AC14: 12 | AE14: 16 | AM14: =AK14+AI14+AG14+AE14+AC14+AA14+Y14 -> 41 | AN14: =AL14+AJ14+AH14+AF14+AD14+AB14+Z14 -> 0 | AO14: =AN14+AM14 -> 41 | AR14: 4 | AT14: 5 | AV14: 21 | BD14: =BB14+AZ14+AX14+AV14+AT14+AR14+AP14 -> 30 | BE14: =BC14+BA14+AY14+AW14+AU14+AS14+AQ14 -> 0 | BF14: =BE14+BD14 -> 30 | BG14: 4 | BI14: 14 | BK14: 20 | BM14: 20 | BO14: 5 | BQ14: 5 | BU14: =BS14+BQ14+BO14+BM14+BK14+BI14+BG14 -> 68 | BV14: =BT14+BR14+BP14+BN14+BL14+BJ14+BH14 -> 0 | BW14: =BV14+BU14 -> 68 | BX14: =BG14+AP14+Y14 -> 9 | BY14: =BH14+AQ14+Z14 -> 0 | BZ14: =BI14+AR14+AA14 -> 26 | CA14: =BJ14+AS14+AB14 -> 0 | CB14: =BK14+AT14+AC14 -> 37 | CC14: =BL14+AU14+AD14 -> 0 | CD14: =BM14+AV14+AE14 -> 57 | CE14: =BN14+AW14+AF14 -> 0 | ... CK14: =BT14+BC14+AL14 -> 0 | CL14: =CJ14+CH14+CF14+CD14+CB14+BZ14+BX14 -> 139 | CM14: =CK14+CI14+CG14+CE14+CC14+CA14+BY14 -> 0 | CN14: =CM14+CL14 -> 139 | CO14: 2 | CR14: 2 | CU14: 3 | CX14: =CU14+CR14+CO14 -> 7 | CY14: =CV14+CS14+CP14 -> 0 | CZ14: =CW14+CT14+CQ14 -> 0 | DA14: =CZ14+CY14+CX14 -> 7 | DB14: 7 | DD14: 5 | DF14: 17 | DH14: =DF14+DD14+DB14 -> 29 | DI14: =DG14+DE14+DC14 -> 0 | DJ14: =DI14+DH14 -> 29 | DK14: 5 | DM14: 19 | DO14: 48 | DQ14: =DO14+DM14+DK14 -> 72 | DR14: =DP14+DN14+DL14 -> 0 | DS14: =DR14+DQ14 -> 72 | DT14: 11 | DV14: 8 | DX14: 35 | DZ14: =DX14+DV14+DT14 -> 54 | EA14: =DY14+DW14+DU14 -> 0 | EB14: =EA14+DZ14 -> 54 | EI14: =EG14+EE14+EC14 -> 0 | EJ14: =EH14+EF14+ED14 -> 0 | EK14: =EJ14+EI14 -> 0 | ER14: =EP14+EN14+EL14 -> 0 | ES14: =EQ14+EO14+EM14 -> 0 | ET14: =ES14+ER14 -> 0 | EU14: 1 | EW14: 1 | FC14: =FA14+EY14+EW14+EU14 -> 2 | FD14: =FB14+EZ14+EX14+EV14 -> 0 | FE14: =FD14+FC14 -> 2 | FU14: =FT14+FS14+FR14+FN14+FL14+FH14+FF14 -> 0 | FV14: =FO14+FM14+FI14+FG14 -> 0 | FW14: =FV14+FU14 -> 0 | GB14: 1 | GJ14: 1 | GN14: =GL14+GJ14+GH14+GF14+GD14+GB14+FZ14+FX14 -> 2 | GO14: =GM14+GK14+GI14+GG14+GE14+GC14+GA14+FY14 -> 0 | GP14: =GO14+GN14 -> 2 | GQ14: 2 | GW14: =GU14+GS14+GQ14 -> 2 | GX14: =GV14+GT14+GR14 -> 0 | GY14: =GX14+GW14 -> 2 | GZ14: 2 | HQ14: =HO14+GZ14+HM14+HJ14+HH14+HF14+HD14+HB14 -> 2 | HR14: =HP14+HA14+HN14+HL14+HK14+HI14+HG14+HE14+HC14 -> 0 | HS14: =HR14+HQ14 -> 2 | HV14: 2 | IB14: =HZ14+HX14+HV14+HT14 -> 2 | IC14: =IA14+HY14+HW14+HU14 -> 0 | ID14: =IC14+IB14 -> 2 | IH14: 1 | IJ14: 1 | IL14: 1 | IU14: 1 | IX14: 1 | IY14: حسنين علي مسلم | IZ14: 7805874243 | JA14: حي الوفاء / مع ثانوية الشفق
A15: النجف | B15: المركز | C15: 10 | D15: 1401613 | E15: ابواب الامل | G15: 1 | I15: 1 | K15: 1 | N15: 1 | R15: 1 | V15: 1 | Z15: 4 | AB15: 2 | AD15: 3 | AH15: 3 | AJ15: 2 | AM15: =AK15+AI15+AG15+AE15+AC15+AA15+Y15 -> 0 | AN15: =AL15+AJ15+AH15+AF15+AD15+AB15+Z15 -> 14 | AO15: =AN15+AM15 -> 14 | AS15: 5 | AU15: 4 | AW15: 4 | AY15: 9 | BA15: 4 | BC15: 3 | BD15: =BB15+AZ15+AX15+AV15+AT15+AR15+AP15 -> 0 | BE15: =BC15+BA15+AY15+AW15+AU15+AS15+AQ15 -> 29 | BF15: =BE15+BD15 -> 29 | BJ15: 2 | BL15: 4 | BN15: 5 | BP15: 6 | BR15: 2 | BT15: 2 | BU15: =BS15+BQ15+BO15+BM15+BK15+BI15+BG15 -> 0 | BV15: =BT15+BR15+BP15+BN15+BL15+BJ15+BH15 -> 21 | BW15: =BV15+BU15 -> 21 | BX15: =BG15+AP15+Y15 -> 0 | BY15: =BH15+AQ15+Z15 -> 4 | BZ15: =BI15+AR15+AA15 -> 0 | CA15: =BJ15+AS15+AB15 -> 9 | CB15: =BK15+AT15+AC15 -> 0 | CC15: =BL15+AU15+AD15 -> 11 | CD15: =BM15+AV15+AE15 -> 0 | CE15: =BN15+AW15+AF15 -> 9 | ... CK15: =BT15+BC15+AL15 -> 5 | CL15: =CJ15+CH15+CF15+CD15+CB15+BZ15+BX15 -> 0 | CM15: =CK15+CI15+CG15+CE15+CC15+CA15+BY15 -> 64 | CN15: =CM15+CL15 -> 64 | CP15: 1 | CS15: 2 | CV15: 1 | CX15: =CU15+CR15+CO15 -> 0 | CY15: =CV15+CS15+CP15 -> 4 | CZ15: =CW15+CT15+CQ15 -> 0 | DA15: =CZ15+CY15+CX15 -> 4 | DH15: =DF15+DD15+DB15 -> 0 | DI15: =DG15+DE15+DC15 -> 0 | DJ15: =DI15+DH15 -> 0 | DL15: 8 | DN15: 7 | DP15: 30 | DQ15: =DO15+DM15+DK15 -> 0 | DR15: =DP15+DN15+DL15 -> 45 | DS15: =DR15+DQ15 -> 45 | DU15: 7 | DW15: 8 | DY15: 9 | DZ15: =DX15+DV15+DT15 -> 0 | EA15: =DY15+DW15+DU15 -> 24 | EB15: =EA15+DZ15 -> 24 | EI15: =EG15+EE15+EC15 -> 0 | EJ15: =EH15+EF15+ED15 -> 0 | EK15: =EJ15+EI15 -> 0 | ER15: =EP15+EN15+EL15 -> 0 | ES15: =EQ15+EO15+EM15 -> 0 | ET15: =ES15+ER15 -> 0 | EV15: 1 | FC15: =FA15+EY15+EW15+EU15 -> 0 | FD15: =FB15+EZ15+EX15+EV15 -> 1 | FE15: =FD15+FC15 -> 1 | FU15: =FT15+FS15+FR15+FN15+FL15+FH15+FF15 -> 0 | FV15: =FO15+FM15+FI15+FG15 -> 0 | FW15: =FV15+FU15 -> 0 | GI15: 1 | GN15: =GL15+GJ15+GH15+GF15+GD15+GB15+FZ15+FX15 -> 0 | GO15: =GM15+GK15+GI15+GG15+GE15+GC15+GA15+FY15 -> 1 | GP15: =GO15+GN15 -> 1 | GR15: 1 | GW15: =GU15+GS15+GQ15 -> 0 | GX15: =GV15+GT15+GR15 -> 1 | GY15: =GX15+GW15 -> 1 | HA15: 1 | HQ15: =HO15+GZ15+HM15+HJ15+HH15+HF15+HD15+HB15 -> 0 | HR15: =HP15+HA15+HN15+HL15+HK15+HI15+HG15+HE15+HC15 -> 1 | HS15: =HR15+HQ15 -> 1 | IA15: 1 | IB15: =HZ15+HX15+HV15+HT15 -> 0 | IC15: =IA15+HY15+HW15+HU15 -> 1 | ID15: =IC15+IB15 -> 1 | IH15: 1 | IJ15: 1 | IL15: 1 | IQ15: 32 | IS15: 4 | IX15: 1 | IY15: صبيحة مهدي حميدي | IZ15: 7837973367 | JA15: حي النداء
A16: النجف | B16: المركز | C16: 11 | D16: 1401614 | E16: طريق الامل | G16: 1 | H16: 1 | K16: 1 | N16: 1 | R16: 1 | V16: 1 | Y16: 28 | AA16: 23 | AC16: 24 | AE16: 13 | AG16: 11 | AI16: 3 | AM16: =AK16+AI16+AG16+AE16+AC16+AA16+Y16 -> 102 | AN16: =AL16+AJ16+AH16+AF16+AD16+AB16+Z16 -> 0 | AO16: =AN16+AM16 -> 102 | AP16: 1 | AR16: 6 | AT16: 6 | AV16: 1 | AX16: 2 | AZ16: 1 | BB16: 1 | BD16: =BB16+AZ16+AX16+AV16+AT16+AR16+AP16 -> 18 | BE16: =BC16+BA16+AY16+AW16+AU16+AS16+AQ16 -> 0 | BF16: =BE16+BD16 -> 18 | BI16: 9 | BK16: 13 | BM16: 21 | BO16: 23 | BQ16: 10 | BS16: 4 | BU16: =BS16+BQ16+BO16+BM16+BK16+BI16+BG16 -> 80 | BV16: =BT16+BR16+BP16+BN16+BL16+BJ16+BH16 -> 0 | BW16: =BV16+BU16 -> 80 | BX16: =BG16+AP16+Y16 -> 29 | BY16: =BH16+AQ16+Z16 -> 0 | BZ16: =BI16+AR16+AA16 -> 38 | CA16: =BJ16+AS16+AB16 -> 0 | CB16: =BK16+AT16+AC16 -> 43 | CC16: =BL16+AU16+AD16 -> 0 | CD16: =BM16+AV16+AE16 -> 35 | CE16: =BN16+AW16+AF16 -> 0 | ... CK16: =BT16+BC16+AL16 -> 0 | CL16: =CJ16+CH16+CF16+CD16+CB16+BZ16+BX16 -> 200 | CM16: =CK16+CI16+CG16+CE16+CC16+CA16+BY16 -> 0 | CN16: =CM16+CL16 -> 200 | CO16: 3 | CR16: 1 | CU16: 3 | CX16: =CU16+CR16+CO16 -> 7 | CY16: =CV16+CS16+CP16 -> 0 | CZ16: =CW16+CT16+CQ16 -> 0 | DA16: =CZ16+CY16+CX16 -> 7 | DH16: =DF16+DD16+DB16 -> 0 | DI16: =DG16+DE16+DC16 -> 0 | DJ16: =DI16+DH16 -> 0 | DK16: 16 | DM16: 20 | DO16: 34 | DQ16: =DO16+DM16+DK16 -> 70 | DR16: =DP16+DN16+DL16 -> 0 | DS16: =DR16+DQ16 -> 70 | DT16: 3 | DX16: 34 | DZ16: =DX16+DV16+DT16 -> 37 | EA16: =DY16+DW16+DU16 -> 0 | EB16: =EA16+DZ16 -> 37 | EI16: =EG16+EE16+EC16 -> 0 | EJ16: =EH16+EF16+ED16 -> 0 | EK16: =EJ16+EI16 -> 0 | ER16: =EP16+EN16+EL16 -> 0 | ES16: =EQ16+EO16+EM16 -> 0 | ET16: =ES16+ER16 -> 0 | EU16: 1 | FC16: =FA16+EY16+EW16+EU16 -> 1 | FD16: =FB16+EZ16+EX16+EV16 -> 0 | FE16: =FD16+FC16 -> 1 | FU16: =FT16+FS16+FR16+FN16+FL16+FH16+FF16 -> 0 | FV16: =FO16+FM16+FI16+FG16 -> 0 | FW16: =FV16+FU16 -> 0 | GB16: 1 | GN16: =GL16+GJ16+GH16+GF16+GD16+GB16+FZ16+FX16 -> 1 | GO16: =GM16+GK16+GI16+GG16+GE16+GC16+GA16+FY16 -> 0 | GP16: =GO16+GN16 -> 1 | GQ16: 1 | GW16: =GU16+GS16+GQ16 -> 1 | GX16: =GV16+GT16+GR16 -> 0 | GY16: =GX16+GW16 -> 1 | GZ16: 1 | HQ16: =HO16+GZ16+HM16+HJ16+HH16+HF16+HD16+HB16 -> 1 | HR16: =HP16+HA16+HN16+HL16+HK16+HI16+HG16+HE16+HC16 -> 0 | HS16: =HR16+HQ16 -> 1 | HV16: 1 | IB16: =HZ16+HX16+HV16+HT16 -> 1 | IC16: =IA16+HY16+HW16+HU16 -> 0 | ID16: =IC16+IB16 -> 1 | IE16: 1 | IH16: 1 | IJ16: 1 | IL16: 1 | IQ16: 95 | IS16: 24 | IX16: 1 | IY16: حيدر محسن صبر | IZ16: 7715895507
A17: النجف | B17: المركز | C17: 21 | D17: 1401616 | E17: وطن السلام | G17: 1 | I17: 1 | K17: 1 | N17: 1 | R17: 1 | V17: 1 | AB17: 4 | AD17: 6 | AF17: 3 | AH17: 3 | AJ17: 3 | AL17: 1 | AM17: =AK17+AI17+AG17+AE17+AC17+AA17+Y17 -> 0 | AN17: =AL17+AJ17+AH17+AF17+AD17+AB17+Z17 -> 20 | AO17: =AN17+AM17 -> 20 | AS17: 2 | AU17: 2 | AW17: 3 | AY17: 1 | BA17: 3 | BC17: 1 | BD17: =BB17+AZ17+AX17+AV17+AT17+AR17+AP17 -> 0 | BE17: =BC17+BA17+AY17+AW17+AU17+AS17+AQ17 -> 12 | BF17: =BE17+BD17 -> 12 | BL17: 1 | BN17: 4 | BP17: 8 | BR17: 8 | BT17: 5 | BU17: =BS17+BQ17+BO17+BM17+BK17+BI17+BG17 -> 0 | BV17: =BT17+BR17+BP17+BN17+BL17+BJ17+BH17 -> 26 | BW17: =BV17+BU17 -> 26 | BX17: =BG17+AP17+Y17 -> 0 | BY17: =BH17+AQ17+Z17 -> 0 | BZ17: =BI17+AR17+AA17 -> 0 | CA17: =BJ17+AS17+AB17 -> 6 | CB17: =BK17+AT17+AC17 -> 0 | CC17: =BL17+AU17+AD17 -> 9 | CD17: =BM17+AV17+AE17 -> 0 | CE17: =BN17+AW17+AF17 -> 10 | ... CK17: =BT17+BC17+AL17 -> 7 | CL17: =CJ17+CH17+CF17+CD17+CB17+BZ17+BX17 -> 0 | CM17: =CK17+CI17+CG17+CE17+CC17+CA17+BY17 -> 58 | CN17: =CM17+CL17 -> 58 | CP17: 1 | CS17: 1 | CV17: 1 | CX17: =CU17+CR17+CO17 -> 0 | CY17: =CV17+CS17+CP17 -> 3 | CZ17: =CW17+CT17+CQ17 -> 0 | DA17: =CZ17+CY17+CX17 -> 3 | DC17: 3 | DE17: 6 | DG17: 15 | DH17: =DF17+DD17+DB17 -> 0 | DI17: =DG17+DE17+DC17 -> 24 | DJ17: =DI17+DH17 -> 24 | DL17: 4 | DN17: 2 | DP17: 25 | DQ17: =DO17+DM17+DK17 -> 0 | DR17: =DP17+DN17+DL17 -> 31 | DS17: =DR17+DQ17 -> 31 | DU17: 8 | DW17: 10 | DY17: 24 | DZ17: =DX17+DV17+DT17 -> 0 | EA17: =DY17+DW17+DU17 -> 42 | EB17: =EA17+DZ17 -> 42 | EI17: =EG17+EE17+EC17 -> 0 | EJ17: =EH17+EF17+ED17 -> 0 | EK17: =EJ17+EI17 -> 0 | ER17: =EP17+EN17+EL17 -> 0 | ES17: =EQ17+EO17+EM17 -> 0 | ET17: =ES17+ER17 -> 0 | EV17: 1 | FC17: =FA17+EY17+EW17+EU17 -> 0 | FD17: =FB17+EZ17+EX17+EV17 -> 1 | FE17: =FD17+FC17 -> 1 | GC17: 1 | GN17: =GL17+GJ17+GH17+GF17+GD17+GB17+FZ17+FX17 -> 0 | GO17: =GM17+GK17+GI17+GG17+GE17+GC17+GA17+FY17 -> 1 | GP17: =GO17+GN17 -> 1 | GR17: 1 | GW17: =GU17+GS17+GQ17 -> 0 | GX17: =GV17+GT17+GR17 -> 1 | GY17: =GX17+GW17 -> 1 | HA17: 1 | HQ17: =HO17+GZ17+HM17+HJ17+HH17+HF17+HD17+HB17 -> 0 | HR17: =HP17+HA17+HN17+HL17+HK17+HI17+HG17+HE17+HC17 -> 1 | HS17: =HR17+HQ17 -> 1 | HY17: 1 | IB17: =HZ17+HX17+HV17+HT17 -> 0 | IC17: =IA17+HY17+HW17+HU17 -> 1 | ID17: =IC17+IB17 -> 1 | IH17: 1 | IJ17: 1 | IL17: 1 | IU17: 1 | IX17: 1 | IY17: اسراء حكيم نوري | IZ17: 7808247774 | JA17: الوفاء - ضيف على الولاية
A18: النجف | B18: المركز | C18: 12 | D18: 1401494 | E18: حياة شرارة | G18: 1 | I18: 1 | L18: 1 | N18: 1 | R18: 1 | V18: 1 | Z18: 5 | AB18: 2 | AD18: 3 | AF18: 3 | AJ18: 1 | AL18: 3 | AM18: =AK18+AI18+AG18+AE18+AC18+AA18+Y18 -> 0 | AN18: =AL18+AJ18+AH18+AF18+AD18+AB18+Z18 -> 17 | AO18: =AN18+AM18 -> 17 | AQ18: 1 | AS18: 1 | AU18: 4 | AW18: 5 | AY18: 8 | BA18: 4 | BC18: 4 | BD18: =BB18+AZ18+AX18+AV18+AT18+AR18+AP18 -> 0 | BE18: =BC18+BA18+AY18+AW18+AU18+AS18+AQ18 -> 27 | BF18: =BE18+BD18 -> 27 | BH18: 1 | BJ18: 1 | BL18: 4 | BN18: 4 | BP18: 2 | BR18: 2 | BT18: 8 | BU18: =BS18+BQ18+BO18+BM18+BK18+BI18+BG18 -> 0 | BV18: =BT18+BR18+BP18+BN18+BL18+BJ18+BH18 -> 22 | BW18: =BV18+BU18 -> 22 | BX18: =BG18+AP18+Y18 -> 0 | BY18: =BH18+AQ18+Z18 -> 7 | BZ18: =BI18+AR18+AA18 -> 0 | CA18: =BJ18+AS18+AB18 -> 4 | CB18: =BK18+AT18+AC18 -> 0 | CC18: =BL18+AU18+AD18 -> 11 | CD18: =BM18+AV18+AE18 -> 0 | CE18: =BN18+AW18+AF18 -> 12 | ... CK18: =BT18+BC18+AL18 -> 15 | CL18: =CJ18+CH18+CF18+CD18+CB18+BZ18+BX18 -> 0 | CM18: =CK18+CI18+CG18+CE18+CC18+CA18+BY18 -> 66 | CN18: =CM18+CL18 -> 66 | CP18: 1 | CS18: 1 | CV18: 1 | CX18: =CU18+CR18+CO18 -> 0 | CY18: =CV18+CS18+CP18 -> 3 | CZ18: =CW18+CT18+CQ18 -> 0 | DA18: =CZ18+CY18+CX18 -> 3 | DC18: 5 | DE18: 2 | DG18: 6 | DH18: =DF18+DD18+DB18 -> 0 | DI18: =DG18+DE18+DC18 -> 13 | DJ18: =DI18+DH18 -> 13 | DL18: 17 | DN18: 14 | DP18: 28 | DQ18: =DO18+DM18+DK18 -> 0 | DR18: =DP18+DN18+DL18 -> 59 | DS18: =DR18+DQ18 -> 59 | DU18: 22 | DW18: 14 | DY18: 17 | DZ18: =DX18+DV18+DT18 -> 0 | EA18: =DY18+DW18+DU18 -> 53 | EB18: =EA18+DZ18 -> 53 | EI18: =EG18+EE18+EC18 -> 0 | EJ18: =EH18+EF18+ED18 -> 0 | EK18: =EJ18+EI18 -> 0 | ER18: =EP18+EN18+EL18 -> 0 | ES18: =EQ18+EO18+EM18 -> 0 | ET18: =ES18+ER18 -> 0 | EV18: 1 | EZ18: 5 | FC18: =FA18+EY18+EW18+EU18 -> 0 | FD18: =FB18+EZ18+EX18+EV18 -> 6 | FE18: =FD18+FC18 -> 6 | FU18: =FT18+FS18+FR18+FN18+FL18+FH18+FF18 -> 0 | FV18: =FO18+FM18+FI18+FG18 -> 0 | FW18: =FV18+FU18 -> 0 | GC18: 1 | GI18: 3 | GK18: 2 | GN18: =GL18+GJ18+GH18+GF18+GD18+GB18+FZ18+FX18 -> 0 | GO18: =GM18+GK18+GI18+GG18+GE18+GC18+GA18+FY18 -> 6 | GP18: =GO18+GN18 -> 6 | GR18: 6 | GW18: =GU18+GS18+GQ18 -> 0 | GX18: =GV18+GT18+GR18 -> 6 | GY18: =GX18+GW18 -> 6 | HA18: 6 | HQ18: =HO18+GZ18+HM18+HJ18+HH18+HF18+HD18+HB18 -> 0 | HR18: =HP18+HA18+HN18+HL18+HK18+HI18+HG18+HE18+HC18 -> 6 | HS18: =HR18+HQ18 -> 6 | HU18: 1 | HW18: 5 | IB18: =HZ18+HX18+HV18+HT18 -> 0 | IC18: =IA18+HY18+HW18+HU18 -> 6 | ID18: =IC18+IB18 -> 6 | IF18: 6 | IH18: 1 | IJ18: 1 | IL18: 1 | IQ18: 200 | IS18: 12 | IX18: 1 | IY18: رشا مهدي بنية | IZ18: 7816032430 | JA18: مزارع اليرموك / مع مدرسة الافاضة
A19: النجف | B19: المركز | C19: 13 | D19: 1401710 | E19: الشيخ الكرباسي | G19: 1 | H19: 1 | K19: 1 | N19: 1 | R19: 1 | V19: 1 | X19: 1 | Y19: 6 | AA19: 13 | AC19: 11 | AE19: 8 | AG19: 8 | AI19: 2 | AM19: =AK19+AI19+AG19+AE19+AC19+AA19+Y19 -> 48 | AN19: =AL19+AJ19+AH19+AF19+AD19+AB19+Z19 -> 0 | AO19: =AN19+AM19 -> 48 | AP19: 1 | AR19: 7 | AT19: 5 | AV19: 10 | AX19: 6 | AZ19: 2 | BB19: 4 | BD19: =BB19+AZ19+AX19+AV19+AT19+AR19+AP19 -> 35 | BE19: =BC19+BA19+AY19+AW19+AU19+AS19+AQ19 -> 0 | BF19: =BE19+BD19 -> 35 | BG19: 2 | BI19: 5 | BK19: 6 | BM19: 15 | BO19: 19 | BQ19: 3 | BS19: 3 | BU19: =BS19+BQ19+BO19+BM19+BK19+BI19+BG19 -> 53 | BV19: =BT19+BR19+BP19+BN19+BL19+BJ19+BH19 -> 0 | BW19: =BV19+BU19 -> 53 | BX19: =BG19+AP19+Y19 -> 9 | BY19: =BH19+AQ19+Z19 -> 0 | BZ19: =BI19+AR19+AA19 -> 25 | CA19: =BJ19+AS19+AB19 -> 0 | CB19: =BK19+AT19+AC19 -> 22 | CC19: =BL19+AU19+AD19 -> 0 | CD19: =BM19+AV19+AE19 -> 33 | CE19: =BN19+AW19+AF19 -> 0 | ... CK19: =BT19+BC19+AL19 -> 0 | CL19: =CJ19+CH19+CF19+CD19+CB19+BZ19+BX19 -> 136 | CM19: =CK19+CI19+CG19+CE19+CC19+CA19+BY19 -> 0 | CN19: =CM19+CL19 -> 136 | CO19: 3 | CR19: 2 | CU19: 2 | CX19: =CU19+CR19+CO19 -> 7 | CY19: =CV19+CS19+CP19 -> 0 | CZ19: =CW19+CT19+CQ19 -> 0 | DA19: =CZ19+CY19+CX19 -> 7 | DH19: =DF19+DD19+DB19 -> 0 | DI19: =DG19+DE19+DC19 -> 0 | DJ19: =DI19+DH19 -> 0 | DQ19: =DO19+DM19+DK19 -> 0 | DR19: =DP19+DN19+DL19 -> 0 | DS19: =DR19+DQ19 -> 0 | DZ19: =DX19+DV19+DT19 -> 0 | EA19: =DY19+DW19+DU19 -> 0 | EB19: =EA19+DZ19 -> 0 | EI19: =EG19+EE19+EC19 -> 0 | EJ19: =EH19+EF19+ED19 -> 0 | EK19: =EJ19+EI19 -> 0 | ER19: =EP19+EN19+EL19 -> 0 | ES19: =EQ19+EO19+EM19 -> 0 | ET19: =ES19+ER19 -> 0 | EU19: 1 | FC19: =FA19+EY19+EW19+EU19 -> 1 | FD19: =FB19+EZ19+EX19+EV19 -> 0 | FE19: =FD19+FC19 -> 1 | GB19: 1 | GN19: =GL19+GJ19+GH19+GF19+GD19+GB19+FZ19+FX19 -> 1 | GO19: =GM19+GK19+GI19+GG19+GE19+GC19+GA19+FY19 -> 0 | GP19: =GO19+GN19 -> 1 | GQ19: 1 | GW19: =GU19+GS19+GQ19 -> 1 | GX19: =GV19+GT19+GR19 -> 0 | GY19: =GX19+GW19 -> 1 | GZ19: 1 | HQ19: =HO19+GZ19+HM19+HJ19+HH19+HF19+HD19+HB19 -> 1 | HR19: =HP19+HA19+HN19+HL19+HK19+HI19+HG19+HE19+HC19 -> 0 | HS19: =HR19+HQ19 -> 1 | HV19: 1 | IB19: =HZ19+HX19+HV19+HT19 -> 1 | IC19: =IA19+HY19+HW19+HU19 -> 0 | ID19: =IC19+IB19 -> 1 | IE19: 1 | IH19: 1 | IJ19: 1 | IL19: 1 | IY19: حسين سحاب عاشور | IZ19: 7813872421 | JA19: مع مدرسة القائم
A20: مجموع مركز النجف | F20: =SUM(F6:F19) -> 0 | G20: =SUM(G6:G19) -> 14 | H20: =SUM(H6:H19) -> 6 | I20: =SUM(I6:I19) -> 8 | J20: =SUM(J6:J19) -> 0 | K20: =SUM(K6:K19) -> 13 | L20: =SUM(L6:L19) -> 1 | M20: =SUM(M6:M19) -> 0 | ... IX20: =SUM(IX6:IX19) -> 13
A21: النجف | B21: الحيدرية | C21: 13 | D21: 1400728 | E21: النبراس | G21: 1 | I21: 1 | K21: 1 | N21: 1 | R21: 1 | V21: 1 | Z21: 1 | AB21: 1 | AD21: 3 | AF21: 3 | AJ21: 2 | AL21: 2 | AM21: =AK21+AI21+AG21+AE21+AC21+AA21+Y21 -> 0 | AN21: =AL21+AJ21+AH21+AF21+AD21+AB21+Z21 -> 12 | AO21: =AN21+AM21 -> 12 | AU21: 3 | AW21: 4 | AY21: 3 | BA21: 3 | BC21: 2 | BD21: =BB21+AZ21+AX21+AV21+AT21+AR21+AP21 -> 0 | BE21: =BC21+BA21+AY21+AW21+AU21+AS21+AQ21 -> 15 | BF21: =BE21+BD21 -> 15 | BL21: 2 | BN21: 4 | BP21: 7 | BR21: 4 | BT21: 5 | BU21: =BS21+BQ21+BO21+BM21+BK21+BI21+BG21 -> 0 | BV21: =BT21+BR21+BP21+BN21+BL21+BJ21+BH21 -> 22 | BW21: =BV21+BU21 -> 22 | BX21: =BG21+AP21+Y21 -> 0 | BY21: =BH21+AQ21+Z21 -> 1 | BZ21: =BI21+AR21+AA21 -> 0 | CA21: =BJ21+AS21+AB21 -> 1 | CB21: =BK21+AT21+AC21 -> 0 | CC21: =BL21+AU21+AD21 -> 8 | CD21: =BM21+AV21+AE21 -> 0 | CE21: =BN21+AW21+AF21 -> 11 | ... CK21: =BT21+BC21+AL21 -> 9 | CL21: =CJ21+CH21+CF21+CD21+CB21+BZ21+BX21 -> 0 | CM21: =CK21+CI21+CG21+CE21+CC21+CA21+BY21 -> 49 | CN21: =CM21+CL21 -> 49 | CP21: 1 | CS21: 1 | CV21: 1 | CX21: =CU21+CR21+CO21 -> 0 | CY21: =CV21+CS21+CP21 -> 3 | CZ21: =CW21+CT21+CQ21 -> 0 | DA21: =CZ21+CY21+CX21 -> 3 | DC21: 1 | DE21: 1 | DG21: 4 | DH21: =DF21+DD21+DB21 -> 0 | DI21: =DG21+DE21+DC21 -> 6 | DJ21: =DI21+DH21 -> 6 | DL21: 8 | DN21: 11 | DP21: 23 | DQ21: =DO21+DM21+DK21 -> 0 | DR21: =DP21+DN21+DL21 -> 42 | DS21: =DR21+DQ21 -> 42 | DU21: 5 | DW21: 4 | DY21: 11 | DZ21: =DX21+DV21+DT21 -> 0 | EA21: =DY21+DW21+DU21 -> 20 | EB21: =EA21+DZ21 -> 20 | EI21: =EG21+EE21+EC21 -> 0 | EJ21: =EH21+EF21+ED21 -> 0 | EK21: =EJ21+EI21 -> 0 | ER21: =EP21+EN21+EL21 -> 0 | ES21: =EQ21+EO21+EM21 -> 0 | ET21: =ES21+ER21 -> 0 | EV21: 1 | EZ21: 5 | FC21: =FA21+EY21+EW21+EU21 -> 0 | FD21: =FB21+EZ21+EX21+EV21 -> 6 | FE21: =FD21+FC21 -> 6 | FO21: 1 | FU21: =FT21+FS21+FR21+FN21+FL21+FH21+FF21 -> 0 | FV21: =FO21+FM21+FI21+FG21 -> 1 | FW21: =FV21+FU21 -> 1 | GC21: 4 | GG21: 1 | GI21: 1 | GN21: =GL21+GJ21+GH21+GF21+GD21+GB21+FZ21+FX21 -> 0 | GO21: =GM21+GK21+GI21+GG21+GE21+GC21+GA21+FY21 -> 6 | GP21: =GO21+GN21 -> 6 | GR21: 6 | GW21: =GU21+GS21+GQ21 -> 0 | GX21: =GV21+GT21+GR21 -> 6 | GY21: =GX21+GW21 -> 6 | HA21: 6 | HQ21: =HO21+GZ21+HM21+HJ21+HH21+HF21+HD21+HB21 -> 0 | HR21: =HP21+HA21+HN21+HL21+HK21+HI21+HG21+HE21+HC21 -> 6 | HS21: =HR21+HQ21 -> 6 | HW21: 5 | HY21: 1 | IB21: =HZ21+HX21+HV21+HT21 -> 0 | IC21: =IA21+HY21+HW21+HU21 -> 6 | ID21: =IC21+IB21 -> 6 | IH21: 1 | IJ21: 1 | IL21: 1 | IS21: 5 | IT21: 1 | IU21: 1 | IX21: 1 | IY21: انعام نعمه منسي | IZ21: 7814850538 | JA21: مع م . المنارة للبنات
A22: النجف | B22: الحيدرية | C22: 14 | D22: 1400729 | E22: ام ابيها | G22: 1 | H22: 1 | L22: 1 | N22: 1 | R22: 1 | V22: 1 | Y22: 1 | AA22: 3 | AC22: 1 | AE22: 2 | AG22: 1 | AI22: 1 | AM22: =AK22+AI22+AG22+AE22+AC22+AA22+Y22 -> 9 | AN22: =AL22+AJ22+AH22+AF22+AD22+AB22+Z22 -> 0 | AO22: =AN22+AM22 -> 9 | AP22: 1 | AR22: 4 | AT22: 6 | AV22: 6 | AX22: 2 | AZ22: 4 | BB22: 3 | BD22: =BB22+AZ22+AX22+AV22+AT22+AR22+AP22 -> 26 | BE22: =BC22+BA22+AY22+AW22+AU22+AS22+AQ22 -> 0 | BF22: =BE22+BD22 -> 26 | BI22: 1 | BK22: 7 | BM22: 5 | BO22: 13 | BQ22: 3 | BS22: 4 | BU22: =BS22+BQ22+BO22+BM22+BK22+BI22+BG22 -> 33 | BV22: =BT22+BR22+BP22+BN22+BL22+BJ22+BH22 -> 0 | BW22: =BV22+BU22 -> 33 | BX22: =BG22+AP22+Y22 -> 2 | BY22: =BH22+AQ22+Z22 -> 0 | BZ22: =BI22+AR22+AA22 -> 8 | CA22: =BJ22+AS22+AB22 -> 0 | CB22: =BK22+AT22+AC22 -> 14 | CC22: =BL22+AU22+AD22 -> 0 | CD22: =BM22+AV22+AE22 -> 13 | CE22: =BN22+AW22+AF22 -> 0 | ... CK22: =BT22+BC22+AL22 -> 0 | CL22: =CJ22+CH22+CF22+CD22+CB22+BZ22+BX22 -> 68 | CM22: =CK22+CI22+CG22+CE22+CC22+CA22+BY22 -> 0 | CN22: =CM22+CL22 -> 68 | CO22: 1 | CR22: 1 | CU22: 1 | CX22: =CU22+CR22+CO22 -> 3 | CY22: =CV22+CS22+CP22 -> 0 | CZ22: =CW22+CT22+CQ22 -> 0 | DA22: =CZ22+CY22+CX22 -> 3 | DH22: =DF22+DD22+DB22 -> 0 | DI22: =DG22+DE22+DC22 -> 0 | DJ22: =DI22+DH22 -> 0 | DK22: 20 | DM22: 11 | DO22: 22 | DQ22: =DO22+DM22+DK22 -> 53 | DR22: =DP22+DN22+DL22 -> 0 | DS22: =DR22+DQ22 -> 53 | DT22: 9 | DV22: 21 | DX22: 15 | DZ22: =DX22+DV22+DT22 -> 45 | EA22: =DY22+DW22+DU22 -> 0 | EB22: =EA22+DZ22 -> 45 | EI22: =EG22+EE22+EC22 -> 0 | EJ22: =EH22+EF22+ED22 -> 0 | EK22: =EJ22+EI22 -> 0 | ER22: =EP22+EN22+EL22 -> 0 | ES22: =EQ22+EO22+EM22 -> 0 | ET22: =ES22+ER22 -> 0 | EU22: 1 | EY22: 7 | FC22: =FA22+EY22+EW22+EU22 -> 8 | FD22: =FB22+EZ22+EX22+EV22 -> 0 | FE22: =FD22+FC22 -> 8 | FN22: 1 | FU22: =FT22+FS22+FR22+FN22+FL22+FH22+FF22 -> 1 | FV22: =FO22+FM22+FI22+FG22 -> 0 | FW22: =FV22+FU22 -> 1 | GB22: 3 | GH22: 3 | GJ22: 1 | GL22: 1 | GN22: =GL22+GJ22+GH22+GF22+GD22+GB22+FZ22+FX22 -> 8 | GO22: =GM22+GK22+GI22+GG22+GE22+GC22+GA22+FY22 -> 0 | GP22: =GO22+GN22 -> 8 | GQ22: 8 | GW22: =GU22+GS22+GQ22 -> 8 | GX22: =GV22+GT22+GR22 -> 0 | GY22: =GX22+GW22 -> 8 | GZ22: 7 | HO22: 1 | HQ22: =HO22+GZ22+HM22+HJ22+HH22+HF22+HD22+HB22 -> 8 | HR22: =HP22+HA22+HN22+HL22+HK22+HI22+HG22+HE22+HC22 -> 0 | HS22: =HR22+HQ22 -> 8 | HT22: 2 | HV22: 6 | IB22: =HZ22+HX22+HV22+HT22 -> 8 | IC22: =IA22+HY22+HW22+HU22 -> 0 | ID22: =IC22+IB22 -> 8 | IE22: 3 | IH22: 1 | IJ22: 1 | IL22: 1 | IS22: 4 | IT22: 1 | IU22: 3 | IX22: 1 | IY22: محمد خلف جابر | IZ22: 7816033841 | JA22: المزارع - مع مدرسة محمد تقي الخوئي
A23: النجف | B23: الحيدرية | C23: 15 | D23: 1400814 | E23: الكنز | G23: 1 | H23: 1 | K23: 1 | N23: 1 | R23: 1 | V23: 1 | Y23: 4 | AA23: 2 | AC23: 3 | AE23: 2 | AG23: 2 | AI23: 2 | AM23: =AK23+AI23+AG23+AE23+AC23+AA23+Y23 -> 15 | AN23: =AL23+AJ23+AH23+AF23+AD23+AB23+Z23 -> 0 | AO23: =AN23+AM23 -> 15 | AR23: 8 | AT23: 5 | AV23: 7 | AX23: 8 | BD23: =BB23+AZ23+AX23+AV23+AT23+AR23+AP23 -> 28 | BE23: =BC23+BA23+AY23+AW23+AU23+AS23+AQ23 -> 0 | BF23: =BE23+BD23 -> 28 | BK23: 3 | BM23: 4 | BQ23: 3 | BS23: 20 | BU23: =BS23+BQ23+BO23+BM23+BK23+BI23+BG23 -> 30 | BV23: =BT23+BR23+BP23+BN23+BL23+BJ23+BH23 -> 0 | BW23: =BV23+BU23 -> 30 | BX23: =BG23+AP23+Y23 -> 4 | BY23: =BH23+AQ23+Z23 -> 0 | BZ23: =BI23+AR23+AA23 -> 10 | CA23: =BJ23+AS23+AB23 -> 0 | CB23: =BK23+AT23+AC23 -> 11 | CC23: =BL23+AU23+AD23 -> 0 | CD23: =BM23+AV23+AE23 -> 13 | CE23: =BN23+AW23+AF23 -> 0 | ... CK23: =BT23+BC23+AL23 -> 0 | CL23: =CJ23+CH23+CF23+CD23+CB23+BZ23+BX23 -> 73 | CM23: =CK23+CI23+CG23+CE23+CC23+CA23+BY23 -> 0 | CN23: =CM23+CL23 -> 73 | CO23: 1 | CR23: 1 | CU23: 1 | CX23: =CU23+CR23+CO23 -> 3 | CY23: =CV23+CS23+CP23 -> 0 | CZ23: =CW23+CT23+CQ23 -> 0 | DA23: =CZ23+CY23+CX23 -> 3 | DD23: 1 | DF23: 7 | DH23: =DF23+DD23+DB23 -> 8 | DI23: =DG23+DE23+DC23 -> 0 | DJ23: =DI23+DH23 -> 8 | DK23: 18 | DM23: 6 | DO23: 19 | DQ23: =DO23+DM23+DK23 -> 43 | DR23: =DP23+DN23+DL23 -> 0 | DS23: =DR23+DQ23 -> 43 | DT23: 4 | DV23: 11 | DX23: 26 | DZ23: =DX23+DV23+DT23 -> 41 | EA23: =DY23+DW23+DU23 -> 0 | EB23: =EA23+DZ23 -> 41 | EI23: =EG23+EE23+EC23 -> 0 | EJ23: =EH23+EF23+ED23 -> 0 | EK23: =EJ23+EI23 -> 0 | ER23: =EP23+EN23+EL23 -> 0 | ES23: =EQ23+EO23+EM23 -> 0 | ET23: =ES23+ER23 -> 0 | EU23: 1 | EY23: 7 | FC23: =FA23+EY23+EW23+EU23 -> 8 | FD23: =FB23+EZ23+EX23+EV23 -> 0 | FE23: =FD23+FC23 -> 8 | FN23: 1 | FU23: =FT23+FS23+FR23+FN23+FL23+FH23+FF23 -> 1 | FV23: =FO23+FM23+FI23+FG23 -> 0 | FW23: =FV23+FU23 -> 1 | GB23: 5 | GH23: 2 | GJ23: 1 | GN23: =GL23+GJ23+GH23+GF23+GD23+GB23+FZ23+FX23 -> 8 | GO23: =GM23+GK23+GI23+GG23+GE23+GC23+GA23+FY23 -> 0 | GP23: =GO23+GN23 -> 8 | GQ23: 8 | GW23: =GU23+GS23+GQ23 -> 8 | GX23: =GV23+GT23+GR23 -> 0 | GY23: =GX23+GW23 -> 8 | GZ23: 8 | HQ23: =HO23+GZ23+HM23+HJ23+HH23+HF23+HD23+HB23 -> 8 | HR23: =HP23+HA23+HN23+HL23+HK23+HI23+HG23+HE23+HC23 -> 0 | HS23: =HR23+HQ23 -> 8 | HV23: 8 | IB23: =HZ23+HX23+HV23+HT23 -> 8 | IC23: =IA23+HY23+HW23+HU23 -> 0 | ID23: =IC23+IB23 -> 8 | IE23: 5 | IH23: 1 | IJ23: 1 | IL23: 1 | IT23: 1 | IU23: 1 | IX23: 1 | IY23: علي عبيد اسماعيل | IZ23: 7802707634 | JA23: مركز الناحية - مع مدرسة عابس الشاكري
A24: مجموع الحيدرية | F24: =SUM(F21:F23) -> 0 | G24: =SUM(G21:G23) -> 3 | H24: =SUM(H21:H23) -> 2 | I24: =SUM(I21:I23) -> 1 | J24: =SUM(J21:J23) -> 0 | K24: =SUM(K21:K23) -> 2 | L24: =SUM(L21:L23) -> 1 | M24: =SUM(M21:M23) -> 0 | ... IX24: =SUM(IX21:IX23) -> 3
A25: النجف | B25: الرضوية | C25: 16 | D25: 1400819 | E25: يثرب | G25: 1 | H25: 1 | K25: 1 | N25: 1 | R25: 1 | V25: 1 | Y25: 5 | AA25: 6 | AC25: 6 | AE25: 4 | AI25: 1 | AM25: =AK25+AI25+AG25+AE25+AC25+AA25+Y25 -> 22 | AN25: =AL25+AJ25+AH25+AF25+AD25+AB25+Z25 -> 0 | AO25: =AN25+AM25 -> 22 | AR25: 7 | AT25: 5 | AV25: 5 | AZ25: 1 | BB25: 2 | BD25: =BB25+AZ25+AX25+AV25+AT25+AR25+AP25 -> 20 | BE25: =BC25+BA25+AY25+AW25+AU25+AS25+AQ25 -> 0 | BF25: =BE25+BD25 -> 20 | BI25: 1 | BK25: 11 | BM25: 12 | BO25: 23 | BQ25: 6 | BS25: 1 | BU25: =BS25+BQ25+BO25+BM25+BK25+BI25+BG25 -> 54 | BV25: =BT25+BR25+BP25+BN25+BL25+BJ25+BH25 -> 0 | BW25: =BV25+BU25 -> 54 | BX25: =BG25+AP25+Y25 -> 5 | BY25: =BH25+AQ25+Z25 -> 0 | BZ25: =BI25+AR25+AA25 -> 14 | CA25: =BJ25+AS25+AB25 -> 0 | CB25: =BK25+AT25+AC25 -> 22 | CC25: =BL25+AU25+AD25 -> 0 | CD25: =BM25+AV25+AE25 -> 21 | CE25: =BN25+AW25+AF25 -> 0 | ... CK25: =BT25+BC25+AL25 -> 0 | CL25: =CJ25+CH25+CF25+CD25+CB25+BZ25+BX25 -> 96 | CM25: =CK25+CI25+CG25+CE25+CC25+CA25+BY25 -> 0 | CN25: =CM25+CL25 -> 96 | CO25: 1 | CR25: 1 | CU25: 2 | CX25: =CU25+CR25+CO25 -> 4 | CY25: =CV25+CS25+CP25 -> 0 | CZ25: =CW25+CT25+CQ25 -> 0 | DA25: =CZ25+CY25+CX25 -> 4 | DH25: =DF25+DD25+DB25 -> 0 | DI25: =DG25+DE25+DC25 -> 0 | DJ25: =DI25+DH25 -> 0 | DK25: 17 | DM25: 18 | DO25: 26 | DQ25: =DO25+DM25+DK25 -> 61 | DR25: =DP25+DN25+DL25 -> 0 | DS25: =DR25+DQ25 -> 61 | DT25: 10 | DV25: 8 | DX25: 33 | DZ25: =DX25+DV25+DT25 -> 51 | EA25: =DY25+DW25+DU25 -> 0 | EB25: =EA25+DZ25 -> 51 | EI25: =EG25+EE25+EC25 -> 0 | EJ25: =EH25+EF25+ED25 -> 0 | EK25: =EJ25+EI25 -> 0 | ER25: =EP25+EN25+EL25 -> 0 | ES25: =EQ25+EO25+EM25 -> 0 | ET25: =ES25+ER25 -> 0 | EU25: 1 | EY25: 9 | FC25: =FA25+EY25+EW25+EU25 -> 10 | FD25: =FB25+EZ25+EX25+EV25 -> 0 | FE25: =FD25+FC25 -> 10 | FO25: 1 | FU25: =FT25+FS25+FR25+FN25+FL25+FH25+FF25 -> 0 | FV25: =FO25+FM25+FI25+FG25 -> 1 | FW25: =FV25+FU25 -> 1 | GB25: 6 | GH25: 4 | GN25: =GL25+GJ25+GH25+GF25+GD25+GB25+FZ25+FX25 -> 10 | GO25: =GM25+GK25+GI25+GG25+GE25+GC25+GA25+FY25 -> 0 | GP25: =GO25+GN25 -> 10 | GQ25: 10 | GW25: =GU25+GS25+GQ25 -> 10 | GX25: =GV25+GT25+GR25 -> 0 | GY25: =GX25+GW25 -> 10 | GZ25: 6 | HH25: 1 | HO25: 3 | HQ25: =HO25+GZ25+HM25+HJ25+HH25+HF25+HD25+HB25 -> 10 | HR25: =HP25+HA25+HN25+HL25+HK25+HI25+HG25+HE25+HC25 -> 0 | HS25: =HR25+HQ25 -> 10 | HV25: 10 | IB25: =HZ25+HX25+HV25+HT25 -> 10 | IC25: =IA25+HY25+HW25+HU25 -> 0 | ID25: =IC25+IB25 -> 10 | IH25: 1 | IJ25: 1 | IL25: 1 | IT25: 1 | IU25: 1 | IX25: 1 | IY25: انور صباح هاشم | IZ25: 7706911091 | JA25: الرضوية مع مدرسة الوتر للبنين | JE25: 0
A26: مجموع الرضوية | F26: =SUM(F25:F25) -> 0 | G26: =SUM(G25:G25) -> 1 | H26: =SUM(H25:H25) -> 1 | I26: =SUM(I25:I25) -> 0 | J26: =SUM(J25:J25) -> 0 | K26: =SUM(K25:K25) -> 1 | L26: =SUM(L25:L25) -> 0 | M26: =SUM(M25:M25) -> 0 | ... IX26: =SUM(IX25:IX25) -> 1
A27: قضاء النجف | F27: =F20+F24+F26 -> 0 | G27: =G20+G24+G26 -> 18 | H27: =H20+H24+H26 -> 9 | I27: =I20+I24+I26 -> 9 | J27: =J20+J24+J26 -> 0 | K27: =K20+K24+K26 -> 16 | L27: =L20+L24+L26 -> 2 | M27: =M20+M24+M26 -> 0 | ... IX27: =IX20+IX24+IX26 -> 17
A28: الكوفة | B28: المركز | C28: 17 | D28: 1400730 | E28: الرحيق | G28: 1 | H28: 1 | K28: 1 | N28: 1 | R28: 1 | V28: 1 | Y28: 1 | AA28: 9 | AC28: 12 | AE28: 13 | AG28: 7 | AI28: 3 | AK28: 4 | AM28: =AK28+AI28+AG28+AE28+AC28+AA28+Y28 -> 49 | AN28: =AL28+AJ28+AH28+AF28+AD28+AB28+Z28 -> 0 | AO28: =AN28+AM28 -> 49 | AR28: 8 | AT28: 6 | AV28: 14 | AX28: 12 | AZ28: 10 | BB28: 7 | BD28: =BB28+AZ28+AX28+AV28+AT28+AR28+AP28 -> 57 | BE28: =BC28+BA28+AY28+AW28+AU28+AS28+AQ28 -> 0 | BF28: =BE28+BD28 -> 57 | BK28: 4 | BM28: 2 | BO28: 25 | BQ28: 15 | BS28: 7 | BU28: =BS28+BQ28+BO28+BM28+BK28+BI28+BG28 -> 53 | BV28: =BT28+BR28+BP28+BN28+BL28+BJ28+BH28 -> 0 | BW28: =BV28+BU28 -> 53 | BX28: =BG28+AP28+Y28 -> 1 | BY28: =BH28+AQ28+Z28 -> 0 | BZ28: =BI28+AR28+AA28 -> 17 | CA28: =BJ28+AS28+AB28 -> 0 | CB28: =BK28+AT28+AC28 -> 22 | CC28: =BL28+AU28+AD28 -> 0 | CD28: =BM28+AV28+AE28 -> 29 | CE28: =BN28+AW28+AF28 -> 0 | ... CK28: =BT28+BC28+AL28 -> 0 | CL28: =CJ28+CH28+CF28+CD28+CB28+BZ28+BX28 -> 159 | CM28: =CK28+CI28+CG28+CE28+CC28+CA28+BY28 -> 0 | CN28: =CM28+CL28 -> 159 | CO28: 2 | CR28: 2 | CU28: 2 | CX28: =CU28+CR28+CO28 -> 6 | CY28: =CV28+CS28+CP28 -> 0 | CZ28: =CW28+CT28+CQ28 -> 0 | DA28: =CZ28+CY28+CX28 -> 6 | DH28: =DF28+DD28+DB28 -> 0 | DI28: =DG28+DE28+DC28 -> 0 | DJ28: =DI28+DH28 -> 0 | DK28: 27 | DM28: 21 | DO28: 37 | DQ28: =DO28+DM28+DK28 -> 85 | DR28: =DP28+DN28+DL28 -> 0 | DS28: =DR28+DQ28 -> 85 | DT28: 29 | DV28: 27 | DX28: 31 | DZ28: =DX28+DV28+DT28 -> 87 | EA28: =DY28+DW28+DU28 -> 0 | EB28: =EA28+DZ28 -> 87 | EI28: =EG28+EE28+EC28 -> 0 | EJ28: =EH28+EF28+ED28 -> 0 | EK28: =EJ28+EI28 -> 0 | ER28: =EP28+EN28+EL28 -> 0 | ES28: =EQ28+EO28+EM28 -> 0 | ET28: =ES28+ER28 -> 0 | EU28: 1 | EW28: 1 | EY28: 7 | FC28: =FA28+EY28+EW28+EU28 -> 9 | FD28: =FB28+EZ28+EX28+EV28 -> 0 | FE28: =FD28+FC28 -> 9 | FU28: =FT28+FS28+FR28+FN28+FL28+FH28+FF28 -> 0 | FV28: =FO28+FM28+FI28+FG28 -> 0 | FW28: =FV28+FU28 -> 0 | GB28: 2 | GH28: 7 | GN28: =GL28+GJ28+GH28+GF28+GD28+GB28+FZ28+FX28 -> 9 | GO28: =GM28+GK28+GI28+GG28+GE28+GC28+GA28+FY28 -> 0 | GP28: =GO28+GN28 -> 9 | GQ28: 9 | GW28: =GU28+GS28+GQ28 -> 9 | GX28: =GV28+GT28+GR28 -> 0 | GY28: =GX28+GW28 -> 9 | GZ28: 7 | HH28: 1 | HO28: 1 | HQ28: 9 | HR28: =HP28+HA28 -> 0 | HS28: 9 | HV28: 9 | IB28: =HZ28+HX28+HV28+HT28 -> 9 | IC28: =IA28+HY28+HW28+HU28 -> 0 | ID28: =IC28+IB28 -> 9 | IH28: 1 | IJ28: 1 | IL28: 1 | IS28: 3 | IT28: 1 | IU28: 1 | IW28: 1 | IY28: محمد عبد الرزاق ابراهيم | IZ28: 7812782060 | JA28: الجمهورية -قرب اولاد الحسن مع مدرسة الصحابة الابتدائية
A29: الكوفة | B29: المركز | C29: 18 | D29: 1400731 | E29: الوادي المقدس | G29: 1 | I29: 1 | K29: 1 | N29: 1 | R29: 1 | V29: 1 | Z29: 2 | AB29: 1 | AD29: 1 | AF29: 2 | AJ29: 1 | AM29: =AK29+AI29+AG29+AE29+AC29+AA29+Y29 -> 0 | AN29: =AL29+AJ29+AH29+AF29+AD29+AB29+Z29 -> 7 | AO29: =AN29+AM29 -> 7 | AQ29: 2 | AS29: 5 | AU29: 3 | AW29: 3 | AY29: 1 | BA29: 2 | BC29: 1 | BD29: =BB29+AZ29+AX29+AV29+AT29+AR29+AP29 -> 0 | BE29: =BC29+BA29+AY29+AW29+AU29+AS29+AQ29 -> 17 | BF29: =BE29+BD29 -> 17 | BH29: 1 | BJ29: 1 | BL29: 3 | BN29: 6 | BP29: 11 | BR29: 8 | BT29: 7 | BU29: =BS29+BQ29+BO29+BM29+BK29+BI29+BG29 -> 0 | BV29: =BT29+BR29+BP29+BN29+BL29+BJ29+BH29 -> 37 | BW29: =BV29+BU29 -> 37 | BX29: =BG29+AP29+Y29 -> 0 | BY29: =BH29+AQ29+Z29 -> 5 | BZ29: =BI29+AR29+AA29 -> 0 | CA29: =BJ29+AS29+AB29 -> 7 | CB29: =BK29+AT29+AC29 -> 0 | CC29: =BL29+AU29+AD29 -> 7 | CD29: =BM29+AV29+AE29 -> 0 | CE29: =BN29+AW29+AF29 -> 11 | ... CK29: =BT29+BC29+AL29 -> 8 | CL29: =CJ29+CH29+CF29+CD29+CB29+BZ29+BX29 -> 0 | CM29: =CK29+CI29+CG29+CE29+CC29+CA29+BY29 -> 61 | CN29: =CM29+CL29 -> 61 | CP29: 2 | CS29: 1 | CV29: 2 | CX29: =CU29+CR29+CO29 -> 0 | CY29: =CV29+CS29+CP29 -> 5 | CZ29: =CW29+CT29+CQ29 -> 0 | DA29: =CZ29+CY29+CX29 -> 5 | DC29: 5 | DE29: 4 | DG29: 14 | DH29: =DF29+DD29+DB29 -> 0 | DI29: =DG29+DE29+DC29 -> 23 | DJ29: =DI29+DH29 -> 23 | DL29: 9 | DN29: 21 | DP29: 29 | DQ29: =DO29+DM29+DK29 -> 0 | DR29: =DP29+DN29+DL29 -> 59 | DS29: =DR29+DQ29 -> 59 | DU29: 20 | DW29: 20 | DY29: 13 | DZ29: =DX29+DV29+DT29 -> 0 | EA29: =DY29+DW29+DU29 -> 53 | EB29: =EA29+DZ29 -> 53 | ED29: 1 | EF29: 2 | EH29: 29 | EI29: =EG29+EE29+EC29 -> 0 | EJ29: =EH29+EF29+ED29 -> 32 | EK29: =EJ29+EI29 -> 32 | ER29: =EP29+EN29+EL29 -> 0 | ES29: =EQ29+EO29+EM29 -> 0 | ET29: =ES29+ER29 -> 0 | EV29: 1 | EX29: 1 | EZ29: 3 | FC29: =FA29+EY29+EW29+EU29 -> 0 | FD29: =FB29+EZ29+EX29+EV29 -> 5 | FE29: =FD29+FC29 -> 5 | FO29: 1 | FU29: =FT29+FS29+FR29+FN29+FL29+FH29+FF29 -> 0 | FV29: =FO29+FM29+FI29+FG29 -> 1 | FW29: =FV29+FU29 -> 1 | GC29: 1 | GI29: 3 | GM29: 1 | GN29: =GL29+GJ29+GH29+GF29+GD29+GB29+FZ29+FX29 -> 0 | GO29: =GM29+GK29+GI29+GG29+GE29+GC29+GA29+FY29 -> 5 | GP29: =GO29+GN29 -> 5 | GR29: 5 | GW29: =GU29+GS29+GQ29 -> 0 | GX29: =GV29+GT29+GR29 -> 5 | GY29: =GX29+GW29 -> 5 | HA29: 5 | HQ29: =HO29+GZ29 -> 0 | HR29: =HP29+HA29 -> 5 | HS29: =HR29+HQ29 -> 5 | HU29: 1 | HW29: 4 | IB29: =HZ29+HX29+HV29+HT29 -> 0 | IC29: =IA29+HY29+HW29+HU29 -> 5 | ID29: =IC29+IB29 -> 5 | IF29: 1 | IG29: 1 | IJ29: 1 | IL29: 1 | IT29: 1 | IU29: 1 | IW29: 1 | IY29: خلود محسن متعب | IZ29: 7816116131 | JA29: حي الفرات - مع اعدادية الكوفة المركزية للبنين
