Workbook

Sheet survey
A1: رقم المدرسة الاحصائي | B1: التصنيف | C1: بيئة المدرسة | D1: اسم المدرسة | E1: القضاء | F1: الناحية | G1: القرية | H1: الحي | I1: المحلة | J1: الزقاق | K1: سنة التأسيس | L1: هل المدرسة فتح جديد | M1: رقم الهاتف | N1: عائدية البناية | O1: رقم المبنى | P1: جنس المدرسة | Q1: دوام المدرسة | R1: استقلالية المدرسة | S1: اسم المدرسة الاصلية | T1: الرقم الاحصائي للمدرسة الاصلية | U1: هل المدرسة | V1: عدد التلامذة المستجدين في الصف الأول الابتدائي | W1: 5 سنوات | X1: بنون | Y1: بنات | Z1: 6 سنوات | AA1: بنون | AB1: بنات | AC1: 7 سنوات | AD1: بنون | AE1: بنات | AF1: 8 سنوات | AG1: بنون | AH1: بنات | AI1: 9 سنوات | AJ1: بنون | AK1: بنات | AL1: 10 سنوات | AM1: بنون | AN1: بنات | AO1: المجموع الكلي | AP1: بنون | AQ1: بنات | AR1: المجموع | AS1: عدد التلامذة المسجلين في الصف الاول الابتدائي | AT1: 5 سنوات | AU1: بنون | AV1: بنات | AW1: 6 سنوات | AX1: بنون | AY1: بنات | AZ1: 7 سنوات | BA1: بنون | BB1: بنات | BC1: 8 سنوات | BD1: بنون | BE1: بنات | BF1: 9 سنوات | BG1: بنون | BH1: بنات | BI1: 10 سنوات | BJ1: بنون | BK1: بنات | BL1: المجموع | BM1: بنون | BN1: بنات | BO1: المجموع | BP1: عدد التلامذة المسجلين في الصف الثاني الابتدائي | BQ1: 7 سنوات | BR1: بنون | BS1: بنات | BT1: 8 سنوات | BU1: بنون | BV1: بنات | BW1: 9 سنوات | BX1: بنون | BY1: بنات | BZ1: 10 سنوات | CA1: بنون | CB1: بنات | CC1: 11 سنوات | CD1: بنون | CE1: بنات | CF1: المجموع | CG1: بنون | CH1: بنات | CI1: المجموع | CJ1: عدد التلامذة المسجلين في الصف الثالث الابتدائي | CK1: 8 سنوات | CL1: بنون | CM1: بنات | CN1: 9 سنوات | CO1: بنون | CP1: بنات | CQ1: 10 سنوات | CR1: بنون | CS1: بنات | CT1: 11 سنوات | CU1: بنون | CV1: بنات | CW1: 12 سنوات | CX1: بنون | CY1: بنات | CZ1: المجموع | DA1: بنون | DB1: بنات | DC1: المجموع | DD1: عدد التلامذة المسجلين في الصف الرابع الابتدائي | DE1: 9 سنوات | DF1: بنون | DG1: بنات | DH1: 10 سنوات | DI1: بنون | DJ1: بنات | DK1: 11 سنوات | DL1: بنون | DM1: بنات | DN1: 12 سنوات | DO1: بنون | DP1: بنات | DQ1: 13 سنوات | DR1: بنون | DS1: بنات | DT1: المجموع | DU1: بنون | DV1: بنات | DW1: المجموع | DX1: عدد التلامذة المسجلين في الصف الخامس الابتدائي | DY1: 10 سنوات | DZ1: بنون | EA1: بنات | EB1: 11 سنوات | EC1: بنون | ED1: بنات | EE1: 12 سنوات | EF1: بنون | EG1: بنات | EH1: 13 سنوات | EI1: بنون | EJ1: بنات | EK1: 14 سنوات | EL1: بنون | EM1: بنات | EN1: المجموع | EO1: بنون | EP1: بنات | EQ1: المجموع | ER1: عدد التلامذة المسجلين في الصف السادس الابتدائي | ES1: 11 سنوات | ET1: بنون | EU1: بنات | EV1: 12 سنوات | EW1: بنون | EX1: بنات | EY1: 13 سنوات | EZ1: بنون | FA1: بنات | FB1: 14 سنوات | FC1: بنون | FD1: بنات | FE1: 15 سنوات | FF1: بنون | FG1: بنات | FH1: المجموع | FI1: بنون | FJ1: بنات | FK1: المجموع | FL1: عدد الشعب حسب الصف والجنس | FM1: الصف الاول | FN1: بنون | FO1: بنات | FP1: مختلط | FQ1: الصف الثاني | FR1: بنون | FS1: بنات | FT1: مختلط | FU1: الصف الثالث | FV1: بنون | FW1: بنات | FX1: مختلط | FY1: الصف الرابع | FZ1: بنون | GA1: بنات | GB1: مختلط | GC1: الصف الخامس | GD1: بنون | GE1: بنات | GF1: مختلط | GG1: الصف السادس | GH1: بنون | GI1: بنات | GJ1: مختلط | GK1: المجموع | GL1: بنون | GM1: بنات | GN1: مختلط | GO1: المجموع | GP1: عدد التلامذة التاركين | GQ1: الاول | GR1: بنون | GS1: بنات | GT1: الثاني | GU1: بنون | GV1: بنات | GW1: الثالث | GX1: بنون | GY1: بنات | GZ1: الرابع | HA1: بنون | HB1: بنات | HC1: الخامس | HD1: بنون | HE1: بنات | HF1: السادس | HG1: بنون | HH1: بنات | HI1: المجموع | HJ1: بنون | HK1: بنات | HL1: المجموع | HM1: عدد التلامذة الناجحون | HN1: الاول | HO1: بنون | HP1: بنات | HQ1: الثاني | HR1: بنون | HS1: بنات | HT1: الثالث | HU1: بنون | HV1: بنات | HW1: الرابع | HX1: بنون | HY1: بنات | HZ1: الخامس | IA1: بنون | IB1: بنات | IC1: السادس | ID1: بنون | IE1: بنات | IF1: المجموع | IG1: بنون | IH1: بنات | II1: المجموع | IJ1: التلامذة الراسبين بسبب الفشل بالامتحان | IK1: الاول | IL1: بنون | IM1: بنات | IN1: الثاني | IO1: بنون | IP1: بنات | IQ1: الثالث | IR1: بنون | IS1: بنات | IT1: الرابع | IU1: بنون | IV1: بنات | IW1: الخامس | IX1: بنون | IY1: بنات | IZ1: السادس | JA1: بنون | JB1: بنات | JC1: المجموع | JD1: بنون | JE1: بنات | JF1: المجموع | JG1: التلامذة الراسبين بسبب تجاوز أيام الغياب | JH1: الاول | JI1: بنون | JJ1: بنات | JK1: الثاني | JL1: بنون | JM1: بنات | JN1: الثالث | JO1: بنون | JP1: بنات | JQ1: الرابع | JR1: بنون | JS1: بنات | JT1: الخامس | JU1: بنون | JV1: بنات | JW1: السادس | JX1: بنون | JY1: بنات | JZ1: المجموع | KA1: بنون | KB1: بنات | KC1: المجموع | KD1: التلامذة الراسبين لاسباب أخرى | KE1: الاول | KF1: بنون | KG1: بنات | KH1: الثاني | KI1: بنون | KJ1: بنات | KK1: الثالث | KL1: بنون | KM1: بنات | KN1: الرابع | KO1: بنون | KP1: بنات | KQ1: الخامس | KR1: بنون | KS1: بنات | KT1: السادس | KU1: بنون | KV1: بنات | KW1: المجموع | KX1: بنون | KY1: بنات | KZ1: المجموع | LA1: مجموع التلامذة الراسبين لكل الاسباب | LB1: الاول | LC1: بنون | LD1: بنات | LE1: الثاني | LF1: بنون | LG1: بنات | LH1: الثالث | LI1: بنون | LJ1: بنات | LK1: الرابع | LL1: بنون | LM1: بنات | LN1: الخامس | LO1: بنون | LP1: بنات | LQ1: السادس | LR1: بنون | LS1: بنات | LT1: المجموع | LU1: بنون | LV1: بنات | LW1: المجموع | LX1: أعضاء الهيئة التعليمية حسب العنوان الوظيفي | LY1: مدير | LZ1: ذكور | MA1: اناث | MB1: معاون | MC1: ذكور | MD1: اناث | ME1: مدرس | MF1: ذكور | MG1: اناث | MH1: مرشد | MI1: ذكور | MJ1: اناث | MK1: المجموع | ML1: ذكور | MM1: اناث | MN1: المجموع | MO1: الموظفون الاداريون والخدميون حسب العنوان الوظيفي | MP1: موظف ادراي | MQ1: ذكور | MR1: اناث | MS1: محاسب | MT1: ذكور | MU1: اناث | MV1: كاتب | MW1: ذكور | MX1: اناث | MY1: مساعد مختبر | MZ1: ذكور | NA1: اناث | NB1: امين مكتبة | NC1: ذكور | ND1: اناث | NE1: موظف خدمات | NF1: ذكور | NG1: اناث | NH1: حارس | NI1: ذكور | NJ1: اناث | NK1: سائق | NL1: ذكور | NM1: اناث | NN1: فلاح | NO1: ذكور | NP1: اناث | NQ1: المجموع | NR1: ذكور | NS1: اناث | NT1: المجموع | NU1: عدد أعضاء الهيئة التدريسية حسب الجنسية | NV1: عراقية | NW1: ذكور | NX1: اناث | NY1: عربية | NZ1: ذكور | OA1: اناث | OB1: اجنبية | OC1: ذكور | OD1: اناث | OE1: المجموع | OF1: ذكور | OG1: اناث | OH1: المجموع | OI1: عدد أعضاء الهيئة التدريسية حسب الحالة الوظيفية | OJ1: داخل قوة العمل | OK1: ذكور | OL1: اناث | OM1: بعثة او زمالة دراسية | ON1: ذكور | OO1: اناث | OP1: إجازة دراسية | OQ1: ذكور | OR1: اناث | OS1: إجازة مصاحبة | OT1: ذكور | OU1: اناث | OV1: اجازة بدون راتب | OW1: ذكور | OX1: اناث | OY1: إجازة مرضية طويلة | OZ1: ذكور | PA1: اناث | PB1: إجازة امومة | PC1: ذكور | PD1: اناث | PE1: منسب الى جهات اخرى | PF1: ذكور | PG1: اناث | PH1: اجازة (4-5) سنوات | PI1: ذكور | PJ1: اناث | PK1: المجموع | PL1: ذكور | PM1: اناث | PN1: المجموع | PO1: عدد أعضاء الهيئة التدريسية حسب الحالة الاجتماعية | PP1: اعزب | PQ1: ذكور | PR1: اناث | PS1: متزوج | PT1: ذكور | PU1: اناث | PV1: ارمل | PW1: ذكور | PX1: اناث | PY1: مطلق | PZ1: ذكور | QA1: اناث | QB1: المجموع | QC1: ذكور | QD1: اناث | QE1: المجموع | QF1: عدد أعضاء الهيئة التدريسية حسب سنوات الخدمة | QG1: 5 سنوات او اقل | QH1: ذكور | QI1: اناث | QJ1: من 6 الى 10 | QK1: ذكور | QL1: اناث | QM1: من 11 الى 15 | QN1: ذكور | QO1: اناث | QP1: 16 فاكثر | QQ1: ذكور | QR1: اناث | QS1: المجموع | QT1: ذكور | QU1: اناث | QV1: المجموع | QW1: عدد أعضاء الهيئة التدريسية حسب العمر | QX1: اقل من 30 | QY1: ذكور | QZ1: اناث | RA1: من 30 الى 39 | RB1: ذكور | RC1: اناث | RD1: من 40 الى 49 | RE1: ذكور | RF1: اناث | RG1: من 50 الى 59 | RH1: ذكور | RI1: اناث | RJ1: 60 فاكثر | RK1: ذكور | RL1: اناث | RM1: المجموع | RN1: ذكور | RO1: اناث | RP1: المجموع | RQ1: عدد أعضاء الهيئة التدريسية المشاركين في الدورات التدريبية للعام السابق | RR1: ذكور | RS1: اناث | RT1: المجموع | RU1: عدد أعضاء الهيئة التدريسية حسب الشهادة والتخصص والجنس | RV1: التربية الإسلامية | RW1: الذكور | RX1: الاناث | RY1: المجموع | RZ1: اللعة العربية | SA1: الذكور | SB1: الاناث | SC1: المجموع | SD1: اللغة الانكليزية | SE1: الذكور | SF1: الاناث | SG1: المجموع | SH1: اللغة الكردية | SI1: الذكور | SJ1: الاناث | SK1: المجموع | SL1: رياضيات | SM1: الذكور | SN1: الاناث | SO1: المجموع | SP1: علوم وعلوم الحياة | SQ1: الذكور | SR1: الاناث | SS1: المجموع | ST1: كيمياء | SU1: الذكور | SV1: الاناث | SW1: المجموع | SX1: فيزياء | SY1: الذكور | SZ1: الاناث | TA1: المجموع | TB1: اجتماعيات | TC1: الذكور | TD1: الاناث | TE1: المجموع | TF1: تاريخ | TG1: الذكور | TH1: الاناث | TI1: المجموع | TJ1: جغرافية | TK1: الذكور | TL1: الاناث | TM1: المجموع | TN1: اقتصاد منزلي | TO1: الذكور | TP1: الاناث | TQ1: المجموع | TR1: تربية خاصة | TS1: الذكور | TT1: الاناث | TU1: المجموع | TV1: علم النفس | TW1: الذكور | TX1: الاناث | TY1: المجموع | TZ1: تربية الفنية | UA1: الذكور | UB1: الاناث | UC1: المجموع | UD1: تربية رياضية | UE1: الذكور | UF1: الاناث | UG1: المجموع | UH1: حاسوب | UI1: الذكور | UJ1: الاناث | UK1: المجموع | UL1: اللغة التركمانية | UM1: الذكور | UN1: الاناث | UO1: المجموع | UP1: اللغة السريانية | UQ1: الذكور | UR1: الاناث | US1: المجموع | UT1: عام | UU1: الذكور | UV1: الاناث | UW1: المجموع | UX1: اخرى | UY1: الذكور | UZ1: الاناث | VA1: المجموع | VB1: المجموع | VC1: ذكور | VD1: دورات تربوية | VE1: دبلوم تعليمي | VF1: دبلوم فنون جميلة | VG1: دبلوم عام | VH1: بكالوريوس تعليمي | VI1: بكالوريوس عام | VJ1: دبلوم عالي | VK1: ماجستير | VL1: دكتوراه | VM1: اخرى | VN1: المجموع | VO1: اناث | VP1: دورات تربوية | VQ1: دبلوم تعليمي | VR1: دبلوم فنون جميلة | VS1: دبلوم عام | VT1: بكالوريوس تعليمي | VU1: بكالوريوس عام | VV1: دبلوم عالي | VW1: ماجستير | VX1: دكتوراه | VY1: اخرى | VZ1: المجموع | WA1: المجموع | WB1: دورات تربوية | WC1: دبلوم تعليمي | WD1: دبلوم فنون جميلة | WE1: دبلوم عام | WF1: بكالوريوس تعليمي | WG1: بكالوريوس عام | WH1: دبلوم عالي | WI1: ماجستير | WJ1: دكتوراه | WK1: اخرى | WL1: المجموع | WM1: 7| عدد التلامذة المسجلين من غير العراقيين | WN1: الاول | WO1: بنون | WP1: بنات | WQ1: الثاني | WR1: بنون | WS1: بنات | WT1: الثالث | WU1: بنون | WV1: بنات | WW1: الرابع | WX1: بنون | WY1: بنات | WZ1: الخامس | XA1: بنون | XB1: بنات | XC1: السادس | XD1: بنون | XE1: بنات | XF1: المجموع | XG1: بنون | XH1: بنات | XI1: المجموع | XJ1: هل المدرسة مشمولة بـــ : | XK1: الارشاد التربوي | XL1: التغذية المدرسية | XM1: خدمة الانترنت | XN1: تدريس الحاسوب | XO1: تدريس اللغات الأجنبية | XP1: ما هي اللغة الأجنبية | XQ1: اللغات المحلية | XR1: نوع البناء | XS1: سنة البناء | XT1: رقم القطعة | XU1: رقم المقاطعة | XV1: هل توجد مساحة للتوسيع؟ | XW1: عدد طوابق البناية | XX1: هل المدرسة بحاجة الى صفوف إضافية | XY1: عدد الصفوف الإضافية | XZ1: سعة المدرسة | YA1: عدد الغرف بالبناية / صفوف | YB1: عدد الغرف بالبناية / أخرى | YC1: المجموع | YD1: مادة البناء | YE1: هل تتوفر في المدرسة مرافق صحية | YF1: صالحة / غير صالحة | YG1: كافية / غير كافية | YH1: هل ترتبط البناية بشبكة الماء الصالح للشرب؟ | YI1: مصدرالماء الصالح للشرب | YJ1: هل المدرسة مزودة بخدمة المجاري؟ | YK1: ما نوع خدمه المجاري | YL1: هل هناك سياج حول البناية؟ | YM1: نوع السياج | YN1: حالة السياج | YO1: هل توجد ساحة رياضية في المدرسة؟ | YP1: هل توجد حديقة مدرسية؟ | YQ1: هل توجد قاعة أنشطة مستقلة؟ | YR1: نوعها | YS1: هل البناية تشغلها | YT1: عائدية البناية | YU1: الحالة العمرانية | YV1: عدد الرحلات ذات المقعدين | YW1: صالحة | YX1: غير صالحة | YY1: عدد الرحلات ذات المقعد الواحد | YZ1: صالحة | ZA1: غير صالحة | ZB1: عدد لوحات الكتابة (السبورات) | ZC1: صالحة | ZD1: غير صالحة | ZE1: عدد الحاسبات الالكترونية (كمبيوتر) | ZF1: صالحة | ZG1: غير صالحة | ZH1: عدد الطابعات | ZI1: صالحة | ZJ1: غير صالحة | ZK1: عدد الماسح الضوئي (سكنر) | ZL1: صالحة | ZM1: غير صالحة | ZN1: هل توجد مكتبة | ZO1: المسؤول عن المكتبة | ZP1: نوعية المكتبة | ZQ1: عدد الكتب والمجلات في المكتبة | ZR1: عدد الكتب | ZS1: عدد المجلات او القصص | ZT1: المجموع | ZU1: هل يوجد مختبر | ZV1: اسم المدير | ZW1: اقرب نقطة دالة | ZX1: اسم المدرسة الضيف | ZY1: _id | ZZ1: _uuid | AAA1: _submission_time | AAB1: _validation_status | AAC1: _notes | AAD1: _status | AAE1: _submitted_by | AAF1: __version__ | AAG1: _tags | AAH1: meta/rootUuid | AAI1: _index
A2: 1400955 | B2: ابتدائي حكومي | C2: حضر | D2: الرسل الابتدائية للبنات | E2: النجف | F2: مركز النجف | G2: 0 | H2: الرحمة | I2: 0 | J2: 0 | K2: 2024 | L2: لا | M2: 07810483096 | N2: حكومية | O2: 0 | P2: بنات | Q2: صباحاً | R2: اصلية | U2: مزدوجة مع نفسها ومع اخرى | Y2: 0 | AB2: 64 | AE2: 39 | AH2: 12 | AK2: 5 | AN2: 5 | AQ2: 125 | AR2: 125 | AV2: 0 | AY2: 64 | BB2: 39 | BE2: 12 | BH2: 5 | BK2: 5 | BN2: 125 | BO2: 125 | BS2: 68 | BV2: 33 | BY2: 15 | CB2: 7 | CE2: 9 | CH2: 132 | CI2: 132 | CM2: 76 | CP2: 46 | CS2: 20 | CV2: 10 | CY2: 10 | DB2: 162 | DC2: 162 | DG2: 66 | DJ2: 56 | DM2: 13 | DP2: 11 | DS2: 10 | DV2: 156 | DW2: 156 | EA2: 64 | ED2: 55 | EG2: 20 | EJ2: 11 | EM2: 10 | EP2: 160 | EQ2: 160 | EU2: 29 | EX2: 20 | FA2: 15 | FD2: 5 | FG2: 10 | FJ2: 79 | FK2: 79 | FO2: 3 | FS2: 3 | FW2: 3 | GA2: 3 | GE2: 3 | GI2: 3 | GM2: 18 | GO2: 18 | GS2: 6 | GV2: 9 | GY2: 8 | HB2: 17 | HE2: 15 | HH2: 10 | HK2: 65 | HL2: 65 | HP2: 92 | HS2: 91 | HV2: 121 | HY2: 89 | IB2: 42 | IE2: 57 | IH2: 492 | II2: 492 | IM2: 9 | IP2: 7 | IS2: 0 | IV2: 14 | IY2: 38 | JB2: 6 | JE2: 74 | JF2: 74 | JJ2: 3 | JM2: 2 | JP2: 0 | JS2: 0 | JV2: 18 | JY2: 13 | KB2: 36 | KC2: 36 | KG2: 0 | KJ2: 0 | KM2: 0 | KP2: 0 | KS2: 0 | KV2: 0 | KY2: 0 | KZ2: 0 | LD2: 12 | LG2: 9 | LJ2: 0 | LM2: 14 | LP2: 56 | LS2: 19 | LV2: 110 | LW2: 110 | MA2: 1 | MD2: 2 | MG2: 15 | ML2: 0 | MM2: 18 | MN2: 18 | ND2: 1 | NF2: 1 | NG2: 1 | NR2: 1 | NS2: 2 | NT2: 3 | NW2: 0 | NX2: 18 | OF2: 0 | OG2: 18 | OH2: 18 | OL2: 12 | PA2: 4 | PJ2: 2 | PL2: 0 | PM2: 18 | PN2: 18 | PU2: 17 | PX2: 1 | QC2: 0 | QD2: 18 | QE2: 18 | QL2: 5 | QO2: 5 | QR2: 8 | QT2: 0 | QU2: 18 | QV2: 18 | RC2: 4 | RF2: 11 | RI2: 3 | RN2: 0 | RO2: 18 | RP2: 18 | RR2: 0 | RS2: 0 | RT2: 0 | RX2: 2 | RY2: 2 | SB2: 3 | SC2: 3 | SF2: 2 | SG2: 2 | SJ2: 0 | SK2: 0 | SN2: 4 | SO2: 4 | SR2: 0 | SS2: 0 | SV2: 0 | SW2: 0 | SZ2: 1 | TA2: 1 | TD2: 0 | TE2: 0 | TH2: 1 | TI2: 1 | TL2: 0 | TM2: 0 | TP2: 0 | TQ2: 0 | TT2: 0 | TU2: 0 | TX2: 1 | TY2: 1 | UB2: 1 | UC2: 1 | UF2: 3 | UG2: 3 | UJ2: 0 | UK2: 0 | UN2: 0 | UO2: 0 | UR2: 0 | US2: 0 | UV2: 0 | UW2: 0 | UZ2: 0 | VA2: 0 | VP2: 0 | VQ2: 10 | VR2: 0 | VS2: 2 | VT2: 5 | VU2: 0 | VV2: 0 | VW2: 1 | VX2: 0 | VY2: 0 | VZ2: 18 | WB2: 0 | WC2: 10 | WD2: 0 | WE2: 2 | WF2: 5 | WG2: 0 | WH2: 0 | WI2: 1 | WJ2: 0 | WK2: 0 | WL2: 18 | WP2: 1 | WS2: 1 | WV2: 0 | WY2: 0 | XB2: 0 | XE2: 0 | XH2: 0 | XK2: نعم | XL2: كلا | XM2: كلا | XN2: كلا | XO2: كلا | XR2: مدرسي | XS2: 1900 | XT2: 0 | XU2: 0 | XV2: نعم | XW2: طابقين | XX2: نعم | XY2: 6 | XZ2: 18 صف | YA2: 18 | YB2: 6 | YC2: 24 | YD2: طابوق او حجر او بلوك | YE2: نعم | YF2: صالحة | YG2: كافية | YH2: نعم | YI2: بلدية | YJ2: نعم | YK2: صهاريج | YL2: نعم | YM2: بناء | YN2: جيد | YO2: كلا | YP2: نعم | YQ2: كلا | YS2: مدرستان | YT2: حكومية تابعة لجهات أخرى | YU2: صالحة | YW2: 75 | YX2: 85 | YZ2: 0 | ZA2: 0 | ZC2: 13 | ZD2: 11 | ZF2: 1 | ZG2: 2 | ZI2: 1 | ZJ2: 2 | ZL2: 0 | ZM2: 0 | ZN2: نعم | ZO2: معلم غير متفرغ | ZP2: غرفة | ZR2: 200 | ZS2: 50 | ZT2: 250 | ZU2: نعم | ZV2: ركزان جبار صياح | ZW2: 0 | ZX2: 0 | ZY2: 753718442 | ZZ2: 13956a09-34ec-4af7-a61d-7e54ff2b3942 | AAA2: 46085.383 | AAD2: submitted_via_web | AAF2: vVzzfX65n7BFB4zHT6BDkS | AAH2: uuid:352469fb-42b1-41d8-a2ac-16c50030b28b | AAI2: 1
A3: 1400507 | B3: ابتدائي حكومي | C3: حضر | D3: انوار الصحراء | E3: النجف | F3: الحيدرية | G3: 0 | H3: 0 | I3: 0 | J3: 0 | K3: 2006 | L3: لا | M3: 07827749457 | N3: حكومية | O3: 0 | P3: مختلط | Q3: صباحاً | R3: اصلية | U3: مزدوجة مع اخرى | X3: 1 | Y3: 0 | AA3: 26 | AB3: 23 | AD3: 11 | AE3: 10 | AG3: 3 | AH3: 4 | AJ3: 1 | AK3: 1 | AM3: 0 | AN3: 0 | AP3: 42 | AQ3: 38 | AR3: 80 | AU3: 1 | AV3: 0 | AX3: 26 | AY3: 23 | BA3: 17 | BB3: 15 | BD3: 5 | BE3: 6 | BG3: 6 | BH3: 2 | BJ3: 0 | BK3: 0 | BM3: 55 | BN3: 46 | BO3: 101 | BR3: 16 | BS3: 16 | BU3: 14 | BV3: 10 | BX3: 17 | BY3: 6 | CA3: 2 | CB3: 1 | CD3: 5 | CE3: 1 | CG3: 54 | CH3: 34 | CI3: 88 | CL3: 21 | CM3: 18 | CO3: 9 | CP3: 12 | CR3: 9 | CS3: 2 | CU3: 6 | CV3: 8 | CX3: 1 | CY3: 1 | DA3: 46 | DB3: 41 | DC3: 87 | DF3: 14 | DG3: 15 | DI3: 13 | DJ3: 8 | DL3: 20 | DM3: 12 | DO3: 9 | DP3: 7 | DR3: 7 | DS3: 7 | DU3: 63 | DV3: 49 | DW3: 112 | DZ3: 11 | EA3: 8 | EC3: 8 | ED3: 7 | EF3: 9 | EG3: 1 | EI3: 3 | EJ3: 5 | EL3: 4 | EM3: 2 | EO3: 35 | EP3: 23 | EQ3: 58 | ET3: 9 | EU3: 10 | EW3: 10 | EX3: 6 | EZ3: 6 | FA3: 9 | FC3: 2 | FD3: 2 | FF3: 2 | FG3: 1 | FI3: 29 | FJ3: 28 | FK3: 57 | FN3: 0 | FO3: 0 | FP3: 2 | FR3: 1 | FS3: 1 | FT3: 0 | FV3: 1 | FW3: 1 | FX3: 0 | FZ3: 1 | GA3: 1 | GB3: 0 | GD3: 0 | GE3: 0 | GF3: 1 | GH3: 0 | GI3: 0 | GJ3: 1 | GL3: 3 | GM3: 3 | GN3: 4 | GO3: 10 | GR3: 0 | GS3: 0 | GU3: 0 | GV3: 0 | GX3: 0 | GY3: 0 | HA3: 0 | HB3: 0 | HD3: 0 | HE3: 0 | HG3: 0 | HH3: 0 | HJ3: 0 | HK3: 0 | HL3: 0 | HO3: 39 | HP3: 29 | HR3: 36 | HS3: 35 | HU3: 41 | HV3: 36 | HX3: 25 | HY3: 15 | IA3: 26 | IB3: 24 | ID3: 19 | IE3: 16 | IG3: 186 | IH3: 155 | II3: 341 | IL3: 7 | IM3: 10 | IO3: 13 | IP3: 6 | IR3: 10 | IS3: 7 | IU3: 26 | IV3: 14 | IX3: 11 | IY3: 8 | JA3: 5 | JB3: 1 | JD3: 72 | JE3: 46 | JF3: 118 | JI3: 9 | JJ3: 2 | JL3: 2 | JM3: 1 | JO3: 2 | JP3: 1 | JR3: 6 | JS3: 3 | JU3: 5 | JV3: 1 | JX3: 2 | JY3: 3 | KA3: 26 | KB3: 11 | KC3: 37 | KF3: 0 | KG3: 0 | KI3: 0 | KJ3: 0 | KL3: 0 | KM3: 0 | KO3: 0 | KP3: 0 | KR3: 0 | KS3: 0 | KU3: 0 | KV3: 0 | KX3: 0 | KY3: 0 | KZ3: 0 | LC3: 16 | LD3: 12 | LF3: 15 | LG3: 7 | LI3: 12 | LJ3: 8 | LL3: 32 | LM3: 17 | LO3: 16 | LP3: 9 | LR3: 7 | LS3: 4 | LU3: 98 | LV3: 57 | LW3: 155 | LZ3: 1 | MC3: 2 | MF3: 26 | MG3: 46 | ML3: 29 | MM3: 46 | MN3: 75 | NF3: 1 | NG3: 1 | NI3: 1 | NR3: 2 | NS3: 1 | NT3: 3 | NW3: 29 | NX3: 46 | OF3: 29 | OG3: 46 | OH3: 75 | OK3: 27 | OL3: 41 | OQ3: 1 | OR3: 2 | OT3: 1 | PD3: 2 | PJ3: 1 | PL3: 29 | PM3: 46 | PN3: 75 | PQ3: 2 | PR3: 4 | PT3: 27 | PU3: 41 | QA3: 1 | QC3: 29 | QD3: 46 | QE3: 75 | QH3: 16 | QI3: 41 | QK3: 10 | QL3: 3 | QN3: 3 | QO3: 2 | QT3: 29 | QU3: 46 | QV3: 75 | QY3: 3 | QZ3: 2 | RB3: 22 | RC3: 34 | RE3: 3 | RF3: 8 | RH3: 1 | RI3: 2 | RN3: 29 | RO3: 46 | RP3: 75 | RR3: 4 | RS3: 2 | RT3: 6 | RW3: 5 | RX3: 7 | RY3: 12 | SA3: 9 | SB3: 12 | SC3: 21 | SE3: 2 | SF3: 6 | SG3: 8 | SI3: 0 | SJ3: 0 | SK3: 0 | SM3: 2 | SN3: 13 | SO3: 15 | SQ3: 0 | SR3: 1 | SS3: 1 | SU3: 0 | SV3: 0 | SW3: 0 | SY3: 2 | SZ3: 0 | TA3: 2 | TC3: 0 | TD3: 0 | TE3: 0 | TG3: 1 | TH3: 0 | TI3: 1 | TK3: 0 | TL3: 5 | TM3: 5 | TO3: 0 | TP3: 0 | TQ3: 0 | TS3: 0 | TT3: 0 | TU3: 0 | TW3: 0 | TX3: 0 | TY3: 0 | UA3: 5 | UB3: 0 | UC3: 5 | UE3: 2 | UF3: 1 | UG3: 3 | UI3: 0 | UJ3: 0 | UK3: 0 | UM3: 0 | UN3: 0 | UO3: 0 | UQ3: 0 | UR3: 0 | US3: 0 | UU3: 0 | UV3: 0 | UW3: 0 | UY3: 1 | UZ3: 1 | VA3: 2 | VD3: 0 | VE3: 12 | VF3: 0 | VG3: 0 | VH3: 16 | VI3: 1 | VJ3: 0 | VK3: 0 | VL3: 0 | VM3: 0 | VN3: 29 | VP3: 0 | VQ3: 21 | VR3: 0 | VS3: 0 | VT3: 20 | VU3: 3 | VV3: 0 | VW3: 1 | VX3: 1 | VY3: 0 | VZ3: 46 | WB3: 0 | WC3: 33 | WD3: 0 | WE3: 0 | WF3: 36 | WG3: 4 | WH3: 0 | WI3: 1 | WJ3: 1 | WK3: 0 | WL3: 75 | WO3: 0 | WP3: 0 | WR3: 0 | WS3: 0 | WU3: 0 | WV3: 0 | WX3: 0 | WY3: 0 | XA3: 0 | XB3: 0 | XD3: 0 | XE3: 0 | XG3: 0 | XH3: 0 | XI3: 0 | XK3: كلا | XL3: كلا | XM3: كلا | XN3: كلا | XO3: كلا | XR3: مدرسي | XS3: 2005 | XT3: 0 | XU3: 0 | XV3: نعم | XW3: طابقين | XX3: كلا | XZ3: 9 صف | YA3: 9 | YB3: 6 | YC3: 15 | YD3: طابوق او حجر او بلوك | YE3: نعم | YF3: صالحة | YG3: كافية | YH3: نعم | YI3: بئر عميق | YJ3: نعم | YK3: صهاريج | YL3: نعم | YM3: اسلاك | YN3: جيد | YO3: كلا | YP3: كلا | YQ3: كلا | YS3: ثلاث مدارس فأكثر | YT3: حكومية تابعة لوزارة التربية | YU3: بحاجة الى ترميم | YW3: 221 | YX3: 21 | YZ3: 0 | ZA3: 50 | ZC3: 16 | ZD3: 35 | ZF3: 0 | ZG3: 2 | ZI3: 0 | ZJ3: 1 | ZL3: 0 | ZM3: 2 | ZN3: كلا | ZU3: كلا | ZV3: علي عبدالرضا حياوي | ZW3: 0 | ZX3: 0 | ZY3: 753990291 | ZZ3: 04432313-680c-4850-8091-166b6c26b98e | AAA3: 46086.232 | AAD3: submitted_via_web | AAF3: vFhJwvyD6D9zebJz27xgr3 | AAH3: uuid:a30b9470-9b89-4747-ab73-55dc7db27359 | AAI3: 2
A4: 1400231 | B4: ابتدائي حكومي | C4: حضر | D4: الانصاف | E4: النجف | F4: مركز النجف | G4: 0 | H4: المثنى | I4: 0 | J4: 0 | K4: 1973 | L4: لا | M4: 07813817009 | N4: حكومية | O4: 0 | P4: بنات | Q4: صباحاً | R4: اصلية | U4: مزدوجة مع اخرى | Y4: 0 | AB4: 52 | AE4: 0 | AH4: 0 | AK4: 0 | AN4: 0 | AQ4: 52 | AR4: 52 | AV4: 0 | AY4: 52 | BB4: 2 | BE4: 0 | BH4: 0 | BK4: 0 | BN4: 54 | BO4: 54 | BS4: 46 | BV4: 0 | BY4: 0 | CB4: 0 | CE4: 0 | CH4: 46 | CI4: 46 | CM4: 48 | CP4: 0 | CS4: 0 | CV4: 0 | CY4: 0 | DB4: 48 | DC4: 48 | DG4: 62 | DJ4: 0 | DM4: 0 | DP4: 0 | DS4: 0 | DV4: 62 | DW4: 62 | EA4: 54 | ED4: 0 | EG4: 0 | EJ4: 0 | EM4: 0 | EP4: 54 | EQ4: 54 | EU4: 58 | EX4: 0 | FA4: 0 | FD4: 0 | FG4: 0 | FJ4: 58 | FK4: 58 | FO4: 2 | FS4: 2 | FW4: 2 | GA4: 2 | GE4: 2 | GI4: 2 | GM4: 12 | GO4: 12 | GS4: 0 | GV4: 0 | GY4: 0 | HB4: 0 | HE4: 0 | HH4: 0 | HK4: 0 | HL4: 0 | HP4: 46 | HS4: 48 | HV4: 62 | HY4: 54 | IB4: 58 | IE4: 76 | IH4: 344 | II4: 344 | IM4: 2 | IP4: 1 | IS4: 0 | IV4: 1 | IY4: 4 | JB4: 0 | JE4: 8 | JF4: 8 | JJ4: 0 | JM4: 0 | JP4: 0 | JS4: 0 | JV4: 0 | JY4: 0 | KB4: 0 | KC4: 0 | KG4: 0 | KJ4: 0 | KM4: 0 | KP4: 0 | KS4: 0 | KV4: 0 | KY4: 0 | KZ4: 0 | LD4: 2 | LG4: 1 | LJ4: 0 | LM4: 1 | LP4: 4 | LS4: 0 | LV4: 8 | LW4: 8 | MA4: 1 | MD4: 2 | MG4: 16 | ML4: 0 | MM4: 19 | MN4: 19 | NG4: 1 | NI4: 1 | NR4: 1 | NS4: 1 | NT4: 2 | NW4: 0 | NX4: 19 | OF4: 0 | OG4: 19 | OH4: 19 | OL4: 17 | PA4: 2 | PL4: 0 | PM4: 19 | PN4: 19 | PR4: 2 | PU4: 14 | PX4: 2 | QA4: 1 | QC4: 0 | QD4: 19 | QE4: 19 | QO4: 1 | QR4: 18 | QT4: 0 | QU4: 19 | QV4: 19 | RC4: 3 | RI4: 14 | RL4: 2 | RN4: 0 | RO4: 19 | RP4: 19 | RR4: 0 | RS4: 0 | RT4: 0 | RX4: 2 | RY4: 2 | SB4: 2 | SC4: 2 | SF4: 3 | SG4: 3 | SJ4: 0 | SK4: 0 | SN4: 0 | SO4: 0 | SR4: 0 | SS4: 0 | SV4: 1 | SW4: 1 | SZ4: 0 | TA4: 0 | TD4: 0 | TE4: 0 | TH4: 2 | TI4: 2 | TL4: 0 | TM4: 0 | TP4: 0 | TQ4: 0 | TT4: 0 | TU4: 0 | TX4: 0 | TY4: 0 | UB4: 2 | UC4: 2 | UF4: 2 | UG4: 2 | UJ4: 0 | UK4: 0 | UN4: 0 | UO4: 0 | UR4: 0 | US4: 0 | UV4: 4 | UW4: 4 | UZ4: 1 | VA4: 1 | VP4: 1 | VQ4: 7 | VR4: 0 | VS4: 4 | VT4: 7 | VU4: 0 | VV4: 0 | VW4: 0 | VX4: 0 | VY4: 0 | VZ4: 19 | WB4: 1 | WC4: 7 | WD4: 0 | WE4: 4 | WF4: 7 | WG4: 0 | WH4: 0 | WI4: 0 | WJ4: 0 | WK4: 0 | WL4: 19 | WP4: 0 | WS4: 0 | WV4: 0 | WY4: 0 | XB4: 0 | XE4: 0 | XH4: 0 | XK4: كلا | XL4: كلا | XM4: كلا | XN4: كلا | XO4: كلا | XR4: مدرسي | XS4: 1973 | XT4: 0 | XU4: 0 | XV4: كلا | XW4: طابق | XX4: كلا | XZ4: 12 صف | YA4: 13 | YB4: 2 | YC4: 15 | YD4: طابوق او حجر او بلوك | YE4: نعم | YF4: صالحة | YG4: كافية | YH4: نعم | YI4: بلدية | YJ4: نعم | YK4: شبكة مجاري | YL4: نعم | YM4: بناء | YN4: جيد | YO4: نعم | YP4: نعم | YQ4: كلا | YS4: مدرسة واحدة | YT4: حكومية تابعة لوزارة التربية | YU4: بحاجة الى ترميم | YW4: 240 | YX4: 0 | YZ4: 0 | ZA4: 0 | ZC4: 0 | ZD4: 0 | ZF4: 1 | ZG4: 0 | ZI4: 2 | ZJ4: 0 | ZL4: 0 | ZM4: 0 | ZN4: نعم | ZO4: معلم غير متفرغ | ZP4: خزانة | ZR4: 414 | ZS4: 100 | ZT4: 514 | ZU4: كلا | ZV4: زينب جعفر جواد | ZW4: 0 | ZX4: 0 | ZY4: 753993798 | ZZ4: edeb681b-2027-4812-b8a8-64b8fe3974c1 | AAA4: 46086.24 | AAD4: submitted_via_web | AAF4: vFhJwvyD6D9zebJz27xgr3 | AAH4: uuid:a1bd8c75-e3b3-485c-8bc5-02d13c0efdf1 | AAI4: 3
A5: 1400304 | B5: ابتدائي حكومي | C5: حضر | D5: مصعب بن عمير | E5: النجف | F5: مركز النجف | G5: 0 | H5: الجديدة الثانية | I5: 0 | J5: 0 | K5: 2001 | L5: لا | M5: 07865146950 | N5: حكومية | O5: 0 | P5: بنون | Q5: ظهراً | R5: ضيف | S5: النضال الابتدائية | T5: 0 | U5: مزدوجة مع اخرى | X5: 0 | AA5: 34 | AD5: 12 | AG5: 3 | AJ5: 0 | AM5: 0 | AP5: 49 | AR5: 49 | AU5: 0 | AX5: 34 | BA5: 12 | BD5: 3 | BG5: 0 | BJ5: 0 | BM5: 49 | BO5: 49 | BR5: 16 | BU5: 20 | BX5: 11 | CA5: 10 | CD5: 0 | CG5: 57 | CI5: 57 | CL5: 19 | CO5: 30 | CR5: 10 | CU5: 0 | CX5: 0 | DA5: 59 | DC5: 59 | DF5: 13 | DI5: 33 | DL5: 3 | DO5: 4 | DR5: 0 | DU5: 53 | DW5: 53 | DZ5: 15 | EC5: 20 | EF5: 16 | EI5: 11 | EL5: 0 | EO5: 62 | EQ5: 62 | ET5: 10 | EW5: 12 | EZ5: 3 | FC5: 0 | FF5: 0 | FI5: 25 | FK5: 25 | FN5: 2 | FR5: 2 | FV5: 1 | FZ5: 2 | GD5: 2 | GH5: 1 | GL5: 10 | GO5: 10 | GR5: 3 | GU5: 4 | GX5: 3 | HA5: 4 | HD5: 2 | HG5: 4 | HJ5: 20 | HL5: 20 | HO5: 39 | HR5: 24 | HU5: 47 | HX5: 34 | IA5: 21 | ID5: 39 | IG5: 204 | II5: 204 | IL5: 4 | IO5: 5 | IR5: 0 | IU5: 3 | IX5: 18 | JA5: 0 | JD5: 30 | JF5: 30 | JI5: 0 | JL5: 0 | JO5: 0 | JR5: 0 | JU5: 0 | JX5: 0 | KA5: 0 | KC5: 0 | KF5: 0 | KI5: 0 | KL5: 0 | KO5: 0 | KR5: 0 | KU5: 0 | KX5: 0 | KZ5: 0 | LC5: 4 | LF5: 5 | LI5: 0 | LL5: 3 | LO5: 18 | LR5: 0 | LU5: 30 | LW5: 30 | LZ5: 1 | MC5: 2 | MF5: 8 | MG5: 1 | ML5: 11 | MM5: 1 | MN5: 12 | NG5: 1 | NR5: 0 | NS5: 1 | NT5: 1 | NW5: 11 | NX5: 1 | OF5: 11 | OG5: 1 | OH5: 12 | OK5: 10 | OL5: 1 | OW5: 1 | PL5: 11 | PM5: 1 | PN5: 12 | PQ5: 1 | PT5: 10 | PU5: 1 | QC5: 11 | QD5: 1 | QE5: 12 | QK5: 6 | QN5: 3 | QO5: 1 | QQ5: 2 | QT5: 11 | QU5: 1 | QV5: 12 | RB5: 2 | RE5: 3 | RF5: 1 | RH5: 6 | RN5: 11 | RO5: 1 | RP5: 12 | RR5: 3 | RS5: 0 | RT5: 3 | RW5: 2 | RX5: 0 | RY5: 2 | SA5: 1 | SB5: 0 | SC5: 1 | SE5: 1 | SF5: 1 | SG5: 2 | SI5: 0 | SJ5: 0 | SK5: 0 | SM5: 1 | SN5: 0 | SO5: 1 | SQ5: 0 | SR5: 0 | SS5: 0 | SU5: 0 | SV5: 0 | SW5: 0 | SY5: 0 | SZ5: 0 | TA5: 0 | TC5: 0 | TD5: 0 | TE5: 0 | TG5: 2 | TH5: 0 | TI5: 2 | TK5: 0 | TL5: 0 | TM5: 0 | TO5: 0 | TP5: 0 | TQ5: 0 | TS5: 0 | TT5: 0 | TU5: 0 | TW5: 0 | TX5: 0 | TY5: 0 | UA5: 0 | UB5: 0 | UC5: 0 | UE5: 1 | UF5: 0 | UG5: 1 | UI5: 1 | UJ5: 0 | UK5: 1 | UM5: 0 | UN5: 0 | UO5: 0 | UQ5: 0 | UR5: 0 | US5: 0 | UU5: 0 | UV5: 0 | UW5: 0 | UY5: 2 | UZ5: 0 | VA5: 2 | VD5: 0 | VE5: 5 | VF5: 0 | VG5: 0 | VH5: 4 | VI5: 0 | VJ5: 0 | VK5: 0 | VL5: 2 | VM5: 0 | VN5: 11 | VP5: 0 | VQ5: 1 | VR5: 0 | VS5: 0 | VT5: 0 | VU5: 0 | VV5: 0 | VW5: 0 | VX5: 0 | VY5: 0 | VZ5: 1 | WB5: 0 | WC5: 6 | WD5: 0 | WE5: 0 | WF5: 4 | WG5: 0 | WH5: 0 | WI5: 0 | WJ5: 2 | WK5: 0 | WL5: 12 | WO5: 13 | WR5: 10 | WU5: 4 | WX5: 3 | XA5: 3 | XD5: 1 | XG5: 0 | XK5: كلا | XL5: كلا | XM5: كلا | XN5: كلا | XO5: كلا | YW5: 23 | YX5: 44 | YZ5: 0 | ZA5: 0 | ZC5: 3 | ZD5: 8 | ZF5: 0 | ZG5: 1 | ZI5: 0 | ZJ5: 2 | ZL5: 0 | ZM5: 0 | ZN5: نعم | ZO5: معاون | ZP5: خزانة | ZR5: 33 | ZS5: 1350 | ZT5: 1383 | ZU5: كلا | ZV5: محمد عبد الزهرة إبراهيم | ZW5: جديدة 2 المنطقة القديمة | ZY5: 755778828 | ZZ5: b03c7708-7671-423e-af65-73bb19a7b322 | AAA5: 46091.745 | AAD5: submitted_via_web | AAF5: v6nmEQkamJVjF9JCqSwLhn | AAH5: uuid:b03c7708-7671-423e-af65-73bb19a7b322 | AAI5: 4

Sheet e_codes
A1: code_key | B1: القضاء | C1: الناحية | D1: ت | E1: اسم المدرسة | F1: الحي او المحلة | G1: TRUE
A2: 1400179 | B2: النجف | C2: المركز | D2: 1 | E2: الغفاري | F2: الجديدة الثانية | G2: =VLOOKUP(A2,survey!$1:$1048576,1,FALSE) -> #N/A
A3: 1400180 | B3: النجف | C3: المركز | D3: 2 | E3: الحيدرية | F3: الجديدة الاولى | G3: =VLOOKUP(A3,survey!$1:$1048576,1,FALSE) -> #N/A
A4: 1400181 | B4: النجف | C4: المركز | D4: 3 | E4: النضــال | F4: الجديدة الثانية | G4: =VLOOKUP(A4,survey!$1:$1048576,1,FALSE) -> #N/A
A5: 1400182 | B5: النجف | C5: المركز | D5: 4 | E5: التهــذيب | F5: الجديدة الرابعة | G5: =VLOOKUP(A5,survey!$1:$1048576,1,FALSE) -> #N/A
A6: 1400183 | B6: النجف | C6: المركز | D6: 5 | E6: مالك الاشتر | F6: الجديدة الرابعة | G6: =VLOOKUP(A6,survey!$1:$1048576,1,FALSE) -> #N/A
A7: 1400184 | B7: النجف | C7: المركز | D7: 6 | E7: حليف القرآن | F7: المثنى | G7: =VLOOKUP(A7,survey!$1:$1048576,1,FALSE) -> #N/A
A8: 1400185 | B8: النجف | C8: المركز | D8: 7 | E8: اصحاب الكساء | F8: الجديدة الثالثة | G8: =VLOOKUP(A8,survey!$1:$1048576,1,FALSE) -> #N/A
A9: 1400186 | B9: النجف | C9: المركز | D9: 8 | E9: السدير الأساسية | F9: الجديدة الاولى | G9: =VLOOKUP(A9,survey!$1:$1048576,1,FALSE) -> #N/A
A10: 1400188 | B10: النجف | C10: المركز | D10: 9 | E10: الاميــــر | F10: الجديدة الرابعة | G10: =VLOOKUP(A10,survey!$1:$1048576,1,FALSE) -> #N/A
A11: 1400189 | B11: النجف | C11: المركز | D11: 10 | E11: التيسير | F11: الكرامة | G11: =VLOOKUP(A11,survey!$1:$1048576,1,FALSE) -> #N/A
A12: 1400190 | B12: النجف | C12: المركز | D12: 11 | E12: العاصفة | F12: الاسكان | G12: =VLOOKUP(A12,survey!$1:$1048576,1,FALSE) -> #N/A
A13: 1400191 | B13: النجف | C13: المركز | D13: 12 | E13: دعبل الخزاعي | F13: المعلمين | G13: =VLOOKUP(A13,survey!$1:$1048576,1,FALSE) -> #N/A
... A280: 1401644 | B280: النجف | C280: المركز | D280: 279 | E280: الفرح/2 النموذجية المختلطة | F280: الانصار | G280: =VLOOKUP(A280,survey!$1:$1048576,1,FALSE) -> #N/A
A281: 1401645 | B281: النجف | C281: المركز | E281: الفرح / 1 النموذجية للينات | F281: الانصار | G281: =VLOOKUP(A281,survey!$1:$1048576,1,FALSE) -> #N/A
A282: 1401646 | B282: النجف | C282: المركز | D282: 280 | E282: الفرح / 1 النموذجية المختلطة | F282: الجمعية | G282: =VLOOKUP(A282,survey!$1:$1048576,1,FALSE) -> #N/A
A283: 1401647 | B283: النجف | C283: المركز | E283: الفرح /2 النموذجية للبنات | F283: الجمعية | G283: =VLOOKUP(A283,survey!$1:$1048576,1,FALSE) -> #N/A
A284: 1401649 | B284: النجف | C284: المركز | D284: 281 | E284: الرفعة | F284: الرحمة | G284: =VLOOKUP(A284,survey!$1:$1048576,1,FALSE) -> #N/A
A285: 1401550 | B285: النجف | C285: المركز | D285: 282 | E285: عبدالزهرة عنوز | F285: الميلاد / شمال الحولي | G285: =VLOOKUP(A285,survey!$1:$1048576,1,FALSE) -> #N/A
A286: 1401665 | B286: النجف | C286: المركز | D286: 283 | E286: زهور الغد الاساسية (قرض) | F286: مجمع السلطان | G286: =VLOOKUP(A286,survey!$1:$1048576,1,FALSE) -> #N/A
A287: 1401664 | B287: النجف | C287: المركز | D287: 284 | E287: تراث النجف الاساسية | F287: مجمع السلطان | G287: =VLOOKUP(A287,survey!$1:$1048576,1,FALSE) -> #N/A
A288: 1401680 | B288: النجف | C288: المركز | D288: 285 | E288: الشهيد ثائر الهلالي | F288: النداء | G288: =VLOOKUP(A288,survey!$1:$1048576,1,FALSE) -> #N/A
A289: 1401666 | B289: النجف | C289: المركز | D289: 286 | E289: ثمرة العلم | F289: السلام | G289: =VLOOKUP(A289,survey!$1:$1048576,1,FALSE) -> #N/A
A290: 1401709 | B290: النجف | C290: المركز | D290: 287 | E290: زهور السوسن | F290: المكرمة | G290: =VLOOKUP(A290,survey!$1:$1048576,1,FALSE) -> #N/A
A291: 1400324 | B291: النجف | C291: الحيدرية | D291: 1 | E291: الكاظمي | F291: المركز | G291: =VLOOKUP(A291,survey!$1:$1048576,1,FALSE) -> #N/A
A292: 1400325 | B292: النجف | C292: الحيدرية | D292: 2 | E292: الاصمعي | F292: المنيثر | G292: =VLOOKUP(A292,survey!$1:$1048576,1,FALSE) -> #N/A
A293: 1400326 | B293: النجف | C293: الحيدرية | D293: 3 | E293: غرناطــة | F293: المزوكة | G293: =VLOOKUP(A293,survey!$1:$1048576,1,FALSE) -> #N/A
A294: 1400327 | B294: النجف | C294: الحيدرية | D294: 4 | E294: الفجر الجديد | F294: الاجدع الشمالي | G294: =VLOOKUP(A294,survey!$1:$1048576,1,FALSE) -> #N/A
A295: 1400328 | B295: النجف | C295: الحيدرية | D295: 5 | E295: الشموس | F295: الزهراء | G295: =VLOOKUP(A295,survey!$1:$1048576,1,FALSE) -> #N/A
... A629: 1400563 | B629: قضاء المشخاب | C629: مركز المشخاب | D629: 3 | E629: العزة | F629: العصري | G629: =VLOOKUP(A629,survey!$1:$1048576,1,FALSE) -> #N/A
A630: 1400564 | B630: قضاء المشخاب | C630: مركز المشخاب | D630: 4 | E630: الحديبية | F630: ابو واوية | G630: =VLOOKUP(A630,survey!$1:$1048576,1,FALSE) -> #N/A
A631: 1400529 | B631: قضاء المشخاب | C631: مركز المشخاب | D631: 5 | E631: الخورنق | F631: رمل الثواير | G631: =VLOOKUP(A631,survey!$1:$1048576,1,FALSE) -> #N/A
A632: 1400565 | B632: قضاء المشخاب | C632: مركز المشخاب | D632: 6 | E632: النجاح | F632: هور فريق | G632: =VLOOKUP(A632,survey!$1:$1048576,1,FALSE) -> #N/A
A633: 1400566 | B633: قضاء المشخاب | C633: مركز المشخاب | D633: 7 | E633: التأخي | F633: الهارمية | G633: =VLOOKUP(A633,survey!$1:$1048576,1,FALSE) -> #N/A
A634: 1400567 | B634: قضاء المشخاب | C634: مركز المشخاب | D634: 8 | E634: السعادة | F634: المالحة | G634: =VLOOKUP(A634,survey!$1:$1048576,1,FALSE) -> #N/A
A635: 1400568 | B635: قضاء المشخاب | C635: مركز المشخاب | D635: 9 | E635: ثورة العشرين | F635: راك الحصوة | G635: =VLOOKUP(A635,survey!$1:$1048576,1,FALSE) -> #N/A
A636: 1400569 | B636: قضاء المشخاب | C636: مركز المشخاب | D636: 10 | E636: الخمائل | F636: طبر سيد نور | G636: =VLOOKUP(A636,survey!$1:$1048576,1,FALSE) -> #N/A
A637: 1400570 | B637: قضاء المشخاب | C637: مركز المشخاب | D637: 11 | E637: النبوغ | F637: الجفلاوية | G637: =VLOOKUP(A637,survey!$1:$1048576,1,FALSE) -> #N/A
A638: 1400571 | B638: قضاء المشخاب | C638: مركز المشخاب | D638: 12 | E638: الشهيد راهي عبدالواحد | F638: راك الحصوة | G638: =VLOOKUP(A638,survey!$1:$1048576,1,FALSE) -> #N/A
A639: 1400572 | B639: قضاء المشخاب | C639: مركز المشخاب | D639: 13 | E639: النهروان | F639: ال فرعون | G639: =VLOOKUP(A639,survey!$1:$1048576,1,FALSE) -> #N/A
...

Sheet t1
A1: المديرية العامة للتربية في محافظة النجف الاشرف | S1: خلاصة محافظة النجف الاشرف
A2: قسم التخطيط التربوي | T2: التعليم الابتدائي
B4: جدول رقم (( 1 ))
B5: التعليم الابتدائي للعام الدراسي2025/2024
B6: عدد المدارس والتلامذة الموجودين والمقبولين الجدد وعدد اعضاء الهيئة التعليمية واستقلالية المدرسة ( الصباحي والمسائي )
A9: الموقع البيئي | B9: عدد المدارس | F9: عدد التلامذة المقبولين ( الجدد ) | I9: عدد التلامذة الموجودين | L9: عدد اعضاء الهيئة التعليمية | O9: عدد المدارس حسب الاستقلالية | Q9: عدد المدارس حسب الدوام | V9: مدارس الفتح الجديد
F10: في الصف الاول
B11: بنون | C11: بنات | D11: مختلطة | E11: المجموع | F11: بنون | G11: بنات | H11: المجموع | I11: بنون | J11: بنات | K11: المجموع | L11: ذكور | M11: اناث | N11: المجموع | O11: اصلية | P11: ضيف | Q11: صباحاً | R11: ظهرا | S11: صباحا وظهرا | T11: مساءاً | U11: المجموع
A12: حضـــر | B12: =COUNTIFS(survey!C:C,"حضر",survey!P:P,"بنون") -> 1
A14: ريـــــف
A16: المجموع
B17: ملاحظة : لايوجد في محافظتنا مدارس ابتدائية مسائية .
A18: المديرية العامة للتربية في محافظة النجف الاشرف | S18: قضاء النجف
A19: قسم التخطيط التربوي | S19: التعليم الابتدائي
B21: جدول رقم (( 1 ))
B22: التعليم الابتدائي للعام الدراسي2025/2024
B23: عدد المدارس والتلامذة الموجودين والمقبولين الجدد وعدد اعضاء الهيئة التعليمية واستقلالية المدرسة ( الصباحي والمسائي )
A26: الموقع البيئي | B26: عدد المدارس | F26: عدد التلامذة المقبولين ( الجدد ) | I26: عدد التلامذة الموجودين | L26: عدد اعضاء الهيئة التعليمية | O26: استقلالية المدرسة | Q26: عدد المدارس حسب الدوام | V26: مدارس الفتح الجديد
F27: في الصف الاول
B28: بنون | C28: بنات | D28: مختلطة | E28: المجموع | F28: بنون | G28: بنات | H28: المجموع | I28: بنون | J28: بنات | K28: المجموع | L28: ذكور | M28: اناث | N28: المجموع | O28: اصلية | P28: ضيف | Q28: صباحاً | R28: ظهرا | S28: صباحا وظهرا | T28: مساءاً | U28: المجموع
A29: حضـــر | B29: =[1]الحضر!G329 -> 0 | C29: =[1]الحضر!H329 -> 0 | D29: =[1]الحضر!I329 -> 0 | E29: =D29+C29+B29 -> 0 | F29: =[1]الحضر!AM329 -> 0 | G29: =[1]الحضر!AN329 -> 0 | H29: =F29+G29 -> 0 | I29: =[1]الحضر!EN329 -> 0 | J29: =[1]الحضر!EO329 -> 0 | K29: =I29+J29 -> 0 | L29: =[1]الحضر!JG329 -> 0 | M29: =[1]الحضر!JH329 -> 0 | N29: =L29+M29 -> 0 | O29: =[1]الحضر!P329 -> 0 | P29: =[1]الحضر!Q329 -> 0 | Q29: =[1]الحضر!L329 -> 0 | R29: =[1]الحضر!M329 -> 0 | S29: =[1]الحضر!N329 -> 0 | T29: =[1]الحضر!O329 -> 0 | U29: =T29+S29+R29+Q29 -> 0 | V29: =[1]الحضر!W329 -> 0
A31: ريـــــف | B31: =[1]الريف!G73 -> 0 | C31: =[1]الريف!H73 -> 0 | D31: =[1]الريف!I73 -> 0 | E31: =D31+C31+B31 -> 0 | F31: =[1]الريف!AM73 -> 0 | G31: =[1]الريف!AN73 -> 0 | H31: =F31+G31 -> 0 | I31: =[1]الريف!EN73 -> 0 | J31: =[1]الريف!EO73 -> 0 | K31: =I31+J31 -> 0 | L31: =[1]الريف!JG73 -> 0 | M31: =[1]الريف!JH73 -> 0 | N31: =L31+M31 -> 0 | O31: =[1]الريف!P73 -> 0 | P31: =[1]الريف!Q73 -> 0 | Q31: =[1]الريف!L73 -> 0 | R31: =[1]الريف!M73 -> 0 | S31: =[1]الريف!N73 -> 0 | T31: =[1]الريف!O73 -> 0 | U31: =T31+S31+R31+Q31 -> 0 | V31: =[1]الريف!W73 -> 0
A33: المجموع | B33: =SUM(B29:B32) -> 0 | C33: =SUM(C29:C32) -> 0 | D33: =SUM(D29:D32) -> 0 | E33: =SUM(E29:E32) -> 0 | F33: =SUM(F29:F32) -> 0 | G33: =SUM(G29:G32) -> 0 | H33: =SUM(H29:H32) -> 0 | I33: =SUM(I29:I32) -> 0 | J33: =SUM(J29:J32) -> 0 | K33: =J33+I33 -> 0 | L33: =SUM(L29:L32) -> 0 | M33: =SUM(M29:M32) -> 0 | N33: =SUM(N29:N32) -> 0 | O33: =SUM(O29:O32) -> 0 | P33: =SUM(P29:P32) -> 0 | Q33: =SUM(Q29:Q32) -> 0 | R33: =SUM(R29:R32) -> 0 | S33: =SUM(S29:S32) -> 0 | ... U33: =SUM(U29:U32) -> 0 | V33: =V31+V29 -> 0
A35: المديرية العامة للتربية في محافظة النجف الاشرف | R35: مركز النجف
A36: قسم التخطيط التربوي | R36: التعليم الابتدائي
B38: جدول رقم (( 1 ))
B39: التعليم الابتدائي للعام الدراسي2025/2024
B40: عدد المدارس والتلامذة الموجودين والمقبولين الجدد وعدد اعضاء الهيئة التعليمية واستقلالية المدرسة ( الصباحي والمسائي )
A43: الموقع البيئي | B43: عدد المدارس | F43: عدد التلامذة المقبولين ( الجدد ) | I43: عدد التلامذة الموجودين | L43: عدد اعضاء الهيئة التعليمية | O43: استقلالية المدرسة | Q43: عدد المدارس حسب الدوام | V43: مدارس الفتح الجديد
F44: في الصف الاول
B45: بنون | C45: بنات | D45: مختلطة | E45: المجموع | F45: بنون | G45: بنات | H45: المجموع | I45: بنون | J45: بنات | K45: المجموع | L45: ذكور | M45: اناث | N45: المجموع | O45: اصلية | P45: ضيف | Q45: صباحاً | R45: ظهرا | S45: صباحا وظهرا | T45: مساءاً | U45: المجموع
A46: حضـــر
A48: ريـــــف
A50: المجموع
A52: المديرية العامة للتربية في محافظة النجف الاشرف | R52: ناحية الحيدرية
A53: قسم التخطيط التربوي | R53: التعليم الابتدائي
B55: جدول رقم (( 1 ))
B56: التعليم الابتدائي للعام الدراسي2025/2024
B57: عدد المدارس والتلامذة الموجودين والمقبولين الجدد وعدد اعضاء الهيئة التعليمية واستقلالية المدرسة ( الصباحي والمسائي )
A59: الموقع البيئي | B59: عدد المدارس | F59: عدد التلامذة المقبولين ( الجدد ) | I59: عدد التلامذة الموجودين | L59: عدد اعضاء الهيئة التعليمية | O59: استقلالية المدرسة | Q59: عدد المدارس حسب الدوام | V59: مدارس الفتح الجديد
...

Sheet t4&t5
A1: المديرية العامة للتربية في محافظة النجف الاشرف | O1: خلاصة محافظة النجف الاشرف
A2: قسم التخطيط التربوي | O2: التعليم الابتدائي
A3: جدول رقم ((4))
A4: التعليم الابتدائي للعام الدراسي2024 / 2025
A5: عدد التلامذة الجدد حسب العمر والجنس
B7: عمر 5 | D7: عمر6 | F7: عمر 7 | H7: عمر 8 | J7: عمر 9 | L7: عمر 10 | N7: المجموع
A9: بنــــــــون | B9: =SUM(survey!X:X) -> 1 | N9: =L9+J9+H9+F9+D9+B9 -> 1
A10: بنــــــــات | B10: =SUM(survey!Y:Y) -> 0 | N10: =L10+J10+H10+F10+D10+B10 -> 0
A11: المجمــــــــوع | N11: =L11+J11+H11+F11+D11+B11 -> 0
G12: `
G13: (( 5 )) جدول رقم
F14: التعليم الابتدائي للعام الدراسي2024 / 2025
F15: عدد التلامذة المسجلين حسب الصف والعمروالجنس
B17: الأول | D17: الثاني | F17: الثالث | H17: الرابع | J17: الخامس | L17: السادس | N17: المجموع
B18: بنون | C18: بنات | D18: بنون | E18: بنات | F18: بنون | G18: بنات | H18: بنون | I18: بنات | J18: بنون | K18: بنات | L18: بنون | M18: بنات | N18: بنون | O18: بنات | P18: المجموع
A19: عمر 5 | B19: ='[1]التعليم الابتدائي'!AP754 -> 0 | C19: ='[1]التعليم الابتدائي'!AQ754 -> 0 | N19: =B19 -> 0 | O19: =C19 -> 0 | P19: =O19+N19 -> 0
A20: عمر6 | B20: ='[1]التعليم الابتدائي'!AR754 -> 0 | C20: ='[1]التعليم الابتدائي'!AS754 -> 0 | N20: =B20 -> 0 | O20: =C20 -> 0 | P20: =O20+N20 -> 0
A21: عمر 7 | B21: ='[1]التعليم الابتدائي'!AT754 -> 0 | C21: ='[1]التعليم الابتدائي'!AU754 -> 0 | D21: ='[1]التعليم الابتدائي'!BE754 -> 0 | E21: ='[1]التعليم الابتدائي'!BF754 -> 0 | N21: =D21+B21 -> 0 | O21: =E21+C21 -> 0 | P21: =O21+N21 -> 0
A22: عمر 8 | B22: ='[1]التعليم الابتدائي'!AV754 -> 0 | C22: ='[1]التعليم الابتدائي'!AW754 -> 0 | D22: ='[1]التعليم الابتدائي'!BG754 -> 0 | E22: ='[1]التعليم الابتدائي'!BH754 -> 0 | F22: ='[1]التعليم الابتدائي'!BR754 -> 0 | G22: ='[1]التعليم الابتدائي'!BS754 -> 0 | N22: =F22+D22+B22 -> 0 | O22: =G22+E22+C22 -> 0 | P22: =O22+N22 -> 0
A23: عمر 9 | B23: ='[1]التعليم الابتدائي'!AX754 -> 0 | C23: ='[1]التعليم الابتدائي'!AY754 -> 0 | D23: ='[1]التعليم الابتدائي'!BI754 -> 0 | E23: ='[1]التعليم الابتدائي'!BJ754 -> 0 | F23: ='[1]التعليم الابتدائي'!BT754 -> 0 | G23: ='[1]التعليم الابتدائي'!BU754 -> 0 | H23: ='[1]التعليم الابتدائي'!CE754 -> 0 | I23: ='[1]التعليم الابتدائي'!CF754 -> 0 | N23: =B23+D23+F23+H23 -> 0 | O23: =I23+G23+E23+C23 -> 0 | P23: =O23+N23 -> 0
A24: عمر 10 | B24: ='[1]التعليم الابتدائي'!AZ754 -> 0 | C24: ='[1]التعليم الابتدائي'!BA754 -> 0 | D24: ='[1]التعليم الابتدائي'!BK754 -> 0 | E24: ='[1]التعليم الابتدائي'!BL754 -> 0 | F24: ='[1]التعليم الابتدائي'!BV754 -> 0 | G24: ='[1]التعليم الابتدائي'!BW754 -> 0 | H24: ='[1]التعليم الابتدائي'!CG754 -> 0 | I24: ='[1]التعليم الابتدائي'!CH754 -> 0 | J24: ='[1]التعليم الابتدائي'!CR754 -> 0 | K24: ='[1]التعليم الابتدائي'!CS754 -> 0 | N24: =B24+D24+F24+H24+J24 -> 0 | O24: =K24+I24+G24+E24+C24 -> 0 | P24: =O24+N24 -> 0
A25: عمر 11 | D25: ='[1]التعليم الابتدائي'!BM754 -> 0 | E25: ='[1]التعليم الابتدائي'!BN754 -> 0 | F25: ='[1]التعليم الابتدائي'!BX754 -> 0 | G25: ='[1]التعليم الابتدائي'!BY754 -> 0 | H25: ='[1]التعليم الابتدائي'!CI754 -> 0 | I25: ='[1]التعليم الابتدائي'!CJ754 -> 0 | J25: ='[1]التعليم الابتدائي'!CT754 -> 0 | K25: ='[1]التعليم الابتدائي'!CU754 -> 0 | L25: ='[1]التعليم الابتدائي'!DE754 -> 0 | M25: ='[1]التعليم الابتدائي'!DF754 -> 0 | N25: =D25+F25+H25+J25+L25 -> 0 | O25: =M25+K25+I25+G25+E25 -> 0 | P25: =O25+N25 -> 0
A26: عمر 12 | F26: ='[1]التعليم الابتدائي'!BZ754 -> 0 | G26: ='[1]التعليم الابتدائي'!CA754 -> 0 | H26: ='[1]التعليم الابتدائي'!CK754 -> 0 | I26: ='[1]التعليم الابتدائي'!CL754 -> 0 | J26: ='[1]التعليم الابتدائي'!CV754 -> 0 | K26: ='[1]التعليم الابتدائي'!CW754 -> 0 | L26: ='[1]التعليم الابتدائي'!DG754 -> 0 | M26: ='[1]التعليم الابتدائي'!DH754 -> 0 | N26: =L26+J26+H26+F26 -> 0 | O26: =M26+K26+I26+G26 -> 0 | P26: =O26+N26 -> 0
A27: عمر 13 | H27: ='[1]التعليم الابتدائي'!CM754 -> 0 | I27: ='[1]التعليم الابتدائي'!CN754 -> 0 | J27: ='[1]التعليم الابتدائي'!CX754 -> 0 | K27: ='[1]التعليم الابتدائي'!CY754 -> 0 | L27: ='[1]التعليم الابتدائي'!DI754 -> 0 | M27: ='[1]التعليم الابتدائي'!DJ754 -> 0 | N27: =L27+J27+H27 -> 0 | O27: =M27+K27+I27 -> 0 | P27: =O27+N27 -> 0
A28: عمر14 | J28: ='[1]التعليم الابتدائي'!CZ754 -> 0 | K28: ='[1]التعليم الابتدائي'!DA754 -> 0 | L28: ='[1]التعليم الابتدائي'!DK754 -> 0 | M28: ='[1]التعليم الابتدائي'!DL754 -> 0 | N28: =L28+J28 -> 0 | O28: =M28+K28 -> 0 | P28: =O28+N28 -> 0
A29: عمر 15 فأكثر | L29: ='[1]التعليم الابتدائي'!DM754 -> 0 | M29: ='[1]التعليم الابتدائي'!DN754 -> 0 | N29: =L29 -> 0 | O29: =M29 -> 0 | P29: =O29+N29 -> 0
A30: المجموع | B30: =SUM(B19:B29) -> 0 | C30: =SUM(C19:C29) -> 0 | D30: =D25+D24+D23+D22+D21 -> 0 | E30: =SUM(E19:E29) -> 0 | F30: =SUM(F19:F29) -> 0 | G30: =SUM(G19:G29) -> 0 | H30: =SUM(H19:H29) -> 0 | I30: =SUM(I19:I29) -> 0 | J30: =SUM(J19:J29) -> 0 | K30: =SUM(K19:K29) -> 0 | L30: =SUM(L25:L29) -> 0 | M30: =SUM(M25:M29) -> 0 | N30: =SUM(N19:N29) -> 0 | O30: =SUM(O19:O29) -> 0 | P30: =SUM(P19:P29) -> 0
A32: المديرية العامة للتربية في محافظة النجف الاشرف | O32: قضاء النجف
A33: قسم التخطيط التربوي | O33: التعليم الابتدائي
A34: جدول رقم ((4))
A35: التعليم الابتدائي للعام الدراسي2024 / 2025
A36: عدد التلامذة الجدد حسب العمر والجنس
B38: عمر 5 | D38: عمر6 | F38: عمر 7 | H38: عمر 8 | J38: عمر 9 | L38: عمر 10 | N38: المجموع
A40: بنــــــــون | B40: ='[1]التعليم الابتدائي'!AA377 -> 0 | D40: ='[1]التعليم الابتدائي'!AC377 -> 0 | F40: ='[1]التعليم الابتدائي'!AE377 -> 0 | H40: ='[1]التعليم الابتدائي'!AG377 -> 0 | J40: ='[1]التعليم الابتدائي'!AI377 -> 0 | L40: ='[1]التعليم الابتدائي'!AK377 -> 0 | N40: =L40+J40+H40+F40+D40+B40 -> 0
A41: بنــــــــات | B41: ='[1]التعليم الابتدائي'!AB377 -> 0 | D41: ='[1]التعليم الابتدائي'!AD377 -> 0 | F41: ='[1]التعليم الابتدائي'!AF377 -> 0 | H41: ='[1]التعليم الابتدائي'!AH377 -> 0 | J41: ='[1]التعليم الابتدائي'!AJ377 -> 0 | L41: ='[1]التعليم الابتدائي'!AL377 -> 0 | N41: =L41+J41+H41+F41+D41+B41 -> 0
A42: المجمــــــــوع | B42: =SUM(B40:B41) -> 0 | D42: =SUM(D40:D41) -> 0 | F42: =SUM(F40:F41) -> 0 | H42: =SUM(H40:H41) -> 0 | J42: =SUM(J40:J41) -> 0 | L42: =SUM(L40:L41) -> 0 | N42: =L42+J42+H42+F42+D42+B42 -> 0
A43: *
A44: جدول رقم ((5))
A45: التعليم الابتدائي للعام الدراسي2024 / 2025
A46: عدد التلامذة المسجلين حسب الصف والعمروالجنس
...

Sheet t6&t7
A1: المديرية العامة للتربية في محافظة النجف الاشرف | T1: خلاصة محافظة النجف الاشرف
A2: قسم التخطيط التربوي | U2: التعليم الابتدائي
B3: جدول رقم (( 6 ))
B4: التعليم الابتدائي للعام الدراسي2025/2024
B5: عدد الهيئات التعليمية حسب العنوان الوظيفي والشهادة
B7: الجنس | C7: الهيئة التعليمية حسب العنوان الوظيفي | H7: الهيئة التعليمية حسب العنوان والشهادة
H8: دورات تربوية | I8: دبلوم تعليمي لمعاهد المعلمين والمعاهد المركزية | J8: دبلوم عام | K8: دبلوم فنون جميلة | L8: جامعية | N8: دراسات عليا | Q8: اخــرى | R8: المجموع
C9: مدير | D9: معاون | E9: معلم | F9: مرشد | G9: المجموع | L9: تربوية تعليمية | M9: غير تربوية | N9: دبلوم عالي | O9: ماجستير | P9: دكتوراه
B10: ذكــــــور | C10: ='[1]التعليم الابتدائي'!IY754 -> 428 | D10: ='[1]التعليم الابتدائي'!JA754 -> 0 | E10: ='[1]التعليم الابتدائي'!JC754 -> 0 | F10: ='[1]التعليم الابتدائي'!JE754 -> 0 | G10: =E10+D10+C10+F10 -> 428 | H10: ='[1]التعليم الابتدائي'!ADR754 -> 0 | I10: ='[1]التعليم الابتدائي'!ADT754 -> 0 | J10: ='[1]التعليم الابتدائي'!ADX754 -> 0 | K10: ='[1]التعليم الابتدائي'!ADV754 -> 0 | L10: ='[1]التعليم الابتدائي'!ADZ754 -> 0 | M10: ='[1]التعليم الابتدائي'!AEB754 -> 0 | N10: ='[1]التعليم الابتدائي'!AED754 -> 0 | O10: ='[1]التعليم الابتدائي'!AEF754 -> 0 | P10: ='[1]التعليم الابتدائي'!AEH754 -> 0 | Q10: ='[1]التعليم الابتدائي'!AEJ754 -> 1 | R10: =Q10+P10+N10+M10+L10+K10+I10+J10+H10+O10 -> 1
B11: انــــــــاث | C11: ='[1]التعليم الابتدائي'!IZ754 -> 295 | D11: ='[1]التعليم الابتدائي'!JB754 -> 0 | E11: ='[1]التعليم الابتدائي'!JD754 -> 0 | F11: ='[1]التعليم الابتدائي'!JF754 -> 0 | G11: =E11+D11+C11+F11 -> 295 | H11: ='[1]التعليم الابتدائي'!ADS754 -> 0 | I11: ='[1]التعليم الابتدائي'!ADU754 -> 0 | J11: ='[1]التعليم الابتدائي'!ADY754 -> 0 | K11: ='[1]التعليم الابتدائي'!ADW754 -> 0 | L11: ='[1]التعليم الابتدائي'!AEA754 -> 0 | M11: ='[1]التعليم الابتدائي'!AEC754 -> 0 | N11: ='[1]التعليم الابتدائي'!AEE754 -> 0 | O11: ='[1]التعليم الابتدائي'!AEG754 -> 0 | P11: ='[1]التعليم الابتدائي'!AEI754 -> 0 | Q11: ='[1]التعليم الابتدائي'!AEK754 -> 1 | R11: =Q11+P11+N11+M11+L11+K11+I11+J11+H11+O11 -> 1
B12: المجموع | C12: =C10+C11 -> 723 | D12: =D10+D11 -> 0 | E12: =E10+E11 -> 0 | F12: =SUM(F10:F11) -> 0 | G12: =E12+D12+C12+F12 -> 723 | H12: =H11+H10 -> 0 | I12: =I11+I10 -> 0 | J12: =J11+J10 -> 0 | K12: =K11+K10 -> 0 | L12: =L11+L10 -> 0 | M12: =M11+M10 -> 0 | N12: =N11+N10 -> 0 | O12: =O11+O10 -> 0 | ... R12: =R11+R10 -> 2
B14: جدول رقم (( 7 ))
B15: التعليم الابتدائي للعام الدراسي2025/2024
B16: عدد الابنية المدرسية وعدد المكتبات
A18: عدد الابنية حسب العائدية | D18: عدد الابنية التي تشغلها | G18: عدد الابنية حسب الحالة العمرانية | J18: عدد الابنية حسب نوع البناء | L18: عدد الابنية حسب مادة البناء | R18: المجموع الكلي للابنية | S18: عدد الابنية حسب نوع الخدمات
A19: حكومية | C19: مستاجرة | D19: مدرسة واحدة | E19: مدرستان | F19: ثلاث مدارس فاكثر | G19: صالحة | H19: بحاجة الى ترميم | I19: غير صالحة | J19: مدرسي | K19: غير مدرسي | L19: طابوق او حجر | M19: بناء جاهز | N19: طين او صريفة | O19: هياكل حديدية | P19: كرفان | Q19: اخرى | S19: عدد الابنية التي تتوفر فيها مرافق صحية | T19: عدد الابنية التي يصلها ماء صالح للشرب | U19: عدد الابنية المزودة بخدمة مجاري | V19: عدد الابنية التي تحتوي سياج مدرسي
A20: عائدة للتربية | B20: لجهات اخرى
A21: ='[1]التعليم الابتدائي'!ALH754 -> 1 | B21: ='[1]التعليم الابتدائي'!ALI754 -> 466 | C21: ='[1]التعليم الابتدائي'!ALJ754 -> 0 | D21: ='[1]التعليم الابتدائي'!ALE754 -> 172 | E21: ='[1]التعليم الابتدائي'!ALF754 -> 282 | F21: ='[1]التعليم الابتدائي'!ALG754 -> 13 | G21: ='[1]التعليم الابتدائي'!ALK754 -> 216 | H21: ='[1]التعليم الابتدائي'!ALL754 -> 219 | I21: ='[1]التعليم الابتدائي'!ALM754 -> 32 | J21: ='[1]التعليم الابتدائي'!AIS754 -> 467 | K21: ='[1]التعليم الابتدائي'!AIT754 -> 0 | L21: ='[1]التعليم الابتدائي'!AJN754 -> 427 | M21: ='[1]التعليم الابتدائي'!AJR754 -> 7 | N21: ='[1]التعليم الابتدائي'!AJP754 -> 0 | O21: ='[1]التعليم الابتدائي'!AJQ754 -> 4 | P21: ='[1]التعليم الابتدائي'!AJS754 -> 29 | Q21: ='[1]التعليم الابتدائي'!AJT754 -> 0 | R21: =Q21+M21+P21+N21+L21+O21 -> 467 | S21: ='[1]التعليم الابتدائي'!AJU754 -> 467 | T21: ='[1]التعليم الابتدائي'!AKA754 -> 466 | U21: ='[1]التعليم الابتدائي'!AKH754 -> 467 | V21: ='[1]التعليم الابتدائي'!AKL754 -> 465
G23: عدد الابنية المدرسية حسب عدد الطوابق وعدد الصفوف للعام المدرسي2024-2025
B24: عدد الابنية حسب عدد الطوابق | J24: عدد الابنية حسب عدد الصفوف
B25: طابق واحد | D25: طابقين | F25: ثلاثة طوابق | H25: المجموع | J25: 6 صف | L25: 9 صف | N25: 12 صف | P25: 18 صف | R25: 24 صف | T25: المجموع
B26: ='[1]التعليم الابتدائي'!AIZ754 -> 193 | D26: ='[1]التعليم الابتدائي'!AJA754 -> 263 | F26: ='[1]التعليم الابتدائي'!AJB754 -> 11 | H26: =F26+D26+B26 -> 467 | J26: ='[1]التعليم الابتدائي'!AJF754 -> 46 | L26: ='[1]التعليم الابتدائي'!AJG754 -> 51 | N26: ='[1]التعليم الابتدائي'!AJH754 -> 239 | P26: ='[1]التعليم الابتدائي'!AJI754 -> 100 | R26: ='[1]التعليم الابتدائي'!AJJ754 -> 31 | T26: =R26+P26+N26+L26+J26 -> 467
A28: المديرية العامة للتربية في محافظة النجف الاشرف | R28: قضاء النجف
A29: قسم التخطيط التربوي | S29: التعليم الابتدائي
B30: جدول رقم (( 6 ))
B31: التعليم الابتدائي للعام الدراسي2024/2025
B32: عدد الهيئات التعليمية حسب العنوان الوظيفي والشهادة
B34: الجنس | C34: الهيئة التعليمية حسب العنوان الوظيفي | H34: الهيئة التعليمية حسب العنوان والشهادة | S34: المجموع
H35: دورات تربوية | I35: دبلوم تعليمي لمعاهد المعلمين والمعاهد المركزية | J35: دبلوم عام | K35: دبلوم فنون جميلة | L35: جامعية | N35: دراسات عليا | Q35: اخــرى
C36: مدير | D36: معاون | E36: معلم | F36: مرشد | G36: المجموع | L36: تربوية | M36: غير تربوية | N36: دبلوم عالي | O36: ماجستير | P36: دكتوراه
B37: ذكــــــور | C37: ='[1]التعليم الابتدائي'!IY377 -> 198 | D37: ='[1]التعليم الابتدائي'!JA377 -> 0 | E37: ='[1]التعليم الابتدائي'!JC377 -> 0 | F37: ='[1]التعليم الابتدائي'!JE377 -> 0 | G37: =E37+D37+C37+F37 -> 198 | H37: ='[1]التعليم الابتدائي'!ADR377 -> 0 | I37: ='[1]التعليم الابتدائي'!ADT377 -> 0 | J37: ='[1]التعليم الابتدائي'!ADX377 -> 0 | K37: ='[1]التعليم الابتدائي'!ADV377 -> 0 | L37: ='[1]التعليم الابتدائي'!ADZ377 -> 0 | M37: ='[1]التعليم الابتدائي'!AEB377 -> 0 | N37: ='[1]التعليم الابتدائي'!AED377 -> 0 | O37: ='[1]التعليم الابتدائي'!AEF377 -> 0 | P37: ='[1]التعليم الابتدائي'!AEH377 -> 0 | Q37: ='[1]التعليم الابتدائي'!AEJ377 -> 0 | S37: =Q37+P37+O37+M37+N37+J37+K37+L37+I37+H37 -> 0
B38: انــــــــاث | C38: ='[1]التعليم الابتدائي'!IZ377 -> 161 | D38: ='[1]التعليم الابتدائي'!JB377 -> 0 | E38: ='[1]التعليم الابتدائي'!JD377 -> 0 | F38: ='[1]التعليم الابتدائي'!JF377 -> 0 | G38: =E38+D38+C38+F38 -> 161 | H38: ='[1]التعليم الابتدائي'!ADS377 -> 0 | I38: ='[1]التعليم الابتدائي'!ADU377 -> 0 | J38: ='[1]التعليم الابتدائي'!ADY377 -> 0 | K38: ='[1]التعليم الابتدائي'!ADW377 -> 0 | L38: ='[1]التعليم الابتدائي'!AEA377 -> 0 | M38: ='[1]التعليم الابتدائي'!AEC377 -> 0 | N38: ='[1]التعليم الابتدائي'!AEE377 -> 0 | O38: ='[1]التعليم الابتدائي'!AEG377 -> 0 | P38: ='[1]التعليم الابتدائي'!AEI377 -> 0 | Q38: ='[1]التعليم الابتدائي'!AEK377 -> 0 | S38: =Q38+P38+O38+M38+N38+J38+K38+L38+I38+H38 -> 0
B39: المجموع | C39: =C37+C38 -> 359 | D39: =D37+D38 -> 0 | E39: =E37+E38 -> 0 | F39: =SUM(F37:F38) -> 0 | G39: =E39+D39+C39+F39 -> 359 | H39: =H38+H37 -> 0 | I39: =I38+I37 -> 0 | J39: =J38+J37 -> 0 | K39: =K38+K37 -> 0 | L39: =L38+L37 -> 0 | M39: =M38+M37 -> 0 | N39: =N38+N37 -> 0 | O39: =O38+O37 -> 0 | ... Q39: =Q38+Q37 -> 0 | S39: =S38+S37 -> 0
B41: جدول رقم (( 7 ))
B42: التعليم الابتدائي للعام الدراسي2024/2025
B43: عدد الابنية المدرسية وعدد المكتبات
A45: عدد الابنية حسب العائدية | D45: عدد الابنية التي تشغلها | G45: عدد الابنية حسب الحالة العمرانية | J45: عدد الابنية حسب نوع البناء | L45: عدد الابنية حسب مادة البناء | R45: المجموع الكلي للابنية | S45: عدد الابنية حسب نوع الخدمات
A46: حكومية | C46: مستاجرة | D46: مدرسة واحدة | E46: مدرستان | F46: ثلاث مدارس | G46: صالحة | H46: بحاجة الى ترميم | I46: غير صالحة | J46: مدرسي | K46: غير مدرسي | L46: طابوق او حجر | M46: بناء جاهز | N46: طين اوصريفة | O46: هياكل حديدية | P46: كرفان | Q46: اخرى | S46: عدد الابنية التي تتوفر فيها مرافق صحية | T46: عدد الابنية التي يصلها ماء صالح للشرب | U46: عدد الابنية المزودة بخدمة مجاري | V46: عدد الابنية التي تحتوي سياج
A47: عائدة للتربية | B47: لجهات اخرى
A48: ='[1]التعليم الابتدائي'!ALH377 -> 1 | B48: ='[1]التعليم الابتدائي'!ALI377 -> 221 | C48: ='[1]التعليم الابتدائي'!ALJ377 -> 0 | D48: ='[1]التعليم الابتدائي'!ALE377 -> 78 | E48: ='[1]التعليم الابتدائي'!ALF377 -> 134 | F48: ='[1]التعليم الابتدائي'!ALG377 -> 10 | G48: ='[1]التعليم الابتدائي'!ALK377 -> 110 | H48: ='[1]التعليم الابتدائي'!ALL377 -> 102 | I48: ='[1]التعليم الابتدائي'!ALM377 -> 10 | J48: ='[1]التعليم الابتدائي'!AIS377 -> 222 | K48: ='[1]التعليم الابتدائي'!AIT377 -> 0 | L48: ='[1]التعليم الابتدائي'!AJN377 -> 201 | M48: ='[1]التعليم الابتدائي'!AJP377 -> 0 | N48: ='[1]التعليم الابتدائي'!AJQ377 -> 0 | O48: ='[1]التعليم الابتدائي'!AJR377 -> 6 | P48: ='[1]التعليم الابتدائي'!AJS377 -> 15 | Q48: ='[1]التعليم الابتدائي'!AJT377 -> 0 | R48: =Q48+P48+O48+N48+L48 -> 222 | S48: ='[1]التعليم الابتدائي'!AJU377 -> 222 | T48: ='[1]التعليم الابتدائي'!AKA377 -> 222 | U48: ='[1]التعليم الابتدائي'!AKH377 -> 222 | V48: ='[1]التعليم الابتدائي'!AKL377 -> 221
...

Sheet t8&t9
A1: المديرية العامة للتربية في محافظة النجف الاشرف | N1: خلاصة محافظة النجف الاشرف
A2: قسم التخطيط التربوي | O2: التعليم الابتدائي
J3: جدول رقم ( 8 )
I4: عدد المكتبات والمختبرات للعام الدراسي 2024-2025
C6: المكتبات المدرسية | F6: المختبرات المدرسية
F7: هل توجد مختبرات | H7: المختبرات العلمية | M7: مختبر اللغة | N7: مختبر الحاسوب
C8: عدد المكتبات | E8: عدد الكتب | F8: نعم | G8: كلا | H8: العلوم | I8: الفيزياء | J8: الكيمياء | K8: الاحياء | L8: مجمع المختبرات
C9: نعم | D9: كلا | H9: ='[1]التعليم الابتدائي'!AMN754 -> 132 | I9: 0 | J9: 0 | K9: 0 | L9: 0
C10: ='[1]التعليم الابتدائي'!ALZ754 -> 524 | D10: ='[1]التعليم الابتدائي'!AMA754 -> 198 | E10: ='[1]التعليم الابتدائي'!AMM754 -> 175057 | F10: ='[1]التعليم الابتدائي'!AMN754 -> 132 | G10: ='[1]التعليم الابتدائي'!AMO754 -> 589 | M10: 0 | N10: 0
A12: جدول رقم (( 9 ))
A13: التعليم الابتدائي للعام الدراسي2025/2024
A14: عدد الشعب للعام الدراسي2024 /2025 حسب الجنس والصف
I16: عدد الشعب حسب الصف والجنس
I17: بنون | J17: بنات | K17: مختلطة | L17: المجموع
H18: الاول | I18: ='[1]التعليم الابتدائي'!EQ754 -> 0 | J18: ='[1]التعليم الابتدائي'!ER754 -> 0 | K18: ='[1]التعليم الابتدائي'!ES754 -> 0 | L18: =K18+J18+I18 -> 0
H19: الثاني | I19: ='[1]التعليم الابتدائي'!ET754 -> 0 | J19: ='[1]التعليم الابتدائي'!EU754 -> 0 | K19: ='[1]التعليم الابتدائي'!EV754 -> 0 | L19: =K19+J19+I19 -> 0
H20: الثالث | I20: ='[1]التعليم الابتدائي'!EW754 -> 0 | J20: ='[1]التعليم الابتدائي'!EX754 -> 0 | K20: ='[1]التعليم الابتدائي'!EY754 -> 0 | L20: =K20+J20+I20 -> 0
H21: الرابع | I21: ='[1]التعليم الابتدائي'!EZ754 -> 0 | J21: ='[1]التعليم الابتدائي'!FA754 -> 0 | K21: ='[1]التعليم الابتدائي'!FB754 -> 0 | L21: =K21+J21+I21 -> 0
H22: الخامس | I22: ='[1]التعليم الابتدائي'!FC754 -> 0 | J22: ='[1]التعليم الابتدائي'!FD754 -> 0 | K22: ='[1]التعليم الابتدائي'!FE754 -> 0 | L22: =K22+J22+I22 -> 0
H23: السادس | I23: ='[1]التعليم الابتدائي'!FF754 -> 0 | J23: ='[1]التعليم الابتدائي'!FG754 -> 0 | K23: ='[1]التعليم الابتدائي'!FH754 -> 0 | L23: =K23+J23+I23 -> 0
H24: المجموع | I24: =SUM(I18:I23) -> 0 | J24: =SUM(J18:J23) -> 0 | K24: =SUM(K18:K23) -> 0 | L24: =SUM(I24:K24) -> 0
A26: المديرية العامة للتربية في محافظة النجف الاشرف | P26: قضاء النجف
A27: قسم التخطيط التربوي | P27: التعليم الابتدائي
J28: جدول رقم ( 8 )
I29: عدد المكتبات والمختبرات للعام الدراسي 2025-2025
C31: المكتبات المدرسية | F31: المختبرات المدرسية
F32: هل توجد مختبرات | H32: المختبرات العلمية | M32: مختبر اللغة | N32: مختبر الحاسوب
C33: عدد المكتبات | E33: عدد الكتب | F33: نعم | G33: كلا | H33: العلوم | I33: الفيزياء | J33: الكيمياء | K33: الاحياء | L33: مجمع المختبرات
C34: نعم | D34: كلا | H34: ='[1]التعليم الابتدائي'!AMN377 -> 74 | I34: 0 | J34: 0 | K34: 0 | L34: 0
C35: ='[1]التعليم الابتدائي'!ALZ377 -> 242 | D35: ='[1]التعليم الابتدائي'!AMA377 -> 117 | E35: ='[1]التعليم الابتدائي'!AMM377 -> 85917 | F35: ='[1]التعليم الابتدائي'!AMN377 -> 74 | G35: ='[1]التعليم الابتدائي'!AMO377 -> 284 | M35: 0 | N35: 0
A36: جدول رقم (( 9 ))
A37: التعليم الابتدائي للعام الدراسي2024/2025
A38: عدد الشعب للعام الدراسي2025 -2024 حسب الجنس والصف
I40: عدد الشعب حسب الصف والجنس
I41: بنون | J41: بنات | K41: مختلطة | L41: المجموع
H42: الاول | I42: ='[1]التعليم الابتدائي'!EQ377 -> 0 | J42: ='[1]التعليم الابتدائي'!ER377 -> 0 | K42: ='[1]التعليم الابتدائي'!ES377 -> 0 | L42: =K42+J42+I42 -> 0
H43: الثاني | I43: ='[1]التعليم الابتدائي'!ET377 -> 0 | J43: ='[1]التعليم الابتدائي'!EU377 -> 0 | K43: ='[1]التعليم الابتدائي'!EV377 -> 0 | L43: =K43+J43+I43 -> 0
H44: الثالث | I44: ='[1]التعليم الابتدائي'!EW377 -> 0 | J44: ='[1]التعليم الابتدائي'!EX377 -> 0 | K44: ='[1]التعليم الابتدائي'!EY377 -> 0 | L44: =K44+J44+I44 -> 0
H45: الرابع | I45: ='[1]التعليم الابتدائي'!EZ377 -> 0 | J45: ='[1]التعليم الابتدائي'!FA377 -> 0 | K45: ='[1]التعليم الابتدائي'!FB377 -> 0 | L45: =K45+J45+I45 -> 0
H46: الخامس | I46: ='[1]التعليم الابتدائي'!FC377 -> 0 | J46: ='[1]التعليم الابتدائي'!FD377 -> 0 | K46: ='[1]التعليم الابتدائي'!FE377 -> 0 | L46: =K46+J46+I46 -> 0
...

Sheet t10
A1: المديرية العامة للتربية في محافظة النجف الاشرف | R1: خلاصة محافظة النجف الاشرف
A2: قسم التخطيط التربوي | S2: التعليم الابتدائي
B3: جدول رقم (( 10 ))
B4: التعليم الابتدائي للعام الدراسي2024/2025
B5: عدد التلامذة الناجحين والتلامذة الراسبين للعام الدراسي2023 /2024 حسب الجنس والصف
D7: الصف | E7: عدد التلامذة التاركون حسب الصف والجنس للعام الدراسي 2025/2024 | H7: عدد التلامذة الناجحين للعام الدراسي2024/2023حسب الصف والجنس | K7: عدد التلامذة الراسبين حسب اسباب الرسوب والصف والجنس للعام الدراسي2024/2023
E8: بنين | F8: بنات | G8: المجموع | H8: بنين | I8: بنات | J8: المجموع | K8: الفشل في الامتحان | M8: تجاوز ايام الغياب | O8: أسباب أخرى | Q8: المجموع
D9: الجنس | K9: بنون | L9: بنات | M9: بنون | N9: بنات | O9: بنون | P9: بنات | Q9: بنون | R9: بنات | S9: المجموع
D10: الاول | E10: ='[1]التعليم الابتدائي'!FM754 -> 0 | F10: ='[1]التعليم الابتدائي'!FN754 -> 0 | G10: =F10+E10 -> 0 | H10: ='[1]التعليم الابتدائي'!GB754 -> 0 | I10: ='[1]التعليم الابتدائي'!GC754 -> 0 | J10: =I10+H10 -> 0 | K10: ='[1]التعليم الابتدائي'!GQ754 -> 0 | L10: ='[1]التعليم الابتدائي'!GR754 -> 0 | M10: ='[1]التعليم الابتدائي'!HF754 -> 0 | N10: ='[1]التعليم الابتدائي'!HG754 -> 0 | O10: ='[1]التعليم الابتدائي'!HU754 -> 0 | P10: ='[1]التعليم الابتدائي'!HV754 -> 0 | Q10: =O10+M10+K10 -> 0 | R10: =P10+N10+L10 -> 0 | S10: =R10+Q10 -> 0
D11: الثاني | E11: ='[1]التعليم الابتدائي'!FO754 -> 0 | F11: ='[1]التعليم الابتدائي'!FP754 -> 0 | G11: =F11+E11 -> 0 | H11: ='[1]التعليم الابتدائي'!GD754 -> 0 | I11: ='[1]التعليم الابتدائي'!GE754 -> 0 | J11: =I11+H11 -> 0 | K11: ='[1]التعليم الابتدائي'!GS754 -> 0 | L11: ='[1]التعليم الابتدائي'!GT754 -> 0 | M11: ='[1]التعليم الابتدائي'!HH754 -> 0 | N11: ='[1]التعليم الابتدائي'!HI754 -> 0 | O11: ='[1]التعليم الابتدائي'!HW754 -> 0 | P11: ='[1]التعليم الابتدائي'!HX754 -> 0 | Q11: =O11+M11+K11 -> 0 | R11: =P11+N11+L11 -> 0 | S11: =R11+Q11 -> 0
D12: الثالث | E12: ='[1]التعليم الابتدائي'!FQ754 -> 0 | F12: ='[1]التعليم الابتدائي'!FR754 -> 0 | G12: =F12+E12 -> 0 | H12: ='[1]التعليم الابتدائي'!GF754 -> 0 | I12: ='[1]التعليم الابتدائي'!GG754 -> 0 | J12: =I12+H12 -> 0 | K12: ='[1]التعليم الابتدائي'!GU754 -> 0 | L12: ='[1]التعليم الابتدائي'!GV754 -> 0 | M12: ='[1]التعليم الابتدائي'!HJ754 -> 0 | N12: ='[1]التعليم الابتدائي'!HK754 -> 0 | O12: ='[1]التعليم الابتدائي'!HY754 -> 0 | P12: ='[1]التعليم الابتدائي'!HZ754 -> 0 | Q12: =O12+M12+K12 -> 0 | R12: =P12+N12+L12 -> 0 | S12: =R12+Q12 -> 0
D13: الرابع | E13: ='[1]التعليم الابتدائي'!FS754 -> 0 | F13: ='[1]التعليم الابتدائي'!FT754 -> 0 | G13: =F13+E13 -> 0 | H13: ='[1]التعليم الابتدائي'!GH754 -> 0 | I13: ='[1]التعليم الابتدائي'!GI754 -> 0 | J13: =I13+H13 -> 0 | K13: ='[1]التعليم الابتدائي'!GW754 -> 0 | L13: ='[1]التعليم الابتدائي'!GX754 -> 0 | M13: ='[1]التعليم الابتدائي'!HL754 -> 0 | N13: ='[1]التعليم الابتدائي'!HM754 -> 0 | O13: ='[1]التعليم الابتدائي'!IA754 -> 0 | P13: ='[1]التعليم الابتدائي'!IB754 -> 0 | Q13: =O13+M13+K13 -> 0 | R13: =P13+N13+L13 -> 0 | S13: =R13+Q13 -> 0
D14: الخامس | E14: ='[1]التعليم الابتدائي'!FU754 -> 0 | F14: ='[1]التعليم الابتدائي'!FV754 -> 0 | G14: =F14+E14 -> 0 | H14: ='[1]التعليم الابتدائي'!GJ754 -> 0 | I14: ='[1]التعليم الابتدائي'!GK754 -> 0 | J14: =I14+H14 -> 0 | K14: ='[1]التعليم الابتدائي'!GY754 -> 0 | L14: ='[1]التعليم الابتدائي'!GZ754 -> 0 | M14: ='[1]التعليم الابتدائي'!HN754 -> 0 | N14: ='[1]التعليم الابتدائي'!HO754 -> 0 | O14: ='[1]التعليم الابتدائي'!IC754 -> 0 | P14: ='[1]التعليم الابتدائي'!ID754 -> 0 | Q14: =O14+M14+K14 -> 0 | R14: =P14+N14+L14 -> 0 | S14: =R14+Q14 -> 0
D15: السادس | E15: ='[1]التعليم الابتدائي'!FW754 -> 0 | F15: ='[1]التعليم الابتدائي'!FX754 -> 0 | G15: =F15+E15 -> 0 | H15: ='[1]التعليم الابتدائي'!GL754 -> 0 | I15: ='[1]التعليم الابتدائي'!GM754 -> 0 | J15: =I15+H15 -> 0 | K15: ='[1]التعليم الابتدائي'!HA754 -> 0 | L15: ='[1]التعليم الابتدائي'!HB754 -> 0 | M15: ='[1]التعليم الابتدائي'!HP754 -> 0 | N15: ='[1]التعليم الابتدائي'!HQ754 -> 0 | O15: ='[1]التعليم الابتدائي'!IE754 -> 0 | P15: ='[1]التعليم الابتدائي'!IF754 -> 0 | Q15: =O15+M15+K15 -> 0 | R15: =P15+N15+L15 -> 0 | S15: =R15+Q15 -> 0
