Workbook

Sheet المهني
A1: المديرية العامة للتربية في محافظة النجف الاشرف | K1: دوام المدرسة | O1: استقلالية المدرسة | Q1: نوع الازدواج | U1: هل المدرسة فتح جديد | V1: عدد الطلبة المستجدين في الصف الاول حسب العمر | AI1: عدد الطلبة المسجلين في الصف الاول حسب العمر والجنس | AV1: عدد الطلبة المسجلين في الصف الثاني حسب العمر والجنس | BI1: عدد الطلبة المسجلين في الصف الثالث حسب العمر والجنس | BV1: عدد الطلبة المسجلين حسب الصف والجنس (المجموع الكلي) | CM1: عدد الشعب حسب الصف والجنس | CZ1: عدد الطلبة التاركين حسب الصف والجنس للعام الدراسي 2025 / 2026 | DI1: عدد الطلبة المشاركين في الامتحانات النهائية و حسب الصف والجنس للعام الدراسي 2015 / 2021 | DR1: عدد الطلبة الناجحين حسب الصف والجنس للعام الدراسي 2024 / 2025 | EA1: عدد الطلبة الراسبين بسبب الفشل في الامتحان و حسب الصف والجنس للعام الدراسي 2024 / 2025 | EJ1: عدد الطلبة الراسبين بسبب تجاوز ايام الغياب و حسب الصف والجنس للعام الدراسي 2024 / 2025 | ES1: عدد الطلبة الراسبين لاسباب اخرى و حسب الصف والجنس للعام الدراسي 2024 / 2025 | FB1: اعضاء الهيئة التعليمية و التدريسية حسب العنوان الوظيفي | FO1: الموظفون الاداريون والخدميون حسب العنوان الوظيفي | GJ1: عدد اعضاء الهيئة التعليمية والتدريسية حسب الاختصاص | KY1: عدد اعضاء الهئية التعليمية والتدريسية حسب الحالة الوظيفية | LT1: عدد الهيئة التدريسية حسب سنوات الخدمة | ME1: عدد الهيئة التدريسية حسب سنوات العمر | MR1: عدد اعضاء الهئية التعليمية والتدريسية حسب الحالة الاجتماعية | NC1: عدد المدرسين المشاركين في الدورات التدريبية للعام الماضي | NE1: اعضاء الهيئة التعليمية والتدريسية حسب الشهادة | NZ1: عددالطلبة المسجلين من غير العراقيين
OI2: هل المدرسة مشمولة بـ :- | OU2: الأبنية المدرسية | RU2: الحاسبات :- | SA2: المكتبات المدرسية :-
A3: التعليم المهني 2026/2025 | F3: جنس المدرسة | I3: بيئة المدرسة | KY3: داخل قوة العمل | LA3: خارج قوة العمل | LQ3: المجموع الكلي | NE3: اعدادية | NG3: دبلوم تعليمي | NI3: دبلوم عام | NK3: بكلوريوس عام | NM3: بكلوريوس تعليمي | NO3: دبلوم عالي | NQ3: ماجستير | NS3: دكتوراه | NU3: اخرى تذكر | NW3: المجموع | OI3: الارشاد التربوي | OK3: تدريس الحاسوب | OM3: خدمة الانترنت | OO3: اللغات | OQ3: اذا كان الجواب نعم اذكر اللغة | OU3: عدد الابنية المدرسية حسب :- | PV3: هل تتوفر في البناية مرافق صحية | QB3: هل ترتبط البناية بشبكة الماء الصالح للشرب | QD3: مصدر الماء | QI3: هل البناية مزودة بخدمة المجاري | QK3: نوع المجاري | QM3: هل هناك سياج حول البناية | QO3: نوع السياج | QR3: حالة السياج | QU3: هل توجد ساحة رياضية | QW3: نوع الساحة الرياضية | RB3: هل توجد حديقة مدرسية | RD3: هل توجد قاعة انشطة مستقلة | RO3: عدد الرحلات مقعدين | RQ3: عدد الرحلات مقعد واحد | RS3: عدد السبورات | RU3: عدد الحاسبات الالكترونية (كومبيوتر) | RW3: عدد الطابعات | RY3: عدد الماسحات الضوئية (سكنرات) | SA3: هل توجد مكتبة | SC3: من المسؤول عن المكتبة | SI3: نوعية المكتبة | SL3: عدد الكتب والمجلات والقصص | SO3: عدد الورش المستقلة الموجودة | SP3: عدد الورش الصالحة
V4: 15 سنة | X4: 16 سنة | Z4: 17 سنة | AB4: 18 سنة | AD4: 19 سنة | AF4: المجموع | AI4: 15 سنة | AK4: 16 سنة | AM4: 17 سنة | AO4: 18 سنة | AQ4: 19 سنة | AS4: المجموع | AV4: 16 سنة | AX4: 17 سنة | AZ4: 18 سنة | BB4: 19 سنة | BD4: 20 سنة | BF4: المجموع | BI4: 17سنة | BK4: 18سنة | BM4: 19سنة | BO4: 20سنة | BQ4: 21سنة | BS4: المجموع | BV4: 15سنة | BX4: 16سنة | BZ4: 17سنة | CB4: 18سنة | CD4: 19سنة | CF4: 20سنة | CH4: 21سنة | CJ4: المجموع | CM4: الصف الاول | CP4: الصف الثاني | CS4: الصف الثالث | CV4: المجموع | CZ4: الصف الاول | DB4: الصف الثاني | DD4: الصف الثالث | DF4: المجموع | DI4: الصف الاول | DK4: الصف الثاني | DM4: الصف الثالث | DO4: المجموع | DR4: الصف الاول | DT4: الصف الثاني | DV4: الصف الثالث | DX4: المجموع | EA4: الصف الاول | EC4: الصف الثاني | EE4: الصف الثالث | EG4: المجموع | EJ4: الصف الاول | EL4: الصف الثاني | EN4: الصف الثالث | EP4: المجموع | ES4: الصف الاول | EU4: الصف الثاني | EW4: الصف الثالث | EY4: المجموع | FB4: مدير | FD4: معاون | FF4: مدرس | FH4: معلم مهني | FJ4: مرشد تربوي | FL4: المجموع | FO4: موظف ادارة | FQ4: كاتب | FS4: محاسب | FU4: امين مكتبة | FW4: موظف خدمة | FY4: حارس | GA4: سائق | GC4: حرفي | GE4: فلاح | GG4: المجموع | GJ4: التربية الاسلامية | GL4: اللغة العربية | GN4: اللغة الانكليزية | GP4: اللغة الكردية | GR4: الرياضيات | GT4: الفيزياء | GV4: الكيمياء | GX4: علوم الحياة | GZ4: التاريخ | HB4: الجغرافية | HD4: الاجتماع | HF4: التربية الرياضية | HH4: التربية الفنية | HJ4: زراعة عامة | HL4: انتاج نباتي | HN4: الغابات | HP4: انتاج حيواني | HR4: البستنة | HT4: محاصيل حقلية | HV4: صناعات غذائية والبان | HX4: التربة | HZ4: اقتصاد وارشاد زراعي | IB4: مقاومة الافات | ID4: البيطرة العامة | IF4: الكهرباء | IH4: ميكانيك | IJ4: السيارات | IL4: المعامل | IN4: راديو وتلفزيون | IP4: السباكة | IR4: النجارة | IT4: النسيج | IV4: الطباعة | IX4: تاسيس صحيات | IZ4: صناعة زجاج | JB4: البناء | JD4: النماذج | JF4: بترو كمياويات | JH4: مكننة زراعية | JJ4: المعادن | JL4: العلوم التجارية | JN4: محاسبة | JP4: ادارة | JR4: الاحصاء | JT4: الاقتصاد | JV4: السكرتارية | JX4: ادارة المزارع | JZ4: تعاونيات زراعية | KB4: هندسة كيمياوية | KD4: رسم هندسي | KF4: علم نفس | KH4: القانون | KJ4: اقتصاد منزلي | KL4: محاسبة كلفة | KN4: حاسوب | KP4: اللغة التركمانية | KR4: اللغة السريانية | KT4: اخرى | KV4: المجموع | LA4: بعثة او زمالة | LC4: اجازة دراسية | LE4: اجازة مصاحبة | LG4: اجازة بدون راتب | LI4: اجازة مرضية طويلة | LK4: اجازة امومة | LM4: منسب الى جهات اخرى | LO4: 4-5سنوات | LT4: 5سنوات فاقل | LV4: 6ــ10 | LX4: 11ــ15 | LZ4: 16فاكثر | MB4: المجموع | ME4: اقل من 30 | MG4: 30ــ39 | MI4: 40ــ49 | MK4: 50ــ59 | MM4: 60ــ فاكثر | MO4: المجموع الكلي | MR4: اعزب | MT4: متزوج | MV4: ارمل | MX4: مطلق | MZ4: المجموع | NC4: عدد المدرسين | NZ4: الاول المهني | OB4: الثاني مهني | OD4: الثالث المهني | OF4: المجموع | OU4: نوع البناء | OW4: البناية | OZ4: هل توجد مساحة للتوسعة | PB4: عدد الطوابق | PE4: حجم المدرسة | PJ4: هل المدرسة تحتاج الى صفوف اضافية | PM4: عدد الغرف في البناية | PP4: مادة البناء | RF4: عدد المدارس التي تشغلها | RI4: العائدية | RL4: الحالة العمرانية
A5: القضاء | B5: الناحية | C5: ت | D5: الرقم الاحصائي | E5: اسم المدرسة | F5: بنون | G5: بنات | H5: مختلط | I5: حضر | J5: ريف | K5: صباحا | L5: ظهرا | M5: صباحا وظهرا | N5: مساءا | O5: اصلية | P5: ضيف | Q5: غير مزدوجة | R5: مع نفسها | S5: مع اخرى | T5: مع نفسها ومع اخرى | V5: بنون | W5: بنات | X5: بنون | Y5: بنات | Z5: بنون | AA5: بنات | AB5: بنون | AC5: بنات | AD5: بنون | AE5: بنات | AF5: بنون | AG5: بنات | AH5: المجموع | AI5: بنون | AJ5: بنات | AK5: بنون | AL5: بنات | AM5: بنون | AN5: بنات | AO5: بنون | AP5: بنات | AQ5: بنون | AR5: بنات | AS5: بنون | AT5: بنات | AU5: المجموع | AV5: بنون | AW5: بنات | AX5: بنون | AY5: بنات | AZ5: بنون | BA5: بنات | BB5: بنون | BC5: بنات | BD5: بنون | BE5: بنات | BF5: بنون | BG5: بنات | BH5: المجموع | BI5: بنون | BJ5: بنات | BK5: بنون | BL5: بنات | BM5: بنون | BN5: بنات | BO5: بنون | BP5: بنات | BQ5: بنون | BR5: بنات | BS5: بنون | BT5: بنات | BU5: المجموع | BV5: بنون | BW5: بنات | BX5: بنون | BY5: بنات | BZ5: بنون | CA5: بنات | CB5: بنون | CC5: بنات | CD5: بنون | CE5: بنات | CF5: بنون | CG5: بنات | CH5: بنون | CI5: بنات | CJ5: بنون | CK5: بنات | CL5: المجموع | CM5: بنون | CN5: بنات | CO5: مختلطة | CP5: بنون | CQ5: بنات | CR5: مختلطة | CS5: بنون | CT5: بنات | CU5: مختلطة | CV5: بنون | CW5: بنات | CX5: مختلطة | CY5: المجموع | CZ5: بنون | DA5: بنات | DB5: بنون | DC5: بنات | DD5: بنون | DE5: بنات | DF5: بنون | DG5: بنات | DH5: المجموع | DI5: بنون | DJ5: بنات | DK5: بنون | DL5: بنات | DM5: بنون | DN5: بنات | DO5: بنون | DP5: بنات | DQ5: المجموع | DR5: بنون | DS5: بنات | DT5: بنون | DU5: بنات | DV5: بنون | DW5: بنات | DX5: بنون | DY5: بنات | DZ5: المجموع | EA5: بنون | EB5: بنات | EC5: بنون | ED5: بنات | EE5: بنون | EF5: بنات | EG5: بنون | EH5: بنات | EI5: المجموع | EJ5: بنون | EK5: بنات | EL5: بنون | EM5: بنات | EN5: بنون | EO5: بنات | EP5: بنون | EQ5: بنات | ER5: المجموع | ES5: بنون | ET5: بنات | EU5: بنون | EV5: بنات | EW5: بنون | EX5: بنات | EY5: بنون | EZ5: بنات | FA5: المجموع | FB5: ذكور | FC5: اناث | FD5: ذكور | FE5: اناث | FF5: ذكور | FG5: اناث | FH5: ذكور | FI5: اناث | FJ5: ذكور | FK5: اناث | FL5: ذكور | FM5: اناث | FN5: المجموع | FO5: ذكور | FP5: اناث | FQ5: ذكور | FR5: اناث | FS5: ذكور | FT5: اناث | FU5: ذكور | FV5: اناث | FW5: ذكور | FX5: اناث | FY5: ذكور | FZ5: اناث | GA5: ذكور | GB5: اناث | GC5: ذكور | GD5: اناث | GE5: ذكور | GF5: اناث | GG5: ذكور | GH5: اناث | GI5: المجموع | GJ5: ذكور | GK5: اناث | GL5: ذكور | GM5: اناث | GN5: ذكور | GO5: اناث | GP5: ذكور | GQ5: اناث | GR5: ذكور | GS5: اناث | GT5: ذكور | GU5: اناث | GV5: ذكور | GW5: اناث | GX5: ذكور | GY5: اناث | GZ5: ذكور | HA5: اناث | HB5: ذكور | HC5: اناث | HD5: ذكور | HE5: اناث | HF5: ذكور | HG5: اناث | HH5: ذكور | HI5: اناث | HJ5: ذكور | HK5: اناث | HL5: ذكور | HM5: اناث | HN5: ذكور | HO5: اناث | HP5: ذكور | HQ5: اناث | HR5: ذكور | HS5: اناث | HT5: ذكور | HU5: اناث | HV5: ذكور | HW5: اناث | HX5: ذكور | HY5: اناث | HZ5: ذكور | IA5: اناث | IB5: ذكور | IC5: اناث | ID5: ذكور | IE5: اناث | IF5: ذكور | IG5: اناث | IH5: ذكور | II5: اناث | IJ5: ذكور | IK5: اناث | IL5: ذكور | IM5: اناث | IN5: ذكور | IO5: اناث | IP5: ذكور | IQ5: اناث | IR5: ذكور | IS5: اناث | IT5: ذكور | IU5: اناث | IV5: ذكور | IW5: اناث | IX5: ذكور | IY5: اناث | IZ5: ذكور | JA5: اناث | JB5: ذكور | JC5: اناث | JD5: ذكور | JE5: اناث | JF5: ذكور | JG5: اناث | JH5: ذكور | JI5: اناث | JJ5: ذكور | JK5: اناث | JL5: ذكور | JM5: اناث | JN5: ذكور | JO5: اناث | JP5: ذكور | JQ5: اناث | JR5: ذكور | JS5: اناث | JT5: ذكور | JU5: اناث | JV5: ذكور | JW5: اناث | JX5: ذكور | JY5: اناث | JZ5: ذكور | KA5: اناث | KB5: ذكور | KC5: اناث | KD5: ذكور | KE5: اناث | KF5: ذكور | KG5: اناث | KH5: ذكور | KI5: اناث | KJ5: ذكور | KK5: اناث | KL5: ذكور | KM5: اناث | KN5: ذكور | KO5: اناث | KP5: ذكور | KQ5: اناث | KR5: ذكور | KS5: اناث | KT5: ذكور | KU5: اناث | KV5: ذكور | KW5: اناث | KX5: المجموع | KY5: ذكور | KZ5: اناث | LA5: ذكور | LB5: اناث | LC5: ذكور | LD5: اناث | LE5: ذكور | LF5: اناث | LG5: ذكور | LH5: اناث | LI5: ذكور | LJ5: اناث | LK5: ذكور | LL5: اناث | LM5: ذكور | LN5: اناث | LO5: ذكور | LP5: اناث | LQ5: ذكور | LR5: اناث | LS5: المجموع | LT5: ذكور | LU5: اناث | LV5: ذكور | LW5: اناث | LX5: ذكور | LY5: اناث | LZ5: ذكور | MA5: اناث | MB5: ذكور | MC5: اناث | MD5: المجموع | ME5: ذكور | MF5: اناث | MG5: ذكور | MH5: اناث | MI5: ذكور | MJ5: اناث | MK5: ذكور | ML5: اناث | MM5: ذكور | MN5: اناث | MO5: ذكور | MP5: اناث | MQ5: المجموع | MR5: ذكور | MS5: اناث | MT5: ذكور | MU5: اناث | MV5: ذكور | MW5: اناث | MX5: ذكور | MY5: اناث | MZ5: ذكور | NA5: اناث | NB5: المجموع | NC5: ذكور | ND5: اناث | NE5: ذكور | NF5: اناث | NG5: ذكور | NH5: اناث | NI5: ذكور | NJ5: اناث | NK5: ذكور | NL5: اناث | NM5: ذكور | NN5: اناث | NO5: ذكور | NP5: اناث | NQ5: ذكور | NR5: اناث | NS5: ذكور | NT5: اناث | NU5: ذكور | NV5: اناث | NW5: ذكور | NX5: اناث | NY5: المجموع | NZ5: بنون | OA5: بنات | OB5: بنون | OC5: بنات | OD5: بنون | OE5: بنات | OF5: بنون | OG5: بنات | OH5: المجموع | OI5: نعم | OJ5: كلا | OK5: نعم | OL5: كلا | OM5: نعم | ON5: كلا | OO5: نعم | OP5: كلا | OQ5: فرنسي | OR5: روسي | OS5: اسباني | OT5: كردي | OU5: مدرسي | OV5: غير مدرسي | OW5: سنة البناء | OX5: رقم القطعة | OY5: رقم المقاطعة | OZ5: نعم | PA5: كلا | PB5: طابق واحد | PC5: طابقين | PD5: ثلاث طوابق | PE5: 6صف | PF5: 9صف | PG5: 12صف | PH5: 18صف | PI5: 24صف | PJ5: نعم | PK5: كلا | PL5: عدد الصفوف الاضافية | PM5: عدد الصفوف في البناية | PN5: عدد الغرف الاخرى | PO5: المجموع الكلي للغرف في البناية | PP5: طابوق او حجر او بلوك | PQ5: طين او صريفة | PR5: هياكل حديدية | PS5: بناء جاهز | PT5: كرفان | PU5: اخرى | PV5: نعم | PW5: كلا | PX5: صالحة | PY5: غيرصالحة | PZ5: كافية | QA5: غيركافية | QB5: نعم | QC5: كلا | QD5: بلدية | QE5: بئر عميق | QF5: نهر | QG5: صهاريج | QH5: اخرى | QI5: نعم | QJ5: كلا | QK5: شبكة المجاري | QL5: خزانات | QM5: نعم | QN5: كلا | QO5: بناء | QP5: اسلاك | QQ5: اخرى | QR5: جيد | QS5: متصدع | QT5: غير امن | QU5: نعم | QV5: كلا | QW5: كرة قدم | QX5: كرة سلة | QY5: كرة طائرة | QZ5: ساحة رياضية | RA5: اخرى | RB5: نعم | RC5: كلا | RD5: نعم | RE5: كلا | RF5: مدرسة واحدة | RG5: مدرستان | RH5: ثلاث مدارس | RI5: حكومية تابعة لوزارة التربية | RJ5: حكومية تابعة لجهات اخرى | RK5: مستأجرة | RL5: صالحة | RM5: بحاجة الى ترميم | RN5: غير صالحة | RO5: الصالح | RP5: العاطل | RQ5: الصالح | RR5: العاطل | RS5: الصالح | RT5: العاطل | RU5: الصالح | RV5: العاطل | RW5: الصالح | RX5: العاطل | RY5: الصالح | RZ5: العاطل | SA5: نعم | SB5: كلا | SC5: مدير | SD5: معاون | SE5: مدرس او معلم | SF5: امين مكتبة | SG5: كاتب | SH5: قاعة | SI5: غرفة | SJ5: خزانة | SK5: رفوف عارضة | SL5: عدد الكتب | SM5: عدد المجلات والقصص | SN5: العدد الكلي للكتب | SQ5: اقرب نقطة | SR5: اسم المدير | SS5: رقم الموبايل
A6: النجف | B6: المركز | C6: 1 | D6: 1400169 | E6: إعدادية النجف المهنية | F6: 1 | I6: 1 | K6: 1 | O6: 1 | Q6: 1 | V6: 97 | X6: 72 | Z6: 48 | AB6: 31 | AD6: 15 | AF6: =AD6+AB6+Z6+X6+V6 -> 263 | AG6: =AE6+AC6+AA6+Y6+W6 -> 0 | AH6: =SUM(AF6:AG6) -> 263 | AI6: 97 | AK6: 75 | AM6: 56 | AO6: 36 | AQ6: 25 | AS6: =AQ6+AO6+AM6+AK6+AI6 -> 289 | AT6: =AR6+AP6+AN6+AL6+AJ6 -> 0 | AU6: =SUM(AS6:AT6) -> 289 | AV6: 53 | AX6: 37 | AZ6: 47 | BB6: 25 | BD6: 18 | BF6: =BD6+BB6+AZ6+AX6+AV6 -> 180 | BG6: =BE6+BC6+BA6+AY6+AW6 -> 0 | BH6: =SUM(BF6:BG6) -> 180 | BI6: 27 | BK6: 32 | BM6: 19 | BO6: 15 | BQ6: 22 | BS6: =BQ6+BO6+BM6+BK6+BI6 -> 115 | BT6: =BR6+BP6+BN6+BL6+BJ6 -> 0 | BU6: =SUM(BS6:BT6) -> 115 | BV6: =AI6 -> 97 | BW6: =AJ6 -> 0 | BX6: =AV6+AK6 -> 128 | BY6: =AL6+AW6 -> 0 | BZ6: =BI6+AX6+AM6 -> 120 | CA6: =AN6+AY6+BJ6 -> 0 | CB6: =BK6+AZ6+AO6 -> 115 | CC6: =AP6+BA6+BL6 -> 0 | CD6: =BM6+BB6+AQ6 -> 69 | CE6: =BN6+BC6+AR6 -> 0 | CF6: =BO6+BD6 -> 33 | CG6: =BP6+BE6 -> 0 | CH6: =BQ6 -> 22 | CI6: =BR6 -> 0 | CJ6: =BV6+BX6+BZ6+CB6+CD6+CF6+CH6 -> 584 | CK6: =BW6+BY6+CA6+CC6+CE6+CG6+CI6 -> 0 | CL6: =SUM(CJ6:CK6) -> 584 | CM6: 6 | CP6: 8 | CS6: 6 | CV6: =CS6+CP6+CM6 -> 20 | CW6: =CT6+CQ6+CN6 -> 0 | CX6: =CU6+CR6+CO6 -> 0 | CY6: =SUM(CV6:CX6) -> 20 | CZ6: 13 | DB6: 3 | DD6: 1 | DF6: =DD6+DB6+CZ6 -> 17 | DG6: =DE6+DC6+DA6 -> 0 | DH6: =SUM(DF6:DG6) -> 17 | DO6: =DM6+DK6+DI6 -> 0 | DP6: =DN6+DL6+DJ6 -> 0 | DQ6: =SUM(DO6:DP6) -> 0 | DR6: 164 | DT6: 72 | DV6: 107 | DX6: =DV6+DT6+DR6 -> 343 | DY6: =DW6+DU6+DS6 -> 0 | DZ6: =SUM(DX6:DY6) -> 343 | EA6: 16 | EC6: 4 | EE6: 32 | EG6: =EE6+EC6+EA6 -> 52 | EH6: =EF6+ED6+EB6 -> 0 | EI6: =SUM(EG6:EH6) -> 52 | EJ6: 14 | EL6: 4 | EN6: 10 | EP6: =EN6+EL6+EJ6 -> 28 | EQ6: =EO6+EM6+EK6 -> 0 | ER6: =SUM(EP6:EQ6) -> 28 | EY6: =EW6+EU6+ES6 -> 0 | EZ6: =EX6+EV6+ET6 -> 0 | FA6: =SUM(EY6:EZ6) -> 0 | FB6: 1 | FD6: 2 | FE6: 1 | FF6: 22 | FG6: 20 | FH6: 7 | FI6: 10 | FL6: =FJ6+FH6+FF6+FD6+FB6 -> 32 | FM6: =FK6+FI6+FG6+FE6+FC6 -> 31 | FN6: =SUM(FL6:FM6) -> 63 | FO6: 5 | FP6: 1 | FQ6: 1 | FW6: 2 | FX6: 1 | FY6: 1 | GG6: =GE6+GA6+FY6+FW6+FU6+FS6+FO6+FQ6+GC6 -> 9 | GH6: =GF6+GB6+FZ6+FX6+FV6+FT6+FP6+FR6+GD6 -> 2 | GI6: =GH6+GG6 -> 11 | GJ6: 1 | GK6: 3 | GL6: 1 | GS6: 2 | GT6: 2 | HF6: 3 | IF6: 4 | IG6: 13 | IH6: 1 | II6: 4 | IJ6: 7 | JJ6: 3 | KN6: 2 | KO6: 6 | KT6: 8 | KU6: 3 | KV6: =KT6+KN6+KJ6+KH6+KF6+KD6+KB6+JZ6+JX6+JV6+JT6+JR6+JP6+JN6+JL6+JJ6+JH6+JF6+JD6+JB6+IZ6+IX6+IV6+IT6+IR6+IP6+IN6+IL6+IJ6+IH6+IF6+ID6+IB6+HZ6+HX6+HV6+HT6+HR6+HP6+HN6+HL6+HJ6+HH6+HF6+HD6+HB6+GZ6+GX6+GV6+GT6+GR6+GP6+GN6+GL6+GJ6 -> 32 | KW6: =KU6+KO6+KK6+KI6+KG6+KE6+KC6+KA6+JY6+JW6+JU6+JS6+JQ6+JO6+JM6+JK6+JI6+JG6+JE6+JC6+JA6+IY6+IW6+IU6+IS6+IQ6+IO6+IM6+IK6+II6+IG6+IE6+IC6+IA6+HY6+HW6+HU6+HS6+HQ6+HO6+HM6+HK6+HI6+HG6+HE6+HC6+HA6+GY6+GW6+GU6+GS6+GQ6+GO6+GM6+GK6 -> 31 | KX6: =KW6+KV6 -> 63 | KY6: 27 | KZ6: 27 | LC6: 1 | LG6: 1 | LI6: 1 | LJ6: 1 | LL6: 2 | LO6: 2 | LP6: 1 | LQ6: =LA6+LC6+KY6+LE6+LG6+LI6+LK6+LM6+LO6 -> 32 | LR6: =LB6+LD6+KZ6+LF6+LH6+LJ6+LL6+LN6+LP6 -> 31 | LS6: =LR6+LQ6 -> 63 | LV6: 5 | LW6: 5 | LX6: 12 | LY6: 12 | LZ6: 15 | MA6: 14 | MB6: =LX6+LV6+LT6+LZ6 -> 32 | MC6: =LY6+LW6+LU6+MA6 -> 31 | MD6: =MC6+MB6 -> 63 | MG6: 1 | MH6: 2 | MI6: 15 | MJ6: 10 | MK6: 12 | ML6: 14 | MM6: 4 | MN6: 5 | MO6: =MM6+MK6+MI6+MG6+ME6 -> 32 | MP6: =MN6+ML6+MJ6+MH6+MF6 -> 31 | MQ6: =MP6+MO6 -> 63 | MS6: 3 | MT6: 32 | MU6: 24 | MW6: 3 | MY6: 1 | MZ6: =MR6+MT6+MV6+MX6 -> 32 | NA6: =MS6+MU6+MW6+MY6 -> 31 | NB6: =NA6+MZ6 -> 63 | NC6: 10 | ND6: 5 | NE6: 1 | NI6: 8 | NJ6: 10 | NK6: 11 | NL6: 13 | NM6: 7 | NN6: 5 | NQ6: 4 | NR6: 3 | NS6: 1 | NW6: =NU6+NS6+NQ6+NO6+NM6+NK6+NG6+NI6+NE6 -> 32 | NX6: =NV6+NT6+NR6+NP6+NN6+NL6+NH6+NJ6+NF6 -> 31 | NY6: =NX6+NW6 -> 63 | OF6: =OD6+OB6+NZ6 -> 0 | OG6: =OE6+OC6+OA6 -> 0 | OH6: =OG6+OF6 -> 0 | OJ6: 1 | OK6: 1 | ON6: 1 | OP6: 1 | OU6: 1 | OW6: 2024 | OY6: 3 | OZ6: 1 | PD6: 1 | PI6: 1 | PK6: 1 | PM6: 25 | PN6: 5 | PO6: =PN6+PM6 -> 30 | PP6: 1 | PV6: 1 | PX6: 1 | PZ6: 1 | QB6: 1 | QD6: 1 | QI6: 1 | QL6: 1 | QM6: 1 | QO6: 1 | QR6: 1 | QU6: 1 | QZ6: 1 | RB6: 1 | RD6: 1 | RF6: 1 | RI6: 1 | RL6: 1 | RO6: 370 | RS6: 40 | RU6: 33 | RV6: 5 | RW6: 5 | RX6: 2 | RY6: 1 | RZ6: 1 | SA6: 1 | SE6: 1 | SI6: 1 | SL6: 300 | SM6: 50 | SN6: =SM6+SL6 -> 350 | SO6: 6 | SP6: 6 | SQ6: الحي الصناعي البناية الجديدة | SR6: المهندس كاظم عبد مسلم | SS6: 7809716004
A7: النجف | B7: المركز | C7: 2 | D7: 1400170 | E7: إعدادية الكوثر المهنية | F7: 1 | I7: 1 | K7: 1 | O7: 1 | Q7: 1 | V7: 38 | X7: 37 | Z7: 22 | AB7: 17 | AD7: 14 | AF7: =AD7+AB7+Z7+X7+V7 -> 128 | AG7: =AE7+AC7+AA7+Y7+W7 -> 0 | AH7: =SUM(AF7:AG7) -> 128 | AI7: 38 | AK7: 39 | AM7: 26 | AO7: 23 | AQ7: 19 | AS7: =AQ7+AO7+AM7+AK7+AI7 -> 145 | AT7: =AR7+AP7+AN7+AL7+AJ7 -> 0 | AU7: =SUM(AS7:AT7) -> 145 | AV7: 21 | AX7: 27 | AZ7: 23 | BB7: 16 | BD7: 16 | BF7: =BD7+BB7+AZ7+AX7+AV7 -> 103 | BG7: =BE7+BC7+BA7+AY7+AW7 -> 0 | BH7: =SUM(BF7:BG7) -> 103 | BI7: 7 | BK7: 32 | BM7: 22 | BO7: 14 | BQ7: 9 | BS7: =BQ7+BO7+BM7+BK7+BI7 -> 84 | BT7: =BR7+BP7+BN7+BL7+BJ7 -> 0 | BU7: =SUM(BS7:BT7) -> 84 | BV7: =AI7 -> 38 | BW7: =AJ7 -> 0 | BX7: =AV7+AK7 -> 60 | BY7: =AL7+AW7 -> 0 | BZ7: =BI7+AX7+AM7 -> 60 | CA7: =AN7+AY7+BJ7 -> 0 | CB7: =BK7+AZ7+AO7 -> 78 | CC7: =AP7+BA7+BL7 -> 0 | CD7: =BM7+BB7+AQ7 -> 57 | CE7: =BN7+BC7+AR7 -> 0 | CF7: =BO7+BD7 -> 30 | CG7: =BP7+BE7 -> 0 | CH7: =BQ7 -> 9 | CI7: =BR7 -> 0 | CJ7: =BV7+BX7+BZ7+CB7+CD7+CF7+CH7 -> 332 | CK7: =BW7+BY7+CA7+CC7+CE7+CG7+CI7 -> 0 | CL7: =SUM(CJ7:CK7) -> 332 | CM7: 4 | CP7: 4 | CS7: 4 | CV7: =CS7+CP7+CM7 -> 12 | CW7: =CT7+CQ7+CN7 -> 0 | CX7: =CU7+CR7+CO7 -> 0 | CY7: =SUM(CV7:CX7) -> 12 | CZ7: 7 | DB7: 4 | DD7: 2 | DF7: =DD7+DB7+CZ7 -> 13 | DG7: =DE7+DC7+DA7 -> 0 | DH7: =SUM(DF7:DG7) -> 13 | DO7: =DM7+DK7+DI7 -> 0 | DP7: =DN7+DL7+DJ7 -> 0 | DQ7: =SUM(DO7:DP7) -> 0 | DR7: 89 | DT7: 45 | DV7: 45 | DX7: =DV7+DT7+DR7 -> 179 | DY7: =DW7+DU7+DS7 -> 0 | DZ7: =SUM(DX7:DY7) -> 179 | EA7: 29 | EC7: 11 | EE7: 21 | EG7: =EE7+EC7+EA7 -> 61 | EH7: =EF7+ED7+EB7 -> 0 | EI7: =SUM(EG7:EH7) -> 61 | EJ7: 3 | EL7: 1 | EN7: 13 | EP7: =EN7+EL7+EJ7 -> 17 | EQ7: =EO7+EM7+EK7 -> 0 | ER7: =SUM(EP7:EQ7) -> 17 | EW7: 1 | EY7: =EW7+EU7+ES7 -> 1 | EZ7: =EX7+EV7+ET7 -> 0 | FA7: =SUM(EY7:EZ7) -> 1 | FB7: 1 | FD7: 3 | FF7: 21 | FG7: 12 | FH7: 10 | FI7: 6 | FL7: =FJ7+FH7+FF7+FD7+FB7 -> 35 | FM7: =FK7+FI7+FG7+FE7+FC7 -> 18 | FN7: =SUM(FL7:FM7) -> 53 | FO7: 1 | FP7: 2 | FR7: 1 | FW7: 3 | GG7: =GE7+GA7+FY7+FW7+FU7+FS7+FO7+FQ7+GC7 -> 4 | GH7: =GF7+GB7+FZ7+FX7+FV7+FT7+FP7+FR7+GD7 -> 3 | GI7: =GH7+GG7 -> 7 | GJ7: 2 | GK7: 1 | GL7: 1 | GM7: 1 | GN7: 2 | GS7: 2 | GT7: 1 | GU7: 1 | HG7: 1 | IF7: 5 | IG7: 10 | IH7: 2 | IJ7: 1 | IN7: 2 | KN7: 8 | KO7: 1 | KT7: 11 | KU7: 1 | KV7: =KT7+KN7+KJ7+KH7+KF7+KD7+KB7+JZ7+JX7+JV7+JT7+JR7+JP7+JN7+JL7+JJ7+JH7+JF7+JD7+JB7+IZ7+IX7+IV7+IT7+IR7+IP7+IN7+IL7+IJ7+IH7+IF7+ID7+IB7+HZ7+HX7+HV7+HT7+HR7+HP7+HN7+HL7+HJ7+HH7+HF7+HD7+HB7+GZ7+GX7+GV7+GT7+GR7+GP7+GN7+GL7+GJ7 -> 35 | KW7: =KU7+KO7+KK7+KI7+KG7+KE7+KC7+KA7+JY7+JW7+JU7+JS7+JQ7+JO7+JM7+JK7+JI7+JG7+JE7+JC7+JA7+IY7+IW7+IU7+IS7+IQ7+IO7+IM7+IK7+II7+IG7+IE7+IC7+IA7+HY7+HW7+HU7+HS7+HQ7+HO7+HM7+HK7+HI7+HG7+HE7+HC7+HA7+GY7+GW7+GU7+GS7+GQ7+GO7+GM7+GK7 -> 18 | KX7: =KW7+KV7 -> 53 | KY7: 34 | KZ7: 16 | LC7: 1 | LJ7: 2 | LQ7: =LA7+LC7+KY7+LE7+LG7+LI7+LK7+LM7+LO7 -> 35 | LR7: =LB7+LD7+KZ7+LF7+LH7+LJ7+LL7+LN7+LP7 -> 18 | LS7: =LR7+LQ7 -> 53 | LV7: 3 | LW7: 1 | LX7: 8 | LY7: 1 | LZ7: 24 | MA7: 16 | MB7: =LX7+LV7+LT7+LZ7 -> 35 | MC7: =LY7+LW7+LU7+MA7 -> 18 | MD7: =MC7+MB7 -> 53 | MG7: 9 | MH7: 3 | MI7: 14 | MJ7: 3 | MK7: 11 | ML7: 10 | MM7: 1 | MN7: 2 | MO7: =MM7+MK7+MI7+MG7+ME7 -> 35 | MP7: =MN7+ML7+MJ7+MH7+MF7 -> 18 | MQ7: =MP7+MO7 -> 53 | MR7: 1 | MS7: 2 | MT7: 33 | MU7: 16 | MV7: 1 | MZ7: =MR7+MT7+MV7+MX7 -> 35 | NA7: =MS7+MU7+MW7+MY7 -> 18 | NB7: =NA7+MZ7 -> 53 | NC7: 13 | ND7: 10 | NI7: 10 | NJ7: 7 | NK7: 10 | NL7: 5 | NM7: 5 | NN7: 6 | NQ7: 8 | NS7: 2 | NW7: =NU7+NS7+NQ7+NO7+NM7+NK7+NG7+NI7+NE7 -> 35 | NX7: =NV7+NT7+NR7+NP7+NN7+NL7+NH7+NJ7+NF7 -> 18 | NY7: =NX7+NW7 -> 53 | OB7: 1 | OF7: =OD7+OB7+NZ7 -> 1 | OG7: =OE7+OC7+OA7 -> 0 | OH7: =OG7+OF7 -> 1 | OJ7: 1 | OK7: 1 | ON7: 1 | OP7: 1 | OU7: 1 | OW7: 1978 | OX7: 2425/158 | PA7: 1 | PC7: 1 | PI7: 1 | PJ7: 1 | PL7: 5 | PM7: 24 | PN7: 10 | PO7: =PN7+PM7 -> 34 | PP7: 1 | PV7: 1 | PX7: 1 | PZ7: 1 | QB7: 1 | QD7: 1 | QI7: 1 | QL7: 1 | QM7: 1 | QO7: 1 | QS7: 1 | QU7: 1 | QY7: 1 | RB7: 1 | RD7: 1 | RF7: 1 | RI7: 1 | RM7: 1 | RO7: 530 | RQ7: 92 | RS7: 4 | RT7: 20 | RU7: 2 | RW7: 2 | SA7: 1 | SE7: 1 | SI7: 1 | SL7: 72 | SN7: =SM7+SL7 -> 72 | SO7: 3 | SP7: 3 | SQ7: شارع المدينة / مركز شرطة الغري | SR7: غياث جودي ياسين | SS7: 7808504400
A8: النجف | B8: المركز | C8: 3 | D8: 1400171 | E8: إعدادية الغري المهنية للبنين | F8: 1 | I8: 1 | K8: 1 | O8: 1 | Q8: 1 | V8: 81 | X8: 59 | Z8: 43 | AB8: 21 | AD8: 11 | AF8: =AD8+AB8+Z8+X8+V8 -> 215 | AG8: =AE8+AC8+AA8+Y8+W8 -> 0 | AH8: =SUM(AF8:AG8) -> 215 | AI8: 81 | AK8: 59 | AM8: 43 | AO8: 21 | AQ8: 11 | AS8: =AQ8+AO8+AM8+AK8+AI8 -> 215 | AT8: =AR8+AP8+AN8+AL8+AJ8 -> 0 | AU8: =SUM(AS8:AT8) -> 215 | AV8: 53 | AX8: 30 | AZ8: 32 | BB8: 27 | BD8: 7 | BF8: =BD8+BB8+AZ8+AX8+AV8 -> 149 | BG8: =BE8+BC8+BA8+AY8+AW8 -> 0 | BH8: =SUM(BF8:BG8) -> 149 | BI8: 25 | BK8: 42 | BM8: 29 | BO8: 14 | BQ8: 11 | BS8: =BQ8+BO8+BM8+BK8+BI8 -> 121 | BT8: =BR8+BP8+BN8+BL8+BJ8 -> 0 | BU8: =SUM(BS8:BT8) -> 121 | BV8: =AI8 -> 81 | BW8: =AJ8 -> 0 | BX8: =AV8+AK8 -> 112 | BY8: =AL8+AW8 -> 0 | BZ8: =BI8+AX8+AM8 -> 98 | CA8: =AN8+AY8+BJ8 -> 0 | CB8: =BK8+AZ8+AO8 -> 95 | CC8: =AP8+BA8+BL8 -> 0 | CD8: =BM8+BB8+AQ8 -> 67 | CE8: =BN8+BC8+AR8 -> 0 | CF8: =BO8+BD8 -> 21 | CG8: =BP8+BE8 -> 0 | CH8: =BQ8 -> 11 | CI8: =BR8 -> 0 | CJ8: =BV8+BX8+BZ8+CB8+CD8+CF8+CH8 -> 485 | CK8: =BW8+BY8+CA8+CC8+CE8+CG8+CI8 -> 0 | CL8: =SUM(CJ8:CK8) -> 485 | CM8: 5 | CP8: 5 | CS8: 4 | CV8: =CS8+CP8+CM8 -> 14 | CW8: =CT8+CQ8+CN8 -> 0 | CX8: =CU8+CR8+CO8 -> 0 | CY8: =SUM(CV8:CX8) -> 14 | CZ8: 4 | DB8: 3 | DD8: 2 | DF8: =DD8+DB8+CZ8 -> 9 | DG8: =DE8+DC8+DA8 -> 0 | DH8: =SUM(DF8:DG8) -> 9 | DO8: =DM8+DK8+DI8 -> 0 | DP8: =DN8+DL8+DJ8 -> 0 | DQ8: =SUM(DO8:DP8) -> 0 | DR8: 143 | DT8: 82 | DV8: 106 | DX8: =DV8+DT8+DR8 -> 331 | DY8: =DW8+DU8+DS8 -> 0 | DZ8: =SUM(DX8:DY8) -> 331 | EA8: 24 | EC8: 6 | EE8: 38 | EG8: =EE8+EC8+EA8 -> 68 | EH8: =EF8+ED8+EB8 -> 0 | EI8: =SUM(EG8:EH8) -> 68 | EJ8: 5 | EL8: 2 | EN8: 5 | EP8: =EN8+EL8+EJ8 -> 12 | EQ8: =EO8+EM8+EK8 -> 0 | ER8: =SUM(EP8:EQ8) -> 12 | EW8: 28 | EY8: =EW8+EU8+ES8 -> 28 | EZ8: =EX8+EV8+ET8 -> 0 | FA8: =SUM(EY8:EZ8) -> 28 | FB8: 1 | FD8: 2 | FE8: 1 | FF8: 10 | FG8: 8 | FH8: 9 | FI8: 7 | FL8: =FJ8+FH8+FF8+FD8+FB8 -> 22 | FM8: =FK8+FI8+FG8+FE8+FC8 -> 16 | FN8: =SUM(FL8:FM8) -> 38 | FO8: 2 | FP8: 2 | FR8: 1 | FS8: 1 | FY8: 2 | GG8: =GE8+GA8+FY8+FW8+FU8+FS8+FO8+FQ8+GC8 -> 5 | GH8: =GF8+GB8+FZ8+FX8+FV8+FT8+FP8+FR8+GD8 -> 3 | GI8: =GH8+GG8 -> 8 | GK8: 2 | GM8: 1 | GN8: 1 | GO8: 2 | GR8: 1 | GS8: 1 | GT8: 1 | GV8: 1 | HF8: 1 | IF8: 2 | IG8: 2 | JP8: 1 | KE8: 1 | KN8: 6 | KO8: 2 | KT8: 8 | KU8: 5 | KV8: =KT8+KN8+KJ8+KH8+KF8+KD8+KB8+JZ8+JX8+JV8+JT8+JR8+JP8+JN8+JL8+JJ8+JH8+JF8+JD8+JB8+IZ8+IX8+IV8+IT8+IR8+IP8+IN8+IL8+IJ8+IH8+IF8+ID8+IB8+HZ8+HX8+HV8+HT8+HR8+HP8+HN8+HL8+HJ8+HH8+HF8+HD8+HB8+GZ8+GX8+GV8+GT8+GR8+GP8+GN8+GL8+GJ8+KL8 -> 22 | KW8: =KU8+KO8+KK8+KI8+KG8+KE8+KC8+KA8+JY8+JW8+JU8+JS8+JQ8+JO8+JM8+JK8+JI8+JG8+JE8+JC8+JA8+IY8+IW8+IU8+IS8+IQ8+IO8+IM8+IK8+II8+IG8+IE8+IC8+IA8+HY8+HW8+HU8+HS8+HQ8+HO8+HM8+HK8+HI8+HG8+HE8+HC8+HA8+GY8+GW8+GU8+GS8+GQ8+GO8+GM8+GK8 -> 16 | KX8: =KW8+KV8 -> 38 | KY8: 20 | KZ8: 15 | LC8: 1 | LL8: 1 | LO8: 1 | LQ8: =LA8+LC8+KY8+LE8+LG8+LI8+LK8+LM8+LO8 -> 22 | LR8: =LB8+LD8+KZ8+LF8+LH8+LJ8+LL8+LN8+LP8 -> 16 | LS8: =LR8+LQ8 -> 38 | LT8: 1 | LU8: 1 | LZ8: 21 | MA8: 15 | MB8: =LX8+LV8+LT8+LZ8 -> 22 | MC8: =LY8+LW8+LU8+MA8 -> 16 | MD8: =MC8+MB8 -> 38 | MG8: 3 | MH8: 2 | MI8: 7 | MJ8: 1 | MK8: 7 | ML8: 9 | MM8: 5 | MN8: 4 | MO8: =MM8+MK8+MI8+MG8+ME8 -> 22 | MP8: =MN8+ML8+MJ8+MH8+MF8 -> 16 | MQ8: =MP8+MO8 -> 38 | MS8: 2 | MT8: 20 | MU8: 12 | MW8: 2 | MX8: 2 | MZ8: =MR8+MT8+MV8+MX8 -> 22 | NA8: =MS8+MU8+MW8+MY8 -> 16 | NB8: =NA8+MZ8 -> 38 | NI8: 9 | NJ8: 6 | NK8: 8 | NL8: 4 | NM8: 3 | NN8: 5 | NQ8: 2 | NR8: 1 | NW8: =NU8+NS8+NQ8+NO8+NM8+NK8+NG8+NI8+NE8 -> 22 | NX8: =NV8+NT8+NR8+NP8+NN8+NL8+NH8+NJ8+NF8 -> 16 | NY8: =NX8+NW8 -> 38 | OF8: =OD8+OB8+NZ8 -> 0 | OG8: =OE8+OC8+OA8 -> 0 | OH8: =OG8+OF8 -> 0 | OJ8: 1 | OK8: 1 | ON8: 1 | OP8: 1 | OU8: 1 | OW8: 1975 | OX8: 10478/2 | OY8: 2 | PA8: 1 | PC8: 1 | PI8: 1 | PJ8: 1 | PL8: 6 | PM8: 24 | PN8: 4 | PO8: =PN8+PM8 -> 28 | PP8: 1 | PV8: 1 | PY8: 1 | QA8: 1 | QB8: 1 | QD8: 1 | QI8: 1 | QK8: 1 | QM8: 1 | QO8: 1 | QR8: 1 | QU8: 1 | QY8: 1 | RB8: 1 | RD8: 1 | RF8: 1 | RI8: 1 | RL8: 1 | RO8: 316 | RQ8: 375 | RS8: 10 | RT8: 20 | RU8: 15 | RV8: 15 | RW8: 1 | SB8: 1 | SN8: =SM8+SL8 -> 0 | SO8: 3 | SP8: 3 | SQ8: مقابل السوق العصري / حي الحوراء | SR8: م . م . علي ناظم محمد حسين | SS8: 7800070051
A9: النجف | B9: المركز | C9: 4 | D9: 1400172 | E9: إعدادية الغري المهنية للبنات | G9: 1 | I9: 1 | K9: 1 | O9: 1 | Q9: 1 | W9: 77 | Y9: 64 | AA9: 56 | AC9: 23 | AE9: 29 | AF9: =AD9+AB9+Z9+X9+V9 -> 0 | AG9: =AE9+AC9+AA9+Y9+W9 -> 249 | AH9: =SUM(AF9:AG9) -> 249 | AJ9: 77 | AL9: 64 | AN9: 56 | AP9: 23 | AR9: 29 | AS9: =AQ9+AO9+AM9+AK9+AI9 -> 0 | AT9: =AR9+AP9+AN9+AL9+AJ9 -> 249 | AU9: =SUM(AS9:AT9) -> 249 | AW9: 46 | AY9: 23 | BA9: 29 | BC9: 15 | BE9: 29 | BF9: =BD9+BB9+AZ9+AX9+AV9 -> 0 | BG9: =BE9+BC9+BA9+AY9+AW9 -> 142 | BH9: =SUM(BF9:BG9) -> 142 | BJ9: 31 | BL9: 22 | BN9: 28 | BP9: 15 | BR9: 29 | BS9: =BQ9+BO9+BM9+BK9+BI9 -> 0 | BT9: =BR9+BP9+BN9+BL9+BJ9 -> 125 | BU9: =SUM(BS9:BT9) -> 125 | BV9: =AI9 -> 0 | BW9: =AJ9 -> 77 | BX9: =AV9+AK9 -> 0 | BY9: =AL9+AW9 -> 110 | BZ9: =BI9+AX9+AM9 -> 0 | CA9: =AN9+AY9+BJ9 -> 110 | CB9: =BK9+AZ9+AO9 -> 0 | CC9: =AP9+BA9+BL9 -> 74 | CD9: =BM9+BB9+AQ9 -> 0 | CE9: =BN9+BC9+AR9 -> 72 | CF9: =BO9+BD9 -> 0 | CG9: =BP9+BE9 -> 44 | CH9: =BQ9 -> 0 | CI9: =BR9 -> 29 | CJ9: =BV9+BX9+BZ9+CB9+CD9+CF9+CH9 -> 0 | CK9: =BW9+BY9+CA9+CC9+CE9+CG9+CI9 -> 516 | CL9: =SUM(CJ9:CK9) -> 516 | CN9: 7 | CQ9: 4 | CT9: 3 | CV9: =CS9+CP9+CM9 -> 0 | CW9: =CT9+CQ9+CN9 -> 14 | CX9: =CU9+CR9+CO9 -> 0 | CY9: =SUM(CV9:CX9) -> 14 | DA9: 1 | DC9: 4 | DE9: 1 | DF9: =DD9+DB9+CZ9 -> 0 | DG9: =DE9+DC9+DA9 -> 6 | DH9: =SUM(DF9:DG9) -> 6 | DO9: =DM9+DK9+DI9 -> 0 | DP9: =DN9+DL9+DJ9 -> 0 | DQ9: =SUM(DO9:DP9) -> 0 | DS9: 137 | DU9: 116 | DW9: 102 | DX9: =DV9+DT9+DR9 -> 0 | DY9: =DW9+DU9+DS9 -> 355 | DZ9: =SUM(DX9:DY9) -> 355 | EB9: 3 | ED9: 2 | EF9: 8 | EG9: =EE9+EC9+EA9 -> 0 | EH9: =EF9+ED9+EB9 -> 13 | EI9: =SUM(EG9:EH9) -> 13 | EK9: 3 | EM9: 2 | EP9: =EN9+EL9+EJ9 -> 0 | EQ9: =EO9+EM9+EK9 -> 5 | ER9: =SUM(EP9:EQ9) -> 5 | EX9: 1 | EY9: =EW9+EU9+ES9 -> 0 | EZ9: =EX9+EV9+ET9 -> 1 | FA9: =SUM(EY9:EZ9) -> 1 | FC9: 1 | FE9: 3 | FG9: 34 | FI9: 23 | FL9: =FJ9+FH9+FF9+FD9+FB9 -> 0 | FM9: =FK9+FI9+FG9+FE9+FC9 -> 61 | FN9: =SUM(FL9:FM9) -> 61 | FO9: 1 | FP9: 4 | FR9: 1 | FX9: 1 | GG9: =GE9+GA9+FY9+FW9+FU9+FS9+FO9+FQ9+GC9 -> 1 | GH9: =GF9+GB9+FZ9+FX9+FV9+FT9+FP9+FR9+GD9 -> 6 | GI9: =GH9+GG9 -> 7 | GK9: 5 | GM9: 4 | GO9: 1 | GS9: 3 | GU9: 3 | HG9: 1 | HI9: 2 | IG9: 7 | II9: 1 | IO9: 2 | JC9: 3 | KO9: 17 | KU9: 12 | KV9: =KT9+KN9+KJ9+KH9+KF9+KD9+KB9+JZ9+JX9+JV9+JT9+JR9+JP9+JN9+JL9+JJ9+JH9+JF9+JD9+JB9+IZ9+IX9+IV9+IT9+IR9+IP9+IN9+IL9+IJ9+IH9+IF9+ID9+IB9+HZ9+HX9+HV9+HT9+HR9+HP9+HN9+HL9+HJ9+HH9+HF9+HD9+HB9+GZ9+GX9+GV9+GT9+GR9+GP9+GN9+GL9+GJ9 -> 0 | KW9: =KU9+KO9+KK9+KI9+KG9+KE9+KC9+KA9+JY9+JW9+JU9+JS9+JQ9+JO9+JM9+JK9+JI9+JG9+JE9+JC9+JA9+IY9+IW9+IU9+IS9+IQ9+IO9+IM9+IK9+II9+IG9+IE9+IC9+IA9+HY9+HW9+HU9+HS9+HQ9+HO9+HM9+HK9+HI9+HG9+HE9+HC9+HA9+GY9+GW9+GU9+GS9+GQ9+GO9+GM9+GK9 -> 61 | KX9: =KW9+KV9 -> 61 | KZ9: 57 | LJ9: 3 | LP9: 1 | LQ9: =LA9+LC9+KY9+LE9+LG9+LI9+LK9+LM9+LO9 -> 0 | LR9: =LB9+LD9+KZ9+LF9+LH9+LJ9+LL9+LN9+LP9 -> 61 | LS9: =LR9+LQ9 -> 61 | LU9: 4 | LW9: 4 | LY9: 3 | MA9: 50 | MB9: =LX9+LV9+LT9+LZ9 -> 0 | MC9: =LY9+LW9+LU9+MA9 -> 61 | MD9: =MC9+MB9 -> 61 | MF9: 2 | MH9: 8 | MJ9: 22 | ML9: 27 | MN9: 2 | MO9: =MM9+MK9+MI9+MG9+ME9 -> 0 | MP9: =MN9+ML9+MJ9+MH9+MF9 -> 61 | MQ9: =MP9+MO9 -> 61 | MS9: 12 | MU9: 48 | MW9: 1 | MZ9: =MR9+MT9+MV9+MX9 -> 0 | NA9: =MS9+MU9+MW9+MY9 -> 61 | NB9: =NA9+MZ9 -> 61 | ND9: 2 | NH9: 2 | NJ9: 15 | NL9: 17 | NN9: 24 | NR9: 3 | NW9: =NU9+NS9+NQ9+NO9+NM9+NK9+NG9+NI9+NE9 -> 0 | NX9: =NV9+NT9+NR9+NP9+NN9+NL9+NH9+NJ9+NF9 -> 61 | NY9: =NX9+NW9 -> 61 | OF9: =OD9+OB9+NZ9 -> 0 | OG9: =OE9+OC9+OA9 -> 0 | OH9: =OG9+OF9 -> 0 | OJ9: 1 | OK9: 1 | ON9: 1 | OP9: 1 | OU9: 1 | OW9: 1979 | OX9: 17198/2 | OY9: 2 | PA9: 1 | PC9: 1 | PH9: 1 | PJ9: 1 | PL9: 6 | PM9: 18 | PN9: 13 | PO9: =PN9+PM9 -> 31 | PP9: 1 | PV9: 1 | PX9: 1 | QA9: 1 | QB9: 1 | QD9: 1 | QI9: 1 | QK9: 1 | QM9: 1 | QO9: 1 | QS9: 1 | QU9: 1 | QZ9: 1 | RB9: 1 | RD9: 1 | RG9: 1 | RI9: 1 | RM9: 1 | RO9: 250 | RQ9: 250 | RS9: 20 | RT9: 10 | RU9: 12 | RW9: 5 | RY9: 1 | SB9: 1 | SN9: =SM9+SL9 -> 0 | SO9: 2 | SP9: 2 | SQ9: حي الامير/ قرب مدرسة المهاجرين | SR9: سهاد جواد كاظم | SS9: 7817806358
A10: النجف | B10: المركز | C10: 5 | D10: 1400629 | E10: إعدادية الغدير المهنية المسائية | F10: 1 | I10: 1 | N10: 1 | P10: 1 | S10: 1 | AF10: =AD10+AB10+Z10+X10+V10 -> 0 | AG10: =AE10+AC10+AA10+Y10+W10 -> 0 | AH10: =SUM(AF10:AG10) -> 0 | AS10: =AQ10+AO10+AM10+AK10+AI10 -> 0 | AT10: =AR10+AP10+AN10+AL10+AJ10 -> 0 | AU10: =SUM(AS10:AT10) -> 0 | BF10: =BD10+BB10+AZ10+AX10+AV10 -> 0 | BG10: =BE10+BC10+BA10+AY10+AW10 -> 0 | BH10: =SUM(BF10:BG10) -> 0 | BO10: 6 | BQ10: 27 | BS10: =BQ10+BO10+BM10+BK10+BI10 -> 33 | BT10: =BR10+BP10+BN10+BL10+BJ10 -> 0 | BU10: =SUM(BS10:BT10) -> 33 | BV10: =AI10 -> 0 | BW10: =AJ10 -> 0 | BX10: =AV10+AK10 -> 0 | BY10: =AL10+AW10 -> 0 | BZ10: =BI10+AX10+AM10 -> 0 | CA10: =AN10+AY10+BJ10 -> 0 | CB10: =BK10+AZ10+AO10 -> 0 | CC10: =AP10+BA10+BL10 -> 0 | CD10: =BM10+BB10+AQ10 -> 0 | CE10: =BN10+BC10+AR10 -> 0 | CF10: =BO10+BD10 -> 6 | CG10: =BP10+BE10 -> 0 | CH10: =BQ10 -> 27 | CI10: =BR10 -> 0 | CJ10: =BV10+BX10+BZ10+CB10+CD10+CF10+CH10 -> 33 | CK10: =BW10+BY10+CA10+CC10+CE10+CG10+CI10 -> 0 | CL10: =SUM(CJ10:CK10) -> 33 | CS10: 1 | CV10: =CS10+CP10+CM10 -> 1 | CW10: =CT10+CQ10+CN10 -> 0 | CX10: =CU10+CR10+CO10 -> 0 | CY10: =SUM(CV10:CX10) -> 1 | DF10: =DD10+DB10+CZ10 -> 0 | DG10: =DE10+DC10+DA10 -> 0 | DH10: =SUM(DF10:DG10) -> 0 | DO10: =DM10+DK10+DI10 -> 0 | DP10: =DN10+DL10+DJ10 -> 0 | DQ10: =SUM(DO10:DP10) -> 0 | DT10: 2 | DX10: =DV10+DT10+DR10 -> 2 | DY10: =DW10+DU10+DS10 -> 0 | DZ10: =SUM(DX10:DY10) -> 2 | EC10: 3 | EG10: =EE10+EC10+EA10 -> 3 | EH10: =EF10+ED10+EB10 -> 0 | EI10: =SUM(EG10:EH10) -> 3 | EP10: =EN10+EL10+EJ10 -> 0 | EQ10: =EO10+EM10+EK10 -> 0 | ER10: =SUM(EP10:EQ10) -> 0 | EY10: =EW10+EU10+ES10 -> 0 | EZ10: =EX10+EV10+ET10 -> 0 | FA10: =SUM(EY10:EZ10) -> 0 | FB10: 1 | FD10: 3 | FF10: 15 | FH10: 6 | FL10: =FJ10+FH10+FF10+FD10+FB10 -> 25 | FM10: =FK10+FI10+FG10+FE10+FC10 -> 0 | FN10: =SUM(FL10:FM10) -> 25 | FO10: 1 | FW10: 1 | GG10: =GE10+GA10+FY10+FW10+FU10+FS10+FO10+FQ10+GC10 -> 2 | GH10: =GF10+GB10+FZ10+FX10+FV10+FT10+FP10+FR10+GD10 -> 0 | GI10: =GH10+GG10 -> 2 | GJ10: 1 | GL10: 1 | GN10: 1 | GR10: 1 | GT10: 1 | HF10: 1 | HH10: 1 | ID10: 1 | IH10: 3 | IJ10: 1 | JR10: 2 | KH10: 1 | KN10: 7 | KT10: 3 | KV10: =KT10+KN10+KJ10+KH10+KF10+KD10+KB10+JZ10+JX10+JV10+JT10+JR10+JP10+JN10+JL10+JJ10+JH10+JF10+JD10+JB10+IZ10+IX10+IV10+IT10+IR10+IP10+IN10+IL10+IJ10+IH10+IF10+ID10+IB10+HZ10+HX10+HV10+HT10+HR10+HP10+HN10+HL10+HJ10+HH10+HF10+HD10+HB10+GZ10+GX10+GV10+GT10+GR10+GP10+GN10+GL10+GJ10 -> 25 | KW10: =KU10+KO10+KK10+KI10+KG10+KE10+KC10+KA10+JY10+JW10+JU10+JS10+JQ10+JO10+JM10+JK10+JI10+JG10+JE10+JC10+JA10+IY10+IW10+IU10+IS10+IQ10+IO10+IM10+IK10+II10+IG10+IE10+IC10+IA10+HY10+HW10+HU10+HS10+HQ10+HO10+HM10+HK10+HI10+HG10+HE10+HC10+HA10+GY10+GW10+GU10+GS10+GQ10+GO10+GM10+GK10 -> 0 | KX10: =KW10+KV10 -> 25 | KY10: 25 | LQ10: =LA10+LC10+KY10+LE10+LG10+LI10+LK10+LM10+LO10 -> 25 | LR10: =LB10+LD10+KZ10+LF10+LH10+LJ10+LL10+LN10+LP10 -> 0 | LS10: =LR10+LQ10 -> 25 | LT10: 6 | LX10: 4 | LZ10: 15 | MB10: =LX10+LV10+LT10+LZ10 -> 25 | MC10: =LY10+LW10+LU10+MA10 -> 0 | MD10: =MC10+MB10 -> 25 | ME10: 8 | MG10: 6 | MI10: 2 | MK10: 9 | MO10: =MM10+MK10+MI10+MG10+ME10 -> 25 | MP10: =MN10+ML10+MJ10+MH10+MF10 -> 0 | MQ10: =MP10+MO10 -> 25 | MR10: 1 | MT10: 24 | MZ10: =MR10+MT10+MV10+MX10 -> 25 | NA10: =MS10+MU10+MW10+MY10 -> 0 | NB10: =NA10+MZ10 -> 25 | NC10: 20 | NE10: 1 | NG10: 3 | NI10: 2 | NK10: 2 | NM10: 12 | NQ10: 5 | NW10: =NU10+NS10+NQ10+NO10+NM10+NK10+NG10+NI10+NE10 -> 25 | NX10: =NV10+NT10+NR10+NP10+NN10+NL10+NH10+NJ10+NF10 -> 0 | NY10: =NX10+NW10 -> 25 | OF10: =OD10+OB10+NZ10 -> 0 | OG10: =OE10+OC10+OA10 -> 0 | OH10: =OG10+OF10 -> 0 | OI10: 1 | OK10: 1 | ON10: 1 | OP10: 1 | PO10: =PN10+PM10 -> 0 | RO10: 150 | RS10: 15 | RU10: 24 | RW10: 2 | RY10: 1 | SB10: 1 | SN10: =SM10+SL10 -> 0 | SQ10: الجامعة | SR10: احمد عبد الرحيم كاظم | SS10: 7801361410
A11: خلاصة مركز النجف الصناعي | F11: =F10+F9+F8+F7+F6 -> 4 | G11: =G10+G9+G8+G7+G6 -> 1 | H11: =H10+H9+H8+H7+H6 -> 0 | I11: =I10+I9+I8+I7+I6 -> 5 | J11: =J10+J9+J8+J7+J6 -> 0 | K11: =K10+K9+K8+K7+K6 -> 4 | L11: =L10+L9+L8+L7+L6 -> 0 | M11: =M10+M9+M8+M7+M6 -> 0 | ... EX11: =EX10+EX9+EX8+EX7+EX6 -> 1 | EY11: =EW11+EU11+ES11 -> 29 | EZ11: =EX11+EV11+ET11 -> 1 | FA11: =SUM(EY11:EZ11) -> 30 | FB11: =FB10+FB9+FB8+FB7+FB6 -> 4 | FC11: =FC10+FC9+FC8+FC7+FC6 -> 1 | FD11: =FD10+FD9+FD8+FD7+FD6 -> 10 | FE11: =FE10+FE9+FE8+FE7+FE6 -> 5 | FF11: =FF10+FF9+FF8+FF7+FF6 -> 68 | FG11: =FG10+FG9+FG8+FG7+FG6 -> 74 | FH11: =FH10+FH9+FH8+FH7+FH6 -> 32 | FI11: =FI10+FI9+FI8+FI7+FI6 -> 46 | ... GB11: =GB10+GB9+GB8+GB7+GB6 -> 0 | GE11: =GE10+GE9+GE8+GE7+GE6 -> 0 | GF11: =GF10+GF9+GF8+GF7+GF6 -> 0 | GG11: =GG10+GG9+GG8+GG7+GG6 -> 21 | GH11: =GH10+GH9+GH8+GH7+GH6 -> 14 | GI11: =GI10+GI9+GI8+GI7+GI6 -> 35 | GJ11: =GJ10+GJ9+GJ8+GJ7+GJ6 -> 4 | GK11: =GK10+GK9+GK8+GK7+GK6 -> 11 | GL11: =GL10+GL9+GL8+GL7+GL6 -> 3 | ... LP11: =LP10+LP9+LP8+LP7+LP6 -> 2 | LQ11: =LA11+LC11+KY11+LE11+LG11+LI11+LK11+LM11+LO11 -> 114 | LR11: =LB11+LD11+KZ11+LF11+LH11+LJ11+LL11+LN11+LP11 -> 126 | LS11: =LS10+LS9+LS8+LS7+LS6 -> 240 | LT11: =LT10+LT9+LT8+LT7+LT6 -> 7 | LU11: =LU10+LU9+LU8+LU7+LU6 -> 5 | LV11: =LV10+LV9+LV8+LV7+LV6 -> 8 | LW11: =LW10+LW9+LW8+LW7+LW6 -> 10 | LX11: =LX10+LX9+LX8+LX7+LX6 -> 24 | LY11: =LY10+LY9+LY8+LY7+LY6 -> 16 | LZ11: =LZ10+LZ9+LZ8+LZ7+LZ6 -> 75 | ... OV11: =OV10+OV9+OV8+OV7+OV6 -> 0 | OZ11: =OZ10+OZ9+OZ8+OZ7+OZ6 -> 1 | PA11: =PA10+PA9+PA8+PA7+PA6 -> 3 | PB11: =PB10+PB9+PB8+PB7+PB6 -> 0 | PC11: =PC10+PC9+PC8+PC7+PC6 -> 3 | PD11: =PD10+PD9+PD8+PD7+PD6 -> 1 | PE11: =PE10+PE9+PE8+PE7+PE6 -> 0 | PF11: =PF10+PF9+PF8+PF7+PF6 -> 0 | PG11: =PG10+PG9+PG8+PG7+PG6 -> 0 | ... RN11: =RN10+RN9+RN8+RN7+RN6 -> 0 | RU11: =RU10+RU9+RU8+RU7+RU6 -> 86 | RV11: =RV10+RV9+RV8+RV7+RV6 -> 20 | RW11: =RW10+RW9+RW8+RW7+RW6 -> 15 | RX11: =RX10+RX9+RX8+RX7+RX6 -> 2 | RY11: =RY10+RY9+RY8+RY7+RY6 -> 3 | RZ11: =RZ10+RZ9+RZ8+RZ7+RZ6 -> 1 | SA11: =SA10+SA9+SA8+SA7+SA6 -> 2 | SB11: =SB10+SB9+SB8+SB7+SB6 -> 3 | ... SP11: =SP10+SP9+SP8+SP7+SP6 -> 14
A12: خلاصة قضاء النجف الصناعي | F12: =F11 -> 4 | G12: =G11 -> 1 | H12: =H11 -> 0 | I12: =I11 -> 5 | J12: =J11 -> 0 | K12: =K11 -> 4 | L12: =L11 -> 0 | M12: =M11 -> 0 | ... EX12: =EX11 -> 1 | EY12: =EW12+EU12+ES12 -> 29 | EZ12: =EX12+EV12+ET12 -> 1 | FA12: =SUM(EY12:EZ12) -> 30 | FB12: =FB11 -> 4 | FC12: =FC11 -> 1 | FD12: =FD11 -> 10 | FE12: =FE11 -> 5 | FF12: =FF11 -> 68 | FG12: =FG11 -> 74 | FH12: =FH11 -> 32 | FI12: =FI11 -> 46 | ... GB12: =GB11 -> 0 | GE12: =GE11 -> 0 | GF12: =GF11 -> 0 | GG12: =GG11 -> 21 | GH12: =GH11 -> 14 | GI12: =GI11 -> 35 | GJ12: =GJ11 -> 4 | GK12: =GK11 -> 11 | GL12: =GL11 -> 3 | ... LP12: =LP11 -> 2 | LQ12: =LA12+LC12+KY12+LE12+LG12+LI12+LK12+LM12+LO12 -> 114 | LR12: =LB12+LD12+KZ12+LF12+LH12+LJ12+LL12+LN12+LP12 -> 126 | LS12: =LS11 -> 240 | LT12: =LT11 -> 7 | LU12: =LU11 -> 5 | LV12: =LV11 -> 8 | LW12: =LW11 -> 10 | LX12: =LX11 -> 24 | LY12: =LY11 -> 16 | LZ12: =LZ11 -> 75 | ... OV12: =OV11 -> 0 | OZ12: =OZ11 -> 1 | PA12: =PA11 -> 3 | PB12: =PB11 -> 0 | PC12: =PC11 -> 3 | PD12: =PD11 -> 1 | PE12: =PE11 -> 0 | PF12: =PF11 -> 0 | PG12: =PG11 -> 0 | ... RN12: =RN11 -> 0 | RU12: =RU11 -> 86 | RV12: =RV11 -> 20 | RW12: =RW11 -> 15 | RX12: =RX11 -> 2 | RY12: =RY11 -> 3 | RZ12: =RZ11 -> 1 | SA12: =SA11 -> 2 | SB12: =SB11 -> 3 | ... SP12: =SP11 -> 14
A13: الكوفة | B13: المركز | C13: 6 | D13: 1400173 | E13: اعدادية الكوفة المهنية | F13: 1 | I13: 1 | K13: 1 | O13: 1 | Q13: 1 | V13: 24 | X13: 9 | Z13: 7 | AB13: 11 | AD13: 2 | AF13: =AD13+AB13+Z13+X13+V13 -> 53 | AG13: =AE13+AC13+AA13+Y13+W13 -> 0 | AH13: =SUM(AF13:AG13) -> 53 | AI13: 24 | AK13: 9 | AM13: 7 | AO13: 11 | AQ13: 2 | AS13: =AQ13+AO13+AM13+AK13+AI13 -> 53 | AT13: =AR13+AP13+AN13+AL13+AJ13 -> 0 | AU13: =SUM(AS13:AT13) -> 53 | AV13: 12 | AX13: 7 | AZ13: 13 | BB13: 4 | BD13: 2 | BF13: =BD13+BB13+AZ13+AX13+AV13 -> 38 | BG13: =BE13+BC13+BA13+AY13+AW13 -> 0 | BH13: =SUM(BF13:BG13) -> 38 | BI13: 6 | BK13: 14 | BM13: 14 | BO13: 5 | BQ13: 1 | BS13: =BQ13+BO13+BM13+BK13+BI13 -> 40 | BT13: =BR13+BP13+BN13+BL13+BJ13 -> 0 | BU13: =SUM(BS13:BT13) -> 40 | BV13: =AI13 -> 24 | BW13: =AJ13 -> 0 | BX13: =AV13+AK13 -> 21 | BY13: =AL13+AW13 -> 0 | BZ13: =BI13+AX13+AM13 -> 20 | CA13: =AN13+AY13+BJ13 -> 0 | CB13: =BK13+AZ13+AO13 -> 38 | CC13: =AP13+BA13+BL13 -> 0 | CD13: =BM13+BB13+AQ13 -> 20 | CE13: =BN13+BC13+AR13 -> 0 | CF13: =BO13+BD13 -> 7 | CG13: =BP13+BE13 -> 0 | CH13: =BQ13 -> 1 | CI13: =BR13 -> 0 | CJ13: =BV13+BX13+BZ13+CB13+CD13+CF13+CH13 -> 131 | CK13: =BW13+BY13+CA13+CC13+CE13+CG13+CI13 -> 0 | CL13: =SUM(CJ13:CK13) -> 131 | CM13: 1 | CP13: 1 | CS13: 1 | CV13: =CS13+CP13+CM13 -> 3 | CW13: =CT13+CQ13+CN13 -> 0 | CX13: =CU13+CR13+CO13 -> 0 | CY13: =SUM(CV13:CX13) -> 3 | DD13: 1 | DF13: =DD13+DB13+CZ13 -> 1 | DG13: =DE13+DC13+DA13 -> 0 | DH13: =SUM(DF13:DG13) -> 1 | DO13: =DM13+DK13+DI13 -> 0 | DP13: =DN13+DL13+DJ13 -> 0 | DQ13: =SUM(DO13:DP13) -> 0 | DR13: 31 | DT13: 18 | DV13: 28 | DX13: =DV13+DT13+DR13 -> 77 | DY13: =DW13+DU13+DS13 -> 0 | DZ13: =SUM(DX13:DY13) -> 77 | EA13: 5 | EC13: 5 | EE13: 11 | EG13: =EE13+EC13+EA13 -> 21 | EH13: =EF13+ED13+EB13 -> 0 | EI13: =SUM(EG13:EH13) -> 21 | EL13: 1 | EP13: =EN13+EL13+EJ13 -> 1 | EQ13: =EO13+EM13+EK13 -> 0 | ER13: =SUM(EP13:EQ13) -> 1 | EY13: =EW13+EU13+ES13 -> 0 | EZ13: =EX13+EV13+ET13 -> 0 | FA13: =SUM(EY13:EZ13) -> 0 | FB13: 1 | FD13: 3 | FF13: 24 | FG13: 12 | FH13: 6 | FI13: 4 | FL13: =FJ13+FH13+FF13+FD13+FB13 -> 34 | FM13: =FK13+FI13+FG13+FE13+FC13 -> 16 | FN13: =SUM(FL13:FM13) -> 50 | FW13: 2 | GG13: =GE13+GA13+FY13+FW13+FU13+FS13+FO13+FQ13+GC13 -> 2 | GH13: =GF13+GB13+FZ13+FX13+FV13+FT13+FP13+FR13+GD13 -> 0 | GI13: =GH13+GG13 -> 2 | GJ13: 1 | GK13: 1 | GL13: 1 | GM13: 1 | GN13: 1 | GO13: 1 | GP13: 1 | GR13: 1 | GS13: 2 | GU13: 1 | HF13: 1 | HJ13: 1 | HK13: 1 | HP13: 1 | HR13: 1 | HX13: 1 | HY13: 2 | IB13: 1 | IC13: 1 | IH13: 1 | II13: 1 | JB13: 11 | JC13: 3 | JH13: 1 | JP13: 1 | KN13: 9 | KO13: 2 | KV13: =KT13+KN13+KJ13+KH13+KF13+KD13+KB13+JZ13+JX13+JV13+JT13+JR13+JP13+JN13+JL13+JJ13+JH13+JF13+JD13+JB13+IZ13+IX13+IV13+IT13+IR13+IP13+IN13+IL13+IJ13+IH13+IF13+ID13+IB13+HZ13+HX13+HV13+HT13+HR13+HP13+HN13+HL13+HJ13+HH13+HF13+HD13+HB13+GZ13+GX13+GV13+GT13+GR13+GP13+GN13+GL13+GJ13+KL13 -> 34 | KW13: =KU13+KO13+KK13+KI13+KG13+KE13+KC13+KA13+JY13+JW13+JU13+JS13+JQ13+JO13+JM13+JK13+JI13+JG13+JE13+JC13+JA13+IY13+IW13+IU13+IS13+IQ13+IO13+IM13+IK13+II13+IG13+IE13+IC13+IA13+HY13+HW13+HU13+HS13+HQ13+HO13+HM13+HK13+HI13+HG13+HE13+HC13+HA13+GY13+GW13+GU13+GS13+GQ13+GO13+GM13+GK13 -> 16 | KX13: =KW13+KV13 -> 50 | KY13: 28 | KZ13: 13 | LC13: 3 | LG13: 1 | LI13: 1 | LJ13: 3 | LO13: 1 | LQ13: =LA13+LC13+KY13+LE13+LG13+LI13+LK13+LM13+LO13 -> 34 | LR13: =LB13+LD13+KZ13+LF13+LH13+LJ13+LL13+LN13+LP13 -> 16 | LS13: =LR13+LQ13 -> 50 | LT13: 2 | LU13: 1 | LV13: 12 | LW13: 2 | LY13: 2 | LZ13: 20 | MA13: 11 | MB13: =LX13+LV13+LT13+LZ13 -> 34 | MC13: =LY13+LW13+LU13+MA13 -> 16 | MD13: =MC13+MB13 -> 50 | MG13: 3 | MH13: 5 | MI13: 16 | MJ13: 6 | MK13: 11 | ML13: 5 | MM13: 4 | MO13: =MM13+MK13+MI13+MG13+ME13 -> 34 | MP13: =MN13+ML13+MJ13+MH13+MF13 -> 16 | MQ13: =MP13+MO13 -> 50 | MR13: 2 | MS13: 2 | MT13: 32 | MU13: 13 | MY13: 1 | MZ13: =MX13+MV13+MT13+MR13 -> 34 | NA13: =MY13+MW13+MU13+MS13 -> 16 | NB13: =NA13+MZ13 -> 50 | NE13: 1 | NI13: 5 | NJ13: 5 | NK13: 22 | NL13: 9 | NQ13: 4 | NR13: 2 | NS13: 2 | NW13: =NU13+NS13+NQ13+NO13+NM13+NK13+NG13+NI13+NE13 -> 34 | NX13: =NV13+NT13+NR13+NP13+NN13+NL13+NH13+NJ13+NF13 -> 16 | NY13: =NX13+NW13 -> 50 | OF13: =OD13+OB13+NZ13 -> 0 | OG13: =OE13+OC13+OA13 -> 0 | OH13: =OG13+OF13 -> 0 | OJ13: 1 | OK13: 1 | ON13: 1 | OP13: 1 | OT13: 1 | OU13: 1 | OW13: 1976 | OX13: 2445/1 | OY13: 3 | OZ13: 1 | PD13: 1 | PH13: 1 | PJ13: 1 | PL13: 6 | PM13: 18 | PN13: 7 | PO13: =PN13+PM13 -> 25 | PP13: 1 | PV13: 1 | PX13: 1 | PZ13: 1 | QB13: 1 | QD13: 1 | QI13: 1 | QL13: 1 | QM13: 1 | QO13: 1 | QR13: 1 | QU13: 1 | QZ13: 1 | RB13: 1 | RD13: 1 | RF13: 1 | RI13: 1 | RL13: 1 | RO13: 240 | RP13: 10 | RQ13: 150 | RR13: 40 | RS13: 12 | RT13: 12 | RU13: 10 | RV13: 20 | RW13: 2 | RX13: 2 | RY13: 1 | RZ13: 3 | SB13: 1 | SN13: =SM13+SL13 -> 0 | SO13: 7 | SP13: 7 | SQ13: الحي الصناعي | SR13: م . م . عدي محسن محمد جواد | SS13: 7803484077
A14: خلاصة مركز الكوفة الصناعي | F14: =F13 -> 1 | G14: =G13 -> 0 | H14: =H13 -> 0 | I14: =I13 -> 1 | J14: =J13 -> 0 | K14: =K13 -> 1 | L14: =L13 -> 0 | M14: =M13 -> 0 | ... EX14: =EX13 -> 0 | EY14: =EW14+EU14+ES14 -> 0 | EZ14: =EX14+EV14+ET14 -> 0 | FA14: =SUM(EY14:EZ14) -> 0 | FB14: =FB13 -> 1 | FC14: =FC13 -> 0 | FD14: =FD13 -> 3 | FE14: =FE13 -> 0 | FF14: =FF13 -> 24 | FG14: =FG13 -> 12 | FH14: =FH13 -> 6 | FI14: =FI13 -> 4 | ... GB14: =GB13 -> 0 | GE14: =GE13 -> 0 | GF14: =GF13 -> 0 | GG14: =GG13 -> 2 | GH14: =GH13 -> 0 | GI14: =GI13 -> 2 | GJ14: =GJ13 -> 1 | GK14: =GK13 -> 1 | GL14: =GL13 -> 1 | ... LP14: =LP13 -> 0 | LQ14: =LA14+LC14+KY14+LE14+LG14+LI14+LK14+LM14+LO14 -> 34 | LR14: =LB14+LD14+KZ14+LF14+LH14+LJ14+LL14+LN14+LP14 -> 16 | LS14: =LS13 -> 50 | LT14: =LT13 -> 2 | LU14: =LU13 -> 1 | LV14: =LV13 -> 12 | LW14: =LW13 -> 2 | LX14: =LX13 -> 0 | LY14: =LY13 -> 2 | LZ14: =LZ13 -> 20 | ... OV14: =OV13 -> 0 | OZ14: =OZ13 -> 1 | PA14: =PA13 -> 0 | PB14: =PB13 -> 0 | PC14: =PC13 -> 0 | PD14: =PD13 -> 1 | PE14: =PE13 -> 0 | PF14: =PF13 -> 0 | PG14: =PG13 -> 0 | ... RN14: =RN13 -> 0 | RU14: =RU13 -> 10 | RV14: =RV13 -> 20 | RW14: =RW13 -> 2 | RX14: =RX13 -> 2 | RY14: =RY13 -> 1 | RZ14: =RZ13 -> 3 | SA14: =SA13 -> 0 | SB14: =SB13 -> 1 | ... SP14: =SP13 -> 7
A15: خلاصة قضاء الكوفة الصناعي | F15: =F14 -> 1 | G15: =G14 -> 0 | H15: =H14 -> 0 | I15: =I14 -> 1 | J15: =J14 -> 0 | K15: =K14 -> 1 | L15: =L14 -> 0 | M15: =M14 -> 0 | ... EX15: =EX14 -> 0 | EY15: =EW15+EU15+ES15 -> 0 | EZ15: =EX15+EV15+ET15 -> 0 | FA15: =SUM(EY15:EZ15) -> 0 | FB15: =FB14 -> 1 | FC15: =FC14 -> 0 | FD15: =FD14 -> 3 | FE15: =FE14 -> 0 | FF15: =FF14 -> 24 | FG15: =FG14 -> 12 | FH15: =FH14 -> 6 | FI15: =FI14 -> 4 | ... GB15: =GB14 -> 0 | GE15: =GE14 -> 0 | GF15: =GF14 -> 0 | GG15: =GG14 -> 2 | GH15: =GH14 -> 0 | GI15: =GI14 -> 2 | GJ15: =GJ14 -> 1 | GK15: =GK14 -> 1 | GL15: =GL14 -> 1 | ... LP15: =LP14 -> 0 | LQ15: =LA15+LC15+KY15+LE15+LG15+LI15+LK15+LM15+LO15 -> 34 | LR15: =LB15+LD15+KZ15+LF15+LH15+LJ15+LL15+LN15+LP15 -> 16 | LS15: =LS14 -> 50 | LT15: =LT14 -> 2 | LU15: =LU14 -> 1 | LV15: =LV14 -> 12 | LW15: =LW14 -> 2 | LX15: =LX14 -> 0 | LY15: =LY14 -> 2 | LZ15: =LZ14 -> 20 | ... OV15: =OV14 -> 0 | OZ15: =OZ14 -> 1 | PA15: =PA14 -> 0 | PB15: =PB14 -> 0 | PC15: =PC14 -> 0 | PD15: =PD14 -> 1 | PE15: =PE14 -> 0 | PF15: =PF14 -> 0 | PG15: =PG14 -> 0 | ... RN15: =RN14 -> 0 | RU15: =RU14 -> 10 | RV15: =RV14 -> 20 | RW15: =RW14 -> 2 | RX15: =RX14 -> 2 | RY15: =RY14 -> 1 | RZ15: =RZ14 -> 3 | SA15: =SA14 -> 0 | SB15: =SB14 -> 1 | ... SP15: =SP14 -> 7
A16: المناذرة | B16: المركز | C16: 7 | D16: 1400174 | E16: اعدادية المناذرة المهنية | F16: 1 | I16: 1 | K16: 1 | O16: 1 | Q16: 1 | V16: 34 | X16: 66 | Z16: 34 | AB16: 22 | AD16: 8 | AF16: =AD16+AB16+Z16+X16+V16 -> 164 | AG16: =AE16+AC16+AA16+Y16+W16 -> 0 | AH16: =SUM(AF16:AG16) -> 164 | AI16: 34 | AK16: 66 | AM16: 34 | AO16: 22 | AQ16: 8 | AS16: =AQ16+AO16+AM16+AK16+AI16 -> 164 | AT16: =AR16+AP16+AN16+AL16+AJ16 -> 0 | AU16: =SUM(AS16:AT16) -> 164 | AV16: 2 | AX16: 6 | AZ16: 10 | BB16: 24 | BD16: 15 | BF16: =BD16+BB16+AZ16+AX16+AV16 -> 57 | BG16: =BE16+BC16+BA16+AY16+AW16 -> 0 | BH16: =SUM(BF16:BG16) -> 57 | BI16: 7 | BK16: 27 | BM16: 12 | BO16: 12 | BQ16: 5 | BS16: =BQ16+BO16+BM16+BK16+BI16 -> 63 | BT16: =BR16+BP16+BN16+BL16+BJ16 -> 0 | BU16: =SUM(BS16:BT16) -> 63 | BV16: =AI16 -> 34 | BW16: =AJ16 -> 0 | BX16: =AV16+AK16 -> 68 | BY16: =AL16+AW16 -> 0 | BZ16: =BI16+AX16+AM16 -> 47 | CA16: =AN16+AY16+BJ16 -> 0 | CB16: =BK16+AZ16+AO16 -> 59 | CC16: =AP16+BA16+BL16 -> 0 | CD16: =BM16+BB16+AQ16 -> 44 | CE16: =BN16+BC16+AR16 -> 0 | CF16: =BO16+BD16 -> 27 | CG16: =BP16+BE16 -> 0 | CH16: =BQ16 -> 5 | CI16: =BR16 -> 0 | CJ16: =BV16+BX16+BZ16+CB16+CD16+CF16+CH16 -> 284 | CK16: =BW16+BY16+CA16+CC16+CE16+CG16+CI16 -> 0 | CL16: =SUM(CJ16:CK16) -> 284 | CM16: 5 | CP16: 3 | CS16: 3 | CV16: =CS16+CP16+CM16 -> 11 | CW16: =CT16+CQ16+CN16 -> 0 | CX16: =CU16+CR16+CO16 -> 0 | CY16: =SUM(CV16:CX16) -> 11 | CZ16: 6 | DB16: 2 | DD16: 10 | DF16: =DD16+DB16+CZ16 -> 18 | DG16: =DE16+DC16+DA16 -> 0 | DH16: =SUM(DF16:DG16) -> 18 | DO16: =DM16+DK16+DI16 -> 0 | DP16: =DN16+DL16+DJ16 -> 0 | DQ16: =SUM(DO16:DP16) -> 0 | DR16: 54 | DS16: 22 | DT16: 44 | DU16: 21 | DV16: 40 | DW16: 23 | DX16: =DV16+DT16+DR16 -> 138 | DY16: =DW16+DU16+DS16 -> 66 | DZ16: =SUM(DX16:DY16) -> 204 | EE16: 16 | EF16: 1 | EG16: =EE16+EC16+EA16 -> 16 | EH16: =EF16+ED16+EB16 -> 1 | EI16: =SUM(EG16:EH16) -> 17 | EP16: =EN16+EL16+EJ16 -> 0 | EQ16: =EO16+EM16+EK16 -> 0 | ER16: =SUM(EP16:EQ16) -> 0 | EY16: =EW16+EU16+ES16 -> 0 | EZ16: =EX16+EV16+ET16 -> 0 | FA16: =SUM(EY16:EZ16) -> 0 | FB16: 1 | FD16: 2 | FE16: 1 | FF16: 33 | FG16: 40 | FH16: 13 | FI16: 19 | FL16: =FJ16+FH16+FF16+FD16+FB16 -> 49 | FM16: =FK16+FI16+FG16+FE16+FC16 -> 60 | FN16: =SUM(FL16:FM16) -> 109 | FS16: 1 | FW16: 6 | FX16: 1 | GG16: =GE16+GA16+FY16+FW16+FU16+FS16+FO16+FQ16+GC16 -> 7 | GH16: =GF16+GB16+FZ16+FX16+FV16+FT16+FP16+FR16+GD16 -> 1 | GI16: =GH16+GG16 -> 8 | GJ16: 1 | GK16: 4 | GL16: 2 | GN16: 2 | GO16: 4 | GR16: 1 | GS16: 2 | GU16: 3 | GV16: 1 | GW16: 2 | HP16: 1 | HS16: 1 | HV16: 3 | HX16: 1 | IF16: 2 | IG16: 1 | IH16: 5 | II16: 1 | IJ16: 2 | IK16: 1 | JN16: 3 | JO16: 1 | JQ16: 1 | JS16: 1 | JU16: 4 | KE16: 1 | KN16: 12 | KO16: 13 | KT16: 13 | KU16: 20 | KV16: =KT16+KN16+KJ16+KH16+KF16+KD16+KB16+JZ16+JX16+JV16+JT16+JR16+JP16+JN16+JL16+JJ16+JH16+JF16+JD16+JB16+IZ16+IX16+IV16+IT16+IR16+IP16+IN16+IL16+IJ16+IH16+IF16+ID16+IB16+HZ16+HX16+HV16+HT16+HR16+HP16+HN16+HL16+HJ16+HH16+HF16+HD16+HB16+GZ16+GX16+GV16+GT16+GR16+GP16+GN16+GL16+GJ16 -> 49 | KW16: =KU16+KO16+KK16+KI16+KG16+KE16+KC16+KA16+JY16+JW16+JU16+JS16+JQ16+JO16+JM16+JK16+JI16+JG16+JE16+JC16+JA16+IY16+IW16+IU16+IS16+IQ16+IO16+IM16+IK16+II16+IG16+IE16+IC16+IA16+HY16+HW16+HU16+HS16+HQ16+HO16+HM16+HK16+HI16+HG16+HE16+HC16+HA16+GY16+GW16+GU16+GS16+GQ16+GO16+GM16+GK16 -> 60 | KX16: =KW16+KV16 -> 109 | KY16: 48 | KZ16: 60 | LG16: 1 | LQ16: =LA16+LC16+KY16+LE16+LG16+LI16+LK16+LM16+LO16 -> 49 | LR16: =LB16+LD16+KZ16+LF16+LH16+LJ16+LL16+LN16+LP16 -> 60 | LS16: =LR16+LQ16 -> 109 | LT16: 30 | LU16: 51 | LV16: 5 | LW16: 2 | LX16: 1 | LZ16: 13 | MA16: 7 | MB16: =LX16+LV16+LT16+LZ16 -> 49 | MC16: =LY16+LW16+LU16+MA16 -> 60 | MD16: =MC16+MB16 -> 109 | ME16: 2 | MF16: 5 | MG16: 27 | MH16: 41 | MI16: 9 | MJ16: 8 | MK16: 9 | ML16: 5 | MM16: 2 | MN16: 1 | MO16: =MM16+MK16+MI16+MG16+ME16 -> 49 | MP16: =MN16+ML16+MJ16+MH16+MF16 -> 60 | MQ16: =MP16+MO16 -> 109 | MR16: 7 | MS16: 9 | MT16: 42 | MU16: 51 | MZ16: =MX16+MV16+MT16+MR16 -> 49 | NA16: =MY16+MW16+MU16+MS16 -> 60 | NB16: =NA16+MZ16 -> 109 | NE16: 1 | NI16: 12 | NJ16: 19 | NK16: 32 | NL16: 30 | NM16: 3 | NN16: 10 | NQ16: 1 | NR16: 1 | NW16: =NU16+NS16+NQ16+NO16+NM16+NK16+NG16+NI16+NE16 -> 49 | NX16: =NV16+NT16+NR16+NP16+NN16+NL16+NH16+NJ16+NF16 -> 60 | NY16: =NX16+NW16 -> 109 | OF16: =OD16+OB16+NZ16 -> 0 | OG16: =OE16+OC16+OA16 -> 0 | OH16: =OG16+OF16 -> 0 | OJ16: 1 | OK16: 1 | ON16: 1 | OP16: 1 | OU16: 1 | OW16: 1980 | OX16: 900/1 | OY16: 3 | OZ16: 1 | PB16: 1 | PG16: 1 | PJ16: 1 | PL16: 12 | PM16: 12 | PN16: 10 | PO16: =PN16+PM16 -> 22 | PS16: 1 | PV16: 1 | PX16: 1 | QA16: 1 | QB16: 1 | QD16: 1 | QI16: 1 | QL16: 1 | QM16: 1 | QO16: 1 | QS16: 1 | QU16: 1 | QW16: 1 | QX16: 1 | QY16: 1 | RB16: 1 | RD16: 1 | RF16: 1 | RI16: 1 | RM16: 1 | RO16: 340 | RP16: 45 | RQ16: 50 | RR16: 50 | RS16: 10 | RT16: 15 | RU16: 4 | RV16: 11 | RX16: 1 | SA16: 1 | SE16: 1 | SK16: 1 | SL16: 80 | SM16: 10 | SN16: =SM16+SL16 -> 90 | SO16: 5 | SP16: 5 | SQ16: حي العسكري - معمل ضغط الاخشاب | SR16: م . م . سيف علاء صبحي | SS16: 7812391658
A17: المناذرة | B17: المركز | C17: 8 | D17: 1401694 | E17: اعدادية المناذرة للبنات | G17: 1 | I17: 1 | K17: 1 | O17: 1 | S17: 1 | U17: 1 | W17: 15 | Y17: 13 | AA17: 5 | AC17: 10 | AE17: 9 | AF17: =AD17+AB17+Z17+X17+V17 -> 0 | AG17: =AE17+AC17+AA17+Y17+W17 -> 52 | AH17: =SUM(AF17:AG17) -> 52 | AJ17: 15 | AL17: 13 | AN17: 5 | AP17: 10 | AR17: 9 | AS17: =AQ17+AO17+AM17+AK17+AI17 -> 0 | AT17: =AR17+AP17+AN17+AL17+AJ17 -> 52 | AU17: =SUM(AS17:AT17) -> 52 | AW17: 3 | AY17: 8 | BA17: 4 | BC17: 1 | BE17: 8 | BF17: =BD17+BB17+AZ17+AX17+AV17 -> 0 | BG17: =BE17+BC17+BA17+AY17+AW17 -> 24 | BH17: =SUM(BF17:BG17) -> 24 | BJ17: 1 | BL17: 6 | BN17: 4 | BP17: 7 | BS17: =BQ17+BO17+BM17+BK17+BI17 -> 0 | BT17: =BR17+BP17+BN17+BL17+BJ17 -> 18 | BU17: =SUM(BS17:BT17) -> 18 | BV17: =AI17 -> 0 | BW17: =AJ17 -> 15 | BX17: =AV17+AK17 -> 0 | BY17: =AL17+AW17 -> 16 | BZ17: =BI17+AX17+AM17 -> 0 | CA17: =AN17+AY17+BJ17 -> 14 | CB17: =BK17+AZ17+AO17 -> 0 | CC17: =AP17+BA17+BL17 -> 20 | CD17: =BM17+BB17+AQ17 -> 0 | CE17: =BN17+BC17+AR17 -> 14 | CF17: =BO17+BD17 -> 0 | CG17: =BP17+BE17 -> 15 | CH17: =BQ17 -> 0 | CI17: =BR17 -> 0 | CJ17: =BV17+BX17+BZ17+CB17+CD17+CF17+CH17 -> 0 | CK17: =BW17+BY17+CA17+CC17+CE17+CG17+CI17 -> 94 | CL17: =SUM(CJ17:CK17) -> 94 | CN17: 2 | CQ17: 1 | CT17: 1 | CV17: =CS17+CP17+CM17 -> 0 | CW17: =CT17+CQ17+CN17 -> 4 | CX17: =CU17+CR17+CO17 -> 0 | CY17: =SUM(CV17:CX17) -> 4 | DF17: =DD17+DB17+CZ17 -> 0 | DG17: =DE17+DC17+DA17 -> 0 | DH17: =SUM(DF17:DG17) -> 0 | DX17: =DV17+DT17+DR17 -> 0 | DY17: =DW17+DU17+DS17 -> 0 | DZ17: =SUM(DX17:DY17) -> 0 | EG17: =EE17+EC17+EA17 -> 0 | EH17: =EF17+ED17+EB17 -> 0 | EI17: =SUM(EG17:EH17) -> 0 | EP17: =EN17+EL17+EJ17 -> 0 | EQ17: =EO17+EM17+EK17 -> 0 | ER17: =SUM(EP17:EQ17) -> 0 | EY17: =EW17+EU17+ES17 -> 0 | EZ17: =EX17+EV17+ET17 -> 0 | FA17: =SUM(EY17:EZ17) -> 0 | FC17: 1 | FL17: =FJ17+FH17+FF17+FD17+FB17 -> 0 | FM17: =FK17+FI17+FG17+FE17+FC17 -> 1 | FN17: =SUM(FL17:FM17) -> 1 | GG17: =GE17+GA17+FY17+FW17+FU17+FS17+FO17+FQ17+GC17 -> 0 | GH17: =GF17+GB17+FZ17+FX17+FV17+FT17+FP17+FR17+GD17 -> 0 | GI17: =GH17+GG17 -> 0 | KU17: 1 | KV17: =KT17+KN17+KJ17+KH17+KF17+KD17+KB17+JZ17+JX17+JV17+JT17+JR17+JP17+JN17+JL17+JJ17+JH17+JF17+JD17+JB17+IZ17+IX17+IV17+IT17+IR17+IP17+IN17+IL17+IJ17+IH17+IF17+ID17+IB17+HZ17+HX17+HV17+HT17+HR17+HP17+HN17+HL17+HJ17+HH17+HF17+HD17+HB17+GZ17+GX17+GV17+GT17+GR17+GP17+GN17+GL17+GJ17 -> 0 | KW17: =KU17+KO17+KK17+KI17+KG17+KE17+KC17+KA17+JY17+JW17+JU17+JS17+JQ17+JO17+JM17+JK17+JI17+JG17+JE17+JC17+JA17+IY17+IW17+IU17+IS17+IQ17+IO17+IM17+IK17+II17+IG17+IE17+IC17+IA17+HY17+HW17+HU17+HS17+HQ17+HO17+HM17+HK17+HI17+HG17+HE17+HC17+HA17+GY17+GW17+GU17+GS17+GQ17+GO17+GM17+GK17 -> 1 | KX17: =KW17+KV17 -> 1 | KZ17: 1 | LQ17: =LA17+LC17+KY17+LE17+LG17+LI17+LK17+LM17+LO17 -> 0 | LR17: =LB17+LD17+KZ17+LF17+LH17+LJ17+LL17+LN17+LP17 -> 1 | LS17: =LR17+LQ17 -> 1 | MA17: 1 | MB17: =LX17+LV17+LT17+LZ17 -> 0 | MC17: =LY17+LW17+LU17+MA17 -> 1 | MD17: =MC17+MB17 -> 1 | ML17: 1 | MO17: =MM17+MK17+MI17+MG17+ME17 -> 0 | MP17: =MN17+ML17+MJ17+MH17+MF17 -> 1 | MQ17: =MP17+MO17 -> 1 | MS17: 1 | MZ17: =MX17+MV17+MT17+MR17 -> 0 | NA17: =MY17+MW17+MU17+MS17 -> 1 | NB17: =NA17+MZ17 -> 1 | NR17: 1 | NW17: =NU17+NS17+NQ17+NO17+NM17+NK17+NG17+NI17+NE17 -> 0 | NX17: =NV17+NT17+NR17+NP17+NN17+NL17+NH17+NJ17+NF17 -> 1 | NY17: =NX17+NW17 -> 1 | OF17: =OD17+OB17+NZ17 -> 0 | OG17: =OE17+OC17+OA17 -> 0 | OH17: =OG17+OF17 -> 0 | OJ17: 1 | OK17: 1 | ON17: 1 | OP17: 1 | OU17: 1 | OW17: 2024 | PA17: 1 | PD17: 1 | PI17: 1 | PK17: 1 | PM17: 24 | PN17: 4 | PO17: =PN17+PM17 -> 28 | PP17: 1 | PV17: 1 | PX17: 1 | PZ17: 1 | QB17: 1 | QD17: 1 | QI17: 1 | QL17: 1 | QM17: 1 | QO17: 1 | QR17: 1 | QV17: 1 | RB17: 1 | RE17: 1 | RG17: 1 | RI17: 1 | RL17: 1 | RO17: 210 | RS17: 20 | SB17: 1 | SQ17: حي العسكري - معمل ضغط الاخشاب | SR17: م . م . ندى كاظم عبد الزهرة | SS17: 7730803031
A18: خلاصة مركز المناذرة الصناعي | F18: =F16 -> 1 | G18: =G16+G17 -> 1 | H18: =H16+H17 -> 0 | I18: =I16+I17 -> 2 | J18: =J16+J17 -> 0 | K18: =K16+K17 -> 2 | L18: =L16+L17 -> 0 | M18: =M16+M17 -> 0 | N18: =N16+N17 -> 0 | ... OV18: =OV16+OV17 -> 0 | OY18: =OY16+OY17 -> 3 | OZ18: =OZ16+OZ17 -> 1 | PA18: =PA16+PA17 -> 1 | PB18: =PB16+PB17 -> 1 | PC18: =PC16+PC17 -> 0 | PD18: =PD16+PD17 -> 1 | PE18: =PE16+PE17 -> 0 | PF18: =PF16+PF17 -> 0 | ... SP18: =SP16+SP17 -> 5
A19: خلاصة قضاء المناذرة الصناعي | F19: =F18 -> 1 | G19: =G18 -> 1 | H19: =H18 -> 0 | I19: =I18 -> 2 | J19: =J18 -> 0 | K19: =K18 -> 2 | L19: =L18 -> 0 | M19: =M18 -> 0 | ... GB19: =GB18 -> 0 | GE19: =GE18 -> 0 | GF19: =GF18 -> 0 | GG19: =GG18 -> 7 | GH19: =GH18 -> 1 | GI19: =GI18 -> 8 | GJ19: =GJ18 -> 1 | GK19: =GK18 -> 4 | GL19: =GL18 -> 2 | ... LP19: =LP18 -> 0 | LQ19: =LA19+LC19+KY19+LE19+LG19+LI19+LK19+LM19+LO19 -> 49 | LR19: =LB19+LD19+KZ19+LF19+LH19+LJ19+LL19+LN19+LP19 -> 61 | LS19: =LS18 -> 110 | LT19: =LT18 -> 30 | LU19: =LU18 -> 51 | LV19: =LV18 -> 5 | LW19: =LW18 -> 2 | LX19: =LX18 -> 1 | LY19: =LY18 -> 0 | LZ19: =LZ18 -> 13 | ... OV19: =OV18 -> 0 | OZ19: =OZ18 -> 1 | PA19: =PA18 -> 1 | PB19: =PB18 -> 1 | PC19: =PC18 -> 0 | PD19: =PD18 -> 1 | PE19: =PE18 -> 0 | PF19: =PF18 -> 0 | PG19: =PG18 -> 1 | ... RN19: =RN18 -> 0 | RU19: =RU18 -> 4 | RV19: =RV18 -> 11 | RW19: =RW18 -> 0 | RX19: =RX18 -> 1 | RY19: =RY18 -> 0 | RZ19: =RZ18 -> 0 | SA19: =SA18 -> 1 | SB19: =SB18 -> 1 | ... SP19: =SP18 -> 5
A20: خلاصة محافظة النجف الاشرف الصناعي | F20: =F19+F15+F12 -> 6 | G20: =G19+G15+G12 -> 2 | H20: =H19+H15+H12 -> 0 | I20: =I19+I15+I12 -> 8 | J20: =J19+J15+J12 -> 0 | K20: =K19+K15+K12 -> 7 | L20: =L19+L15+L12 -> 0 | M20: =M19+M15+M12 -> 0 | ... GB20: =GB19+GB15+GB12 -> 0 | GE20: =GE19+GE15+GE12 -> 0 | GF20: =GF19+GF15+GF12 -> 0 | GG20: =GG19+GG15+GG12 -> 30 | GH20: =GH19+GH15+GH12 -> 15 | GI20: =GI19+GI15+GI12 -> 45 | GJ20: =GJ19+GJ15+GJ12 -> 6 | GK20: =GK19+GK15+GK12 -> 16 | GL20: =GL19+GL15+GL12 -> 6 | ... LP20: =LP19+LP15+LP12 -> 2 | LQ20: =LA20+LC20+KY20+LE20+LG20+LI20+LK20+LM20+LO20 -> 197 | LR20: =LB20+LD20+KZ20+LF20+LH20+LJ20+LL20+LN20+LP20 -> 203 | LS20: =LS19+LS15+LS12 -> 400 | LT20: =LT19+LT15+LT12 -> 39 | LU20: =LU19+LU15+LU12 -> 57 | LV20: =LV19+LV15+LV12 -> 25 | LW20: =LW19+LW15+LW12 -> 14 | LX20: =LX19+LX15+LX12 -> 25 | LY20: =LY19+LY15+LY12 -> 18 | LZ20: =LZ19+LZ15+LZ12 -> 108 | ... OV20: =OV19+OV15+OV12 -> 0 | OZ20: =OZ19+OZ15+OZ12 -> 3 | PA20: =PA19+PA15+PA12 -> 4 | PB20: =PB19+PB15+PB12 -> 1 | PC20: =PC19+PC15+PC12 -> 3 | PD20: =PD19+PD15+PD12 -> 3 | PE20: =PE19+PE15+PE12 -> 0 | PF20: =PF19+PF15+PF12 -> 0 | PG20: =PG19+PG15+PG12 -> 1 | ... RN20: =RN19+RN15+RN12 -> 0 | RU20: =RU19+RU15+RU12 -> 100 | RV20: =RV19+RV15+RV12 -> 51 | RW20: =RW19+RW15+RW12 -> 17 | RX20: =RX19+RX15+RX12 -> 5 | RY20: =RY19+RY15+RY12 -> 4 | RZ20: =RZ19+RZ15+RZ12 -> 4 | SA20: =SA19+SA15+SA12 -> 3 | SB20: =SB19+SB15+SB12 -> 5 | ... SP20: =SP19+SP15+SP12 -> 26
A21: النجف | B21: المركز | C21: 8 | D21: 1401081 | E21: اعدادية النجف التجارية للبنين | F21: 1 | I21: 1 | L21: 1 | P21: 1 | S21: 1 | X21: 40 | Z21: 100 | AB21: 44 | AD21: 14 | AF21: =AD21+AB21+Z21+X21+V21 -> 198 | AG21: =AE21+AC21+AA21+Y21+W21 -> 0 | AH21: =AG21+AF21 -> 198 | AK21: 40 | AM21: 100 | AO21: 44 | AQ21: 14 | AS21: =AQ21+AO21+AM21+AK21+AI21 -> 198 | AT21: =AR21+AP21+AN21+AL21+AJ21 -> 0 | AU21: =AT21+AS21 -> 198 | AX21: 20 | AZ21: 34 | BB21: 36 | BF21: =BD21+BB21+AZ21+AX21+AV21 -> 90 | BG21: =BE21+BC21+BA21+AY21+AW21 -> 0 | BH21: =BG21+BF21 -> 90 | BI21: 10 | BK21: 10 | BM21: 28 | BO21: 19 | BQ21: 22 | BS21: =BQ21+BO21+BM21+BK21+BI21 -> 89 | BT21: =BR21+BP21+BN21+BL21+BJ21 -> 0 | BU21: =BT21+BS21 -> 89 | BV21: =AI21 -> 0 | BW21: =AJ21 -> 0 | BX21: =AV21+AK21 -> 40 | BY21: =AL21+AW21 -> 0 | BZ21: =BI21+AX21+AM21 -> 130 | CA21: =AN21+AY21+BJ21 -> 0 | CB21: =BK21+AZ21+AO21 -> 88 | CC21: =AP21+BA21+BL21 -> 0 | CD21: =BM21+BB21+AQ21 -> 78 | CE21: =BN21+BC21+AR21 -> 0 | CF21: =BO21+BD21 -> 19 | CG21: =BP21+BE21 -> 0 | CH21: =BQ21 -> 22 | CI21: =BR21 -> 0 | CJ21: =BV21+BX21+BZ21+CB21+CD21+CF21+CH21 -> 377 | CK21: =BW21+BY21+CA21+CC21+CE21+CG21+CI21 -> 0 | CL21: =SUM(CJ21:CK21) -> 377 | CM21: 5 | CP21: 4 | CS21: 3 | CV21: =CS21+CP21+CM21 -> 12 | CW21: =CT21+CQ21+CN21 -> 0 | CX21: =CU21+CR21+CO21 -> 0 | CY21: =CX21+CW21+CV21 -> 12 | CZ21: 4 | DB21: 2 | DD21: 8 | DF21: =DD21+DB21+CZ21 -> 14 | DG21: =DE21+DC21+DA21 -> 0 | DH21: =DG21+DF21 -> 14 | DO21: =DM21+DK21+DI21 -> 0 | DP21: =DN21+DL21+DJ21 -> 0 | DQ21: =DP21+DO21 -> 0 | DR21: 86 | DT21: 28 | DV21: 102 | DX21: =DV21+DT21+DR21 -> 216 | DY21: =DW21+DU21+DS21 -> 0 | DZ21: =DY21+DX21 -> 216 | EA21: 14 | EE21: 26 | EG21: =EE21+EC21+EA21 -> 40 | EH21: =EF21+ED21+EB21 -> 0 | EI21: =EH21+EG21 -> 40 | EJ21: 4 | EL21: 2 | EP21: =EN21+EL21+EJ21 -> 6 | EQ21: =EO21+EM21+EK21 -> 0 | ER21: =EQ21+EP21 -> 6 | EY21: =EY20+EY16+EY13 -> 29 | EZ21: =EX21+EV21+ET21 -> 0 | FA21: =EZ21+EY21 -> 29 | FB21: 1 | FD21: 1 | FE21: 1 | FF21: 17 | FG21: 5 | FH21: 1 | FL21: =FJ21+FH21+FF21+FD21+FB21 -> 20 | FM21: =FK21+FI21+FG21+FE21+FC21 -> 6 | FN21: =FM21+FL21 -> 26 | FR21: 1 | FW21: 1 | GG21: =GE21+GA21+FY21+FW21+FU21+FS21+FO21+FQ21+GC21 -> 1 | GH21: =GF21+GB21+FZ21+FX21+FV21+FT21+FP21+FR21+GD21 -> 1 | GI21: =GH21+GG21 -> 2 | GJ21: 1 | GM21: 1 | GN21: 2 | GR21: 1 | HB21: 1 | HF21: 1 | JL21: 2 | JN21: 3 | JP21: 3 | JQ21: 1 | JT21: 5 | JU21: 1 | KI21: 1 | KN21: 1 | KO21: 2 | KV21: =KT21+KN21+KJ21+KH21+KF21+KD21+KB21+JZ21+JX21+JV21+JT21+JR21+JP21+JN21+JL21+JJ21+JH21+JF21+JD21+JB21+IZ21+IX21+IV21+IT21+IR21+IP21+IN21+IL21+IJ21+IH21+IF21+ID21+IB21+HZ21+HX21+HV21+HT21+HR21+HP21+HN21+HL21+HJ21+HH21+HF21+HD21+HB21+GZ21+GX21+GV21+GT21+GR21+GP21+GN21+GL21+GJ21 -> 20 | KW21: =KU21+KO21+KK21+KI21+KG21+KE21+KC21+KA21+JY21+JW21+JU21+JS21+JQ21+JO21+JM21+JK21+JI21+JG21+JE21+JC21+JA21+IY21+IW21+IU21+IS21+IQ21+IO21+IM21+IK21+II21+IG21+IE21+IC21+IA21+HY21+HW21+HU21+HS21+HQ21+HO21+HM21+HK21+HI21+HG21+HE21+HC21+HA21+GY21+GW21+GU21+GS21+GQ21+GO21+GM21+GK21 -> 6 | KX21: =KW21+KV21 -> 26 | KY21: 14 | KZ21: 4 | LD21: 1 | LG21: 2 | LI21: 1 | LJ21: 1 | LO21: 3 | LQ21: =LA21+LC21+KY21+LE21+LG21+LI21+LK21+LM21+LO21 -> 20 | LR21: =LB21+LD21+KZ21+LF21+LH21+LJ21+LL21+LN21+LP21 -> 6 | LS21: =LR21+LQ21 -> 26 | LT21: 6 | LU21: 3 | LV21: 4 | LW21: 1 | LX21: 4 | LY21: 1 | LZ21: 6 | MA21: 1 | MB21: =LX21+LV21+LT21+LZ21 -> 20 | MC21: =LY21+LW21+LU21+MA21 -> 6 | MD21: =MC21+MB21 -> 26 | ME21: 5 | MF21: 4 | MG21: 5 | MI21: 3 | MK21: 7 | ML21: 2 | MO21: =MM21+MK21+MI21+MG21+ME21 -> 20 | MP21: =MN21+ML21+MJ21+MH21+MF21 -> 6 | MQ21: =MP21+MO21 -> 26 | MR21: 1 | MS21: 2 | MT21: 19 | MU21: 4 | MZ21: =MX21+MV21+MT21+MR21 -> 20 | NA21: =MY21+MW21+MU21+MS21 -> 6 | NB21: =NA21+MZ21 -> 26 | NC21: 20 | ND21: 6 | NI21: 1 | NK21: 14 | NL21: 5 | NM21: 2 | NN21: 1 | NQ21: 1 | NS21: 2 | NW21: =NU21+NS21+NQ21+NO21+NM21+NK21+NG21+NI21+NE21 -> 20 | NX21: =NV21+NT21+NR21+NP21+NN21+NL21+NH21+NJ21+NF21 -> 6 | NY21: =NX21+NW21 -> 26 | OF21: =OD21+OB21+NZ21 -> 0 | OG21: =OE21+OC21+OA21 -> 0 | OH21: =OG21+OF21 -> 0 | OJ21: 1 | OK21: 1 | OM21: 1 | OP21: 1 | PO21: =PN21+PM21 -> 0 | RS21: 4 | RU21: 1 | RY21: 1 | SB21: 1 | SN21: =SM21+SL21 -> 0 | SQ21: ضيف على ع الفندقة والسياحة | SR21: عباس عبد الحسن عبود | SS21: 7802836052
