Workbook

Sheet الفنون الجميلة
A1: المديرية العامة لتربية في محافظة النجف الاشرف | O1: استقلالية المعهد | Q1: نوع الازدواج | U1: عدد المعاهد الفتح الجديد | X1: عدد الطلبة المستجدين في الصف الاول حسب العمر | AS1: عدد الطلبة المسجلين في الصف الاول حسب العمر والجنس | BN1: عدد الطلبة المسجلين في الصف الثاني حسب العمر والجنس | CG1: عدد الطلبة المسجلين في الصف الثالث حسب العمر والجنس | CX1: عدد الطلبة المسجلين في الصف الرابع حسب العمر والجنس | DM1: عدد الطلبة المسجلين في الصف الخامس حسب العمر والجنس | DZ1: عدد الطلبة المسجلين حسب الصف والجنس ( المجموع الكلي) | EU1: عدد الطلبة المسجلين حسب الاقسام الدراسية | FJ1: عدد الشعب حسب الصف والجنس | GC1: عدد الطلبة التاركين حسب الصف والجنس للعام الدراسي 2025 / 2026 | GP1: عدد الطلبة المشاركين في الامتحانات النهائية و حسب الصف والجنس للعام الدراسي 2015 / 2016 | HC1: عدد الطلبة الناجحين حسب الصف والجنس للعام الدراسي 2024 / 2025 | HP1: عدد الطلبة الراسبين بسبب الفشل في الامتحان و حسب الصف والجنس للعام الدراسي 2024 / 2025 | IC1: عدد الطلبة الراسبين بسبب تجاوز ايام الغياب و حسب الصف والجنس للعام الدراسي 2024 / 2025 | IP1: عدد الطلبة الراسبين لاسباب اخرى و حسب الصف والجنس للعام الدراسي 2024 / 2025 | JC1: اعضاء الهيئة التعليمية و التدريسية حسب العنوان الوظيفي | JP1: عدد الموظفون الاداريون والخدميون حسب العنوان الوظيفي | KM1: عدد اعضاء الهيئة التعليمية حسب الجنسية | KV1: عدد اعضاء الهيئة التعليمية والتدريسية حسب الحالة الوظيفية | LQ1: اعضاء الهيئة التعليمية والتدريسية حسب الشهادة | MJ1: اعضاء الهيئة التعليمية والتدريسية حسب الشهادة | NC1: اعضاء الهيئة التعليمية والتدريسية حسب الشهادة | NV1: اعضاء الهيئة التعليمية والتدريسية حسب الشهادة | OO1: اعضاء الهيئة التعليمية والتدريسية حسب الشهادة | PH1: اعضاء الهيئة التعليمية والتدريسية حسب الشهادة | QA1: اعضاء الهيئة التعليمية والتدريسية حسب الشهادة | QT1: اعضاء الهيئة التعليمية والتدريسية حسب الشهادة | RM1: اعضاء الهيئة التعليمية والتدريسية حسب الشهادة | SF1: اعضاء الهيئة التعليمية والتدريسية حسب الشهادة | SY1: اعضاء الهيئة التعليمية والتدريسية حسب الشهادة | TR1: اعضاء الهيئة التعليمية والتدريسية حسب الشهادة | UK1: اعضاء الهيئة التعليمية والتدريسية حسب الشهادة | VD1: اعضاء الهيئة التعليمية والتدريسية حسب الشهادة | VW1: اعضاء الهيئة التعليمية والتدريسية حسب الشهادة | WP1: اعضاء الهيئة التعليمية والتدريسية حسب الشهادة | XI1: اعضاء الهيئة التعليمية والتدريسية حسب الشهادة | YB1: اعضاء الهيئة التعليمية والتدريسية حسب الشهادة | YU1: اعضاء الهيئة التعليمية والتدريسية حسب الشهادة | ZN1: اعضاء الهيئة التعليمية والتدريسية حسب الشهادة | AAG1: اعضاء الهيئة التعليمية والتدريسية حسب الشهادة | AAZ1: اعضاء الهيئة التعليمية والتدريسية حسب الشهادة | ABS1: اعضاء الهيئة التعليمية والتدريسية حسب الشهادة | ACL1: اعضاء الهيئة التعليمية والتدريسية حسب الشهادة | ADE1: اعضاء الهيئة التعليمية والتدريسية حسب الشهادة | ADX1: اعضاء الهيئة التعليمية والتدريسية حسب الشهادة | AEQ1: اعضاء الهيئة التعليمية والتدريسية حسب الشهادة | AFJ1: اعضاء الهيئة التعليمية والتدريسية حسب الشهادة | AGC1: اعضاء الهيئة التعليمية والتدريسية حسب الشهادة | AGV1: اعضاء الهيئة التعليمية والتدريسية حسب الشهادة | AHO1: اعضاء الهيئة التعليمية والتدريسية حسب الشهادة | AIH1: اعضاء الهيئة التعليمية والتدريسية حسب الشهادة | AJA1: اعضاء الهيئة التعليمية والتدريسية حسب الشهادة | AJT1: عدد الهيئة التدريسية حسب سنوات الخدمة | AKE1: عدد الهيئة التدريسية حسب سنوات العمر | AKR1: عدد اعضاء الهيئة التعليمية والتدريسية حسب الحالة الاجتماعية | ALC1: عدد الهيئة التدريسية المشاركين بدورات | ANV1: هل المعهد مشمول بـ : | ANZ1: عدد الرحلات ذات المقعدين | AOB1: عدد الرحلات ذات المقعد الواحد او الكرسي | AOD1: عدد السبورات
A2: قسم التخطيط التربوي / شعبة الاحصاء | F2: جنس المعهد | I2: بيئة المعهد | K2: دوام المعهد | ALE2: الابنية المدرسية | AOF2: الحاسبات :- | AOL2: المكتبات المدرسية :- | APB2: المختبرات المدرسية :-
A3: معاهد الفنون الجميلة 2026-2025 | KV3: داخل القوة العمل | KX3: خارج قوة العمل | LN3: المجموع الكلي | LQ3: التربية الاسلامية | MJ3: اللغة العربية | NC3: اللغة الانكيزية | NV3: اللغة الكردية | OO3: الرياضيات | PH3: الفيزياء | QA3: الكيمياء | QT3: العلوم | RM3: علوم الحياة | SF3: التاريخ | SY3: الجغرافية | TR3: الاجتماعيات | UK3: الاجتماع | VD3: التربية الرياضية | VW3: التربية الفنية | WP3: الاقتصاد | XI3: علم النفس التربوي | YB3: علوم تربوية ونفسية | YU3: ارشاد تربوي | ZN3: حاسوب | AAG3: الرسم | AAZ3: النحت | ABS3: الكرافيك | ACL3: السيراميك | ADE3: سينما ومسرح | ADX3: الخط | AEQ3: الزخرفة | AFJ3: التصميم | AGC3: الديكور | AGV3: ادارة تربوية | AHO3: الموسيقى | AIH3: اخرى | AJA3: المجموع | ALE3: عدد الابنية المدرسية حسب :- | AMF3: هل تتوفر في البناية مرافق صحية | AML3: هل البناية مزودة بخدمة المجاري | AMN3: نوع المجاري | AMP3: هل ترتبط البناية بشبكة الماء الصالح للشرب | AMR3: مصدر الماء | AMW3: هل هناك سياج حول البناية | AMY3: حالة السياج | ANB3: هل توجد ساحة رياضية | AND3: نوع الساحة الرياضية | ANI3: هل توجد حديقة في المعهد | ANK3: هل توجد قاعة مستقلة للانشطة | AOF3: عدد الحاسبات الالكترونية | AOH3: عدد الطابعات | AOI3: عدد الطابعات غيرالصالحة | AOJ3: عدد الماسحات الضوئية (سكنرات) | AOK3: عدد الماسحات الضوئية (سكنرات) غيرالصالحة | AOL3: هل توجد مكتبة | AON3: المسؤول المكتبة | AOS3: نوعية المكتبة | AOW3: عدد الكتب | AOY3: عدد الكتب الكلي | AOZ3: هل يوجد مختبر :-
X4: 15 سنة | Z4: 16 سنة | AB4: 17 سنة | AD4: 18 سنة | AF4: 19 سنة | AH4: 20 سنة | AJ4: 21 سنة | AL4: 22 سنة | AN4: 23 سنة | AP4: المجموع | AS4: 15 سنة | AU4: 16 سنة | AW4: 17 سنة | AY4: 18 سنة | BA4: 19 سنة | BC4: 20 سنة | BE4: 21 سنة | BG4: 22 سنة | BI4: 23 سنة | BK4: المجموع | BN4: 16 سنة | BP4: 17 سنة | BR4: 18 سنة | BT4: 19 سنة | BV4: 20 سنة | BX4: 21 سنة | BZ4: 22 سنة | CB4: 23 سنة | CD4: المجموع | CG4: 17سنة | CI4: 18سنة | CK4: 19سنة | CM4: 20سنة | CO4: 21سنة | CQ4: 22 سنة | CS4: 23 سنة | CU4: المجموع | CX4: 18سنة | CZ4: 19سنة | DB4: 20سنة | DD4: 21سنة | DF4: 22 سنة | DH4: 23 سنة | DJ4: المجموع | DM4: 19سنة | DO4: 20سنة | DQ4: 21سنة | DS4: 22 سنة | DU4: 23 سنة | DW4: المجموع | DZ4: 16سنة | EB4: 17سنة | ED4: 17سنة | EF4: 18سنة | EH4: 19سنة | EJ4: 20سنة | EL4: 21سنة | EN4: 22سنة | EP4: 23سنة | ER4: المجموع | EU4: الموسيقى | EW4: التشكيلي | EY4: الخط والزخرفة | FA4: السينما | FC4: المسرح | FE4: التصميم | FG4: المجموع | FJ4: الصف الاول | FM4: الصف الثاني | FP4: الصف الثالث | FS4: الصف الرابع | FV4: الصف الخامس | FY4: المجموع | GC4: الصف الاول | GE4: الصف الثاني | GG4: الصف الثالث | GI4: الصف الرابع | GK4: الصف الخامس | GM4: المجموع | GP4: الصف الاول | GR4: الصف الثاني | GT4: الصف الثالث | GV4: الصف الرابع | GX4: الصف الخامس | GZ4: المجموع | HC4: الصف الاول | HE4: الصف الثاني | HG4: الصف الثالث | HI4: الصف الرابع | HK4: الصف الخامس | HM4: المجموع | HP4: الصف الاول | HR4: الصف الثاني | HT4: الصف الثالث | HV4: الصف الرابع | HX4: الصف الخامس | HZ4: المجموع | IC4: الصف الاول | IE4: الصف الثاني | IG4: الصف الثالث | II4: الصف الرابع | IK4: الصف الخامس | IM4: المجموع | IP4: الصف الاول | IR4: الصف الثاني | IT4: الصف الثالث | IV4: الصف الرابع | IX4: الصف الخامس | IZ4: المجموع | JC4: مدير | JE4: معاون | JG4: مدرس | JI4: معلم | JK4: مرشد تربوي | JM4: المجموع | JP4: موظف الادارة | JR4: كاتب | JT4: محاسب | JV4: مساعد مختبر | JX4: امين مكتب | JZ4: موظف خدمة | KB4: حارس | KD4: سائق | KF4: حرفي | KH4: فلاح | KJ4: المجموع | KM4: عراقية | KO4: عربية | KQ4: اجنبية | KS4: المجموع | KX4: بعثة او زمالة دراسية | KZ4: اجازة دراسية | LB4: اجازة مصاحبة | LD4: اجازة بدون راتب | LF4: اجازة مرضية طويلة | LH4: اجازة امومة | LJ4: منسب الى جهات اخرى | LL4: 4-5سنوات | LQ4: دبلوم تعليمي | LS4: دبلوم عام | LU4: بكلوريوس عام | LW4: بكلوريوس تعليمي | LY4: دبلوم عالي | MA4: ماجستير | MC4: دكتوراه | ME4: اخرى | MG4: المجموع | MJ4: دبلوم تعليمي | ML4: دبلوم عام | MN4: بكلوريوس عام | MP4: بكلوريوس تعليمي | MR4: دبلوم عالي | MT4: ماجستير | MV4: دكتوراه | MX4: اخرى | MZ4: المجموع | NC4: دبلوم تعليمي | NE4: دبلوم عام | NG4: بكلوريوس عام | NI4: بكلوريوس تعليمي | NK4: دبلوم عالي | NM4: ماجستير | NO4: دكتوراه | NQ4: اخرى | NS4: المجموع | NV4: دبلوم تعليمي | NX4: دبلوم عام | NZ4: بكلوريوس عام | OB4: بكلوريوس تعليمي | OD4: دبلوم عالي | OF4: ماجستير | OH4: دكتوراه | OJ4: اخرى | OL4: المجموع | OO4: دبلوم تعليمي | OQ4: دبلوم عام | OS4: بكلوريوس عام | OU4: بكلوريوس تعليمي | OW4: دبلوم عالي | OY4: ماجستير | PA4: دكتوراه | PC4: اخرى | PE4: المجموع | PH4: دبلوم تعليمي | PJ4: دبلوم عام | PL4: بكلوريوس عام | PN4: بكلوريوس تعليمي | PP4: دبلوم عالي | PR4: ماجستير | PT4: دكتوراه | PV4: اخرى | PX4: المجموع | QA4: دبلوم تعليمي | QC4: دبلوم عام | QE4: بكلوريوس عام | QG4: بكلوريوس تعليمي | QI4: دبلوم عالي | QK4: ماجستير | QM4: دكتوراه | QO4: اخرى | QQ4: المجموع | QT4: دبلوم تعليمي | QV4: دبلوم عام | QX4: بكلوريوس عام | QZ4: بكلوريوس تعليمي | RB4: دبلوم عالي | RD4: ماجستير | RF4: دكتوراه | RH4: اخرى | RJ4: المجموع | RM4: دبلوم تعليمي | RO4: دبلوم عام | RQ4: بكلوريوس عام | RS4: بكلوريوس تعليمي | RU4: دبلوم عالي | RW4: ماجستير | RY4: دكتوراه | SA4: اخرى | SC4: المجموع | SF4: دبلوم تعليمي | SH4: دبلوم عام | SJ4: بكلوريوس عام | SL4: بكلوريوس تعليمي | SN4: دبلوم عالي | SP4: ماجستير | SR4: دكتوراه | ST4: اخرى | SV4: المجموع | SY4: دبلوم تعليمي | TA4: دبلوم عام | TC4: بكلوريوس عام | TE4: بكلوريوس تعليمي | TG4: دبلوم عالي | TI4: ماجستير | TK4: دكتوراه | TM4: اخرى | TO4: المجموع | TR4: دبلوم تعليمي | TT4: دبلوم عام | TV4: بكلوريوس عام | TX4: بكلوريوس تعليمي | TZ4: دبلوم عالي | UB4: ماجستير | UD4: دكتوراه | UF4: اخرى | UH4: المجموع | UK4: دبلوم تعليمي | UM4: دبلوم عام | UO4: بكلوريوس عام | UQ4: بكلوريوس تعليمي | US4: دبلوم عالي | UU4: ماجستير | UW4: دكتوراه | UY4: اخرى | VA4: المجموع | VD4: دبلوم تعليمي | VF4: دبلوم عام | VH4: بكلوريوس عام | VJ4: بكلوريوس تعليمي | VL4: دبلوم عالي | VN4: ماجستير | VP4: دكتوراه | VR4: اخرى | VT4: المجموع | VW4: دبلوم تعليمي | VY4: دبلوم عام | WA4: بكلوريوس عام | WC4: بكلوريوس تعليمي | WE4: دبلوم عالي | WG4: ماجستير | WI4: دكتوراه | WK4: اخرى | WM4: المجموع | WP4: دبلوم تعليمي | WR4: دبلوم عام | WT4: بكلوريوس عام | WV4: بكلوريوس تعليمي | WX4: دبلوم عالي | WZ4: ماجستير | XB4: دكتوراه | XD4: اخرى | XF4: المجموع | XI4: دبلوم تعليمي | XK4: دبلوم عام | XM4: بكلوريوس عام | XO4: بكلوريوس تعليمي | XQ4: دبلوم عالي | XS4: ماجستير | XU4: دكتوراه | XW4: اخرى | XY4: المجموع | YB4: دبلوم تعليمي | YD4: دبلوم عام | YF4: بكلوريوس عام | YH4: بكلوريوس تعليمي | YJ4: دبلوم عالي | YL4: ماجستير | YN4: دكتوراه | YP4: اخرى | YR4: المجموع | YU4: دبلوم تعليمي | YW4: دبلوم عام | YY4: بكلوريوس عام | ZA4: بكلوريوس تعليمي | ZC4: دبلوم عالي | ZE4: ماجستير | ZG4: دكتوراه | ZI4: اخرى | ZK4: المجموع | ZN4: دبلوم تعليمي | ZP4: دبلوم عام | ZR4: بكلوريوس عام | ZT4: بكلوريوس تعليمي | ZV4: دبلوم عالي | ZX4: ماجستير | ZZ4: دكتوراه | AAB4: اخرى | AAD4: المجموع | AAG4: دبلوم تعليمي | AAI4: دبلوم عام | AAK4: بكلوريوس عام | AAM4: بكلوريوس تعليمي | AAO4: دبلوم عالي | AAQ4: ماجستير | AAS4: دكتوراه | AAU4: اخرى | AAW4: المجموع | AAZ4: دبلوم تعليمي | ABB4: دبلوم عام | ABD4: بكلوريوس عام | ABF4: بكلوريوس تعليمي | ABH4: دبلوم عالي | ABJ4: ماجستير | ABL4: دكتوراه | ABN4: اخرى | ABP4: المجموع | ABS4: دبلوم تعليمي | ABU4: دبلوم عام | ABW4: بكلوريوس عام | ABY4: بكلوريوس تعليمي | ACA4: دبلوم عالي | ACC4: ماجستير | ACE4: دكتوراه | ACG4: اخرى | ACI4: المجموع | ACL4: دبلوم تعليمي | ACN4: دبلوم عام | ACP4: بكلوريوس عام | ACR4: بكلوريوس تعليمي | ACT4: دبلوم عالي | ACV4: ماجستير | ACX4: دكتوراه | ACZ4: اخرى | ADB4: المجموع | ADE4: دبلوم تعليمي | ADG4: دبلوم عام | ADI4: بكلوريوس عام | ADK4: بكلوريوس تعليمي | ADM4: دبلوم عالي | ADO4: ماجستير | ADQ4: دكتوراه | ADS4: اخرى | ADU4: المجموع | ADX4: دبلوم تعليمي | ADZ4: دبلوم عام | AEB4: بكلوريوس عام | AED4: بكلوريوس تعليمي | AEF4: دبلوم عالي | AEH4: ماجستير | AEJ4: دكتوراه | AEL4: اخرى | AEN4: المجموع | AEQ4: دبلوم تعليمي | AES4: دبلوم عام | AEU4: بكلوريوس عام | AEW4: بكلوريوس تعليمي | AEY4: دبلوم عالي | AFA4: ماجستير | AFC4: دكتوراه | AFE4: اخرى | AFG4: المجموع | AFJ4: دبلوم تعليمي | AFL4: دبلوم عام | AFN4: بكلوريوس عام | AFP4: بكلوريوس تعليمي | AFR4: دبلوم عالي | AFT4: ماجستير | AFV4: دكتوراه | AFX4: اخرى | AFZ4: المجموع | AGC4: دبلوم تعليمي | AGE4: دبلوم عام | AGG4: بكلوريوس عام | AGI4: بكلوريوس تعليمي | AGK4: دبلوم عالي | AGM4: ماجستير | AGO4: دكتوراه | AGQ4: اخرى | AGS4: المجموع | AGV4: دبلوم تعليمي | AGX4: دبلوم عام | AGZ4: بكلوريوس عام | AHB4: بكلوريوس تعليمي | AHD4: دبلوم عالي | AHF4: ماجستير | AHH4: دكتوراه | AHJ4: اخرى | AHL4: المجموع | AHO4: دبلوم تعليمي | AHQ4: دبلوم عام | AHS4: بكلوريوس عام | AHU4: بكلوريوس تعليمي | AHW4: دبلوم عالي | AHY4: ماجستير | AIA4: دكتوراه | AIC4: اخرى | AIE4: المجموع | AIH4: دبلوم تعليمي | AIJ4: دبلوم عام | AIL4: بكلوريوس عام | AIN4: بكلوريوس تعليمي | AIP4: دبلوم عالي | AIR4: ماجستير | AIT4: دكتوراه | AIV4: اخرى | AIX4: المجموع | AJA4: دبلوم تعليمي | AJC4: دبلوم عام | AJE4: بكلوريوس تعليمي | AJG4: بكلوريوس عام | AJI4: دبلوم عالي | AJK4: ماجستير | AJM4: دكتوراه | AJO4: اخرى | AJQ4: المجموع | AJT4: 5سنوات فاقل | AJV4: 6ــ 10 | AJX4: 11ــ15 | AJZ4: 16فاكثر | AKB4: المجموع الكلي | AKE4: 30فاقل | AKG4: 30ــ 39 | AKI4: 40ــ49 | AKK4: 50ــ 59 | AKM4: 60فأكثر | AKO4: المجموع الكلي | AKR4: اعزب | AKT4: متزوج | AKV4: ارمل | AKX4: مطلق | AKZ4: المجموع | ALE4: نوع البتاء | ALH4: البناية | ALJ4: هل توجد مساحة للتوسعة | ALL4: عدد الطوابق | ALO4: هل المدرسة بحاجة الى صفوف | ALR4: عدد الصفوف في البناية | ALU4: حجم المعهد | ALZ4: مادة البناء | ANM4: العائدية | ANP4: عدد المدارس التي تشغلها | ANS4: الحالة العمرانية | AOZ4: هل يوجد مختبر | APB4: العلوم مستقل | APD4: الفيزياء مستقل | APF4: الكيمياء مستقل | APH4: الاحياء مستقل | APJ4: مجمع المختبرات | APL4: لغة مستقل | APN4: حاسوب مستقل
A5: القضاء | B5: الناحية | C5: ت | D5: الرقم الاحصائي | E5: اسم المعهد | F5: بنون | G5: بنات | H5: مختلط | I5: حضر | J5: ريف | K5: صباحا | L5: ظهرا | M5: صباحا وظهرا | N5: مساءا | O5: اصلية | P5: ضيف | Q5: غير مزدوجة | R5: مع نفسها | S5: مع اخرى | T5: مع نفسها ومع اخرى | U5: بنون | V5: بنات | W5: مختلط | X5: بنون | Y5: بنات | Z5: بنون | AA5: بنات | AB5: بنون | AC5: بنات | AD5: بنون | AE5: بنات | AF5: بنون | AG5: بنات | AH5: بنون | AI5: بنات | AJ5: بنون | AK5: بنات | AL5: بنون | AM5: بنات | AN5: بنون | AO5: بنات | AP5: بنون | AQ5: بنات | AR5: المجموع | AS5: بنون | AT5: بنات | AU5: بنون | AV5: بنات | AW5: بنون | AX5: بنات | AY5: بنون | AZ5: بنات | BA5: بنون | BB5: بنات | BC5: بنون | BD5: بنات | BE5: بنون | BF5: بنات | BG5: بنون | BH5: بنات | BI5: بنون | BJ5: بنات | BK5: بنون | BL5: بنات | BM5: المجموع | BN5: بنون | BO5: بنات | BP5: بنون | BQ5: بنات | BR5: بنون | BS5: بنات | BT5: بنون | BU5: بنات | BV5: بنون | BW5: بنات | BX5: بنون | BY5: بنات | BZ5: بنون | CA5: بنات | CB5: بنون | CC5: بنات | CD5: بنون | CE5: بنات | CF5: المجموع | CG5: بنون | CH5: بنات | CI5: بنون | CJ5: بنات | CK5: بنون | CL5: بنات | CM5: بنون | CN5: بنات | CO5: بنون | CP5: بنات | CQ5: بنون | CR5: بنات | CS5: بنون | CT5: بنات | CU5: بنون | CV5: بنات | CW5: المجموع | CX5: بنون | CY5: بنات | CZ5: بنون | DA5: بنات | DB5: بنون | DC5: بنات | DD5: بنون | DE5: بنات | DF5: بنون | DG5: بنات | DH5: بنون | DI5: بنات | DJ5: بنون | DK5: بنات | DL5: المجموع | DM5: بنون | DN5: بنات | DO5: بنون | DP5: بنات | DQ5: بنون | DR5: بنات | DS5: بنون | DT5: بنات | DU5: بنون | DV5: بنات | DW5: بنون | DX5: بنات | DY5: المجموع | DZ5: بنون | EA5: بنات | EB5: بنون | EC5: بنات | ED5: بنون | EE5: بنات | EF5: بنون | EG5: بنات | EH5: بنون | EI5: بنات | EJ5: بنون | EK5: بنات | EL5: بنون | EM5: بنات | EN5: بنون | EO5: بنات | EP5: بنون | EQ5: بنات | ER5: بنون | ES5: بنات | ET5: المجموع | EU5: بنون | EV5: بنات | EW5: بنون | EX5: بنات | EY5: بنون | EZ5: بنات | FA5: بنون | FB5: بنات | FC5: بنون | FD5: بنات | FE5: بنون | FF5: بنات | FG5: بنون | FH5: بنات | FI5: المجموع | FJ5: بنون | FK5: بنات | FL5: مختلطة | FM5: بنون | FN5: بنات | FO5: مختلطة | FP5: بنون | FQ5: بنات | FR5: مختلطة | FS5: بنون | FT5: بنات | FU5: مختلطة | FV5: بنون | FW5: بنات | FX5: مختلطة | FY5: بنون | FZ5: بنات | GA5: مختلطة | GB5: المجموع | GC5: بنون | GD5: بنات | GE5: بنون | GF5: بنات | GG5: بنون | GH5: بنات | GI5: بنون | GJ5: بنات | GK5: بنون | GL5: بنات | GM5: بنون | GN5: بنات | GO5: المجموع | GP5: بنون | GQ5: بنات | GR5: بنون | GS5: بنات | GT5: بنون | GU5: بنات | GV5: بنون | GW5: بنات | GX5: بنون | GY5: بنات | GZ5: بنون | HA5: بنات | HB5: المجموع | HC5: بنون | HD5: بنات | HE5: بنون | HF5: بنات | HG5: بنون | HH5: بنات | HI5: بنون | HJ5: بنات | HK5: بنون | HL5: بنات | HM5: بنون | HN5: بنات | HO5: المجموع | HP5: بنون | HQ5: بنات | HR5: بنون | HS5: بنات | HT5: بنون | HU5: بنات | HV5: بنون | HW5: بنات | HX5: بنون | HY5: بنات | HZ5: بنون | IA5: بنات | IB5: المجموع | IC5: بنون | ID5: بنات | IE5: بنون | IF5: بنات | IG5: بنون | IH5: بنات | II5: بنون | IJ5: بنات | IK5: بنون | IL5: بنات | IM5: بنون | IN5: بنات | IO5: المجموع | IP5: بنون | IQ5: بنات | IR5: بنون | IS5: بنات | IT5: بنون | IU5: بنات | IV5: بنون | IW5: بنات | IX5: بنون | IY5: بنات | IZ5: بنون | JA5: بنات | JB5: المجموع | JC5: ذكور | JD5: اناث | JE5: ذكور | JF5: اناث | JG5: ذكور | JH5: اناث | JI5: ذكور | JJ5: اناث | JK5: ذكور | JL5: اناث | JM5: ذكور | JN5: اناث | JO5: المجموع | JP5: ذكور | JQ5: اناث | JR5: ذكور | JS5: اناث | JT5: ذكور | JU5: اناث | JV5: ذكور | JW5: اناث | JX5: ذكور | JY5: اناث | JZ5: ذكور | KA5: اناث | KB5: ذكور | KC5: اناث | KD5: ذكور | KE5: اناث | KF5: ذكور | KG5: اناث | KH5: ذكور | KI5: اناث | KJ5: ذكور | KK5: اناث | KL5: المجموع | KM5: ذكور | KN5: اناث | KO5: ذكور | KP5: اناث | KQ5: ذكور | KR5: اناث | KS5: ذكور | KT5: اناث | KU5: المجموع | KV5: ذكور | KW5: اناث | KX5: ذكور | KY5: اناث | KZ5: ذكور | LA5: اناث | LB5: ذكور | LC5: اناث | LD5: ذكور | LE5: اناث | LF5: ذكور | LG5: اناث | LH5: ذكور | LI5: اناث | LJ5: ذكور | LK5: اناث | LL5: ذكور | LM5: اناث | LN5: ذكور | LO5: اناث | LP5: المجموع | LQ5: ذكور | LR5: اناث | LS5: ذكور | LT5: اناث | LU5: ذكور | LV5: اناث | LW5: ذكور | LX5: اناث | LY5: ذكور | LZ5: اناث | MA5: ذكور | MB5: اناث | MC5: ذكور | MD5: اناث | ME5: ذكور | MF5: اناث | MG5: ذكور | MH5: اناث | MI5: المجموع | MJ5: ذكور | MK5: اناث | ML5: ذكور | MM5: اناث | MN5: ذكور | MO5: اناث | MP5: ذكور | MQ5: اناث | MR5: ذكور | MS5: اناث | MT5: ذكور | MU5: اناث | MV5: ذكور | MW5: اناث | MX5: ذكور | MY5: اناث | MZ5: ذكور | NA5: اناث | NB5: المجموع | NC5: ذكور | ND5: اناث | NE5: ذكور | NF5: اناث | NG5: ذكور | NH5: اناث | NI5: ذكور | NJ5: اناث | NK5: ذكور | NL5: اناث | NM5: ذكور | NN5: اناث | NO5: ذكور | NP5: اناث | NQ5: ذكور | NR5: اناث | NS5: ذكور | NT5: اناث | NU5: المجموع | NV5: ذكور | NW5: اناث | NX5: ذكور | NY5: اناث | NZ5: ذكور | OA5: اناث | OB5: ذكور | OC5: اناث | OD5: ذكور | OE5: اناث | OF5: ذكور | OG5: اناث | OH5: ذكور | OI5: اناث | OJ5: ذكور | OK5: اناث | OL5: ذكور | OM5: اناث | ON5: المجموع | OO5: ذكور | OP5: اناث | OQ5: ذكور | OR5: اناث | OS5: ذكور | OT5: اناث | OU5: ذكور | OV5: اناث | OW5: ذكور | OX5: اناث | OY5: ذكور | OZ5: اناث | PA5: ذكور | PB5: اناث | PC5: ذكور | PD5: اناث | PE5: ذكور | PF5: اناث | PG5: المجموع | PH5: ذكور | PI5: اناث | PJ5: ذكور | PK5: اناث | PL5: ذكور | PM5: اناث | PN5: ذكور | PO5: اناث | PP5: ذكور | PQ5: اناث | PR5: ذكور | PS5: اناث | PT5: ذكور | PU5: اناث | PV5: ذكور | PW5: اناث | PX5: ذكور | PY5: اناث | PZ5: المجموع | QA5: ذكور | QB5: اناث | QC5: ذكور | QD5: اناث | QE5: ذكور | QF5: اناث | QG5: ذكور | QH5: اناث | QI5: ذكور | QJ5: اناث | QK5: ذكور | QL5: اناث | QM5: ذكور | QN5: اناث | QO5: ذكور | QP5: اناث | QQ5: ذكور | QR5: اناث | QS5: المجموع | QT5: ذكور | QU5: اناث | QV5: ذكور | QW5: اناث | QX5: ذكور | QY5: اناث | QZ5: ذكور | RA5: اناث | RB5: ذكور | RC5: اناث | RD5: ذكور | RE5: اناث | RF5: ذكور | RG5: اناث | RH5: ذكور | RI5: اناث | RJ5: ذكور | RK5: اناث | RL5: المجموع | RM5: ذكور | RN5: اناث | RO5: ذكور | RP5: اناث | RQ5: ذكور | RR5: اناث | RS5: ذكور | RT5: اناث | RU5: ذكور | RV5: اناث | RW5: ذكور | RX5: اناث | RY5: ذكور | RZ5: اناث | SA5: ذكور | SB5: اناث | SC5: ذكور | SD5: اناث | SE5: المجموع | SF5: ذكور | SG5: اناث | SH5: ذكور | SI5: اناث | SJ5: ذكور | SK5: اناث | SL5: ذكور | SM5: اناث | SN5: ذكور | SO5: اناث | SP5: ذكور | SQ5: اناث | SR5: ذكور | SS5: اناث | ST5: ذكور | SU5: اناث | SV5: ذكور | SW5: اناث | SX5: المجموع | SY5: ذكور | SZ5: اناث | TA5: ذكور | TB5: اناث | TC5: ذكور | TD5: اناث | TE5: ذكور | TF5: اناث | TG5: ذكور | TH5: اناث | TI5: ذكور | TJ5: اناث | TK5: ذكور | TL5: اناث | TM5: ذكور | TN5: اناث | TO5: ذكور | TP5: اناث | TQ5: المجموع | TR5: ذكور | TS5: اناث | TT5: ذكور | TU5: اناث | TV5: ذكور | TW5: اناث | TX5: ذكور | TY5: اناث | TZ5: ذكور | UA5: اناث | UB5: ذكور | UC5: اناث | UD5: ذكور | UE5: اناث | UF5: ذكور | UG5: اناث | UH5: ذكور | UI5: اناث | UJ5: المجموع | UK5: ذكور | UL5: اناث | UM5: ذكور | UN5: اناث | UO5: ذكور | UP5: اناث | UQ5: ذكور | UR5: اناث | US5: ذكور | UT5: اناث | UU5: ذكور | UV5: اناث | UW5: ذكور | UX5: اناث | UY5: ذكور | UZ5: اناث | VA5: ذكور | VB5: اناث | VC5: المجموع | VD5: ذكور | VE5: اناث | VF5: ذكور | VG5: اناث | VH5: ذكور | VI5: اناث | VJ5: ذكور | VK5: اناث | VL5: ذكور | VM5: اناث | VN5: ذكور | VO5: اناث | VP5: ذكور | VQ5: اناث | VR5: ذكور | VS5: اناث | VT5: ذكور | VU5: اناث | VV5: المجموع | VW5: ذكور | VX5: اناث | VY5: ذكور | VZ5: اناث | WA5: ذكور | WB5: اناث | WC5: ذكور | WD5: اناث | WE5: ذكور | WF5: اناث | WG5: ذكور | WH5: اناث | WI5: ذكور | WJ5: اناث | WK5: ذكور | WL5: اناث | WM5: ذكور | WN5: اناث | WO5: المجموع | WP5: ذكور | WQ5: اناث | WR5: ذكور | WS5: اناث | WT5: ذكور | WU5: اناث | WV5: ذكور | WW5: اناث | WX5: ذكور | WY5: اناث | WZ5: ذكور | XA5: اناث | XB5: ذكور | XC5: اناث | XD5: ذكور | XE5: اناث | XF5: ذكور | XG5: اناث | XH5: المجموع | XI5: ذكور | XJ5: اناث | XK5: ذكور | XL5: اناث | XM5: ذكور | XN5: اناث | XO5: ذكور | XP5: اناث | XQ5: ذكور | XR5: اناث | XS5: ذكور | XT5: اناث | XU5: ذكور | XV5: اناث | XW5: ذكور | XX5: اناث | XY5: ذكور | XZ5: اناث | YA5: المجموع | YB5: ذكور | YC5: اناث | YD5: ذكور | YE5: اناث | YF5: ذكور | YG5: اناث | YH5: ذكور | YI5: اناث | YJ5: ذكور | YK5: اناث | YL5: ذكور | YM5: اناث | YN5: ذكور | YO5: اناث | YP5: ذكور | YQ5: اناث | YR5: ذكور | YS5: اناث | YT5: المجموع | YU5: ذكور | YV5: اناث | YW5: ذكور | YX5: اناث | YY5: ذكور | YZ5: اناث | ZA5: ذكور | ZB5: اناث | ZC5: ذكور | ZD5: اناث | ZE5: ذكور | ZF5: اناث | ZG5: ذكور | ZH5: اناث | ZI5: ذكور | ZJ5: اناث | ZK5: ذكور | ZL5: اناث | ZM5: المجموع | ZN5: ذكور | ZO5: اناث | ZP5: ذكور | ZQ5: اناث | ZR5: ذكور | ZS5: اناث | ZT5: ذكور | ZU5: اناث | ZV5: ذكور | ZW5: اناث | ZX5: ذكور | ZY5: اناث | ZZ5: ذكور | AAA5: اناث | AAB5: ذكور | AAC5: اناث | AAD5: ذكور | AAE5: اناث | AAF5: المجموع | AAG5: ذكور | AAH5: اناث | AAI5: ذكور | AAJ5: اناث | AAK5: ذكور | AAL5: اناث | AAM5: ذكور | AAN5: اناث | AAO5: ذكور | AAP5: اناث | AAQ5: ذكور | AAR5: اناث | AAS5: ذكور | AAT5: اناث | AAU5: ذكور | AAV5: اناث | AAW5: ذكور | AAX5: اناث | AAY5: المجموع | AAZ5: ذكور | ABA5: اناث | ABB5: ذكور | ABC5: اناث | ABD5: ذكور | ABE5: اناث | ABF5: ذكور | ABG5: اناث | ABH5: ذكور | ABI5: اناث | ABJ5: ذكور | ABK5: اناث | ABL5: ذكور | ABM5: اناث | ABN5: ذكور | ABO5: اناث | ABP5: ذكور | ABQ5: اناث | ABR5: المجموع | ABS5: ذكور | ABT5: اناث | ABU5: ذكور | ABV5: اناث | ABW5: ذكور | ABX5: اناث | ABY5: ذكور | ABZ5: اناث | ACA5: ذكور | ACB5: اناث | ACC5: ذكور | ACD5: اناث | ACE5: ذكور | ACF5: اناث | ACG5: ذكور | ACH5: اناث | ACI5: ذكور | ACJ5: اناث | ACK5: المجموع | ACL5: ذكور | ACM5: اناث | ACN5: ذكور | ACO5: اناث | ACP5: ذكور | ACQ5: اناث | ACR5: ذكور | ACS5: اناث | ACT5: ذكور | ACU5: اناث | ACV5: ذكور | ACW5: اناث | ACX5: ذكور | ACY5: اناث | ACZ5: ذكور | ADA5: اناث | ADB5: ذكور | ADC5: اناث | ADD5: المجموع | ADE5: ذكور | ADF5: اناث | ADG5: ذكور | ADH5: اناث | ADI5: ذكور | ADJ5: اناث | ADK5: ذكور | ADL5: اناث | ADM5: ذكور | ADN5: اناث | ADO5: ذكور | ADP5: اناث | ADQ5: ذكور | ADR5: اناث | ADS5: ذكور | ADT5: اناث | ADU5: ذكور | ADV5: اناث | ADW5: المجموع | ADX5: ذكور | ADY5: اناث | ADZ5: ذكور | AEA5: اناث | AEB5: ذكور | AEC5: اناث | AED5: ذكور | AEE5: اناث | AEF5: ذكور | AEG5: اناث | AEH5: ذكور | AEI5: اناث | AEJ5: ذكور | AEK5: اناث | AEL5: ذكور | AEM5: اناث | AEN5: ذكور | AEO5: اناث | AEP5: المجموع | AEQ5: ذكور | AER5: اناث | AES5: ذكور | AET5: اناث | AEU5: ذكور | AEV5: اناث | AEW5: ذكور | AEX5: اناث | AEY5: ذكور | AEZ5: اناث | AFA5: ذكور | AFB5: اناث | AFC5: ذكور | AFD5: اناث | AFE5: ذكور | AFF5: اناث | AFG5: ذكور | AFH5: اناث | AFI5: المجموع | AFJ5: ذكور | AFK5: اناث | AFL5: ذكور | AFM5: اناث | AFN5: ذكور | AFO5: اناث | AFP5: ذكور | AFQ5: اناث | AFR5: ذكور | AFS5: اناث | AFT5: ذكور | AFU5: اناث | AFV5: ذكور | AFW5: اناث | AFX5: ذكور | AFY5: اناث | AFZ5: ذكور | AGA5: اناث | AGB5: المجموع | AGC5: ذكور | AGD5: اناث | AGE5: ذكور | AGF5: اناث | AGG5: ذكور | AGH5: اناث | AGI5: ذكور | AGJ5: اناث | AGK5: ذكور | AGL5: اناث | AGM5: ذكور | AGN5: اناث | AGO5: ذكور | AGP5: اناث | AGQ5: ذكور | AGR5: اناث | AGS5: ذكور | AGT5: اناث | AGU5: المجموع | AGV5: ذكور | AGW5: اناث | AGX5: ذكور | AGY5: اناث | AGZ5: ذكور | AHA5: اناث | AHB5: ذكور | AHC5: اناث | AHD5: ذكور | AHE5: اناث | AHF5: ذكور | AHG5: اناث | AHH5: ذكور | AHI5: اناث | AHJ5: ذكور | AHK5: اناث | AHL5: ذكور | AHM5: اناث | AHN5: المجموع | AHO5: ذكور | AHP5: اناث | AHQ5: ذكور | AHR5: اناث | AHS5: ذكور | AHT5: اناث | AHU5: ذكور | AHV5: اناث | AHW5: ذكور | AHX5: اناث | AHY5: ذكور | AHZ5: اناث | AIA5: ذكور | AIB5: اناث | AIC5: ذكور | AID5: اناث | AIE5: ذكور | AIF5: اناث | AIG5: المجموع | AIH5: ذكور | AII5: اناث | AIJ5: ذكور | AIK5: اناث | AIL5: ذكور | AIM5: اناث | AIN5: ذكور | AIO5: اناث | AIP5: ذكور | AIQ5: اناث | AIR5: ذكور | AIS5: اناث | AIT5: ذكور | AIU5: اناث | AIV5: ذكور | AIW5: اناث | AIX5: ذكور | AIY5: اناث | AIZ5: المجموع | AJA5: ذكور | AJB5: اناث | AJC5: ذكور | AJD5: اناث | AJE5: ذكور | AJF5: اناث | AJG5: ذكور | AJH5: اناث | AJI5: ذكور | AJJ5: اناث | AJK5: ذكور | AJL5: اناث | AJM5: ذكور | AJN5: اناث | AJO5: ذكور | AJP5: اناث | AJQ5: ذكور | AJR5: اناث | AJS5: المجموع | AJT5: ذكور | AJU5: اناث | AJV5: ذكور | AJW5: اناث | AJX5: ذكور | AJY5: اناث | AJZ5: ذكور | AKA5: اناث | AKB5: ذكور | AKC5: اناث | AKD5: المجموع | AKE5: ذكور | AKF5: اناث | AKG5: ذكور | AKH5: اناث | AKI5: ذكور | AKJ5: اناث | AKK5: ذكور | AKL5: اناث | AKM5: ذكور | AKN5: اناث | AKO5: ذكور | AKP5: اناث | AKQ5: المجموع | AKR5: ذكور | AKS5: اناث | AKT5: ذكور | AKU5: اناث | AKV5: ذكور | AKW5: اناث | AKX5: ذكور | AKY5: اناث | AKZ5: ذكور | ALA5: اناث | ALB5: المجموع الكلي | ALC5: ذكور | ALD5: اناث | ALE5: مدرسي | ALF5: غير مدرسي | ALG5: سنة البناء | ALH5: رقم القطعة | ALI5: رقم المقاطعة | ALJ5: نعم | ALK5: كلا | ALL5: طابق واحد | ALM5: طابقين | ALN5: ثلاث طوابق | ALO5: نعم | ALP5: كلا | ALQ5: عدد الصفوف الاضافية | ALR5: عدد الصفوف | ALS5: عدد الغرف في البناية | ALT5: المجموع | ALU5: 6صف | ALV5: 9صف | ALW5: 12صف | ALX5: 18صف | ALY5: 24صف | ALZ5: طابوق او حجر او بلوك | AMA5: طين او صريفة | AMB5: هياكل حديدية | AMC5: بناء جاهز | AMD5: كرفان | AME5: اخرى | AMF5: نعم | AMG5: كلا | AMH5: صالحة | AMI5: غيرصالحة | AMJ5: كافية | AMK5: غيركافية | AML5: نعم | AMM5: كلا | AMN5: شبكة المجاري | AMO5: خزانات | AMP5: نعم | AMQ5: كلا | AMR5: بلدية | AMS5: بئر عميق | AMT5: نهر | AMU5: صهاريج | AMV5: اخرى | AMW5: نعم | AMX5: كلا | AMY5: جيد | AMZ5: متصدع | ANA5: غير امن | ANB5: نعم | ANC5: كلا | AND5: كرة قدم | ANE5: كرة سلة | ANF5: كرة طائرة | ANG5: ساحة رياضية | ANH5: اخرى | ANI5: نعم | ANJ5: كلا | ANK5: نعم | ANL5: كلا | ANM5: حكومية تابعة لوزارة التربية | ANN5: حكومية تابعة لجهات اخرى | ANO5: مستأجرة | ANP5: مدرسة واحدة | ANQ5: مدرستان | ANR5: ثلاث مدارس | ANS5: صالحة | ANT5: بحاجة الى ترميم | ANU5: غير صالحة | ANV5: الارشاد التربوي | ANW5: تدريس الحاسوب | ANX5: تدريس اللغات الاجنبية والمحلية | ANY5: التغذية المدرسية | ANZ5: صالح | AOA5: غير صالح | AOB5: صالح | AOC5: غير صالح | AOD5: صالح | AOE5: غير صالح | AOF5: صالحة | AOG5: غير صالحة | AOH5: صالحة | AOI5: غير صالحة | AOJ5: صالحة | AOK5: غير صالحة | AOL5: نعم | AOM5: كلا | AON5: مدير | AOO5: معاون | AOP5: مدرس او معلم | AOQ5: امين مكتبة | AOR5: كاتب | AOS5: قاعة | AOT5: غرفة | AOU5: خزانة | AOV5: رفوف عارضة | AOW5: الكتب | AOX5: المجلات والقصص | AOZ5: نعم | APA5: كلا | APB5: نعم | APC5: كلا | APD5: نعم | APE5: كلا | APF5: نعم | APG5: كلا | APH5: نعم | API5: كلا | APJ5: نعم | APK5: كلا | APL5: نعم | APM5: كلا | APN5: نعم | APO5: كلا | APP5: اسم المدير | APQ5: رقم الموبايل
A6: النجف | B6: المركز | C6: 1 | D6: 1500953 | E6: معهد الفنون الجميلة للبنين | F6: 1 | I6: 1 | K6: 1 | O6: 1 | Q6: 1 | X6: 1 | Z6: 47 | AB6: 45 | AD6: 13 | AF6: 5 | AH6: 4 | AP6: =AN6+AL6+AJ6+AH6+AF6+AD6+AB6+Z6+X6 -> 115 | AQ6: =AO6+AM6+AK6+AI6+AG6+AE6+AC6+AA6+Y6 -> 0 | AR6: =AQ6+AP6 -> 115 | AS6: 1 | AU6: 47 | AW6: 45 | AY6: 13 | BA6: 5 | BC6: 4 | BK6: =BI6+BG6+BE6+BC6+BA6+AY6+AW6+AU6+AS6 -> 115 | BL6: =BJ6+BH6+BF6+BD6+BB6+AZ6+AX6+AV6+AT6 -> 0 | BM6: =BL6+BK6 -> 115 | BN6: 1 | BP6: 55 | BR6: 41 | BT6: 4 | CD6: =CB6+BZ6+BX6+BV6+BT6+BR6+BP6+BN6 -> 101 | CE6: =CC6+CA6+BY6+BW6+BU6+BS6+BQ6+BO6 -> 0 | CF6: =CE6+CD6 -> 101 | CG6: 4 | CI6: 20 | CK6: 31 | CM6: 22 | CO6: 6 | CQ6: 5 | CS6: 2 | CU6: =CS6+CQ6+CO6+CM6+CK6+CI6+CG6 -> 90 | CV6: =CT6+CR6+CP6+CN6+CL6+CJ6+CH6 -> 0 | CW6: =CV6+CU6 -> 90 | CX6: 3 | CZ6: 15 | DB6: 23 | DD6: 12 | DF6: 14 | DH6: 8 | DJ6: =DH6+DF6+DD6+DB6+CZ6+CX6 -> 75 | DK6: =DI6+DG6+DE6+DC6+DA6+CY6 -> 0 | DL6: =DK6+DJ6 -> 75 | DM6: 2 | DO6: 14 | DQ6: 16 | DS6: 22 | DU6: 15 | DW6: =DU6+DS6+DQ6+DO6+DM6 -> 69 | DX6: =DV6+DT6+DR6+DP6+DN6 -> 0 | DY6: =DX6+DW6 -> 69 | DZ6: =AS6 -> 1 | EA6: =AT6 -> 0 | EB6: =BN6+AU6 -> 48 | EC6: =BO6+AV6 -> 0 | ED6: =CG6+BP6+AW6 -> 104 | EE6: =CH6+BQ6+AX6 -> 0 | EF6: =CX6+CI6+BR6+AY6 -> 77 | EG6: =CY6+CJ6+BS6+AZ6 -> 0 | EH6: =DM6+CZ6+CK6+BT6+BA6 -> 57 | EI6: =DN6+DA6+CL6+BU6+BB6+AG6 -> 0 | EJ6: =DO6+DB6+CM6+BV6+BC6 -> 63 | EK6: =DP6+DC6+CN6+BW6+BD6 -> 0 | EL6: =DQ6+DD6+CO6+BX6+BE6 -> 34 | EM6: =DR6+DE6+CP6+BY6+BF6 -> 0 | EN6: =DS6+DF6+CQ6+BZ6+BG6 -> 41 | EO6: =DT6+DG6+CR6+CA6+BH6 -> 0 | EP6: =DU6+DH6+CS6+CB6+BI6 -> 25 | EQ6: =DV6+DI6+CT6+CC6+BJ6 -> 0 | ER6: =EP6+EN6+EL6+EJ6+EH6+EF6+ED6+EB6+DZ6 -> 450 | ES6: =EQ6+EO6+EM6+EK6+EI6+EG6+EE6+EC6+EA6 -> 0 | ET6: =ES6+ER6 -> 450 | EW6: 87 | EY6: 101 | FA6: 149 | FC6: 113 | FG6: =FC6+FA6+EY6+EW6+EU6+FE6 -> 450 | FH6: =FD6+FB6+EZ6+EX6+EV6+FF6 -> 0 | FI6: =FH6+FG6 -> 450 | FJ6: 4 | FM6: 4 | FP6: 5 | FS6: 5 | FV6: 5 | FY6: =FV6+FS6+FP6+FM6+FJ6 -> 23 | FZ6: =FW6+FT6+FQ6+FN6+FK6 -> 0 | GA6: =FX6+FU6+FR6+FO6+FL6 -> 0 | GB6: =GA6+FZ6+FY6 -> 23 | GM6: =GK6+GI6+GG6+GE6+GC6 -> 0 | GN6: =GL6+GJ6+GH6+GF6+GD6 -> 0 | GO6: =GN6+GM6 -> 0 | GZ6: =GX6+GV6+GT6+GR6+GP6 -> 0 | HA6: =GY6+GW6+GU6+GS6+GQ6 -> 0 | HB6: =HA6+GZ6 -> 0 | HC6: 99 | HE6: 86 | HG6: 72 | HI6: 69 | HK6: 109 | HM6: =HK6+HI6+HG6+HE6+HC6 -> 435 | HN6: =HL6+HJ6+HH6+HF6+HD6 -> 0 | HO6: =HN6+HM6 -> 435 | HR6: 4 | HT6: 7 | HV6: 5 | HZ6: =HX6+HV6+HT6+HR6+HP6 -> 16 | IA6: =HY6+HW6+HU6+HS6+HQ6 -> 0 | IB6: =IA6+HZ6 -> 16 | IC6: 1 | II6: 1 | IM6: =IK6+II6+IG6+IE6+IC6 -> 2 | IN6: =IL6+IJ6+IH6+IF6+ID6 -> 0 | IO6: =IN6+IM6 -> 2 | IZ6: =IX6+IV6+IT6+IR6+IP6 -> 0 | JA6: =IY6+IW6+IU6+IS6+IQ6 -> 0 | JB6: =JA6+IZ6 -> 0 | JC6: 1 | JE6: 3 | JG6: 29 | JH6: 5 | JI6: 10 | JK6: 2 | JM6: =JK6+JI6+JG6+JE6+JC6 -> 45 | JN6: =JL6+JJ6+JH6+JF6+JD6 -> 5 | JO6: =JN6+JM6 -> 50 | JU6: 1 | JY6: 1 | JZ6: 4 | KB6: 1 | KJ6: =KH6+KD6+KB6+JZ6+JX6+JV6+JT6+JP6+JR6+KF6 -> 5 | KK6: =KI6+KE6+KC6+KA6+JY6+JW6+JU6+JQ6+JS6+KG6 -> 2 | KL6: =KK6+KJ6 -> 7 | KM6: 45 | KN6: 5 | KS6: =KQ6+KO6+KM6 -> 45 | KT6: =KR6+KP6+KN6 -> 5 | KU6: =KT6+KS6 -> 50 | KV6: 41 | KW6: 4 | KZ6: 2 | LG6: 1 | LL6: 2 | LN6: =LL6+KV6+LJ6+LH6+LF6+LD6+LB6+KZ6+KX6 -> 45 | LO6: =LM6+KW6+LK6+LI6+LG6+LE6+LC6+LA6+KY6 -> 5 | LP6: =LO6+LN6 -> 50 | LX6: 1 | MA6: 1 | MD6: 2 | MG6: =ME6+MC6+MA6+LY6+LW6+LU6+LS6+LQ6 -> 1 | MH6: =MF6+MD6+MB6+LZ6+LX6+LV6+LT6+LR6 -> 3 | MI6: =MH6+MG6 -> 4 | MP6: 1 | MT6: 2 | MU6: 1 | MV6: 1 | MZ6: =MX6+MV6+MT6+MR6+MP6+MN6+ML6+MJ6 -> 4 | NA6: =MY6+MW6+MU6+MS6+MQ6+MO6+MM6+MK6 -> 1 | NB6: =NA6+MZ6 -> 5 | NG6: 1 | NI6: 1 | NJ6: 1 | NM6: 1 | NS6: =NQ6+NO6+NM6+NK6+NI6+NG6+NE6+NC6 -> 3 | NT6: =NR6+NP6+NN6+NL6+NJ6+NH6+NF6+ND6 -> 1 | NU6: =NT6+NS6 -> 4 | OL6: =OJ6+OH6+OF6+OD6+OB6+NZ6+NX6+NV6 -> 0 | OM6: =OK6+OI6+OG6+OE6+OC6+OA6+NY6+NW6 -> 0 | ON6: =OM6+OL6 -> 0 | PE6: =PC6+PA6+OY6+OW6+OU6+OS6+OQ6+OO6 -> 0 | PF6: =PD6+PB6+OZ6+OX6+OV6+OT6+OR6+OP6 -> 0 | PG6: =PF6+PE6 -> 0 | PX6: =PV6+PT6+PR6+PP6+PN6+PL6+PJ6+PH6 -> 0 | PY6: =PW6+PU6+PS6+PQ6+PO6+PM6+PK6+PI6 -> 0 | PZ6: =PY6+PX6 -> 0 | QQ6: =QO6+QM6+QK6+QI6+QG6+QE6+QC6+QA6 -> 0 | QR6: =QP6+QN6+QL6+QJ6+QH6+QF6+QD6+QB6 -> 0 | QS6: =QR6+QQ6 -> 0 | RJ6: =RH6+RF6+RD6+RB6+QZ6+QX6+QV6+QT6 -> 0 | RK6: =RI6+RG6+RE6+RC6+RA6+QY6+QW6+QU6 -> 0 | RL6: =RK6+RJ6 -> 0 | SC6: =SA6+RY6+RW6+RU6+RS6+RQ6+RO6+RM6 -> 0 | SD6: =SB6+RZ6+RX6+RV6+RT6+RR6+RP6+RN6 -> 0 | SE6: =SD6+SC6 -> 0 | SV6: =ST6+SR6+SP6+SN6+SL6+SJ6+SH6+SF6 -> 0 | SW6: =SU6+SS6+SQ6+SO6+SM6+SK6+SI6+SG6 -> 0 | SX6: =SW6+SV6 -> 0 | TO6: =TM6+TK6+TI6+TG6+TE6+TC6+TA6+SY6 -> 0 | TP6: =TN6+TL6+TJ6+TH6+TF6+TD6+TB6+SZ6 -> 0 | TQ6: =TP6+TO6 -> 0 | UH6: =UF6+UD6+UB6+TZ6+TX6+TV6+TT6+TR6 -> 0 | UI6: =UG6+UE6+UC6+UA6+TY6+TW6+TU6+TS6 -> 0 | UJ6: =UI6+UH6 -> 0 | VA6: =UY6+UW6+UU6+US6+UQ6+UO6+UM6+UK6 -> 0 | VB6: =UZ6+UX6+UV6+UT6+UR6+UP6+UN6+UL6 -> 0 | VC6: =VB6+VA6 -> 0 | VJ6: 2 | VT6: =VR6+VP6+VN6+VL6+VJ6+VH6+VF6+VD6 -> 2 | VU6: =VS6+VQ6+VO6+VM6+VK6+VI6+VG6+VE6 -> 0 | VV6: =VU6+VT6 -> 2 | VW6: 2 | WC6: 3 | WG6: 2 | WI6: 1 | WM6: =WK6+WI6+WG6+WE6+WC6+WA6+VY6+VW6 -> 8 | WN6: =WL6+WJ6+WH6+WF6+WD6+WB6+VZ6+VX6 -> 0 | WO6: =WN6+WM6 -> 8 | XF6: =XD6+XB6+WZ6+WX6+WV6+WT6+WR6+WP6 -> 0 | XG6: =XE6+XC6+XA6+WY6+WW6+WU6+WS6+WQ6 -> 0 | XH6: =XG6+XF6 -> 0 | XO6: 1 | XS6: 1 | XY6: =XW6+XU6+XS6+XQ6+XO6+XM6+XK6+XI6 -> 2 | XZ6: =XX6+XV6+XT6+XR6+XP6+XN6+XL6+XJ6 -> 0 | YA6: =XZ6+XY6 -> 2 | YR6: =YP6+YN6+YL6+YJ6+YH6+YF6+YD6+YB6 -> 0 | YS6: =YQ6+YO6+YM6+YK6+YI6+YG6+YE6+YC6 -> 0 | YT6: =YS6+YR6 -> 0 | ZK6: =ZI6+ZG6+ZE6+ZC6+ZA6+YY6+YW6+YU6 -> 0 | ZL6: =ZJ6+ZH6+ZF6+ZD6+ZB6+YZ6+YX6+YV6 -> 0 | ZM6: =ZL6+ZK6 -> 0 | ZT6: 1 | AAD6: =AAB6+ZZ6+ZX6+ZV6+ZT6+ZR6+ZP6+ZN6 -> 1 | AAE6: =AAC6+AAA6+ZY6+ZW6+ZU6+ZS6+ZQ6+ZO6 -> 0 | AAF6: =AAE6+AAD6 -> 1 | AAM6: 7 | AAS6: 1 | AAW6: =AAU6+AAS6+AAQ6+AAO6+AAM6+AAK6+AAI6+AAG6 -> 8 | AAX6: =AAV6+AAT6+AAR6+AAP6+AAN6+AAL6+AAJ6+AAH6 -> 0 | AAY6: =AAX6+AAW6 -> 8 | ABP6: =ABN6+ABL6+ABJ6+ABH6+ABF6+ABD6+ABB6+AAZ6 -> 0 | ABQ6: =ABO6+ABM6+ABK6+ABI6+ABG6+ABE6+ABC6+ABA6 -> 0 | ABR6: =ABQ6+ABP6 -> 0 | ACI6: =ACG6+ACE6+ACC6+ACA6+ABY6+ABW6+ABU6+ABS6 -> 0 | ACJ6: =ACH6+ACF6+ACD6+ACB6+ABZ6+ABX6+ABV6+ABT6 -> 0 | ACK6: =ACJ6+ACI6 -> 0 | ADB6: =ACZ6+ACX6+ACV6+ACT6+ACR6+ACP6+ACN6+ACL6 -> 0 | ADC6: =ADA6+ACY6+ACW6+ACU6+ACS6+ACQ6+ACO6+ACM6 -> 0 | ADD6: =ADC6+ADB6 -> 0 | ADK6: 5 | ADO6: 2 | ADQ6: 1 | ADU6: =ADS6+ADQ6+ADO6+ADM6+ADK6+ADI6+ADG6+ADE6 -> 8 | ADV6: =ADT6+ADR6+ADP6+ADN6+ADL6+ADJ6+ADH6+ADF6 -> 0 | ADW6: =ADV6+ADU6 -> 8 | AED6: 1 | AEH6: 1 | AEN6: =AEL6+AEJ6+AEH6+AEF6+AED6+AEB6+ADZ6+ADX6 -> 2 | AEO6: =AEM6+AEK6+AEI6+AEG6+AEE6+AEC6+AEA6+ADY6 -> 0 | AEP6: =AEO6+AEN6 -> 2 | AFG6: =AFE6+AFC6+AFA6+AEY6+AEW6+AEU6+AES6+AEQ6 -> 0 | AFH6: =AFF6+AFD6+AFB6+AEZ6+AEX6+AEV6+AET6+AER6 -> 0 | AFI6: =AFH6+AFG6 -> 0 | AFP6: 1 | AFZ6: =AFX6+AFV6+AFT6+AFR6+AFP6+AFN6+AFL6+AFJ6 -> 1 | AGA6: =AFY6+AFW6+AFU6+AFS6+AFQ6+AFO6+AFM6+AFK6 -> 0 | AGB6: =AGA6+AFZ6 -> 1 | AGS6: =AGQ6+AGO6+AGM6+AGK6+AGI6+AGG6+AGE6+AGC6 -> 0 | AGT6: =AGR6+AGP6+AGN6+AGL6+AGJ6+AGH6+AGF6+AGD6 -> 0 | AGU6: =AGT6+AGS6 -> 0 | AHL6: =AHJ6+AHH6+AHF6+AHD6+AHB6+AGZ6+AGX6+AGV6 -> 0 | AHM6: =AHK6+AHI6+AHG6+AHE6+AHC6+AHA6+AGY6+AGW6 -> 0 | AHN6: =AHM6+AHL6 -> 0 | AHO6: 1 | AIE6: =AIC6+AIA6+AHY6+AHW6+AHU6+AHS6+AHQ6+AHO6 -> 1 | AIF6: =AID6+AIB6+AHZ6+AHX6+AHV6+AHT6+AHR6+AHP6 -> 0 | AIG6: =AIF6+AIE6 -> 1 | AIR6: 1 | AIT6: 3 | AIX6: =AIV6+AIT6+AIR6+AIP6+AIN6+AIL6+AIJ6+AIH6 -> 4 | AIY6: =AIW6+AIU6+AIS6+AIQ6+AIO6+AIM6+AIK6+AII6 -> 0 | AIZ6: =AIY6+AIX6 -> 4 | AJA6: =AIH6+AGV6+AGC6+AFJ6+AEQ6+ADX6+ADE6+ACL6+ABS6+AAZ6+AAG6+ZN6+YU6+YB6+XI6+WP6+VW6+VD6+UK6+TR6+SY6+SF6+RM6+QT6+QA6+PH6+OO6+NV6+NC6+MJ6+LQ6+AHO6 -> 3 | AJB6: =AII6+AGW6+AGD6+AFK6+AER6+ADY6+ADF6+ACM6+ABT6+ABA6+AAH6+ZO6+YV6+YC6+XJ6+WQ6+VX6+VE6+UL6+TS6+SZ6+SG6+RN6+QU6+QB6+PI6+OP6+NW6+ND6+MK6+LR6+AHP6 -> 0 | AJC6: =AIJ6+AGX6+AGE6+AFL6+AES6+ADZ6+ADG6+ACN6+ABU6+ABB6+AAI6+ZP6+YW6+YD6+XK6+WR6+VY6+VF6+UM6+TT6+TA6+SH6+RO6+QV6+QC6+PJ6+OQ6+NX6+NE6+ML6+LS6+AHQ6 -> 0 | AJD6: =AIK6+AGY6+AGF6+AFM6+AET6+AEA6+ADH6+ACO6+ABV6+ABC6+AAJ6+ZQ6+YX6+YE6+XL6+WS6+VZ6+VG6+UN6+TU6+TB6+SI6+RP6+QW6+QD6+PK6+OR6+NY6+NF6+MM6+LT6+AHR6 -> 0 | AJE6: =AIL6+AGZ6+AGG6+AFN6+AEU6+AEB6+ADI6+ACP6+ABW6+ABD6+AAK6+ZR6+YY6+YF6+XM6+WT6+WA6+VH6+UO6+TV6+TC6+SJ6+RQ6+QX6+QE6+PL6+OS6+NZ6+NG6+MN6+LU6+AHS6 -> 1 | AJF6: =AIM6+AHA6+AGH6+AFO6+AEV6+AEC6+ADJ6+ACQ6+ABX6+ABE6+AAL6+ZS6+YZ6+YG6+XN6+WU6+WB6+VI6+UP6+TW6+TD6+SK6+RR6+QY6+QF6+PM6+OT6+OA6+NH6+MO6+LV6+AHT6 -> 0 | AJG6: =AIN6+AHB6+AGI6+AFP6+AEW6+AED6+ADK6+ACR6+ABY6+ABF6+AAM6+ZT6+ZA6+YH6+XO6+WV6+WC6+VJ6+UQ6+TX6+TE6+SL6+RS6+QZ6+QG6+PN6+OU6+OB6+NI6+MP6+LW6+AHU6 -> 23 | AJH6: =AIO6+AHC6+AGJ6+AFQ6+AEX6+AEE6+ADL6+ACS6+ABZ6+ABG6+AAN6+ZU6+ZB6+YI6+XP6+WW6+WD6+VK6+UR6+TY6+TF6+SM6+RT6+RA6+QH6+PO6+OV6+OC6+NJ6+MQ6+LX6+AHV6 -> 2 | ... AJP6: =AIW6+AHK6+AGR6+AFY6+AFF6+AEM6+ADT6+ADA6+ACH6+ABO6+AAV6+AAC6+ZJ6+YQ6+XX6+XE6+WL6+VS6+UZ6+UG6+TN6+SU6+SB6+RI6+QP6+PW6+PD6+OK6+NR6+MY6+MF6+AID6 -> 0 | AJQ6: =AJO6+AJM6+AJK6+AJI6+AJE6+AJG6+AJC6+AJA6 -> 45 | AJR6: =AJP6+AJN6+AJL6+AJJ6+AJF6+AJH6+AJD6+AJB6 -> 5 | AJS6: =AJR6+AJQ6 -> 50 | AJV6: 9 | AJX6: 16 | AJY6: 3 | AJZ6: 20 | AKA6: 2 | AKB6: =AJX6+AJV6+AJT6+AJZ6 -> 45 | AKC6: =AJY6+AJW6+AJU6+AKA6 -> 5 | AKD6: =AKC6+AKB6 -> 50 | AKG6: 8 | AKI6: 21 | AKJ6: 3 | AKK6: 16 | AKL6: 2 | AKO6: =AKM6+AKK6+AKI6+AKG6+AKE6 -> 45 | AKP6: =AKN6+AKL6+AKJ6+AKH6+AKF6 -> 5 | AKQ6: =AKP6+AKO6 -> 50 | AKT6: 45 | AKU6: 5 | AKZ6: =AKX6+AKV6+AKT6+AKR6 -> 45 | ALA6: =AKY6+AKW6+AKU6+AKS6 -> 5 | ALB6: =SUM(AKZ6:ALA6) -> 50 | ALC6: 5 | ALE6: 1 | ALG6: 2022 | ALH6: 17063/2 | ALI6: 2 | ALK6: 1 | ALN6: 1 | ALP6: 1 | ALR6: 27 | ALS6: 10 | ALT6: =ALS6+ALR6 -> 37 | ALY6: 1 | ALZ6: 1 | AMF6: 1 | AMH6: 1 | AMJ6: 1 | AML6: 1 | AMN6: 1 | AMP6: 1 | AMR6: 1 | AMW6: 1 | AMY6: 1 | ANB6: 1 | ANH6: 1 | ANI6: 1 | ANK6: 1 | ANN6: 1 | ANP6: 1 | ANS6: 1 | ANV6: 1 | ANW6: 1 | ANZ6: 250 | AOD6: 25 | AOF6: 27 | AOG6: 16 | AOH6: 4 | AOI6: 13 | AOJ6: 1 | AOL6: 1 | AOQ6: 1 | AOT6: 1 | AOW6: 1316 | AOX6: 330 | AOY6: =AOX6+AOW6 -> 1646 | AOZ6: 1 | APC6: 1 | APE6: 1 | APG6: 1 | API6: 1 | APK6: 1 | APM6: 1 | APN6: 1 | APP6: م . م . علي عبد الحسين فياض | APQ6: 7811661655
A7: النجف | B7: المركز | C7: 2 | D7: 1501039 | E7: معهد الفنون الجميلة للبنات | G7: 1 | I7: 1 | K7: 1 | O7: 1 | S7: 1 | Y7: 5 | AA7: 57 | AC7: 47 | AE7: 29 | AG7: 11 | AI7: 14 | AK7: 4 | AP7: =AN7+AL7+AJ7+AH7+AF7+AD7+AB7+Z7+X7 -> 0 | AQ7: =AO7+AM7+AK7+AI7+AG7+AE7+AC7+AA7+Y7 -> 167 | AR7: =AQ7+AP7 -> 167 | AT7: 5 | AV7: 57 | AX7: 47 | AZ7: 29 | BB7: 11 | BD7: 14 | BF7: 4 | BK7: =BI7+BG7+BE7+BC7+BA7+AY7+AW7+AU7+AS7 -> 0 | BL7: =BJ7+BH7+BF7+BD7+BB7+AZ7+AX7+AV7+AT7 -> 167 | BM7: =BL7+BK7 -> 167 | BO7: 32 | BQ7: 40 | BS7: 20 | BU7: 17 | BW7: 11 | BY7: 5 | CA7: 1 | CC7: 1 | CD7: =CB7+BZ7+BX7+BV7+BT7+BR7+BP7+BN7 -> 0 | CE7: =CC7+CA7+BY7+BW7+BU7+BS7+BQ7+BO7 -> 127 | CF7: =CE7+CD7 -> 127 | CH7: 31 | CJ7: 17 | CL7: 21 | CN7: 9 | CP7: 8 | CR7: 5 | CT7: 9 | CU7: =CS7+CQ7+CO7+CM7+CK7+CI7+CG7 -> 0 | CV7: =CT7+CR7+CP7+CN7+CL7+CJ7+CH7 -> 100 | CW7: =CV7+CU7 -> 100 | CY7: 6 | DA7: 24 | DC7: 19 | DE7: 8 | DG7: 5 | DI7: 6 | DJ7: =DH7+DF7+DD7+DB7+CZ7+CX7 -> 0 | DK7: =DI7+DG7+DE7+DC7+DA7+CY7 -> 68 | DL7: =DK7+DJ7 -> 68 | DN7: 4 | DP7: 30 | DR7: 8 | DT7: 8 | DV7: 28 | DW7: =DU7+DS7+DQ7+DO7+DM7 -> 0 | DX7: =DV7+DT7+DR7+DP7+DN7 -> 78 | DY7: =DX7+DW7 -> 78 | DZ7: =AS7 -> 0 | EA7: =AT7 -> 5 | EB7: =BN7+AU7 -> 0 | EC7: =BO7+AV7 -> 89 | ED7: =CG7+BP7+AW7 -> 0 | EE7: =CH7+BQ7+AX7 -> 118 | EF7: =CX7+CI7+BR7+AY7 -> 0 | EG7: =CY7+CJ7+BS7+AZ7 -> 72 | EH7: =DM7+CZ7+CK7+BT7+BA7 -> 0 | EI7: =DN7+DA7+CL7+BU7+BB7 -> 77 | EJ7: =DO7+DB7+CM7+BV7+BC7 -> 0 | EK7: =DP7+DC7+CN7+BW7+BD7 -> 83 | EL7: =DQ7+DD7+CO7+BX7+BE7 -> 0 | EM7: =DR7+DE7+CP7+BY7+BF7 -> 33 | EN7: =DS7+DF7+CQ7+BZ7+BG7 -> 0 | EO7: =DT7+DG7+CR7+CA7+BH7 -> 19 | ... EQ7: =DV7+DI7+CT7+CC7+BJ7 -> 44 | ER7: =EP7+EN7+EL7+EJ7+EH7+EF7+ED7+EB7+DZ7 -> 0 | ES7: =EQ7+EO7+EM7+EK7+EI7+EG7+EE7+EC7+EA7 -> 540 | ET7: =ES7+ER7 -> 540 | EX7: 174 | EZ7: 181 | FF7: 185 | FG7: =FC7+FA7+EY7+EW7+EU7+FE7 -> 0 | FH7: =FD7+FB7+EZ7+EX7+EV7+FF7 -> 540 | FI7: =FH7+FG7 -> 540 | FK7: 6 | FN7: 4 | FQ7: 4 | FT7: 4 | FW7: 4 | FY7: =FV7+FS7+FP7+FM7+FJ7 -> 0 | FZ7: =FW7+FT7+FQ7+FN7+FK7 -> 22 | GA7: =FX7+FU7+FR7+FO7+FL7 -> 0 | GB7: =GA7+FZ7+FY7 -> 22 | GF7: 5 | GH7: 1 | GM7: =GK7+GI7+GG7+GE7+GC7 -> 0 | GN7: =GL7+GJ7+GH7+GF7+GD7 -> 6 | GO7: =GN7+GM7 -> 6 | GZ7: =GX7+GV7+GT7+GR7+GP7 -> 0 | HA7: =GY7+GW7+GU7+GS7+GQ7 -> 0 | HB7: =HA7+GZ7 -> 0 | HD7: 122 | HF7: 102 | HH7: 66 | HJ7: 78 | HL7: 101 | HM7: =HK7+HI7+HG7+HE7+HC7 -> 0 | HN7: =HL7+HJ7+HH7+HF7+HD7 -> 469 | HO7: =HN7+HM7 -> 469 | HQ7: 3 | HS7: 4 | HU7: 1 | HZ7: =HX7+HV7+HT7+HR7+HP7 -> 0 | IA7: =HY7+HW7+HU7+HS7+HQ7 -> 8 | IB7: =IA7+HZ7 -> 8 | IF7: 9 | IH7: 1 | IM7: =IK7+II7+IG7+IE7+IC7 -> 0 | IN7: =IL7+IJ7+IH7+IF7+ID7 -> 10 | IO7: =IN7+IM7 -> 10 | IZ7: =IX7+IV7+IT7+IR7+IP7 -> 0 | JA7: =IY7+IW7+IU7+IS7+IQ7 -> 0 | JB7: =JA7+IZ7 -> 0 | JD7: 1 | JF7: 2 | JG7: 4 | JH7: 14 | JJ7: 1 | JL7: 1 | JM7: =JK7+JI7+JG7+JE7+JC7 -> 4 | JN7: =JL7+JJ7+JH7+JF7+JD7 -> 19 | JO7: =JN7+JM7 -> 23 | JS7: 2 | KA7: 2 | KJ7: =KH7+KD7+KB7+JZ7+JX7+JV7+JT7+JP7+JR7+KF7 -> 0 | KK7: =KI7+KE7+KC7+KA7+JY7+JW7+JU7+JQ7+JS7+KG7 -> 4 | KL7: =KK7+KJ7 -> 4 | KM7: 4 | KN7: 19 | KS7: =KQ7+KO7+KM7 -> 4 | KT7: =KR7+KP7+KN7 -> 19 | KU7: =KT7+KS7 -> 23 | KV7: 3 | KW7: 18 | KZ7: 1 | LG7: 1 | LN7: =LL7+KV7+LJ7+LH7+LF7+LD7+LB7+KZ7+KX7 -> 4 | LO7: =LM7+KW7+LK7+LI7+LG7+LE7+LC7+LA7+KY7 -> 19 | LP7: =LO7+LN7 -> 23 | LX7: 1 | MB7: 1 | MD7: 1 | MG7: =ME7+MC7+MA7+LY7+LW7+LU7+LS7+LQ7 -> 0 | MH7: =MF7+MD7+MB7+LZ7+LX7+LV7+LT7+LR7 -> 3 | MI7: =MH7+MG7 -> 3 | MQ7: 2 | MZ7: =MX7+MV7+MT7+MR7+MP7+MN7+ML7+MJ7 -> 0 | NA7: =MY7+MW7+MU7+MS7+MQ7+MO7+MM7+MK7 -> 2 | NB7: =NA7+MZ7 -> 2 | NH7: 4 | NJ7: 1 | NS7: =NQ7+NO7+NM7+NK7+NI7+NG7+NE7+NC7 -> 0 | NT7: =NR7+NP7+NN7+NL7+NJ7+NH7+NF7+ND7 -> 5 | NU7: =NT7+NS7 -> 5 | OL7: =OJ7+OH7+OF7+OD7+OB7+NZ7+NX7+NV7 -> 0 | OM7: =OK7+OI7+OG7+OE7+OC7+OA7+NY7+NW7 -> 0 | ON7: =OM7+OL7 -> 0 | PE7: =PC7+PA7+OY7+OW7+OU7+OS7+OQ7+OO7 -> 0 | PF7: =PD7+PB7+OZ7+OX7+OV7+OT7+OR7+OP7 -> 0 | PG7: =PF7+PE7 -> 0 | PX7: =PV7+PT7+PR7+PP7+PN7+PL7+PJ7+PH7 -> 0 | PY7: =PW7+PU7+PS7+PQ7+PO7+PM7+PK7+PI7 -> 0 | PZ7: =PY7+PX7 -> 0 | QQ7: =QO7+QM7+QK7+QI7+QG7+QE7+QC7+QA7 -> 0 | QR7: =QP7+QN7+QL7+QJ7+QH7+QF7+QD7+QB7 -> 0 | QS7: =QR7+QQ7 -> 0 | RJ7: =RH7+RF7+RD7+RB7+QZ7+QX7+QV7+QT7 -> 0 | RK7: =RI7+RG7+RE7+RC7+RA7+QY7+QW7+QU7 -> 0 | RL7: =RK7+RJ7 -> 0 | SC7: =SA7+RY7+RW7+RU7+RS7+RQ7+RO7+RM7 -> 0 | SD7: =SB7+RZ7+RX7+RV7+RT7+RR7+RP7+RN7 -> 0 | SE7: =SD7+SC7 -> 0 | SV7: =ST7+SR7+SP7+SN7+SL7+SJ7+SH7+SF7 -> 0 | SW7: =SU7+SS7+SQ7+SO7+SM7+SK7+SI7+SG7 -> 0 | SX7: =SW7+SV7 -> 0 | TO7: =TM7+TK7+TI7+TG7+TE7+TC7+TA7+SY7 -> 0 | TP7: =TN7+TL7+TJ7+TH7+TF7+TD7+TB7+SZ7 -> 0 | TQ7: =TP7+TO7 -> 0 | UH7: =UF7+UD7+UB7+TZ7+TX7+TV7+TT7+TR7 -> 0 | UI7: =UG7+UE7+UC7+UA7+TY7+TW7+TU7+TS7 -> 0 | UJ7: =UI7+UH7 -> 0 | VA7: =UY7+UW7+UU7+US7+UQ7+UO7+UM7+UK7 -> 0 | VB7: =UZ7+UX7+UV7+UT7+UR7+UP7+UN7+UL7 -> 0 | VC7: =VB7+VA7 -> 0 | VK7: 1 | VT7: =VR7+VP7+VN7+VL7+VJ7+VH7+VF7+VD7 -> 0 | VU7: =VS7+VQ7+VO7+VM7+VK7+VI7+VG7+VE7 -> 1 | VV7: =VU7+VT7 -> 1 | WC7: 1 | WD7: 2 | WM7: =WK7+WI7+WG7+WE7+WC7+WA7+VY7+VW7 -> 1 | WN7: =WL7+WJ7+WH7+WF7+WD7+WB7+VZ7+VX7 -> 2 | WO7: =WN7+WM7 -> 3 | XF7: =XD7+XB7+WZ7+WX7+WV7+WT7+WR7+WP7 -> 0 | XG7: =XE7+XC7+XA7+WY7+WW7+WU7+WS7+WQ7 -> 0 | XH7: =XG7+XF7 -> 0 | XT7: 1 | XY7: =XW7+XU7+XS7+XQ7+XO7+XM7+XK7+XI7 -> 0 | XZ7: =XX7+XV7+XT7+XR7+XP7+XN7+XL7+XJ7 -> 1 | YA7: =XZ7+XY7 -> 1 | YR7: =YP7+YN7+YL7+YJ7+YH7+YF7+YD7+YB7 -> 0 | YS7: =YQ7+YO7+YM7+YK7+YI7+YG7+YE7+YC7 -> 0 | YT7: =YS7+YR7 -> 0 | ZK7: =ZI7+ZG7+ZE7+ZC7+ZA7+YY7+YW7+YU7 -> 0 | ZL7: =ZJ7+ZH7+ZF7+ZD7+ZB7+YZ7+YX7+YV7 -> 0 | ZM7: =ZL7+ZK7 -> 0 | ZS7: 1 | ZU7: 1 | AAD7: =AAB7+ZZ7+ZX7+ZV7+ZT7+ZR7+ZP7+ZN7 -> 0 | AAE7: =AAC7+AAA7+ZY7+ZW7+ZU7+ZS7+ZQ7+ZO7 -> 2 | AAF7: =AAE7+AAD7 -> 2 | AAN7: 1 | AAW7: =AAU7+AAS7+AAQ7+AAO7+AAM7+AAK7+AAI7+AAG7 -> 0 | AAX7: =AAV7+AAT7+AAR7+AAP7+AAN7+AAL7+AAJ7+AAH7 -> 1 | AAY7: =AAX7+AAW7 -> 1 | ABP7: =ABN7+ABL7+ABJ7+ABH7+ABF7+ABD7+ABB7+AAZ7 -> 0 | ABQ7: =ABO7+ABM7+ABK7+ABI7+ABG7+ABE7+ABC7+ABA7 -> 0 | ABR7: =ABQ7+ABP7 -> 0 | ACI7: =ACG7+ACE7+ACC7+ACA7+ABY7+ABW7+ABU7+ABS7 -> 0 | ACJ7: =ACH7+ACF7+ACD7+ACB7+ABZ7+ABX7+ABV7+ABT7 -> 0 | ACK7: =ACJ7+ACI7 -> 0 | ADB7: =ACZ7+ACX7+ACV7+ACT7+ACR7+ACP7+ACN7+ACL7 -> 0 | ADC7: =ADA7+ACY7+ACW7+ACU7+ACS7+ACQ7+ACO7+ACM7 -> 0 | ADD7: =ADC7+ADB7 -> 0 | ADL7: 1 | ADU7: =ADS7+ADQ7+ADO7+ADM7+ADK7+ADI7+ADG7+ADE7 -> 0 | ADV7: =ADT7+ADR7+ADP7+ADN7+ADL7+ADJ7+ADH7+ADF7 -> 1 | ADW7: =ADV7+ADU7 -> 1 | AEN7: =AEL7+AEJ7+AEH7+AEF7+AED7+AEB7+ADZ7+ADX7 -> 0 | AEO7: =AEM7+AEK7+AEI7+AEG7+AEE7+AEC7+AEA7+ADY7 -> 0 | AEP7: =AEO7+AEN7 -> 0 | AFG7: =AFE7+AFC7+AFA7+AEY7+AEW7+AEU7+AES7+AEQ7 -> 0 | AFH7: =AFF7+AFD7+AFB7+AEZ7+AEX7+AEV7+AET7+AER7 -> 0 | AFI7: =AFH7+AFG7 -> 0 | AFQ7: 1 | AFZ7: =AFX7+AFV7+AFT7+AFR7+AFP7+AFN7+AFL7+AFJ7 -> 0 | AGA7: =AFY7+AFW7+AFU7+AFS7+AFQ7+AFO7+AFM7+AFK7 -> 1 | AGB7: =AGA7+AFZ7 -> 1 | AGI7: 3 | AGS7: =AGQ7+AGO7+AGM7+AGK7+AGI7+AGG7+AGE7+AGC7 -> 3 | AGT7: =AGR7+AGP7+AGN7+AGL7+AGJ7+AGH7+AGF7+AGD7 -> 0 | AGU7: =AGT7+AGS7 -> 3 | AHL7: =AHJ7+AHH7+AHF7+AHD7+AHB7+AGZ7+AGX7+AGV7 -> 0 | AHM7: =AHK7+AHI7+AHG7+AHE7+AHC7+AHA7+AGY7+AGW7 -> 0 | AHN7: =AHM7+AHL7 -> 0 | AIE7: =AIC7+AIA7+AHY7+AHW7+AHU7+AHS7+AHQ7+AHO7 -> 0 | AIF7: =AID7+AIB7+AHZ7+AHX7+AHV7+AHT7+AHR7+AHP7 -> 0 | AIG7: =AIF7+AIE7 -> 0 | AIX7: =AIV7+AIT7+AIR7+AIP7+AIN7+AIL7+AIJ7+AIH7 -> 0 | AIY7: =AIW7+AIU7+AIS7+AIQ7+AIO7+AIM7+AIK7+AII7 -> 0 | AIZ7: =AIY7+AIX7 -> 0 | AJA7: =AIH7+AGV7+AGC7+AFJ7+AEQ7+ADX7+ADE7+ACL7+ABS7+AAZ7+AAG7+ZN7+YU7+YB7+XI7+WP7+VW7+VD7+UK7+TR7+SY7+SF7+RM7+QT7+QA7+PH7+OO7+NV7+NC7+MJ7+LQ7+AHO7 -> 0 | AJB7: =AII7+AGW7+AGD7+AFK7+AER7+ADY7+ADF7+ACM7+ABT7+ABA7+AAH7+ZO7+YV7+YC7+XJ7+WQ7+VX7+VE7+UL7+TS7+SZ7+SG7+RN7+QU7+QB7+PI7+OP7+NW7+ND7+MK7+LR7+AHP7 -> 0 | AJC7: =AIJ7+AGX7+AGE7+AFL7+AES7+ADZ7+ADG7+ACN7+ABU7+ABB7+AAI7+ZP7+YW7+YD7+XK7+WR7+VY7+VF7+UM7+TT7+TA7+SH7+RO7+QV7+QC7+PJ7+OQ7+NX7+NE7+ML7+LS7+AHQ7 -> 0 | AJD7: =AIK7+AGY7+AGF7+AFM7+AET7+AEA7+ADH7+ACO7+ABV7+ABC7+AAJ7+ZQ7+YX7+YE7+XL7+WS7+VZ7+VG7+UN7+TU7+TB7+SI7+RP7+QW7+QD7+PK7+OR7+NY7+NF7+MM7+LT7+AHR7 -> 0 | AJE7: =AIL7+AGZ7+AGG7+AFN7+AEU7+AEB7+ADI7+ACP7+ABW7+ABD7+AAK7+ZR7+YY7+YF7+XM7+WT7+WA7+VH7+UO7+TV7+TC7+SJ7+RQ7+QX7+QE7+PL7+OS7+NZ7+NG7+MN7+LU7+AHS7 -> 0 | AJF7: =AIM7+AHA7+AGH7+AFO7+AEV7+AEC7+ADJ7+ACQ7+ABX7+ABE7+AAL7+ZS7+YZ7+YG7+XN7+WU7+WB7+VI7+UP7+TW7+TD7+SK7+RR7+QY7+QF7+PM7+OT7+OA7+NH7+MO7+LV7+AHT7 -> 5 | AJG7: =AIN7+AHB7+AGI7+AFP7+AEW7+AED7+ADK7+ACR7+ABY7+ABF7+AAM7+ZT7+ZA7+YH7+XO7+WV7+WC7+VJ7+UQ7+TX7+TE7+SL7+RS7+QZ7+QG7+PN7+OU7+OB7+NI7+MP7+LW7+AHU7 -> 4 | AJH7: =AIO7+AHC7+AGJ7+AFQ7+AEX7+AEE7+ADL7+ACS7+ABZ7+ABG7+AAN7+ZU7+ZB7+YI7+XP7+WW7+WD7+VK7+UR7+TY7+TF7+SM7+RT7+RA7+QH7+PO7+OV7+OC7+NJ7+MQ7+LX7+AHV7 -> 11 | ... AJP7: =AIW7+AHK7+AGR7+AFY7+AFF7+AEM7+ADT7+ADA7+ACH7+ABO7+AAV7+AAC7+ZJ7+YQ7+XX7+XE7+WL7+VS7+UZ7+UG7+TN7+SU7+SB7+RI7+QP7+PW7+PD7+OK7+NR7+MY7+MF7+AID7 -> 0 | AJQ7: =AJO7+AJM7+AJK7+AJI7+AJE7+AJG7+AJC7+AJA7 -> 4 | AJR7: =AJP7+AJN7+AJL7+AJJ7+AJF7+AJH7+AJD7+AJB7 -> 19 | AJS7: =AJR7+AJQ7 -> 23 | AJZ7: 4 | AKA7: 19 | AKB7: =AJX7+AJV7+AJT7+AJZ7 -> 4 | AKC7: =AJY7+AJW7+AJU7+AKA7 -> 19 | AKD7: =AKC7+AKB7 -> 23 | AKI7: 3 | AKJ7: 8 | AKK7: 1 | AKL7: 11 | AKO7: =AKM7+AKK7+AKI7+AKG7+AKE7 -> 4 | AKP7: =AKN7+AKL7+AKJ7+AKH7+AKF7 -> 19 | AKQ7: =AKP7+AKO7 -> 23 | AKS7: 1 | AKT7: 4 | AKU7: 16 | AKW7: 2 | AKZ7: =AKX7+AKV7+AKT7+AKR7 -> 4 | ALA7: =AKY7+AKW7+AKU7+AKS7 -> 19 | ALB7: =SUM(AKZ7:ALA7) -> 23 | ALC7: 2 | ALD7: 5 | ALE7: 1 | ALG7: 2007 | ALH7: 82234/3 | ALI7: 3 | ALJ7: 1 | ALM7: 1 | ALO7: 1 | ALQ7: 6 | ALR7: 18 | ALS7: 18 | ALT7: =ALS7+ALR7 -> 36 | ALX7: 1 | ALZ7: 1 | AMF7: 1 | AMI7: 1 | AMJ7: 1 | AML7: 1 | AMN7: 1 | AMP7: 1 | AMR7: 1 | AMW7: 1 | AMY7: 1 | ANB7: 1 | ANE7: 1 | ANI7: 1 | ANK7: 1 | ANN7: 1 | ANQ7: 1 | ANT7: 1 | ANV7: 1 | ANW7: 1 | ANZ7: 50 | AOB7: 400 | AOC7: 108 | AOD7: 23 | AOE7: 1 | AOF7: 12 | AOG7: 10 | AOH7: 2 | AOI7: 1 | AOK7: 2 | AOL7: 1 | AOP7: 1 | AOS7: 1 | AOW7: 2505 | AOY7: =AOX7+AOW7 -> 2505 | AOZ7: 1 | APC7: 1 | APE7: 1 | APG7: 1 | API7: 1 | APK7: 1 | APM7: 1 | APN7: 1 | APP7: ابتسام عبد الحسن شنان | APQ7: 7803343910
A8: النجف | B8: المركز | C8: 3 | E8: معهد الفنون الجميلة المسائية للبنين | F8: 1 | I8: 1 | N8: 1 | O8: 1 | Q8: 1 | AN8: 153 | AP8: =AN8+AL8+AJ8+AH8+AF8+AD8+AB8+Z8+X8 -> 153 | AQ8: =AO8+AM8+AK8+AI8+AG8+AE8+AC8+AA8+Y8 -> 0 | AR8: =AQ8+AP8 -> 153 | BI8: 181 | BK8: =BI8+BG8+BE8+BC8+BA8+AY8+AW8+AU8+AS8 -> 181 | BL8: =BJ8+BH8+BF8+BD8+BB8+AZ8+AX8+AV8+AT8 -> 0 | BM8: =BL8+BK8 -> 181 | CB8: 124 | CD8: =CB8+BZ8+BX8+BV8+BT8+BR8+BP8+BN8 -> 124 | CE8: =CC8+CA8+BY8+BW8+BU8+BS8+BQ8+BO8 -> 0 | CF8: =CE8+CD8 -> 124 | CS8: 123 | CU8: =CS8+CQ8+CO8+CM8+CK8+CI8+CG8 -> 123 | CV8: =CT8+CR8+CP8+CN8+CL8+CJ8+CH8 -> 0 | CW8: =CV8+CU8 -> 123 | DJ8: =DH8+DF8+DD8+DB8+CZ8+CX8 -> 0 | DK8: =DI8+DG8+DE8+DC8+DA8+CY8 -> 0 | DL8: =DK8+DJ8 -> 0 | DW8: =DU8+DS8+DQ8+DO8+DM8 -> 0 | DX8: =DV8+DT8+DR8+DP8+DN8 -> 0 | DY8: =DX8+DW8 -> 0 | DZ8: =AS8 -> 0 | EA8: =AT8 -> 0 | EB8: =BN8+AU8 -> 0 | EC8: =BO8+AV8 -> 0 | ED8: =CG8+BP8+AW8 -> 0 | EE8: =CH8+BQ8+AX8 -> 0 | EF8: =CX8+CI8+BR8+AY8 -> 0 | EG8: =CY8+CJ8+BS8+AZ8 -> 0 | EH8: =DM8+CZ8+CK8+BT8+BA8 -> 0 | EI8: =DN8+DA8+CL8+BU8+BB8 -> 0 | EJ8: =DO8+DB8+CM8+BV8+BC8 -> 0 | EK8: =DP8+DC8+CN8+BW8+BD8 -> 0 | EL8: =DQ8+DD8+CO8+BX8+BE8 -> 0 | EM8: =DR8+DE8+CP8+BY8+BF8 -> 0 | EN8: =DS8+DF8+CQ8+BZ8+BG8 -> 0 | EO8: =DT8+DG8+CR8+CA8+BH8 -> 0 | ... EQ8: =DV8+DI8+CT8+CC8+BJ8 -> 0 | ER8: =EP8+EN8+EL8+EJ8+EH8+EF8+ED8+EB8+DZ8 -> 428 | ES8: =EQ8+EO8+EM8+EK8+EI8+EG8+EE8+EC8+EA8 -> 0 | ET8: =ES8+ER8 -> 428 | EW8: 96 | EY8: 111 | FA8: 127 | FC8: 94 | FG8: =FC8+FA8+EY8+EW8+EU8+FE8 -> 428 | FH8: =FD8+FB8+EZ8+EX8+EV8+FF8 -> 0 | FI8: =FH8+FG8 -> 428 | FJ8: 8 | FM8: 8 | FP8: 8 | FY8: =FV8+FS8+FP8+FM8+FJ8 -> 24 | FZ8: =FW8+FT8+FQ8+FN8+FK8 -> 0 | GA8: =FX8+FU8+FR8+FO8+FL8 -> 0 | GB8: =GA8+FZ8+FY8 -> 24 | GC8: 28 | GE8: 4 | GG8: 1 | GM8: =GK8+GI8+GG8+GE8+GC8 -> 33 | GN8: =GL8+GJ8+GH8+GF8+GD8 -> 0 | GO8: =GN8+GM8 -> 33 | HC8: 120 | HE8: 122 | HM8: =HK8+HI8+HG8+HE8+HC8 -> 242 | HN8: =HL8+HJ8+HH8+HF8+HD8 -> 0 | HO8: =HN8+HM8 -> 242 | HP8: 8 | HR8: 1 | HZ8: =HX8+HV8+HT8+HR8+HP8 -> 9 | IA8: =HY8+HW8+HU8+HS8+HQ8 -> 0 | IB8: =IA8+HZ8 -> 9 | IM8: =IK8+II8+IG8+IE8+IC8 -> 0 | IN8: =IL8+IJ8+IH8+IF8+ID8 -> 0 | IO8: =IN8+IM8 -> 0 | IZ8: =IX8+IV8+IT8+IR8+IP8 -> 0 | JA8: =IY8+IW8+IU8+IS8+IQ8 -> 0 | JB8: =JA8+IZ8 -> 0 | JC8: 1 | JE8: 1 | JG8: 6 | JM8: =JK8+JI8+JG8+JE8+JC8 -> 8 | JN8: =JL8+JJ8+JH8+JF8+JD8 -> 0 | JO8: =JN8+JM8 -> 8 | JP8: 1 | KB8: 1 | KJ8: =KH8+KD8+KB8+JZ8+JX8+JV8+JT8+JP8+JR8+KF8 -> 2 | KK8: =KI8+KE8+KC8+KA8+JY8+JW8+JU8+JQ8+JS8+KG8 -> 0 | KL8: =KK8+KJ8 -> 2 | KM8: 8 | KS8: =KQ8+KO8+KM8 -> 8 | KT8: =KR8+KP8+KN8 -> 0 | KU8: =KT8+KS8 -> 8 | KV8: 5 | KZ8: 2 | LF8: 1 | LN8: =LL8+KV8+LJ8+LH8+LF8+LD8+LB8+KZ8+KX8 -> 8 | LO8: =LM8+KW8+LK8+LI8+LG8+LE8+LC8+LA8+KY8 -> 0 | LP8: =LO8+LN8 -> 8 | MC8: 1 | MG8: =ME8+MC8+MA8+LY8+LW8+LU8+LS8+LQ8 -> 1 | MH8: =MF8+MD8+MB8+LZ8+LX8+LV8+LT8+LR8 -> 0 | MI8: =MH8+MG8 -> 1 | MV8: 1 | MZ8: =MX8+MV8+MT8+MR8+MP8+MN8+ML8+MJ8 -> 1 | NA8: =MY8+MW8+MU8+MS8+MQ8+MO8+MM8+MK8 -> 0 | NB8: =NA8+MZ8 -> 1 | NK8: 1 | NS8: =NQ8+NO8+NM8+NK8+NI8+NG8+NE8+NC8 -> 1 | NT8: =NR8+NP8+NN8+NL8+NJ8+NH8+NF8+ND8 -> 0 | NU8: =NT8+NS8 -> 1 | OL8: =OJ8+OH8+OF8+OD8+OB8+NZ8+NX8+NV8 -> 0 | OM8: =OK8+OI8+OG8+OE8+OC8+OA8+NY8+NW8 -> 0 | ON8: =OM8+OL8 -> 0 | PE8: =PC8+PA8+OY8+OW8+OU8+OS8+OQ8+OO8 -> 0 | PF8: =PD8+PB8+OZ8+OX8+OV8+OT8+OR8+OP8 -> 0 | PG8: =PF8+PE8 -> 0 | PX8: =PV8+PT8+PR8+PP8+PN8+PL8+PJ8+PH8 -> 0 | PY8: =PW8+PU8+PS8+PQ8+PO8+PM8+PK8+PI8 -> 0 | PZ8: =PY8+PX8 -> 0 | QQ8: =QO8+QM8+QK8+QI8+QG8+QE8+QC8+QA8 -> 0 | QR8: =QP8+QN8+QL8+QJ8+QH8+QF8+QD8+QB8 -> 0 | QS8: =QR8+QQ8 -> 0 | RJ8: =RH8+RF8+RD8+RB8+QZ8+QX8+QV8+QT8 -> 0 | RK8: =RI8+RG8+RE8+RC8+RA8+QY8+QW8+QU8 -> 0 | RL8: =RK8+RJ8 -> 0 | SC8: =SA8+RY8+RW8+RU8+RS8+RQ8+RO8+RM8 -> 0 | SD8: =SB8+RZ8+RX8+RV8+RT8+RR8+RP8+RN8 -> 0 | SE8: =SD8+SC8 -> 0 | SV8: =ST8+SR8+SP8+SN8+SL8+SJ8+SH8+SF8 -> 0 | SW8: =SU8+SS8+SQ8+SO8+SM8+SK8+SI8+SG8 -> 0 | SX8: =SW8+SV8 -> 0 | TO8: =TM8+TK8+TI8+TG8+TE8+TC8+TA8+SY8 -> 0 | TP8: =TN8+TL8+TJ8+TH8+TF8+TD8+TB8+SZ8 -> 0 | TQ8: =TP8+TO8 -> 0 | UH8: =UF8+UD8+UB8+TZ8+TX8+TV8+TT8+TR8 -> 0 | UI8: =UG8+UE8+UC8+UA8+TY8+TW8+TU8+TS8 -> 0 | UJ8: =UI8+UH8 -> 0 | VA8: =UY8+UW8+UU8+US8+UQ8+UO8+UM8+UK8 -> 0 | VB8: =UZ8+UX8+UV8+UT8+UR8+UP8+UN8+UL8 -> 0 | VC8: =VB8+VA8 -> 0 | VT8: =VR8+VP8+VN8+VL8+VJ8+VH8+VF8+VD8 -> 0 | VU8: =VS8+VQ8+VO8+VM8+VK8+VI8+VG8+VE8 -> 0 | VV8: =VU8+VT8 -> 0 | WC8: 5 | WM8: =WK8+WI8+WG8+WE8+WC8+WA8+VY8+VW8 -> 5 | WN8: =WL8+WJ8+WH8+WF8+WD8+WB8+VZ8+VX8 -> 0 | WO8: =WN8+WM8 -> 5 | XF8: =XD8+XB8+WZ8+WX8+WV8+WT8+WR8+WP8 -> 0 | XG8: =XE8+XC8+XA8+WY8+WW8+WU8+WS8+WQ8 -> 0 | XH8: =XG8+XF8 -> 0 | XY8: =XW8+XU8+XS8+XQ8+XO8+XM8+XK8+XI8 -> 0 | XZ8: =XX8+XV8+XT8+XR8+XP8+XN8+XL8+XJ8 -> 0 | YA8: =XZ8+XY8 -> 0 | YR8: =YP8+YN8+YL8+YJ8+YH8+YF8+YD8+YB8 -> 0 | YS8: =YQ8+YO8+YM8+YK8+YI8+YG8+YE8+YC8 -> 0 | YT8: =YS8+YR8 -> 0 | ZK8: =ZI8+ZG8+ZE8+ZC8+ZA8+YY8+YW8+YU8 -> 0 | ZL8: =ZJ8+ZH8+ZF8+ZD8+ZB8+YZ8+YX8+YV8 -> 0 | ZM8: =ZL8+ZK8 -> 0 | AAD8: =AAB8+ZZ8+ZX8+ZV8+ZT8+ZR8+ZP8+ZN8 -> 0 | AAE8: =AAC8+AAA8+ZY8+ZW8+ZU8+ZS8+ZQ8+ZO8 -> 0 | AAF8: =AAE8+AAD8 -> 0 | AAW8: =AAU8+AAS8+AAQ8+AAO8+AAM8+AAK8+AAI8+AAG8 -> 0 | AAX8: =AAV8+AAT8+AAR8+AAP8+AAN8+AAL8+AAJ8+AAH8 -> 0 | AAY8: =AAX8+AAW8 -> 0 | ABP8: =ABN8+ABL8+ABJ8+ABH8+ABF8+ABD8+ABB8+AAZ8 -> 0 | ABQ8: =ABO8+ABM8+ABK8+ABI8+ABG8+ABE8+ABC8+ABA8 -> 0 | ABR8: =ABQ8+ABP8 -> 0 | ACI8: =ACG8+ACE8+ACC8+ACA8+ABY8+ABW8+ABU8+ABS8 -> 0 | ACJ8: =ACH8+ACF8+ACD8+ACB8+ABZ8+ABX8+ABV8+ABT8 -> 0 | ACK8: =ACJ8+ACI8 -> 0 | ADB8: =ACZ8+ACX8+ACV8+ACT8+ACR8+ACP8+ACN8+ACL8 -> 0 | ADC8: =ADA8+ACY8+ACW8+ACU8+ACS8+ACQ8+ACO8+ACM8 -> 0 | ADD8: =ADC8+ADB8 -> 0 | ADU8: =ADS8+ADQ8+ADO8+ADM8+ADK8+ADI8+ADG8+ADE8 -> 0 | ADV8: =ADT8+ADR8+ADP8+ADN8+ADL8+ADJ8+ADH8+ADF8 -> 0 | ADW8: =ADV8+ADU8 -> 0 | AEN8: =AEL8+AEJ8+AEH8+AEF8+AED8+AEB8+ADZ8+ADX8 -> 0 | AEO8: =AEM8+AEK8+AEI8+AEG8+AEE8+AEC8+AEA8+ADY8 -> 0 | AEP8: =AEO8+AEN8 -> 0 | AFG8: =AFE8+AFC8+AFA8+AEY8+AEW8+AEU8+AES8+AEQ8 -> 0 | AFH8: =AFF8+AFD8+AFB8+AEZ8+AEX8+AEV8+AET8+AER8 -> 0 | AFI8: =AFH8+AFG8 -> 0 | AFZ8: =AFX8+AFV8+AFT8+AFR8+AFP8+AFN8+AFL8+AFJ8 -> 0 | AGA8: =AFY8+AFW8+AFU8+AFS8+AFQ8+AFO8+AFM8+AFK8 -> 0 | AGB8: =AGA8+AFZ8 -> 0 | AGS8: =AGQ8+AGO8+AGM8+AGK8+AGI8+AGG8+AGE8+AGC8 -> 0 | AGT8: =AGR8+AGP8+AGN8+AGL8+AGJ8+AGH8+AGF8+AGD8 -> 0 | AGU8: =AGT8+AGS8 -> 0 | AHL8: =AHJ8+AHH8+AHF8+AHD8+AHB8+AGZ8+AGX8+AGV8 -> 0 | AHM8: =AHK8+AHI8+AHG8+AHE8+AHC8+AHA8+AGY8+AGW8 -> 0 | AHN8: =AHM8+AHL8 -> 0 | AIE8: =AIC8+AIA8+AHY8+AHW8+AHU8+AHS8+AHQ8+AHO8 -> 0 | AIF8: =AID8+AIB8+AHZ8+AHX8+AHV8+AHT8+AHR8+AHP8 -> 0 | AIG8: =AIF8+AIE8 -> 0 | AIX8: =AIV8+AIT8+AIR8+AIP8+AIN8+AIL8+AIJ8+AIH8 -> 0 | AIY8: =AIW8+AIU8+AIS8+AIQ8+AIO8+AIM8+AIK8+AII8 -> 0 | AIZ8: =AIY8+AIX8 -> 0 | AJA8: =AIH8+AGV8+AGC8+AFJ8+AEQ8+ADX8+ADE8+ACL8+ABS8+AAZ8+AAG8+ZN8+YU8+YB8+XI8+WP8+VW8+VD8+UK8+TR8+SY8+SF8+RM8+QT8+QA8+PH8+OO8+NV8+NC8+MJ8+LQ8+AHO8 -> 0 | AJB8: =AII8+AGW8+AGD8+AFK8+AER8+ADY8+ADF8+ACM8+ABT8+ABA8+AAH8+ZO8+YV8+YC8+XJ8+WQ8+VX8+VE8+UL8+TS8+SZ8+SG8+RN8+QU8+QB8+PI8+OP8+NW8+ND8+MK8+LR8+AHP8 -> 0 | AJC8: =AIJ8+AGX8+AGE8+AFL8+AES8+ADZ8+ADG8+ACN8+ABU8+ABB8+AAI8+ZP8+YW8+YD8+XK8+WR8+VY8+VF8+UM8+TT8+TA8+SH8+RO8+QV8+QC8+PJ8+OQ8+NX8+NE8+ML8+LS8+AHQ8 -> 0 | AJD8: =AIK8+AGY8+AGF8+AFM8+AET8+AEA8+ADH8+ACO8+ABV8+ABC8+AAJ8+ZQ8+YX8+YE8+XL8+WS8+VZ8+VG8+UN8+TU8+TB8+SI8+RP8+QW8+QD8+PK8+OR8+NY8+NF8+MM8+LT8+AHR8 -> 0 | AJE8: =AIL8+AGZ8+AGG8+AFN8+AEU8+AEB8+ADI8+ACP8+ABW8+ABD8+AAK8+ZR8+YY8+YF8+XM8+WT8+WA8+VH8+UO8+TV8+TC8+SJ8+RQ8+QX8+QE8+PL8+OS8+NZ8+NG8+MN8+LU8+AHS8 -> 0 | AJF8: =AIM8+AHA8+AGH8+AFO8+AEV8+AEC8+ADJ8+ACQ8+ABX8+ABE8+AAL8+ZS8+YZ8+YG8+XN8+WU8+WB8+VI8+UP8+TW8+TD8+SK8+RR8+QY8+QF8+PM8+OT8+OA8+NH8+MO8+LV8+AHT8 -> 0 | AJG8: =AIN8+AHB8+AGI8+AFP8+AEW8+AED8+ADK8+ACR8+ABY8+ABF8+AAM8+ZT8+ZA8+YH8+XO8+WV8+WC8+VJ8+UQ8+TX8+TE8+SL8+RS8+QZ8+QG8+PN8+OU8+OB8+NI8+MP8+LW8+AHU8 -> 5 | AJH8: =AIO8+AHC8+AGJ8+AFQ8+AEX8+AEE8+ADL8+ACS8+ABZ8+ABG8+AAN8+ZU8+ZB8+YI8+XP8+WW8+WD8+VK8+UR8+TY8+TF8+SM8+RT8+RA8+QH8+PO8+OV8+OC8+NJ8+MQ8+LX8+AHV8 -> 0 | ... AJP8: =AIW8+AHK8+AGR8+AFY8+AFF8+AEM8+ADT8+ADA8+ACH8+ABO8+AAV8+AAC8+ZJ8+YQ8+XX8+XE8+WL8+VS8+UZ8+UG8+TN8+SU8+SB8+RI8+QP8+PW8+PD8+OK8+NR8+MY8+MF8+AID8 -> 0 | AJQ8: =AJO8+AJM8+AJK8+AJI8+AJE8+AJG8+AJC8+AJA8 -> 8 | AJR8: =AJP8+AJN8+AJL8+AJJ8+AJF8+AJH8+AJD8+AJB8 -> 0 | AJS8: =AJR8+AJQ8 -> 8 | AJT8: 1 | AJV8: 2 | AJX8: 2 | AJZ8: 3 | AKB8: =AJX8+AJV8+AJT8+AJZ8 -> 8 | AKC8: =AJY8+AJW8+AJU8+AKA8 -> 0 | AKD8: =AKC8+AKB8 -> 8 | AKG8: 3 | AKI8: 1 | AKK8: 4 | AKO8: =AKM8+AKK8+AKI8+AKG8+AKE8 -> 8 | AKP8: =AKN8+AKL8+AKJ8+AKH8+AKF8 -> 0 | AKQ8: =AKP8+AKO8 -> 8 | AKT8: 8 | AKZ8: =AKX8+AKV8+AKT8+AKR8 -> 8 | ALA8: =AKY8+AKW8+AKU8+AKS8 -> 0 | ALB8: =SUM(AKZ8:ALA8) -> 8 | ALC8: 1 | ALE8: 1 | ALG8: 2014 | ALJ8: 1 | ALM8: 1 | ALP8: 1 | ALR8: 18 | ALS8: 12 | ALX8: 1 | ALZ8: 1 | AMF8: 1 | AMI8: 1 | AMJ8: 1 | AML8: 1 | AMO8: 1 | AMP8: 1 | AMR8: 1 | AMW8: 1 | AMY8: 1 | ANB8: 1 | AND8: 1 | ANI8: 1 | ANK8: 1 | ANN8: 1 | ANP8: 1 | ANT8: 1 | ANZ8: 150 | AOD8: 10 | AOH8: 2 | AOM8: 1 | AOY8: =AOX8+AOW8 -> 0 | APA8: 1 | APP8: علي رافع عبداكاظم | APQ8: 7813968478
