Workbook

Sheet رياض
A1: المديرية العامة للتربية في محافظة النجف الاشرف | H1: جنس الروضة | K1: بيئة الروضة | M1: دوام الروضة | Y1: عدد الاطفال المسجلين في الروضة حسب المرحلة للسنة الدراسية 2025/2026 | AF1: عدد الشعب بالروضة حسب المرحلة و الجنس | AI1: عدد الاطفال التاركين بالروضة حسب المرحلة و الجنس للسنة الدراسية 2025/2024 | AP1: عدد الاطفال المسجلين من غير العراقيين بالروضة حسب المرحلة و الجنس | AW1: هل الروضة مشمولة بـ تعلم الحاسوب | AY1: هل الروضة مشمولة بالارشاد التربوي | BA1: هل الروضة مشمولة بالتغذية | BC1: هل مشمولة بخدمة الانترنت | BE1: هل الروضة مشمولة بـ تعلم اللغات الاجنبية | BG1: نوع اللغة | BK1: اللغات المحلية | BN1: اعضاء الهيئة التعليمية حسب العنوان الوظيفي | BS1: عدد الملاك الاداري والخدمي حسب العنوان الوظيفي | CN1: عدد اعضاء الهئية التعليمية حسب الجنسية | CR1: عدد اعضاء الهيئة التعليمية حسب الحالة الوظيفية | DB1: المجموع الكلي | DM1: عدد اعضاء الهيئة التعليمية حسب الحالة الاجتماعية | DR1: عدد المعلمين المشاركين بدورات تدريبية للعام الماضي | DS1: عدد اعضاء الهيئة التعليمية حسب سنوات الخدمة | EF1: عدد اعضاء الهيئة التعليمية حسب العمر | ES1: الأبنية المدرسية | HL1: التجهيزات والاثاث :- | HR1: الحاسبات :- | HX1: هل توجد مكتبة | HZ1: المسؤول عنها | ID1: نوع المكتبة | IH1: عدد الكتب | IJ1: عدد الكتب الكلي | IK1: اقرب نقطة دالة | IL1: اسم المدير | IM1: رقم الموبايل
Q2: استقلالية الروضة | T2: نوع الازدواج | X2: هل الروضة فتح جديد | CR2: داخل القوة | CS2: خارج القوة
A3: رياض الاطفال 2025/2026 | G3: الموقع | BS3: موظف ادارة | BU3: كاتب | BW3: محاسب | BY3: امينة مكتبة | CA3: مراقبة روضة | CC3: موظف خدمة | CE3: حارس | CG3: سائق | CI3: فلاح | CK3: المجموع | CN3: عراقية | CO3: عربية | CP3: اجنبية | CQ3: المجموع | CS3: بعثة او زمالة | CT3: اجازة دراسية | CU3: اجازة مصاحبة | CV3: اجازة بدون راتب | CW3: اجازة مرضية طويلة | CX3: اجازة امومة | CY3: منسب الى جهات اخرى | CZ3: 4-5سنوات | DA3: المجموع | DC3: دورات تربوية (اعدادية ومهني ودور المعلمات ) | DD3: معاهد اعداد المعلمات والمعاهد المركزية | DE3: معاهد فنون جميلة | DF3: جامعية | DI3: الشهادات العليا | DK3: اخرى | DL3: المجموع | ES3: نوع البناء | EU3: البناية | EX3: هل توجد مساحة للتوسعة | EZ3: عدد الطوابق | FC3: هل المدرسة بحاجة الى صفوف اضافية | FF3: حجم الروضة | FI3: عدد الغرف في البناية | FL3: مادة البناء | FS3: هل تتوفر في البناية مرافق صحية | FY3: هل ترتبط البناية بشبكة الماء الصالح للشرب | GA3: مصدر الماء | GF3: هل البناية مزودة بخدمة المجاري | GH3: نوع المجاري | GJ3: هل هناك سياج حول البناية | GL3: نوع السياج | GO3: حالة السياج | GR3: هل توجد ساحة رياضية | GT3: هل توجد حديقة مدرسية | GV3: هل توجد قاعة انشطة مستقلة | GX3: نوع الساحة الرياضية | HB3: عدد المدارس التي تشغلها | HE3: العائدية | HI3: الحالة العمرانية | HL3: عدد الرحلات المزدوجة (ذات المقعدين) الصالحة | HN3: عدد الرحلات (ذات المقعد الواحد) الصالحة | HP3: عدد لوحات الكتابة ( السبورات) الصالحة | HR3: عدد الحاسبات الالكترونية (كومبيوتر) | HT3: عدد الطابعات | HV3: عدد الماسحات الضوئية (سكنرات)
Y4: روضة | AA4: تمهيدي | AC4: المجموع | AF4: روضة | AG4: تمهيدي | AH4: المجموع | AI4: روضة | AK4: تمهيدي | AM4: المجموع | AP4: روضة | AR4: تمهيدي | AT4: المجموع | BN4: مديرة | BO4: معاونة | BP4: معلمة | BQ4: مرشدة | BR4: المجموع | BS4: ذكور | BT4: اناث | BU4: ذكور | BV4: اناث | BW4: ذكور | BX4: اناث | BY4: ذكور | BZ4: اناث | CA4: ذكور | CB4: اناث | CC4: ذكور | CD4: اناث | CE4: ذكور | CF4: اناث | CG4: ذكور | CH4: اناث | CI4: ذكور | CJ4: اناث | CK4: ذكور | CL4: اناث | CM4: المجموع | CU4: ذكور | CV4: ذكور | CW4: ذكور | CX4: ذكور | DS4: 5سنوات فاقل | DU4: 10-6 | DW4: 15-11 | DY4: 16-20 | EA4: اكثر من21 | EC4: المجموع | EF4: اقل من 30 | EH4: 39-30 | EJ4: 49-40 | EL4: 59-50 | EN4: 60سنة فاكثر | EP4: المجموع
A5: ت | B5: الرقم الاحصائي | C5: المحافظة | D5: القضاء | E5: الناحية | F5: اسم الروضة | H5: بنون | I5: بنات | J5: مختلط | K5: حضر | L5: ريف | M5: صباحا | N5: ظهرا | O5: صباحا وظهرا | P5: مساءا | Q5: اصلية | R5: ضيف | S5: استضافة | T5: غير مزدوجة | U5: مع نفسها | V5: مع اخرى | W5: مع نفسها ومع اخرى | Y5: بنون | Z5: بنات | AA5: بنون | AB5: بنات | AC5: بنون | AD5: بنات | AE5: المجموع | AI5: بنون | AJ5: بنات | AK5: بنون | AL5: بنات | AM5: بنون | AN5: بنات | AO5: المجموع | AP5: بنون | AQ5: بنات | AR5: بنون | AS5: بنات | AT5: بنون | AU5: بنات | AV5: المجموع | AW5: نعم | AX5: كلا | AY5: نعم | AZ5: كلا | BA5: نعم | BB5: كلا | BC5: نعم | BD5: كلا | BE5: نعم | BF5: كلا | BG5: الانكليزي | BH5: فرنسي | BI5: اسباني | BJ5: اخرى | BK5: كردية | BL5: تركمانية | BM5: سيريانية | DF5: تربوية | DG5: رياض | DH5: غير تربوية | DI5: ماجستير | DJ5: دكتوراه | DM5: اعزب | DN5: متزوج | DO5: ارمل | DP5: مطلق | DQ5: المجموع | DR5: عدد المعلمات | DS5: ذكور | DT5: اناث | DU5: ذكور | DV5: اناث | DW5: ذكور | DX5: اناث | DY5: ذكور | DZ5: اناث | EA5: ذكور | EB5: اناث | EC5: ذكور | ED5: اناث | EE5: المجموع | EF5: ذكور | EG5: اناث | EH5: ذكور | EI5: اناث | EJ5: ذكور | EK5: اناث | EL5: ذكور | EM5: اناث | EN5: ذكور | EO5: اناث | EP5: ذكور | EQ5: اناث | ER5: المجموع | ES5: مدرسي | ET5: غير مدرسي | EU5: سنة البناء | EV5: رقم القطعة | EW5: رقم المقاطعة | EX5: نعم | EY5: كلا | EZ5: طابق واحد | FA5: طابقين | FB5: ثلاث طوابق | FC5: نعم | FD5: كلا | FE5: عدد الصفوف الاضافية | FF5: 6صف | FG5: 9صف | FH5: 12صف | FI5: عدد الصفوف | FJ5: عدد الغرف الاخرى | FK5: المجموع | FL5: طابوق او حجر او بلوك | FM5: طين | FN5: صريفة او خيمة | FO5: بناء جاهز | FP5: هياكل حديدية | FQ5: كرفان | FR5: اخرى | FS5: نعم | FT5: كلا | FU5: صالحة | FV5: غير صالحة | FW5: كافية | FX5: غير كافية | FY5: نعم | FZ5: كلا | GA5: بلدية | GB5: بئر عميق | GC5: نهر | GD5: صهاريج | GE5: اخرى | GF5: نعم | GG5: كلا | GH5: شبكة مجاري | GI5: خزانات | GJ5: نعم | GK5: كلا | GL5: بناء | GM5: اسلاك | GN5: اخرى | GO5: جيد | GP5: متصدع | GQ5: غير امن | GR5: نعم | GS5: كلا | GT5: نعم | GU5: كلا | GV5: نعم | GW5: كلا | GX5: رياضية مبلطة | GY5: مزروعة بالثيل | GZ5: بالرمل والماء | HA5: اخرى | HB5: مدرسة واحدة | HC5: مدرستان | HD5: ثلاث مدارس | HE5: حكومية تابعة لوزارة التربية | HF5: حكومية تابعة لجهات اخرى | HG5: مستأجرة | HH5: خاصة | HI5: صالحة | HJ5: بحاجة الى ترميم | HK5: غير صالحة | HL5: الصالحة | HM5: غيرالصالحة | HN5: الصالحة | HO5: غيرالصالحة | HP5: الصالحة | HQ5: غيرالصالحة | HR5: الصالحة | HS5: عاطلة | HT5: الصالحة | HU5: عاطلة | HV5: الصالحة | HW5: عاطلة | HX5: نعم | HY5: كلا | HZ5: المدير | IA5: المعاون | IB5: المعلم | IC5: امينة مكتبة | ID5: قاعة | IE5: غرفة | IF5: خزانة | IG5: رفوف عارضة | IH5: عدد الكتب | II5: عدد المجلات والقصص
A6: 1 | B6: 1400135 | C6: النجف | D6: النجف | E6: المركز | F6: اطفال النجف | G6: السعد | J6: 1 | K6: 1 | M6: 1 | Q6: 1 | T6: 1 | Y6: 15 | Z6: 18 | AA6: 38 | AB6: 37 | AC6: =AA6+Y6 -> 53 | AD6: =AB6+Z6 -> 55 | AE6: =AD6+AC6 -> 108 | AF6: 1 | AG6: 2 | AH6: =AG6+AF6 -> 3 | AM6: =AK6+AI6 -> 0 | AN6: =AL6+AJ6 -> 0 | AO6: =AN6+AM6 -> 0 | AT6: =AR6+AP6 -> 0 | AU6: =AS6+AQ6 -> 0 | AV6: =AU6+AT6 -> 0 | AX6: 1 | AZ6: 1 | BB6: 1 | BD6: 1 | BF6: 1 | BN6: 1 | BO6: 1 | BP6: 9 | BR6: =BQ6+BP6+BO6+BN6 -> 11 | CD6: 1 | CK6: =CI6+CG6+CE6+CC6+CA6+BY6+BW6+BS6 -> 0 | CL6: =CJ6+CH6+CD6+CB6+BZ6+BX6+BV6+BT6 -> 1 | CM6: =CL6+CK6 -> 1 | CN6: 11 | CQ6: =CP6+CO6+CN6 -> 11 | CR6: 8 | CW6: 2 | CX6: 1 | DA6: =CY6+CX6+CW6+CV6+CU6+CT6+CS6+CZ6 -> 3 | DB6: =DA6+CR6 -> 11 | DD6: 3 | DF6: 2 | DG6: 5 | DI6: 1 | DL6: =DK6+DJ6+DI6+DH6+DG6+DF6+DE6+DD6+DC6 -> 11 | DN6: 9 | DO6: 1 | DP6: 1 | DQ6: =DP6+DO6+DN6+DM6 -> 11 | DR6: 1 | DT6: 2 | DV6: 4 | DZ6: 5 | EC6: =DW6+DU6+DS6+DY6 -> 0 | ED6: =DX6+DV6+DT6+DZ6 -> 11 | EE6: =ED6+EC6 -> 11 | EG6: 1 | EI6: 4 | EK6: 2 | EM6: 4 | EP6: =EN6+EL6+EJ6+EH6+EF6 -> 0 | EQ6: =EO6+EM6+EK6+EI6+EG6 -> 11 | ER6: =EQ6+EP6 -> 11 | ES6: 1 | EU6: 1955 | EV6: 3188/149 | EW6: 2 | EX6: 1 | EZ6: 1 | FC6: 1 | FE6: 4 | FG6: 1 | FI6: 6 | FJ6: 4 | FK6: =FJ6+FI6 -> 10 | FL6: 1 | FS6: 1 | FU6: 1 | FW6: 1 | FY6: 1 | GA6: 1 | GF6: 1 | GH6: 1 | GJ6: 1 | GL6: 1 | GO6: 1 | GR6: 1 | GT6: 1 | GW6: 1 | GX6: 1 | HB6: 1 | HF6: 1 | HJ6: 1 | HN6: 100 | HO6: 60 | HP6: 5 | HQ6: 1 | HR6: 2 | HS6: 1 | HT6: 1 | HU6: 1 | HX6: 1 | HZ6: 1 | IF6: 1 | IH6: 62 | II6: 527 | IJ6: =II6+IH6 -> 589 | IK6: دائرة الاشراف | IL6: انوار نوري حسن | IM6: 7809359640
A7: 2 | B7: 1400136 | C7: النجف | D7: النجف | E7: المركز | F7: الحوراء | G7: الجديدة الثانية | J7: 1 | K7: 1 | M7: 1 | Q7: 1 | T7: 1 | Y7: 41 | Z7: 39 | AA7: 60 | AB7: 60 | AC7: =AA7+Y7 -> 101 | AD7: =AB7+Z7 -> 99 | AE7: =AD7+AC7 -> 200 | AF7: 2 | AG7: 2 | AH7: =AG7+AF7 -> 4 | AI7: 11 | AJ7: 6 | AK7: 5 | AL7: 1 | AM7: =AK7+AI7 -> 16 | AN7: =AL7+AJ7 -> 7 | AO7: =AN7+AM7 -> 23 | AQ7: 3 | AR7: 1 | AS7: 4 | AT7: =AR7+AP7 -> 1 | AU7: =AS7+AQ7 -> 7 | AV7: =AU7+AT7 -> 8 | AX7: 1 | AZ7: 1 | BB7: 1 | BD7: 1 | BF7: 1 | BN7: 1 | BP7: 6 | BR7: =BQ7+BP7+BO7+BN7 -> 7 | CD7: 1 | CE7: 1 | CK7: =CI7+CG7+CE7+CC7+CA7+BY7+BW7+BS7 -> 1 | CL7: =CJ7+CH7+CD7+CB7+BZ7+BX7+BV7+BT7 -> 1 | CM7: =CL7+CK7 -> 2 | CN7: 7 | CQ7: =CP7+CO7+CN7 -> 7 | CR7: 7 | DA7: =CY7+CX7+CW7+CV7+CU7+CT7+CS7+CZ7 -> 0 | DB7: =DA7+CR7 -> 7 | DD7: 1 | DG7: 6 | DL7: =DK7+DJ7+DI7+DH7+DG7+DF7+DE7+DD7+DC7 -> 7 | DM7: 1 | DN7: 6 | DQ7: =DP7+DO7+DN7+DM7 -> 7 | DT7: 6 | DZ7: 1 | EC7: =DW7+DU7+DS7+DY7 -> 0 | ED7: =DX7+DV7+DT7+DZ7 -> 7 | EE7: =ED7+EC7 -> 7 | EI7: 4 | EK7: 1 | EM7: 2 | EP7: =EN7+EL7+EJ7+EH7+EF7 -> 0 | EQ7: =EO7+EM7+EK7+EI7+EG7 -> 7 | ER7: =EQ7+EP7 -> 7 | ES7: 1 | EU7: 1982 | EV7: 1772/2 | EW7: 2 | EX7: 1 | FA7: 1 | FC7: 1 | FE7: 4 | FG7: 1 | FI7: 9 | FJ7: 3 | FK7: =FJ7+FI7 -> 12 | FL7: 1 | FS7: 1 | FU7: 1 | FW7: 1 | FY7: 1 | GA7: 1 | GF7: 1 | GI7: 1 | GJ7: 1 | GL7: 1 | GP7: 1 | GR7: 1 | GT7: 1 | GW7: 1 | GY7: 1 | HB7: 1 | HF7: 1 | HJ7: 1 | HN7: 44 | HO7: 15 | HP7: 6 | HR7: 1 | HT7: 1 | HX7: 1 | HZ7: 1 | IF7: 1 | II7: 306 | IJ7: =II7+IH7 -> 306 | IK7: ع0النجف المركزية | IL7: سندس ناجح عبدالزهره | IM7: 7825989301
A8: 3 | B8: 1400137 | C8: النجف | D8: النجف | E8: المركز | F8: الاجيال | G8: الصحة | J8: 1 | K8: 1 | M8: 1 | Q8: 1 | T8: 1 | Y8: 23 | Z8: 23 | AA8: 9 | AB8: 16 | AC8: =AA8+Y8 -> 32 | AD8: =AB8+Z8 -> 39 | AE8: =AD8+AC8 -> 71 | AF8: 2 | AG8: 2 | AH8: =AG8+AF8 -> 4 | AJ8: 2 | AK8: 2 | AL8: 1 | AM8: =AK8+AI8 -> 2 | AN8: =AL8+AJ8 -> 3 | AO8: =AN8+AM8 -> 5 | AP8: 7 | AQ8: 1 | AR8: 2 | AS8: 1 | AT8: =AR8+AP8 -> 9 | AU8: =AS8+AQ8 -> 2 | AV8: =AU8+AT8 -> 11 | AW8: 1 | AZ8: 1 | BB8: 1 | BC8: 1 | BF8: 1 | BN8: 1 | BO8: 1 | BP8: 8 | BR8: =BQ8+BP8+BO8+BN8 -> 10 | CB8: 2 | CE8: 1 | CK8: =CI8+CG8+CE8+CC8+CA8+BY8+BW8+BS8 -> 1 | CL8: =CJ8+CH8+CD8+CB8+BZ8+BX8+BV8+BT8 -> 2 | CM8: =CL8+CK8 -> 3 | CN8: 10 | CQ8: =CP8+CO8+CN8 -> 10 | CR8: 9 | CZ8: 1 | DA8: =CY8+CX8+CW8+CV8+CU8+CT8+CS8+CZ8 -> 1 | DB8: =DA8+CR8 -> 10 | DC8: 1 | DD8: 4 | DF8: 1 | DG8: 4 | DL8: =DK8+DJ8+DI8+DH8+DG8+DF8+DE8+DD8+DC8 -> 10 | DM8: 2 | DN8: 7 | DO8: 1 | DQ8: =DP8+DO8+DN8+DM8 -> 10 | DR8: 10 | DT8: 4 | DX8: 1 | DZ8: 5 | EC8: =DW8+DU8+DS8+DY8 -> 0 | ED8: =DX8+DV8+DT8+DZ8 -> 10 | EE8: =ED8+EC8 -> 10 | EI8: 4 | EK8: 2 | EM8: 4 | EP8: =EN8+EL8+EJ8+EH8+EF8 -> 0 | EQ8: =EO8+EM8+EK8+EI8+EG8 -> 10 | ER8: =EQ8+EP8 -> 10 | ES8: 1 | EU8: 1973 | EV8: 17254/2 | EW8: 2 | EY8: 1 | EZ8: 1 | FD8: 1 | FF8: 1 | FI8: 6 | FJ8: 5 | FK8: =FJ8+FI8 -> 11 | FL8: 1 | FS8: 1 | FU8: 1 | FW8: 1 | FY8: 1 | GA8: 1 | GF8: 1 | GH8: 1 | GJ8: 1 | GL8: 1 | GO8: 1 | GR8: 1 | GT8: 1 | GW8: 1 | GX8: 1 | HB8: 1 | HF8: 1 | HI8: 1 | HN8: 109 | HO8: 30 | HP8: 6 | HQ8: 3 | HR8: 1 | HT8: 1 | HU8: 1 | HX8: 1 | IB8: 1 | IF8: 1 | IH8: 97 | II8: 100 | IJ8: =II8+IH8 -> 197 | IK8: شرطة الكرار | IL8: فوزية شمران غيدان | IM8: 7816033328
A9: 4 | B9: 1400138 | C9: النجف | D9: النجف | E9: المركز | F9: البراعم | G9: الاسكان | J9: 1 | K9: 1 | M9: 1 | Q9: 1 | T9: 1 | Y9: 14 | Z9: 11 | AA9: 20 | AB9: 16 | AC9: =AA9+Y9 -> 34 | AD9: =AB9+Z9 -> 27 | AE9: =AD9+AC9 -> 61 | AF9: 1 | AG9: 1 | AH9: =AG9+AF9 -> 2 | AM9: =AK9+AI9 -> 0 | AN9: =AL9+AJ9 -> 0 | AO9: =AN9+AM9 -> 0 | AT9: =AR9+AP9 -> 0 | AU9: =AS9+AQ9 -> 0 | AV9: =AU9+AT9 -> 0 | AW9: 1 | AZ9: 1 | BB9: 1 | BD9: 1 | BF9: 1 | BN9: 1 | BP9: 9 | BR9: =BQ9+BP9+BO9+BN9 -> 10 | CB9: 2 | CD9: 1 | CE9: 1 | CK9: =CI9+CG9+CE9+CC9+CA9+BY9+BW9+BS9 -> 1 | CL9: =CJ9+CH9+CD9+CB9+BZ9+BX9+BV9+BT9 -> 3 | CM9: =CL9+CK9 -> 4 | CN9: 10 | CQ9: =CP9+CO9+CN9 -> 10 | CR9: 3 | CW9: 6 | CX9: 1 | DA9: =CY9+CX9+CW9+CV9+CU9+CT9+CS9+CZ9 -> 7 | DB9: =DA9+CR9 -> 10 | DD9: 5 | DF9: 2 | DG9: 2 | DH9: 1 | DL9: =DK9+DJ9+DI9+DH9+DG9+DF9+DE9+DD9+DC9 -> 10 | DN9: 9 | DO9: 1 | DQ9: =DP9+DO9+DN9+DM9 -> 10 | DR9: 3 | DT9: 1 | DX9: 2 | DZ9: 7 | EC9: =DW9+DU9+DS9+DY9 -> 0 | ED9: =DX9+DV9+DT9+DZ9 -> 10 | EE9: =ED9+EC9 -> 10 | EI9: 3 | EK9: 5 | EM9: 2 | EP9: =EN9+EL9+EJ9+EH9+EF9 -> 0 | EQ9: =EO9+EM9+EK9+EI9+EG9 -> 10 | ER9: =EQ9+EP9 -> 10 | ES9: 1 | EU9: 1967 | EV9: 11576/2 | EW9: 2 | EX9: 1 | EZ9: 1 | FD9: 1 | FE9: 2 | FF9: 1 | FI9: 6 | FJ9: 3 | FK9: =FJ9+FI9 -> 9 | FL9: 1 | FS9: 1 | FU9: 1 | FW9: 1 | FY9: 1 | GA9: 1 | GF9: 1 | GH9: 1 | GJ9: 1 | GL9: 1 | GO9: 1 | GR9: 1 | GT9: 1 | GW9: 1 | GY9: 1 | HB9: 1 | HF9: 1 | HJ9: 1 | HN9: 25 | HP9: 4 | HR9: 2 | HT9: 1 | HV9: 1 | HX9: 1 | HZ9: 1 | IE9: 1 | IH9: 1179 | IJ9: =II9+IH9 -> 1179 | IK9: شارع الروان | IL9: زهراء يحيى محمد | IM9: 7725713323
A10: 5 | B10: 1400139 | C10: النجف | D10: النجف | E10: المركز | F10: الزيتون | G10: المعلمين | J10: 1 | K10: 1 | M10: 1 | Q10: 1 | T10: 1 | Y10: 27 | Z10: 43 | AA10: 23 | AB10: 27 | AC10: =AA10+Y10 -> 50 | AD10: =AB10+Z10 -> 70 | AE10: =AD10+AC10 -> 120 | AF10: 1 | AG10: 2 | AH10: =AG10+AF10 -> 3 | AM10: =AK10+AI10 -> 0 | AN10: =AL10+AJ10 -> 0 | AO10: =AN10+AM10 -> 0 | AT10: =AR10+AP10 -> 0 | AU10: =AS10+AQ10 -> 0 | AV10: =AU10+AT10 -> 0 | AX10: 1 | AZ10: 1 | BB10: 1 | BD10: 1 | BF10: 1 | BN10: 1 | BO10: 1 | BP10: 5 | BR10: =BQ10+BP10+BO10+BN10 -> 7 | BT10: 1 | CD10: 1 | CE10: 1 | CK10: =CI10+CG10+CE10+CC10+CA10+BY10+BW10+BS10 -> 1 | CL10: =CJ10+CH10+CD10+CB10+BZ10+BX10+BV10+BT10 -> 2 | CM10: =CL10+CK10 -> 3 | CN10: 7 | CQ10: =CP10+CO10+CN10 -> 7 | CR10: 7 | DA10: =CY10+CX10+CW10+CV10+CU10+CT10+CS10+CZ10 -> 0 | DB10: =DA10+CR10 -> 7 | DD10: 4 | DF10: 2 | DH10: 1 | DL10: =DK10+DJ10+DI10+DH10+DG10+DF10+DE10+DD10+DC10 -> 7 | DM10: 1 | DN10: 6 | DQ10: =DP10+DO10+DN10+DM10 -> 7 | DV10: 2 | DX10: 2 | DZ10: 3 | EC10: =DW10+DU10+DS10+DY10 -> 0 | ED10: =DX10+DV10+DT10+DZ10 -> 7 | EE10: =ED10+EC10 -> 7 | EI10: 1 | EK10: 4 | EM10: 2 | EP10: =EN10+EL10+EJ10+EH10+EF10 -> 0 | EQ10: =EO10+EM10+EK10+EI10+EG10 -> 7 | ER10: =EQ10+EP10 -> 7 | ES10: 1 | EU10: 1978 | EV10: 10990/2 | EW10: م2 | EX10: 1 | EZ10: 1 | FC10: 1 | FE10: 2 | FF10: 1 | FI10: 4 | FJ10: 6 | FK10: =FJ10+FI10 -> 10 | FL10: 1 | FS10: 1 | FU10: 1 | FW10: 1 | FY10: 1 | GA10: 1 | GF10: 1 | GI10: 1 | GJ10: 1 | GL10: 1 | GO10: 1 | GR10: 1 | GT10: 1 | GW10: 1 | HA10: 1 | HB10: 1 | HF10: 1 | HI10: 1 | HN10: 24 | HO10: 9 | HP10: 4 | HR10: 1 | HT10: 1 | HX10: 1 | HZ10: 1 | IF10: 1 | II10: 261 | IJ10: =II10+IH10 -> 261 | IK10: م0 ميسلون | IL10: زينب شاكر كاظم | IM10: 7861911415
A11: 6 | B11: 1400140 | C11: النجف | D11: النجف | E11: المركز | F11: النرجس | G11: الانصار | J11: 1 | K11: 1 | M11: 1 | Q11: 1 | T11: 1 | Y11: 53 | Z11: 59 | AA11: 41 | AB11: 35 | AC11: =AA11+Y11 -> 94 | AD11: =AB11+Z11 -> 94 | AE11: =AD11+AC11 -> 188 | AF11: 2 | AG11: 2 | AH11: =AG11+AF11 -> 4 | AI11: 10 | AJ11: 13 | AK11: 10 | AL11: 10 | AM11: =AK11+AI11 -> 20 | AN11: =AL11+AJ11 -> 23 | AO11: =AN11+AM11 -> 43 | AT11: =AR11+AP11 -> 0 | AU11: =AS11+AQ11 -> 0 | AV11: =AU11+AT11 -> 0 | AX11: 1 | AZ11: 1 | BB11: 1 | BD11: 1 | BF11: 1 | BN11: 1 | BO11: 1 | BP11: 6 | BR11: =BQ11+BP11+BO11+BN11 -> 8 | BT11: 2 | CB11: 1 | CD11: 1 | CE11: 1 | CK11: =CI11+CG11+CE11+CC11+CA11+BY11+BW11+BS11 -> 1 | CL11: =CJ11+CH11+CD11+CB11+BZ11+BX11+BV11+BT11 -> 4 | CM11: =CL11+CK11 -> 5 | CN11: 8 | CQ11: =CP11+CO11+CN11 -> 8 | CR11: 6 | CW11: 1 | CX11: 1 | DA11: =CY11+CX11+CW11+CV11+CU11+CT11+CS11+CZ11 -> 2 | DB11: =DA11+CR11 -> 8 | DD11: 1 | DF11: 1 | DG11: 5 | DH11: 1 | DL11: =DK11+DJ11+DI11+DH11+DG11+DF11+DE11+DD11+DC11 -> 8 | DM11: 1 | DN11: 6 | DO11: 1 | DQ11: =DP11+DO11+DN11+DM11 -> 8 | DR11: 8 | DV11: 5 | DZ11: 3 | EC11: =DW11+DU11+DS11+DY11 -> 0 | ED11: =DX11+DV11+DT11+DZ11 -> 8 | EE11: =ED11+EC11 -> 8 | EI11: 3 | EK11: 3 | EM11: 2 | EP11: =EN11+EL11+EJ11+EH11+EF11 -> 0 | EQ11: =EO11+EM11+EK11+EI11+EG11 -> 8 | ER11: =EQ11+EP11 -> 8 | ES11: 1 | EU11: 1980 | EV11: 9227/2 | EW11: 2 | EX11: 1 | EZ11: 1 | FC11: 1 | FE11: 6 | FF11: 1 | FI11: 4 | FJ11: 6 | FK11: =FJ11+FI11 -> 10 | FL11: 1 | FS11: 1 | FV11: 1 | FX11: 1 | FY11: 1 | GA11: 1 | GF11: 1 | GH11: 1 | GJ11: 1 | GL11: 1 | GP11: 1 | GR11: 1 | GT11: 1 | GW11: 1 | HA11: 1 | HB11: 1 | HF11: 1 | HJ11: 1 | HN11: 200 | HO11: 62 | HP11: 2 | HQ11: 3 | HR11: 1 | HS11: 1 | HT11: 1 | HX11: 1 | IA11: 1 | IE11: 1 | II11: 696 | IJ11: =II11+IH11 -> 696 | IK11: شارع البنزين خانة | IL11: هناء جبار شهيد | IM11: 7839217375
A12: 7 | B12: 1400141 | C12: النجف | D12: النجف | E12: المركز | F12: البيادر | G12: الحوراء زينب | J12: 1 | K12: 1 | M12: 1 | Q12: 1 | T12: 1 | Y12: 16 | Z12: 10 | AA12: 30 | AB12: 20 | AC12: =AA12+Y12 -> 46 | AD12: =AB12+Z12 -> 30 | AE12: =AD12+AC12 -> 76 | AF12: 1 | AG12: 1 | AH12: =AG12+AF12 -> 2 | AM12: =AK12+AI12 -> 0 | AN12: =AL12+AJ12 -> 0 | AO12: =AN12+AM12 -> 0 | AT12: =AR12+AP12 -> 0 | AU12: =AS12+AQ12 -> 0 | AV12: =AU12+AT12 -> 0 | AX12: 1 | AZ12: 1 | BB12: 1 | BC12: 1 | BF12: 1 | BN12: 1 | BP12: 5 | BR12: =BQ12+BP12+BO12+BN12 -> 6 | CD12: 1 | CK12: =CI12+CG12+CE12+CC12+CA12+BY12+BW12+BS12 -> 0 | CL12: =CJ12+CH12+CD12+CB12+BZ12+BX12+BV12+BT12 -> 1 | CM12: =CL12+CK12 -> 1 | CN12: 6 | CQ12: =CP12+CO12+CN12 -> 6 | CR12: 5 | CW12: 1 | DA12: =CY12+CX12+CW12+CV12+CU12+CT12+CS12+CZ12 -> 1 | DB12: =DA12+CR12 -> 6 | DD12: 2 | DF12: 2 | DH12: 1 | DI12: 1 | DL12: =DK12+DJ12+DI12+DH12+DG12+DF12+DE12+DD12+DC12 -> 6 | DN12: 6 | DQ12: =DP12+DO12+DN12+DM12 -> 6 | DR12: 1 | DT12: 1 | DZ12: 5 | EC12: =DW12+DU12+DS12+DY12 -> 0 | ED12: =DX12+DV12+DT12+DZ12 -> 6 | EE12: =ED12+EC12 -> 6 | EK12: 3 | EM12: 3 | EP12: =EN12+EL12+EJ12+EH12+EF12 -> 0 | EQ12: =EO12+EM12+EK12+EI12+EG12 -> 6 | ER12: =EQ12+EP12 -> 6 | ES12: 1 | EU12: 1981 | EV12: 10481/2 | EW12: 2 | EY12: 1 | EZ12: 1 | FD12: 1 | FF12: 1 | FI12: 4 | FJ12: 7 | FK12: =FJ12+FI12 -> 11 | FL12: 1 | FS12: 1 | FU12: 1 | FW12: 1 | FY12: 1 | GA12: 1 | GF12: 1 | GI12: 1 | GJ12: 1 | GL12: 1 | GO12: 1 | GR12: 1 | GT12: 1 | GV12: 1 | GX12: 1 | HB12: 1 | HF12: 1 | HJ12: 1 | HN12: 23 | HO12: 10 | HP12: 3 | HQ12: 2 | HR12: 1 | HT12: 1 | HX12: 1 | IB12: 1 | IE12: 1 | IH12: 135 | II12: 120 | IJ12: =II12+IH12 -> 255 | IK12: اعدادية الغري المهنية | IL12: حلا نجاح مرزة | IM12: 7802835692
A13: 8 | B13: 1400142 | C13: النجف | D13: النجف | E13: المركز | F13: الربيع | G13: الزهراء | J13: 1 | K13: 1 | M13: 1 | Q13: 1 | T13: 1 | Y13: 34 | Z13: 36 | AA13: 75 | AB13: 70 | AC13: =AA13+Y13 -> 109 | AD13: =AB13+Z13 -> 106 | AE13: =AD13+AC13 -> 215 | AF13: 2 | AG13: 2 | AH13: =AG13+AF13 -> 4 | AM13: =AK13+AI13 -> 0 | AN13: =AL13+AJ13 -> 0 | AO13: =AN13+AM13 -> 0 | AT13: =AR13+AP13 -> 0 | AU13: =AS13+AQ13 -> 0 | AV13: =AU13+AT13 -> 0 | AX13: 1 | AZ13: 1 | BB13: 1 | BD13: 1 | BF13: 1 | BN13: 1 | BO13: 1 | BP13: 7 | BR13: =BQ13+BP13+BO13+BN13 -> 9 | CD13: 1 | CK13: =CI13+CG13+CE13+CC13+CA13+BY13+BW13+BS13 -> 0 | CL13: =CJ13+CH13+CD13+CB13+BZ13+BX13+BV13+BT13 -> 1 | CM13: =CL13+CK13 -> 1 | CN13: 9 | CQ13: =CP13+CO13+CN13 -> 9 | CR13: 6 | CW13: 1 | CX13: 1 | CZ13: 1 | DA13: =CY13+CX13+CW13+CV13+CU13+CT13+CS13+CZ13 -> 3 | DB13: =DA13+CR13 -> 9 | DD13: 3 | DG13: 6 | DL13: =DK13+DJ13+DI13+DH13+DG13+DF13+DE13+DD13+DC13 -> 9 | DM13: 2 | DN13: 7 | DQ13: =DP13+DO13+DN13+DM13 -> 9 | DT13: 6 | DZ13: 3 | EC13: =DW13+DU13+DS13+DY13 -> 0 | ED13: =DX13+DV13+DT13+DZ13 -> 9 | EE13: =ED13+EC13 -> 9 | EI13: 4 | EK13: 5 | EP13: =EN13+EL13+EJ13+EH13+EF13 -> 0 | EQ13: =EO13+EM13+EK13+EI13+EG13 -> 9 | ER13: =EQ13+EP13 -> 9 | ES13: 1 | EU13: 1981 | EV13: 16614 | EW13: 2 | EX13: 1 | EZ13: 1 | FC13: 1 | FE13: 2 | FF13: 1 | FI13: 4 | FJ13: 8 | FK13: =FJ13+FI13 -> 12 | FL13: 1 | FS13: 1 | FV13: 1 | FW13: 1 | FY13: 1 | GA13: 1 | GF13: 1 | GI13: 1 | GJ13: 1 | GL13: 1 | GO13: 1 | GR13: 1 | GT13: 1 | GV13: 1 | GX13: 1 | HB13: 1 | HF13: 1 | HI13: 1 | HL13: 45 | HM13: 20 | HN13: 50 | HO13: 20 | HP13: 6 | HR13: 2 | HT13: 1 | HX13: 1 | IB13: 1 | IE13: 1 | IH13: 50 | II13: 120 | IJ13: =II13+IH13 -> 170 | IK13: السوق العصري -الزهراء | IL13: شيماء عبد المنعم هادي | IM13: 7802545032
A14: 9 | B14: 1400143 | C14: النجف | D14: النجف | E14: المركز | F14: الهديل | G14: العلماء | J14: 1 | K14: 1 | M14: 1 | Q14: 1 | T14: 1 | Y14: 41 | Z14: 33 | AA14: 50 | AB14: 42 | AC14: =AA14+Y14 -> 91 | AD14: =AB14+Z14 -> 75 | AE14: =AD14+AC14 -> 166 | AF14: 2 | AG14: 2 | AH14: =AG14+AF14 -> 4 | AK14: 12 | AL14: 10 | AM14: =AK14+AI14 -> 12 | AN14: =AL14+AJ14 -> 10 | AO14: =AN14+AM14 -> 22 | AT14: =AR14+AP14 -> 0 | AU14: =AS14+AQ14 -> 0 | AV14: =AU14+AT14 -> 0 | AX14: 1 | AZ14: 1 | BB14: 1 | BD14: 1 | BF14: 1 | BN14: 1 | BO14: 1 | BP14: 6 | BR14: =BQ14+BP14+BO14+BN14 -> 8 | CB14: 1 | CD14: 2 | CE14: 1 | CK14: =CI14+CG14+CE14+CC14+CA14+BY14+BW14+BS14 -> 1 | CL14: =CJ14+CH14+CD14+CB14+BZ14+BX14+BV14+BT14 -> 3 | CM14: =CL14+CK14 -> 4 | CN14: 8 | CQ14: =CP14+CO14+CN14 -> 8 | CR14: 6 | CW14: 1 | CX14: 1 | DA14: =CY14+CX14+CW14+CV14+CU14+CT14+CS14+CZ14 -> 2 | DB14: =DA14+CR14 -> 8 | DD14: 2 | DF14: 2 | DG14: 4 | DL14: =DK14+DJ14+DI14+DH14+DG14+DF14+DE14+DD14+DC14 -> 8 | DM14: 1 | DN14: 6 | DP14: 1 | DQ14: =DP14+DO14+DN14+DM14 -> 8 | DT14: 3 | DV14: 1 | DX14: 1 | DZ14: 3 | EC14: =DW14+DU14+DS14+DY14 -> 0 | ED14: =DX14+DV14+DT14+DZ14 -> 8 | EE14: =ED14+EC14 -> 8 | EI14: 3 | EK14: 1 | EM14: 4 | EP14: =EN14+EL14+EJ14+EH14+EF14 -> 0 | EQ14: =EO14+EM14+EK14+EI14+EG14 -> 8 | ER14: =EQ14+EP14 -> 8 | ES14: 1 | EU14: 1981 | EV14: 2961/2 | EW14: 2 | EX14: 1 | EZ14: 1 | FC14: 1 | FE14: 2 | FF14: 1 | FI14: 4 | FJ14: 6 | FK14: =FJ14+FI14 -> 10 | FL14: 1 | FS14: 1 | FU14: 1 | FW14: 1 | FY14: 1 | GA14: 1 | GF14: 1 | GI14: 1 | GJ14: 1 | GL14: 1 | GQ14: 1 | GR14: 1 | GT14: 1 | GV14: 1 | GX14: 1 | HB14: 1 | HF14: 1 | HJ14: 1 | HL14: 60 | HN14: 60 | HO14: 60 | HP14: 4 | HQ14: 12 | HR14: 1 | HS14: 1 | HT14: 2 | HX14: 1 | IB14: 1 | IG14: 1 | II14: 490 | IJ14: =II14+IH14 -> 490 | IK14: جامع الفرطوسي | IL14: تغريد سعيد كريم | IM14: 7801532325
A15: 10 | B15: 1400144 | C15: النجف | D15: النجف | E15: المركز | F15: الشهيدة احلام رزاق | G15: الغري | J15: 1 | K15: 1 | M15: 1 | Q15: 1 | T15: 1 | Y15: 39 | Z15: 25 | AA15: 48 | AB15: 56 | AC15: =AA15+Y15 -> 87 | AD15: =AB15+Z15 -> 81 | AE15: =AD15+AC15 -> 168 | AF15: 2 | AG15: 2 | AH15: =AG15+AF15 -> 4 | AM15: =AK15+AI15 -> 0 | AN15: =AL15+AJ15 -> 0 | AO15: =AN15+AM15 -> 0 | AT15: =AR15+AP15 -> 0 | AU15: =AS15+AQ15 -> 0 | AV15: =AU15+AT15 -> 0 | AX15: 1 | AZ15: 1 | BB15: 1 | BD15: 1 | BF15: 1 | BN15: 1 | BP15: 12 | BR15: =BQ15+BP15+BO15+BN15 -> 13 | CD15: 3 | CE15: 1 | CK15: =CI15+CG15+CE15+CC15+CA15+BY15+BW15+BS15 -> 1 | CL15: =CJ15+CH15+CD15+CB15+BZ15+BX15+BV15+BT15 -> 3 | CM15: =CL15+CK15 -> 4 | CN15: 13 | CQ15: =CP15+CO15+CN15 -> 13 | CR15: 9 | CW15: 2 | CZ15: 2 | DA15: =CY15+CX15+CW15+CV15+CU15+CT15+CS15+CZ15 -> 4 | DB15: =DA15+CR15 -> 13 | DC15: 1 | DD15: 2 | DF15: 4 | DG15: 6 | DL15: =DK15+DJ15+DI15+DH15+DG15+DF15+DE15+DD15+DC15 -> 13 | DN15: 12 | DP15: 1 | DQ15: =DP15+DO15+DN15+DM15 -> 13 | DR15: 8 | DV15: 8 | DX15: 2 | DZ15: 3 | EC15: =DW15+DU15+DS15+DY15 -> 0 | ED15: =DX15+DV15+DT15+DZ15 -> 13 | EE15: =ED15+EC15 -> 13 | EI15: 9 | EK15: 2 | EM15: 2 | EP15: =EN15+EL15+EJ15+EH15+EF15 -> 0 | EQ15: =EO15+EM15+EK15+EI15+EG15 -> 13 | ER15: =EQ15+EP15 -> 13 | ES15: 1 | EU15: 1979 | EV15: 72917/3 | EW15: 4 | EX15: 1 | EZ15: 1 | FD15: 1 | FF15: 1 | FI15: 4 | FJ15: 4 | FK15: =FJ15+FI15 -> 8 | FL15: 1 | FS15: 1 | FU15: 1 | FW15: 1 | FY15: 1 | GA15: 1 | GF15: 1 | GH15: 1 | GJ15: 1 | GL15: 1 | GO15: 1 | GR15: 1 | GT15: 1 | GV15: 1 | GX15: 1 | HB15: 1 | HF15: 1 | HI15: 1 | HN15: 178 | HO15: 30 | HP15: 4 | HQ15: 4 | HR15: 1 | HS15: 1 | HT15: 1 | HW15: 1 | HX15: 1 | IB15: 1 | ID15: 1 | IH15: 111 | II15: 1061 | IJ15: =II15+IH15 -> 1172 | IK15: المستوصف الصحي -الاطباء | IL15: تماضر سعيد حسين | IM15: 7702708819
A16: 11 | B16: 1400145 | C16: النجف | D16: النجف | E16: المركز | F16: قتيبة | G16: الوفاء | J16: 1 | K16: 1 | M16: 1 | Q16: 1 | T16: 1 | Y16: 10 | Z16: 23 | AA16: 38 | AB16: 33 | AC16: =AA16+Y16 -> 48 | AD16: =AB16+Z16 -> 56 | AE16: =AD16+AC16 -> 104 | AF16: 1 | AG16: 2 | AH16: =AG16+AF16 -> 3 | AI16: 1 | AJ16: 2 | AM16: =AK16+AI16 -> 1 | AN16: =AL16+AJ16 -> 2 | AO16: =AN16+AM16 -> 3 | AT16: =AR16+AP16 -> 0 | AU16: =AS16+AQ16 -> 0 | AV16: =AU16+AT16 -> 0 | AX16: 1 | AZ16: 1 | BB16: 1 | BD16: 1 | BF16: 1 | BN16: 1 | BP16: 8 | BR16: =BQ16+BP16+BO16+BN16 -> 9 | CD16: 2 | CE16: 1 | CK16: =CI16+CG16+CE16+CC16+CA16+BY16+BW16+BS16 -> 1 | CL16: =CJ16+CH16+CD16+CB16+BZ16+BX16+BV16+BT16 -> 2 | CM16: =CL16+CK16 -> 3 | CN16: 9 | CQ16: =CP16+CO16+CN16 -> 9 | CR16: 9 | DA16: =CY16+CX16+CW16+CV16+CU16+CT16+CS16+CZ16 -> 0 | DB16: =DA16+CR16 -> 9 | DC16: 1 | DD16: 2 | DF16: 2 | DG16: 4 | DL16: =DK16+DJ16+DI16+DH16+DG16+DF16+DE16+DD16+DC16 -> 9 | DM16: 1 | DN16: 8 | DQ16: =DP16+DO16+DN16+DM16 -> 9 | DT16: 5 | DV16: 2 | DZ16: 2 | EC16: =DW16+DU16+DS16+DY16 -> 0 | ED16: =DX16+DV16+DT16+DZ16 -> 9 | EE16: =ED16+EC16 -> 9 | EI16: 5 | EK16: 2 | EM16: 2 | EP16: =EN16+EL16+EJ16+EH16+EF16 -> 0 | EQ16: =EO16+EM16+EK16+EI16+EG16 -> 9 | ER16: =EQ16+EP16 -> 9 | ES16: 1 | EU16: 1986 | EV16: 41/41105 | EW16: 4 | EX16: 1 | EZ16: 1 | FC16: 1 | FE16: 3 | FF16: 1 | FI16: 6 | FJ16: 7 | FK16: =FJ16+FI16 -> 13 | FL16: 1 | FS16: 1 | FU16: 1 | FW16: 1 | FY16: 1 | GA16: 1 | GF16: 1 | GH16: 1 | GJ16: 1 | GL16: 1 | GO16: 1 | GS16: 1 | GT16: 1 | GW16: 1 | HB16: 1 | HF16: 1 | HJ16: 1 | HN16: 120 | HP16: 3 | HR16: 1 | HT16: 1 | HX16: 1 | IB16: 1 | IE16: 1 | IH16: 113 | II16: 140 | IJ16: =II16+IH16 -> 253 | IK16: قسم محو الامية | IL16: وفاء علي حسين | IM16: 7822874003
A17: 12 | B17: 1400146 | C17: النجف | D17: النجف | E17: المركز | F17: العبير | G17: الزهراء | J17: 1 | K17: 1 | M17: 1 | Q17: 1 | T17: 1 | Y17: 55 | Z17: 61 | AA17: 65 | AB17: 69 | AC17: =AA17+Y17 -> 120 | AD17: =AB17+Z17 -> 130 | AE17: =AD17+AC17 -> 250 | AF17: 2 | AG17: 3 | AH17: =AG17+AF17 -> 5 | AM17: =AK17+AI17 -> 0 | AN17: =AL17+AJ17 -> 0 | AO17: =AN17+AM17 -> 0 | AT17: =AR17+AP17 -> 0 | AU17: =AS17+AQ17 -> 0 | AV17: =AU17+AT17 -> 0 | AX17: 1 | AZ17: 1 | BB17: 1 | BD17: 1 | BE17: 1 | BG17: 1 | BN17: 1 | BO17: 1 | BP17: 8 | BR17: =BQ17+BP17+BO17+BN17 -> 10 | CB17: 2 | CD17: 2 | CE17: 1 | CK17: =CI17+CG17+CE17+CC17+CA17+BY17+BW17+BS17 -> 1 | CL17: =CJ17+CH17+CD17+CB17+BZ17+BX17+BV17+BT17 -> 4 | CM17: =CL17+CK17 -> 5 | CN17: 10 | CQ17: =CP17+CO17+CN17 -> 10 | CR17: 8 | CZ17: 2 | DA17: =CY17+CX17+CW17+CV17+CU17+CT17+CS17+CZ17 -> 2 | DB17: =DA17+CR17 -> 10 | DD17: 6 | DG17: 4 | DL17: =DK17+DJ17+DI17+DH17+DG17+DF17+DE17+DD17+DC17 -> 10 | DN17: 10 | DQ17: =DP17+DO17+DN17+DM17 -> 10 | DT17: 4 | DX17: 2 | DZ17: 4 | EC17: =DW17+DU17+DS17+DY17 -> 0 | ED17: =DX17+DV17+DT17+DZ17 -> 10 | EE17: =ED17+EC17 -> 10 | EI17: 6 | EM17: 4 | EP17: =EN17+EL17+EJ17+EH17+EF17 -> 0 | EQ17: =EO17+EM17+EK17+EI17+EG17 -> 10 | ER17: =EQ17+EP17 -> 10 | ES17: 1 | EU17: 1982 | EV17: 1651/1 | EW17: 3 | EX17: 1 | EZ17: 1 | FC17: 1 | FE17: 4 | FF17: 1 | FI17: 4 | FJ17: 7 | FK17: =FJ17+FI17 -> 11 | FL17: 1 | FS17: 1 | FU17: 1 | FW17: 1 | FY17: 1 | GA17: 1 | GF17: 1 | GH17: 1 | GJ17: 1 | GL17: 1 | GO17: 1 | GR17: 1 | GT17: 1 | GV17: 1 | HA17: 1 | HB17: 1 | HF17: 1 | HJ17: 1 | HN17: 300 | HP17: 6 | HR17: 1 | HT17: 1 | HW17: 1 | HX17: 1 | HZ17: 1 | IG17: 1 | IH17: 256 | IJ17: =II17+IH17 -> 256 | IK17: شارع المدارس-الزهراء | IL17: زينب محمد باقر مجبل | IM17: 7717355664
A18: 13 | B18: 1400147 | C18: النجف | D18: النجف | E18: المركز | F18: المباهج | G18: الانصار | J18: 1 | K18: 1 | M18: 1 | Q18: 1 | T18: 1 | Y18: 41 | Z18: 47 | AA18: 101 | AB18: 111 | AC18: =AA18+Y18 -> 142 | AD18: =AB18+Z18 -> 158 | AE18: =AD18+AC18 -> 300 | AF18: 2 | AG18: 3 | AH18: =AG18+AF18 -> 5 | AM18: =AK18+AI18 -> 0 | AN18: =AL18+AJ18 -> 0 | AO18: =AN18+AM18 -> 0 | AT18: =AR18+AP18 -> 0 | AU18: =AS18+AQ18 -> 0 | AV18: =AU18+AT18 -> 0 | AX18: 1 | AZ18: 1 | BB18: 1 | BD18: 1 | BF18: 1 | BN18: 1 | BO18: 1 | BP18: 8 | BR18: =BQ18+BP18+BO18+BN18 -> 10 | CD18: 3 | CE18: 1 | CK18: =CI18+CG18+CE18+CC18+CA18+BY18+BW18+BS18 -> 1 | CL18: =CJ18+CH18+CD18+CB18+BZ18+BX18+BV18+BT18 -> 3 | CM18: =CL18+CK18 -> 4 | CN18: 10 | CQ18: =CP18+CO18+CN18 -> 10 | CR18: 9 | CZ18: 1 | DA18: =CY18+CX18+CW18+CV18+CU18+CT18+CS18+CZ18 -> 1 | DB18: =DA18+CR18 -> 10 | DD18: 5 | DF18: 1 | DG18: 4 | DL18: =DK18+DJ18+DI18+DH18+DG18+DF18+DE18+DD18+DC18 -> 10 | DM18: 1 | DN18: 9 | DQ18: =DP18+DO18+DN18+DM18 -> 10 | DR18: 2 | DT18: 4 | DV18: 1 | DX18: 2 | DZ18: 3 | EC18: =DW18+DU18+DS18+DY18 -> 0 | ED18: =DX18+DV18+DT18+DZ18 -> 10 | EE18: =ED18+EC18 -> 10 | EI18: 4 | EK18: 4 | EM18: 2 | EP18: =EN18+EL18+EJ18+EH18+EF18 -> 0 | EQ18: =EO18+EM18+EK18+EI18+EG18 -> 10 | ER18: =EQ18+EP18 -> 10 | ES18: 1 | EU18: 1982 | EX18: 1 | EZ18: 1 | FC18: 1 | FE18: 2 | FF18: 1 | FI18: 5 | FJ18: 5 | FK18: =FJ18+FI18 -> 10 | FL18: 1 | FS18: 1 | FU18: 1 | FW18: 1 | FY18: 1 | GA18: 1 | GF18: 1 | GH18: 1 | GJ18: 1 | GL18: 1 | GO18: 1 | GR18: 1 | GT18: 1 | GV18: 1 | GX18: 1 | HB18: 1 | HF18: 1 | HI18: 1 | HM18: 200 | HN18: 200 | HO18: 50 | HP18: 5 | HQ18: 4 | HR18: 1 | HX18: 1 | IB18: 1 | IE18: 1 | IH18: 107 | IJ18: =II18+IH18 -> 107 | IK18: الانصار-الشارع العام | IL18: نهلة هادي غني | IM18: 7803088476
A19: 14 | B19: 1400148 | C19: النجف | D19: النجف | E19: المركز | F19: اطفال الثورة | G19: الثورة | J19: 1 | K19: 1 | M19: 1 | Q19: 1 | S19: 1 | T19: 1 | AC19: =AA19+Y19 -> 0 | AD19: =AB19+Z19 -> 0 | AE19: =AD19+AC19 -> 0 | AH19: =AG19+AF19 -> 0 | AM19: =AK19+AI19 -> 0 | AN19: =AL19+AJ19 -> 0 | AO19: =AN19+AM19 -> 0 | AT19: =AR19+AP19 -> 0 | AU19: =AS19+AQ19 -> 0 | AV19: =AU19+AT19 -> 0 | AX19: 1 | AZ19: 1 | BB19: 1 | BD19: 1 | BF19: 1 | BN19: 1 | BP19: 1 | BR19: =BQ19+BP19+BO19+BN19 -> 2 | CD19: 1 | CK19: =CI19+CG19+CE19+CC19+CA19+BY19+BW19+BS19 -> 0 | CL19: =CJ19+CH19+CF19+CD19+CB19+BZ19+BX19+BT19 -> 1 | CM19: =CL19+CK19 -> 1 | CN19: 2 | CQ19: =CP19+CO19+CN19 -> 2 | CR19: 2 | DA19: =CY19+CX19+CW19+CV19+CU19+CT19+CS19+CZ19 -> 0 | DB19: =DA19+CR19 -> 2 | DG19: 2 | DL19: =DK19+DJ19+DI19+DH19+DG19+DF19+DE19+DD19+DC19 -> 2 | DM19: 1 | DN19: 1 | DQ19: =DP19+DO19+DN19+DM19 -> 2 | DR19: 1 | DX19: 1 | DZ19: 1 | EC19: =DW19+DU19+DS19+DY19 -> 0 | ED19: =DX19+DV19+DT19+DZ19 -> 2 | EE19: =ED19+EC19 -> 2 | EK19: 2 | EP19: =EN19+EL19+EJ19+EH19+EF19 -> 0 | EQ19: =EO19+EM19+EK19+EI19+EG19 -> 2 | ER19: =EQ19+EP19 -> 2 | ES19: 1 | EU19: 1984 | EX19: 1 | EZ19: 1 | FD19: 1 | FF19: 1 | FI19: 4 | FJ19: 6 | FK19: =FJ19+FI19 -> 10 | FL19: 1 | FS19: 1 | FV19: 1 | FX19: 1 | FY19: 1 | GA19: 1 | GF19: 1 | GH19: 1 | GJ19: 1 | GL19: 1 | GQ19: 1 | GS19: 1 | GU19: 1 | GW19: 1 | HB19: 1 | HF19: 1 | HK19: 1 | IJ19: =II19+IH19 -> 0 | IK19: المصلخ | IL19: نورس حسن سعد | IM19: 7842816800
A20: 15 | B20: 1400149 | C20: النجف | D20: النجف | E20: المركز | F20: الحسين | G20: الحسين | J20: 1 | K20: 1 | M20: 1 | Q20: 1 | T20: 1 | Y20: 45 | Z20: 40 | AA20: 51 | AB20: 44 | AC20: =AA20+Y20 -> 96 | AD20: =AB20+Z20 -> 84 | AE20: =AD20+AC20 -> 180 | AF20: 2 | AG20: 2 | AH20: =AG20+AF20 -> 4 | AI20: 12 | AJ20: 10 | AK20: 10 | AL20: 5 | AM20: =AK20+AI20 -> 22 | AN20: =AL20+AJ20 -> 15 | AO20: =AN20+AM20 -> 37 | AR20: 1 | AT20: =AR20+AP20 -> 1 | AU20: =AS20+AQ20 -> 0 | AV20: =AU20+AT20 -> 1 | AX20: 1 | AZ20: 1 | BB20: 1 | BD20: 1 | BF20: 1 | BN20: 1 | BO20: 1 | BP20: 10 | BR20: =BQ20+BP20+BO20+BN20 -> 12 | BT20: 1 | BV20: 1 | CD20: 3 | CE20: 1 | CK20: =CI20+CG20+CE20+CC20+CA20+BY20+BW20+BS20 -> 1 | CL20: =CJ20+CH20+CD20+CB20+BZ20+BX20+BV20+BT20 -> 5 | CM20: =CL20+CK20 -> 6 | CN20: 12 | CQ20: =CP20+CO20+CN20 -> 12 | CR20: 10 | CZ20: 2 | DA20: =CY20+CX20+CW20+CV20+CU20+CT20+CS20+CZ20 -> 2 | DB20: =DA20+CR20 -> 12 | DD20: 5 | DF20: 3 | DG20: 4 | DL20: =DK20+DJ20+DI20+DH20+DG20+DF20+DE20+DD20+DC20 -> 12 | DM20: 2 | DN20: 9 | DO20: 1 | DQ20: =DP20+DO20+DN20+DM20 -> 12 | DR20: 1 | DT20: 1 | DZ20: 11 | EC20: =DW20+DU20+DS20+DY20 -> 0 | ED20: =DX20+DV20+DT20+DZ20 -> 12 | EE20: =ED20+EC20 -> 12 | EI20: 3 | EK20: 4 | EM20: 4 | EO20: 1 | EP20: =EN20+EL20+EJ20+EH20+EF20 -> 0 | EQ20: =EO20+EM20+EK20+EI20+EG20 -> 12 | ER20: =EQ20+EP20 -> 12 | ES20: 1 | EU20: 1985 | EV20: 17240/2 | EW20: 2 | EX20: 1 | EZ20: 1 | FC20: 1 | FE20: 2 | FF20: 1 | FI20: 4 | FJ20: 5 | FK20: =FJ20+FI20 -> 9 | FL20: 1 | FS20: 1 | FU20: 1 | FW20: 1 | FY20: 1 | GA20: 1 | GF20: 1 | GH20: 1 | GJ20: 1 | GL20: 1 | GQ20: 1 | GS20: 1 | GT20: 1 | GW20: 1 | HB20: 1 | HF20: 1 | HJ20: 1 | HN20: 20 | HO20: 50 | HP20: 4 | HQ20: 5 | HS20: 2 | HU20: 1 | HW20: 1 | HX20: 1 | IB20: 1 | IE20: 1 | IH20: 75 | II20: 97 | IJ20: =II20+IH20 -> 172 | IK20: معهد الامل للصم والبكم | IL20: حميدة عبد زيد عقيل | IM20: 7801505324
A21: 16 | B21: 1400150 | C21: النجف | D21: النجف | E21: المركز | F21: الشموع | G21: العمارات السكنية | J21: 1 | K21: 1 | M21: 1 | Q21: 1 | T21: 1 | Y21: 8 | Z21: 20 | AA21: 33 | AB21: 20 | AC21: =AA21+Y21 -> 41 | AD21: =AB21+Z21 -> 40 | AE21: =AD21+AC21 -> 81 | AF21: 1 | AG21: 1 | AH21: =AG21+AF21 -> 2 | AM21: =AK21+AI21 -> 0 | AN21: =AL21+AJ21 -> 0 | AO21: =AN21+AM21 -> 0 | AT21: =AR21+AP21 -> 0 | AU21: =AS21+AQ21 -> 0 | AV21: =AU21+AT21 -> 0 | AX21: 1 | AZ21: 1 | BB21: 1 | BD21: 1 | BF21: 1 | BN21: 1 | BO21: 1 | BP21: 3 | BR21: =BQ21+BP21+BO21+BN21 -> 5 | CD21: 1 | CE21: 1 | CK21: =CI21+CG21+CE21+CC21+CA21+BY21+BW21+BS21 -> 1 | CL21: =CJ21+CH21+CF21+CD21+CB21+BZ21+BX21+BT21 -> 1 | CM21: =CL21+CK21 -> 2 | CN21: 5 | CQ21: =CP21+CO21+CN21 -> 5 | CR21: 5 | DA21: =CY21+CX21+CW21+CV21+CU21+CT21+CS21+CZ21 -> 0 | DB21: =DA21+CR21 -> 5 | DD21: 3 | DF21: 1 | DG21: 1 | DL21: =DK21+DJ21+DI21+DH21+DG21+DF21+DE21+DD21+DC21 -> 5 | DM21: 1 | DN21: 4 | DQ21: =DP21+DO21+DN21+DM21 -> 5 | DR21: 3 | DT21: 1 | DZ21: 4 | EC21: =DW21+DU21+DS21+DY21 -> 0 | ED21: =DX21+DV21+DT21+DZ21 -> 5 | EE21: =ED21+EC21 -> 5 | EK21: 3 | EM21: 2 | EP21: =EN21+EL21+EJ21+EH21+EF21 -> 0 | EQ21: =EO21+EM21+EK21+EI21+EG21 -> 5 | ER21: =EQ21+EP21 -> 5 | ES21: 1 | EU21: 1985 | EV21: 15840/2 | EW21: 4 | EY21: 1 | EZ21: 1 | FD21: 1 | FF21: 1 | FI21: 6 | FJ21: 7 | FK21: =FJ21+FI21 -> 13 | FL21: 1 | FS21: 1 | FU21: 1 | FW21: 1 | FY21: 1 | GA21: 1 | GF21: 1 | GH21: 1 | GJ21: 1 | GL21: 1 | GO21: 1 | GR21: 1 | GT21: 1 | GV21: 1 | GX21: 1 | HB21: 1 | HF21: 1 | HI21: 1 | HN21: 50 | HO21: 65 | HP21: 3 | HQ21: 7 | HR21: 1 | HV21: 1 | HX21: 1 | IB21: 1 | IG21: 1 | IH21: 55 | II21: 200 | IJ21: =II21+IH21 -> 255 | IK21: الشقق-شارع الكوفة | IL21: فاتن عبد الكاظم جبر | IM21: 7816244538
A22: 17 | B22: 1400151 | C22: النجف | D22: النجف | E22: المركز | F22: الغدير | G22: الغدير | J22: 1 | K22: 1 | M22: 1 | Q22: 1 | T22: 1 | Y22: 25 | Z22: 27 | AA22: 22 | AB22: 27 | AC22: =AA22+Y22 -> 47 | AD22: =AB22+Z22 -> 54 | AE22: =AD22+AC22 -> 101 | AF22: 2 | AG22: 2 | AH22: =AG22+AF22 -> 4 | AI22: 3 | AJ22: 3 | AL22: 1 | AM22: =AK22+AI22 -> 3 | AN22: =AL22+AJ22 -> 4 | AO22: =AN22+AM22 -> 7 | AR22: 1 | AS22: 2 | AT22: =AR22+AP22 -> 1 | AU22: =AS22+AQ22 -> 2 | AV22: =AU22+AT22 -> 3 | AX22: 1 | AZ22: 1 | BB22: 1 | BD22: 1 | BF22: 1 | BN22: 1 | BP22: 8 | BR22: =BQ22+BP22+BO22+BN22 -> 9 | CB22: 1 | CD22: 2 | CK22: =CI22+CG22+CE22+CC22+CA22+BY22+BW22+BS22 -> 0 | CL22: =CJ22+CH22+CF22+CD22+CB22+BZ22+BX22+BT22 -> 3 | CM22: =CL22+CK22 -> 3 | CN22: 9 | CQ22: =CP22+CO22+CN22 -> 9 | CR22: 9 | DA22: =CY22+CX22+CW22+CV22+CU22+CT22+CS22+CZ22 -> 0 | DB22: =DA22+CR22 -> 9 | DC22: 1 | DD22: 1 | DF22: 2 | DG22: 5 | DL22: =DK22+DJ22+DI22+DH22+DG22+DF22+DE22+DD22+DC22 -> 9 | DM22: 2 | DN22: 6 | DP22: 1 | DQ22: =DP22+DO22+DN22+DM22 -> 9 | DR22: 2 | DT22: 4 | DV22: 2 | DX22: 1 | DZ22: 2 | EC22: =DW22+DU22+DS22+DY22 -> 0 | ED22: =DX22+DV22+DT22+DZ22 -> 9 | EE22: =ED22+EC22 -> 9 | EG22: 1 | EI22: 4 | EK22: 1 | EM22: 3 | EP22: =EN22+EL22+EJ22+EH22+EF22 -> 0 | EQ22: =EO22+EM22+EK22+EI22+EG22 -> 9 | ER22: =EQ22+EP22 -> 9 | ES22: 1 | EU22: 1983 | EV22: 17063/2 | EW22: 28 | EY22: 1 | EZ22: 1 | FD22: 1 | FF22: 1 | FI22: 6 | FJ22: 6 | FK22: =FJ22+FI22 -> 12 | FL22: 1 | FS22: 1 | FU22: 1 | FW22: 1 | FY22: 1 | GA22: 1 | GF22: 1 | GH22: 1 | GJ22: 1 | GL22: 1 | GO22: 1 | GR22: 1 | GT22: 1 | GV22: 1 | GX22: 1 | HB22: 1 | HF22: 1 | HJ22: 1 | HN22: 120 | HP22: 4 | HR22: 1 | HS22: 1 | HT22: 2 | HX22: 1 | IB22: 1 | IE22: 1 | II22: 584 | IJ22: =II22+IH22 -> 584 | IK22: السوق العصري -الغدير | IL22: ثناء محمد عوجة | IM22: 7815219265
A23: 18 | B23: 1400152 | C23: النجف | D23: النجف | E23: المركز | F23: الاستبرق | G23: الجديدة الثالثة | J23: 1 | K23: 1 | M23: 1 | Q23: 1 | T23: 1 | Y23: 30 | Z23: 20 | AA23: 56 | AB23: 54 | AC23: =AA23+Y23 -> 86 | AD23: =AB23+Z23 -> 74 | AE23: =AD23+AC23 -> 160 | AF23: 1 | AG23: 2 | AH23: =AG23+AF23 -> 3 | AI23: 7 | AJ23: 4 | AK23: 8 | AL23: 6 | AM23: =AK23+AI23 -> 15 | AN23: =AL23+AJ23 -> 10 | AO23: =AN23+AM23 -> 25 | AT23: =AR23+AP23 -> 0 | AU23: =AS23+AQ23 -> 0 | AV23: =AU23+AT23 -> 0 | AX23: 1 | AZ23: 1 | BB23: 1 | BC23: 1 | BF23: 1 | BN23: 1 | BP23: 10 | BR23: =BQ23+BP23+BO23+BN23 -> 11 | CC23: 1 | CD23: 2 | CE23: 1 | CK23: =CI23+CG23+CE23+CC23+CA23+BY23+BW23+BS23 -> 2 | CL23: =CJ23+CH23+CF23+CD23+CB23+BZ23+BX23+BT23 -> 2 | CM23: =CL23+CK23 -> 4 | CN23: 11 | CQ23: =CP23+CO23+CN23 -> 11 | CR23: 9 | CW23: 1 | CX23: 1 | DA23: =CY23+CX23+CW23+CV23+CU23+CT23+CS23+CZ23 -> 2 | DB23: =DA23+CR23 -> 11 | DD23: 3 | DF23: 1 | DG23: 6 | DH23: 1 | DL23: =DK23+DJ23+DI23+DH23+DG23+DF23+DE23+DD23+DC23 -> 11 | DM23: 1 | DN23: 10 | DQ23: =DP23+DO23+DN23+DM23 -> 11 | DR23: 2 | DT23: 4 | DX23: 1 | DZ23: 6 | EC23: =DW23+DU23+DS23+DY23 -> 0 | ED23: =DX23+DV23+DT23+DZ23 -> 11 | EE23: =ED23+EC23 -> 11 | EG23: 1 | EI23: 4 | EK23: 5 | EM23: 1 | EP23: =EN23+EL23+EJ23+EH23+EF23 -> 0 | EQ23: =EO23+EM23+EK23+EI23+EG23 -> 11 | ER23: =EQ23+EP23 -> 11 | ES23: 1 | EU23: 2000 | EV23: 3329 | EX23: 1 | FA23: 1 | FC23: 1 | FE23: 2 | FF23: 1 | FI23: 3 | FJ23: 7 | FK23: =FJ23+FI23 -> 10 | FL23: 1 | FS23: 1 | FV23: 1 | FX23: 1 | FY23: 1 | GA23: 1 | GF23: 1 | GH23: 1 | GJ23: 1 | GL23: 1 | GP23: 1 | GR23: 1 | GT23: 1 | GW23: 1 | GX23: 1 | HB23: 1 | HF23: 1 | HJ23: 1 | HN23: 30 | HO23: 70 | HP23: 2 | HQ23: 8 | HR23: 1 | HT23: 1 | HX23: 1 | IB23: 1 | IF23: 1 | IH23: 6 | II23: 140 | IJ23: =II23+IH23 -> 146 | IK23: شارع حنون خلف متوسطة الجمهورية | IL23: نورس حسن سعد | IM23: 7842816800
A24: 19 | B24: 1400153 | C24: النجف | D24: النجف | E24: المركز | F24: الافاق الرحبة | G24: النصر | J24: 1 | K24: 1 | M24: 1 | Q24: 1 | T24: 1 | Y24: 45 | Z24: 45 | AA24: 128 | AB24: 102 | AC24: =AA24+Y24 -> 173 | AD24: =AB24+Z24 -> 147 | AE24: =AD24+AC24 -> 320 | AF24: 1 | AG24: 3 | AH24: =AG24+AF24 -> 4 | AK24: 12 | AL24: 17 | AM24: =AK24+AI24 -> 12 | AN24: =AL24+AJ24 -> 17 | AO24: =AN24+AM24 -> 29 | AT24: =AR24+AP24 -> 0 | AU24: =AS24+AQ24 -> 0 | AV24: =AU24+AT24 -> 0 | AX24: 1 | AZ24: 1 | BB24: 1 | BD24: 1 | BE24: 1 | BG24: 1 | BN24: 1 | BP24: 9 | BR24: =BQ24+BP24+BO24+BN24 -> 10 | CB24: 1 | CD24: 3 | CK24: =CI24+CG24+CE24+CC24+CA24+BY24+BW24+BS24 -> 0 | CL24: =CJ24+CH24+CF24+CD24+CB24+BZ24+BX24+BT24 -> 4 | CM24: =CL24+CK24 -> 4 | CN24: 10 | CQ24: =CP24+CO24+CN24 -> 10 | CR24: 9 | CZ24: 1 | DA24: =CY24+CX24+CW24+CV24+CU24+CT24+CS24+CZ24 -> 1 | DB24: =DA24+CR24 -> 10 | DD24: 3 | DG24: 7 | DL24: =DK24+DJ24+DI24+DH24+DG24+DF24+DE24+DD24+DC24 -> 10 | DM24: 1 | DN24: 9 | DQ24: =DP24+DO24+DN24+DM24 -> 10 | DT24: 6 | DV24: 1 | DX24: 1 | DZ24: 2 | EC24: =DW24+DU24+DS24+DY24 -> 0 | ED24: =DX24+DV24+DT24+DZ24 -> 10 | EE24: =ED24+EC24 -> 10 | EG24: 1 | EI24: 5 | EK24: 4 | EP24: =EN24+EL24+EJ24+EH24+EF24 -> 0 | EQ24: =EO24+EM24+EK24+EI24+EG24 -> 10 | ER24: =EQ24+EP24 -> 10 | ES24: 1 | EU24: 2000 | EV24: 19612/3 | EW24: 4 | EX24: 1 | EZ24: 1 | FD24: 1 | FF24: 1 | FI24: 4 | FJ24: 8 | FK24: =FJ24+FI24 -> 12 | FL24: 1 | FS24: 1 | FV24: 1 | FX24: 1 | FY24: 1 | GA24: 1 | GF24: 1 | GH24: 1 | GJ24: 1 | GL24: 1 | GO24: 1 | GR24: 1 | GT24: 1 | GW24: 1 | GX24: 1 | HB24: 1 | HF24: 1 | HJ24: 1 | HN24: 260 | HO24: 5 | HP24: 4 | HQ24: 6 | HR24: 1 | HT24: 1 | HX24: 1 | IB24: 1 | IE24: 1 | IH24: 114 | II24: 130 | IJ24: =II24+IH24 -> 244 | IK24: المركز الصحي -حي النصر | IL24: صفاء محمود محمد | IM24: 7706757118
A25: 20 | B25: 1400794 | C25: النجف | D25: النجف | E25: المركز | F25: طيور الجنة | G25: الوفاء | J25: 1 | K25: 1 | M25: 1 | Q25: 1 | T25: 1 | Y25: 77 | Z25: 85 | AA25: 48 | AB25: 65 | AC25: =AA25+Y25 -> 125 | AD25: =AB25+Z25 -> 150 | AE25: =AD25+AC25 -> 275 | AF25: 2 | AG25: 3 | AH25: =AG25+AF25 -> 5 | AI25: 17 | AJ25: 13 | AK25: 13 | AL25: 14 | AM25: =AK25+AI25 -> 30 | AN25: =AL25+AJ25 -> 27 | AO25: =AN25+AM25 -> 57 | AT25: =AR25+AP25 -> 0 | AU25: =AS25+AQ25 -> 0 | AV25: =AU25+AT25 -> 0 | AX25: 1 | AZ25: 1 | BB25: 1 | BD25: 1 | BF25: 1 | BN25: 1 | BP25: 12 | BR25: =BQ25+BP25+BO25+BN25 -> 13 | CE25: 1 | CK25: =CI25+CG25+CE25+CC25+CA25+BY25+BW25+BS25 -> 1 | CL25: =CJ25+CH25+CF25+CD25+CB25+BZ25+BX25+BT25 -> 0 | CM25: =CL25+CK25 -> 1 | CN25: 13 | CQ25: =CP25+CO25+CN25 -> 13 | CR25: 9 | CT25: 2 | CW25: 2 | DA25: =CY25+CX25+CW25+CV25+CU25+CT25+CS25+CZ25 -> 4 | DB25: =DA25+CR25 -> 13 | DD25: 3 | DF25: 2 | DG25: 7 | DK25: 1 | DL25: =DK25+DJ25+DI25+DH25+DG25+DF25+DE25+DD25+DC25 -> 13 | DM25: 2 | DN25: 10 | DP25: 1 | DQ25: =DP25+DO25+DN25+DM25 -> 13 | DR25: 4 | DT25: 2 | DV25: 1 | DX25: 2 | DZ25: 8 | EC25: =DW25+DU25+DS25+DY25 -> 0 | ED25: =DX25+DV25+DT25+DZ25 -> 13 | EE25: =ED25+EC25 -> 13 | EG25: 1 | EI25: 1 | EK25: 7 | EM25: 2 | EO25: 2 | EP25: =EN25+EL25+EJ25+EH25+EF25 -> 0 | EQ25: =EO25+EM25+EK25+EI25+EG25 -> 13 | ER25: =EQ25+EP25 -> 13 | ES25: 1 | EU25: 2008 | EV25: 41094/3 | EW25: 4 | EX25: 1 | EZ25: 1 | FC25: 1 | FE25: 2 | FF25: 1 | FI25: 5 | FJ25: 5 | FK25: =FJ25+FI25 -> 10 | FL25: 1 | FS25: 1 | FV25: 1 | FX25: 1 | FY25: 1 | GA25: 1 | GF25: 1 | GI25: 1 | GJ25: 1 | GL25: 1 | GQ25: 1 | GR25: 1 | GU25: 1 | GW25: 1 | HA25: 1 | HB25: 1 | HF25: 1 | HJ25: 1 | HN25: 160 | HP25: 60 | HR25: 2 | HT25: 1 | HX25: 1 | IB25: 1 | IE25: 1 | IH25: 27 | II25: 550 | IJ25: =II25+IH25 -> 577 | IK25: مقابل دورالهندية | IL25: رشا حامد جهاد | IM25: 7804951177
A26: 21 | B26: 1400760 | C26: النجف | D26: النجف | E26: المركز | F26: العسل | G26: العدالة | J26: 1 | K26: 1 | M26: 1 | Q26: 1 | T26: 1 | Y26: 19 | Z26: 20 | AA26: 29 | AB26: 33 | AC26: =AA26+Y26 -> 48 | AD26: =AB26+Z26 -> 53 | AE26: =AD26+AC26 -> 101 | AF26: 2 | AG26: 2 | AH26: =AG26+AF26 -> 4 | AI26: 7 | AJ26: 4 | AK26: 8 | AL26: 2 | AM26: =AK26+AI26 -> 15 | AN26: =AL26+AJ26 -> 6 | AO26: =AN26+AM26 -> 21 | AP26: 2 | AQ26: 4 | AT26: =AR26+AP26 -> 2 | AU26: =AS26+AQ26 -> 4 | AV26: =AU26+AT26 -> 6 | AX26: 1 | AZ26: 1 | BB26: 1 | BD26: 1 | BF26: 1 | BN26: 1 | BO26: 1 | BP26: 9 | BR26: =BQ26+BP26+BO26+BN26 -> 11 | CD26: 2 | CE26: 1 | CK26: =CI26+CG26+CE26+CC26+CA26+BY26+BW26+BS26 -> 1 | CL26: =CJ26+CH26+CF26+CD26+CB26+BZ26+BX26+BT26 -> 2 | CM26: =CL26+CK26 -> 3 | CN26: 11 | CQ26: =CP26+CO26+CN26 -> 11 | CR26: 11 | DA26: =CY26+CX26+CW26+CV26+CU26+CT26+CS26+CZ26 -> 0 | DB26: =DA26+CR26 -> 11 | DD26: 1 | DF26: 4 | DG26: 5 | DI26: 1 | DL26: =DK26+DJ26+DI26+DH26+DG26+DF26+DE26+DD26+DC26 -> 11 | DN26: 10 | DP26: 1 | DQ26: =DP26+DO26+DN26+DM26 -> 11 | DR26: 11 | DT26: 4 | DX26: 1 | DZ26: 6 | EC26: =DW26+DU26+DS26+DY26 -> 0 | ED26: =DX26+DV26+DT26+DZ26 -> 11 | EE26: =ED26+EC26 -> 11 | EG26: 2 | EK26: 3 | EM26: 6 | EP26: =EN26+EL26+EJ26+EH26+EF26 -> 0 | EQ26: =EO26+EM26+EK26+EI26+EG26 -> 11 | ER26: =EQ26+EP26 -> 11 | ES26: 1 | EU26: 2008 | EV26: 35069/3 | EW26: 4 | EX26: 1 | EZ26: 1 | FC26: 1 | FE26: 4 | FF26: 1 | FI26: 4 | FJ26: 4 | FK26: =FJ26+FI26 -> 8 | FL26: 1 | FS26: 1 | FU26: 1 | FW26: 1 | FY26: 1 | GA26: 1 | GF26: 1 | GI26: 1 | GJ26: 1 | GL26: 1 | GP26: 1 | GR26: 1 | GT26: 1 | GW26: 1 | GZ26: 1 | HB26: 1 | HF26: 1 | HJ26: 1 | HO26: 59 | HP26: 4 | HQ26: 6 | HR26: 1 | HS26: 1 | HT26: 1 | HU26: 1 | HX26: 1 | HZ26: 1 | IE26: 1 | IH26: 444 | II26: 101 | IJ26: =II26+IH26 -> 545 | IK26: حي العدالة | IL26: ابتهال عزيز عبود | IM26: 7831857062
A27: 22 | B27: 1400774 | C27: النجف | D27: النجف | E27: المركز | F27: جنة الزهراء | G27: المكرمة | J27: 1 | K27: 1 | M27: 1 | Q27: 1 | T27: 1 | Y27: 55 | Z27: 60 | AA27: 53 | AB27: 44 | AC27: =AA27+Y27 -> 108 | AD27: =AB27+Z27 -> 104 | AE27: =AD27+AC27 -> 212 | AF27: 2 | AG27: 2 | AH27: =AG27+AF27 -> 4 | AI27: 23 | AJ27: 10 | AK27: 11 | AL27: 6 | AM27: =AK27+AI27 -> 34 | AN27: =AL27+AJ27 -> 16 | AO27: =AN27+AM27 -> 50 | AT27: =AR27+AP27 -> 0 | AU27: =AS27+AQ27 -> 0 | AV27: =AU27+AT27 -> 0 | AX27: 1 | AZ27: 1 | BB27: 1 | BD27: 1 | BF27: 1 | BN27: 1 | BO27: 2 | BP27: 10 | BR27: =BQ27+BP27+BO27+BN27 -> 13 | CB27: 1 | CD27: 2 | CE27: 1 | CK27: =CI27+CG27+CE27+CC27+CA27+BY27+BW27+BS27 -> 1 | CL27: =CJ27+CH27+CF27+CD27+CB27+BZ27+BX27+BT27 -> 3 | CM27: =CL27+CK27 -> 4 | CN27: 13 | CQ27: =CP27+CO27+CN27 -> 13 | CR27: 12 | CT27: 1 | DA27: =CY27+CX27+CW27+CV27+CU27+CT27+CS27+CZ27 -> 1 | DB27: =DA27+CR27 -> 13 | DD27: 2 | DF27: 3 | DG27: 8 | DL27: =DK27+DJ27+DI27+DH27+DG27+DF27+DE27+DD27+DC27 -> 13 | DM27: 2 | DN27: 9 | DO27: 2 | DQ27: =DP27+DO27+DN27+DM27 -> 13 | DR27: 1 | DT27: 4 | DV27: 3 | DX27: 1 | DZ27: 5 | EC27: =DW27+DU27+DS27+DY27 -> 0 | ED27: =DX27+DV27+DT27+DZ27 -> 13 | EE27: =ED27+EC27 -> 13 | EI27: 8 | EK27: 2 | EM27: 3 | EP27: =EN27+EL27+EJ27+EH27+EF27 -> 0 | EQ27: =EO27+EM27+EK27+EI27+EG27 -> 13 | ER27: =EQ27+EP27 -> 13 | ES27: 1 | EU27: 2009 | EV27: 3/ 355 | EW27: 3 | EX27: 1 | EZ27: 1 | FC27: 1 | FE27: 4 | FF27: 1 | FI27: 5 | FJ27: 4 | FK27: =FJ27+FI27 -> 9 | FL27: 1 | FS27: 1 | FU27: 1 | FW27: 1 | FY27: 1 | GA27: 1 | GF27: 1 | GI27: 1 | GJ27: 1 | GL27: 1 | GP27: 1 | GR27: 1 | GT27: 1 | GV27: 1 | GX27: 1 | HB27: 1 | HF27: 1 | HJ27: 1 | HN27: 44 | HO27: 30 | HP27: 5 | HQ27: 4 | HR27: 2 | HT27: 1 | HX27: 1 | HZ27: 1 | IF27: 1 | IH27: 255 | II27: 112 | IJ27: =II27+IH27 -> 367 | IK27: المركز الصحي سيدالشهداء | IL27: ماجدة قاسم شلال | IM27: 7800269746
A28: 23 | B28: 1400779 | C28: النجف | D28: النجف | E28: المركز | F28: زهرة الوادي | G28: النصر | J28: 1 | K28: 1 | M28: 1 | Q28: 1 | T28: 1 | Y28: 47 | Z28: 59 | AA28: 83 | AB28: 77 | AC28: =AA28+Y28 -> 130 | AD28: =AB28+Z28 -> 136 | AE28: =AD28+AC28 -> 266 | AF28: 2 | AG28: 2 | AH28: =AG28+AF28 -> 4 | AK28: 20 | AL28: 25 | AM28: =AK28+AI28 -> 20 | AN28: =AL28+AJ28 -> 25 | AO28: =AN28+AM28 -> 45 | AT28: =AR28+AP28 -> 0 | AU28: =AS28+AQ28 -> 0 | AV28: =AU28+AT28 -> 0 | AX28: 1 | AZ28: 1 | BB28: 1 | BD28: 1 | BF28: 1 | BN28: 1 | BP28: 9 | BR28: =BQ28+BP28+BO28+BN28 -> 10 | BZ28: 1 | CD28: 3 | CE28: 1 | CK28: =CI28+CG28+CE28+CC28+CA28+BY28+BW28+BS28 -> 1 | CL28: =CJ28+CH28+CF28+CD28+CB28+BZ28+BX28+BT28 -> 4 | CM28: =CL28+CK28 -> 5 | CN28: 10 | CQ28: =CP28+CO28+CN28 -> 10 | CR28: 7 | CW28: 1 | CX28: 2 | DA28: =CY28+CX28+CW28+CV28+CU28+CT28+CS28+CZ28 -> 3 | DB28: =DA28+CR28 -> 10 | DD28: 4 | DF28: 2 | DG28: 4 | DL28: =DK28+DJ28+DI28+DH28+DG28+DF28+DE28+DD28+DC28 -> 10 | DM28: 1 | DN28: 8 | DO28: 1 | DQ28: =DP28+DO28+DN28+DM28 -> 10 | DR28: 3 | DV28: 5 | DZ28: 5 | EC28: =DW28+DU28+DS28+DY28 -> 0 | ED28: =DX28+DV28+DT28+DZ28 -> 10 | EE28: =ED28+EC28 -> 10 | EI28: 4 | EK28: 5 | EM28: 1 | EP28: =EN28+EL28+EJ28+EH28+EF28 -> 0 | EQ28: =EO28+EM28+EK28+EI28+EG28 -> 10 | ER28: =EQ28+EP28 -> 10 | ES28: 1 | EU28: 2009 | EV28: 18336 | EW28: 4 | EX28: 1 | EZ28: 1 | FD28: 1 | FF28: 1 | FI28: 4 | FJ28: 5 | FK28: =FJ28+FI28 -> 9 | FL28: 1 | FS28: 1 | FU28: 1 | FW28: 1 | FY28: 1 | GA28: 1 | GF28: 1 | GI28: 1 | GJ28: 1 | GL28: 1 | GP28: 1 | GR28: 1 | GT28: 1 | GV28: 1 | GX28: 1 | HB28: 1 | HF28: 1 | HI28: 1 | HN28: 50 | HP28: 4 | HQ28: 1 | HR28: 1 | HX28: 1 | HZ28: 1 | IE28: 1 | IH28: 221 | II28: 4 | IJ28: =II28+IH28 -> 225 | IK28: جامع الامام موسى الكاظم | IL28: سارة احمد عبد | IM28: 7806692373
A29: 24 | B29: 1400827 | C29: النجف | D29: النجف | E29: المركز | F29: ندى القلوب | G29: المكرمة | J29: 1 | K29: 1 | M29: 1 | Q29: 1 | T29: 1 | Y29: 100 | Z29: 100 | AA29: 90 | AB29: 100 | AC29: =AA29+Y29 -> 190 | AD29: =AB29+Z29 -> 200 | AE29: =AD29+AC29 -> 390 | AF29: 2 | AG29: 2 | AH29: =AG29+AF29 -> 4 | AI29: 5 | AJ29: 5 | AM29: =AK29+AI29 -> 5 | AN29: =AL29+AJ29 -> 5 | AO29: =AN29+AM29 -> 10 | AT29: =AR29+AP29 -> 0 | AU29: =AS29+AQ29 -> 0 | AV29: =AU29+AT29 -> 0 | AX29: 1 | AZ29: 1 | BB29: 1 | BD29: 1 | BF29: 1 | BN29: 1 | BO29: 1 | BP29: 9 | BR29: =BQ29+BP29+BO29+BN29 -> 11 | CB29: 1 | CD29: 2 | CE29: 1 | CK29: =CI29+CG29+CE29+CC29+CA29+BY29+BW29+BS29 -> 1 | CL29: =CJ29+CH29+CF29+CD29+CB29+BZ29+BX29+BT29 -> 3 | CM29: =CL29+CK29 -> 4 | CN29: 11 | CQ29: =CP29+CO29+CN29 -> 11 | CR29: 10 | CW29: 1 | DA29: =CY29+CX29+CW29+CV29+CU29+CT29+CS29+CZ29 -> 1 | DB29: =DA29+CR29 -> 11 | DD29: 2 | DG29: 9 | DL29: =DK29+DJ29+DI29+DH29+DG29+DF29+DE29+DD29+DC29 -> 11 | DN29: 9 | DO29: 1 | DP29: 1 | DQ29: =DP29+DO29+DN29+DM29 -> 11 | DR29: 3 | DT29: 7 | DX29: 2 | DZ29: 2 | EC29: =DW29+DU29+DS29+DY29 -> 0 | ED29: =DX29+DV29+DT29+DZ29 -> 11 | EE29: =ED29+EC29 -> 11 | EI29: 5 | EK29: 4 | EM29: 1 | EO29: 1 | EP29: =EN29+EL29+EJ29+EH29+EF29 -> 0 | EQ29: =EO29+EM29+EK29+EI29+EG29 -> 11 | ER29: =EQ29+EP29 -> 11 | ES29: 1 | EU29: 2009 | EV29: 8355/3 | EW29: 4 | EX29: 1 | EZ29: 1 | FC29: 1 | FE29: 4 | FF29: 1 | FI29: 4 | FJ29: 5 | FK29: =FJ29+FI29 -> 9 | FL29: 1 | FS29: 1 | FV29: 1 | FX29: 1 | FY29: 1 | GA29: 1 | GF29: 1 | GI29: 1 | GJ29: 1 | GL29: 1 | GQ29: 1 | GR29: 1 | GT29: 1 | GW29: 1 | HA29: 1 | HB29: 1 | HF29: 1 | HJ29: 1 | HM29: 55 | HN29: 240 | HP29: 6 | HQ29: 4 | HR29: 1 | HT29: 1 | HX29: 1 | IA29: 1 | IE29: 1 | IH29: 301 | II29: 144 | IJ29: =II29+IH29 -> 445 | IK29: شارع العسكري | IL29: نسرين جابر حسين | IM29: 7813063649
A30: 25 | B30: 1400960 | C30: النجف | D30: النجف | E30: المركز | F30: الابتسامة | G30: الجامعة | J30: 1 | K30: 1 | M30: 1 | Q30: 1 | T30: 1 | Y30: 22 | Z30: 20 | AA30: 61 | AB30: 53 | AC30: =AA30+Y30 -> 83 | AD30: =AB30+Z30 -> 73 | AE30: =AD30+AC30 -> 156 | AF30: 2 | AG30: 2 | AH30: =AG30+AF30 -> 4 | AI30: 7 | AJ30: 7 | AK30: 4 | AL30: 5 | AM30: =AK30+AI30 -> 11 | AN30: =AL30+AJ30 -> 12 | AO30: =AN30+AM30 -> 23 | AT30: =AR30+AP30 -> 0 | AU30: =AS30+AQ30 -> 0 | AV30: =AU30+AT30 -> 0 | AW30: 1 | AZ30: 1 | BB30: 1 | BD30: 1 | BF30: 1 | BN30: 1 | BO30: 1 | BP30: 9 | BR30: =BQ30+BP30+BO30+BN30 -> 11 | CD30: 2 | CE30: 1 | CK30: =CI30+CG30+CE30+CC30+CA30+BY30+BW30+BS30 -> 1 | CL30: =CJ30+CH30+CF30+CD30+CB30+BZ30+BX30+BT30 -> 2 | CM30: =CL30+CK30 -> 3 | CN30: 11 | CQ30: =CP30+CO30+CN30 -> 11 | CR30: 11 | DA30: =CY30+CX30+CW30+CV30+CU30+CT30+CS30+CZ30 -> 0 | DB30: =DA30+CR30 -> 11 | DD30: 11 | DL30: =DK30+DJ30+DI30+DH30+DG30+DF30+DE30+DD30+DC30 -> 11 | DN30: 11 | DQ30: =DP30+DO30+DN30+DM30 -> 11 | DR30: 2 | DZ30: 11 | EC30: =DW30+DU30+DS30+DY30 -> 0 | ED30: =DX30+DV30+DT30+DZ30 -> 11 | EE30: =ED30+EC30 -> 11 | EK30: 5 | EM30: 6 | EP30: =EN30+EL30+EJ30+EH30+EF30 -> 0 | EQ30: =EO30+EM30+EK30+EI30+EG30 -> 11 | ER30: =EQ30+EP30 -> 11 | ES30: 1 | EU30: 2012 | EV30: 85051/ 23 | EW30: 3 | EX30: 1 | EZ30: 1 | FC30: 1 | FE30: 2 | FF30: 1 | FI30: 4 | FJ30: 7 | FK30: =FJ30+FI30 -> 11 | FL30: 1 | FS30: 1 | FV30: 1 | FW30: 1 | FY30: 1 | GA30: 1 | GF30: 1 | GI30: 1 | GJ30: 1 | GL30: 1 | GP30: 1 | GR30: 1 | GT30: 1 | GW30: 1 | HA30: 1 | HB30: 1 | HF30: 1 | HJ30: 1 | HN30: 40 | HO30: 20 | HP30: 8 | HR30: 1 | HS30: 1 | HT30: 1 | HX30: 1 | IA30: 1 | IG30: 1 | IH30: 278 | II30: 181 | IJ30: =II30+IH30 -> 459 | IK30: شارع ابو حكمت -شركة الكفيل | IL30: انوار إبراهيم حميد | IM30: 7801563616
A31: 26 | B31: 1401004 | C31: النجف | D31: النجف | E31: المركز | F31: حمائم السلام | G31: مجمع حي السلام | J31: 1 | K31: 1 | M31: 1 | Q31: 1 | T31: 1 | Y31: 34 | Z31: 40 | AA31: 21 | AB31: 31 | AC31: =AA31+Y31 -> 55 | AD31: =AB31+Z31 -> 71 | AE31: =AD31+AC31 -> 126 | AF31: 2 | AG31: 2 | AH31: =AG31+AF31 -> 4 | AM31: =AK31+AI31 -> 0 | AN31: =AL31+AJ31 -> 0 | AO31: =AN31+AM31 -> 0 | AT31: =AR31+AP31 -> 0 | AU31: =AS31+AQ31 -> 0 | AV31: =AU31+AT31 -> 0 | AX31: 1 | AZ31: 1 | BB31: 1 | BD31: 1 | BF31: 1 | BN31: 1 | BO31: 1 | BP31: 9 | BR31: =BQ31+BP31+BO31+BN31 -> 11 | CD31: 1 | CE31: 1 | CK31: =CI31+CG31+CE31+CC31+CA31+BY31+BW31+BS31 -> 1 | CL31: =CJ31+CH31+CF31+CD31+CB31+BZ31+BX31+BT31 -> 1 | CM31: =CL31+CK31 -> 2 | CN31: 11 | CQ31: =CP31+CO31+CN31 -> 11 | CR31: 9 | CW31: 2 | DA31: =CY31+CX31+CW31+CV31+CU31+CT31+CS31+CZ31 -> 2 | DB31: =DA31+CR31 -> 11 | DC31: 1 | DD31: 1 | DF31: 4 | DG31: 4 | DH31: 1 | DL31: =DK31+DJ31+DI31+DH31+DG31+DF31+DE31+DD31+DC31 -> 11 | DN31: 10 | DO31: 1 | DQ31: =DP31+DO31+DN31+DM31 -> 11 | DR31: 1 | DT31: 3 | DV31: 1 | DX31: 4 | DZ31: 3 | EC31: =DW31+DU31+DS31+DY31 -> 0 | ED31: =DX31+DV31+DT31+DZ31 -> 11 | EE31: =ED31+EC31 -> 11 | EI31: 3 | EK31: 6 | EM31: 2 | EP31: =EN31+EL31+EJ31+EH31+EF31 -> 0 | EQ31: =EO31+EM31+EK31+EI31+EG31 -> 11 | ER31: =EQ31+EP31 -> 11 | ES31: 1 | EU31: 2013 | EX31: 1 | EZ31: 1 | FD31: 1 | FF31: 1 | FI31: 4 | FJ31: 6 | FK31: =FJ31+FI31 -> 10 | FL31: 1 | FS31: 1 | FU31: 1 | FW31: 1 | FY31: 1 | GA31: 1 | GF31: 1 | GH31: 1 | GJ31: 1 | GL31: 1 | GP31: 1 | GR31: 1 | GT31: 1 | GW31: 1 | GX31: 1 | HB31: 1 | HF31: 1 | HJ31: 1 | HN31: 20 | HO31: 62 | HP31: 3 | HQ31: 2 | HR31: 1 | HV31: 1 | HY31: 1 | IJ31: =II31+IH31 -> 0 | IK31: شقق السلام | IL31: وسام موسى حسين | IM31: 7817225550
A32: 27 | B32: 1401121 | C32: النجف | D32: النجف | E32: المركز | F32: العصافير | G32: العسكري | J32: 1 | K32: 1 | M32: 1 | Q32: 1 | T32: 1 | Y32: 20 | Z32: 31 | AA32: 85 | AB32: 84 | AC32: =AA32+Y32 -> 105 | AD32: =AB32+Z32 -> 115 | AE32: =AD32+AC32 -> 220 | AF32: 1 | AG32: 3 | AH32: =AG32+AF32 -> 4 | AI32: 6 | AJ32: 4 | AK32: 7 | AL32: 8 | AM32: =AK32+AI32 -> 13 | AN32: =AL32+AJ32 -> 12 | AO32: =AN32+AM32 -> 25 | AT32: =AR32+AP32 -> 0 | AU32: =AS32+AQ32 -> 0 | AV32: =AU32+AT32 -> 0 | AX32: 1 | AZ32: 1 | BB32: 1 | BD32: 1 | BF32: 1 | BN32: 1 | BO32: 1 | BP32: 8 | BR32: =BQ32+BP32+BO32+BN32 -> 10 | CC32: 1 | CD32: 4 | CK32: =CI32+CG32+CE32+CC32+CA32+BY32+BW32+BS32 -> 1 | CL32: =CJ32+CH32+CF32+CD32+CB32+BZ32+BX32+BT32 -> 4 | CM32: =CL32+CK32 -> 5 | CN32: 10 | CQ32: =CP32+CO32+CN32 -> 10 | CR32: 9 | CW32: 1 | DA32: =CY32+CX32+CW32+CV32+CU32+CT32+CS32+CZ32 -> 1 | DB32: =DA32+CR32 -> 10 | DD32: 1 | DF32: 1 | DG32: 7 | DH32: 1 | DL32: =DK32+DJ32+DI32+DH32+DG32+DF32+DE32+DD32+DC32 -> 10 | DN32: 8 | DO32: 1 | DP32: 1 | DQ32: =DP32+DO32+DN32+DM32 -> 10 | DT32: 4 | DV32: 3 | DZ32: 3 | EC32: =DW32+DU32+DS32+DY32 -> 0 | ED32: =DX32+DV32+DT32+DZ32 -> 10 | EE32: =ED32+EC32 -> 10 | EG32: 1 | EI32: 6 | EK32: 2 | EM32: 1 | EP32: =EN32+EL32+EJ32+EH32+EF32 -> 0 | EQ32: =EO32+EM32+EK32+EI32+EG32 -> 10 | ER32: =EQ32+EP32 -> 10 | ES32: 1 | EU32: 2014 | EV32: 5062 | EW32: 4 | EX32: 1 | EZ32: 1 | FC32: 1 | FE32: 6 | FF32: 1 | FI32: 4 | FJ32: 5 | FK32: =FJ32+FI32 -> 9 | FL32: 1 | FS32: 1 | FU32: 1 | FW32: 1 | FY32: 1 | GA32: 1 | GF32: 1 | GI32: 1 | GJ32: 1 | GL32: 1 | GO32: 1 | GS32: 1 | GT32: 1 | GW32: 1 | HB32: 1 | HF32: 1 | HI32: 1 | HN32: 65 | HO32: 30 | HP32: 4 | HQ32: 2 | HR32: 1 | HT32: 1 | HU32: 1 | HY32: 1 | IJ32: =II32+IH32 -> 0 | IK32: شارع عسكري مدارس | IL32: انوار عبد المحمد كاظم | IM32: 7847950009
A33: 28 | B33: 1401402 | C33: النجف | D33: النجف | E33: المركز | F33: الملاك | G33: السلام | J33: 1 | K33: 1 | M33: 1 | Q33: 1 | T33: 1 | Y33: 28 | Z33: 40 | AA33: 45 | AB33: 41 | AC33: =AA33+Y33 -> 73 | AD33: =AB33+Z33 -> 81 | AE33: =AD33+AC33 -> 154 | AF33: 1 | AG33: 2 | AH33: =AG33+AF33 -> 3 | AM33: =AK33+AI33 -> 0 | AN33: =AL33+AJ33 -> 0 | AO33: =AN33+AM33 -> 0 | AX33: 1 | AZ33: 1 | BB33: 1 | BD33: 1 | BF33: 1 | BN33: 1 | BO33: 1 | BP33: 5 | BR33: =BQ33+BP33+BO33+BN33 -> 7 | CD33: 2 | CK33: =CI33+CG33+CE33+CC33+CA33+BY33+BW33+BS33 -> 0 | CL33: =CJ33+CH33+CF33+CD33+CB33+BZ33+BX33+BT33 -> 2 | CM33: =CL33+CK33 -> 2 | CN33: 7 | CQ33: =CP33+CO33+CN33 -> 7 | CR33: 6 | CX33: 1 | DA33: =CY33+CX33+CW33+CV33+CU33+CT33+CS33+CZ33 -> 1 | DB33: =DA33+CR33 -> 7 | DF33: 2 | DG33: 5 | DL33: =DK33+DJ33+DI33+DH33+DG33+DF33+DE33+DD33+DC33 -> 7 | DM33: 1 | DN33: 6 | DQ33: =DP33+DO33+DN33+DM33 -> 7 | DR33: 4 | DT33: 2 | DV33: 1 | DX33: 2 | DZ33: 2 | EC33: =DW33+DU33+DS33+DY33 -> 0 | ED33: =DX33+DV33+DT33+DZ33 -> 7 | EE33: =ED33+EC33 -> 7 | EI33: 5 | EK33: 1 | EM33: 1 | EP33: =EN33+EL33+EJ33+EH33+EF33 -> 0 | EQ33: =EO33+EM33+EK33+EI33+EG33 -> 7 | ER33: =EQ33+EP33 -> 7 | ES33: 1 | EU33: 2019 | EX33: 1 | EZ33: 1 | FD33: 1 | FF33: 1 | FI33: 4 | FJ33: 4 | FK33: =FJ33+FI33 -> 8 | FL33: 1 | FS33: 1 | FU33: 1 | FW33: 1 | FY33: 1 | GA33: 1 | GF33: 1 | GH33: 1 | GJ33: 1 | GL33: 1 | GO33: 1 | GR33: 1 | GT33: 1 | GW33: 1 | HA33: 1 | HB33: 1 | HF33: 1 | HI33: 1 | HN33: 46 | HO33: 2 | HP33: 4 | HR33: 2 | HT33: 1 | HY33: 1 | IJ33: =II33+IH33 -> 0 | IK33: مقابل مدرسة الموهوبين | IL33: نغم عبد الهادي عبدالامير | IM33: 7715796306
A34: مجموع مركز قضاء النجف | H34: =SUM(H6:H33) -> 0 | I34: =SUM(I6:I33) -> 0 | J34: =SUM(J6:J33) -> 28 | K34: =SUM(K6:K33) -> 28 | L34: =SUM(L6:L33) -> 0 | M34: =SUM(M6:M33) -> 28 | N34: =SUM(N6:N33) -> 0 | O34: =SUM(O6:O33) -> 0 | ... ET34: =SUM(ET6:ET33) -> 0 | EX34: =SUM(EX6:EX33) -> 24 | EY34: =SUM(EY6:EY33) -> 4 | EZ34: =SUM(EZ6:EZ33) -> 26 | FA34: =SUM(FA6:FA33) -> 2 | FB34: =SUM(FB6:FB33) -> 0 | FC34: =SUM(FC6:FC33) -> 17 | FD34: =SUM(FD6:FD33) -> 11 | FE34: =SUM(FE6:FE33) -> 57 | ... HY34: =SUM(HY6:HY33) -> 3 | ID34: =SUM(ID6:ID33) -> 1 | IE34: =SUM(IE6:IE33) -> 13 | IF34: =SUM(IF6:IF33) -> 6 | IG34: =SUM(IG6:IG33) -> 4 | IH34: =SUM(IH6:IH33) -> 3886 | II34: =SUM(II6:II33) -> 6064 | IJ34: =SUM(IJ6:IJ33) -> 9950
A35: 1 | B35: 1400154 | C35: النجف | D35: النجف | E35: الحيدرية | F35: الزنابق | G35: 17ـ ربيع الاول | J35: 1 | K35: 1 | M35: 1 | Q35: 1 | T35: 1 | Y35: 60 | Z35: 40 | AA35: 115 | AB35: 85 | AC35: =AA35+Y35 -> 175 | AD35: =AB35+Z35 -> 125 | AE35: =AD35+AC35 -> 300 | AF35: 1 | AG35: 2 | AH35: =AG35+AF35 -> 3 | AM35: =AK35+AI35 -> 0 | AN35: =AL35+AJ35 -> 0 | AO35: =AN35+AM35 -> 0 | AT35: =AR35+AP35 -> 0 | AU35: =AS35+AQ35 -> 0 | AV35: =AU35+AT35 -> 0 | AX35: 1 | AZ35: 1 | BB35: 1 | BD35: 1 | BF35: 1 | BN35: 1 | BP35: 7 | BR35: =BQ35+BP35+BO35+BN35 -> 8 | CB35: 1 | CC35: 1 | CD35: 2 | CE35: 1 | CK35: =CI35+CG35+CE35+CC35+CA35+BY35+BW35+BS35 -> 2 | CL35: =CJ35+CH35+CF35+CD35+CB35+BZ35+BX35+BT35 -> 3 | CM35: =CL35+CK35 -> 5 | CN35: 8 | CQ35: =CP35+CO35+CN35 -> 8 | CR35: 7 | CX35: 1 | DA35: =CY35+CX35+CW35+CV35+CU35+CT35+CS35+CZ35 -> 1 | DB35: =DA35+CR35 -> 8 | DD35: 2 | DG35: 6 | DL35: =DK35+DJ35+DI35+DH35+DG35+DF35+DE35+DD35+DC35 -> 8 | DM35: 3 | DN35: 4 | DO35: 1 | DQ35: =DP35+DO35+DN35+DM35 -> 8 | DR35: 1 | DT35: 6 | DZ35: 2 | EC35: =DW35+DU35+DS35+DY35 -> 0 | ED35: =DX35+DV35+DT35+DZ35 -> 8 | EE35: =ED35+EC35 -> 8 | EI35: 2 | EM35: 6 | EP35: =EN35+EL35+EJ35+EH35+EF35 -> 0 | EQ35: =EO35+EM35+EK35+EI35+EG35 -> 8 | ER35: =EQ35+EP35 -> 8 | ES35: 1 | EU35: 1979 | EV35: 505/114 | EW35: 6 | EX35: 1 | EZ35: 1 | FC35: 1 | FE35: 6 | FF35: 1 | FI35: 4 | FJ35: 8 | FK35: =FJ35+FI35 -> 12 | FL35: 1 | FS35: 1 | FU35: 1 | FW35: 1 | FY35: 1 | GA35: 1 | GF35: 1 | GI35: 1 | GJ35: 1 | GL35: 1 | GP35: 1 | GR35: 1 | GT35: 1 | GW35: 1 | GZ35: 1 | HB35: 1 | HF35: 1 | HI35: 1 | HN35: 110 | HO35: 50 | HP35: 6 | HU35: 1 | HX35: 1 | HZ35: 1 | IF35: 1 | IH35: 240 | IJ35: =II35+IH35 -> 240 | IK35: مركز شرطة الحيدرية | IL35: سكينة جمعة فرعون | IM35: 7802586105
A36: مجموع مركز ناحية الحيدرية | H36: =H35 -> 0 | I36: =I35 -> 0 | J36: =J35 -> 1 | K36: =K35 -> 1 | L36: =L35 -> 0 | M36: =M35 -> 1 | N36: =N35 -> 0 | O36: =O35 -> 0 | ... ET36: =ET35 -> 0 | EX36: =EX35 -> 1 | EY36: =EY35 -> 0 | EZ36: =EZ35 -> 1 | FA36: =FA35 -> 0 | FB36: =FB35 -> 0 | FC36: =FC35 -> 1 | FD36: =FD35 -> 0 | FE36: =FE35 -> 6 | ... HY36: =HY35 -> 0 | ID36: =ID35 -> 0 | IE36: =IE35 -> 0 | IF36: =IF35 -> 1 | IG36: =IG35 -> 0 | IH36: =IH35 -> 240 | II36: =II35 -> 0 | IJ36: =IJ35 -> 240
