Workbook

Sheet المهني
A1: المديرية العامة للتربية في محافظة النجف الاشرف | K1: دوام المدرسة | O1: استقلالية المدرسة | Q1: نوع الازدواج | U1: هل المدرسة فتح جديد | V1: عدد الطلبة المستجدين في الصف الاول حسب العمر | AI1: عدد الطلبة المسجلين في الصف الاول حسب العمر والجنس | AV1: عدد الطلبة المسجلين في الصف الثاني حسب العمر والجنس | BI1: عدد الطلبة المسجلين في الصف الثالث حسب العمر والجنس | BV1: عدد الطلبة المسجلين حسب الصف والجنس (المجموع الكلي) | CM1: عدد الشعب حسب الصف والجنس | CZ1: عدد الطلبة التاركين حسب الصف والجنس للعام الدراسي 2025 / 2026 | DI1: عدد الطلبة المشاركين في الامتحانات النهائية و حسب الصف والجنس للعام الدراسي 2015 / 2021 | DR1: عدد الطلبة الناجحين حسب الصف والجنس للعام الدراسي 2024 / 2025 | EA1: عدد الطلبة الراسبين بسبب الفشل في الامتحان و حسب الصف والجنس للعام الدراسي 2024 / 2025 | EJ1: عدد الطلبة الراسبين بسبب تجاوز ايام الغياب و حسب الصف والجنس للعام الدراسي 2024 / 2025 | ES1: عدد الطلبة الراسبين لاسباب اخرى و حسب الصف والجنس للعام الدراسي 2024 / 2025 | FB1: اعضاء الهيئة التعليمية و التدريسية حسب العنوان الوظيفي | FO1: الموظفون الاداريون والخدميون حسب العنوان الوظيفي | GJ1: عدد اعضاء الهيئة التعليمية والتدريسية حسب الاختصاص | KY1: عدد اعضاء الهئية التعليمية والتدريسية حسب الحالة الوظيفية | LT1: عدد الهيئة التدريسية حسب سنوات الخدمة | ME1: عدد الهيئة التدريسية حسب سنوات العمر | MR1: عدد اعضاء الهئية التعليمية والتدريسية حسب الحالة الاجتماعية | NC1: عدد المدرسين المشاركين في الدورات التدريبية للعام الماضي | NE1: اعضاء الهيئة التعليمية والتدريسية حسب الشهادة | NZ1: عددالطلبة المسجلين من غير العراقيين
OI2: هل المدرسة مشمولة بـ :- | OU2: الأبنية المدرسية | RU2: الحاسبات :- | SA2: المكتبات المدرسية :-
A3: التعليـــم المهـــني الاهـــــلي 2026/2025 | F3: جنس المدرسة | I3: بيئة المدرسة | KY3: داخل قوة العمل | LA3: خارج قوة العمل | LQ3: المجموع الكلي | NE3: اعدادية | NG3: دبلوم تعليمي | NI3: دبلوم عام | NK3: بكلوريوس عام | NM3: بكلوريوس تعليمي | NO3: دبلوم عالي | NQ3: ماجستير | NS3: دكتوراه | NU3: اخرى تذكر | NW3: المجموع | OI3: الارشاد التربوي | OK3: تدريس الحاسوب | OM3: خدمة الانترنت | OO3: اللغات | OQ3: اذا كان الجواب نعم اذكر اللغة | OU3: عدد الابنية المدرسية حسب :- | PV3: هل تتوفر في البناية مرافق صحية | QB3: هل ترتبط البناية بشبكة الماء الصالح للشرب | QD3: مصدر الماء | QI3: هل البناية مزودة بخدمة المجاري | QK3: نوع المجاري | QM3: هل هناك سياج حول البناية | QO3: نوع السياج | QR3: حالة السياج | QU3: هل توجد ساحة رياضية | QW3: نوع الساحة الرياضية | RB3: هل توجد حديقة مدرسية | RD3: هل توجد قاعة انشطة مستقلة | RO3: عدد الرحلات مقعدين | RQ3: عدد الرحلات مقعد واحد | RS3: عدد السبورات | RU3: عدد الحاسبات الالكترونية (كومبيوتر) | RW3: عدد الطابعات | RY3: عدد الماسحات الضوئية (سكنرات) | SA3: هل توجد مكتبة | SC3: من المسؤول عن المكتبة | SI3: نوعية المكتبة | SL3: عدد الكتب والمجلات والقصص | SO3: عدد الورش المستقلة الموجودة | SP3: عدد الورش الصالحة
V4: 15 سنة | X4: 16 سنة | Z4: 17 سنة | AB4: 18 سنة | AD4: 19 سنة | AF4: المجموع | AI4: 15 سنة | AK4: 16 سنة | AM4: 17 سنة | AO4: 18 سنة | AQ4: 19 سنة | AS4: المجموع | AV4: 16 سنة | AX4: 17 سنة | AZ4: 18 سنة | BB4: 19 سنة | BD4: 20 سنة | BF4: المجموع | BI4: 17سنة | BK4: 18سنة | BM4: 19سنة | BO4: 20سنة | BQ4: 21سنة | BS4: المجموع | BV4: 15سنة | BX4: 16سنة | BZ4: 17سنة | CB4: 18سنة | CD4: 19سنة | CF4: 20سنة | CH4: 21سنة | CJ4: المجموع | CM4: الصف الاول | CP4: الصف الثاني | CS4: الصف الثالث | CV4: المجموع | CZ4: الصف الاول | DB4: الصف الثاني | DD4: الصف الثالث | DF4: المجموع | DI4: الصف الاول | DK4: الصف الثاني | DM4: الصف الثالث | DO4: المجموع | DR4: الصف الاول | DT4: الصف الثاني | DV4: الصف الثالث | DX4: المجموع | EA4: الصف الاول | EC4: الصف الثاني | EE4: الصف الثالث | EG4: المجموع | EJ4: الصف الاول | EL4: الصف الثاني | EN4: الصف الثالث | EP4: المجموع | ES4: الصف الاول | EU4: الصف الثاني | EW4: الصف الثالث | EY4: المجموع | FB4: مدير | FD4: معاون | FF4: مدرس | FH4: معلم مهني | FJ4: مرشد تربوي | FL4: المجموع | FO4: موظف ادارة | FQ4: كاتب | FS4: محاسب | FU4: امين مكتبة | FW4: موظف خدمة | FY4: حارس | GA4: سائق | GC4: حرفي | GE4: فلاح | GG4: المجموع | GJ4: التربية الاسلامية | GL4: اللغة العربية | GN4: اللغة الانكليزية | GP4: اللغة الكردية | GR4: الرياضيات | GT4: الفيزياء | GV4: الكيمياء | GX4: علوم الحياة | GZ4: التاريخ | HB4: الجغرافية | HD4: الاجتماع | HF4: التربية الرياضية | HH4: التربية الفنية | HJ4: زراعة عامة | HL4: انتاج نباتي | HN4: الغابات | HP4: انتاج حيواني | HR4: البستنة | HT4: محاصيل حقلية | HV4: صناعات غذائية والبان | HX4: التربة | HZ4: اقتصاد وارشاد زراعي | IB4: مقاومة الافات | ID4: البيطرة العامة | IF4: الكهرباء | IH4: ميكانيك | IJ4: السيارات | IL4: المعامل | IN4: راديو وتلفزيون | IP4: السباكة | IR4: النجارة | IT4: النسيج | IV4: الطباعة | IX4: تاسيس صحيات | IZ4: صناعة زجاج | JB4: البناء | JD4: النماذج | JF4: بترو كمياويات | JH4: مكننة زراعية | JJ4: المعادن | JL4: العلوم التجارية | JN4: محاسبة | JP4: ادارة | JR4: الاحصاء | JT4: الاقتصاد | JV4: السكرتارية | JX4: ادارة المزارع | JZ4: تعاونيات زراعية | KB4: هندسة كيمياوية | KD4: رسم هندسي | KF4: علم نفس | KH4: القانون | KJ4: اقتصاد منزلي | KL4: محاسبة كلفة | KN4: حاسوب | KP4: اللغة التركمانية | KR4: اللغة السريانية | KT4: اخرى | KV4: المجموع | LA4: بعثة او زمالة | LC4: اجازة دراسية | LE4: اجازة مصاحبة | LG4: اجازة بدون راتب | LI4: اجازة مرضية طويلة | LK4: اجازة امومة | LM4: منسب الى جهات اخرى | LO4: 4-5سنوات | LT4: 5سنوات فاقل | LV4: 6ــ10 | LX4: 11ــ15 | LZ4: 16فاكثر | MB4: المجموع | ME4: اقل من 30 | MG4: 30ــ39 | MI4: 40ــ49 | MK4: 50ــ59 | MM4: 60ــ فاكثر | MO4: المجموع الكلي | MR4: اعزب | MT4: متزوج | MV4: ارمل | MX4: مطلق | MZ4: المجموع | NC4: عدد المدرسين | NZ4: الاول المهني | OB4: الثاني مهني | OD4: الثالث المهني | OF4: المجموع | OU4: نوع البناء | OW4: البناية | OZ4: هل توجد مساحة للتوسعة | PB4: عدد الطوابق | PE4: حجم المدرسة | PJ4: هل المدرسة تحتاج الى صفوف اضافية | PM4: عدد الغرف في البناية | PP4: مادة البناء | RF4: عدد المدارس التي تشغلها | RI4: العائدية | RL4: الحالة العمرانية
A5: القضاء | B5: الناحية | C5: ت | D5: الرقم الاحصائي | E5: اسم المدرسة | F5: بنون | G5: بنات | H5: مختلط | I5: حضر | J5: ريف | K5: صباحا | L5: ظهرا | M5: صباحا وظهرا | N5: مساءا | O5: اصلية | P5: ضيف | Q5: غير مزدوجة | R5: مع نفسها | S5: مع اخرى | T5: مع نفسها ومع اخرى | V5: بنون | W5: بنات | X5: بنون | Y5: بنات | Z5: بنون | AA5: بنات | AB5: بنون | AC5: بنات | AD5: بنون | AE5: بنات | AF5: بنون | AG5: بنات | AH5: المجموع | AI5: بنون | AJ5: بنات | AK5: بنون | AL5: بنات | AM5: بنون | AN5: بنات | AO5: بنون | AP5: بنات | AQ5: بنون | AR5: بنات | AS5: بنون | AT5: بنات | AU5: المجموع | AV5: بنون | AW5: بنات | AX5: بنون | AY5: بنات | AZ5: بنون | BA5: بنات | BB5: بنون | BC5: بنات | BD5: بنون | BE5: بنات | BF5: بنون | BG5: بنات | BH5: المجموع | BI5: بنون | BJ5: بنات | BK5: بنون | BL5: بنات | BM5: بنون | BN5: بنات | BO5: بنون | BP5: بنات | BQ5: بنون | BR5: بنات | BS5: بنون | BT5: بنات | BU5: المجموع | BV5: بنون | BW5: بنات | BX5: بنون | BY5: بنات | BZ5: بنون | CA5: بنات | CB5: بنون | CC5: بنات | CD5: بنون | CE5: بنات | CF5: بنون | CG5: بنات | CH5: بنون | CI5: بنات | CJ5: بنون | CK5: بنات | CL5: المجموع | CM5: بنون | CN5: بنات | CO5: مختلطة | CP5: بنون | CQ5: بنات | CR5: مختلطة | CS5: بنون | CT5: بنات | CU5: مختلطة | CV5: بنون | CW5: بنات | CX5: مختلطة | CY5: المجموع | CZ5: بنون | DA5: بنات | DB5: بنون | DC5: بنات | DD5: بنون | DE5: بنات | DF5: بنون | DG5: بنات | DH5: المجموع | DI5: بنون | DJ5: بنات | DK5: بنون | DL5: بنات | DM5: بنون | DN5: بنات | DO5: بنون | DP5: بنات | DQ5: المجموع | DR5: بنون | DS5: بنات | DT5: بنون | DU5: بنات | DV5: بنون | DW5: بنات | DX5: بنون | DY5: بنات | DZ5: المجموع | EA5: بنون | EB5: بنات | EC5: بنون | ED5: بنات | EE5: بنون | EF5: بنات | EG5: بنون | EH5: بنات | EI5: المجموع | EJ5: بنون | EK5: بنات | EL5: بنون | EM5: بنات | EN5: بنون | EO5: بنات | EP5: بنون | EQ5: بنات | ER5: المجموع | ES5: بنون | ET5: بنات | EU5: بنون | EV5: بنات | EW5: بنون | EX5: بنات | EY5: بنون | EZ5: بنات | FA5: المجموع | FB5: ذكور | FC5: اناث | FD5: ذكور | FE5: اناث | FF5: ذكور | FG5: اناث | FH5: ذكور | FI5: اناث | FJ5: ذكور | FK5: اناث | FL5: ذكور | FM5: اناث | FN5: المجموع | FO5: ذكور | FP5: اناث | FQ5: ذكور | FR5: اناث | FS5: ذكور | FT5: اناث | FU5: ذكور | FV5: اناث | FW5: ذكور | FX5: اناث | FY5: ذكور | FZ5: اناث | GA5: ذكور | GB5: اناث | GC5: ذكور | GD5: اناث | GE5: ذكور | GF5: اناث | GG5: ذكور | GH5: اناث | GI5: المجموع | GJ5: ذكور | GK5: اناث | GL5: ذكور | GM5: اناث | GN5: ذكور | GO5: اناث | GP5: ذكور | GQ5: اناث | GR5: ذكور | GS5: اناث | GT5: ذكور | GU5: اناث | GV5: ذكور | GW5: اناث | GX5: ذكور | GY5: اناث | GZ5: ذكور | HA5: اناث | HB5: ذكور | HC5: اناث | HD5: ذكور | HE5: اناث | HF5: ذكور | HG5: اناث | HH5: ذكور | HI5: اناث | HJ5: ذكور | HK5: اناث | HL5: ذكور | HM5: اناث | HN5: ذكور | HO5: اناث | HP5: ذكور | HQ5: اناث | HR5: ذكور | HS5: اناث | HT5: ذكور | HU5: اناث | HV5: ذكور | HW5: اناث | HX5: ذكور | HY5: اناث | HZ5: ذكور | IA5: اناث | IB5: ذكور | IC5: اناث | ID5: ذكور | IE5: اناث | IF5: ذكور | IG5: اناث | IH5: ذكور | II5: اناث | IJ5: ذكور | IK5: اناث | IL5: ذكور | IM5: اناث | IN5: ذكور | IO5: اناث | IP5: ذكور | IQ5: اناث | IR5: ذكور | IS5: اناث | IT5: ذكور | IU5: اناث | IV5: ذكور | IW5: اناث | IX5: ذكور | IY5: اناث | IZ5: ذكور | JA5: اناث | JB5: ذكور | JC5: اناث | JD5: ذكور | JE5: اناث | JF5: ذكور | JG5: اناث | JH5: ذكور | JI5: اناث | JJ5: ذكور | JK5: اناث | JL5: ذكور | JM5: اناث | JN5: ذكور | JO5: اناث | JP5: ذكور | JQ5: اناث | JR5: ذكور | JS5: اناث | JT5: ذكور | JU5: اناث | JV5: ذكور | JW5: اناث | JX5: ذكور | JY5: اناث | JZ5: ذكور | KA5: اناث | KB5: ذكور | KC5: اناث | KD5: ذكور | KE5: اناث | KF5: ذكور | KG5: اناث | KH5: ذكور | KI5: اناث | KJ5: ذكور | KK5: اناث | KL5: ذكور | KM5: اناث | KN5: ذكور | KO5: اناث | KP5: ذكور | KQ5: اناث | KR5: ذكور | KS5: اناث | KT5: ذكور | KU5: اناث | KV5: ذكور | KW5: اناث | KX5: المجموع | KY5: ذكور | KZ5: اناث | LA5: ذكور | LB5: اناث | LC5: ذكور | LD5: اناث | LE5: ذكور | LF5: اناث | LG5: ذكور | LH5: اناث | LI5: ذكور | LJ5: اناث | LK5: ذكور | LL5: اناث | LM5: ذكور | LN5: اناث | LO5: ذكور | LP5: اناث | LQ5: ذكور | LR5: اناث | LS5: المجموع | LT5: ذكور | LU5: اناث | LV5: ذكور | LW5: اناث | LX5: ذكور | LY5: اناث | LZ5: ذكور | MA5: اناث | MB5: ذكور | MC5: اناث | MD5: المجموع | ME5: ذكور | MF5: اناث | MG5: ذكور | MH5: اناث | MI5: ذكور | MJ5: اناث | MK5: ذكور | ML5: اناث | MM5: ذكور | MN5: اناث | MO5: ذكور | MP5: اناث | MQ5: المجموع | MR5: ذكور | MS5: اناث | MT5: ذكور | MU5: اناث | MV5: ذكور | MW5: اناث | MX5: ذكور | MY5: اناث | MZ5: ذكور | NA5: اناث | NB5: المجموع | NC5: ذكور | ND5: اناث | NE5: ذكور | NF5: اناث | NG5: ذكور | NH5: اناث | NI5: ذكور | NJ5: اناث | NK5: ذكور | NL5: اناث | NM5: ذكور | NN5: اناث | NO5: ذكور | NP5: اناث | NQ5: ذكور | NR5: اناث | NS5: ذكور | NT5: اناث | NU5: ذكور | NV5: اناث | NW5: ذكور | NX5: اناث | NY5: المجموع | NZ5: بنون | OA5: بنات | OB5: بنون | OC5: بنات | OD5: بنون | OE5: بنات | OF5: بنون | OG5: بنات | OH5: المجموع | OI5: نعم | OJ5: كلا | OK5: نعم | OL5: كلا | OM5: نعم | ON5: كلا | OO5: نعم | OP5: كلا | OQ5: فرنسي | OR5: روسي | OS5: اسباني | OT5: كردي | OU5: مدرسي | OV5: غير مدرسي | OW5: سنة البناء | OX5: رقم القطعة | OY5: رقم المقاطعة | OZ5: نعم | PA5: كلا | PB5: طابق واحد | PC5: طابقين | PD5: ثلاث طوابق | PE5: 6صف | PF5: 9صف | PG5: 12صف | PH5: 18صف | PI5: 24صف | PJ5: نعم | PK5: كلا | PL5: عدد الصفوف الاضافية | PM5: عدد الصفوف في البناية | PN5: عدد الغرف الاخرى | PO5: المجموع الكلي للغرف في البناية | PP5: طابوق او حجر او بلوك | PQ5: طين او صريفة | PR5: هياكل حديدية | PS5: بناء جاهز | PT5: كرفان | PU5: اخرى | PV5: نعم | PW5: كلا | PX5: صالحة | PY5: غيرصالحة | PZ5: كافية | QA5: غيركافية | QB5: نعم | QC5: كلا | QD5: بلدية | QE5: بئر عميق | QF5: نهر | QG5: صهاريج | QH5: اخرى | QI5: نعم | QJ5: كلا | QK5: شبكة المجاري | QL5: خزانات | QM5: نعم | QN5: كلا | QO5: بناء | QP5: اسلاك | QQ5: اخرى | QR5: جيد | QS5: متصدع | QT5: غير امن | QU5: نعم | QV5: كلا | QW5: كرة قدم | QX5: كرة سلة | QY5: كرة طائرة | QZ5: ساحة رياضية | RA5: اخرى | RB5: نعم | RC5: كلا | RD5: نعم | RE5: كلا | RF5: مدرسة واحدة | RG5: مدرستان | RH5: ثلاث مدارس | RI5: حكومية تابعة لوزارة التربية | RJ5: حكومية تابعة لجهات اخرى | RK5: مستأجرة | RL5: صالحة | RM5: بحاجة الى ترميم | RN5: غير صالحة | RO5: الصالح | RP5: العاطل | RQ5: الصالح | RR5: العاطل | RS5: الصالح | RT5: العاطل | RU5: الصالح | RV5: العاطل | RW5: الصالح | RX5: العاطل | RY5: الصالح | RZ5: العاطل | SA5: نعم | SB5: كلا | SC5: مدير | SD5: معاون | SE5: مدرس او معلم | SF5: امين مكتبة | SG5: كاتب | SH5: قاعة | SI5: غرفة | SJ5: خزانة | SK5: رفوف عارضة | SL5: عدد الكتب | SM5: عدد المجلات والقصص | SN5: العدد الكلي للكتب | SQ5: اقرب نقطة | SR5: اسم المدير | SS5: رقم الموبايل
A6: النجف | B6: المركز | C6: 1 | D6: 1401721 | E6: ع . ايليا المهنية الاهلية | H6: 1 | I6: 1 | K6: 1 | O6: 1 | Q6: 1 | U6: 1 | V6: 67 | W6: 13 | X6: 59 | Y6: 20 | Z6: 45 | AA6: 20 | AB6: 29 | AC6: 7 | AF6: =AD6+AB6+Z6+X6+V6 -> 200 | AG6: =AE6+AC6+AA6+Y6+W6 -> 60 | AH6: =SUM(AF6:AG6) -> 260 | AI6: 67 | AJ6: 13 | AK6: 59 | AL6: 20 | AM6: 45 | AN6: 20 | AO6: 29 | AP6: 7 | AS6: =AQ6+AO6+AM6+AK6+AI6 -> 200 | AT6: =AR6+AP6+AN6+AL6+AJ6 -> 60 | AU6: =SUM(AS6:AT6) -> 260 | BF6: =BD6+BB6+AZ6+AX6+AV6 -> 0 | BG6: =BE6+BC6+BA6+AY6+AW6 -> 0 | BH6: =SUM(BF6:BG6) -> 0 | BS6: =BQ6+BO6+BM6+BK6+BI6 -> 0 | BT6: =BR6+BP6+BN6+BL6+BJ6 -> 0 | BU6: =SUM(BS6:BT6) -> 0 | BV6: =AI6 -> 67 | BW6: =AJ6 -> 13 | BX6: =AV6+AK6 -> 59 | BY6: =AL6+AW6 -> 20 | BZ6: =BI6+AX6+AM6 -> 45 | CA6: =AN6+AY6+BJ6 -> 20 | CB6: =BK6+AZ6+AO6 -> 29 | CC6: =AP6+BA6+BL6 -> 7 | CD6: =BM6+BB6+AQ6 -> 0 | CE6: =BN6+BC6+AR6 -> 0 | CF6: =BO6+BD6 -> 0 | CG6: =BP6+BE6 -> 0 | CH6: =BQ6 -> 0 | CI6: =BR6 -> 0 | CJ6: =BV6+BX6+BZ6+CB6+CD6+CF6+CH6 -> 200 | CK6: =BW6+BY6+CA6+CC6+CE6+CG6+CI6 -> 60 | CL6: =SUM(CJ6:CK6) -> 260 | CM6: 7 | CN6: 3 | CV6: =CS6+CP6+CM6 -> 7 | CW6: =CT6+CQ6+CN6 -> 3 | CX6: =CU6+CR6+CO6 -> 0 | CY6: =SUM(CV6:CX6) -> 10 | DF6: =DD6+DB6+CZ6 -> 0 | DG6: =DE6+DC6+DA6 -> 0 | DH6: =SUM(DF6:DG6) -> 0 | DO6: =DM6+DK6+DI6 -> 0 | DP6: =DN6+DL6+DJ6 -> 0 | DQ6: =SUM(DO6:DP6) -> 0 | DX6: =DV6+DT6+DR6 -> 0 | DY6: =DW6+DU6+DS6 -> 0 | DZ6: =SUM(DX6:DY6) -> 0 | EG6: =EE6+EC6+EA6 -> 0 | EH6: =EF6+ED6+EB6 -> 0 | EI6: =SUM(EG6:EH6) -> 0 | EP6: =EN6+EL6+EJ6 -> 0 | EQ6: =EO6+EM6+EK6 -> 0 | ER6: =SUM(EP6:EQ6) -> 0 | EY6: =EW6+EU6+ES6 -> 0 | EZ6: =EX6+EV6+ET6 -> 0 | FA6: =SUM(EY6:EZ6) -> 0 | FC6: 1 | FD6: 3 | FF6: 10 | FG6: 18 | FL6: =FJ6+FH6+FF6+FD6+FB6 -> 13 | FM6: =FK6+FI6+FG6+FE6+FC6 -> 19 | FN6: =SUM(FL6:FM6) -> 32 | GG6: =GE6+GA6+FY6+FW6+FU6+FS6+FO6+FQ6+GC6 -> 0 | GH6: =GF6+GB6+FZ6+FX6+FV6+FT6+FP6+FR6+GD6 -> 0 | GI6: =GH6+GG6 -> 0 | GJ6: 1 | GK6: 5 | GN6: 4 | GO6: 1 | GR6: 2 | GS6: 1 | GW6: 2 | HF6: 1 | IJ6: 1 | KO6: 5 | KT6: 4 | KU6: 5 | KV6: =KT6+KN6+KJ6+KH6+KF6+KD6+KB6+JZ6+JX6+JV6+JT6+JR6+JP6+JN6+JL6+JJ6+JH6+JF6+JD6+JB6+IZ6+IX6+IV6+IT6+IR6+IP6+IN6+IL6+IJ6+IH6+IF6+ID6+IB6+HZ6+HX6+HV6+HT6+HR6+HP6+HN6+HL6+HJ6+HH6+HF6+HD6+HB6+GZ6+GX6+GV6+GT6+GR6+GP6+GN6+GL6+GJ6 -> 13 | KW6: =KU6+KO6+KK6+KI6+KG6+KE6+KC6+KA6+JY6+JW6+JU6+JS6+JQ6+JO6+JM6+JK6+JI6+JG6+JE6+JC6+JA6+IY6+IW6+IU6+IS6+IQ6+IO6+IM6+IK6+II6+IG6+IE6+IC6+IA6+HY6+HW6+HU6+HS6+HQ6+HO6+HM6+HK6+HI6+HG6+HE6+HC6+HA6+GY6+GW6+GU6+GS6+GQ6+GO6+GM6+GK6 -> 19 | KX6: =KW6+KV6 -> 32 | KY6: 13 | KZ6: 19 | LQ6: =LA6+LC6+KY6+LE6+LG6+LI6+LK6+LM6+LO6 -> 13 | LR6: =LB6+LD6+KZ6+LF6+LH6+LJ6+LL6+LN6+LP6 -> 19 | LS6: =LR6+LQ6 -> 32 | LT6: 9 | LU6: 12 | LW6: 4 | LX6: 4 | LY6: 2 | MA6: 1 | MB6: =LX6+LV6+LT6+LZ6 -> 13 | MC6: =LY6+LW6+LU6+MA6 -> 19 | MD6: =MC6+MB6 -> 32 | ME6: 10 | MF6: 9 | MG6: 2 | MH6: 8 | MJ6: 2 | MM6: 1 | MO6: =MM6+MK6+MI6+MG6+ME6 -> 13 | MP6: =MN6+ML6+MJ6+MH6+MF6 -> 19 | MQ6: =MP6+MO6 -> 32 | MR6: 8 | MS6: 14 | MT6: 5 | MU6: 2 | MW6: 1 | MY6: 2 | MZ6: =MR6+MT6+MV6+MX6 -> 13 | NA6: =MS6+MU6+MW6+MY6 -> 19 | NB6: =NA6+MZ6 -> 32 | NI6: 1 | NK6: 7 | NL6: 6 | NM6: 4 | NN6: 13 | NO6: 1 | NW6: =NU6+NS6+NQ6+NO6+NM6+NK6+NG6+NI6+NE6 -> 13 | NX6: =NV6+NT6+NR6+NP6+NN6+NL6+NH6+NJ6+NF6 -> 19 | NY6: =NX6+NW6 -> 32 | OF6: =OD6+OB6+NZ6 -> 0 | OG6: =OE6+OC6+OA6 -> 0 | OH6: =OG6+OF6 -> 0 | OJ6: 1 | OK6: 1 | OM6: 1 | OP6: 1 | OU6: 1 | OW6: 2025 | OZ6: 1 | PC6: 1 | PI6: 1 | PK6: 1 | PM6: 40 | PN6: 4 | PO6: =PN6+PM6 -> 44 | PP6: 1 | PV6: 1 | PX6: 1 | PZ6: 1 | QB6: 1 | QD6: 1 | QI6: 1 | QK6: 1 | QM6: 1 | QO6: 1 | QR6: 1 | QU6: 1 | QZ6: 1 | RB6: 1 | RD6: 1 | RF6: 1 | RK6: 1 | RL6: 1 | RO6: 500 | RQ6: 500 | RS6: 30 | RU6: 50 | RW6: 3 | RY6: 3 | SB6: 1 | SN6: =SM6+SL6 -> 0 | SO6: 2 | SP6: 2 | SQ6: الحي الصناعي البناية الجديدة | SR6: ايثار جليل عامر | SS6: 7811328001
A8: خلاصة مركز النجف الصناعي | F8: =F7+F6 -> 0 | G8: =G7+G6 -> 0 | H8: =H7+H6 -> 1 | I8: =I7+I6 -> 1 | J8: =J7+J6 -> 0 | K8: =K7+K6 -> 1 | L8: =L7+L6 -> 0 | M8: =M7+M6 -> 0 | ... SP8: =SP7+SP6 -> 2
A9: خلاصة قضاء النجف الصناعي | F9: =F8 -> 0 | G9: =G8 -> 0 | H9: =H8 -> 1 | I9: =I8 -> 1 | J9: =J8 -> 0 | K9: =K8 -> 1 | L9: =L8 -> 0 | M9: =M8 -> 0 | ... EX9: =EX8 -> 0 | EY9: =EW9+EU9+ES9 -> 0 | EZ9: =EX9+EV9+ET9 -> 0 | FA9: =SUM(EY9:EZ9) -> 0 | FB9: =FB8 -> 0 | FC9: =FC8 -> 1 | FD9: =FD8 -> 3 | FE9: =FE8 -> 0 | FF9: =FF8 -> 10 | FG9: =FG8 -> 18 | FH9: =FH8 -> 0 | FI9: =FI8 -> 0 | ... GB9: =GB8 -> 0 | GE9: =GE8 -> 0 | GF9: =GF8 -> 0 | GG9: =GG8 -> 0 | GH9: =GH8 -> 0 | GI9: =GI8 -> 0 | GJ9: =GJ8 -> 1 | GK9: =GK8 -> 5 | GL9: =GL8 -> 0 | ... LP9: =LP8 -> 0 | LQ9: =LA9+LC9+KY9+LE9+LG9+LI9+LK9+LM9+LO9 -> 13 | LR9: =LB9+LD9+KZ9+LF9+LH9+LJ9+LL9+LN9+LP9 -> 19 | LS9: =LS8 -> 32 | LT9: =LT8 -> 9 | LU9: =LU8 -> 12 | LV9: =LV8 -> 0 | LW9: =LW8 -> 4 | LX9: =LX8 -> 4 | LY9: =LY8 -> 2 | LZ9: =LZ8 -> 0 | ... OV9: =OV8 -> 0 | OZ9: =OZ8 -> 1 | PA9: =PA8 -> 0 | PB9: =PB8 -> 0 | PC9: =PC8 -> 1 | PD9: =PD8 -> 0 | PE9: =PE8 -> 0 | PF9: =PF8 -> 0 | PG9: =PG8 -> 0 | ... RN9: =RN8 -> 0 | RU9: =RU8 -> 50 | RV9: =RV8 -> 0 | RW9: =RW8 -> 3 | RX9: =RX8 -> 0 | RY9: =RY8 -> 3 | RZ9: =RZ8 -> 0 | SA9: =SA8 -> 0 | SB9: =SB8 -> 1 | ... SP9: =SP8 -> 2
A11: خلاصة مركز الكوفة الصناعي | F11: =F10 -> 0 | G11: =G10 -> 0 | H11: =H10 -> 0 | I11: =I10 -> 0 | J11: =J10 -> 0 | K11: =K10 -> 0 | L11: =L10 -> 0 | M11: =M10 -> 0 | ... EX11: =EX10 -> 0 | EY11: =EW11+EU11+ES11 -> 0 | EZ11: =EX11+EV11+ET11 -> 0 | FA11: =SUM(EY11:EZ11) -> 0 | FB11: =FB10 -> 0 | FC11: =FC10 -> 0 | FD11: =FD10 -> 0 | FE11: =FE10 -> 0 | FF11: =FF10 -> 0 | FG11: =FG10 -> 0 | FH11: =FH10 -> 0 | FI11: =FI10 -> 0 | ... GB11: =GB10 -> 0 | GE11: =GE10 -> 0 | GF11: =GF10 -> 0 | GG11: =GG10 -> 0 | GH11: =GH10 -> 0 | GI11: =GI10 -> 0 | GJ11: =GJ10 -> 0 | GK11: =GK10 -> 0 | GL11: =GL10 -> 0 | ... LP11: =LP10 -> 0 | LQ11: =LA11+LC11+KY11+LE11+LG11+LI11+LK11+LM11+LO11 -> 0 | LR11: =LB11+LD11+KZ11+LF11+LH11+LJ11+LL11+LN11+LP11 -> 0 | LS11: =LS10 -> 0 | LT11: =LT10 -> 0 | LU11: =LU10 -> 0 | LV11: =LV10 -> 0 | LW11: =LW10 -> 0 | LX11: =LX10 -> 0 | LY11: =LY10 -> 0 | LZ11: =LZ10 -> 0 | ... OV11: =OV10 -> 0 | OZ11: =OZ10 -> 0 | PA11: =PA10 -> 0 | PB11: =PB10 -> 0 | PC11: =PC10 -> 0 | PD11: =PD10 -> 0 | PE11: =PE10 -> 0 | PF11: =PF10 -> 0 | PG11: =PG10 -> 0 | ... RN11: =RN10 -> 0 | RU11: =RU10 -> 0 | RV11: =RV10 -> 0 | RW11: =RW10 -> 0 | RX11: =RX10 -> 0 | RY11: =RY10 -> 0 | RZ11: =RZ10 -> 0 | SA11: =SA10 -> 0 | SB11: =SB10 -> 0 | ... SP11: =SP10 -> 0
A12: خلاصة قضاء الكوفة الصناعي | F12: =F11 -> 0 | G12: =G11 -> 0 | H12: =H11 -> 0 | I12: =I11 -> 0 | J12: =J11 -> 0 | K12: =K11 -> 0 | L12: =L11 -> 0 | M12: =M11 -> 0 | ... EX12: =EX11 -> 0 | EY12: =EW12+EU12+ES12 -> 0 | EZ12: =EX12+EV12+ET12 -> 0 | FA12: =SUM(EY12:EZ12) -> 0 | FB12: =FB11 -> 0 | FC12: =FC11 -> 0 | FD12: =FD11 -> 0 | FE12: =FE11 -> 0 | FF12: =FF11 -> 0 | FG12: =FG11 -> 0 | FH12: =FH11 -> 0 | FI12: =FI11 -> 0 | ... GB12: =GB11 -> 0 | GE12: =GE11 -> 0 | GF12: =GF11 -> 0 | GG12: =GG11 -> 0 | GH12: =GH11 -> 0 | GI12: =GI11 -> 0 | GJ12: =GJ11 -> 0 | GK12: =GK11 -> 0 | GL12: =GL11 -> 0 | ... LP12: =LP11 -> 0 | LQ12: =LA12+LC12+KY12+LE12+LG12+LI12+LK12+LM12+LO12 -> 0 | LR12: =LB12+LD12+KZ12+LF12+LH12+LJ12+LL12+LN12+LP12 -> 0 | LS12: =LS11 -> 0 | LT12: =LT11 -> 0 | LU12: =LU11 -> 0 | LV12: =LV11 -> 0 | LW12: =LW11 -> 0 | LX12: =LX11 -> 0 | LY12: =LY11 -> 0 | LZ12: =LZ11 -> 0 | ... OV12: =OV11 -> 0 | OZ12: =OZ11 -> 0 | PA12: =PA11 -> 0 | PB12: =PB11 -> 0 | PC12: =PC11 -> 0 | PD12: =PD11 -> 0 | PE12: =PE11 -> 0 | PF12: =PF11 -> 0 | PG12: =PG11 -> 0 | ... RN12: =RN11 -> 0 | RU12: =RU11 -> 0 | RV12: =RV11 -> 0 | RW12: =RW11 -> 0 | RX12: =RX11 -> 0 | RY12: =RY11 -> 0 | RZ12: =RZ11 -> 0 | SA12: =SA11 -> 0 | SB12: =SB11 -> 0 | ... SP12: =SP11 -> 0
A15: خلاصة مركز المناذرة الصناعي | F15: =F13 -> 0 | G15: =G13+G14 -> 0 | H15: =H13+H14 -> 0 | I15: =I13+I14 -> 0 | J15: =J13+J14 -> 0 | K15: =K13+K14 -> 0 | L15: =L13+L14 -> 0 | M15: =M13+M14 -> 0 | N15: =N13+N14 -> 0 | ... OV15: =OV13+OV14 -> 0 | OY15: =OY13+OY14 -> 0 | OZ15: =OZ13+OZ14 -> 0 | PA15: =PA13+PA14 -> 0 | PB15: =PB13+PB14 -> 0 | PC15: =PC13+PC14 -> 0 | PD15: =PD13+PD14 -> 0 | PE15: =PE13+PE14 -> 0 | PF15: =PF13+PF14 -> 0 | ... SP15: =SP13+SP14 -> 0
A16: خلاصة قضاء المناذرة الصناعي | F16: =F15 -> 0 | G16: =G15 -> 0 | H16: =H15 -> 0 | I16: =I15 -> 0 | J16: =J15 -> 0 | K16: =K15 -> 0 | L16: =L15 -> 0 | M16: =M15 -> 0 | ... GB16: =GB15 -> 0 | GE16: =GE15 -> 0 | GF16: =GF15 -> 0 | GG16: =GG15 -> 0 | GH16: =GH15 -> 0 | GI16: =GI15 -> 0 | GJ16: =GJ15 -> 0 | GK16: =GK15 -> 0 | GL16: =GL15 -> 0 | ... LP16: =LP15 -> 0 | LQ16: =LA16+LC16+KY16+LE16+LG16+LI16+LK16+LM16+LO16 -> 0 | LR16: =LB16+LD16+KZ16+LF16+LH16+LJ16+LL16+LN16+LP16 -> 0 | LS16: =LS15 -> 0 | LT16: =LT15 -> 0 | LU16: =LU15 -> 0 | LV16: =LV15 -> 0 | LW16: =LW15 -> 0 | LX16: =LX15 -> 0 | LY16: =LY15 -> 0 | LZ16: =LZ15 -> 0 | ... OV16: =OV15 -> 0 | OZ16: =OZ15 -> 0 | PA16: =PA15 -> 0 | PB16: =PB15 -> 0 | PC16: =PC15 -> 0 | PD16: =PD15 -> 0 | PE16: =PE15 -> 0 | PF16: =PF15 -> 0 | PG16: =PG15 -> 0 | ... RN16: =RN15 -> 0 | RU16: =RU15 -> 0 | RV16: =RV15 -> 0 | RW16: =RW15 -> 0 | RX16: =RX15 -> 0 | RY16: =RY15 -> 0 | RZ16: =RZ15 -> 0 | SA16: =SA15 -> 0 | SB16: =SB15 -> 0 | ... SP16: =SP15 -> 0
A17: خلاصة محافظة النجف الاشرف الصناعي | F17: =F16+F12+F9 -> 0 | G17: =G16+G12+G9 -> 0 | H17: =H16+H12+H9 -> 1 | I17: =I16+I12+I9 -> 1 | J17: =J16+J12+J9 -> 0 | K17: =K16+K12+K9 -> 1 | L17: =L16+L12+L9 -> 0 | M17: =M16+M12+M9 -> 0 | ... GB17: =GB16+GB12+GB9 -> 0 | GE17: =GE16+GE12+GE9 -> 0 | GF17: =GF16+GF12+GF9 -> 0 | GG17: =GG16+GG12+GG9 -> 0 | GH17: =GH16+GH12+GH9 -> 0 | GI17: =GI16+GI12+GI9 -> 0 | GJ17: =GJ16+GJ12+GJ9 -> 1 | GK17: =GK16+GK12+GK9 -> 5 | GL17: =GL16+GL12+GL9 -> 0 | ... LP17: =LP16+LP12+LP9 -> 0 | LQ17: =LA17+LC17+KY17+LE17+LG17+LI17+LK17+LM17+LO17 -> 13 | LR17: =LB17+LD17+KZ17+LF17+LH17+LJ17+LL17+LN17+LP17 -> 19 | LS17: =LS16+LS12+LS9 -> 32 | LT17: =LT16+LT12+LT9 -> 9 | LU17: =LU16+LU12+LU9 -> 12 | LV17: =LV16+LV12+LV9 -> 0 | LW17: =LW16+LW12+LW9 -> 4 | LX17: =LX16+LX12+LX9 -> 4 | LY17: =LY16+LY12+LY9 -> 2 | LZ17: =LZ16+LZ12+LZ9 -> 0 | ... OV17: =OV16+OV12+OV9 -> 0 | OZ17: =OZ16+OZ12+OZ9 -> 1 | PA17: =PA16+PA12+PA9 -> 0 | PB17: =PB16+PB12+PB9 -> 0 | PC17: =PC16+PC12+PC9 -> 1 | PD17: =PD16+PD12+PD9 -> 0 | PE17: =PE16+PE12+PE9 -> 0 | PF17: =PF16+PF12+PF9 -> 0 | PG17: =PG16+PG12+PG9 -> 0 | ... RN17: =RN16+RN12+RN9 -> 0 | RU17: =RU16+RU12+RU9 -> 50 | RV17: =RV16+RV12+RV9 -> 0 | RW17: =RW16+RW12+RW9 -> 3 | RX17: =RX16+RX12+RX9 -> 0 | RY17: =RY16+RY12+RY9 -> 3 | RZ17: =RZ16+RZ12+RZ9 -> 0 | SA17: =SA16+SA12+SA9 -> 0 | SB17: =SB16+SB12+SB9 -> 1 | ... SP17: =SP16+SP12+SP9 -> 2
A22: خلاصة مركز النجف التجاري | F22: =SUM(F18:F20) -> 0 | G22: =SUM(G18:G20) -> 0 | H22: =SUM(H18:H20) -> 0 | I22: =SUM(I18:I20) -> 0 | J22: =SUM(J18:J20) -> 0 | K22: =SUM(K18:K20) -> 0 | L22: =SUM(L18:L20) -> 0 | M22: =SUM(M18:M20) -> 0 | ... GB22: =SUM(GB18:GB20) -> 0 | GE22: =SUM(GE18:GE20) -> 0 | GF22: =SUM(GF18:GF20) -> 0 | GG22: =SUM(GG18:GG20) -> 0 | GH22: =SUM(GH18:GH20) -> 0 | GI22: =SUM(GI18:GI20) -> 0 | GJ22: =SUM(GJ18:GJ20) -> 0 | GK22: =SUM(GK18:GK20) -> 0 | GL22: =SUM(GL18:GL20) -> 0 | ... OV22: =SUM(OV18:OV20) -> 0 | OZ22: =SUM(OZ18:OZ20) -> 0 | PA22: =SUM(PA18:PA20) -> 0 | PB22: =SUM(PB18:PB20) -> 0 | PC22: =SUM(PC18:PC20) -> 0 | PD22: =SUM(PD18:PD20) -> 0 | PE22: =SUM(PE18:PE20) -> 0 | PF22: =SUM(PF18:PF20) -> 0 | PG22: =SUM(PG18:PG20) -> 0 | ... RN22: =SUM(RN18:RN20) -> 0 | RU22: =SUM(RU18:RU20) -> 0 | RV22: =SUM(RV18:RV20) -> 0 | RW22: =SUM(RW18:RW20) -> 0 | RX22: =SUM(RX18:RX20) -> 0 | RY22: =SUM(RY18:RY20) -> 0 | RZ22: =SUM(RZ18:RZ20) -> 0 | SA22: =SUM(SA18:SA20) -> 0 | SB22: =SUM(SB18:SB20) -> 0 | ... SP22: =SUM(SP18:SP20) -> 0
A23: خلاصة قضاء النجف التجاري | F23: =F22 -> 0 | G23: =G22 -> 0 | H23: =H22 -> 0 | I23: =I22 -> 0 | J23: =J22 -> 0 | K23: =K22 -> 0 | L23: =L22 -> 0 | M23: =M22 -> 0 | ... GB23: =GB22 -> 0 | GE23: =GE22 -> 0 | GF23: =GF22 -> 0 | GG23: =GG22 -> 0 | GH23: =GH22 -> 0 | GI23: =GI22 -> 0 | GJ23: =GJ22 -> 0 | GK23: =GK22 -> 0 | GL23: =GL22 -> 0 | ... OV23: =OV22 -> 0 | OZ23: =OZ22 -> 0 | PA23: =PA22 -> 0 | PB23: =PB22 -> 0 | PC23: =PC22 -> 0 | PD23: =PD22 -> 0 | PE23: =PE22 -> 0 | PF23: =PF22 -> 0 | PG23: =PG22 -> 0 | ... RN23: =RN22 -> 0 | RU23: =RU22 -> 0 | RV23: =RV22 -> 0 | RW23: =RW22 -> 0 | RX23: =RX22 -> 0 | RY23: =RY22 -> 0 | RZ23: =RZ22 -> 0 | SA23: =SA22 -> 0 | SB23: =SB22 -> 0 | ... SP23: =SP22 -> 0
A27: خلاصة مركز الكوفة الزراعي | F27: =F24+F26+F25 -> 0 | G27: =G24+G26+G25 -> 0 | H27: =H24+H26+H25 -> 0 | I27: =I24+I26+I25 -> 0 | J27: =J24+J26+J25 -> 0 | K27: =K24+K26+K25 -> 0 | L27: =L24+L26+L25 -> 0 | M27: =M24+M26+M25 -> 0 | ... SP27: =SP24+SP26+SP25 -> 0
A28: خلاصة قضاء الكوفة الزراعي | F28: =F27 -> 0 | G28: =G27 -> 0 | H28: =H27 -> 0 | I28: =I27 -> 0 | J28: =J27 -> 0 | K28: =K27 -> 0 | L28: =L27 -> 0 | M28: =M27 -> 0 | ... SP28: =SP27 -> 0
A31: خلاصة مركز النجف الفنون التطبيقية | F31: =F29+F30 -> 0 | G31: =G29+G30 -> 0 | H31: =H29+H30 -> 0 | I31: =I29+I30 -> 0 | J31: =J29+J30 -> 0 | K31: =K29+K30 -> 0 | L31: =L29+L30 -> 0 | M31: =M29+M30 -> 0 | ... GB31: =GB29+GB30 -> 0 | GE31: =GE29+GE30 -> 0 | GF31: =GF29+GF30 -> 0 | GG31: =GG29+GG30 -> 0 | GH31: =GH29+GH30 -> 0 | GI31: =GI29+GI30 -> 0 | GJ31: =GJ29+GJ30 -> 0 | GK31: =GK29+GK30 -> 0 | GL31: =GL29+GL30 -> 0 | ... PU31: =PU29+PU30 -> 0 | PV31: =PV29 -> 0 | PW31: =PW29 -> 0 | PX31: =PX29 -> 0 | PY31: =PY29 -> 0 | PZ31: =PZ29 -> 0 | QA31: =QA29 -> 0 | QB31: =QB29+QB30 -> 0 | QC31: =QC29+QC30 -> 0 | QD31: =QD29+QD30 -> 0 | QE31: =QE29+QE30 -> 0 | QF31: =QF29+QF30 -> 0 | QG31: =QG29+QG30 -> 0 | QH31: =QH29+QH30 -> 0 | QI31: =QI29+QI30 -> 0 | ... QT31: =QT29+QT30 -> 0 | RB31: =RB29+RB30 -> 0 | RC31: =RC29 -> 0 | RD31: =RD29 -> 0 | RE31: =RE29 -> 0 | RF31: =RF29 -> 0 | RG31: =RG29 -> 0 | RH31: =RH29 -> 0 | RI31: =RI29 -> 0 | RJ31: =RJ29 -> 0 | ... RN31: =RN29 -> 0 | RU31: =RU29 -> 0 | RW31: =RW29 -> 0 | RY31: =RY29 -> 0 | SA31: =SA29 -> 0 | SB31: =SB29 -> 0 | SC31: =SC29 -> 0 | SD31: =SD29 -> 0 | SE31: =SE29 -> 0 | SF31: =SF29 -> 0 | SG31: =SG29 -> 0 | SI31: =SI29 -> 0 | SJ31: =SJ29 -> 0 | SK31: =SK29 -> 0 | SL31: =SL29 -> 0 | SM31: =SM29 -> 0 | SN31: =SN29 -> 0 | SO31: =SO29 -> 0 | SP31: =SP29 -> 0
A32: خلاصة محافظة النجف الفنون التطبيقية | F32: =F31 -> 0 | G32: =G31 -> 0 | H32: =H31 -> 0 | I32: =I31 -> 0 | J32: =J31 -> 0 | K32: =K31 -> 0 | L32: =L31 -> 0 | M32: =M31 -> 0 | ... GB32: =GB31 -> 0 | GE32: =GE31 -> 0 | GF32: =GF31 -> 0 | GG32: =GG31 -> 0 | GH32: =GH31 -> 0 | GI32: =GI31 -> 0 | GJ32: =GJ31 -> 0 | GK32: =GK31 -> 0 | GL32: =GL31 -> 0 | ... OV32: =OV31 -> 0 | OZ32: =OZ31 -> 0 | PA32: =PA31 -> 0 | PB32: =PB31 -> 0 | PC32: =PC31 -> 0 | PD32: =PD31 -> 0 | PE32: =PE31 -> 0 | PF32: =PF31 -> 0 | PG32: =PG31 -> 0 | ... QN32: =QN31 -> 0 | RB32: =RB31 -> 0 | RC32: =RC31 -> 0 | RD32: =RD31 -> 0 | RE32: =RE31 -> 0 | RF32: =RF31 -> 0 | RG32: =RG31 -> 0 | RH32: =RH31 -> 0 | RI32: =RI31 -> 0 | ... RN32: =RN31 -> 0 | RU32: =RU31 -> 0 | RW32: =RW31 -> 0 | RY32: =RY31 -> 0 | SA32: =SA31 -> 0 | SB32: =SB31 -> 0 | SC32: =SC31 -> 0 | SD32: =SD31 -> 0 | SE32: =SE31 -> 0 | SF32: =SF31 -> 0 | SG32: =SG31 -> 0 | SI32: =SI31 -> 0 | SJ32: =SJ31 -> 0 | SK32: =SK31 -> 0 | SL32: =SL31 -> 0 | SM32: =SM31 -> 0 | SN32: =SN31 -> 0 | SO32: =SO31 -> 0 | SP32: =SP31 -> 0
E33: ع . ايليا المهنية الاهلية | V33: 100 | W33: 10 | X33: 100 | Y33: 15 | Z33: 100 | AA33: 7 | AB33: 100 | AC33: 8 | AD33: 38 | AF33: =AD33+AB33+Z33+X33+V33 -> 438 | AG33: =AE33+AC33+AA33+Y33+W33 -> 40 | AH33: =AG33+AF33 -> 478 | AI33: 100 | AJ33: 10 | AK33: 100 | AL33: 15 | AM33: 100 | AN33: 7 | AO33: 100 | AP33: 8 | AQ33: 38 | AS33: =AQ33+AO33+AM33+AK33+AI33 -> 438 | AT33: =AR33+AP33+AN33+AL33+AJ33 -> 40 | AU33: =AT33+AS33 -> 478 | AV33: 9 | AX33: 3 | BF33: =BD33+BB33+AZ33+AX33+AV33 -> 12 | BG33: =BE33+BC33+BA33+AY33+AW33 -> 0 | BH33: =BG33+BF33 -> 12 | BI33: 10 | BK33: 10 | BS33: =BQ33+BO33+BM33+BK33+BI33 -> 20 | BT33: =BR33+BP33+BN33+BL33+BJ33 -> 0 | BU33: =BT33+BS33 -> 20 | BV33: =AI33 -> 100 | BW33: =AJ33 -> 10 | BX33: =AV33+AK33 -> 109 | BY33: =AL33+AW33 -> 15 | BZ33: =BI33+AX33+AM33 -> 113 | CA33: =AN33+AY33+BJ33 -> 7 | CB33: =BK33+AZ33+AO33 -> 110 | CC33: =AP33+BA33+BL33 -> 8 | CD33: =BM33+BB33+AQ33 -> 38 | CE33: =BN33+BC33+AR33 -> 0 | CF33: =BO33+BD33 -> 0 | CG33: =BP33+BE33 -> 0 | CH33: =BQ33 -> 0 | CI33: =BR33 -> 0 | CJ33: =CH33+CF33+CD33+CB33+BZ33+BX33+BV33 -> 470 | CK33: =CI33+CG33+CE33+CC33+CA33+BY33+BW33 -> 40 | CL33: =CK33+CJ33 -> 510 | CM33: 16 | CN33: 2 | CP33: 2 | CS33: 2 | CV33: =CS33+CP33+CM33 -> 20 | CW33: =CT33+CQ33+CN33 -> 2 | CX33: =CU33+CR33+CO33 -> 0 | CY33: =CX33+CW33+CV33 -> 22 | DF33: =DD33+DB33+CZ33 -> 0 | DG33: =DE33+DC33+DA33 -> 0 | DH33: =DG33+DF33 -> 0 | DO33: =DM33+DK33+DI33 -> 0 | DP33: =DN33+DL33+DJ33 -> 0 | DQ33: =DP33+DO33 -> 0 | DX33: =DV33+DT33+DR33 -> 0 | DY33: =DW33+DU33+DS33 -> 0 | DZ33: =DY33+DX33 -> 0 | EG33: =EE33+EC33+EA33 -> 0 | EH33: =EF33+ED33+EB33 -> 0 | EI33: =EH33+EG33 -> 0 | EP33: =EN33+EL33+EJ33 -> 0 | EQ33: =EO33+EM33+EK33 -> 0 | ER33: =EQ33+EP33 -> 0 | EY33: =EW33+EU33+ES33 -> 0 | EZ33: =EX33+EV33+ET33 -> 0 | FA33: =EZ33+EY33 -> 0 | FL33: =FJ33+FH33+FF33+FD33+FB33 -> 0 | FM33: =FK33+FI33+FG33+FE33+FC33 -> 0 | FN33: =FM33+FL33 -> 0 | GG33: =GE33+GA33+FY33+FW33+FU33+FS33+FO33 -> 0 | GH33: =GF33+GB33+FZ33+FX33+FV33+FT33+FP33 -> 0 | GI33: =GH33+GG33 -> 0 | KV33: =KT33+KN33+KJ33+KH33+KF33+KD33+KB33+JZ33+JX33+JV33+JT33+JR33+JP33+JN33+JL33+JJ33+JH33+JF33+JD33+JB33+IZ33+IX33+IV33+IT33+IR33+IP33+IN33+IL33+IJ33+IH33+IF33+ID33+IB33+HZ33+HX33+HV33+HT33+HR33+HP33+HN33+HL33+HJ33+HH33+HF33+HD33+HB33+GZ33+GX33+GV33+GT33+GR33+GP33+GN33+GL33+GJ33 -> 0 | KW33: =KU33+KO33+KK33+KI33+KG33+KE33+KC33+KA33+JY33+JW33+JU33+JS33+JQ33+JO33+JM33+JK33+JI33+JG33+JE33+JC33+JA33+IY33+IW33+IU33+IS33+IQ33+IO33+IM33+IK33+II33+IG33+IE33+IC33+IA33+HY33+HW33+HU33+HS33+HQ33+HO33+HM33+HK33+HI33+HG33+HE33+HC33+HA33+GY33+GW33+GU33+GS33+GQ33+GO33+GM33+GK33 -> 0 | KX33: =KW33+KV33 -> 0 | LQ33: =LA33+LC33+KY33+LE33+LG33+LI33+LK33+LM33+LO33 -> 0 | LR33: =LB33+LD33+KZ33+LF33+LH33+LJ33+LL33+LN33+LP33 -> 0 | LS33: =LR33+LQ33 -> 0 | MB33: =LX33+LV33+LT33+LZ33 -> 0 | MC33: =LY33+LW33+LU33+MA33 -> 0 | MD33: =MC33+MB33 -> 0 | MO33: =MM33+MK33+MI33+MG33+ME33 -> 0 | MP33: =MN33+ML33+MJ33+MH33+MF33 -> 0 | MQ33: =MP33+MO33 -> 0 | MZ33: =MX33+MV33+MT33+MR33 -> 0 | NA33: =MY33+MW33+MU33+MS33 -> 0 | NB33: =NA33+MZ33 -> 0 | NW33: =NU33+NS33+NQ33+NO33+NM33+NK33+NG33+NI33+NE33 -> 0 | NX33: =NV33+NT33+NR33+NP33+NN33+NL33+NH33+NJ33+NF33 -> 0 | NY33: =NX33+NW33 -> 0 | PO33: =SUM(PM33:PN33) -> 0
A35: خلاصة الفرع الحاسوب وتقنية المعلومات محافظة النجف | F35: =SUM(F33:F34) -> 0 | G35: =SUM(G33:G34) -> 0 | H35: =SUM(H33:H34) -> 0 | I35: =SUM(I33:I34) -> 0 | J35: =SUM(J33:J34) -> 0 | K35: =SUM(K33:K34) -> 0 | L35: =SUM(L33:L34) -> 0 | M35: =SUM(M33:M34) -> 0 | ... GB35: =SUM(GB33:GB34) -> 0 | GE35: =SUM(GE33:GE34) -> 0 | GF35: =SUM(GF33:GF34) -> 0 | GG35: =SUM(GG33:GG34) -> 0 | GH35: =SUM(GH33:GH34) -> 0 | GI35: =SUM(GI33:GI34) -> 0 | GJ35: =SUM(GJ33:GJ34) -> 0 | GK35: =SUM(GK33:GK34) -> 0 | GL35: =SUM(GL33:GL34) -> 0 | ... OV35: =SUM(OV33:OV34) -> 0 | OZ35: =SUM(OZ33:OZ34) -> 0 | PA35: =SUM(PA33:PA34) -> 0 | PB35: =SUM(PB33:PB34) -> 0 | PC35: =SUM(PC33:PC34) -> 0 | PD35: =SUM(PD33:PD34) -> 0 | PE35: =SUM(PE33:PE34) -> 0 | PF35: =SUM(PF33:PF34) -> 0 | PG35: =SUM(PG33:PG34) -> 0 | ... RN35: =SUM(RN33:RN34) -> 0 | RU35: =SUM(RU33:RU34) -> 0 | RV35: =SUM(RV33:RV34) -> 0 | RW35: =SUM(RW33:RW34) -> 0 | RX35: =SUM(RX33:RX34) -> 0 | RY35: =SUM(RY33:RY34) -> 0 | RZ35: =SUM(RZ33:RZ34) -> 0 | SA35: =SUM(SA33:SA34) -> 0 | SB35: =SUM(SB33:SB34) -> 0 | ... SP35: =SUM(SP33:SP34) -> 0
A36: خلاصة الحاسوب وتقنية المعلومات لقضاء النجف | F36: =SUM(F33:F34) -> 0 | G36: =SUM(G33:G34) -> 0 | H36: =SUM(H33:H34) -> 0 | I36: =SUM(I33:I34) -> 0 | J36: =SUM(J33:J34) -> 0 | K36: =SUM(K33:K34) -> 0 | L36: =SUM(L33:L34) -> 0 | M36: =SUM(M33:M34) -> 0 | ... GB36: =SUM(GB33:GB34) -> 0 | GE36: =SUM(GE33:GE34) -> 0 | GF36: =SUM(GF33:GF34) -> 0 | GG36: =SUM(GG33:GG34) -> 0 | GH36: =SUM(GH33:GH34) -> 0 | GI36: =SUM(GI33:GI34) -> 0 | GJ36: =SUM(GJ33:GJ34) -> 0 | GK36: =SUM(GK33:GK34) -> 0 | GL36: =SUM(GL33:GL34) -> 0 | ... OV36: =SUM(OV33:OV34) -> 0 | OZ36: =SUM(OZ33:OZ34) -> 0 | PA36: =SUM(PA33:PA34) -> 0 | PB36: =SUM(PB33:PB34) -> 0 | PC36: =SUM(PC33:PC34) -> 0 | PD36: =SUM(PD33:PD34) -> 0 | PE36: =SUM(PE33:PE34) -> 0 | PF36: =SUM(PF33:PF34) -> 0 | PG36: =SUM(PG33:PG34) -> 0 | ... RN36: =SUM(RN33:RN34) -> 0 | RU36: =SUM(RU33:RU34) -> 0 | RV36: =SUM(RV33:RV34) -> 0 | RW36: =SUM(RW33:RW34) -> 0 | RX36: =SUM(RX33:RX34) -> 0 | RY36: =SUM(RY33:RY34) -> 0 | RZ36: =SUM(RZ33:RZ34) -> 0 | SA36: =SUM(SA33:SA34) -> 0 | SB36: =SUM(SB33:SB34) -> 0 | ... SP36: =SUM(SP33:SP34) -> 0
A38: خلاصة فرع السياحة والفندقة | F38: =SUM(F37) -> 0 | G38: =SUM(G37) -> 0 | H38: =SUM(H37) -> 0 | I38: =SUM(I37) -> 0 | J38: =SUM(J37) -> 0 | K38: =SUM(K37) -> 0 | L38: =SUM(L37) -> 0 | M38: =SUM(M37) -> 0 | ... GB38: =SUM(GB37) -> 0 | GE38: =SUM(GE37) -> 0 | GF38: =SUM(GF37) -> 0 | GG38: =SUM(GG37) -> 0 | GH38: =SUM(GH37) -> 0 | GI38: =SUM(GI37) -> 0 | GJ38: =SUM(GJ37) -> 0 | GK38: =SUM(GK37) -> 0 | GL38: =SUM(GL37) -> 0 | ... LN38: =SUM(LN37) -> 0 | LQ38: =SUM(LQ37) -> 0 | LR38: =SUM(LR37) -> 0 | LS38: =SUM(LS37) -> 0 | LT38: =SUM(LT37) -> 0 | LU38: =SUM(LU37) -> 0 | LV38: =SUM(LV37) -> 0 | LW38: =SUM(LW37) -> 0 | LX38: =SUM(LX37) -> 0 | ... OV38: =SUM(OV37) -> 0 | OZ38: =SUM(OZ37) -> 0 | PA38: =SUM(PA37) -> 0 | PB38: =SUM(PB37) -> 0 | PC38: =SUM(PC37) -> 0 | PD38: =SUM(PD37) -> 0 | PE38: =SUM(PE37) -> 0 | PF38: =SUM(PF37) -> 0 | PG38: =SUM(PG37) -> 0 | ... RN38: =SUM(RN37) -> 0 | RU38: =SUM(RU37) -> 0 | RV38: =SUM(RV37) -> 0 | RW38: =SUM(RW37) -> 0 | RX38: =SUM(RX37) -> 0 | RY38: =SUM(RY37) -> 0 | RZ38: =SUM(RZ37) -> 0 | SA38: =SUM(SA37) -> 0 | SB38: =SUM(SB37) -> 0 | ... SP38: =SUM(SP37) -> 0
A40: حلاصة العلوم الرياضية | F40: =SUM(F39) -> 0 | G40: =SUM(G39) -> 0 | H40: =SUM(H39) -> 0 | I40: =SUM(I39) -> 0 | J40: =SUM(J39) -> 0 | K40: =SUM(K39) -> 0 | L40: =SUM(L39) -> 0 | M40: =SUM(M39) -> 0 | ... SP40: =SUM(SP39) -> 0
A41: خلاصة التعليـــم المهـــني الاهـــــلي لمحافظة النجف الاشرف | F41: =F32+F28+F23+F17+F35+F38+F40 -> 0 | G41: =G32+G28+G23+G17+G35+G38+G40 -> 0 | H41: =H32+H28+H23+H17+H35+H38+H40 -> 1 | I41: =I32+I28+I23+I17+I35+I38+I40 -> 1 | J41: =J32+J28+J23+J17+J35+J38+J40 -> 0 | K41: =K32+K28+K23+K17+K35+K38+K40 -> 1 | L41: =L32+L28+L23+L17+L35+L38+L40 -> 0 | M41: =M32+M28+M23+M17+M35+M38+M40 -> 0 | ... SP41: =SP32+SP28+SP23+SP17+SP35+SP38+SP40 -> 2
A43: قضاء النجف | F43: =SUM(F33:F34)+F31+F23+F9+F38+F26+F40 -> 0 | G43: =SUM(G33:G34)+G31+G23+G9+G38+G26+G40 -> 0 | H43: =SUM(H33:H34)+H31+H23+H9+H38+H26+H40 -> 1 | I43: =SUM(I33:I34)+I31+I23+I9+I38+I26+I40 -> 1 | J43: =SUM(J33:J34)+J31+J23+J9+J38+J26+J40 -> 0 | K43: =SUM(K33:K34)+K31+K23+K9+K38+K26+K40 -> 1 | L43: =SUM(L33:L34)+L31+L23+L9+L38+L26+L40 -> 0 | M43: =SUM(M33:M34)+M31+M23+M9+M38+M26+M40 -> 0 | ... OV43: =SUM(OV33:OV34)+OV31+OV23+OV9+OV38+OV26+OV40 -> 0 | OY43: =SUM(OY33:OY34)+OY31+OY23+OY9+OY38+OY26+OY40 -> 0 | OZ43: =SUM(OZ33:OZ34)+OZ31+OZ23+OZ9+OZ38+OZ26+OZ40 -> 1 | PA43: =SUM(PA33:PA34)+PA31+PA23+PA9+PA38+PA26+PA40 -> 0 | PB43: =SUM(PB33:PB34)+PB31+PB23+PB9+PB38+PB26+PB40 -> 0 | PC43: =SUM(PC33:PC34)+PC31+PC23+PC9+PC38+PC26+PC40 -> 1 | PD43: =SUM(PD33:PD34)+PD31+PD23+PD9+PD38+PD26+PD40 -> 0 | PE43: =SUM(PE33:PE34)+PE31+PE23+PE9+PE38+PE26+PE40 -> 0 | PF43: =SUM(PF33:PF34)+PF31+PF23+PF9+PF38+PF26+PF40 -> 0 | ... SP43: =SUM(SP33:SP34)+SP31+SP23+SP9+SP38+SP26+SP40 -> 2
A44: قضاء الكوفة | F44: =F24+F12 -> 0 | G44: =G24+G12 -> 0 | H44: =H24+H12 -> 0 | I44: =I24+I12 -> 0 | J44: =J24+J12 -> 0 | K44: =K24+K12 -> 0 | L44: =L24+L12 -> 0 | M44: =M24+M12 -> 0 | ... SP44: =SP24+SP12 -> 0
A45: قضاء المناذرة | F45: =F15+F25 -> 0 | G45: =G15+G25 -> 0 | H45: =H15+H25 -> 0 | I45: =I15+I25 -> 0 | J45: =J15+J25 -> 0 | K45: =K15+K25 -> 0 | L45: =L15+L25 -> 0 | M45: =M15+M25 -> 0 | ... SP45: =SP15+SP25 -> 0

Sheet ج 1,2
A1: المديرية العامة للتربية في محافظة النجف الاشرف | S1: التعليم المهني
A2: قسم التخطيط التربوي | I2: خلاصة محافظة النجف الاشرف
A3: جدول رقم ( 1 )
A4: التعليـــم المهـــني الاهـــــلي للعام الدراسي 2025 / 2026
A5: عدد المدارس والطلبة الموجودين والمستجدين وأعضاء الهيئة التدريسية واستقلالية المدرسة ونوع الازدواج ( الصباحي والمسائي )
A7: الفرع | B7: عدد المدارس | F7: عدد الطلبة المقبولين الجدد | I7: عدد الطلبة الموجودين | L7: عدد أعضاء الهيئة التدريسية | O7: استقلالية المدرسة | Q7: عدد المدارس حسب البيئة | S7: عدد مدارس الفتح الجديد
B8: بنون | C8: بنات | D8: مختلطة | E8: المجموع | F8: بنون | G8: بنات | H8: المجموع | I8: بنون | J8: بنات | K8: المجموع | L8: بنون | M8: بنات | N8: المجموع | O8: أصلية | P8: ضيف | Q8: حضر | R8: ريف
A9: الصناعي | B9: =المهني!F17 -> 0 | C9: =المهني!G17 -> 0 | D9: =المهني!H17 -> 1 | E9: =D9+C9+B9 -> 1 | F9: =المهني!AF17 -> 200 | G9: =المهني!AG17 -> 60 | H9: =G9+F9 -> 260 | I9: =المهني!CJ17 -> 200 | J9: =المهني!CK17 -> 60 | K9: =J9+I9 -> 260 | L9: =المهني!FL17 -> 13 | M9: =المهني!FM17 -> 19 | N9: =M9+L9 -> 32 | O9: =المهني!O17 -> 1 | P9: =المهني!P17 -> 0 | Q9: =المهني!I17 -> 1 | R9: =المهني!J17 -> 0 | S9: =المهني!U17 -> 1
A10: الزراعي | B10: 0 | C10: 0 | D10: 0 | E10: =D10+C10+B10 -> 0 | F10: =المهني!AF28 -> 0 | G10: =المهني!AG28 -> 0 | H10: =G10+F10 -> 0 | I10: =المهني!CJ28 -> 0 | J10: =المهني!CK28 -> 0 | K10: =J10+I10 -> 0 | L10: =المهني!FL28 -> 0 | M10: =المهني!FM28 -> 0 | N10: =M10+L10 -> 0 | O10: 0 | P10: 0 | Q10: 0 | R10: 0 | S10: 0
A11: التجاري | B11: =المهني!F23 -> 0 | C11: =المهني!G23 -> 0 | D11: =المهني!H23 -> 0 | E11: =D11+C11+B11 -> 0 | F11: =المهني!AF23 -> 0 | G11: =المهني!AG23 -> 0 | H11: =G11+F11 -> 0 | I11: =المهني!CJ23 -> 0 | J11: =المهني!CK23 -> 0 | K11: =J11+I11 -> 0 | L11: =المهني!FL23 -> 0 | M11: =المهني!FM23 -> 0 | N11: =M11+L11 -> 0 | O11: =المهني!O23 -> 0 | P11: =المهني!P23 -> 0 | Q11: =المهني!I23 -> 0 | R11: 0 | S11: =المهني!U23 -> 0
A12: فنون تطبيقية | B12: 0 | C12: 0 | D12: 0 | E12: =D12+C12+B12 -> 0 | F12: =المهني!AF32 -> 0 | G12: =المهني!AG32 -> 0 | H12: =G12+F12 -> 0 | I12: 0 | J12: =المهني!CK32 -> 0 | K12: =J12+I12 -> 0 | L12: 0 | M12: =المهني!FM32 -> 0 | N12: =M12+L12 -> 0 | O12: 0 | P12: 0 | Q12: 0 | R12: 0 | S12: 0
A13: سياحة | B13: =المهني!F38 -> 0 | C13: =المهني!G38 -> 0 | D13: =المهني!H38 -> 0 | E13: =D13+C13+B13 -> 0 | F13: =المهني!AF37 -> 0 | G13: =المهني!AG37 -> 0 | H13: =G13+F13 -> 0 | I13: =المهني!CJ37 -> 0 | J13: =المهني!CK37 -> 0 | K13: =J13+I13 -> 0 | L13: =المهني!FL38 -> 0 | M13: =المهني!FM38 -> 0 | N13: =M13+L13 -> 0 | O13: =المهني!O38 -> 0 | P13: =المهني!P38 -> 0 | Q13: =المهني!I38 -> 0 | R13: =المهني!J38 -> 0 | S13: =المهني!U40 -> 0
A14: العلوم الرياضية | B14: =المهني!F40 -> 0 | C14: =المهني!G40 -> 0 | D14: =المهني!H40 -> 0 | E14: =D14+C14+B14 -> 0 | F14: =المهني!AF40 -> 0 | G14: =المهني!AG40 -> 0 | H14: =G14+F14 -> 0 | I14: =المهني!CJ40 -> 0 | J14: =المهني!CK40 -> 0 | K14: =J14+I14 -> 0 | L14: =المهني!FL40 -> 0 | M14: =المهني!FM40 -> 0 | N14: =M14+L14 -> 0 | O14: =المهني!O40 -> 0 | P14: =المهني!P40 -> 0 | Q14: =المهني!I40 -> 0 | R14: =المهني!J40 -> 0 | S14: =المهني!U40 -> 0
A15: الحاسوب وتقنية المعلومات | B15: =المهني!F36 -> 0 | C15: =المهني!G36 -> 0 | D15: =المهني!H36 -> 0 | E15: =D15+C15+B15 -> 0 | F15: =المهني!AF35 -> 438 | G15: =المهني!AG35 -> 40 | H15: =G15+F15 -> 478 | I15: =المهني!CJ35 -> 470 | J15: =المهني!CK35 -> 40 | K15: =J15+I15 -> 510 | L15: =المهني!FL35 -> 0 | M15: =المهني!FM35 -> 0 | N15: =M15+L15 -> 0 | O15: =المهني!O35 -> 0 | P15: 0 | Q15: =المهني!I35 -> 0 | R15: 0 | S15: =المهني!U35 -> 0
A16: المجموع | B16: =B12+B11+B10+B9+B15+B13+B14 -> 0 | C16: =C12+C11+C10+C9+C15+C13+C14 -> 0 | D16: =D12+D11+D10+D9+D15+D13+D14 -> 1 | E16: =E12+E11+E10+E9+E15+E13+E14 -> 1 | F16: =F12+F11+F10+F9+F15+F13+F14 -> 638 | G16: =G12+G11+G10+G9+G15+G13+G14 -> 100 | H16: =H12+H11+H10+H9+H15+H13+H14 -> 738 | I16: =I12+I11+I10+I9+I15+I13+I14 -> 670 | ... R16: =R12+R11+R10+R9+R15+R13+R14 -> 0 | S16: =SUM(S9:T15) -> 1
D18: جدول رقم ( 2 )
D19: التعليـــم المهـــني الاهـــــلي للعام الدراسي 2025 / 2026
D20: عدد الطلبة المقبولين الجدد حسب العمر والجنس ( الصباحي والمسائي)
C22: الفرع | E22: عمر 15 سنة | G22: عمر 16 سنة | I22: عمر 17 سنة | K22: عمر 18 سنة | M22: عمر 19 سنة | O22: المجمـــــــــــــوع
E23: بنون | F23: بنات | G23: بنون | H23: بنات | I23: بنون | J23: بنات | K23: بنون | L23: بنات | M23: بنون | N23: بنات | O23: بنون | P23: بنات | Q23: المجموع
C24: الصناعي | E24: =المهني!V17 -> 67 | F24: =المهني!W17 -> 13 | G24: =المهني!X17 -> 59 | H24: =المهني!Y17 -> 20 | I24: =المهني!Z17 -> 45 | J24: =المهني!AA17 -> 20 | K24: =المهني!AB17 -> 29 | L24: =المهني!AC17 -> 7 | ... N24: =المهني!AE17 -> 0 | O24: =M24+K24+I24+G24+E24 -> 200 | P24: =N24+L24+J24+H24+F24 -> 60 | Q24: =P24+O24 -> 260
C25: الزراعي | E25: =المهني!V28 -> 0 | F25: =المهني!W28 -> 0 | G25: =المهني!X28 -> 0 | H25: =المهني!Y28 -> 0 | I25: =المهني!Z28 -> 0 | J25: =المهني!AA28 -> 0 | K25: =المهني!AB28 -> 0 | L25: =المهني!AC28 -> 0 | ... N25: =المهني!AE28 -> 0 | O25: =M25+K25+I25+G25+E25 -> 0 | P25: =N25+L25+J25+H25+F25 -> 0 | Q25: =P25+O25 -> 0
C26: التجاري | E26: =المهني!V23 -> 0 | F26: =المهني!W23 -> 0 | G26: =المهني!X23 -> 0 | H26: =المهني!Y23 -> 0 | I26: =المهني!Z23 -> 0 | J26: =المهني!AA23 -> 0 | K26: =المهني!AB23 -> 0 | L26: =المهني!AC23 -> 0 | ... N26: =المهني!AE23 -> 0 | O26: =M26+K26+I26+G26+E26 -> 0 | P26: =N26+L26+J26+H26+F26 -> 0 | Q26: =P26+O26 -> 0
C27: فنون تطبيقية | E27: =المهني!V32 -> 0 | F27: =المهني!W32 -> 0 | G27: 0 | H27: =المهني!Y32 -> 0 | I27: 0 | J27: =المهني!AA32 -> 0 | K27: 0 | L27: =المهني!AC32 -> 0 | M27: 0 | N27: =المهني!AE32 -> 0 | O27: =M27+K27+I27+G27+E27 -> 0 | P27: =N27+L27+J27+H27+F27 -> 0 | Q27: =P27+O27 -> 0
C28: سياحة | E28: =المهني!V38 -> 0 | F28: =المهني!W38 -> 0 | G28: =المهني!X38 -> 0 | H28: =المهني!Y38 -> 0 | I28: =المهني!Z38 -> 0 | J28: =المهني!AA38 -> 0 | K28: =المهني!AB38 -> 0 | L28: =المهني!AC38 -> 0 | ... N28: =المهني!AE38 -> 0 | O28: =M28+K28+I28+G28+E28 -> 0 | P28: =N28+L28+J28+H28+F28 -> 0 | Q28: =P28+O28 -> 0
C29: العلوم الرياضية | E29: =المهني!V40 -> 0 | F29: =المهني!W40 -> 0 | G29: =المهني!X40 -> 0 | H29: =المهني!Y40 -> 0 | I29: =المهني!Z40 -> 0 | J29: =المهني!AA40 -> 0 | K29: =المهني!AB40 -> 0 | L29: =المهني!AC40 -> 0 | ... N29: =المهني!AE40 -> 0 | O29: =M29+K29+I29+G29+E29 -> 0 | P29: =N29+L29+J29+H29+F29 -> 0 | Q29: =P29+O29 -> 0
C30: الحاسوب وتقنية المعلومات | E30: =المهني!V35 -> 100 | F30: =المهني!W35 -> 10 | G30: =المهني!X35 -> 100 | H30: =المهني!Y35 -> 15 | I30: =المهني!Z35 -> 100 | J30: =المهني!AA35 -> 7 | K30: =المهني!AB35 -> 100 | L30: =المهني!AC35 -> 8 | ... N30: =المهني!AE35 -> 0 | O30: =M30+K30+I30+G30+E30 -> 438 | P30: =N30+L30+J30+H30+F30 -> 40 | Q30: =P30+O30 -> 478
C31: المجموع | E31: =E27+E26+E25+E24+E30+E28+E29 -> 167 | F31: =F27+F26+F25+F24+F30+F28+F29 -> 23 | G31: =G27+G26+G25+G24+G30+G28+G29 -> 159 | H31: =H27+H26+H25+H24+H30+H28+H29 -> 35 | I31: =I27+I26+I25+I24+I30+I28+I29 -> 145 | J31: =J27+J26+J25+J24+J30+J28+J29 -> 27 | K31: =K27+K26+K25+K24+K30+K28+K29 -> 129 | L31: =L27+L26+L25+L24+L30+L28+L29 -> 15 | ... Q31: =Q27+Q26+Q25+Q24+Q30+Q28+Q29 -> 738
A33: المديرية العامة للتربية في محافظة النجف الاشرف | S33: التعليم المهني
A34: قسم التخطيط التربوي | I34: خلاصة قضاء النجف ومركزها
A35: جدول رقم ( 1 )
A36: التعليـــم المهـــني الاهـــــلي للعام الدراسي 2025 / 2026
A37: عدد المدارس والطلبة الموجودين والمستجدين وأعضاء الهيئة التدريسية واستقلالية المدرسة ونوع الازدواج ( الصباحي والمسائي )
A39: الفرع | B39: عدد المدارس | F39: عدد الطلبة المقبولين الجدد | I39: عدد الطلبة الموجودين | L39: عدد أعضاء الهيئة التدريسية | O39: استقلالية المدرسة | Q39: عدد المدارس حسب البيئة | S39: عدد مدارس الفتح الجديد
B40: بنون | C40: بنات | D40: مختلطة | E40: المجموع | F40: بنون | G40: بنات | H40: المجموع | I40: بنون | J40: بنات | K40: المجموع | L40: بنون | M40: بنات | N40: المجموع | O40: أصلية | P40: ضيف | Q40: حضر | R40: ريف
A41: الصناعي | B41: =المهني!F9 -> 0 | C41: =المهني!G9 -> 0 | D41: =المهني!H9 -> 1 | E41: =D41+C41+B41 -> 1 | F41: =المهني!AF9 -> 200 | G41: =المهني!AG9 -> 60 | H41: =G41+F41 -> 260 | I41: =المهني!CJ9 -> 200 | J41: =المهني!CK9 -> 60 | K41: =J41+I41 -> 260 | L41: =المهني!FL9 -> 13 | M41: =المهني!FM9 -> 19 | N41: =M41+L41 -> 32 | O41: =المهني!O9 -> 1 | P41: =المهني!P9 -> 0 | Q41: =المهني!I9 -> 1 | R41: =المهني!J9 -> 0 | S41: =المهني!U9 -> 1
A42: الزراعي | B42: 0 | C42: 0 | D42: 0 | E42: =D42+C42+B42 -> 0 | F42: 0 | G42: 0 | H42: =G42+F42 -> 0 | I42: 0 | J42: 0 | K42: =J42+I42 -> 0 | L42: 0 | M42: 0 | N42: =M42+L42 -> 0 | O42: 0 | P42: 0 | Q42: 0 | R42: 0 | S42: 0
A43: التجاري | B43: =المهني!F23 -> 0 | C43: =المهني!G23 -> 0 | D43: =المهني!H23 -> 0 | E43: =D43+C43+B43 -> 0 | F43: =المهني!AF23 -> 0 | G43: =المهني!AG23 -> 0 | H43: =G43+F43 -> 0 | I43: =المهني!CJ23 -> 0 | J43: =المهني!CK23 -> 0 | K43: =J43+I43 -> 0 | L43: =المهني!FL23 -> 0 | M43: =المهني!FM23 -> 0 | N43: =M43+L43 -> 0 | O43: 0 | P43: 0 | Q43: 0 | R43: 0 | S43: 0
A44: فنون تطبيقية | B44: 0 | C44: 0 | D44: 0 | E44: =D44+C44+B44 -> 0 | F44: =المهني!AF32 -> 0 | G44: =المهني!AG32 -> 0 | H44: =G44+F44 -> 0 | I44: 0 | J44: =المهني!CK31 -> 0 | K44: =J44+I44 -> 0 | L44: 0 | M44: =المهني!FM31 -> 0 | N44: =M44+L44 -> 0 | O44: 0 | P44: 0 | Q44: 0 | R44: 0 | S44: 0
A45: سياحة | F45: =المهني!AF38 -> 0 | G45: =المهني!AG38 -> 0 | H45: =G45+F45 -> 0 | I45: =المهني!CJ38 -> 0 | J45: =المهني!CK38 -> 0 | K45: =J45+I45 -> 0 | L45: =المهني!FL38 -> 0 | M45: =المهني!FM38 -> 0 | N45: =M45+L45 -> 0
...

Sheet ج3
A1: المديرية العامة للتربية في محافظة النجف الاشرف | S1: التعليم المهني
B2: قسم التخطيط التربوي | J2: خلاصة محافظة النجف الاشرف
A3: جدول رقم ( 3 )
A4: التعليـــم المهـــني الاهـــــلي للعام الدراسي 2025 / 2026
A5: عدد المدارس والمدرسين والطلبة والشعب (( المدارس المسائية فقط ))
A7: الفرع | B7: عدد المدارس | F7: عدد المدرسين | I7: عدد الطلبة الموجودين | R7: الشعب
I8: الصف الاول | K8: الصف الثاني | M8: الصف الثالث | O8: المجموع الكلي
B9: بنون | C9: بنات | D9: مختلطة | E9: المجموع | F9: ذكور | G9: اناث | H9: المجموع | I9: بنون | J9: بنات | K9: بنون | L9: بنات | M9: بنون | N9: بنات | O9: بنون | P9: بنات | Q9: المجموع | R9: بنون | S9: بنات | T9: مختلط | U9: المجموع
A10: الصناعي | B10: 0 | C10: =المهني!#REF! -> #REF! | D10: =المهني!#REF! -> #REF! | E10: =D10+C10+B10 -> #REF! | F10: =المهني!#REF! -> #REF! | G10: =المهني!#REF! -> #REF! | H10: =G10+F10 -> #REF! | I10: =المهني!#REF! -> #REF! | J10: =المهني!#REF! -> #REF! | K10: =المهني!#REF! -> #REF! | L10: =المهني!#REF! -> #REF! | M10: =المهني!#REF! -> #REF! | N10: =المهني!#REF! -> #REF! | O10: =M10+K10+I10 -> #REF! | P10: =N10+L10+J10 -> #REF! | Q10: =P10+O10 -> #REF! | R10: =المهني!#REF! -> #REF! | S10: =المهني!#REF! -> #REF! | T10: =المهني!#REF! -> #REF! | U10: =T10+S10+R10 -> #REF!
A11: الزراعي | B11: 0 | C11: 0 | D11: 0 | E11: =D11+C11+B11 -> 0 | F11: 0 | G11: 0 | H11: =G11+F11 -> 0 | I11: 0 | J11: 0 | K11: 0 | L11: 0 | M11: 0 | N11: 0 | O11: =M11+K11+I11 -> 0 | P11: =N11+L11+J11 -> 0 | Q11: =P11+O11 -> 0 | R11: 0 | S11: 0 | T11: 0 | U11: =T11+S11+R11 -> 0
A12: التجاري | B12: 0 | C12: 0 | D12: 0 | E12: =D12+C12+B12 -> 0 | F12: 0 | G12: 0 | H12: =G12+F12 -> 0 | I12: =المهني!AS20 -> 0 | J12: 0 | K12: =المهني!BF20 -> 0 | L12: 0 | M12: =المهني!BS20 -> 0 | N12: 0 | O12: =M12+K12+I12 -> 0 | P12: =N12+L12+J12 -> 0 | Q12: =P12+O12 -> 0 | R12: =المهني!CV20 -> 0 | S12: 0 | T12: 0 | U12: =T12+S12+R12 -> 0
A13: فنون تطبيقية | B13: 0 | C13: 0 | D13: 0 | E13: =D13+C13+B13 -> 0 | F13: 0 | G13: 0 | H13: =G13+F13 -> 0 | J13: 0 | L13: 0 | N13: 0 | P13: =N13+L13+J13 -> 0 | Q13: =P13+O13 -> 0 | S13: 0 | U13: =T13+S13+R13 -> 0
A14: سياحة | B14: 0 | C14: 0 | D14: 0 | E14: =D14+C14+B14 -> 0 | F14: 0 | G14: 0 | H14: 0 | J14: 0 | K14: 0 | L14: 0 | M14: 0 | N14: 0 | O14: 0 | P14: =N14+L14+J14 -> 0 | Q14: =P14+O14 -> 0 | R14: 0 | S14: 0 | T14: 0 | U14: =T14+S14+R14 -> 0
A15: العلوم الرياضية | B15: 0 | C15: 5 | D15: 0 | E15: =D15+C15+B15 -> 5 | F15: 0 | G15: 0 | H15: 0 | J15: 0 | K15: 0 | L15: 0 | M15: 0 | N15: 0 | O15: 0 | P15: =N15+L15+J15 -> 0 | Q15: =P15+O15 -> 0 | R15: 0 | S15: 0 | T15: 0 | U15: =T15+S15+R15 -> 0
A16: الحاسوب وتقنية المعلومات | B16: 0 | C16: 0 | D16: 0 | E16: =D16+C16+B16 -> 0 | F16: 0 | G16: 0 | H16: =G16+F16 -> 0 | I16: 0 | J16: 0 | K16: 0 | L16: 0 | M16: 0 | N16: 0 | O16: 0 | P16: 0 | Q16: =P16+O16 -> 0 | R16: 0 | S16: 0 | T16: 0 | U16: 0
A17: المجموع | B17: =B13+B12+B11+B10 -> 0 | C17: =C13+C12+C11+C10 -> #REF! | D17: =D13+D12+D11+D10 -> #REF! | E17: =E13+E12+E11+E10 -> #REF! | F17: =F13+F12+F11+F10 -> #REF! | G17: =G13+G12+G11+G10 -> #REF! | H17: =H13+H12+H11+H10 -> #REF! | I17: =I13+I12+I11+I10 -> #REF! | ... U17: =U13+U12+U11+U10 -> #REF!
A19: المديرية العامة للتربية في محافظة النجف الاشرف | S19: التعليم المهني
B20: قسم التخطيط التربوي | J20: خلاصة قضاء النجف
A21: جدول رقم ( 3 )
A22: التعليـــم المهـــني الاهـــــلي للعام الدراسي 2025 / 2026
A23: عدد المدارس والمدرسين والطلبة والشعب (( المدارس المسائية فقط ))
A25: الفرع | B25: عدد المدارس | F25: عدد المدرسين | I25: عدد الطلبة المسجلين | R25: الشعب
I26: الصف الاول | K26: الصف الثاني | M26: الصف الثالث | O26: المجموع الكلي
B27: بنون | C27: بنات | D27: مختلطة | E27: المجموع | F27: بنون | G27: بنات | H27: المجموع | I27: بنون | J27: بنات | K27: بنون | L27: بنات | M27: بنون | N27: بنات | O27: بنون | P27: بنات | Q27: المجموع | R27: بنون | S27: بنات | T27: مختلط | U27: المجموع
A28: الصناعي | B28: =المهني!#REF! -> #REF! | C28: =المهني!#REF! -> #REF! | D28: =المهني!#REF! -> #REF! | E28: =D28+C28+B28 -> #REF! | F28: =المهني!#REF! -> #REF! | G28: =المهني!#REF! -> #REF! | H28: =G28+F28 -> #REF! | I28: =المهني!#REF! -> #REF! | J28: =المهني!#REF! -> #REF! | K28: =المهني!#REF! -> #REF! | L28: =المهني!#REF! -> #REF! | M28: =المهني!#REF! -> #REF! | N28: =المهني!#REF! -> #REF! | O28: =M28+K28+I28 -> #REF! | P28: =N28+L28+J28 -> #REF! | Q28: =P28+O28 -> #REF! | R28: =المهني!#REF! -> #REF! | S28: =المهني!#REF! -> #REF! | T28: =المهني!#REF! -> #REF! | U28: =T28+S28+R28 -> #REF!
A29: الزراعي | B29: 0 | C29: 0 | D29: 0 | E29: =D29+C29+B29 -> 0 | F29: 0 | G29: 0 | H29: =G29+F29 -> 0 | I29: 0 | J29: 0 | K29: 0 | L29: 0 | M29: 0 | N29: 0 | O29: =M29+K29+I29 -> 0 | P29: =N29+L29+J29 -> 0 | Q29: =P29+O29 -> 0 | R29: 0 | S29: 0 | T29: 0 | U29: =T29+S29+R29 -> 0
A30: التجاري | B30: 0 | C30: 0 | D30: 0 | E30: =D30+C30+B30 -> 0 | F30: 0 | G30: 0 | H30: =G30+F30 -> 0 | I30: =المهني!AS20 -> 0 | J30: =المهني!AT20 -> 0 | K30: =المهني!BF20 -> 0 | L30: =المهني!BG20 -> 0 | M30: =المهني!BS20 -> 0 | N30: =المهني!BT20 -> 0 | O30: =M30+K30+I30 -> 0 | P30: =N30+L30+J30 -> 0 | Q30: =P30+O30 -> 0 | R30: =المهني!CV20 -> 0 | S30: 0 | T30: 0 | U30: =T30+S30+R30 -> 0
A31: فنون تطبيقية | B31: 0 | C31: 0 | D31: 0 | E31: =D31+C31+B31 -> 0 | F31: 0 | G31: 0 | H31: =G31+F31 -> 0 | J31: 0 | L31: 0 | N31: 0 | P31: =N31+L31+J31 -> 0 | Q31: =P31+O31 -> 0 | S31: 0 | U31: =T31+S31+R31 -> 0
A32: سياحة
A33: الحاسوب وتقنية المعلومات | E33: =D33+C33+B33 -> 0 | H33: 0 | O33: 0 | P33: 0 | Q33: 0 | U33: 0
A34: المجموع | B34: =B31+B30+B29+B28 -> #REF! | C34: =C31+C30+C29+C28 -> #REF! | D34: =D31+D30+D29+D28 -> #REF! | E34: =E31+E30+E29+E28 -> #REF! | F34: =F31+F30+F29+F28 -> #REF! | G34: =G31+G30+G29+G28 -> #REF! | H34: =H31+H30+H29+H28 -> #REF! | I34: =I31+I30+I29+I28 -> #REF! | ... U34: =U31+U30+U29+U28 -> #REF!
A37: المديرية العامة للتربية في محافظة النجف الاشرف | S37: التعليم المهني
B38: قسم التخطيط التربوي | I38: خلاصة قضاء الكوفة
A39: جدول رقم ( 3 )
A40: التعليـــم المهـــني الاهـــــلي للعام الدراسي 2025 / 2026
A41: عدد المدارس والمدرسين والطلبة والشعب (( المدارس المسائية فقط ))
A43: الفرع | B43: عدد المدارس | F43: عدد المدرسين | I43: عدد الطلبة المسجلين | R43: الشعب
I44: الصف الاول | K44: الصف الثاني | M44: الصف الثالث | O44: المجموع الكلي
B45: بنون | C45: بنات | D45: مختلطة | E45: المجموع | F45: بنون | G45: بنات | H45: المجموع | I45: بنون | J45: بنات | K45: بنون | L45: بنات | M45: بنون | N45: بنات | O45: بنون | P45: بنات | Q45: المجموع | R45: بنون | S45: بنات | T45: مختلط | U45: المجموع
A46: الصناعي | B46: 0 | C46: 0 | D46: 0 | E46: =D46+C46+B46 -> 0 | F46: 0 | G46: 0 | H46: =G46+F46 -> 0 | I46: 0 | J46: 0 | K46: 0 | L46: 0 | M46: 0 | N46: 0 | O46: =M46+K46+I46 -> 0 | P46: =N46+L46+J46 -> 0 | Q46: =P46+O46 -> 0 | R46: 0 | S46: 0 | T46: 0 | U46: =T46+S46+R46 -> 0
...

Sheet ج4
A1: المديرية العامة للتربية في محافظة النجف الاشرف | S1: التعليم المهني
A2: قسم التخطيط التربوي | I2: خلاصة محافظة النجف الاشرف
A3: جدول رقم ( 4 )
A4: التعليـــم المهـــني الاهـــــلي للعام الدراسي 2025 / 2026
A5: عدد الطلبة المسجلين حسب العمر والجنس والصف والفرع ( الصباحي والمسائي )
A7: الفرع | B7: الصف | D7: عمر 15 سنة | F7: عمر 16 سنة | H7: عمر 17 سنة | J7: عمر 18 سنة | L7: عمر 19 سنة | N7: عمر 20 سنة | P7: عمر 21 سنة | R7: المجموع
D8: بنون | E8: بنات | F8: بنون | G8: بنات | H8: بنون | I8: بنات | J8: بنون | K8: بنات | L8: بنون | M8: بنات | N8: بنون | O8: بنات | P8: بنون | Q8: بنات | R8: بنون | S8: بنات | T8: المجموع
A9: الصناعي | B9: الاول | D9: =المهني!AI17 -> 67 | E9: =المهني!AJ17 -> 13 | F9: =المهني!AK17 -> 59 | G9: =المهني!AL17 -> 20 | H9: =المهني!AM17 -> 45 | I9: =المهني!AN17 -> 20 | J9: =المهني!AO17 -> 29 | K9: =المهني!AP17 -> 7 | ... M9: =المهني!AR17 -> 0 | N9: 0 | O9: 0 | P9: 0 | Q9: 0 | R9: =P9+N9+L9+J9+H9+F9+D9 -> 200 | S9: =Q9+O9+M9+K9+I9+G9+E9 -> 60 | T9: =S9+R9 -> 260
B10: الثاني | F10: =المهني!AV17 -> 0 | G10: =المهني!AW17 -> 0 | H10: =المهني!AX17 -> 0 | I10: =المهني!AY17 -> 0 | J10: =المهني!AZ17 -> 0 | K10: =المهني!BA17 -> 0 | L10: =المهني!BB17 -> 0 | M10: =المهني!BC17 -> 0 | ... O10: =المهني!BE17 -> 0 | P10: 0 | Q10: 0 | R10: =P10+N10+L10+J10+H10+F10+D10 -> 0 | S10: =Q10+O10+M10+K10+I10+G10+E10 -> 0 | T10: =S10+R10 -> 0
B11: الثالث | H11: =المهني!BI17 -> 0 | I11: =المهني!BJ17 -> 0 | J11: =المهني!BK17 -> 0 | K11: =المهني!BL17 -> 0 | L11: =المهني!BM17 -> 0 | M11: =المهني!BN17 -> 0 | N11: =المهني!BO17 -> 0 | O11: =المهني!BP17 -> 0 | ... Q11: =المهني!BR17 -> 0 | R11: =P11+N11+L11+J11+H11+F11+D11 -> 0 | S11: =Q11+O11+M11+K11+I11+G11+E11 -> 0 | T11: =S11+R11 -> 0
B12: المجموع | D12: =D11+D10+D9 -> 67 | E12: =E11+E10+E9 -> 13 | F12: =F11+F10+F9 -> 59 | G12: =G11+G10+G9 -> 20 | H12: =H11+H10+H9 -> 45 | I12: =I11+I10+I9 -> 20 | J12: =J11+J10+J9 -> 29 | K12: =K11+K10+K9 -> 7 | ... T12: =T11+T10+T9 -> 260
A13: الزراعي | B13: الاول | D13: =المهني!AI28 -> 0 | E13: =المهني!AJ28 -> 0 | F13: =المهني!AK28 -> 0 | G13: =المهني!AL28 -> 0 | H13: =المهني!AM28 -> 0 | I13: =المهني!AN28 -> 0 | J13: =المهني!AO28 -> 0 | K13: =المهني!AP28 -> 0 | ... M13: =المهني!AR28 -> 0 | N13: 0 | O13: 0 | P13: 0 | Q13: 0 | R13: =P13+N13+L13+J13+H13+F13+D13 -> 0 | S13: =Q13+O13+M13+K13+I13+G13+E13 -> 0 | T13: =S13+R13 -> 0
B14: الثاني | F14: =المهني!AV28 -> 0 | G14: =المهني!AW28 -> 0 | H14: =المهني!AX28 -> 0 | I14: =المهني!AY28 -> 0 | J14: =المهني!AZ28 -> 0 | K14: =المهني!BA28 -> 0 | L14: =المهني!BB28 -> 0 | M14: =المهني!BC28 -> 0 | ... O14: =المهني!BE28 -> 0 | P14: 0 | Q14: 0 | R14: =P14+N14+L14+J14+H14+F14+D14 -> 0 | S14: =Q14+O14+M14+K14+I14+G14+E14 -> 0 | T14: =S14+R14 -> 0
B15: الثالث | H15: =المهني!BI28 -> 0 | I15: =المهني!BJ28 -> 0 | J15: =المهني!BK28 -> 0 | K15: =المهني!BL28 -> 0 | L15: =المهني!BM28 -> 0 | M15: =المهني!BN28 -> 0 | N15: =المهني!BO28 -> 0 | O15: =المهني!BP28 -> 0 | ... Q15: =المهني!BR28 -> 0 | R15: =P15+N15+L15+J15+H15+F15+D15 -> 0 | S15: =Q15+O15+M15+K15+I15+G15+E15 -> 0 | T15: =S15+R15 -> 0
B16: المجموع | D16: =D15+D14+D13 -> 0 | E16: =E15+E14+E13 -> 0 | F16: =F15+F14+F13 -> 0 | G16: =G15+G14+G13 -> 0 | H16: =H15+H14+H13 -> 0 | I16: =I15+I14+I13 -> 0 | J16: =J15+J14+J13 -> 0 | K16: =K15+K14+K13 -> 0 | ... Q16: =Q15+Q14+Q13 -> 0 | R16: =P16+N16+L16+J16+H16+F16+D16 -> 0 | S16: =Q16+O16+M16+K16+I16+G16+E16 -> 0 | T16: =S16+R16 -> 0
A17: التجاري | B17: الاول | D17: =المهني!AI23 -> 0 | E17: =المهني!AJ23 -> 0 | F17: =المهني!AK23 -> 0 | G17: =المهني!AL23 -> 0 | H17: =المهني!AM23 -> 0 | I17: =المهني!AN23 -> 0 | J17: =المهني!AO23 -> 0 | K17: =المهني!AP23 -> 0 | ... M17: =المهني!AR23 -> 0 | N17: 0 | O17: 0 | P17: 0 | Q17: 0 | R17: =P17+N17+L17+J17+H17+F17+D17 -> 0 | S17: =Q17+O17+M17+K17+I17+G17+E17 -> 0 | T17: =S17+R17 -> 0
B18: الثاني | F18: =المهني!AV23 -> 0 | G18: =المهني!AW23 -> 0 | H18: =المهني!AX23 -> 0 | I18: =المهني!AY23 -> 0 | J18: =المهني!AZ23 -> 0 | K18: =المهني!BA23 -> 0 | L18: =المهني!BB23 -> 0 | M18: =المهني!BC23 -> 0 | ... O18: =المهني!BE23 -> 0 | P18: 0 | Q18: 0 | R18: =P18+N18+L18+J18+H18+F18+D18 -> 0 | S18: =Q18+O18+M18+K18+I18+G18+E18 -> 0 | T18: =S18+R18 -> 0
B19: الثالث | H19: =المهني!BI23 -> 0 | I19: =المهني!BJ23 -> 0 | J19: =المهني!BK23 -> 0 | K19: =المهني!BL23 -> 0 | L19: =المهني!BM23 -> 0 | M19: =المهني!BN23 -> 0 | N19: =المهني!BO23 -> 0 | O19: =المهني!BP23 -> 0 | ... Q19: =المهني!BR23 -> 0 | R19: =P19+N19+L19+J19+H19+F19+D19 -> 0 | S19: =Q19+O19+M19+K19+I19+G19+E19 -> 0 | T19: =S19+R19 -> 0
B20: المجموع | D20: =D19+D18+D17 -> 0 | E20: =E19+E18+E17 -> 0 | F20: =F19+F18+F17 -> 0 | G20: =G19+G18+G17 -> 0 | H20: =H19+H18+H17 -> 0 | I20: =I19+I18+I17 -> 0 | J20: =J19+J18+J17 -> 0 | K20: =K19+K18+K17 -> 0 | ... Q20: =Q19+Q18+Q17 -> 0 | R20: =P20+N20+L20+J20+H20+F20+D20 -> 0 | S20: =Q20+O20+M20+K20+I20+G20+E20 -> 0 | T20: =S20+R20 -> 0
A21: الفنون التطبيقية | B21: الاول | E21: =المهني!AJ32 -> 0 | G21: =المهني!AL32 -> 0 | I21: =المهني!AN32 -> 0 | K21: =المهني!AP32 -> 0 | M21: =المهني!AR32 -> 0 | O21: 0 | Q21: 0 | S21: =Q21+O21+M21+K21+I21+G21+E21 -> 0 | T21: =S21+R21 -> 0
B22: الثاني | G22: =المهني!AW32 -> 0 | I22: =المهني!AY32 -> 0 | K22: =المهني!BA32 -> 0 | M22: =المهني!BC32 -> 0 | O22: =المهني!BE32 -> 0 | Q22: 0 | S22: =Q22+O22+M22+K22+I22+G22+E22 -> 0 | T22: =S22+R22 -> 0
B23: الثالث | I23: =المهني!BJ32 -> 0 | K23: =المهني!BL32 -> 0 | M23: =المهني!BN32 -> 0 | O23: =المهني!BP32 -> 0 | Q23: =المهني!BR32 -> 0 | S23: =Q23+O23+M23+K23+I23+G23+E23 -> 0 | T23: =S23+R23 -> 0
B24: المجموع | E24: =E23+E22+E21 -> 0 | G24: =G23+G22+G21 -> 0 | I24: =I23+I22+I21 -> 0 | K24: =K23+K22+K21 -> 0 | M24: =M23+M22+M21 -> 0 | O24: =O23+O22+O21 -> 0 | Q24: =Q23+Q22+Q21 -> 0 | S24: =Q24+O24+M24+K24+I24+G24+E24 -> 0 | T24: =S24+R24 -> 0
A25: سياحة | B25: الاول | D25: =المهني!AI38 -> 0 | E25: =المهني!AJ38 -> 0 | F25: =المهني!AK38 -> 0 | G25: =المهني!AL38 -> 0 | H25: =المهني!AM38 -> 0 | I25: =المهني!AN38 -> 0 | J25: =المهني!AO38 -> 0 | K25: =المهني!AP38 -> 0 | ... M25: =المهني!AR38 -> 0 | R25: =P25+N25+L25+J25+H25+F25+D25 -> 0 | S25: =Q25+O25+M25+K25+I25+G25+E25 -> 0 | T25: =S25+R25 -> 0
B26: الثاني | F26: =المهني!AV38 -> 0 | G26: =المهني!AW38 -> 0 | H26: =المهني!AX38 -> 0 | I26: =المهني!AY38 -> 0 | J26: =المهني!AZ38 -> 0 | K26: =المهني!BA38 -> 0 | L26: =المهني!BB38 -> 0 | M26: =المهني!BC38 -> 0 | ... O26: =المهني!BE38 -> 0 | R26: =P26+N26+L26+J26+H26+F26+D26 -> 0 | S26: =Q26+O26+M26+K26+I26+G26+E26 -> 0 | T26: =S26+R26 -> 0
B27: الثالث | H27: =المهني!BI38 -> 0 | I27: =المهني!BJ38 -> 0 | J27: =المهني!BK38 -> 0 | K27: =المهني!BL38 -> 0 | L27: =المهني!BM38 -> 0 | M27: =المهني!BN38 -> 0 | N27: =المهني!BO38 -> 0 | O27: =المهني!BP38 -> 0 | ... Q27: =المهني!BR38 -> 0 | R27: =P27+N27+L27+J27+H27+F27+D27 -> 0 | S27: =Q27+O27+M27+K27+I27+G27+E27 -> 0 | T27: =S27+R27 -> 0
B28: المجموع | D28: =D27+D26+D25 -> 0 | E28: =E27+E26+E25 -> 0 | F28: =F27+F26+F25 -> 0 | G28: =G27+G26+G25 -> 0 | H28: =H27+H26+H25 -> 0 | I28: =I27+I26+I25 -> 0 | J28: =J27+J26+J25 -> 0 | K28: =K27+K26+K25 -> 0 | ... Q28: =Q27+Q26+Q25 -> 0 | R28: =P28+N28+L28+J28+H28+F28+D28 -> 0 | S28: =Q28+O28+M28+K28+I28+G28+E28 -> 0 | T28: =S28+R28 -> 0
A29: العلوم الرياضية | B29: الاول | D29: =المهني!AI40 -> 0 | E29: =المهني!AJ40 -> 0 | F29: =المهني!AK40 -> 0 | G29: =المهني!AL40 -> 0 | H29: =المهني!AM40 -> 0 | I29: =المهني!AN40 -> 0 | J29: =المهني!AO40 -> 0 | K29: =المهني!AP40 -> 0 | ... M29: =المهني!AR40 -> 0 | R29: =P29+N29+L29+J29+H29+F29+D29 -> 0 | S29: =Q29+O29+M29+K29+I29+G29+E29 -> 0 | T29: =S29+R29 -> 0
